Workbook

Sheet 115+740
B1: 1 | C1: =+B1+1 -> 2 | D1: =+C1+1 -> 3 | E1: =+D1+1 -> 4 | F1: =+E1+1 -> 5 | G1: =+F1+1 -> 6 | H1: =+G1+1 -> 7 | I1: =+H1+1 -> 8 | J1: =+I1+1 -> 9 | ... W1: =+V1+1 -> 22 | Y1: =+W1+1 -> 23 | Z1: =+Y1+1 -> 24 | AA1: =+Z1+1 -> 25 | AB1: =+AA1+1 -> 26
A2: DỰ ÁN THÀNH PHẦN ĐOẠN HẬU GIANG - CÀ MAU
A3: THUỘC DỰ ÁN XÂY DỰNG CÔNG TRÌNH ĐƯỜNG BỘ CAO TỐC BẮC - NAM PHÍA ĐÔNG GIAI ĐOẠN 2021 - 2025
A4: =UPPER("GÓI THẦU XL03 :Thi Công Xây Dựng Đoạn Tuyến Km114+200 - Km126+223 Bao Gồm Tuyến Nối Nút Giao IC12 Với QL1 (bao gồm khảo sát, thiết kế BVTC)") -> GÓI THẦU XL03 :THI CÔNG XÂY DỰNG ĐOẠN TUYẾN KM114+200 - KM126+223 BAO GỒM TUYẾN NỐI NÚT GIAO IC12 VỚI QL1 (BAO GỒM KHẢO SÁT, THIẾT KẾ BVTC)
A5: CHỦ ĐẦU TƯ | I5: TƯ VẤN GIÁM SÁT | S5: NHÀ THẦU
A6: BAN QUẢN LÝ DỰ ÁN MỸ THUẬN | I6: =UPPER("Liên danh Phân viện KHCN GTVT phía Nam - Công ty Cổ phần Tư vấn kỹ thuật và xây dựng Hồng Hà") -> LIÊN DANH PHÂN VIỆN KHCN GTVT PHÍA NAM - CÔNG TY CỔ PHẦN TƯ VẤN KỸ THUẬT VÀ XÂY DỰNG HỒNG HÀ | S6: LIÊN DANH CC1 - HẢI ĐĂNG - VẠN CƯỜNG - 492 - BẮC TRUNG NAM
A7: BIỂU GHI ĐO QUAN TRẮC LÚN
A8: Người lập: | K8: Tên mốc:
A9: Thời tiết: | C9: Nắng | K9: Cao độ mốc: | M9: =C14 -> 1069
A10: Lý trình: | C10: Km115+740 | K10: Ngày đặt bàn: | M10: =B14 -> 45072
A12: Stt | B12: Ngày quan trắc | C12: Cao độ mốc (mm) | D12: Số đọc tại mốc (mm) | E12: Số đọc mia (mm) | H12: Cao độ quan trắc (mm) | K12: Chiều dài cần nối (mm) | N12: Cao độ bàn đo lún (mm) | Q12: Tốc độ lún (mm) | T12: Số đọc mia tại nền đắp tại tâm (mm) | U12: Cao độ nền đắp (mm) | X12: Chiều dày lớp đắp (m) | Y12: Đội quan trắc | Z12: Nhà thầu | AA12: Tư Vấn Giám Sát | AB12: Ghi chú
E13: Trái | F13: Giữa | G13: Phải | H13: Trái | I13: Giữa | J13: Phải | K13: Trái | L13: Giữa | M13: Phải | N13: Trái | O13: Giữa | P13: Phải | Q13: Trái | R13: Giữa | S13: Phải | U13: Trái | V13: Giữa | W13: Phải
A14: 0 | B14: 45072 | C14: 1069 | D14: 1620 | E14: =C14+D14-H14 -> 649 | F14: =C14+D14-I14 -> 699 | G14: =D14+C14-J14 -> 729 | H14: =K14+N14 -> 2040 | I14: =L14+O14 -> 1990 | J14: =M14+P14 -> 1960 | K14: 2000 | L14: 2000 | M14: 2000 | N14: 40 | O14: -10 | P14: -40 | Q14: =RANDBETWEEN(0,0) -> 0 | R14: =RANDBETWEEN(0,0) -> 0 | S14: =RANDBETWEEN(0,0) -> 0 | T14: =D14+C14-V14 -> 2699 | U14: =N14 -> 40 | V14: =O14 -> -10 | W14: =P14 -> -40 | AB14: Lắp đặt ban đầu
A15: 1 | B15: =B14+1 -> 45073 | C15: =C14 -> 1069 | D15: =D14-2 -> 1618 | E15: =C15+D15-H15 -> 647 | F15: =C15+D15-I15 -> 697 | G15: =D15+C15-J15 -> 727 | H15: =K15+N15 -> 2040 | I15: =L15+O15 -> 1990 | J15: =M15+P15 -> 1960 | K15: =K14 -> 2000 | L15: =L14 -> 2000 | M15: =M14 -> 2000 | N15: =N14-Q15 -> 40 | O15: =O14-R15 -> -10 | P15: =P14-S15 -> -40 | Q15: =RANDBETWEEN(0,0) -> 0 | R15: =RANDBETWEEN(0,0) -> 0 | S15: =RANDBETWEEN(0,0) -> 0 | T15: =D15+C15-V15 -> 2697 | U15: =U14+$X15*1000-Q15 -> 40 | V15: =V14+$X15*1000-R15 -> -10 | W15: =W14+$X15*1000-S15 -> -40
A16: 2 | B16: =B15+1 -> 45074 | C16: =C15 -> 1069 | D16: =D15-2 -> 1616 | E16: =C16+D16-H16 -> 645 | F16: =C16+D16-I16 -> 695 | G16: =D16+C16-J16 -> 725 | H16: =K16+N16 -> 2040 | I16: =L16+O16 -> 1990 | J16: =M16+P16 -> 1960 | K16: =K15 -> 2000 | L16: =L15 -> 2000 | M16: =M15 -> 2000 | N16: =N15-Q16 -> 40 | O16: =O15-R16 -> -10 | P16: =P15-S16 -> -40 | Q16: =RANDBETWEEN(0,0) -> 0 | R16: =RANDBETWEEN(0,0) -> 0 | S16: =RANDBETWEEN(0,0) -> 0 | T16: =D16+C16-V16 -> 2695 | U16: =U15+$X16*1000-Q16 -> 40 | V16: =V15+$X16*1000-R16 -> -10 | W16: =W15+$X16*1000-S16 -> -40
A17: 3 | B17: =B16+1 -> 45075 | C17: =C16 -> 1069 | D17: =D16-2 -> 1614 | E17: =C17+D17-H17 -> 643 | F17: =C17+D17-I17 -> 693 | G17: =D17+C17-J17 -> 723 | H17: =K17+N17 -> 2040 | I17: =L17+O17 -> 1990 | J17: =M17+P17 -> 1960 | K17: =K16 -> 2000 | L17: =L16 -> 2000 | M17: =M16 -> 2000 | N17: =N16-Q17 -> 40 | O17: =O16-R17 -> -10 | P17: =P16-S17 -> -40 | Q17: =RANDBETWEEN(0,0) -> 0 | R17: =RANDBETWEEN(0,0) -> 0 | S17: =RANDBETWEEN(0,0) -> 0 | T17: =D17+C17-V17 -> 2693 | U17: =U16+$X17*1000-Q17 -> 40 | V17: =V16+$X17*1000-R17 -> -10 | W17: =W16+$X17*1000-S17 -> -40
A18: 4 | B18: =B17+1 -> 45076 | C18: =C17 -> 1069 | D18: =D17-2 -> 1612 | E18: =C18+D18-H18 -> 641 | F18: =C18+D18-I18 -> 691 | G18: =D18+C18-J18 -> 721 | H18: =K18+N18 -> 2040 | I18: =L18+O18 -> 1990 | J18: =M18+P18 -> 1960 | K18: =K17 -> 2000 | L18: =L17 -> 2000 | M18: =M17 -> 2000 | N18: =N17-Q18 -> 40 | O18: =O17-R18 -> -10 | P18: =P17-S18 -> -40 | Q18: =RANDBETWEEN(0,0) -> 0 | R18: =RANDBETWEEN(0,0) -> 0 | S18: =RANDBETWEEN(0,0) -> 0 | T18: =D18+C18-V18 -> 2691 | U18: =U17+$X18*1000-Q18 -> 40 | V18: =V17+$X18*1000-R18 -> -10 | W18: =W17+$X18*1000-S18 -> -40
A19: 5 | B19: =B18+1 -> 45077 | C19: =C18 -> 1069 | D19: =D18-2 -> 1610 | E19: =C19+D19-H19 -> 639 | F19: =C19+D19-I19 -> 689 | G19: =D19+C19-J19 -> 719 | H19: =K19+N19 -> 2040 | I19: =L19+O19 -> 1990 | J19: =M19+P19 -> 1960 | K19: =K18 -> 2000 | L19: =L18 -> 2000 | M19: =M18 -> 2000 | N19: =N18-Q19 -> 40 | O19: =O18-R19 -> -10 | P19: =P18-S19 -> -40 | Q19: =RANDBETWEEN(0,0) -> 0 | R19: =RANDBETWEEN(0,0) -> 0 | S19: =RANDBETWEEN(0,0) -> 0 | T19: =D19+C19-V19 -> 2689 | U19: =U18+$X19*1000-Q19 -> 40 | V19: =V18+$X19*1000-R19 -> -10 | W19: =W18+$X19*1000-S19 -> -40
A20: 6 | B20: =B19+1 -> 45078 | C20: =C19 -> 1069 | D20: =D19-2 -> 1608 | E20: =C20+D20-H20 -> 637 | F20: =C20+D20-I20 -> 687 | G20: =D20+C20-J20 -> 717 | H20: =K20+N20 -> 2040 | I20: =L20+O20 -> 1990 | J20: =M20+P20 -> 1960 | K20: =K19 -> 2000 | L20: =L19 -> 2000 | M20: =M19 -> 2000 | N20: =N19-Q20 -> 40 | O20: =O19-R20 -> -10 | P20: =P19-S20 -> -40 | Q20: =RANDBETWEEN(0,0) -> 0 | R20: =RANDBETWEEN(0,0) -> 0 | S20: =RANDBETWEEN(0,0) -> 0 | T20: =D20+C20-V20 -> 2687 | U20: =U19+$X20*1000-Q20 -> 40 | V20: =V19+$X20*1000-R20 -> -10 | W20: =W19+$X20*1000-S20 -> -40
A21: 7 | B21: =B20+1 -> 45079 | C21: =C20 -> 1069 | D21: =D20-2 -> 1606 | E21: =C21+D21-H21 -> 635 | F21: =C21+D21-I21 -> 685 | G21: =D21+C21-J21 -> 715 | H21: =K21+N21 -> 2040 | I21: =L21+O21 -> 1990 | J21: =M21+P21 -> 1960 | K21: =K20 -> 2000 | L21: =L20 -> 2000 | M21: =M20 -> 2000 | N21: =N20-Q21 -> 40 | O21: =O20-R21 -> -10 | P21: =P20-S21 -> -40 | Q21: =RANDBETWEEN(0,0) -> 0 | R21: =RANDBETWEEN(0,0) -> 0 | S21: =RANDBETWEEN(0,0) -> 0 | T21: =D21+C21-V21 -> 2685 | U21: =U20+$X21*1000-Q21 -> 40 | V21: =V20+$X21*1000-R21 -> -10 | W21: =W20+$X21*1000-S21 -> -40
A22: 8 | B22: =B21+1 -> 45080 | C22: =C21 -> 1069 | D22: =D21-2 -> 1604 | E22: =C22+D22-H22 -> 633 | F22: =C22+D22-I22 -> 683 | G22: =D22+C22-J22 -> 713 | H22: =K22+N22 -> 2040 | I22: =L22+O22 -> 1990 | J22: =M22+P22 -> 1960 | K22: =K21 -> 2000 | L22: =L21 -> 2000 | M22: =M21 -> 2000 | N22: =N21-Q22 -> 40 | O22: =O21-R22 -> -10 | P22: =P21-S22 -> -40 | Q22: =RANDBETWEEN(0,0) -> 0 | R22: =RANDBETWEEN(0,0) -> 0 | S22: =RANDBETWEEN(0,0) -> 0 | T22: =D22+C22-V22 -> 2683 | U22: =U21+$X22*1000-Q22 -> 40 | V22: =V21+$X22*1000-R22 -> -10 | W22: =W21+$X22*1000-S22 -> -40
A23: 9 | B23: =B22+1 -> 45081 | C23: =C22 -> 1069 | D23: =D22-2 -> 1602 | E23: =C23+D23-H23 -> 631 | F23: =C23+D23-I23 -> 681 | G23: =D23+C23-J23 -> 711 | H23: =K23+N23 -> 2040 | I23: =L23+O23 -> 1990 | J23: =M23+P23 -> 1960 | K23: =K22 -> 2000 | L23: =L22 -> 2000 | M23: =M22 -> 2000 | N23: =N22-Q23 -> 40 | O23: =O22-R23 -> -10 | P23: =P22-S23 -> -40 | Q23: =RANDBETWEEN(0,0) -> 0 | R23: =RANDBETWEEN(0,0) -> 0 | S23: =RANDBETWEEN(0,0) -> 0 | T23: =D23+C23-V23 -> 2681 | U23: =U22+$X23*1000-Q23 -> 40 | V23: =V22+$X23*1000-R23 -> -10 | W23: =W22+$X23*1000-S23 -> -40
A24: 10 | B24: =B23+1 -> 45082 | C24: =C23 -> 1069 | D24: =D23-2 -> 1600 | E24: =C24+D24-H24 -> 629 | F24: =C24+D24-I24 -> 679 | G24: =D24+C24-J24 -> 709 | H24: =K24+N24 -> 2040 | I24: =L24+O24 -> 1990 | J24: =M24+P24 -> 1960 | K24: =K23 -> 2000 | L24: =L23 -> 2000 | M24: =M23 -> 2000 | N24: =N23-Q24 -> 40 | O24: =O23-R24 -> -10 | P24: =P23-S24 -> -40 | Q24: =RANDBETWEEN(0,0) -> 0 | R24: =RANDBETWEEN(0,0) -> 0 | S24: =RANDBETWEEN(0,0) -> 0 | T24: =D24+C24-V24 -> 2679 | U24: =U23+$X24*1000-Q24 -> 40 | V24: =V23+$X24*1000-R24 -> -10 | W24: =W23+$X24*1000-S24 -> -40
A25: 11 | B25: =B24+1 -> 45083 | C25: =C24 -> 1069 | D25: =D24-2 -> 1598 | E25: =C25+D25-H25 -> 627 | F25: =C25+D25-I25 -> 677 | G25: =D25+C25-J25 -> 707 | H25: =K25+N25 -> 2040 | I25: =L25+O25 -> 1990 | J25: =M25+P25 -> 1960 | K25: =K24 -> 2000 | L25: =L24 -> 2000 | M25: =M24 -> 2000 | N25: =N24-Q25 -> 40 | O25: =O24-R25 -> -10 | P25: =P24-S25 -> -40 | Q25: =RANDBETWEEN(0,0) -> 0 | R25: =RANDBETWEEN(0,0) -> 0 | S25: =RANDBETWEEN(0,0) -> 0 | T25: =D25+C25-V25 -> 2677 | U25: =U24+$X25*1000-Q25 -> 40 | V25: =V24+$X25*1000-R25 -> -10 | W25: =W24+$X25*1000-S25 -> -40
A26: 12 | B26: =B25+1 -> 45084 | C26: =C25 -> 1069 | D26: =D25-2 -> 1596 | E26: =C26+D26-H26 -> 625 | F26: =C26+D26-I26 -> 675 | G26: =D26+C26-J26 -> 705 | H26: =K26+N26 -> 2040 | I26: =L26+O26 -> 1990 | J26: =M26+P26 -> 1960 | K26: =K25 -> 2000 | L26: =L25 -> 2000 | M26: =M25 -> 2000 | N26: =N25-Q26 -> 40 | O26: =O25-R26 -> -10 | P26: =P25-S26 -> -40 | Q26: =RANDBETWEEN(0,0) -> 0 | R26: =RANDBETWEEN(0,0) -> 0 | S26: =RANDBETWEEN(0,0) -> 0 | T26: =D26+C26-V26 -> 2675 | U26: =U25+$X26*1000-Q26 -> 40 | V26: =V25+$X26*1000-R26 -> -10 | W26: =W25+$X26*1000-S26 -> -40
A27: 13 | B27: =B26+1 -> 45085 | C27: =C26 -> 1069 | D27: =D26-2 -> 1594 | E27: =C27+D27-H27 -> 630 | F27: =C27+D27-I27 -> 680 | G27: =D27+C27-J27 -> 712 | H27: =K27+N27 -> 2033 | I27: =L27+O27 -> 1983 | J27: =M27+P27 -> 1951 | K27: =K26 -> 2000 | L27: =L26 -> 2000 | M27: =M26 -> 2000 | N27: =N26-Q27 -> 33 | O27: =O26-R27 -> -17 | P27: =P26-S27 -> -49 | Q27: 7 | R27: 7 | S27: 9 | T27: =D27+C27-V27 -> 2570 | U27: =U26+0.06*1000-Q27 -> 93 | V27: =V26+$X27*1000-R27 -> 93 | W27: =W26+0.14*1000-S27 -> 91 | X27: 0.11 | Y27: 100 | Z27: 100 | AA27: 100 | AB27: 9
A28: 14 | B28: =B27+1 -> 45086 | C28: =C27 -> 1069 | D28: =D27-2 -> 1592 | E28: =C28+D28-H28 -> 634 | F28: =C28+D28-I28 -> 682 | G28: =D28+C28-J28 -> 716 | H28: =K28+N28 -> 2027 | I28: =L28+O28 -> 1979 | J28: =M28+P28 -> 1945 | K28: =K27 -> 2000 | L28: =L27 -> 2000 | M28: =M27 -> 2000 | N28: =N27-Q28 -> 27 | O28: =O27-R28 -> -21 | P28: =P27-S28 -> -55 | Q28: 6 | R28: 4 | S28: 6 | T28: =D28+C28-V28 -> 2572 | U28: =U27+$X28*1000-Q28 -> 87 | V28: =V27+$X28*1000-R28 -> 89 | W28: =W27+$X28*1000-S28 -> 85
A29: 15 | B29: =B28+1 -> 45087 | C29: =C28 -> 1069 | D29: =D28-2 -> 1590 | E29: =C29+D29-H29 -> 635 | F29: =C29+D29-I29 -> 682 | G29: =D29+C29-J29 -> 718 | H29: =K29+N29 -> 2024 | I29: =L29+O29 -> 1977 | J29: =M29+P29 -> 1941 | K29: =K28 -> 2000 | L29: =L28 -> 2000 | M29: =M28 -> 2000 | N29: =N28-Q29 -> 24 | O29: =O28-R29 -> -23 | P29: =P28-S29 -> -59 | Q29: 3 | R29: 2 | S29: 4 | T29: =D29+C29-V29 -> 2572 | U29: =U28+$X29*1000-Q29 -> 84 | V29: =V28+$X29*1000-R29 -> 87 | W29: =W28+$X29*1000-S29 -> 81
A30: 16 | B30: =B29+1 -> 45088 | C30: =C29 -> 1069 | D30: =D29-2 -> 1588 | E30: =C30+D30-H30 -> 633 | F30: =C30+D30-I30 -> 681 | G30: =D30+C30-J30 -> 716 | H30: =K30+N30 -> 2024 | I30: =L30+O30 -> 1976 | J30: =M30+P30 -> 1941 | K30: =K29 -> 2000 | L30: =L29 -> 2000 | M30: =M29 -> 2000 | N30: =N29-Q30 -> 24 | O30: =O29-R30 -> -24 | P30: =P29-S30 -> -59 | Q30: 0 | R30: 1 | S30: 0 | T30: =D30+C30-V30 -> 2571 | U30: =U29+$X30*1000-Q30 -> 84 | V30: =V29+$X30*1000-R30 -> 86 | W30: =W29+$X30*1000-S30 -> 81
A31: 17 | B31: =B30+1 -> 45089 | C31: =C30 -> 1069 | D31: =D30-2 -> 1586 | E31: =C31+D31-H31 -> 639 | F31: =C31+D31-I31 -> 685 | G31: =D31+C31-J31 -> 721 | H31: =K31+N31 -> 2016 | I31: =L31+O31 -> 1970 | J31: =M31+P31 -> 1934 | K31: =K30 -> 2000 | L31: =L30 -> 2000 | M31: =M30 -> 2000 | N31: =N30-Q31 -> 16 | O31: =O30-R31 -> -30 | P31: =P30-S31 -> -66 | Q31: 8 | R31: 6 | S31: 7 | T31: =D31+C31-V31 -> 2275 | U31: =U30+$X31*1000-Q31 -> 376 | V31: =V30+$X31*1000-R31 -> 380 | W31: =W30+$X31*1000-S31 -> 374 | X31: 0.3 | AB31: 8
A32: 18 | B32: =B31+1 -> 45090 | C32: =C31 -> 1069 | D32: =D31-2 -> 1584 | E32: =C32+D32-H32 -> 646 | F32: =C32+D32-I32 -> 690 | G32: =D32+C32-J32 -> 725 | H32: =K32+N32 -> 2007 | I32: =L32+O32 -> 1963 | J32: =M32+P32 -> 1928 | K32: =K31 -> 2000 | L32: =L31 -> 2000 | M32: =M31 -> 2000 | N32: =N31-Q32 -> 7 | O32: =O31-R32 -> -37 | P32: =P31-S32 -> -72 | Q32: 9 | R32: 7 | S32: 6 | T32: =D32+C32-V32 -> 2280 | U32: =U31+$X32*1000-Q32 -> 367 | V32: =V31+$X32*1000-R32 -> 373 | W32: =W31+$X32*1000-S32 -> 368
A33: 19 | B33: =B32+1 -> 45091 | C33: =C32 -> 1069 | D33: =D32-2 -> 1582 | E33: =C33+D33-H33 -> 651 | F33: =C33+D33-I33 -> 697 | G33: =D33+C33-J33 -> 730 | H33: =K33+N33 -> 2000 | I33: =L33+O33 -> 1954 | J33: =M33+P33 -> 1921 | K33: =K32 -> 2000 | L33: =L32 -> 2000 | M33: =M32 -> 2000 | N33: =N32-Q33 -> 0 | O33: =O32-R33 -> -46 | P33: =P32-S33 -> -79 | Q33: 7 | R33: 9 | S33: 7 | T33: =D33+C33-V33 -> 2287 | U33: =U32+$X33*1000-Q33 -> 360 | V33: =V32+$X33*1000-R33 -> 364 | W33: =W32+$X33*1000-S33 -> 361
A34: 20 | B34: =B33+1 -> 45092 | C34: =C33 -> 1069 | D34: =D33-2 -> 1580 | E34: =C34+D34-H34 -> 658 | F34: =C34+D34-I34 -> 703 | G34: =D34+C34-J34 -> 736 | H34: =K34+N34 -> 1991 | I34: =L34+O34 -> 1946 | J34: =M34+P34 -> 1913 | K34: =K33 -> 2000 | L34: =L33 -> 2000 | M34: =M33 -> 2000 | N34: =N33-Q34 -> -9 | O34: =O33-R34 -> -54 | P34: =P33-S34 -> -87 | Q34: 9 | R34: 8 | S34: 8 | T34: =D34+C34-V34 -> 2293 | U34: =U33+$X34*1000-Q34 -> 351 | V34: =V33+$X34*1000-R34 -> 356 | W34: =W33+$X34*1000-S34 -> 353
A35: 21 | B35: =B34+1 -> 45093 | C35: =C34 -> 1069 | D35: =D34-2 -> 1578 | E35: =C35+D35-H35 -> 665 | F35: =C35+D35-I35 -> 709 | G35: =D35+C35-J35 -> 743 | H35: =K35+N35 -> 1982 | I35: =L35+O35 -> 1938 | J35: =M35+P35 -> 1904 | K35: =K34 -> 2000 | L35: =L34 -> 2000 | M35: =M34 -> 2000 | N35: =N34-Q35 -> -18 | O35: =O34-R35 -> -62 | P35: =P34-S35 -> -96 | Q35: 9 | R35: 8 | S35: 9 | T35: =D35+C35-V35 -> 1999 | U35: =U34+$X35*1000-Q35 -> 642 | V35: =V34+$X35*1000-R35 -> 648 | W35: =W34+$X35*1000-S35 -> 644 | X35: 0.3 | AB35: 7
A36: 22 | B36: =B35+1 -> 45094 | C36: =C35 -> 1069 | D36: =D35-2 -> 1576 | E36: =C36+D36-H36 -> 665 | F36: =C36+D36-I36 -> 712 | G36: =D36+C36-J36 -> 743 | H36: =K36+N36 -> 1980 | I36: =L36+O36 -> 1933 | J36: =M36+P36 -> 1902 | K36: =K35 -> 2000 | L36: =L35 -> 2000 | M36: =M35 -> 2000 | N36: =N35-Q36 -> -20 | O36: =O35-R36 -> -67 | P36: =P35-S36 -> -98 | Q36: 2 | R36: 5 | S36: 2 | T36: =D36+C36-V36 -> 2002 | U36: =U35+$X36*1000-Q36 -> 640 | V36: =V35+$X36*1000-R36 -> 643 | W36: =W35+$X36*1000-S36 -> 642
A37: 23 | B37: =B36+1 -> 45095 | C37: =C36 -> 1069 | D37: =D36-2 -> 1574 | E37: =C37+D37-H37 -> 667 | F37: =C37+D37-I37 -> 715 | G37: =D37+C37-J37 -> 743 | H37: =K37+N37 -> 1976 | I37: =L37+O37 -> 1928 | J37: =M37+P37 -> 1900 | K37: =K36 -> 2000 | L37: =L36 -> 2000 | M37: =M36 -> 2000 | N37: =N36-Q37 -> -24 | O37: =O36-R37 -> -72 | P37: =P36-S37 -> -100 | Q37: 4 | R37: 5 | S37: 2 | T37: =D37+C37-V37 -> 2005 | U37: =U36+$X37*1000-Q37 -> 636 | V37: =V36+$X37*1000-R37 -> 638 | W37: =W36+$X37*1000-S37 -> 640
A38: 24 | B38: =B37+1 -> 45096 | C38: =C37 -> 1069 | D38: =D37-2 -> 1572 | E38: =C38+D38-H38 -> 669 | F38: =C38+D38-I38 -> 718 | G38: =D38+C38-J38 -> 746 | H38: =K38+N38 -> 1972 | I38: =L38+O38 -> 1923 | J38: =M38+P38 -> 1895 | K38: =K37 -> 2000 | L38: =L37 -> 2000 | M38: =M37 -> 2000 | N38: =N37-Q38 -> -28 | O38: =O37-R38 -> -77 | P38: =P37-S38 -> -105 | Q38: 4 | R38: 5 | S38: 5 | T38: =D38+C38-V38 -> 2008 | U38: =U37+$X38*1000-Q38 -> 632 | V38: =V37+$X38*1000-R38 -> 633 | W38: =W37+$X38*1000-S38 -> 635
A39: 25 | B39: =B38+1 -> 45097 | C39: =C38 -> 1069 | D39: =D38-2 -> 1570 | E39: =C39+D39-H39 -> 675 | F39: =C39+D39-I39 -> 724 | G39: =D39+C39-J39 -> 752 | H39: =K39+N39 -> 1964 | I39: =L39+O39 -> 1915 | J39: =M39+P39 -> 1887 | K39: =K38 -> 2000 | L39: =L38 -> 2000 | M39: =M38 -> 2000 | N39: =N38-Q39 -> -36 | O39: =O38-R39 -> -85 | P39: =P38-S39 -> -113 | Q39: 8 | R39: 8 | S39: 8 | T39: =D39+C39-V39 -> 1714 | U39: =U38+$X39*1000-Q39 -> 924 | V39: =V38+$X39*1000-R39 -> 925 | W39: =W38+$X39*1000-S39 -> 927 | X39: 0.3 | AB39: 6
A40: 26 | B40: =B39+1 -> 45098 | C40: =C39 -> 1069 | D40: =D39-2 -> 1568 | E40: =C40+D40-H40 -> 678 | F40: =C40+D40-I40 -> 724 | G40: =D40+C40-J40 -> 752 | H40: =K40+N40 -> 1959 | I40: =L40+O40 -> 1913 | J40: =M40+P40 -> 1885 | K40: =K39 -> 2000 | L40: =L39 -> 2000 | M40: =M39 -> 2000 | N40: =N39-Q40 -> -41 | O40: =O39-R40 -> -87 | P40: =P39-S40 -> -115 | Q40: 5 | R40: 2 | S40: 2 | T40: =D40+C40-V40 -> 1714 | U40: =U39+$X40*1000-Q40 -> 919 | V40: =V39+$X40*1000-R40 -> 923 | W40: =W39+$X40*1000-S40 -> 925
A41: 27 | B41: =B40+1 -> 45099 | C41: =C40 -> 1069 | D41: =D40-2 -> 1566 | E41: =C41+D41-H41 -> 680 | F41: =C41+D41-I41 -> 726 | G41: =D41+C41-J41 -> 752 | H41: =K41+N41 -> 1955 | I41: =L41+O41 -> 1909 | J41: =M41+P41 -> 1883 | K41: =K40 -> 2000 | L41: =L40 -> 2000 | M41: =M40 -> 2000 | N41: =N40-Q41 -> -45 | O41: =O40-R41 -> -91 | P41: =P40-S41 -> -117 | Q41: 4 | R41: 4 | S41: 2 | T41: =D41+C41-V41 -> 1716 | U41: =U40+$X41*1000-Q41 -> 915 | V41: =V40+$X41*1000-R41 -> 919 | W41: =W40+$X41*1000-S41 -> 923
...

Sheet BC.115+740
A1: 13 | B1: DỰ ÁN THÀNH PHẦN ĐOẠN HẬU GIANG - CÀ MAU
B2: THUỘC DỰ ÁN XÂY DỰNG CÔNG TRÌNH ĐƯỜNG BỘ CAO TỐC BẮC - NAM PHÍA ĐÔNG GIAI ĐOẠN 2021 - 2025
B3: =UPPER("GÓI THẦU XL03 :Thi Công Xây Dựng Đoạn Tuyến Km114+200 - Km126+223 Bao Gồm Tuyến Nối Nút Giao IC12 Với QL1 (bao gồm khảo sát, thiết kế BVTC)") -> GÓI THẦU XL03 :THI CÔNG XÂY DỰNG ĐOẠN TUYẾN KM114+200 - KM126+223 BAO GỒM TUYẾN NỐI NÚT GIAO IC12 VỚI QL1 (BAO GỒM KHẢO SÁT, THIẾT KẾ BVTC)
B4: CHỦ ĐẦU TƯ | J4: TƯ VẤN GIÁM SÁT | T4: NHÀ THẦU
B5: BAN QUẢN LÝ DỰ ÁN MỸ THUẬN | J5: =UPPER("Liên danh Phân viện KHCN GTVT phía Nam - Công ty Cổ phần Tư vấn kỹ thuật và xây dựng Hồng Hà") -> LIÊN DANH PHÂN VIỆN KHCN GTVT PHÍA NAM - CÔNG TY CỔ PHẦN TƯ VẤN KỸ THUẬT VÀ XÂY DỰNG HỒNG HÀ | T5: LIÊN DANH CC1 - HẢI ĐĂNG - VẠN CƯỜNG - 492 - BẮC TRUNG NAM
B6: BIỂU GHI ĐO QUAN TRẮC LÚN
B7: Người lập: | C7: ='115+740'!C8 -> 0 | L7: Tên mốc: | N7: ='115+740'!M8 -> 0
B8: Thời tiết: | C8: ='115+740'!C9 -> Nắng | L8: Cao độ mốc: | N8: ='115+740'!M9 -> 1069
B9: Lý trình: | C9: ='115+740'!C10 -> Km115+740 | L9: Ngày đặt bàn: | N9: ='115+740'!M10 -> 45072
B11: Ngày | C11: Ngày cộng dồn | D11: Cao độ mốc | E11: Số đọc mia của mốc | F11: Cao độ đường ngắm | G11: Trái | M11: Tim | S11: Phải | Z11: Chiều dày lớp đắp (m) | AA11: Chiều dày nền đắp (m) | AB11: Chiều Cao nền đắp (m)
G12: Cao độ đắp (mm) | H12: Số đọc mia | I12: Cao độ quan trắc (mm) | J12: Cao độ bàn đo lún (mm) | K12: Độ lún (mm) | L12: Độ lún tích lũy (mm) | M12: Cao độ đắp (mm) | N12: Số đọc mia | O12: Cao độ quan trắc (mm) | P12: Cao độ bàn đo lún (mm) | Q12: Độ lún (mm) | R12: Độ lún tích lũy (mm) | S12: Cao độ đắp (mm) | T12: Số đọc mia | U12: Cao độ quan trắc (mm) | V12: Cao độ bàn đo lún (mm) | W12: Độ lún (mm) | X12: Độ lún tích lũy (mm)
B13: ='115+740'!B14 -> 45072 | C13: 0 | D13: =VLOOKUP(B13,'115+740'!B14:AB115,2,FALSE) -> 1069 | E13: =VLOOKUP(B13,'115+740'!B14:AB115,3,FALSE) -> 1620 | F13: =D13+E13 -> 2689 | G13: =VLOOKUP(B13,'115+740'!$B$14:$AB$115,20,FALSE) -> 40 | H13: =VLOOKUP(B13,'115+740'!$B$14:$AB$115,4,FALSE) -> 649 | I13: =F13-H13 -> 2040 | J13: =VLOOKUP(B13,'115+740'!$B$14:$AB$115,13,FALSE) -> 40 | K13: ='115+740'!Q14 -> 0 | L13: 0 | M13: =VLOOKUP(B13,'115+740'!$B$14:$AB$115,21,FALSE) -> -10 | N13: =VLOOKUP(B13,'115+740'!$B$14:$AB$115,5,FALSE) -> 699 | O13: =F13-N13 -> 1990 | P13: =VLOOKUP(B13,'115+740'!$B$14:$AB$115,14,FALSE) -> -10 | Q13: 0 | R13: 0 | S13: =VLOOKUP(B13,'115+740'!$B$14:$AB$115,22,FALSE) -> -40 | T13: =VLOOKUP(B13,'115+740'!$B$13:$AB$115,6,FALSE) -> 729 | U13: =F13-T13 -> 1960 | V13: =VLOOKUP(B13,'115+740'!$B$14:$AB$115,15,FALSE) -> -40 | W13: 0 | X13: 0 | Y13: 0 | Z13: =IF(Y13>0,Y13,0) -> 0 | AA13: =Z13 -> 0 | AB13: 0
B14: ='115+740'!B15 -> 45073 | C14: =B14-B13 -> 1 | D14: =D13 -> 1069 | E14: =VLOOKUP(B14,'115+740'!B15:AB116,3,FALSE) -> 1618 | F14: =D14+E14 -> 2687 | G14: =VLOOKUP(B14,'115+740'!$B$15:$AB$115,20,FALSE) -> 40 | H14: =VLOOKUP(B14,'115+740'!$B$15:$AB$115,4,FALSE) -> 647 | I14: =F14-H14 -> 2040 | J14: =VLOOKUP(B14,'115+740'!$B$15:$AB$115,13,FALSE) -> 40 | K14: ='115+740'!Q15 -> 0 | L14: =+K14+L13 -> 0 | M14: =VLOOKUP(B14,'115+740'!$B$14:$AB$115,21,FALSE) -> -10 | N14: =VLOOKUP(B14,'115+740'!$B$15:$AB$115,5,FALSE) -> 697 | O14: =F14-N14 -> 1990 | P14: =VLOOKUP(B14,'115+740'!$B$15:$AB$115,14,FALSE) -> -10 | Q14: ='115+740'!R15 -> 0 | R14: =+Q14+R13 -> 0 | S14: =VLOOKUP(B14,'115+740'!$B$14:$AB$115,22,FALSE) -> -40 | T14: =VLOOKUP(B14,'115+740'!$B$15:$AB$115,6,FALSE) -> 727 | U14: =F14-T14 -> 1960 | V14: =VLOOKUP(B14,'115+740'!$B$15:$AB$115,15,FALSE) -> -40 | W14: ='115+740'!S15 -> 0 | X14: =+W14+X13 -> 0 | Y14: =S14-S13 -> 0 | Z14: =IF(Y14>0,Y14,0)/1000 -> 0 | AA14: =AA13+Z14 -> 0 | AB14: =(M14-$M$13-R14)/1000 -> 0
A15: 1 | B15: ='115+740'!B16 -> 45074 | C15: =B15-B14 -> 1 | D15: =D14 -> 1069 | E15: =VLOOKUP(B15,'115+740'!B16:AB117,3,FALSE) -> 1616 | F15: =D15+E15 -> 2685 | G15: =VLOOKUP(B15,'115+740'!$B$15:$AB$115,20,FALSE) -> 40 | H15: =VLOOKUP(B15,'115+740'!$B$15:$AB$115,4,FALSE) -> 645 | I15: =F15-H15 -> 2040 | J15: =VLOOKUP(B15,'115+740'!$B$15:$AB$115,13,FALSE) -> 40 | K15: ='115+740'!Q16 -> 0 | L15: =+K15+L14 -> 0 | M15: =VLOOKUP(B15,'115+740'!$B$14:$AB$115,21,FALSE) -> -10 | N15: =VLOOKUP(B15,'115+740'!$B$15:$AB$115,5,FALSE) -> 695 | O15: =F15-N15 -> 1990 | P15: =VLOOKUP(B15,'115+740'!$B$15:$AB$115,14,FALSE) -> -10 | Q15: ='115+740'!R16 -> 0 | R15: =+Q15+R14 -> 0 | S15: =VLOOKUP(B15,'115+740'!$B$14:$AB$115,22,FALSE) -> -40 | T15: =VLOOKUP(B15,'115+740'!$B$15:$AB$115,6,FALSE) -> 725 | U15: =F15-T15 -> 1960 | V15: =VLOOKUP(B15,'115+740'!$B$15:$AB$115,15,FALSE) -> -40 | W15: ='115+740'!S16 -> 0 | X15: =+W15+X14 -> 0 | Y15: =S15-S14 -> 0 | Z15: =IF(Y15>0,Y15,0)/1000 -> 0 | AA15: =AA14+Z15 -> 0 | AB15: =(M15-$M$13-R15)/1000 -> 0
A16: =A15+1 -> 2 | B16: ='115+740'!B17 -> 45075 | C16: =B16-B15 -> 1 | D16: =D15 -> 1069 | E16: =VLOOKUP(B16,'115+740'!B17:AB118,3,FALSE) -> 1614 | F16: =D16+E16 -> 2683 | G16: =VLOOKUP(B16,'115+740'!$B$15:$AB$115,20,FALSE) -> 40 | H16: =VLOOKUP(B16,'115+740'!$B$15:$AB$115,4,FALSE) -> 643 | I16: =F16-H16 -> 2040 | J16: =VLOOKUP(B16,'115+740'!$B$15:$AB$115,13,FALSE) -> 40 | K16: ='115+740'!Q17 -> 0 | L16: =+K16+L15 -> 0 | M16: =VLOOKUP(B16,'115+740'!$B$14:$AB$115,21,FALSE) -> -10 | N16: =VLOOKUP(B16,'115+740'!$B$15:$AB$115,5,FALSE) -> 693 | O16: =F16-N16 -> 1990 | P16: =VLOOKUP(B16,'115+740'!$B$15:$AB$115,14,FALSE) -> -10 | Q16: ='115+740'!R17 -> 0 | R16: =+Q16+R15 -> 0 | S16: =VLOOKUP(B16,'115+740'!$B$14:$AB$115,22,FALSE) -> -40 | T16: =VLOOKUP(B16,'115+740'!$B$15:$AB$115,6,FALSE) -> 723 | U16: =F16-T16 -> 1960 | V16: =VLOOKUP(B16,'115+740'!$B$15:$AB$115,15,FALSE) -> -40 | W16: ='115+740'!S17 -> 0 | X16: =+W16+X15 -> 0 | Y16: =S16-S15 -> 0 | Z16: =IF(Y16>0,Y16,0)/1000 -> 0 | AA16: =AA15+Z16 -> 0 | AB16: =(M16-$M$13-R16)/1000 -> 0
A17: =A16+1 -> 3 | B17: ='115+740'!B18 -> 45076 | C17: =B17-B16 -> 1 | D17: =D16 -> 1069 | E17: =VLOOKUP(B17,'115+740'!B18:AB119,3,FALSE) -> 1612 | F17: =D17+E17 -> 2681 | G17: =VLOOKUP(B17,'115+740'!$B$15:$AB$115,20,FALSE) -> 40 | H17: =VLOOKUP(B17,'115+740'!$B$15:$AB$115,4,FALSE) -> 641 | I17: =F17-H17 -> 2040 | J17: =VLOOKUP(B17,'115+740'!$B$15:$AB$115,13,FALSE) -> 40 | K17: ='115+740'!Q18 -> 0 | L17: =+K17+L16 -> 0 | M17: =VLOOKUP(B17,'115+740'!$B$14:$AB$115,21,FALSE) -> -10 | N17: =VLOOKUP(B17,'115+740'!$B$15:$AB$115,5,FALSE) -> 691 | O17: =F17-N17 -> 1990 | P17: =VLOOKUP(B17,'115+740'!$B$15:$AB$115,14,FALSE) -> -10 | Q17: ='115+740'!R18 -> 0 | R17: =+Q17+R16 -> 0 | S17: =VLOOKUP(B17,'115+740'!$B$14:$AB$115,22,FALSE) -> -40 | T17: =VLOOKUP(B17,'115+740'!$B$15:$AB$115,6,FALSE) -> 721 | U17: =F17-T17 -> 1960 | V17: =VLOOKUP(B17,'115+740'!$B$15:$AB$115,15,FALSE) -> -40 | W17: ='115+740'!S18 -> 0 | X17: =+W17+X16 -> 0 | Y17: =S17-S16 -> 0 | Z17: =IF(Y17>0,Y17,0)/1000 -> 0 | AA17: =AA16+Z17 -> 0 | AB17: =(M17-$M$13-R17)/1000 -> 0
A18: =A17+1 -> 4 | B18: ='115+740'!B19 -> 45077 | C18: =B18-B17 -> 1 | D18: =D17 -> 1069 | E18: =VLOOKUP(B18,'115+740'!B19:AB120,3,FALSE) -> 1610 | F18: =D18+E18 -> 2679 | G18: =VLOOKUP(B18,'115+740'!$B$15:$AB$115,20,FALSE) -> 40 | H18: =VLOOKUP(B18,'115+740'!$B$15:$AB$115,4,FALSE) -> 639 | I18: =F18-H18 -> 2040 | J18: =VLOOKUP(B18,'115+740'!$B$15:$AB$115,13,FALSE) -> 40 | K18: ='115+740'!Q19 -> 0 | L18: =+K18+L17 -> 0 | M18: =VLOOKUP(B18,'115+740'!$B$14:$AB$115,21,FALSE) -> -10 | N18: =VLOOKUP(B18,'115+740'!$B$15:$AB$115,5,FALSE) -> 689 | O18: =F18-N18 -> 1990 | P18: =VLOOKUP(B18,'115+740'!$B$15:$AB$115,14,FALSE) -> -10 | Q18: ='115+740'!R19 -> 0 | R18: =+Q18+R17 -> 0 | S18: =VLOOKUP(B18,'115+740'!$B$14:$AB$115,22,FALSE) -> -40 | T18: =VLOOKUP(B18,'115+740'!$B$15:$AB$115,6,FALSE) -> 719 | U18: =F18-T18 -> 1960 | V18: =VLOOKUP(B18,'115+740'!$B$15:$AB$115,15,FALSE) -> -40 | W18: ='115+740'!S19 -> 0 | X18: =+W18+X17 -> 0 | Y18: =S18-S17 -> 0 | Z18: =IF(Y18>0,Y18,0)/1000 -> 0 | AA18: =AA17+Z18 -> 0 | AB18: =(M18-$M$13-R18)/1000 -> 0
A19: =A18+1 -> 5 | B19: ='115+740'!B20 -> 45078 | C19: =B19-B18 -> 1 | D19: =D18 -> 1069 | E19: =VLOOKUP(B19,'115+740'!B20:AB121,3,FALSE) -> 1608 | F19: =D19+E19 -> 2677 | G19: =VLOOKUP(B19,'115+740'!$B$15:$AB$115,20,FALSE) -> 40 | H19: =VLOOKUP(B19,'115+740'!$B$15:$AB$115,4,FALSE) -> 637 | I19: =F19-H19 -> 2040 | J19: =VLOOKUP(B19,'115+740'!$B$15:$AB$115,13,FALSE) -> 40 | K19: ='115+740'!Q20 -> 0 | L19: =+K19+L18 -> 0 | M19: =VLOOKUP(B19,'115+740'!$B$14:$AB$115,21,FALSE) -> -10 | N19: =VLOOKUP(B19,'115+740'!$B$15:$AB$115,5,FALSE) -> 687 | O19: =F19-N19 -> 1990 | P19: =VLOOKUP(B19,'115+740'!$B$15:$AB$115,14,FALSE) -> -10 | Q19: ='115+740'!R20 -> 0 | R19: =+Q19+R18 -> 0 | S19: =VLOOKUP(B19,'115+740'!$B$14:$AB$115,22,FALSE) -> -40 | T19: =VLOOKUP(B19,'115+740'!$B$15:$AB$115,6,FALSE) -> 717 | U19: =F19-T19 -> 1960 | V19: =VLOOKUP(B19,'115+740'!$B$15:$AB$115,15,FALSE) -> -40 | W19: ='115+740'!S20 -> 0 | X19: =+W19+X18 -> 0 | Y19: =S19-S18 -> 0 | Z19: =IF(Y19>0,Y19,0)/1000 -> 0 | AA19: =AA18+Z19 -> 0 | AB19: =(M19-$M$13-R19)/1000 -> 0
A20: =A19+1 -> 6 | B20: ='115+740'!B21 -> 45079 | C20: =B20-B19 -> 1 | D20: =D19 -> 1069 | E20: =VLOOKUP(B20,'115+740'!B21:AB122,3,FALSE) -> 1606 | F20: =D20+E20 -> 2675 | G20: =VLOOKUP(B20,'115+740'!$B$15:$AB$115,20,FALSE) -> 40 | H20: =VLOOKUP(B20,'115+740'!$B$15:$AB$115,4,FALSE) -> 635 | I20: =F20-H20 -> 2040 | J20: =VLOOKUP(B20,'115+740'!$B$15:$AB$115,13,FALSE) -> 40 | K20: ='115+740'!Q21 -> 0 | L20: =+K20+L19 -> 0 | M20: =VLOOKUP(B20,'115+740'!$B$14:$AB$115,21,FALSE) -> -10 | N20: =VLOOKUP(B20,'115+740'!$B$15:$AB$115,5,FALSE) -> 685 | O20: =F20-N20 -> 1990 | P20: =VLOOKUP(B20,'115+740'!$B$15:$AB$115,14,FALSE) -> -10 | Q20: ='115+740'!R21 -> 0 | R20: =+Q20+R19 -> 0 | S20: =VLOOKUP(B20,'115+740'!$B$14:$AB$115,22,FALSE) -> -40 | T20: =VLOOKUP(B20,'115+740'!$B$15:$AB$115,6,FALSE) -> 715 | U20: =F20-T20 -> 1960 | V20: =VLOOKUP(B20,'115+740'!$B$15:$AB$115,15,FALSE) -> -40 | W20: ='115+740'!S21 -> 0 | X20: =+W20+X19 -> 0 | Y20: =S20-S19 -> 0 | Z20: =IF(Y20>0,Y20,0)/1000 -> 0 | AA20: =AA19+Z20 -> 0 | AB20: =(M20-$M$13-R20)/1000 -> 0
A21: =A20+1 -> 7 | B21: ='115+740'!B22 -> 45080 | C21: =B21-B20 -> 1 | D21: =D20 -> 1069 | E21: =VLOOKUP(B21,'115+740'!B22:AB123,3,FALSE) -> 1604 | F21: =D21+E21 -> 2673 | G21: =VLOOKUP(B21,'115+740'!$B$15:$AB$115,20,FALSE) -> 40 | H21: =VLOOKUP(B21,'115+740'!$B$15:$AB$115,4,FALSE) -> 633 | I21: =F21-H21 -> 2040 | J21: =VLOOKUP(B21,'115+740'!$B$15:$AB$115,13,FALSE) -> 40 | K21: ='115+740'!Q22 -> 0 | L21: =+K21+L20 -> 0 | M21: =VLOOKUP(B21,'115+740'!$B$14:$AB$115,21,FALSE) -> -10 | N21: =VLOOKUP(B21,'115+740'!$B$15:$AB$115,5,FALSE) -> 683 | O21: =F21-N21 -> 1990 | P21: =VLOOKUP(B21,'115+740'!$B$15:$AB$115,14,FALSE) -> -10 | Q21: ='115+740'!R22 -> 0 | R21: =+Q21+R20 -> 0 | S21: =VLOOKUP(B21,'115+740'!$B$14:$AB$115,22,FALSE) -> -40 | T21: =VLOOKUP(B21,'115+740'!$B$15:$AB$115,6,FALSE) -> 713 | U21: =F21-T21 -> 1960 | V21: =VLOOKUP(B21,'115+740'!$B$15:$AB$115,15,FALSE) -> -40 | W21: ='115+740'!S22 -> 0 | X21: =+W21+X20 -> 0 | Y21: =S21-S20 -> 0 | Z21: =IF(Y21>0,Y21,0)/1000 -> 0 | AA21: =AA20+Z21 -> 0 | AB21: =(M21-$M$13-R21)/1000 -> 0
B22: ='115+740'!B23 -> 45081 | C22: =B22-B21 -> 1 | D22: =D21 -> 1069 | E22: =VLOOKUP(B22,'115+740'!B23:AB124,3,FALSE) -> 1602 | F22: =D22+E22 -> 2671 | G22: =VLOOKUP(B22,'115+740'!$B$15:$AB$115,20,FALSE) -> 40 | H22: =VLOOKUP(B22,'115+740'!$B$15:$AB$115,4,FALSE) -> 631 | I22: =F22-H22 -> 2040 | J22: =VLOOKUP(B22,'115+740'!$B$15:$AB$115,13,FALSE) -> 40 | K22: ='115+740'!Q23 -> 0 | L22: =+K22+L21 -> 0 | M22: =VLOOKUP(B22,'115+740'!$B$14:$AB$115,21,FALSE) -> -10 | N22: =VLOOKUP(B22,'115+740'!$B$15:$AB$115,5,FALSE) -> 681 | O22: =F22-N22 -> 1990 | P22: =VLOOKUP(B22,'115+740'!$B$15:$AB$115,14,FALSE) -> -10 | Q22: ='115+740'!R23 -> 0 | R22: =+Q22+R21 -> 0 | S22: =VLOOKUP(B22,'115+740'!$B$14:$AB$115,22,FALSE) -> -40 | T22: =VLOOKUP(B22,'115+740'!$B$15:$AB$115,6,FALSE) -> 711 | U22: =F22-T22 -> 1960 | V22: =VLOOKUP(B22,'115+740'!$B$15:$AB$115,15,FALSE) -> -40 | W22: ='115+740'!S23 -> 0 | X22: =+W22+X21 -> 0 | Y22: =S22-S21 -> 0 | Z22: =IF(Y22>0,Y22,0)/1000 -> 0 | AA22: =AA21+Z22 -> 0 | AB22: =(M22-$M$13-R22)/1000 -> 0
B23: ='115+740'!B24 -> 45082 | C23: =B23-B22 -> 1 | D23: =D22 -> 1069 | E23: =VLOOKUP(B23,'115+740'!B24:AB125,3,FALSE) -> 1600 | F23: =D23+E23 -> 2669 | G23: =VLOOKUP(B23,'115+740'!$B$15:$AB$115,20,FALSE) -> 40 | H23: =VLOOKUP(B23,'115+740'!$B$15:$AB$115,4,FALSE) -> 629 | I23: =F23-H23 -> 2040 | J23: =VLOOKUP(B23,'115+740'!$B$15:$AB$115,13,FALSE) -> 40 | K23: ='115+740'!Q24 -> 0 | L23: =+K23+L22 -> 0 | M23: =VLOOKUP(B23,'115+740'!$B$14:$AB$115,21,FALSE) -> -10 | N23: =VLOOKUP(B23,'115+740'!$B$15:$AB$115,5,FALSE) -> 679 | O23: =F23-N23 -> 1990 | P23: =VLOOKUP(B23,'115+740'!$B$15:$AB$115,14,FALSE) -> -10 | Q23: ='115+740'!R24 -> 0 | R23: =+Q23+R22 -> 0 | S23: =VLOOKUP(B23,'115+740'!$B$14:$AB$115,22,FALSE) -> -40 | T23: =VLOOKUP(B23,'115+740'!$B$15:$AB$115,6,FALSE) -> 709 | U23: =F23-T23 -> 1960 | V23: =VLOOKUP(B23,'115+740'!$B$15:$AB$115,15,FALSE) -> -40 | W23: ='115+740'!S24 -> 0 | X23: =+W23+X22 -> 0 | Y23: =S23-S22 -> 0 | Z23: =IF(Y23>0,Y23,0)/1000 -> 0 | AA23: =AA22+Z23 -> 0 | AB23: =(M23-$M$13-R23)/1000 -> 0
B24: ='115+740'!B25 -> 45083 | C24: =B24-B23 -> 1 | D24: =D23 -> 1069 | E24: =VLOOKUP(B24,'115+740'!B25:AB126,3,FALSE) -> 1598 | F24: =D24+E24 -> 2667 | G24: =VLOOKUP(B24,'115+740'!$B$15:$AB$115,20,FALSE) -> 40 | H24: =VLOOKUP(B24,'115+740'!$B$15:$AB$115,4,FALSE) -> 627 | I24: =F24-H24 -> 2040 | J24: =VLOOKUP(B24,'115+740'!$B$15:$AB$115,13,FALSE) -> 40 | K24: ='115+740'!Q25 -> 0 | L24: =+K24+L23 -> 0 | M24: =VLOOKUP(B24,'115+740'!$B$14:$AB$115,21,FALSE) -> -10 | N24: =VLOOKUP(B24,'115+740'!$B$15:$AB$115,5,FALSE) -> 677 | O24: =F24-N24 -> 1990 | P24: =VLOOKUP(B24,'115+740'!$B$15:$AB$115,14,FALSE) -> -10 | Q24: ='115+740'!R25 -> 0 | R24: =+Q24+R23 -> 0 | S24: =VLOOKUP(B24,'115+740'!$B$14:$AB$115,22,FALSE) -> -40 | T24: =VLOOKUP(B24,'115+740'!$B$15:$AB$115,6,FALSE) -> 707 | U24: =F24-T24 -> 1960 | V24: =VLOOKUP(B24,'115+740'!$B$15:$AB$115,15,FALSE) -> -40 | W24: ='115+740'!S25 -> 0 | X24: =+W24+X23 -> 0 | Y24: =S24-S23 -> 0 | Z24: =IF(Y24>0,Y24,0)/1000 -> 0 | AA24: =AA23+Z24 -> 0 | AB24: =(M24-$M$13-R24)/1000 -> 0
B25: ='115+740'!B26 -> 45084 | C25: =B25-B24 -> 1 | D25: =D24 -> 1069 | E25: =VLOOKUP(B25,'115+740'!B26:AB127,3,FALSE) -> 1596 | F25: =D25+E25 -> 2665 | G25: =VLOOKUP(B25,'115+740'!$B$15:$AB$115,20,FALSE) -> 40 | H25: =VLOOKUP(B25,'115+740'!$B$15:$AB$115,4,FALSE) -> 625 | I25: =F25-H25 -> 2040 | J25: =VLOOKUP(B25,'115+740'!$B$15:$AB$115,13,FALSE) -> 40 | K25: ='115+740'!Q26 -> 0 | L25: =+K25+L24 -> 0 | M25: =VLOOKUP(B25,'115+740'!$B$14:$AB$115,21,FALSE) -> -10 | N25: =VLOOKUP(B25,'115+740'!$B$15:$AB$115,5,FALSE) -> 675 | O25: =F25-N25 -> 1990 | P25: =VLOOKUP(B25,'115+740'!$B$15:$AB$115,14,FALSE) -> -10 | Q25: ='115+740'!R26 -> 0 | R25: =+Q25+R24 -> 0 | S25: =VLOOKUP(B25,'115+740'!$B$14:$AB$115,22,FALSE) -> -40 | T25: =VLOOKUP(B25,'115+740'!$B$15:$AB$115,6,FALSE) -> 705 | U25: =F25-T25 -> 1960 | V25: =VLOOKUP(B25,'115+740'!$B$15:$AB$115,15,FALSE) -> -40 | W25: ='115+740'!S26 -> 0 | X25: =+W25+X24 -> 0 | Y25: =S25-S24 -> 0 | Z25: =IF(Y25>0,Y25,0)/1000 -> 0 | AA25: =AA24+Z25 -> 0 | AB25: =(M25-$M$13-R25)/1000 -> 0
B26: ='115+740'!B27 -> 45085 | C26: =B26-B25 -> 1 | D26: =D25 -> 1069 | E26: =VLOOKUP(B26,'115+740'!B27:AB128,3,FALSE) -> 1594 | F26: =D26+E26 -> 2663 | G26: =VLOOKUP(B26,'115+740'!$B$15:$AB$115,20,FALSE) -> 93 | H26: =VLOOKUP(B26,'115+740'!$B$15:$AB$115,4,FALSE) -> 630 | I26: =F26-H26 -> 2033 | J26: =VLOOKUP(B26,'115+740'!$B$15:$AB$115,13,FALSE) -> 33 | K26: ='115+740'!Q27 -> 7 | L26: =+K26+L25 -> 7 | M26: =VLOOKUP(B26,'115+740'!$B$14:$AB$115,21,FALSE) -> 93 | N26: =VLOOKUP(B26,'115+740'!$B$15:$AB$115,5,FALSE) -> 680 | O26: =F26-N26 -> 1983 | P26: =VLOOKUP(B26,'115+740'!$B$15:$AB$115,14,FALSE) -> -17 | Q26: ='115+740'!R27 -> 7 | R26: =+Q26+R25 -> 7 | S26: =VLOOKUP(B26,'115+740'!$B$14:$AB$115,22,FALSE) -> 91 | T26: =VLOOKUP(B26,'115+740'!$B$15:$AB$115,6,FALSE) -> 712 | U26: =F26-T26 -> 1951 | V26: =VLOOKUP(B26,'115+740'!$B$15:$AB$115,15,FALSE) -> -49 | W26: ='115+740'!S27 -> 9 | X26: =+W26+X25 -> 9 | Y26: =S26-S25 -> 131 | Z26: =IF(Y26>0,Y26,0)/1000 -> 0.131 | AA26: =AA25+Z26 -> 0.131 | AB26: =(M26-$M$13-R26)/1000 -> 0.096
B27: ='115+740'!B28 -> 45086 | C27: =B27-B26 -> 1 | D27: =D26 -> 1069 | E27: =VLOOKUP(B27,'115+740'!B28:AB129,3,FALSE) -> 1592 | F27: =D27+E27 -> 2661 | G27: =VLOOKUP(B27,'115+740'!$B$15:$AB$115,20,FALSE) -> 87 | H27: =VLOOKUP(B27,'115+740'!$B$15:$AB$115,4,FALSE) -> 634 | I27: =F27-H27 -> 2027 | J27: =VLOOKUP(B27,'115+740'!$B$15:$AB$115,13,FALSE) -> 27 | K27: ='115+740'!Q28 -> 6 | L27: =+K27+L26 -> 13 | M27: =VLOOKUP(B27,'115+740'!$B$14:$AB$115,21,FALSE) -> 89 | N27: =VLOOKUP(B27,'115+740'!$B$15:$AB$115,5,FALSE) -> 682 | O27: =F27-N27 -> 1979 | P27: =VLOOKUP(B27,'115+740'!$B$15:$AB$115,14,FALSE) -> -21 | Q27: ='115+740'!R28 -> 4 | R27: =+Q27+R26 -> 11 | S27: =VLOOKUP(B27,'115+740'!$B$14:$AB$115,22,FALSE) -> 85 | T27: =VLOOKUP(B27,'115+740'!$B$15:$AB$115,6,FALSE) -> 716 | U27: =F27-T27 -> 1945 | V27: =VLOOKUP(B27,'115+740'!$B$15:$AB$115,15,FALSE) -> -55 | W27: ='115+740'!S28 -> 6 | X27: =+W27+X26 -> 15 | Y27: =S27-S26 -> -6 | Z27: =IF(Y27>0,Y27,0)/1000 -> 0 | AA27: =AA26+Z27 -> 0.131 | AB27: =(M27-$M$13-R27)/1000 -> 0.088
B28: ='115+740'!B29 -> 45087 | C28: =B28-B27 -> 1 | D28: =D27 -> 1069 | E28: =VLOOKUP(B28,'115+740'!B29:AB130,3,FALSE) -> 1590 | F28: =D28+E28 -> 2659 | G28: =VLOOKUP(B28,'115+740'!$B$15:$AB$115,20,FALSE) -> 84 | H28: =VLOOKUP(B28,'115+740'!$B$15:$AB$115,4,FALSE) -> 635 | I28: =F28-H28 -> 2024 | J28: =VLOOKUP(B28,'115+740'!$B$15:$AB$115,13,FALSE) -> 24 | K28: ='115+740'!Q29 -> 3 | L28: =+K28+L27 -> 16 | M28: =VLOOKUP(B28,'115+740'!$B$14:$AB$115,21,FALSE) -> 87 | N28: =VLOOKUP(B28,'115+740'!$B$15:$AB$115,5,FALSE) -> 682 | O28: =F28-N28 -> 1977 | P28: =VLOOKUP(B28,'115+740'!$B$15:$AB$115,14,FALSE) -> -23 | Q28: ='115+740'!R29 -> 2 | R28: =+Q28+R27 -> 13 | S28: =VLOOKUP(B28,'115+740'!$B$14:$AB$115,22,FALSE) -> 81 | T28: =VLOOKUP(B28,'115+740'!$B$15:$AB$115,6,FALSE) -> 718 | U28: =F28-T28 -> 1941 | V28: =VLOOKUP(B28,'115+740'!$B$15:$AB$115,15,FALSE) -> -59 | W28: ='115+740'!S29 -> 4 | X28: =+W28+X27 -> 19 | Y28: =S28-S27 -> -4 | Z28: =IF(Y28>0,Y28,0)/1000 -> 0 | AA28: =AA27+Z28 -> 0.131 | AB28: =(M28-$M$13-R28)/1000 -> 0.084
B29: ='115+740'!B30 -> 45088 | C29: =B29-B28 -> 1 | D29: =D28 -> 1069 | E29: =VLOOKUP(B29,'115+740'!B30:AB131,3,FALSE) -> 1588 | F29: =D29+E29 -> 2657 | G29: =VLOOKUP(B29,'115+740'!$B$15:$AB$115,20,FALSE) -> 84 | H29: =VLOOKUP(B29,'115+740'!$B$15:$AB$115,4,FALSE) -> 633 | I29: =F29-H29 -> 2024 | J29: =VLOOKUP(B29,'115+740'!$B$15:$AB$115,13,FALSE) -> 24 | K29: ='115+740'!Q30 -> 0 | L29: =+K29+L28 -> 16 | M29: =VLOOKUP(B29,'115+740'!$B$14:$AB$115,21,FALSE) -> 86 | N29: =VLOOKUP(B29,'115+740'!$B$15:$AB$115,5,FALSE) -> 681 | O29: =F29-N29 -> 1976 | P29: =VLOOKUP(B29,'115+740'!$B$15:$AB$115,14,FALSE) -> -24 | Q29: ='115+740'!R30 -> 1 | R29: =+Q29+R28 -> 14 | S29: =VLOOKUP(B29,'115+740'!$B$14:$AB$115,22,FALSE) -> 81 | T29: =VLOOKUP(B29,'115+740'!$B$15:$AB$115,6,FALSE) -> 716 | U29: =F29-T29 -> 1941 | V29: =VLOOKUP(B29,'115+740'!$B$15:$AB$115,15,FALSE) -> -59 | W29: ='115+740'!S30 -> 0 | X29: =+W29+X28 -> 19 | Y29: =S29-S28 -> 0 | Z29: =IF(Y29>0,Y29,0)/1000 -> 0 | AA29: =AA28+Z29 -> 0.131 | AB29: =(M29-$M$13-R29)/1000 -> 0.082
B30: ='115+740'!B31 -> 45089 | C30: =B30-B29 -> 1 | D30: =D29 -> 1069 | E30: =VLOOKUP(B30,'115+740'!B31:AB132,3,FALSE) -> 1586 | F30: =D30+E30 -> 2655 | G30: =VLOOKUP(B30,'115+740'!$B$15:$AB$115,20,FALSE) -> 376 | H30: =VLOOKUP(B30,'115+740'!$B$15:$AB$115,4,FALSE) -> 639 | I30: =F30-H30 -> 2016 | J30: =VLOOKUP(B30,'115+740'!$B$15:$AB$115,13,FALSE) -> 16 | K30: ='115+740'!Q31 -> 8 | L30: =+K30+L29 -> 24 | M30: =VLOOKUP(B30,'115+740'!$B$14:$AB$115,21,FALSE) -> 380 | N30: =VLOOKUP(B30,'115+740'!$B$15:$AB$115,5,FALSE) -> 685 | O30: =F30-N30 -> 1970 | P30: =VLOOKUP(B30,'115+740'!$B$15:$AB$115,14,FALSE) -> -30 | Q30: ='115+740'!R31 -> 6 | R30: =+Q30+R29 -> 20 | S30: =VLOOKUP(B30,'115+740'!$B$14:$AB$115,22,FALSE) -> 374 | T30: =VLOOKUP(B30,'115+740'!$B$15:$AB$115,6,FALSE) -> 721 | U30: =F30-T30 -> 1934 | V30: =VLOOKUP(B30,'115+740'!$B$15:$AB$115,15,FALSE) -> -66 | W30: ='115+740'!S31 -> 7 | X30: =+W30+X29 -> 26 | Y30: =S30-S29 -> 293 | Z30: =IF(Y30>0,Y30,0)/1000 -> 0.293 | AA30: =AA29+Z30 -> 0.424 | AB30: =(M30-$M$13-R30)/1000 -> 0.37
B31: ='115+740'!B32 -> 45090 | C31: =B31-B30 -> 1 | D31: =D30 -> 1069 | E31: =VLOOKUP(B31,'115+740'!B32:AB133,3,FALSE) -> 1584 | F31: =D31+E31 -> 2653 | G31: =VLOOKUP(B31,'115+740'!$B$15:$AB$115,20,FALSE) -> 367 | H31: =VLOOKUP(B31,'115+740'!$B$15:$AB$115,4,FALSE) -> 646 | I31: =F31-H31 -> 2007 | J31: =VLOOKUP(B31,'115+740'!$B$15:$AB$115,13,FALSE) -> 7 | K31: ='115+740'!Q32 -> 9 | L31: =+K31+L30 -> 33 | M31: =VLOOKUP(B31,'115+740'!$B$14:$AB$115,21,FALSE) -> 373 | N31: =VLOOKUP(B31,'115+740'!$B$15:$AB$115,5,FALSE) -> 690 | O31: =F31-N31 -> 1963 | P31: =VLOOKUP(B31,'115+740'!$B$15:$AB$115,14,FALSE) -> -37 | Q31: ='115+740'!R32 -> 7 | R31: =+Q31+R30 -> 27 | S31: =VLOOKUP(B31,'115+740'!$B$14:$AB$115,22,FALSE) -> 368 | T31: =VLOOKUP(B31,'115+740'!$B$15:$AB$115,6,FALSE) -> 725 | U31: =F31-T31 -> 1928 | V31: =VLOOKUP(B31,'115+740'!$B$15:$AB$115,15,FALSE) -> -72 | W31: ='115+740'!S32 -> 6 | X31: =+W31+X30 -> 32 | Y31: =S31-S30 -> -6 | Z31: =IF(Y31>0,Y31,0)/1000 -> 0 | AA31: =AA30+Z31 -> 0.424 | AB31: =(M31-$M$13-R31)/1000 -> 0.356
B32: ='115+740'!B33 -> 45091 | C32: =B32-B31 -> 1 | D32: =D31 -> 1069 | E32: =VLOOKUP(B32,'115+740'!B33:AB134,3,FALSE) -> 1582 | F32: =D32+E32 -> 2651 | G32: =VLOOKUP(B32,'115+740'!$B$15:$AB$115,20,FALSE) -> 360 | H32: =VLOOKUP(B32,'115+740'!$B$15:$AB$115,4,FALSE) -> 651 | I32: =F32-H32 -> 2000 | J32: =VLOOKUP(B32,'115+740'!$B$15:$AB$115,13,FALSE) -> 0 | K32: ='115+740'!Q33 -> 7 | L32: =+K32+L31 -> 40 | M32: =VLOOKUP(B32,'115+740'!$B$14:$AB$115,21,FALSE) -> 364 | N32: =VLOOKUP(B32,'115+740'!$B$15:$AB$115,5,FALSE) -> 697 | O32: =F32-N32 -> 1954 | P32: =VLOOKUP(B32,'115+740'!$B$15:$AB$115,14,FALSE) -> -46 | Q32: ='115+740'!R33 -> 9 | R32: =+Q32+R31 -> 36 | S32: =VLOOKUP(B32,'115+740'!$B$14:$AB$115,22,FALSE) -> 361 | T32: =VLOOKUP(B32,'115+740'!$B$15:$AB$115,6,FALSE) -> 730 | U32: =F32-T32 -> 1921 | V32: =VLOOKUP(B32,'115+740'!$B$15:$AB$115,15,FALSE) -> -79 | W32: ='115+740'!S33 -> 7 | X32: =+W32+X31 -> 39 | Y32: =S32-S31 -> -7 | Z32: =IF(Y32>0,Y32,0)/1000 -> 0 | AA32: =AA31+Z32 -> 0.424 | AB32: =(M32-$M$13-R32)/1000 -> 0.338
B33: ='115+740'!B34 -> 45092 | C33: =B33-B32 -> 1 | D33: =D32 -> 1069 | E33: =VLOOKUP(B33,'115+740'!B34:AB135,3,FALSE) -> 1580 | F33: =D33+E33 -> 2649 | G33: =VLOOKUP(B33,'115+740'!$B$15:$AB$115,20,FALSE) -> 351 | H33: =VLOOKUP(B33,'115+740'!$B$15:$AB$115,4,FALSE) -> 658 | I33: =F33-H33 -> 1991 | J33: =VLOOKUP(B33,'115+740'!$B$15:$AB$115,13,FALSE) -> -9 | K33: ='115+740'!Q34 -> 9 | L33: =+K33+L32 -> 49 | M33: =VLOOKUP(B33,'115+740'!$B$14:$AB$115,21,FALSE) -> 356 | N33: =VLOOKUP(B33,'115+740'!$B$15:$AB$115,5,FALSE) -> 703 | O33: =F33-N33 -> 1946 | P33: =VLOOKUP(B33,'115+740'!$B$15:$AB$115,14,FALSE) -> -54 | Q33: ='115+740'!R34 -> 8 | R33: =+Q33+R32 -> 44 | S33: =VLOOKUP(B33,'115+740'!$B$14:$AB$115,22,FALSE) -> 353 | T33: =VLOOKUP(B33,'115+740'!$B$15:$AB$115,6,FALSE) -> 736 | U33: =F33-T33 -> 1913 | V33: =VLOOKUP(B33,'115+740'!$B$15:$AB$115,15,FALSE) -> -87 | W33: ='115+740'!S34 -> 8 | X33: =+W33+X32 -> 47 | Y33: =S33-S32 -> -8 | Z33: =IF(Y33>0,Y33,0)/1000 -> 0 | AA33: =AA32+Z33 -> 0.424 | AB33: =(M33-$M$13-R33)/1000 -> 0.322
... B76: ='115+740'!B77 -> 45135 | C76: =B76-B75 -> 1 | D76: =D75 -> 1069 | E76: =VLOOKUP(B76,'115+740'!B77:AB178,3,FALSE) -> 1494 | F76: =D76+E76 -> 2563 | G76: =VLOOKUP(B76,'115+740'!$B$15:$AB$115,20,FALSE) -> 860 | H76: =VLOOKUP(B76,'115+740'!$B$15:$AB$115,4,FALSE) -> 663 | I76: =F76-H76 -> 1900 | J76: =VLOOKUP(B76,'115+740'!$B$15:$AB$115,13,FALSE) -> -100 | K76: ='115+740'!Q77 -> 0 | L76: =+K76+L75 -> 140 | M76: =VLOOKUP(B76,'115+740'!$B$14:$AB$115,21,FALSE) -> 897 | N76: =VLOOKUP(B76,'115+740'!$B$15:$AB$115,5,FALSE) -> 676 | O76: =F76-N76 -> 1887 | P76: =VLOOKUP(B76,'115+740'!$B$15:$AB$115,14,FALSE) -> -113 | Q76: ='115+740'!R77 -> 0 | R76: =+Q76+R75 -> 103 | S76: =VLOOKUP(B76,'115+740'!$B$14:$AB$115,22,FALSE) -> 874 | T76: =VLOOKUP(B76,'115+740'!$B$15:$AB$115,6,FALSE) -> 729 | U76: =F76-T76 -> 1834 | V76: =VLOOKUP(B76,'115+740'!$B$15:$AB$115,15,FALSE) -> -166 | W76: ='115+740'!S77 -> 0 | X76: =+W76+X75 -> 126 | Y76: =S76-S75 -> 0 | Z76: =IF(Y76>0,Y76,0)/1000 -> 0 | AA76: =AA75+Z76 -> 1.007 | AB76: =(M76-$M$13-R76)/1000 -> 0.804
A77: 42307 | B77: ='115+740'!B78 -> 45136 | C77: =B77-B76 -> 1 | D77: =D76 -> 1069 | E77: =VLOOKUP(B77,'115+740'!B78:AB179,3,FALSE) -> 1492 | F77: =D77+E77 -> 2561 | G77: =VLOOKUP(B77,'115+740'!$B$15:$AB$115,20,FALSE) -> 860 | H77: =VLOOKUP(B77,'115+740'!$B$15:$AB$115,4,FALSE) -> 661 | I77: =F77-H77 -> 1900 | J77: =VLOOKUP(B77,'115+740'!$B$15:$AB$115,13,FALSE) -> -100 | K77: ='115+740'!Q78 -> 0 | L77: =+K77+L76 -> 140 | M77: =VLOOKUP(B77,'115+740'!$B$14:$AB$115,21,FALSE) -> 897 | N77: =VLOOKUP(B77,'115+740'!$B$15:$AB$115,5,FALSE) -> 674 | O77: =F77-N77 -> 1887 | P77: =VLOOKUP(B77,'115+740'!$B$15:$AB$115,14,FALSE) -> -113 | Q77: ='115+740'!R78 -> 0 | R77: =+Q77+R76 -> 103 | S77: =VLOOKUP(B77,'115+740'!$B$14:$AB$115,22,FALSE) -> 874 | T77: =VLOOKUP(B77,'115+740'!$B$15:$AB$115,6,FALSE) -> 727 | U77: =F77-T77 -> 1834 | V77: =VLOOKUP(B77,'115+740'!$B$15:$AB$115,15,FALSE) -> -166 | W77: ='115+740'!S78 -> 0 | X77: =+W77+X76 -> 126 | Y77: =S77-S76 -> 0 | Z77: =IF(Y77>0,Y77,0)/1000 -> 0 | AA77: =AA76+Z77 -> 1.007 | AB77: =(M77-$M$13-R77)/1000 -> 0.804
A78: 02/11/015 | B78: ='115+740'!B79 -> 45137 | C78: =B78-B77 -> 1 | D78: =D77 -> 1069 | E78: =VLOOKUP(B78,'115+740'!B79:AB180,3,FALSE) -> 1490 | F78: =D78+E78 -> 2559 | G78: =VLOOKUP(B78,'115+740'!$B$15:$AB$115,20,FALSE) -> 860 | H78: =VLOOKUP(B78,'115+740'!$B$15:$AB$115,4,FALSE) -> 659 | I78: =F78-H78 -> 1900 | J78: =VLOOKUP(B78,'115+740'!$B$15:$AB$115,13,FALSE) -> -100 | K78: ='115+740'!Q79 -> 0 | L78: =+K78+L77 -> 140 | M78: =VLOOKUP(B78,'115+740'!$B$14:$AB$115,21,FALSE) -> 897 | N78: =VLOOKUP(B78,'115+740'!$B$15:$AB$115,5,FALSE) -> 672 | O78: =F78-N78 -> 1887 | P78: =VLOOKUP(B78,'115+740'!$B$15:$AB$115,14,FALSE) -> -113 | Q78: ='115+740'!R79 -> 0 | R78: =+Q78+R77 -> 103 | S78: =VLOOKUP(B78,'115+740'!$B$14:$AB$115,22,FALSE) -> 874 | T78: =VLOOKUP(B78,'115+740'!$B$15:$AB$115,6,FALSE) -> 725 | U78: =F78-T78 -> 1834 | V78: =VLOOKUP(B78,'115+740'!$B$15:$AB$115,15,FALSE) -> -166 | W78: ='115+740'!S79 -> 0 | X78: =+W78+X77 -> 126 | Y78: =S78-S77 -> 0 | Z78: =IF(Y78>0,Y78,0)/1000 -> 0 | AA78: =AA77+Z78 -> 1.007 | AB78: =(M78-$M$13-R78)/1000 -> 0.804
A79: 42313 | B79: ='115+740'!B80 -> 45138 | C79: =B79-B78 -> 1 | D79: =D78 -> 1069 | E79: =VLOOKUP(B79,'115+740'!B80:AB181,3,FALSE) -> 1488 | F79: =D79+E79 -> 2557 | G79: =VLOOKUP(B79,'115+740'!$B$15:$AB$115,20,FALSE) -> 860 | H79: =VLOOKUP(B79,'115+740'!$B$15:$AB$115,4,FALSE) -> 657 | I79: =F79-H79 -> 1900 | J79: =VLOOKUP(B79,'115+740'!$B$15:$AB$115,13,FALSE) -> -100 | K79: ='115+740'!Q80 -> 0 | L79: =+K79+L78 -> 140 | M79: =VLOOKUP(B79,'115+740'!$B$14:$AB$115,21,FALSE) -> 897 | N79: =VLOOKUP(B79,'115+740'!$B$15:$AB$115,5,FALSE) -> 670 | O79: =F79-N79 -> 1887 | P79: =VLOOKUP(B79,'115+740'!$B$15:$AB$115,14,FALSE) -> -113 | Q79: ='115+740'!R80 -> 0 | R79: =+Q79+R78 -> 103 | S79: =VLOOKUP(B79,'115+740'!$B$14:$AB$115,22,FALSE) -> 874 | T79: =VLOOKUP(B79,'115+740'!$B$15:$AB$115,6,FALSE) -> 723 | U79: =F79-T79 -> 1834 | V79: =VLOOKUP(B79,'115+740'!$B$15:$AB$115,15,FALSE) -> -166 | W79: ='115+740'!S80 -> 0 | X79: =+W79+X78 -> 126 | Y79: =S79-S78 -> 0 | Z79: =IF(Y79>0,Y79,0)/1000 -> 0 | AA79: =AA78+Z79 -> 1.007 | AB79: =(M79-$M$13-R79)/1000 -> 0.804
A80: 42319 | B80: ='115+740'!B81 -> 45139 | C80: =B80-B79 -> 1 | D80: =D79 -> 1069 | E80: =VLOOKUP(B80,'115+740'!B81:AB182,3,FALSE) -> 1486 | F80: =D80+E80 -> 2555 | G80: =VLOOKUP(B80,'115+740'!$B$15:$AB$115,20,FALSE) -> 860 | H80: =VLOOKUP(B80,'115+740'!$B$15:$AB$115,4,FALSE) -> 655 | I80: =F80-H80 -> 1900 | J80: =VLOOKUP(B80,'115+740'!$B$15:$AB$115,13,FALSE) -> -100 | K80: ='115+740'!Q81 -> 0 | L80: =+K80+L79 -> 140 | M80: =VLOOKUP(B80,'115+740'!$B$14:$AB$115,21,FALSE) -> 897 | N80: =VLOOKUP(B80,'115+740'!$B$15:$AB$115,5,FALSE) -> 668 | O80: =F80-N80 -> 1887 | P80: =VLOOKUP(B80,'115+740'!$B$15:$AB$115,14,FALSE) -> -113 | Q80: ='115+740'!R81 -> 0 | R80: =+Q80+R79 -> 103 | S80: =VLOOKUP(B80,'115+740'!$B$14:$AB$115,22,FALSE) -> 874 | T80: =VLOOKUP(B80,'115+740'!$B$15:$AB$115,6,FALSE) -> 721 | U80: =F80-T80 -> 1834 | V80: =VLOOKUP(B80,'115+740'!$B$15:$AB$115,15,FALSE) -> -166 | W80: ='115+740'!S81 -> 0 | X80: =+W80+X79 -> 126 | Y80: =S80-S79 -> 0 | Z80: =IF(Y80>0,Y80,0)/1000 -> 0 | AA80: =AA79+Z80 -> 1.007 | AB80: =(M80-$M$13-R80)/1000 -> 0.804
A81: 42322 | B81: ='115+740'!B82 -> 45140 | C81: =B81-B80 -> 1 | D81: =D80 -> 1069 | E81: =VLOOKUP(B81,'115+740'!B82:AB183,3,FALSE) -> 1484 | F81: =D81+E81 -> 2553 | G81: =VLOOKUP(B81,'115+740'!$B$15:$AB$115,20,FALSE) -> 860 | H81: =VLOOKUP(B81,'115+740'!$B$15:$AB$115,4,FALSE) -> 653 | I81: =F81-H81 -> 1900 | J81: =VLOOKUP(B81,'115+740'!$B$15:$AB$115,13,FALSE) -> -100 | K81: ='115+740'!Q82 -> 0 | L81: =+K81+L80 -> 140 | M81: =VLOOKUP(B81,'115+740'!$B$14:$AB$115,21,FALSE) -> 897 | N81: =VLOOKUP(B81,'115+740'!$B$15:$AB$115,5,FALSE) -> 666 | O81: =F81-N81 -> 1887 | P81: =VLOOKUP(B81,'115+740'!$B$15:$AB$115,14,FALSE) -> -113 | Q81: ='115+740'!R82 -> 0 | R81: =+Q81+R80 -> 103 | S81: =VLOOKUP(B81,'115+740'!$B$14:$AB$115,22,FALSE) -> 874 | T81: =VLOOKUP(B81,'115+740'!$B$15:$AB$115,6,FALSE) -> 719 | U81: =F81-T81 -> 1834 | V81: =VLOOKUP(B81,'115+740'!$B$15:$AB$115,15,FALSE) -> -166 | W81: ='115+740'!S82 -> 0 | X81: =+W81+X80 -> 126 | Y81: =S81-S80 -> 0 | Z81: =IF(Y81>0,Y81,0)/1000 -> 0 | AA81: =AA80+Z81 -> 1.007 | AB81: =(M81-$M$13-R81)/1000 -> 0.804
A82: 17/11/015 | B82: ='115+740'!B83 -> 45141 | C82: =B82-B81 -> 1 | D82: =D81 -> 1069 | E82: =VLOOKUP(B82,'115+740'!B83:AB184,3,FALSE) -> 1482 | F82: =D82+E82 -> 2551 | G82: =VLOOKUP(B82,'115+740'!$B$15:$AB$115,20,FALSE) -> 860 | H82: =VLOOKUP(B82,'115+740'!$B$15:$AB$115,4,FALSE) -> 651 | I82: =F82-H82 -> 1900 | J82: =VLOOKUP(B82,'115+740'!$B$15:$AB$115,13,FALSE) -> -100 | K82: ='115+740'!Q83 -> 0 | L82: =+K82+L81 -> 140 | M82: =VLOOKUP(B82,'115+740'!$B$14:$AB$115,21,FALSE) -> 897 | N82: =VLOOKUP(B82,'115+740'!$B$15:$AB$115,5,FALSE) -> 664 | O82: =F82-N82 -> 1887 | P82: =VLOOKUP(B82,'115+740'!$B$15:$AB$115,14,FALSE) -> -113 | Q82: ='115+740'!R83 -> 0 | R82: =+Q82+R81 -> 103 | S82: =VLOOKUP(B82,'115+740'!$B$14:$AB$115,22,FALSE) -> 874 | T82: =VLOOKUP(B82,'115+740'!$B$15:$AB$115,6,FALSE) -> 717 | U82: =F82-T82 -> 1834 | V82: =VLOOKUP(B82,'115+740'!$B$15:$AB$115,15,FALSE) -> -166 | W82: ='115+740'!S83 -> 0 | X82: =+W82+X81 -> 126 | Y82: =S82-S81 -> 0 | Z82: =IF(Y82>0,Y82,0)/1000 -> 0 | AA82: =AA81+Z82 -> 1.007 | AB82: =(M82-$M$13-R82)/1000 -> 0.804
A83: 42328 | B83: ='115+740'!B84 -> 45142 | C83: =B83-B82 -> 1 | D83: =D82 -> 1069 | E83: =VLOOKUP(B83,'115+740'!B84:AB185,3,FALSE) -> 1480 | F83: =D83+E83 -> 2549 | G83: =VLOOKUP(B83,'115+740'!$B$15:$AB$115,20,FALSE) -> 860 | H83: =VLOOKUP(B83,'115+740'!$B$15:$AB$115,4,FALSE) -> 649 | I83: =F83-H83 -> 1900 | J83: =VLOOKUP(B83,'115+740'!$B$15:$AB$115,13,FALSE) -> -100 | K83: ='115+740'!Q84 -> 0 | L83: =+K83+L82 -> 140 | M83: =VLOOKUP(B83,'115+740'!$B$14:$AB$115,21,FALSE) -> 897 | N83: =VLOOKUP(B83,'115+740'!$B$15:$AB$115,5,FALSE) -> 662 | O83: =F83-N83 -> 1887 | P83: =VLOOKUP(B83,'115+740'!$B$15:$AB$115,14,FALSE) -> -113 | Q83: ='115+740'!R84 -> 0 | R83: =+Q83+R82 -> 103 | S83: =VLOOKUP(B83,'115+740'!$B$14:$AB$115,22,FALSE) -> 874 | T83: =VLOOKUP(B83,'115+740'!$B$15:$AB$115,6,FALSE) -> 715 | U83: =F83-T83 -> 1834 | V83: =VLOOKUP(B83,'115+740'!$B$15:$AB$115,15,FALSE) -> -166 | W83: ='115+740'!S84 -> 0 | X83: =+W83+X82 -> 126 | Y83: =S83-S82 -> 0 | Z83: =IF(Y83>0,Y83,0)/1000 -> 0 | AA83: =AA82+Z83 -> 1.007 | AB83: =(M83-$M$13-R83)/1000 -> 0.804
...

Sheet SL.115+740
A4: CHỦ ĐẦU TƯ | F4: TƯ VẤN GIÁM SÁT | K4: NHÀ THẦU
A6: BIỂU GHI ĐO QUAN TRẮC LÚN
A7: Người lập: | B7: ='[4]BC.95+020'!C7 -> 0 | K7: Tên mốc: | M7: ='[4]BC.95+020'!N7 -> 0
A8: Thời tiết: | B8: ='[4]BC.95+020'!C8 -> năng | K8: Cao độ mốc: | M8: ='115+740'!M9 -> 1069
A9: Lý trình: | B9: ='115+740'!C10 -> Km115+740 | K9: Ngày đặt bàn: | M9: ='115+740'!M10 -> 45072
A11: ="BÀN QUAN TRẮC: "&B9 -> BÀN QUAN TRẮC: Km115+740
A12: Ngày đo | B12: Số ngày | C12: Cao độ đắp(m) | D12: Chiều dày nền đắp (m) | E12: Chiều cao nền đắp (m) | F12: Trái | H12: Giữa | J12: Phải | L12: Độ lún (trái) (mm) | M12: Độ lún (giữa) (mm) | N12: Độ lún (phải) (mm) | O12: Ghi chú
F13: Cao độ quan trắc | G13: Cao độ bàn đo lún | H13: Cao độ quan trắc | I13: Cao độ bàn đo lún | J13: Cao độ quan trắc | K13: Cao độ bàn đo lún
A14: ='BC.115+740'!B13 -> 45072 | B14: 0 | C14: ='BC.115+740'!M13/1000 -> -0.01 | D14: ='BC.115+740'!AA13 -> 0 | E14: ='BC.115+740'!AB13 -> 0 | F14: =VLOOKUP($A14,'BC.115+740'!$B$13:$X$489,8,0)/1000 -> 2.04 | G14: =VLOOKUP($A14,'BC.115+740'!$B$13:$X$489,9,0)/1000 -> 0.04 | H14: =VLOOKUP($A14,'BC.115+740'!$B$13:$X$489,14,0)/1000 -> 1.99 | I14: =VLOOKUP($A14,'BC.115+740'!$B$13:$X$489,15,0)/1000 -> -0.01 | J14: =VLOOKUP($A14,'BC.115+740'!$B$13:$X$489,20,0)/1000 -> 1.96 | K14: =VLOOKUP($A14,'BC.115+740'!$B$13:$X$489,21,0)/1000 -> -0.04 | L14: =(G14-$G$14)*1000 -> 0 | M14: =(I14-$I$14)*1000 -> 0 | N14: 0
A15: ='BC.115+740'!B14 -> 45073 | B15: 1 | C15: ='BC.115+740'!M14/1000 -> -0.01 | D15: ='BC.115+740'!AA14 -> 0 | E15: ='BC.115+740'!AB14 -> 0 | F15: =VLOOKUP($A15,'BC.115+740'!$B$13:$X$489,8,0)/1000 -> 2.04 | G15: =VLOOKUP($A15,'BC.115+740'!$B$13:$X$489,9,0)/1000 -> 0.04 | H15: =VLOOKUP($A15,'BC.115+740'!$B$13:$X$489,14,0)/1000 -> 1.99 | I15: =VLOOKUP($A15,'BC.115+740'!$B$13:$X$489,15,0)/1000 -> -0.01 | J15: =VLOOKUP($A15,'BC.115+740'!$B$13:$X$489,20,0)/1000 -> 1.96 | K15: =VLOOKUP($A15,'BC.115+740'!$B$13:$X$489,21,0)/1000 -> -0.04 | L15: =(G15-$G$14)*1000 -> 0 | M15: =(I15-$I$14)*1000 -> 0 | N15: =(K15-$K$14)*1000 -> 0
A16: ='BC.115+740'!B15 -> 45074 | B16: 2 | C16: ='BC.115+740'!M15/1000 -> -0.01 | D16: ='BC.115+740'!AA15 -> 0 | E16: ='BC.115+740'!AB15 -> 0 | F16: =VLOOKUP($A16,'BC.115+740'!$B$13:$X$489,8,0)/1000 -> 2.04 | G16: =VLOOKUP($A16,'BC.115+740'!$B$13:$X$489,9,0)/1000 -> 0.04 | H16: =VLOOKUP($A16,'BC.115+740'!$B$13:$X$489,14,0)/1000 -> 1.99 | I16: =VLOOKUP($A16,'BC.115+740'!$B$13:$X$489,15,0)/1000 -> -0.01 | J16: =VLOOKUP($A16,'BC.115+740'!$B$13:$X$489,20,0)/1000 -> 1.96 | K16: =VLOOKUP($A16,'BC.115+740'!$B$13:$X$489,21,0)/1000 -> -0.04 | L16: =(G16-$G$14)*1000 -> 0 | M16: =(I16-$I$14)*1000 -> 0 | N16: =(K16-$K$14)*1000 -> 0
A17: ='BC.115+740'!B16 -> 45075 | B17: 3 | C17: ='BC.115+740'!M16/1000 -> -0.01 | D17: ='BC.115+740'!AA16 -> 0 | E17: ='BC.115+740'!AB16 -> 0 | F17: =VLOOKUP($A17,'BC.115+740'!$B$13:$X$489,8,0)/1000 -> 2.04 | G17: =VLOOKUP($A17,'BC.115+740'!$B$13:$X$489,9,0)/1000 -> 0.04 | H17: =VLOOKUP($A17,'BC.115+740'!$B$13:$X$489,14,0)/1000 -> 1.99 | I17: =VLOOKUP($A17,'BC.115+740'!$B$13:$X$489,15,0)/1000 -> -0.01 | J17: =VLOOKUP($A17,'BC.115+740'!$B$13:$X$489,20,0)/1000 -> 1.96 | K17: =VLOOKUP($A17,'BC.115+740'!$B$13:$X$489,21,0)/1000 -> -0.04 | L17: =(G17-$G$14)*1000 -> 0 | M17: =(I17-$I$14)*1000 -> 0 | N17: =(K17-$K$14)*1000 -> 0
A18: ='BC.115+740'!B17 -> 45076 | B18: 4 | C18: ='BC.115+740'!M17/1000 -> -0.01 | D18: ='BC.115+740'!AA17 -> 0 | E18: ='BC.115+740'!AB17 -> 0 | F18: =VLOOKUP($A18,'BC.115+740'!$B$13:$X$489,8,0)/1000 -> 2.04 | G18: =VLOOKUP($A18,'BC.115+740'!$B$13:$X$489,9,0)/1000 -> 0.04 | H18: =VLOOKUP($A18,'BC.115+740'!$B$13:$X$489,14,0)/1000 -> 1.99 | I18: =VLOOKUP($A18,'BC.115+740'!$B$13:$X$489,15,0)/1000 -> -0.01 | J18: =VLOOKUP($A18,'BC.115+740'!$B$13:$X$489,20,0)/1000 -> 1.96 | K18: =VLOOKUP($A18,'BC.115+740'!$B$13:$X$489,21,0)/1000 -> -0.04 | L18: =(G18-$G$14)*1000 -> 0 | M18: =(I18-$I$14)*1000 -> 0 | N18: =(K18-$K$14)*1000 -> 0
A19: ='BC.115+740'!B18 -> 45077 | B19: 5 | C19: ='BC.115+740'!M18/1000 -> -0.01 | D19: ='BC.115+740'!AA18 -> 0 | E19: ='BC.115+740'!AB18 -> 0 | F19: =VLOOKUP($A19,'BC.115+740'!$B$13:$X$489,8,0)/1000 -> 2.04 | G19: =VLOOKUP($A19,'BC.115+740'!$B$13:$X$489,9,0)/1000 -> 0.04 | H19: =VLOOKUP($A19,'BC.115+740'!$B$13:$X$489,14,0)/1000 -> 1.99 | I19: =VLOOKUP($A19,'BC.115+740'!$B$13:$X$489,15,0)/1000 -> -0.01 | J19: =VLOOKUP($A19,'BC.115+740'!$B$13:$X$489,20,0)/1000 -> 1.96 | K19: =VLOOKUP($A19,'BC.115+740'!$B$13:$X$489,21,0)/1000 -> -0.04 | L19: =(G19-$G$14)*1000 -> 0 | M19: =(I19-$I$14)*1000 -> 0 | N19: =(K19-$K$14)*1000 -> 0
A20: ='BC.115+740'!B19 -> 45078 | B20: 6 | C20: ='BC.115+740'!M19/1000 -> -0.01 | D20: ='BC.115+740'!AA19 -> 0 | E20: ='BC.115+740'!AB19 -> 0 | F20: =VLOOKUP($A20,'BC.115+740'!$B$13:$X$489,8,0)/1000 -> 2.04 | G20: =VLOOKUP($A20,'BC.115+740'!$B$13:$X$489,9,0)/1000 -> 0.04 | H20: =VLOOKUP($A20,'BC.115+740'!$B$13:$X$489,14,0)/1000 -> 1.99 | I20: =VLOOKUP($A20,'BC.115+740'!$B$13:$X$489,15,0)/1000 -> -0.01 | J20: =VLOOKUP($A20,'BC.115+740'!$B$13:$X$489,20,0)/1000 -> 1.96 | K20: =VLOOKUP($A20,'BC.115+740'!$B$13:$X$489,21,0)/1000 -> -0.04 | L20: =(G20-$G$14)*1000 -> 0 | M20: =(I20-$I$14)*1000 -> 0 | N20: =(K20-$K$14)*1000 -> 0
A21: ='BC.115+740'!B20 -> 45079 | B21: 7 | C21: ='BC.115+740'!M20/1000 -> -0.01 | D21: ='BC.115+740'!AA20 -> 0 | E21: ='BC.115+740'!AB20 -> 0 | F21: =VLOOKUP($A21,'BC.115+740'!$B$13:$X$489,8,0)/1000 -> 2.04 | G21: =VLOOKUP($A21,'BC.115+740'!$B$13:$X$489,9,0)/1000 -> 0.04 | H21: =VLOOKUP($A21,'BC.115+740'!$B$13:$X$489,14,0)/1000 -> 1.99 | I21: =VLOOKUP($A21,'BC.115+740'!$B$13:$X$489,15,0)/1000 -> -0.01 | J21: =VLOOKUP($A21,'BC.115+740'!$B$13:$X$489,20,0)/1000 -> 1.96 | K21: =VLOOKUP($A21,'BC.115+740'!$B$13:$X$489,21,0)/1000 -> -0.04 | L21: =(G21-$G$14)*1000 -> 0 | M21: =(I21-$I$14)*1000 -> 0 | N21: =(K21-$K$14)*1000 -> 0
A22: ='BC.115+740'!B21 -> 45080 | B22: 8 | C22: ='BC.115+740'!M21/1000 -> -0.01 | D22: ='BC.115+740'!AA21 -> 0 | E22: ='BC.115+740'!AB21 -> 0 | F22: =VLOOKUP($A22,'BC.115+740'!$B$13:$X$489,8,0)/1000 -> 2.04 | G22: =VLOOKUP($A22,'BC.115+740'!$B$13:$X$489,9,0)/1000 -> 0.04 | H22: =VLOOKUP($A22,'BC.115+740'!$B$13:$X$489,14,0)/1000 -> 1.99 | I22: =VLOOKUP($A22,'BC.115+740'!$B$13:$X$489,15,0)/1000 -> -0.01 | J22: =VLOOKUP($A22,'BC.115+740'!$B$13:$X$489,20,0)/1000 -> 1.96 | K22: =VLOOKUP($A22,'BC.115+740'!$B$13:$X$489,21,0)/1000 -> -0.04 | L22: =(G22-$G$14)*1000 -> 0 | M22: =(I22-$I$14)*1000 -> 0 | N22: =(K22-$K$14)*1000 -> 0
A23: ='BC.115+740'!B22 -> 45081 | B23: 9 | C23: ='BC.115+740'!M22/1000 -> -0.01 | D23: ='BC.115+740'!AA22 -> 0 | E23: ='BC.115+740'!AB22 -> 0 | F23: =VLOOKUP($A23,'BC.115+740'!$B$13:$X$489,8,0)/1000 -> 2.04 | G23: =VLOOKUP($A23,'BC.115+740'!$B$13:$X$489,9,0)/1000 -> 0.04 | H23: =VLOOKUP($A23,'BC.115+740'!$B$13:$X$489,14,0)/1000 -> 1.99 | I23: =VLOOKUP($A23,'BC.115+740'!$B$13:$X$489,15,0)/1000 -> -0.01 | J23: =VLOOKUP($A23,'BC.115+740'!$B$13:$X$489,20,0)/1000 -> 1.96 | K23: =VLOOKUP($A23,'BC.115+740'!$B$13:$X$489,21,0)/1000 -> -0.04 | L23: =(G23-$G$14)*1000 -> 0 | M23: =(I23-$I$14)*1000 -> 0 | N23: =(K23-$K$14)*1000 -> 0
A24: ='BC.115+740'!B23 -> 45082 | B24: 10 | C24: ='BC.115+740'!M23/1000 -> -0.01 | D24: ='BC.115+740'!AA23 -> 0 | E24: ='BC.115+740'!AB23 -> 0 | F24: =VLOOKUP($A24,'BC.115+740'!$B$13:$X$489,8,0)/1000 -> 2.04 | G24: =VLOOKUP($A24,'BC.115+740'!$B$13:$X$489,9,0)/1000 -> 0.04 | H24: =VLOOKUP($A24,'BC.115+740'!$B$13:$X$489,14,0)/1000 -> 1.99 | I24: =VLOOKUP($A24,'BC.115+740'!$B$13:$X$489,15,0)/1000 -> -0.01 | J24: =VLOOKUP($A24,'BC.115+740'!$B$13:$X$489,20,0)/1000 -> 1.96 | K24: =VLOOKUP($A24,'BC.115+740'!$B$13:$X$489,21,0)/1000 -> -0.04 | L24: =(G24-$G$14)*1000 -> 0 | M24: =(I24-$I$14)*1000 -> 0 | N24: =(K24-$K$14)*1000 -> 0
A25: ='BC.115+740'!B24 -> 45083 | B25: 11 | C25: ='BC.115+740'!M24/1000 -> -0.01 | D25: ='BC.115+740'!AA24 -> 0 | E25: ='BC.115+740'!AB24 -> 0 | F25: =VLOOKUP($A25,'BC.115+740'!$B$13:$X$489,8,0)/1000 -> 2.04 | G25: =VLOOKUP($A25,'BC.115+740'!$B$13:$X$489,9,0)/1000 -> 0.04 | H25: =VLOOKUP($A25,'BC.115+740'!$B$13:$X$489,14,0)/1000 -> 1.99 | I25: =VLOOKUP($A25,'BC.115+740'!$B$13:$X$489,15,0)/1000 -> -0.01 | J25: =VLOOKUP($A25,'BC.115+740'!$B$13:$X$489,20,0)/1000 -> 1.96 | K25: =VLOOKUP($A25,'BC.115+740'!$B$13:$X$489,21,0)/1000 -> -0.04 | L25: =(G25-$G$14)*1000 -> 0 | M25: =(I25-$I$14)*1000 -> 0 | N25: =(K25-$K$14)*1000 -> 0
A26: ='BC.115+740'!B25 -> 45084 | B26: 12 | C26: ='BC.115+740'!M25/1000 -> -0.01 | D26: ='BC.115+740'!AA25 -> 0 | E26: ='BC.115+740'!AB25 -> 0 | F26: =VLOOKUP($A26,'BC.115+740'!$B$13:$X$489,8,0)/1000 -> 2.04 | G26: =VLOOKUP($A26,'BC.115+740'!$B$13:$X$489,9,0)/1000 -> 0.04 | H26: =VLOOKUP($A26,'BC.115+740'!$B$13:$X$489,14,0)/1000 -> 1.99 | I26: =VLOOKUP($A26,'BC.115+740'!$B$13:$X$489,15,0)/1000 -> -0.01 | J26: =VLOOKUP($A26,'BC.115+740'!$B$13:$X$489,20,0)/1000 -> 1.96 | K26: =VLOOKUP($A26,'BC.115+740'!$B$13:$X$489,21,0)/1000 -> -0.04 | L26: =(G26-$G$14)*1000 -> 0 | M26: =(I26-$I$14)*1000 -> 0 | N26: =(K26-$K$14)*1000 -> 0
... A91: ='BC.115+740'!B90 -> 45149 | B91: 77 | C91: ='BC.115+740'!M90/1000 -> 0.897 | D91: ='BC.115+740'!AA90 -> 1.007 | E91: ='BC.115+740'!AB90 -> 0.804 | F91: =VLOOKUP($A91,'BC.115+740'!$B$13:$X$489,8,0)/1000 -> 1.9 | G91: =VLOOKUP($A91,'BC.115+740'!$B$13:$X$489,9,0)/1000 -> -0.1 | H91: =VLOOKUP($A91,'BC.115+740'!$B$13:$X$489,14,0)/1000 -> 1.887 | I91: =VLOOKUP($A91,'BC.115+740'!$B$13:$X$489,15,0)/1000 -> -0.113 | J91: =VLOOKUP($A91,'BC.115+740'!$B$13:$X$489,20,0)/1000 -> 1.834 | K91: =VLOOKUP($A91,'BC.115+740'!$B$13:$X$489,21,0)/1000 -> -0.166 | L91: =(G91-$G$14)*1000 -> -140 | M91: =(I91-$I$14)*1000 -> -103 | N91: =(K91-$K$14)*1000 -> -126
A92: ='BC.115+740'!B91 -> 45150 | B92: 78 | C92: ='BC.115+740'!M91/1000 -> 0.897 | D92: ='BC.115+740'!AA91 -> 1.007 | E92: ='BC.115+740'!AB91 -> 0.804 | F92: =VLOOKUP($A92,'BC.115+740'!$B$13:$X$489,8,0)/1000 -> 1.9 | G92: =VLOOKUP($A92,'BC.115+740'!$B$13:$X$489,9,0)/1000 -> -0.1 | H92: =VLOOKUP($A92,'BC.115+740'!$B$13:$X$489,14,0)/1000 -> 1.887 | I92: =VLOOKUP($A92,'BC.115+740'!$B$13:$X$489,15,0)/1000 -> -0.113 | J92: =VLOOKUP($A92,'BC.115+740'!$B$13:$X$489,20,0)/1000 -> 1.834 | K92: =VLOOKUP($A92,'BC.115+740'!$B$13:$X$489,21,0)/1000 -> -0.166 | L92: =(G92-$G$14)*1000 -> -140 | M92: =(I92-$I$14)*1000 -> -103 | N92: =(K92-$K$14)*1000 -> -126 | Y92: =A21-A14 -> 7
A93: ='BC.115+740'!B92 -> 45151 | B93: 79 | C93: ='BC.115+740'!M92/1000 -> 0.897 | D93: ='BC.115+740'!AA92 -> 1.007 | E93: ='BC.115+740'!AB92 -> 0.804 | F93: =VLOOKUP($A93,'BC.115+740'!$B$13:$X$489,8,0)/1000 -> 1.9 | G93: =VLOOKUP($A93,'BC.115+740'!$B$13:$X$489,9,0)/1000 -> -0.1 | H93: =VLOOKUP($A93,'BC.115+740'!$B$13:$X$489,14,0)/1000 -> 1.887 | I93: =VLOOKUP($A93,'BC.115+740'!$B$13:$X$489,15,0)/1000 -> -0.113 | J93: =VLOOKUP($A93,'BC.115+740'!$B$13:$X$489,20,0)/1000 -> 1.834 | K93: =VLOOKUP($A93,'BC.115+740'!$B$13:$X$489,21,0)/1000 -> -0.166 | L93: =(G93-$G$14)*1000 -> -140 | M93: =(I93-$I$14)*1000 -> -103 | N93: =(K93-$K$14)*1000 -> -126
