Workbook

Sheet 116+240
B1: 1 | C1: =+B1+1 -> 2 | D1: =+C1+1 -> 3 | E1: =+D1+1 -> 4 | F1: =+E1+1 -> 5 | G1: =+F1+1 -> 6 | H1: =+G1+1 -> 7 | I1: =+H1+1 -> 8 | J1: =+I1+1 -> 9 | ... X1: =+W1+1 -> 23 | Z1: =+X1+1 -> 24 | AA1: =+Z1+1 -> 25 | AB1: =+AA1+1 -> 26
A2: DỰ ÁN THÀNH PHẦN ĐOẠN HẬU GIANG - CÀ MAU
A3: THUỘC DỰ ÁN XÂY DỰNG CÔNG TRÌNH ĐƯỜNG BỘ CAO TỐC BẮC - NAM PHÍA ĐÔNG GIAI ĐOẠN 2021 - 2025
A4: =UPPER("GÓI THẦU XL03 :Thi Công Xây Dựng Đoạn Tuyến Km114+200 - Km126+223 Bao Gồm Tuyến Nối Nút Giao IC12 Với QL1 (bao gồm khảo sát, thiết kế BVTC)") -> GÓI THẦU XL03 :THI CÔNG XÂY DỰNG ĐOẠN TUYẾN KM114+200 - KM126+223 BAO GỒM TUYẾN NỐI NÚT GIAO IC12 VỚI QL1 (BAO GỒM KHẢO SÁT, THIẾT KẾ BVTC)
A5: CHỦ ĐẦU TƯ | I5: TƯ VẤN GIÁM SÁT | S5: NHÀ THẦU
A6: BAN QUẢN LÝ DỰ ÁN MỸ THUẬN | I6: =UPPER("Liên danh Phân viện KHCN GTVT phía Nam - Công ty Cổ phần Tư vấn kỹ thuật và xây dựng Hồng Hà") -> LIÊN DANH PHÂN VIỆN KHCN GTVT PHÍA NAM - CÔNG TY CỔ PHẦN TƯ VẤN KỸ THUẬT VÀ XÂY DỰNG HỒNG HÀ | S6: LIÊN DANH CC1 - HẢI ĐĂNG - VẠN CƯỜNG - 492 - BẮC TRUNG NAM
A7: BIỂU GHI ĐO QUAN TRẮC LÚN
A8: Người lập: | K8: Tên mốc:
A9: Thời tiết: | C9: Nắng | K9: Cao độ mốc: | M9: =C14 -> 844
A10: Lý trình: | C10: Km116+240 | K10: Ngày đặt bàn: | M10: =B14 -> 45281
A12: Stt | B12: Ngày quan trắc | C12: Cao độ mốc (mm) | D12: Số đọc tại mốc (mm) | E12: Số đọc mia (mm) | H12: Cao độ quan trắc (mm) | K12: Chiều dài cần nối (mm) | N12: Cao độ bàn đo lún (mm) | Q12: Tốc độ lún (mm) | T12: Số đọc mia tại nền đắp tại tâm (mm) | U12: Cao độ nền đắp (mm) | X12: Chiều dày lớp đắp (m) | Y12: Đội quan trắc | Z12: Nhà thầu | AA12: Tư Vấn Giám Sát | AB12: Ghi chú
E13: Trái | F13: Giữa | G13: Phải | H13: Trái | I13: Giữa | J13: Phải | K13: Trái | L13: Giữa | M13: Phải | N13: Trái | O13: Giữa | P13: Phải | Q13: Trái | R13: Giữa | S13: Phải | U13: Trái | V13: Giữa | W13: Phải
A14: 0 | B14: 45281 | C14: 844 | D14: 1625 | E14: =C14+D14-H14 -> 429 | F14: =C14+D14-I14 -> 549 | G14: =D14+C14-J14 -> 499 | H14: =K14+N14 -> 2040 | I14: =L14+O14 -> 1920 | J14: =M14+P14 -> 1970 | K14: 2000 | L14: 2000 | M14: 2000 | N14: 40 | O14: -80 | P14: -30 | Q14: 0 | R14: 0 | S14: 0 | T14: =D14+C14-V14 -> 2549 | U14: =N14 -> 40 | V14: =O14 -> -80 | W14: =P14 -> -30 | AB14: Lắp đặt ban đầu
A15: 1 | B15: =B14+1 -> 45282 | C15: =C14 -> 844 | D15: =D14-2 -> 1623 | E15: =C15+D15-H15 -> 427 | F15: =C15+D15-I15 -> 547 | G15: =D15+C15-J15 -> 497 | H15: =K15+N15 -> 2040 | I15: =L15+O15 -> 1920 | J15: =M15+P15 -> 1970 | K15: =K14 -> 2000 | L15: =L14 -> 2000 | M15: =M14 -> 2000 | N15: =N14-Q15 -> 40 | O15: =O14-R15 -> -80 | P15: =P14-S15 -> -30 | Q15: =Q14 -> 0 | R15: =R14 -> 0 | S15: =S14 -> 0 | T15: =D15+C15-V15 -> 2547 | U15: =U14-Q15 -> 40 | V15: =V14-R15 -> -80 | W15: =W14-S15 -> -30
A16: 2 | B16: =B15+1 -> 45283 | C16: =C15 -> 844 | D16: =D15-2 -> 1621 | E16: =C16+D16-H16 -> 425 | F16: =C16+D16-I16 -> 545 | G16: =D16+C16-J16 -> 495 | H16: =K16+N16 -> 2040 | I16: =L16+O16 -> 1920 | J16: =M16+P16 -> 1970 | K16: =K15 -> 2000 | L16: =L15 -> 2000 | M16: =M15 -> 2000 | N16: =N15-Q16 -> 40 | O16: =O15-R16 -> -80 | P16: =P15-S16 -> -30 | Q16: =Q15 -> 0 | R16: =R15 -> 0 | S16: =S15 -> 0 | T16: =D16+C16-V16 -> 2545 | U16: =U15-Q16 -> 40 | V16: =V15-R16 -> -80 | W16: =W15-S16 -> -30
A17: 3 | B17: =B16+1 -> 45284 | C17: =C16 -> 844 | D17: =D16-2 -> 1619 | E17: =C17+D17-H17 -> 423 | F17: =C17+D17-I17 -> 543 | G17: =D17+C17-J17 -> 493 | H17: =K17+N17 -> 2040 | I17: =L17+O17 -> 1920 | J17: =M17+P17 -> 1970 | K17: =K16 -> 2000 | L17: =L16 -> 2000 | M17: =M16 -> 2000 | N17: =N16-Q17 -> 40 | O17: =O16-R17 -> -80 | P17: =P16-S17 -> -30 | Q17: =Q16 -> 0 | R17: =R16 -> 0 | S17: =S16 -> 0 | T17: =D17+C17-V17 -> 2543 | U17: =U16-Q17 -> 40 | V17: =V16-R17 -> -80 | W17: =W16-S17 -> -30 | AD17: 45284
A18: 4 | B18: =B17+1 -> 45285 | C18: =C17 -> 844 | D18: =D17-2 -> 1617 | E18: =C18+D18-H18 -> 421 | F18: =C18+D18-I18 -> 541 | G18: =D18+C18-J18 -> 491 | H18: =K18+N18 -> 2040 | I18: =L18+O18 -> 1920 | J18: =M18+P18 -> 1970 | K18: =K17 -> 2000 | L18: =L17 -> 2000 | M18: =M17 -> 2000 | N18: =N17-Q18 -> 40 | O18: =O17-R18 -> -80 | P18: =P17-S18 -> -30 | Q18: =Q17 -> 0 | R18: =R17 -> 0 | S18: =S17 -> 0 | T18: =D18+C18-V18 -> 2541 | U18: =U17-Q18 -> 40 | V18: =V17-R18 -> -80 | W18: =W17-S18 -> -30 | AD18: 45288
A19: 5 | B19: =B18+1 -> 45286 | C19: =C18 -> 844 | D19: =D18-2 -> 1615 | E19: =C19+D19-H19 -> 419 | F19: =C19+D19-I19 -> 539 | G19: =D19+C19-J19 -> 489 | H19: =K19+N19 -> 2040 | I19: =L19+O19 -> 1920 | J19: =M19+P19 -> 1970 | K19: =K18 -> 2000 | L19: =L18 -> 2000 | M19: =M18 -> 2000 | N19: =N18-Q19 -> 40 | O19: =O18-R19 -> -80 | P19: =P18-S19 -> -30 | Q19: =Q18 -> 0 | R19: =R18 -> 0 | S19: =S18 -> 0 | T19: =D19+C19-V19 -> 2539 | U19: =U18-Q19 -> 40 | V19: =V18-R19 -> -80 | W19: =W18-S19 -> -30 | AD19: 45293
A20: 6 | B20: =B19+1 -> 45287 | C20: =C19 -> 844 | D20: =D19-2 -> 1613 | E20: =C20+D20-H20 -> 417 | F20: =C20+D20-I20 -> 537 | G20: =D20+C20-J20 -> 487 | H20: =K20+N20 -> 2040 | I20: =L20+O20 -> 1920 | J20: =M20+P20 -> 1970 | K20: =K19 -> 2000 | L20: =L19 -> 2000 | M20: =M19 -> 2000 | N20: =N19-Q20 -> 40 | O20: =O19-R20 -> -80 | P20: =P19-S20 -> -30 | Q20: =Q19 -> 0 | R20: =R19 -> 0 | S20: =S19 -> 0 | T20: =D20+C20-V20 -> 2537 | U20: =U19-Q20 -> 40 | V20: =V19-R20 -> -80 | W20: =W19-S20 -> -30 | AD20: 45296
A21: 7 | B21: =B20+1 -> 45288 | C21: =C20 -> 844 | D21: =D20-2 -> 1611 | E21: =C21+D21-H21 -> 415 | F21: =C21+D21-I21 -> 535 | G21: =D21+C21-J21 -> 485 | H21: =K21+N21 -> 2040 | I21: =L21+O21 -> 1920 | J21: =M21+P21 -> 1970 | K21: =K20 -> 2000 | L21: =L20 -> 2000 | M21: =M20 -> 2000 | N21: =N20-Q21 -> 40 | O21: =O20-R21 -> -80 | P21: =P20-S21 -> -30 | Q21: =Q20 -> 0 | R21: =R20 -> 0 | S21: =S20 -> 0 | T21: =D21+C21-V21 -> 2535 | U21: =U20-Q21 -> 40 | V21: =V20-R21 -> -80 | W21: =W20-S21 -> -30 | AD21: 45300
A22: 8 | B22: =B21+1 -> 45289 | C22: =C21 -> 844 | D22: =D21-2 -> 1609 | E22: =C22+D22-H22 -> 413 | F22: =C22+D22-I22 -> 533 | G22: =D22+C22-J22 -> 483 | H22: =K22+N22 -> 2040 | I22: =L22+O22 -> 1920 | J22: =M22+P22 -> 1970 | K22: =K21 -> 2000 | L22: =L21 -> 2000 | M22: =M21 -> 2000 | N22: =N21-Q22 -> 40 | O22: =O21-R22 -> -80 | P22: =P21-S22 -> -30 | Q22: =Q21 -> 0 | R22: =R21 -> 0 | S22: =S21 -> 0 | T22: =D22+C22-V22 -> 2533 | U22: =U21-Q22 -> 40 | V22: =V21-R22 -> -80 | W22: =W21-S22 -> -30 | AD22: 45305
A23: 9 | B23: =B22+1 -> 45290 | C23: =C22 -> 844 | D23: =D22-2 -> 1607 | E23: =C23+D23-H23 -> 411 | F23: =C23+D23-I23 -> 531 | G23: =D23+C23-J23 -> 481 | H23: =K23+N23 -> 2040 | I23: =L23+O23 -> 1920 | J23: =M23+P23 -> 1970 | K23: =K22 -> 2000 | L23: =L22 -> 2000 | M23: =M22 -> 2000 | N23: =N22-Q23 -> 40 | O23: =O22-R23 -> -80 | P23: =P22-S23 -> -30 | Q23: =Q22 -> 0 | R23: =R22 -> 0 | S23: =S22 -> 0 | T23: =D23+C23-V23 -> 2531 | U23: =U22-Q23 -> 40 | V23: =V22-R23 -> -80 | W23: =W22-S23 -> -30 | AD23: 45309
A24: 10 | B24: =B23+1 -> 45291 | C24: =C23 -> 844 | D24: =D23-2 -> 1605 | E24: =C24+D24-H24 -> 409 | F24: =C24+D24-I24 -> 529 | G24: =D24+C24-J24 -> 479 | H24: =K24+N24 -> 2040 | I24: =L24+O24 -> 1920 | J24: =M24+P24 -> 1970 | K24: =K23 -> 2000 | L24: =L23 -> 2000 | M24: =M23 -> 2000 | N24: =N23-Q24 -> 40 | O24: =O23-R24 -> -80 | P24: =P23-S24 -> -30 | Q24: =Q23 -> 0 | R24: =R23 -> 0 | S24: =S23 -> 0 | T24: =D24+C24-V24 -> 2529 | U24: =U23-Q24 -> 40 | V24: =V23-R24 -> -80 | W24: =W23-S24 -> -30 | AD24: 45313
A25: 11 | B25: =B24+1 -> 45292 | C25: =C24 -> 844 | D25: =D24-2 -> 1603 | E25: =C25+D25-H25 -> 407 | F25: =C25+D25-I25 -> 527 | G25: =D25+C25-J25 -> 477 | H25: =K25+N25 -> 2040 | I25: =L25+O25 -> 1920 | J25: =M25+P25 -> 1970 | K25: =K24 -> 2000 | L25: =L24 -> 2000 | M25: =M24 -> 2000 | N25: =N24-Q25 -> 40 | O25: =O24-R25 -> -80 | P25: =P24-S25 -> -30 | Q25: =Q24 -> 0 | R25: =R24 -> 0 | S25: =S24 -> 0 | T25: =D25+C25-V25 -> 2527 | U25: =U24-Q25 -> 40 | V25: =V24-R25 -> -80 | W25: =W24-S25 -> -30 | AD25: 45355
A26: 12 | B26: =B25+1 -> 45293 | C26: =C25 -> 844 | D26: =D25-2 -> 1601 | E26: =C26+D26-H26 -> 411 | F26: =C26+D26-I26 -> 533 | G26: =D26+C26-J26 -> 480 | H26: =K26+N26 -> 2034 | I26: =L26+O26 -> 1912 | J26: =M26+P26 -> 1965 | K26: =K25 -> 2000 | L26: =L25 -> 2000 | M26: =M25 -> 2000 | N26: =N25-Q26 -> 34 | O26: =O25-R26 -> -88 | P26: =P25-S26 -> -35 | Q26: 6 | R26: 8 | S26: 5 | T26: =D26+C26-V26 -> 2353 | U26: =U25+0.06*1000-Q26 -> 94 | V26: =V25+$X26*1000-R26 -> 92 | W26: =W25+0.13*1000-S26 -> 95 | X26: 0.18 | AB26: 9 | AD26: 45359
A27: 13 | B27: =B26+1 -> 45294 | C27: =C26 -> 844 | D27: =D26-2 -> 1599 | E27: =C27+D27-H27 -> 411 | F27: =C27+D27-I27 -> 533 | G27: =D27+C27-J27 -> 479 | H27: =K27+N27 -> 2032 | I27: =L27+O27 -> 1910 | J27: =M27+P27 -> 1964 | K27: =K26 -> 2000 | L27: =L26 -> 2000 | M27: =M26 -> 2000 | N27: =N26-Q27 -> 32 | O27: =O26-R27 -> -90 | P27: =P26-S27 -> -36 | Q27: 2 | R27: 2 | S27: 1 | T27: =D27+C27-V27 -> 2353 | U27: =U26+$X27*1000-Q27 -> 92 | V27: =V26+$X27*1000-R27 -> 90 | W27: =W26+$X27*1000-S27 -> 94 | AD27: 45364
A28: 14 | B28: =B27+1 -> 45295 | C28: =C27 -> 844 | D28: =D27-2 -> 1597 | E28: =C28+D28-H28 -> 411 | F28: =C28+D28-I28 -> 533 | G28: =D28+C28-J28 -> 478 | H28: =K28+N28 -> 2030 | I28: =L28+O28 -> 1908 | J28: =M28+P28 -> 1963 | K28: =K27 -> 2000 | L28: =L27 -> 2000 | M28: =M27 -> 2000 | N28: =N27-Q28 -> 30 | O28: =O27-R28 -> -92 | P28: =P27-S28 -> -37 | Q28: 2 | R28: 2 | S28: 1 | T28: =D28+C28-V28 -> 2353 | U28: =U27+$X28*1000-Q28 -> 90 | V28: =V27+$X28*1000-R28 -> 88 | W28: =W27+$X28*1000-S28 -> 93
A29: 15 | B29: =B28+1 -> 45296 | C29: =C28 -> 844 | D29: =D28-2 -> 1595 | E29: =C29+D29-H29 -> 411 | F29: =C29+D29-I29 -> 533 | G29: =D29+C29-J29 -> 478 | H29: =K29+N29 -> 2028 | I29: =L29+O29 -> 1906 | J29: =M29+P29 -> 1961 | K29: =K28 -> 2000 | L29: =L28 -> 2000 | M29: =M28 -> 2000 | N29: =N28-Q29 -> 28 | O29: =O28-R29 -> -94 | P29: =P28-S29 -> -39 | Q29: 2 | R29: 2 | S29: 2 | T29: =D29+C29-V29 -> 2053 | U29: =U28+$X29*1000-Q29 -> 388 | V29: =V28+$X29*1000-R29 -> 386 | W29: =W28+$X29*1000-S29 -> 391 | X29: 0.3 | AB29: 8
A30: 16 | B30: =B29+1 -> 45297 | C30: =C29 -> 844 | D30: =D29-2 -> 1593 | E30: =C30+D30-H30 -> 414 | F30: =C30+D30-I30 -> 539 | G30: =D30+C30-J30 -> 481 | H30: =K30+N30 -> 2023 | I30: =L30+O30 -> 1898 | J30: =M30+P30 -> 1956 | K30: =K29 -> 2000 | L30: =L29 -> 2000 | M30: =M29 -> 2000 | N30: =N29-Q30 -> 23 | O30: =O29-R30 -> -102 | P30: =P29-S30 -> -44 | Q30: 5 | R30: 8 | S30: 5 | T30: =D30+C30-V30 -> 2059 | U30: =U29+$X30*1000-Q30 -> 383 | V30: =V29+$X30*1000-R30 -> 378 | W30: =W29+$X30*1000-S30 -> 386
A31: 17 | B31: =B30+1 -> 45298 | C31: =C30 -> 844 | D31: =D30-2 -> 1591 | E31: =C31+D31-H31 -> 414 | F31: =C31+D31-I31 -> 539 | G31: =D31+C31-J31 -> 480 | H31: =K31+N31 -> 2021 | I31: =L31+O31 -> 1896 | J31: =M31+P31 -> 1955 | K31: =K30 -> 2000 | L31: =L30 -> 2000 | M31: =M30 -> 2000 | N31: =N30-Q31 -> 21 | O31: =O30-R31 -> -104 | P31: =P30-S31 -> -45 | Q31: 2 | R31: 2 | S31: 1 | T31: =D31+C31-V31 -> 2059 | U31: =U30+$X31*1000-Q31 -> 381 | V31: =V30+$X31*1000-R31 -> 376 | W31: =W30+$X31*1000-S31 -> 385
A32: 18 | B32: =B31+1 -> 45299 | C32: =C31 -> 844 | D32: =D31-2 -> 1589 | E32: =C32+D32-H32 -> 414 | F32: =C32+D32-I32 -> 539 | G32: =D32+C32-J32 -> 480 | H32: =K32+N32 -> 2019 | I32: =L32+O32 -> 1894 | J32: =M32+P32 -> 1953 | K32: =K31 -> 2000 | L32: =L31 -> 2000 | M32: =M31 -> 2000 | N32: =N31-Q32 -> 19 | O32: =O31-R32 -> -106 | P32: =P31-S32 -> -47 | Q32: 2 | R32: 2 | S32: 2 | T32: =D32+C32-V32 -> 2059 | U32: =U31+$X32*1000-Q32 -> 379 | V32: =V31+$X32*1000-R32 -> 374 | W32: =W31+$X32*1000-S32 -> 383
A33: 19 | B33: =B32+1 -> 45300 | C33: =C32 -> 844 | D33: =D32-2 -> 1587 | E33: =C33+D33-H33 -> 414 | F33: =C33+D33-I33 -> 539 | G33: =D33+C33-J33 -> 479 | H33: =K33+N33 -> 2017 | I33: =L33+O33 -> 1892 | J33: =M33+P33 -> 1952 | K33: =K32 -> 2000 | L33: =L32 -> 2000 | M33: =M32 -> 2000 | N33: =N32-Q33 -> 17 | O33: =O32-R33 -> -108 | P33: =P32-S33 -> -48 | Q33: 2 | R33: 2 | S33: 1 | T33: =D33+C33-V33 -> 1759 | U33: =U32+$X33*1000-Q33 -> 677 | V33: =V32+$X33*1000-R33 -> 672 | W33: =W32+$X33*1000-S33 -> 682 | X33: 0.3 | AB33: 7
A34: 20 | B34: =B33+1 -> 45301 | C34: =C33 -> 844 | D34: =D33-2 -> 1585 | E34: =C34+D34-H34 -> 417 | F34: =C34+D34-I34 -> 545 | G34: =D34+C34-J34 -> 483 | H34: =K34+N34 -> 2012 | I34: =L34+O34 -> 1884 | J34: =M34+P34 -> 1946 | K34: =K33 -> 2000 | L34: =L33 -> 2000 | M34: =M33 -> 2000 | N34: =N33-Q34 -> 12 | O34: =O33-R34 -> -116 | P34: =P33-S34 -> -54 | Q34: 5 | R34: 8 | S34: 6 | T34: =D34+C34-V34 -> 1765 | U34: =U33+$X34*1000-Q34 -> 672 | V34: =V33+$X34*1000-R34 -> 664 | W34: =W33+$X34*1000-S34 -> 676
A35: 21 | B35: =B34+1 -> 45302 | C35: =C34 -> 844 | D35: =D34-2 -> 1583 | E35: =C35+D35-H35 -> 421 | F35: =C35+D35-I35 -> 551 | G35: =D35+C35-J35 -> 486 | H35: =K35+N35 -> 2006 | I35: =L35+O35 -> 1876 | J35: =M35+P35 -> 1941 | K35: =K34 -> 2000 | L35: =L34 -> 2000 | M35: =M34 -> 2000 | N35: =N34-Q35 -> 6 | O35: =O34-R35 -> -124 | P35: =P34-S35 -> -59 | Q35: 6 | R35: 8 | S35: 5 | T35: =D35+C35-V35 -> 1771 | U35: =U34+$X35*1000-Q35 -> 666 | V35: =V34+$X35*1000-R35 -> 656 | W35: =W34+$X35*1000-S35 -> 671
A36: 22 | B36: =B35+1 -> 45303 | C36: =C35 -> 844 | D36: =D35-2 -> 1581 | E36: =C36+D36-H36 -> 421 | F36: =C36+D36-I36 -> 551 | G36: =D36+C36-J36 -> 485 | H36: =K36+N36 -> 2004 | I36: =L36+O36 -> 1874 | J36: =M36+P36 -> 1940 | K36: =K35 -> 2000 | L36: =L35 -> 2000 | M36: =M35 -> 2000 | N36: =N35-Q36 -> 4 | O36: =O35-R36 -> -126 | P36: =P35-S36 -> -60 | Q36: 2 | R36: 2 | S36: 1 | T36: =D36+C36-V36 -> 1771 | U36: =U35+$X36*1000-Q36 -> 664 | V36: =V35+$X36*1000-R36 -> 654 | W36: =W35+$X36*1000-S36 -> 670
A37: 23 | B37: =B36+1 -> 45304 | C37: =C36 -> 844 | D37: =D36-2 -> 1579 | E37: =C37+D37-H37 -> 421 | F37: =C37+D37-I37 -> 551 | G37: =D37+C37-J37 -> 484 | H37: =K37+N37 -> 2002 | I37: =L37+O37 -> 1872 | J37: =M37+P37 -> 1939 | K37: =K36 -> 2000 | L37: =L36 -> 2000 | M37: =M36 -> 2000 | N37: =N36-Q37 -> 2 | O37: =O36-R37 -> -128 | P37: =P36-S37 -> -61 | Q37: 2 | R37: 2 | S37: 1 | T37: =D37+C37-V37 -> 1771 | U37: =U36+$X37*1000-Q37 -> 662 | V37: =V36+$X37*1000-R37 -> 652 | W37: =W36+$X37*1000-S37 -> 669
A38: 24 | B38: =B37+1 -> 45305 | C38: =C37 -> 844 | D38: =D37-2 -> 1577 | E38: =C38+D38-H38 -> 421 | F38: =C38+D38-I38 -> 551 | G38: =D38+C38-J38 -> 484 | H38: =K38+N38 -> 2000 | I38: =L38+O38 -> 1870 | J38: =M38+P38 -> 1937 | K38: =K37 -> 2000 | L38: =L37 -> 2000 | M38: =M37 -> 2000 | N38: =N37-Q38 -> -7.1054274e-15 | O38: =O37-R38 -> -130 | P38: =P37-S38 -> -63 | Q38: 2 | R38: 2 | S38: 2 | T38: =D38+C38-V38 -> 1471 | U38: =U37+$X38*1000-Q38 -> 960 | V38: =V37+$X38*1000-R38 -> 950 | W38: =W37+$X38*1000-S38 -> 967 | X38: 0.3 | AB38: 6
A39: 25 | B39: =B38+1 -> 45306 | C39: =C38 -> 844 | D39: =D38-2 -> 1575 | E39: =C39+D39-H39 -> 424 | F39: =C39+D39-I39 -> 557 | G39: =D39+C39-J39 -> 487 | H39: =K39+N39 -> 1995 | I39: =L39+O39 -> 1862 | J39: =M39+P39 -> 1932 | K39: =K38 -> 2000 | L39: =L38 -> 2000 | M39: =M38 -> 2000 | N39: =N38-Q39 -> -5 | O39: =O38-R39 -> -138 | P39: =P38-S39 -> -68 | Q39: 5 | R39: 8 | S39: 5 | T39: =D39+C39-V39 -> 1477 | U39: =U38+$X39*1000-Q39 -> 955 | V39: =V38+$X39*1000-R39 -> 942 | W39: =W38+$X39*1000-S39 -> 962
A40: 26 | B40: =B39+1 -> 45307 | C40: =C39 -> 844 | D40: =D39-2 -> 1573 | E40: =C40+D40-H40 -> 424 | F40: =C40+D40-I40 -> 557 | G40: =D40+C40-J40 -> 486 | H40: =K40+N40 -> 1993 | I40: =L40+O40 -> 1860 | J40: =M40+P40 -> 1931 | K40: =K39 -> 2000 | L40: =L39 -> 2000 | M40: =M39 -> 2000 | N40: =N39-Q40 -> -7 | O40: =O39-R40 -> -140 | P40: =P39-S40 -> -69 | Q40: 2 | R40: 2 | S40: 1 | T40: =D40+C40-V40 -> 1477 | U40: =U39+$X40*1000-Q40 -> 953 | V40: =V39+$X40*1000-R40 -> 940 | W40: =W39+$X40*1000-S40 -> 961
A41: 27 | B41: =B40+1 -> 45308 | C41: =C40 -> 844 | D41: =D40-2 -> 1571 | E41: =C41+D41-H41 -> 424 | F41: =C41+D41-I41 -> 557 | G41: =D41+C41-J41 -> 486 | H41: =K41+N41 -> 1991 | I41: =L41+O41 -> 1858 | J41: =M41+P41 -> 1929 | K41: =K40 -> 2000 | L41: =L40 -> 2000 | M41: =M40 -> 2000 | N41: =N40-Q41 -> -9 | O41: =O40-R41 -> -142 | P41: =P40-S41 -> -71 | Q41: 2 | R41: 2 | S41: 2 | T41: =D41+C41-V41 -> 1477 | U41: =U40+$X41*1000-Q41 -> 951 | V41: =V40+$X41*1000-R41 -> 938 | W41: =W40+$X41*1000-S41 -> 959
...

Sheet BC.116+240
A1: 13 | B1: DỰ ÁN THÀNH PHẦN ĐOẠN HẬU GIANG - CÀ MAU
B2: THUỘC DỰ ÁN XÂY DỰNG CÔNG TRÌNH ĐƯỜNG BỘ CAO TỐC BẮC - NAM PHÍA ĐÔNG GIAI ĐOẠN 2021 - 2025
B3: =UPPER("GÓI THẦU XL03 :Thi Công Xây Dựng Đoạn Tuyến Km114+200 - Km126+223 Bao Gồm Tuyến Nối Nút Giao IC12 Với QL1 (bao gồm khảo sát, thiết kế BVTC)") -> GÓI THẦU XL03 :THI CÔNG XÂY DỰNG ĐOẠN TUYẾN KM114+200 - KM126+223 BAO GỒM TUYẾN NỐI NÚT GIAO IC12 VỚI QL1 (BAO GỒM KHẢO SÁT, THIẾT KẾ BVTC)
B4: CHỦ ĐẦU TƯ | J4: TƯ VẤN GIÁM SÁT | T4: NHÀ THẦU
B5: BAN QUẢN LÝ DỰ ÁN MỸ THUẬN | J5: =UPPER("Liên danh Phân viện KHCN GTVT phía Nam - Công ty Cổ phần Tư vấn kỹ thuật và xây dựng Hồng Hà") -> LIÊN DANH PHÂN VIỆN KHCN GTVT PHÍA NAM - CÔNG TY CỔ PHẦN TƯ VẤN KỸ THUẬT VÀ XÂY DỰNG HỒNG HÀ | T5: LIÊN DANH CC1 - HẢI ĐĂNG - VẠN CƯỜNG - 492 - BẮC TRUNG NAM
B6: BIỂU GHI ĐO QUAN TRẮC LÚN
B7: Người lập: | C7: ='116+240'!C8 -> 0 | L7: Tên mốc: | N7: ='116+240'!M8 -> 0
B8: Thời tiết: | C8: ='116+240'!C9 -> Nắng | L8: Cao độ mốc: | N8: ='116+240'!M9 -> 844
B9: Lý trình: | C9: ='116+240'!C10 -> Km116+240 | L9: Ngày đặt bàn: | N9: ='116+240'!M10 -> 45281
B11: Ngày | C11: Ngày cộng dồn | D11: Cao độ mốc | E11: Số đọc mia của mốc | F11: Cao độ đường ngắm | G11: Trái | M11: Tim | S11: Phải | Z11: Chiều dày lớp đắp (m) | AA11: Chiều cao nền đắp (m) | AB11: Chiều dày nền đắp (m)
G12: Cao độ đắp (mm) | H12: Số đọc mia | I12: Cao độ quan trắc (mm) | J12: Cao độ bàn đo lún (mm) | K12: Độ lún (mm) | L12: Độ lún tích lũy (mm) | M12: Cao độ đắp (mm) | N12: Số đọc mia | O12: Cao độ quan trắc (mm) | P12: Cao độ bàn đo lún (mm) | Q12: Độ lún (mm) | R12: Độ lún tích lũy (mm) | S12: Cao độ đắp (mm) | T12: Số đọc mia | U12: Cao độ quan trắc (mm) | V12: Cao độ bàn đo lún (mm) | W12: Độ lún (mm) | X12: Độ lún tích lũy (mm)
B13: ='116+240'!B14 -> 45281 | C13: 0 | D13: =VLOOKUP(B13,'116+240'!B14:AB115,2,FALSE) -> 844 | E13: =VLOOKUP(B13,'116+240'!B14:AB115,3,FALSE) -> 1625 | F13: =D13+E13 -> 2469 | G13: =VLOOKUP(B13,'116+240'!$B$14:$AB$115,20,FALSE) -> 40 | H13: =VLOOKUP(B13,'116+240'!$B$14:$AB$115,4,FALSE) -> 429 | I13: =F13-H13 -> 2040 | J13: =VLOOKUP(B13,'116+240'!$B$14:$AB$115,13,FALSE) -> 40 | K13: ='116+240'!Q14 -> 0 | L13: 0 | M13: =VLOOKUP(B13,'116+240'!$B$14:$AB$115,21,FALSE) -> -80 | N13: =VLOOKUP(B13,'116+240'!$B$14:$AB$115,5,FALSE) -> 549 | O13: =F13-N13 -> 1920 | P13: =VLOOKUP(B13,'116+240'!$B$14:$AB$115,14,FALSE) -> -80 | Q13: 0 | R13: 0 | S13: =VLOOKUP(B13,'116+240'!$B$14:$AB$115,22,FALSE) -> -30 | T13: =VLOOKUP(B13,'116+240'!$B$13:$AB$115,6,FALSE) -> 499 | U13: =F13-T13 -> 1970 | V13: =VLOOKUP(B13,'116+240'!$B$14:$AB$115,15,FALSE) -> -30 | W13: 0 | X13: 0 | Y13: 0 | Z13: =IF(Y13>0,Y13,0) -> 0 | AA13: =Z13 -> 0 | AB13: 0
B14: ='116+240'!B15 -> 45282 | C14: =B14-B13 -> 1 | D14: =D13 -> 844 | E14: =VLOOKUP(B14,'116+240'!B15:AB116,3,FALSE) -> 1623 | F14: =D14+E14 -> 2467 | G14: =VLOOKUP(B14,'116+240'!$B$15:$AB$115,20,FALSE) -> 40 | H14: =VLOOKUP(B14,'116+240'!$B$15:$AB$115,4,FALSE) -> 427 | I14: =F14-H14 -> 2040 | J14: =VLOOKUP(B14,'116+240'!$B$15:$AB$115,13,FALSE) -> 40 | K14: ='116+240'!Q15 -> 0 | L14: =+K14+L13 -> 0 | M14: =VLOOKUP(B14,'116+240'!$B$14:$AB$115,21,FALSE) -> -80 | N14: =VLOOKUP(B14,'116+240'!$B$15:$AB$115,5,FALSE) -> 547 | O14: =F14-N14 -> 1920 | P14: =VLOOKUP(B14,'116+240'!$B$15:$AB$115,14,FALSE) -> -80 | Q14: ='116+240'!R15 -> 0 | R14: =+Q14+R13 -> 0 | S14: =VLOOKUP(B14,'116+240'!$B$14:$AB$115,22,FALSE) -> -30 | T14: =VLOOKUP(B14,'116+240'!$B$15:$AB$115,6,FALSE) -> 497 | U14: =F14-T14 -> 1970 | V14: =VLOOKUP(B14,'116+240'!$B$15:$AB$115,15,FALSE) -> -30 | W14: ='116+240'!S15 -> 0 | X14: =+W14+X13 -> 0 | Y14: =S14-S13 -> 0 | Z14: =IF(Y14>0,Y14,0)/1000 -> 0 | AA14: =AA13+Z14 -> 0 | AB14: =(M14-$M$13-R14)/1000 -> 0
A15: 1 | B15: ='116+240'!B16 -> 45283 | C15: =B15-B14 -> 1 | D15: =D14 -> 844 | E15: =VLOOKUP(B15,'116+240'!B16:AB117,3,FALSE) -> 1621 | F15: =D15+E15 -> 2465 | G15: =VLOOKUP(B15,'116+240'!$B$15:$AB$115,20,FALSE) -> 40 | H15: =VLOOKUP(B15,'116+240'!$B$15:$AB$115,4,FALSE) -> 425 | I15: =F15-H15 -> 2040 | J15: =VLOOKUP(B15,'116+240'!$B$15:$AB$115,13,FALSE) -> 40 | K15: ='116+240'!Q16 -> 0 | L15: =+K15+L14 -> 0 | M15: =VLOOKUP(B15,'116+240'!$B$14:$AB$115,21,FALSE) -> -80 | N15: =VLOOKUP(B15,'116+240'!$B$15:$AB$115,5,FALSE) -> 545 | O15: =F15-N15 -> 1920 | P15: =VLOOKUP(B15,'116+240'!$B$15:$AB$115,14,FALSE) -> -80 | Q15: ='116+240'!R16 -> 0 | R15: =+Q15+R14 -> 0 | S15: =VLOOKUP(B15,'116+240'!$B$14:$AB$115,22,FALSE) -> -30 | T15: =VLOOKUP(B15,'116+240'!$B$15:$AB$115,6,FALSE) -> 495 | U15: =F15-T15 -> 1970 | V15: =VLOOKUP(B15,'116+240'!$B$15:$AB$115,15,FALSE) -> -30 | W15: ='116+240'!S16 -> 0 | X15: =+W15+X14 -> 0 | Y15: =S15-S14 -> 0 | Z15: =IF(Y15>0,Y15,0)/1000 -> 0 | AA15: =AA14+Z15 -> 0 | AB15: =(M15-$M$13-R15)/1000 -> 0
A16: =A15+1 -> 2 | B16: ='116+240'!B17 -> 45284 | C16: =B16-B15 -> 1 | D16: =D15 -> 844 | E16: =VLOOKUP(B16,'116+240'!B17:AB118,3,FALSE) -> 1619 | F16: =D16+E16 -> 2463 | G16: =VLOOKUP(B16,'116+240'!$B$15:$AB$115,20,FALSE) -> 40 | H16: =VLOOKUP(B16,'116+240'!$B$15:$AB$115,4,FALSE) -> 423 | I16: =F16-H16 -> 2040 | J16: =VLOOKUP(B16,'116+240'!$B$15:$AB$115,13,FALSE) -> 40 | K16: ='116+240'!Q17 -> 0 | L16: =+K16+L15 -> 0 | M16: =VLOOKUP(B16,'116+240'!$B$14:$AB$115,21,FALSE) -> -80 | N16: =VLOOKUP(B16,'116+240'!$B$15:$AB$115,5,FALSE) -> 543 | O16: =F16-N16 -> 1920 | P16: =VLOOKUP(B16,'116+240'!$B$15:$AB$115,14,FALSE) -> -80 | Q16: ='116+240'!R17 -> 0 | R16: =+Q16+R15 -> 0 | S16: =VLOOKUP(B16,'116+240'!$B$14:$AB$115,22,FALSE) -> -30 | T16: =VLOOKUP(B16,'116+240'!$B$15:$AB$115,6,FALSE) -> 493 | U16: =F16-T16 -> 1970 | V16: =VLOOKUP(B16,'116+240'!$B$15:$AB$115,15,FALSE) -> -30 | W16: ='116+240'!S17 -> 0 | X16: =+W16+X15 -> 0 | Y16: =S16-S15 -> 0 | Z16: =IF(Y16>0,Y16,0)/1000 -> 0 | AA16: =AA15+Z16 -> 0 | AB16: =(M16-$M$13-R16)/1000 -> 0
A17: =A16+1 -> 3 | B17: ='116+240'!B18 -> 45285 | C17: =B17-B16 -> 1 | D17: =D16 -> 844 | E17: =VLOOKUP(B17,'116+240'!B18:AB119,3,FALSE) -> 1617 | F17: =D17+E17 -> 2461 | G17: =VLOOKUP(B17,'116+240'!$B$15:$AB$115,20,FALSE) -> 40 | H17: =VLOOKUP(B17,'116+240'!$B$15:$AB$115,4,FALSE) -> 421 | I17: =F17-H17 -> 2040 | J17: =VLOOKUP(B17,'116+240'!$B$15:$AB$115,13,FALSE) -> 40 | K17: ='116+240'!Q18 -> 0 | L17: =+K17+L16 -> 0 | M17: =VLOOKUP(B17,'116+240'!$B$14:$AB$115,21,FALSE) -> -80 | N17: =VLOOKUP(B17,'116+240'!$B$15:$AB$115,5,FALSE) -> 541 | O17: =F17-N17 -> 1920 | P17: =VLOOKUP(B17,'116+240'!$B$15:$AB$115,14,FALSE) -> -80 | Q17: ='116+240'!R18 -> 0 | R17: =+Q17+R16 -> 0 | S17: =VLOOKUP(B17,'116+240'!$B$14:$AB$115,22,FALSE) -> -30 | T17: =VLOOKUP(B17,'116+240'!$B$15:$AB$115,6,FALSE) -> 491 | U17: =F17-T17 -> 1970 | V17: =VLOOKUP(B17,'116+240'!$B$15:$AB$115,15,FALSE) -> -30 | W17: ='116+240'!S18 -> 0 | X17: =+W17+X16 -> 0 | Y17: =S17-S16 -> 0 | Z17: =IF(Y17>0,Y17,0)/1000 -> 0 | AA17: =AA16+Z17 -> 0 | AB17: =(M17-$M$13-R17)/1000 -> 0
A18: =A17+1 -> 4 | B18: ='116+240'!B19 -> 45286 | C18: =B18-B17 -> 1 | D18: =D17 -> 844 | E18: =VLOOKUP(B18,'116+240'!B19:AB120,3,FALSE) -> 1615 | F18: =D18+E18 -> 2459 | G18: =VLOOKUP(B18,'116+240'!$B$15:$AB$115,20,FALSE) -> 40 | H18: =VLOOKUP(B18,'116+240'!$B$15:$AB$115,4,FALSE) -> 419 | I18: =F18-H18 -> 2040 | J18: =VLOOKUP(B18,'116+240'!$B$15:$AB$115,13,FALSE) -> 40 | K18: ='116+240'!Q19 -> 0 | L18: =+K18+L17 -> 0 | M18: =VLOOKUP(B18,'116+240'!$B$14:$AB$115,21,FALSE) -> -80 | N18: =VLOOKUP(B18,'116+240'!$B$15:$AB$115,5,FALSE) -> 539 | O18: =F18-N18 -> 1920 | P18: =VLOOKUP(B18,'116+240'!$B$15:$AB$115,14,FALSE) -> -80 | Q18: ='116+240'!R19 -> 0 | R18: =+Q18+R17 -> 0 | S18: =VLOOKUP(B18,'116+240'!$B$14:$AB$115,22,FALSE) -> -30 | T18: =VLOOKUP(B18,'116+240'!$B$15:$AB$115,6,FALSE) -> 489 | U18: =F18-T18 -> 1970 | V18: =VLOOKUP(B18,'116+240'!$B$15:$AB$115,15,FALSE) -> -30 | W18: ='116+240'!S19 -> 0 | X18: =+W18+X17 -> 0 | Y18: =S18-S17 -> 0 | Z18: =IF(Y18>0,Y18,0)/1000 -> 0 | AA18: =AA17+Z18 -> 0 | AB18: =(M18-$M$13-R18)/1000 -> 0
A19: =A18+1 -> 5 | B19: ='116+240'!B20 -> 45287 | C19: =B19-B18 -> 1 | D19: =D18 -> 844 | E19: =VLOOKUP(B19,'116+240'!B20:AB121,3,FALSE) -> 1613 | F19: =D19+E19 -> 2457 | G19: =VLOOKUP(B19,'116+240'!$B$15:$AB$115,20,FALSE) -> 40 | H19: =VLOOKUP(B19,'116+240'!$B$15:$AB$115,4,FALSE) -> 417 | I19: =F19-H19 -> 2040 | J19: =VLOOKUP(B19,'116+240'!$B$15:$AB$115,13,FALSE) -> 40 | K19: ='116+240'!Q20 -> 0 | L19: =+K19+L18 -> 0 | M19: =VLOOKUP(B19,'116+240'!$B$14:$AB$115,21,FALSE) -> -80 | N19: =VLOOKUP(B19,'116+240'!$B$15:$AB$115,5,FALSE) -> 537 | O19: =F19-N19 -> 1920 | P19: =VLOOKUP(B19,'116+240'!$B$15:$AB$115,14,FALSE) -> -80 | Q19: ='116+240'!R20 -> 0 | R19: =+Q19+R18 -> 0 | S19: =VLOOKUP(B19,'116+240'!$B$14:$AB$115,22,FALSE) -> -30 | T19: =VLOOKUP(B19,'116+240'!$B$15:$AB$115,6,FALSE) -> 487 | U19: =F19-T19 -> 1970 | V19: =VLOOKUP(B19,'116+240'!$B$15:$AB$115,15,FALSE) -> -30 | W19: ='116+240'!S20 -> 0 | X19: =+W19+X18 -> 0 | Y19: =S19-S18 -> 0 | Z19: =IF(Y19>0,Y19,0)/1000 -> 0 | AA19: =AA18+Z19 -> 0 | AB19: =(M19-$M$13-R19)/1000 -> 0
A20: =A19+1 -> 6 | B20: ='116+240'!B21 -> 45288 | C20: =B20-B19 -> 1 | D20: =D19 -> 844 | E20: =VLOOKUP(B20,'116+240'!B21:AB122,3,FALSE) -> 1611 | F20: =D20+E20 -> 2455 | G20: =VLOOKUP(B20,'116+240'!$B$15:$AB$115,20,FALSE) -> 40 | H20: =VLOOKUP(B20,'116+240'!$B$15:$AB$115,4,FALSE) -> 415 | I20: =F20-H20 -> 2040 | J20: =VLOOKUP(B20,'116+240'!$B$15:$AB$115,13,FALSE) -> 40 | K20: ='116+240'!Q21 -> 0 | L20: =+K20+L19 -> 0 | M20: =VLOOKUP(B20,'116+240'!$B$14:$AB$115,21,FALSE) -> -80 | N20: =VLOOKUP(B20,'116+240'!$B$15:$AB$115,5,FALSE) -> 535 | O20: =F20-N20 -> 1920 | P20: =VLOOKUP(B20,'116+240'!$B$15:$AB$115,14,FALSE) -> -80 | Q20: ='116+240'!R21 -> 0 | R20: =+Q20+R19 -> 0 | S20: =VLOOKUP(B20,'116+240'!$B$14:$AB$115,22,FALSE) -> -30 | T20: =VLOOKUP(B20,'116+240'!$B$15:$AB$115,6,FALSE) -> 485 | U20: =F20-T20 -> 1970 | V20: =VLOOKUP(B20,'116+240'!$B$15:$AB$115,15,FALSE) -> -30 | W20: ='116+240'!S21 -> 0 | X20: =+W20+X19 -> 0 | Y20: =S20-S19 -> 0 | Z20: =IF(Y20>0,Y20,0)/1000 -> 0 | AA20: =AA19+Z20 -> 0 | AB20: =(M20-$M$13-R20)/1000 -> 0
A21: =A20+1 -> 7 | B21: ='116+240'!B22 -> 45289 | C21: =B21-B20 -> 1 | D21: =D20 -> 844 | E21: =VLOOKUP(B21,'116+240'!B22:AB123,3,FALSE) -> 1609 | F21: =D21+E21 -> 2453 | G21: =VLOOKUP(B21,'116+240'!$B$15:$AB$115,20,FALSE) -> 40 | H21: =VLOOKUP(B21,'116+240'!$B$15:$AB$115,4,FALSE) -> 413 | I21: =F21-H21 -> 2040 | J21: =VLOOKUP(B21,'116+240'!$B$15:$AB$115,13,FALSE) -> 40 | K21: ='116+240'!Q22 -> 0 | L21: =+K21+L20 -> 0 | M21: =VLOOKUP(B21,'116+240'!$B$14:$AB$115,21,FALSE) -> -80 | N21: =VLOOKUP(B21,'116+240'!$B$15:$AB$115,5,FALSE) -> 533 | O21: =F21-N21 -> 1920 | P21: =VLOOKUP(B21,'116+240'!$B$15:$AB$115,14,FALSE) -> -80 | Q21: ='116+240'!R22 -> 0 | R21: =+Q21+R20 -> 0 | S21: =VLOOKUP(B21,'116+240'!$B$14:$AB$115,22,FALSE) -> -30 | T21: =VLOOKUP(B21,'116+240'!$B$15:$AB$115,6,FALSE) -> 483 | U21: =F21-T21 -> 1970 | V21: =VLOOKUP(B21,'116+240'!$B$15:$AB$115,15,FALSE) -> -30 | W21: ='116+240'!S22 -> 0 | X21: =+W21+X20 -> 0 | Y21: =S21-S20 -> 0 | Z21: =IF(Y21>0,Y21,0)/1000 -> 0 | AA21: =AA20+Z21 -> 0 | AB21: =(M21-$M$13-R21)/1000 -> 0
B22: ='116+240'!B23 -> 45290 | C22: =B22-B21 -> 1 | D22: =D21 -> 844 | E22: =VLOOKUP(B22,'116+240'!B23:AB124,3,FALSE) -> 1607 | F22: =D22+E22 -> 2451 | G22: =VLOOKUP(B22,'116+240'!$B$15:$AB$115,20,FALSE) -> 40 | H22: =VLOOKUP(B22,'116+240'!$B$15:$AB$115,4,FALSE) -> 411 | I22: =F22-H22 -> 2040 | J22: =VLOOKUP(B22,'116+240'!$B$15:$AB$115,13,FALSE) -> 40 | K22: ='116+240'!Q23 -> 0 | L22: =+K22+L21 -> 0 | M22: =VLOOKUP(B22,'116+240'!$B$14:$AB$115,21,FALSE) -> -80 | N22: =VLOOKUP(B22,'116+240'!$B$15:$AB$115,5,FALSE) -> 531 | O22: =F22-N22 -> 1920 | P22: =VLOOKUP(B22,'116+240'!$B$15:$AB$115,14,FALSE) -> -80 | Q22: ='116+240'!R23 -> 0 | R22: =+Q22+R21 -> 0 | S22: =VLOOKUP(B22,'116+240'!$B$14:$AB$115,22,FALSE) -> -30 | T22: =VLOOKUP(B22,'116+240'!$B$15:$AB$115,6,FALSE) -> 481 | U22: =F22-T22 -> 1970 | V22: =VLOOKUP(B22,'116+240'!$B$15:$AB$115,15,FALSE) -> -30 | W22: ='116+240'!S23 -> 0 | X22: =+W22+X21 -> 0 | Y22: =S22-S21 -> 0 | Z22: =IF(Y22>0,Y22,0)/1000 -> 0 | AA22: =AA21+Z22 -> 0 | AB22: =(M22-$M$13-R22)/1000 -> 0
B23: ='116+240'!B24 -> 45291 | C23: =B23-B22 -> 1 | D23: =D22 -> 844 | E23: =VLOOKUP(B23,'116+240'!B24:AB125,3,FALSE) -> 1605 | F23: =D23+E23 -> 2449 | G23: =VLOOKUP(B23,'116+240'!$B$15:$AB$115,20,FALSE) -> 40 | H23: =VLOOKUP(B23,'116+240'!$B$15:$AB$115,4,FALSE) -> 409 | I23: =F23-H23 -> 2040 | J23: =VLOOKUP(B23,'116+240'!$B$15:$AB$115,13,FALSE) -> 40 | K23: ='116+240'!Q24 -> 0 | L23: =+K23+L22 -> 0 | M23: =VLOOKUP(B23,'116+240'!$B$14:$AB$115,21,FALSE) -> -80 | N23: =VLOOKUP(B23,'116+240'!$B$15:$AB$115,5,FALSE) -> 529 | O23: =F23-N23 -> 1920 | P23: =VLOOKUP(B23,'116+240'!$B$15:$AB$115,14,FALSE) -> -80 | Q23: ='116+240'!R24 -> 0 | R23: =+Q23+R22 -> 0 | S23: =VLOOKUP(B23,'116+240'!$B$14:$AB$115,22,FALSE) -> -30 | T23: =VLOOKUP(B23,'116+240'!$B$15:$AB$115,6,FALSE) -> 479 | U23: =F23-T23 -> 1970 | V23: =VLOOKUP(B23,'116+240'!$B$15:$AB$115,15,FALSE) -> -30 | W23: ='116+240'!S24 -> 0 | X23: =+W23+X22 -> 0 | Y23: =S23-S22 -> 0 | Z23: =IF(Y23>0,Y23,0)/1000 -> 0 | AA23: =AA22+Z23 -> 0 | AB23: =(M23-$M$13-R23)/1000 -> 0
B24: ='116+240'!B25 -> 45292 | C24: =B24-B23 -> 1 | D24: =D23 -> 844 | E24: =VLOOKUP(B24,'116+240'!B25:AB126,3,FALSE) -> 1603 | F24: =D24+E24 -> 2447 | G24: =VLOOKUP(B24,'116+240'!$B$15:$AB$115,20,FALSE) -> 40 | H24: =VLOOKUP(B24,'116+240'!$B$15:$AB$115,4,FALSE) -> 407 | I24: =F24-H24 -> 2040 | J24: =VLOOKUP(B24,'116+240'!$B$15:$AB$115,13,FALSE) -> 40 | K24: ='116+240'!Q25 -> 0 | L24: =+K24+L23 -> 0 | M24: =VLOOKUP(B24,'116+240'!$B$14:$AB$115,21,FALSE) -> -80 | N24: =VLOOKUP(B24,'116+240'!$B$15:$AB$115,5,FALSE) -> 527 | O24: =F24-N24 -> 1920 | P24: =VLOOKUP(B24,'116+240'!$B$15:$AB$115,14,FALSE) -> -80 | Q24: ='116+240'!R25 -> 0 | R24: =+Q24+R23 -> 0 | S24: =VLOOKUP(B24,'116+240'!$B$14:$AB$115,22,FALSE) -> -30 | T24: =VLOOKUP(B24,'116+240'!$B$15:$AB$115,6,FALSE) -> 477 | U24: =F24-T24 -> 1970 | V24: =VLOOKUP(B24,'116+240'!$B$15:$AB$115,15,FALSE) -> -30 | W24: ='116+240'!S25 -> 0 | X24: =+W24+X23 -> 0 | Y24: =S24-S23 -> 0 | Z24: =IF(Y24>0,Y24,0)/1000 -> 0 | AA24: =AA23+Z24 -> 0 | AB24: =(M24-$M$13-R24)/1000 -> 0
B25: ='116+240'!B26 -> 45293 | C25: =B25-B24 -> 1 | D25: =D24 -> 844 | E25: =VLOOKUP(B25,'116+240'!B26:AB127,3,FALSE) -> 1601 | F25: =D25+E25 -> 2445 | G25: =VLOOKUP(B25,'116+240'!$B$15:$AB$115,20,FALSE) -> 94 | H25: =VLOOKUP(B25,'116+240'!$B$15:$AB$115,4,FALSE) -> 411 | I25: =F25-H25 -> 2034 | J25: =VLOOKUP(B25,'116+240'!$B$15:$AB$115,13,FALSE) -> 34 | K25: ='116+240'!Q26 -> 6 | L25: =+K25+L24 -> 6 | M25: =VLOOKUP(B25,'116+240'!$B$14:$AB$115,21,FALSE) -> 92 | N25: =VLOOKUP(B25,'116+240'!$B$15:$AB$115,5,FALSE) -> 533 | O25: =F25-N25 -> 1912 | P25: =VLOOKUP(B25,'116+240'!$B$15:$AB$115,14,FALSE) -> -88 | Q25: ='116+240'!R26 -> 8 | R25: =+Q25+R24 -> 8 | S25: =VLOOKUP(B25,'116+240'!$B$14:$AB$115,22,FALSE) -> 95 | T25: =VLOOKUP(B25,'116+240'!$B$15:$AB$115,6,FALSE) -> 480 | U25: =F25-T25 -> 1965 | V25: =VLOOKUP(B25,'116+240'!$B$15:$AB$115,15,FALSE) -> -35 | W25: ='116+240'!S26 -> 5 | X25: =+W25+X24 -> 5 | Y25: =S25-S24 -> 125 | Z25: =IF(Y25>0,Y25,0)/1000 -> 0.125 | AA25: =AA24+Z25 -> 0.125 | AB25: =(M25-$M$13-R25)/1000 -> 0.164
B26: ='116+240'!B27 -> 45294 | C26: =B26-B25 -> 1 | D26: =D25 -> 844 | E26: =VLOOKUP(B26,'116+240'!B27:AB128,3,FALSE) -> 1599 | F26: =D26+E26 -> 2443 | G26: =VLOOKUP(B26,'116+240'!$B$15:$AB$115,20,FALSE) -> 92 | H26: =VLOOKUP(B26,'116+240'!$B$15:$AB$115,4,FALSE) -> 411 | I26: =F26-H26 -> 2032 | J26: =VLOOKUP(B26,'116+240'!$B$15:$AB$115,13,FALSE) -> 32 | K26: ='116+240'!Q27 -> 2 | L26: =+K26+L25 -> 8 | M26: =VLOOKUP(B26,'116+240'!$B$14:$AB$115,21,FALSE) -> 90 | N26: =VLOOKUP(B26,'116+240'!$B$15:$AB$115,5,FALSE) -> 533 | O26: =F26-N26 -> 1910 | P26: =VLOOKUP(B26,'116+240'!$B$15:$AB$115,14,FALSE) -> -90 | Q26: ='116+240'!R27 -> 2 | R26: =+Q26+R25 -> 10 | S26: =VLOOKUP(B26,'116+240'!$B$14:$AB$115,22,FALSE) -> 94 | T26: =VLOOKUP(B26,'116+240'!$B$15:$AB$115,6,FALSE) -> 479 | U26: =F26-T26 -> 1964 | V26: =VLOOKUP(B26,'116+240'!$B$15:$AB$115,15,FALSE) -> -36 | W26: ='116+240'!S27 -> 1 | X26: =+W26+X25 -> 6 | Y26: =S26-S25 -> -1 | Z26: =IF(Y26>0,Y26,0)/1000 -> 0 | AA26: =AA25+Z26 -> 0.125 | AB26: =(M26-$M$13-R26)/1000 -> 0.16
B27: ='116+240'!B28 -> 45295 | C27: =B27-B26 -> 1 | D27: =D26 -> 844 | E27: =VLOOKUP(B27,'116+240'!B28:AB129,3,FALSE) -> 1597 | F27: =D27+E27 -> 2441 | G27: =VLOOKUP(B27,'116+240'!$B$15:$AB$115,20,FALSE) -> 90 | H27: =VLOOKUP(B27,'116+240'!$B$15:$AB$115,4,FALSE) -> 411 | I27: =F27-H27 -> 2030 | J27: =VLOOKUP(B27,'116+240'!$B$15:$AB$115,13,FALSE) -> 30 | K27: ='116+240'!Q28 -> 2 | L27: =+K27+L26 -> 10 | M27: =VLOOKUP(B27,'116+240'!$B$14:$AB$115,21,FALSE) -> 88 | N27: =VLOOKUP(B27,'116+240'!$B$15:$AB$115,5,FALSE) -> 533 | O27: =F27-N27 -> 1908 | P27: =VLOOKUP(B27,'116+240'!$B$15:$AB$115,14,FALSE) -> -92 | Q27: ='116+240'!R28 -> 2 | R27: =+Q27+R26 -> 12 | S27: =VLOOKUP(B27,'116+240'!$B$14:$AB$115,22,FALSE) -> 93 | T27: =VLOOKUP(B27,'116+240'!$B$15:$AB$115,6,FALSE) -> 478 | U27: =F27-T27 -> 1963 | V27: =VLOOKUP(B27,'116+240'!$B$15:$AB$115,15,FALSE) -> -37 | W27: ='116+240'!S28 -> 1 | X27: =+W27+X26 -> 7 | Y27: =S27-S26 -> -1 | Z27: =IF(Y27>0,Y27,0)/1000 -> 0 | AA27: =AA26+Z27 -> 0.125 | AB27: =(M27-$M$13-R27)/1000 -> 0.156
B28: ='116+240'!B29 -> 45296 | C28: =B28-B27 -> 1 | D28: =D27 -> 844 | E28: =VLOOKUP(B28,'116+240'!B29:AB130,3,FALSE) -> 1595 | F28: =D28+E28 -> 2439 | G28: =VLOOKUP(B28,'116+240'!$B$15:$AB$115,20,FALSE) -> 388 | H28: =VLOOKUP(B28,'116+240'!$B$15:$AB$115,4,FALSE) -> 411 | I28: =F28-H28 -> 2028 | J28: =VLOOKUP(B28,'116+240'!$B$15:$AB$115,13,FALSE) -> 28 | K28: ='116+240'!Q29 -> 2 | L28: =+K28+L27 -> 12 | M28: =VLOOKUP(B28,'116+240'!$B$14:$AB$115,21,FALSE) -> 386 | N28: =VLOOKUP(B28,'116+240'!$B$15:$AB$115,5,FALSE) -> 533 | O28: =F28-N28 -> 1906 | P28: =VLOOKUP(B28,'116+240'!$B$15:$AB$115,14,FALSE) -> -94 | Q28: ='116+240'!R29 -> 2 | R28: =+Q28+R27 -> 14 | S28: =VLOOKUP(B28,'116+240'!$B$14:$AB$115,22,FALSE) -> 391 | T28: =VLOOKUP(B28,'116+240'!$B$15:$AB$115,6,FALSE) -> 478 | U28: =F28-T28 -> 1961 | V28: =VLOOKUP(B28,'116+240'!$B$15:$AB$115,15,FALSE) -> -39 | W28: ='116+240'!S29 -> 2 | X28: =+W28+X27 -> 9 | Y28: =S28-S27 -> 298 | Z28: =IF(Y28>0,Y28,0)/1000 -> 0.298 | AA28: =AA27+Z28 -> 0.423 | AB28: =(M28-$M$13-R28)/1000 -> 0.452
B29: ='116+240'!B30 -> 45297 | C29: =B29-B28 -> 1 | D29: =D28 -> 844 | E29: =VLOOKUP(B29,'116+240'!B30:AB131,3,FALSE) -> 1593 | F29: =D29+E29 -> 2437 | G29: =VLOOKUP(B29,'116+240'!$B$15:$AB$115,20,FALSE) -> 383 | H29: =VLOOKUP(B29,'116+240'!$B$15:$AB$115,4,FALSE) -> 414 | I29: =F29-H29 -> 2023 | J29: =VLOOKUP(B29,'116+240'!$B$15:$AB$115,13,FALSE) -> 23 | K29: ='116+240'!Q30 -> 5 | L29: =+K29+L28 -> 17 | M29: =VLOOKUP(B29,'116+240'!$B$14:$AB$115,21,FALSE) -> 378 | N29: =VLOOKUP(B29,'116+240'!$B$15:$AB$115,5,FALSE) -> 539 | O29: =F29-N29 -> 1898 | P29: =VLOOKUP(B29,'116+240'!$B$15:$AB$115,14,FALSE) -> -102 | Q29: ='116+240'!R30 -> 8 | R29: =+Q29+R28 -> 22 | S29: =VLOOKUP(B29,'116+240'!$B$14:$AB$115,22,FALSE) -> 386 | T29: =VLOOKUP(B29,'116+240'!$B$15:$AB$115,6,FALSE) -> 481 | U29: =F29-T29 -> 1956 | V29: =VLOOKUP(B29,'116+240'!$B$15:$AB$115,15,FALSE) -> -44 | W29: ='116+240'!S30 -> 5 | X29: =+W29+X28 -> 14 | Y29: =S29-S28 -> -5 | Z29: =IF(Y29>0,Y29,0)/1000 -> 0 | AA29: =AA28+Z29 -> 0.423 | AB29: =(M29-$M$13-R29)/1000 -> 0.436
B30: ='116+240'!B31 -> 45298 | C30: =B30-B29 -> 1 | D30: =D29 -> 844 | E30: =VLOOKUP(B30,'116+240'!B31:AB132,3,FALSE) -> 1591 | F30: =D30+E30 -> 2435 | G30: =VLOOKUP(B30,'116+240'!$B$15:$AB$115,20,FALSE) -> 381 | H30: =VLOOKUP(B30,'116+240'!$B$15:$AB$115,4,FALSE) -> 414 | I30: =F30-H30 -> 2021 | J30: =VLOOKUP(B30,'116+240'!$B$15:$AB$115,13,FALSE) -> 21 | K30: ='116+240'!Q31 -> 2 | L30: =+K30+L29 -> 19 | M30: =VLOOKUP(B30,'116+240'!$B$14:$AB$115,21,FALSE) -> 376 | N30: =VLOOKUP(B30,'116+240'!$B$15:$AB$115,5,FALSE) -> 539 | O30: =F30-N30 -> 1896 | P30: =VLOOKUP(B30,'116+240'!$B$15:$AB$115,14,FALSE) -> -104 | Q30: ='116+240'!R31 -> 2 | R30: =+Q30+R29 -> 24 | S30: =VLOOKUP(B30,'116+240'!$B$14:$AB$115,22,FALSE) -> 385 | T30: =VLOOKUP(B30,'116+240'!$B$15:$AB$115,6,FALSE) -> 480 | U30: =F30-T30 -> 1955 | V30: =VLOOKUP(B30,'116+240'!$B$15:$AB$115,15,FALSE) -> -45 | W30: ='116+240'!S31 -> 1 | X30: =+W30+X29 -> 15 | Y30: =S30-S29 -> -1 | Z30: =IF(Y30>0,Y30,0)/1000 -> 0 | AA30: =AA29+Z30 -> 0.423 | AB30: =(M30-$M$13-R30)/1000 -> 0.432
B31: ='116+240'!B32 -> 45299 | C31: =B31-B30 -> 1 | D31: =D30 -> 844 | E31: =VLOOKUP(B31,'116+240'!B32:AB133,3,FALSE) -> 1589 | F31: =D31+E31 -> 2433 | G31: =VLOOKUP(B31,'116+240'!$B$15:$AB$115,20,FALSE) -> 379 | H31: =VLOOKUP(B31,'116+240'!$B$15:$AB$115,4,FALSE) -> 414 | I31: =F31-H31 -> 2019 | J31: =VLOOKUP(B31,'116+240'!$B$15:$AB$115,13,FALSE) -> 19 | K31: ='116+240'!Q32 -> 2 | L31: =+K31+L30 -> 21 | M31: =VLOOKUP(B31,'116+240'!$B$14:$AB$115,21,FALSE) -> 374 | N31: =VLOOKUP(B31,'116+240'!$B$15:$AB$115,5,FALSE) -> 539 | O31: =F31-N31 -> 1894 | P31: =VLOOKUP(B31,'116+240'!$B$15:$AB$115,14,FALSE) -> -106 | Q31: ='116+240'!R32 -> 2 | R31: =+Q31+R30 -> 26 | S31: =VLOOKUP(B31,'116+240'!$B$14:$AB$115,22,FALSE) -> 383 | T31: =VLOOKUP(B31,'116+240'!$B$15:$AB$115,6,FALSE) -> 480 | U31: =F31-T31 -> 1953 | V31: =VLOOKUP(B31,'116+240'!$B$15:$AB$115,15,FALSE) -> -47 | W31: ='116+240'!S32 -> 2 | X31: =+W31+X30 -> 17 | Y31: =S31-S30 -> -2 | Z31: =IF(Y31>0,Y31,0)/1000 -> 0 | AA31: =AA30+Z31 -> 0.423 | AB31: =(M31-$M$13-R31)/1000 -> 0.428
B32: ='116+240'!B33 -> 45300 | C32: =B32-B31 -> 1 | D32: =D31 -> 844 | E32: =VLOOKUP(B32,'116+240'!B33:AB134,3,FALSE) -> 1587 | F32: =D32+E32 -> 2431 | G32: =VLOOKUP(B32,'116+240'!$B$15:$AB$115,20,FALSE) -> 677 | H32: =VLOOKUP(B32,'116+240'!$B$15:$AB$115,4,FALSE) -> 414 | I32: =F32-H32 -> 2017 | J32: =VLOOKUP(B32,'116+240'!$B$15:$AB$115,13,FALSE) -> 17 | K32: ='116+240'!Q33 -> 2 | L32: =+K32+L31 -> 23 | M32: =VLOOKUP(B32,'116+240'!$B$14:$AB$115,21,FALSE) -> 672 | N32: =VLOOKUP(B32,'116+240'!$B$15:$AB$115,5,FALSE) -> 539 | O32: =F32-N32 -> 1892 | P32: =VLOOKUP(B32,'116+240'!$B$15:$AB$115,14,FALSE) -> -108 | Q32: ='116+240'!R33 -> 2 | R32: =+Q32+R31 -> 28 | S32: =VLOOKUP(B32,'116+240'!$B$14:$AB$115,22,FALSE) -> 682 | T32: =VLOOKUP(B32,'116+240'!$B$15:$AB$115,6,FALSE) -> 479 | U32: =F32-T32 -> 1952 | V32: =VLOOKUP(B32,'116+240'!$B$15:$AB$115,15,FALSE) -> -48 | W32: ='116+240'!S33 -> 1 | X32: =+W32+X31 -> 18 | Y32: =S32-S31 -> 299 | Z32: =IF(Y32>0,Y32,0)/1000 -> 0.299 | AA32: =AA31+Z32 -> 0.722 | AB32: =(M32-$M$13-R32)/1000 -> 0.724
B33: ='116+240'!B34 -> 45301 | C33: =B33-B32 -> 1 | D33: =D32 -> 844 | E33: =VLOOKUP(B33,'116+240'!B34:AB135,3,FALSE) -> 1585 | F33: =D33+E33 -> 2429 | G33: =VLOOKUP(B33,'116+240'!$B$15:$AB$115,20,FALSE) -> 672 | H33: =VLOOKUP(B33,'116+240'!$B$15:$AB$115,4,FALSE) -> 417 | I33: =F33-H33 -> 2012 | J33: =VLOOKUP(B33,'116+240'!$B$15:$AB$115,13,FALSE) -> 12 | K33: ='116+240'!Q34 -> 5 | L33: =+K33+L32 -> 28 | M33: =VLOOKUP(B33,'116+240'!$B$14:$AB$115,21,FALSE) -> 664 | N33: =VLOOKUP(B33,'116+240'!$B$15:$AB$115,5,FALSE) -> 545 | O33: =F33-N33 -> 1884 | P33: =VLOOKUP(B33,'116+240'!$B$15:$AB$115,14,FALSE) -> -116 | Q33: ='116+240'!R34 -> 8 | R33: =+Q33+R32 -> 36 | S33: =VLOOKUP(B33,'116+240'!$B$14:$AB$115,22,FALSE) -> 676 | T33: =VLOOKUP(B33,'116+240'!$B$15:$AB$115,6,FALSE) -> 483 | U33: =F33-T33 -> 1946 | V33: =VLOOKUP(B33,'116+240'!$B$15:$AB$115,15,FALSE) -> -54 | W33: ='116+240'!S34 -> 6 | X33: =+W33+X32 -> 24 | Y33: =S33-S32 -> -6 | Z33: =IF(Y33>0,Y33,0)/1000 -> 0 | AA33: =AA32+Z33 -> 0.722 | AB33: =(M33-$M$13-R33)/1000 -> 0.708
... B76: ='116+240'!B77 -> 45344 | C76: =B76-B75 -> 1 | D76: =D75 -> 844 | E76: =VLOOKUP(B76,'116+240'!B77:AB178,3,FALSE) -> 1499 | F76: =D76+E76 -> 2343 | G76: =VLOOKUP(B76,'116+240'!$B$15:$AB$115,20,FALSE) -> 1428 | H76: =VLOOKUP(B76,'116+240'!$B$15:$AB$115,4,FALSE) -> 475 | I76: =F76-H76 -> 1868 | J76: =VLOOKUP(B76,'116+240'!$B$15:$AB$115,13,FALSE) -> -132 | K76: ='116+240'!Q77 -> 2 | L76: =+K76+L75 -> 172 | M76: =VLOOKUP(B76,'116+240'!$B$14:$AB$115,21,FALSE) -> 1478 | N76: =VLOOKUP(B76,'116+240'!$B$15:$AB$115,5,FALSE) -> 545 | O76: =F76-N76 -> 1798 | P76: =VLOOKUP(B76,'116+240'!$B$15:$AB$115,14,FALSE) -> -202 | Q76: ='116+240'!R77 -> 2 | R76: =+Q76+R75 -> 122 | S76: =VLOOKUP(B76,'116+240'!$B$14:$AB$115,22,FALSE) -> 1517 | T76: =VLOOKUP(B76,'116+240'!$B$15:$AB$115,6,FALSE) -> 456 | U76: =F76-T76 -> 1887 | V76: =VLOOKUP(B76,'116+240'!$B$15:$AB$115,15,FALSE) -> -113 | W76: ='116+240'!S77 -> 0 | X76: =+W76+X75 -> 83 | Y76: =S76-S75 -> 0 | Z76: =IF(Y76>0,Y76,0)/1000 -> 0 | AA76: =AA75+Z76 -> 1.618 | AB76: =(M76-$M$13-R76)/1000 -> 1.436
A77: 42307 | B77: ='116+240'!B78 -> 45345 | C77: =B77-B76 -> 1 | D77: =D76 -> 844 | E77: =VLOOKUP(B77,'116+240'!B78:AB179,3,FALSE) -> 1497 | F77: =D77+E77 -> 2341 | G77: =VLOOKUP(B77,'116+240'!$B$15:$AB$115,20,FALSE) -> 1426 | H77: =VLOOKUP(B77,'116+240'!$B$15:$AB$115,4,FALSE) -> 475 | I77: =F77-H77 -> 1866 | J77: =VLOOKUP(B77,'116+240'!$B$15:$AB$115,13,FALSE) -> -134 | K77: ='116+240'!Q78 -> 2 | L77: =+K77+L76 -> 174 | M77: =VLOOKUP(B77,'116+240'!$B$14:$AB$115,21,FALSE) -> 1477 | N77: =VLOOKUP(B77,'116+240'!$B$15:$AB$115,5,FALSE) -> 544 | O77: =F77-N77 -> 1797 | P77: =VLOOKUP(B77,'116+240'!$B$15:$AB$115,14,FALSE) -> -203 | Q77: ='116+240'!R78 -> 1 | R77: =+Q77+R76 -> 123 | S77: =VLOOKUP(B77,'116+240'!$B$14:$AB$115,22,FALSE) -> 1517 | T77: =VLOOKUP(B77,'116+240'!$B$15:$AB$115,6,FALSE) -> 454 | U77: =F77-T77 -> 1887 | V77: =VLOOKUP(B77,'116+240'!$B$15:$AB$115,15,FALSE) -> -113 | W77: ='116+240'!S78 -> 0 | X77: =+W77+X76 -> 83 | Y77: =S77-S76 -> 0 | Z77: =IF(Y77>0,Y77,0)/1000 -> 0 | AA77: =AA76+Z77 -> 1.618 | AB77: =(M77-$M$13-R77)/1000 -> 1.434
A78: 02/11/015 | B78: ='116+240'!B79 -> 45346 | C78: =B78-B77 -> 1 | D78: =D77 -> 844 | E78: =VLOOKUP(B78,'116+240'!B79:AB180,3,FALSE) -> 1495 | F78: =D78+E78 -> 2339 | G78: =VLOOKUP(B78,'116+240'!$B$15:$AB$115,20,FALSE) -> 1423 | H78: =VLOOKUP(B78,'116+240'!$B$15:$AB$115,4,FALSE) -> 476 | I78: =F78-H78 -> 1863 | J78: =VLOOKUP(B78,'116+240'!$B$15:$AB$115,13,FALSE) -> -137 | K78: ='116+240'!Q79 -> 3 | L78: =+K78+L77 -> 177 | M78: =VLOOKUP(B78,'116+240'!$B$14:$AB$115,21,FALSE) -> 1477 | N78: =VLOOKUP(B78,'116+240'!$B$15:$AB$115,5,FALSE) -> 542 | O78: =F78-N78 -> 1797 | P78: =VLOOKUP(B78,'116+240'!$B$15:$AB$115,14,FALSE) -> -203 | Q78: ='116+240'!R79 -> 0 | R78: =+Q78+R77 -> 123 | S78: =VLOOKUP(B78,'116+240'!$B$14:$AB$115,22,FALSE) -> 1517 | T78: =VLOOKUP(B78,'116+240'!$B$15:$AB$115,6,FALSE) -> 452 | U78: =F78-T78 -> 1887 | V78: =VLOOKUP(B78,'116+240'!$B$15:$AB$115,15,FALSE) -> -113 | W78: ='116+240'!S79 -> 0 | X78: =+W78+X77 -> 83 | Y78: =S78-S77 -> 0 | Z78: =IF(Y78>0,Y78,0)/1000 -> 0 | AA78: =AA77+Z78 -> 1.618 | AB78: =(M78-$M$13-R78)/1000 -> 1.434
A79: 42313 | B79: ='116+240'!B80 -> 45347 | C79: =B79-B78 -> 1 | D79: =D78 -> 844 | E79: =VLOOKUP(B79,'116+240'!B80:AB181,3,FALSE) -> 1493 | F79: =D79+E79 -> 2337 | G79: =VLOOKUP(B79,'116+240'!$B$15:$AB$115,20,FALSE) -> 1419 | H79: =VLOOKUP(B79,'116+240'!$B$15:$AB$115,4,FALSE) -> 478 | I79: =F79-H79 -> 1859 | J79: =VLOOKUP(B79,'116+240'!$B$15:$AB$115,13,FALSE) -> -141 | K79: ='116+240'!Q80 -> 4 | L79: =+K79+L78 -> 181 | M79: =VLOOKUP(B79,'116+240'!$B$14:$AB$115,21,FALSE) -> 1477 | N79: =VLOOKUP(B79,'116+240'!$B$15:$AB$115,5,FALSE) -> 540 | O79: =F79-N79 -> 1797 | P79: =VLOOKUP(B79,'116+240'!$B$15:$AB$115,14,FALSE) -> -203 | Q79: ='116+240'!R80 -> 0 | R79: =+Q79+R78 -> 123 | S79: =VLOOKUP(B79,'116+240'!$B$14:$AB$115,22,FALSE) -> 1517 | T79: =VLOOKUP(B79,'116+240'!$B$15:$AB$115,6,FALSE) -> 450 | U79: =F79-T79 -> 1887 | V79: =VLOOKUP(B79,'116+240'!$B$15:$AB$115,15,FALSE) -> -113 | W79: ='116+240'!S80 -> 0 | X79: =+W79+X78 -> 83 | Y79: =S79-S78 -> 0 | Z79: =IF(Y79>0,Y79,0)/1000 -> 0 | AA79: =AA78+Z79 -> 1.618 | AB79: =(M79-$M$13-R79)/1000 -> 1.434
A80: 42319 | B80: ='116+240'!B81 -> 45348 | C80: =B80-B79 -> 1 | D80: =D79 -> 844 | E80: =VLOOKUP(B80,'116+240'!B81:AB182,3,FALSE) -> 1491 | F80: =D80+E80 -> 2335 | G80: =VLOOKUP(B80,'116+240'!$B$15:$AB$115,20,FALSE) -> 1416 | H80: =VLOOKUP(B80,'116+240'!$B$15:$AB$115,4,FALSE) -> 479 | I80: =F80-H80 -> 1856 | J80: =VLOOKUP(B80,'116+240'!$B$15:$AB$115,13,FALSE) -> -144 | K80: ='116+240'!Q81 -> 3 | L80: =+K80+L79 -> 184 | M80: =VLOOKUP(B80,'116+240'!$B$14:$AB$115,21,FALSE) -> 1474 | N80: =VLOOKUP(B80,'116+240'!$B$15:$AB$115,5,FALSE) -> 541 | O80: =F80-N80 -> 1794 | P80: =VLOOKUP(B80,'116+240'!$B$15:$AB$115,14,FALSE) -> -206 | Q80: ='116+240'!R81 -> 3 | R80: =+Q80+R79 -> 126 | S80: =VLOOKUP(B80,'116+240'!$B$14:$AB$115,22,FALSE) -> 1517 | T80: =VLOOKUP(B80,'116+240'!$B$15:$AB$115,6,FALSE) -> 448 | U80: =F80-T80 -> 1887 | V80: =VLOOKUP(B80,'116+240'!$B$15:$AB$115,15,FALSE) -> -113 | W80: ='116+240'!S81 -> 0 | X80: =+W80+X79 -> 83 | Y80: =S80-S79 -> 0 | Z80: =IF(Y80>0,Y80,0)/1000 -> 0 | AA80: =AA79+Z80 -> 1.618 | AB80: =(M80-$M$13-R80)/1000 -> 1.428
A81: 42322 | B81: ='116+240'!B82 -> 45349 | C81: =B81-B80 -> 1 | D81: =D80 -> 844 | E81: =VLOOKUP(B81,'116+240'!B82:AB183,3,FALSE) -> 1489 | F81: =D81+E81 -> 2333 | G81: =VLOOKUP(B81,'116+240'!$B$15:$AB$115,20,FALSE) -> 1407 | H81: =VLOOKUP(B81,'116+240'!$B$15:$AB$115,4,FALSE) -> 486 | I81: =F81-H81 -> 1847 | J81: =VLOOKUP(B81,'116+240'!$B$15:$AB$115,13,FALSE) -> -153 | K81: ='116+240'!Q82 -> 9 | L81: =+K81+L80 -> 193 | M81: =VLOOKUP(B81,'116+240'!$B$14:$AB$115,21,FALSE) -> 1473 | N81: =VLOOKUP(B81,'116+240'!$B$15:$AB$115,5,FALSE) -> 540 | O81: =F81-N81 -> 1793 | P81: =VLOOKUP(B81,'116+240'!$B$15:$AB$115,14,FALSE) -> -207 | Q81: ='116+240'!R82 -> 1 | R81: =+Q81+R80 -> 127 | S81: =VLOOKUP(B81,'116+240'!$B$14:$AB$115,22,FALSE) -> 1517 | T81: =VLOOKUP(B81,'116+240'!$B$15:$AB$115,6,FALSE) -> 446 | U81: =F81-T81 -> 1887 | V81: =VLOOKUP(B81,'116+240'!$B$15:$AB$115,15,FALSE) -> -113 | W81: ='116+240'!S82 -> 0 | X81: =+W81+X80 -> 83 | Y81: =S81-S80 -> 0 | Z81: =IF(Y81>0,Y81,0)/1000 -> 0 | AA81: =AA80+Z81 -> 1.618 | AB81: =(M81-$M$13-R81)/1000 -> 1.426
A82: 17/11/015 | B82: ='116+240'!B83 -> 45350 | C82: =B82-B81 -> 1 | D82: =D81 -> 844 | E82: =VLOOKUP(B82,'116+240'!B83:AB184,3,FALSE) -> 1487 | F82: =D82+E82 -> 2331 | G82: =VLOOKUP(B82,'116+240'!$B$15:$AB$115,20,FALSE) -> 1405 | H82: =VLOOKUP(B82,'116+240'!$B$15:$AB$115,4,FALSE) -> 486 | I82: =F82-H82 -> 1845 | J82: =VLOOKUP(B82,'116+240'!$B$15:$AB$115,13,FALSE) -> -155 | K82: ='116+240'!Q83 -> 2 | L82: =+K82+L81 -> 195 | M82: =VLOOKUP(B82,'116+240'!$B$14:$AB$115,21,FALSE) -> 1473 | N82: =VLOOKUP(B82,'116+240'!$B$15:$AB$115,5,FALSE) -> 538 | O82: =F82-N82 -> 1793 | P82: =VLOOKUP(B82,'116+240'!$B$15:$AB$115,14,FALSE) -> -207 | Q82: ='116+240'!R83 -> 0 | R82: =+Q82+R81 -> 127 | S82: =VLOOKUP(B82,'116+240'!$B$14:$AB$115,22,FALSE) -> 1516 | T82: =VLOOKUP(B82,'116+240'!$B$15:$AB$115,6,FALSE) -> 445 | U82: =F82-T82 -> 1886 | V82: =VLOOKUP(B82,'116+240'!$B$15:$AB$115,15,FALSE) -> -114 | W82: ='116+240'!S83 -> 1 | X82: =+W82+X81 -> 84 | Y82: =S82-S81 -> -1 | Z82: =IF(Y82>0,Y82,0)/1000 -> 0 | AA82: =AA81+Z82 -> 1.618 | AB82: =(M82-$M$13-R82)/1000 -> 1.426
A83: 42328 | B83: ='116+240'!B84 -> 45351 | C83: =B83-B82 -> 1 | D83: =D82 -> 844 | E83: =VLOOKUP(B83,'116+240'!B84:AB185,3,FALSE) -> 1485 | F83: =D83+E83 -> 2329 | G83: =VLOOKUP(B83,'116+240'!$B$15:$AB$115,20,FALSE) -> 1401 | H83: =VLOOKUP(B83,'116+240'!$B$15:$AB$115,4,FALSE) -> 488 | I83: =F83-H83 -> 1841 | J83: =VLOOKUP(B83,'116+240'!$B$15:$AB$115,13,FALSE) -> -159 | K83: ='116+240'!Q84 -> 4 | L83: =+K83+L82 -> 199 | M83: =VLOOKUP(B83,'116+240'!$B$14:$AB$115,21,FALSE) -> 1473 | N83: =VLOOKUP(B83,'116+240'!$B$15:$AB$115,5,FALSE) -> 536 | O83: =F83-N83 -> 1793 | P83: =VLOOKUP(B83,'116+240'!$B$15:$AB$115,14,FALSE) -> -207 | Q83: ='116+240'!R84 -> 0 | R83: =+Q83+R82 -> 127 | S83: =VLOOKUP(B83,'116+240'!$B$14:$AB$115,22,FALSE) -> 1516 | T83: =VLOOKUP(B83,'116+240'!$B$15:$AB$115,6,FALSE) -> 443 | U83: =F83-T83 -> 1886 | V83: =VLOOKUP(B83,'116+240'!$B$15:$AB$115,15,FALSE) -> -114 | W83: ='116+240'!S84 -> 0 | X83: =+W83+X82 -> 84 | Y83: =S83-S82 -> 0 | Z83: =IF(Y83>0,Y83,0)/1000 -> 0 | AA83: =AA82+Z83 -> 1.618 | AB83: =(M83-$M$13-R83)/1000 -> 1.426
...

Sheet SL.116+240
A1: DỰ ÁN THÀNH PHẦN ĐOẠN HẬU GIANG - CÀ MAU
A2: THUỘC DỰ ÁN XÂY DỰNG CÔNG TRÌNH ĐƯỜNG BỘ CAO TỐC BẮC - NAM PHÍA ĐÔNG GIAI ĐOẠN 2021 - 2025
A3: =UPPER("GÓI THẦU XL03 :Thi Công Xây Dựng Đoạn Tuyến Km114+200 - Km126+223 Bao Gồm Tuyến Nối Nút Giao IC12 Với QL1 (bao gồm khảo sát, thiết kế BVTC)") -> GÓI THẦU XL03 :THI CÔNG XÂY DỰNG ĐOẠN TUYẾN KM114+200 - KM126+223 BAO GỒM TUYẾN NỐI NÚT GIAO IC12 VỚI QL1 (BAO GỒM KHẢO SÁT, THIẾT KẾ BVTC)
A4: CHỦ ĐẦU TƯ | F4: TƯ VẤN GIÁM SÁT | K4: NHÀ THẦU
A5: BAN QUẢN LÝ DỰ ÁN MỸ THUẬN | F5: =UPPER("Liên danh Phân viện KHCN GTVT phía Nam - Công ty Cổ phần Tư vấn kỹ thuật và xây dựng Hồng Hà") -> LIÊN DANH PHÂN VIỆN KHCN GTVT PHÍA NAM - CÔNG TY CỔ PHẦN TƯ VẤN KỸ THUẬT VÀ XÂY DỰNG HỒNG HÀ | K5: LIÊN DANH CC1 - HẢI ĐĂNG - VẠN CƯỜNG - 492 - BẮC TRUNG NAM
A6: BIỂU GHI ĐO QUAN TRẮC LÚN
A7: Người lập: | B7: ='[4]BC.95+020'!C7 -> 0 | K7: Tên mốc: | M7: ='[4]BC.95+020'!N7 -> 0
A8: Thời tiết: | B8: ='[4]BC.95+020'!C8 -> năng | K8: Cao độ mốc: | M8: ='116+240'!M9 -> 844
A9: Lý trình: | B9: ='116+240'!C10 -> Km116+240 | K9: Ngày đặt bàn: | M9: ='116+240'!M10 -> 45281
A11: ="BÀN QUAN TRẮC: "&B9 -> BÀN QUAN TRẮC: Km116+240
A12: Ngày đo | B12: Số ngày | C12: Cao độ đắp(m) | D12: Chiều cao nền đắp (m) | E12: chiều dày đắp(m) | F12: Trái | H12: Giữa | J12: Phải | L12: Độ lún (trái) (mm) | M12: Độ lún (giữa) (mm) | N12: Độ lún (phải) (mm) | O12: Ghi chú
F13: Cao độ quan trắc | G13: Cao độ bàn đo lún | H13: Cao độ quan trắc | I13: Cao độ bàn đo lún | J13: Cao độ quan trắc | K13: Cao độ bàn đo lún
A14: ='BC.116+240'!B13 -> 45281 | B14: 0 | C14: ='BC.116+240'!M13/1000 -> -0.08 | D14: ='BC.116+240'!AA13 -> 0 | E14: ='BC.116+240'!AB13 -> 0 | F14: =VLOOKUP($A14,'BC.116+240'!$B$13:$X$489,8,0)/1000 -> 2.04 | G14: =VLOOKUP($A14,'BC.116+240'!$B$13:$X$489,9,0)/1000 -> 0.04 | H14: =VLOOKUP($A14,'BC.116+240'!$B$13:$X$489,14,0)/1000 -> 1.92 | I14: =VLOOKUP($A14,'BC.116+240'!$B$13:$X$489,15,0)/1000 -> -0.08 | J14: =VLOOKUP($A14,'BC.116+240'!$B$13:$X$489,20,0)/1000 -> 1.97 | K14: =VLOOKUP($A14,'BC.116+240'!$B$13:$X$489,21,0)/1000 -> -0.03 | L14: =(G14-$G$14)*1000 -> 0 | M14: =(I14-$I$14)*1000 -> 0 | N14: 0
A15: ='BC.116+240'!B14 -> 45282 | B15: 1 | C15: ='BC.116+240'!M14/1000 -> -0.08 | D15: ='BC.116+240'!AA14 -> 0 | E15: ='BC.116+240'!AB14 -> 0 | F15: =VLOOKUP($A15,'BC.116+240'!$B$13:$X$489,8,0)/1000 -> 2.04 | G15: =VLOOKUP($A15,'BC.116+240'!$B$13:$X$489,9,0)/1000 -> 0.04 | H15: =VLOOKUP($A15,'BC.116+240'!$B$13:$X$489,14,0)/1000 -> 1.92 | I15: =VLOOKUP($A15,'BC.116+240'!$B$13:$X$489,15,0)/1000 -> -0.08 | J15: =VLOOKUP($A15,'BC.116+240'!$B$13:$X$489,20,0)/1000 -> 1.97 | K15: =VLOOKUP($A15,'BC.116+240'!$B$13:$X$489,21,0)/1000 -> -0.03 | L15: =(G15-$G$14)*1000 -> 0 | M15: =(I15-$I$14)*1000 -> 0 | N15: =(K15-$K$14)*1000 -> 0
A16: ='BC.116+240'!B15 -> 45283 | B16: 2 | C16: ='BC.116+240'!M15/1000 -> -0.08 | D16: ='BC.116+240'!AA15 -> 0 | E16: ='BC.116+240'!AB15 -> 0 | F16: =VLOOKUP($A16,'BC.116+240'!$B$13:$X$489,8,0)/1000 -> 2.04 | G16: =VLOOKUP($A16,'BC.116+240'!$B$13:$X$489,9,0)/1000 -> 0.04 | H16: =VLOOKUP($A16,'BC.116+240'!$B$13:$X$489,14,0)/1000 -> 1.92 | I16: =VLOOKUP($A16,'BC.116+240'!$B$13:$X$489,15,0)/1000 -> -0.08 | J16: =VLOOKUP($A16,'BC.116+240'!$B$13:$X$489,20,0)/1000 -> 1.97 | K16: =VLOOKUP($A16,'BC.116+240'!$B$13:$X$489,21,0)/1000 -> -0.03 | L16: =(G16-$G$14)*1000 -> 0 | M16: =(I16-$I$14)*1000 -> 0 | N16: =(K16-$K$14)*1000 -> 0
A17: ='BC.116+240'!B16 -> 45284 | B17: 3 | C17: ='BC.116+240'!M16/1000 -> -0.08 | D17: ='BC.116+240'!AA16 -> 0 | E17: ='BC.116+240'!AB16 -> 0 | F17: =VLOOKUP($A17,'BC.116+240'!$B$13:$X$489,8,0)/1000 -> 2.04 | G17: =VLOOKUP($A17,'BC.116+240'!$B$13:$X$489,9,0)/1000 -> 0.04 | H17: =VLOOKUP($A17,'BC.116+240'!$B$13:$X$489,14,0)/1000 -> 1.92 | I17: =VLOOKUP($A17,'BC.116+240'!$B$13:$X$489,15,0)/1000 -> -0.08 | J17: =VLOOKUP($A17,'BC.116+240'!$B$13:$X$489,20,0)/1000 -> 1.97 | K17: =VLOOKUP($A17,'BC.116+240'!$B$13:$X$489,21,0)/1000 -> -0.03 | L17: =(G17-$G$14)*1000 -> 0 | M17: =(I17-$I$14)*1000 -> 0 | N17: =(K17-$K$14)*1000 -> 0
A18: ='BC.116+240'!B17 -> 45285 | B18: 4 | C18: ='BC.116+240'!M17/1000 -> -0.08 | D18: ='BC.116+240'!AA17 -> 0 | E18: ='BC.116+240'!AB17 -> 0 | F18: =VLOOKUP($A18,'BC.116+240'!$B$13:$X$489,8,0)/1000 -> 2.04 | G18: =VLOOKUP($A18,'BC.116+240'!$B$13:$X$489,9,0)/1000 -> 0.04 | H18: =VLOOKUP($A18,'BC.116+240'!$B$13:$X$489,14,0)/1000 -> 1.92 | I18: =VLOOKUP($A18,'BC.116+240'!$B$13:$X$489,15,0)/1000 -> -0.08 | J18: =VLOOKUP($A18,'BC.116+240'!$B$13:$X$489,20,0)/1000 -> 1.97 | K18: =VLOOKUP($A18,'BC.116+240'!$B$13:$X$489,21,0)/1000 -> -0.03 | L18: =(G18-$G$14)*1000 -> 0 | M18: =(I18-$I$14)*1000 -> 0 | N18: =(K18-$K$14)*1000 -> 0
A19: ='BC.116+240'!B18 -> 45286 | B19: 5 | C19: ='BC.116+240'!M18/1000 -> -0.08 | D19: ='BC.116+240'!AA18 -> 0 | E19: ='BC.116+240'!AB18 -> 0 | F19: =VLOOKUP($A19,'BC.116+240'!$B$13:$X$489,8,0)/1000 -> 2.04 | G19: =VLOOKUP($A19,'BC.116+240'!$B$13:$X$489,9,0)/1000 -> 0.04 | H19: =VLOOKUP($A19,'BC.116+240'!$B$13:$X$489,14,0)/1000 -> 1.92 | I19: =VLOOKUP($A19,'BC.116+240'!$B$13:$X$489,15,0)/1000 -> -0.08 | J19: =VLOOKUP($A19,'BC.116+240'!$B$13:$X$489,20,0)/1000 -> 1.97 | K19: =VLOOKUP($A19,'BC.116+240'!$B$13:$X$489,21,0)/1000 -> -0.03 | L19: =(G19-$G$14)*1000 -> 0 | M19: =(I19-$I$14)*1000 -> 0 | N19: =(K19-$K$14)*1000 -> 0
A20: ='BC.116+240'!B19 -> 45287 | B20: 6 | C20: ='BC.116+240'!M19/1000 -> -0.08 | D20: ='BC.116+240'!AA19 -> 0 | E20: ='BC.116+240'!AB19 -> 0 | F20: =VLOOKUP($A20,'BC.116+240'!$B$13:$X$489,8,0)/1000 -> 2.04 | G20: =VLOOKUP($A20,'BC.116+240'!$B$13:$X$489,9,0)/1000 -> 0.04 | H20: =VLOOKUP($A20,'BC.116+240'!$B$13:$X$489,14,0)/1000 -> 1.92 | I20: =VLOOKUP($A20,'BC.116+240'!$B$13:$X$489,15,0)/1000 -> -0.08 | J20: =VLOOKUP($A20,'BC.116+240'!$B$13:$X$489,20,0)/1000 -> 1.97 | K20: =VLOOKUP($A20,'BC.116+240'!$B$13:$X$489,21,0)/1000 -> -0.03 | L20: =(G20-$G$14)*1000 -> 0 | M20: =(I20-$I$14)*1000 -> 0 | N20: =(K20-$K$14)*1000 -> 0
A21: ='BC.116+240'!B20 -> 45288 | B21: 7 | C21: ='BC.116+240'!M20/1000 -> -0.08 | D21: ='BC.116+240'!AA20 -> 0 | E21: ='BC.116+240'!AB20 -> 0 | F21: =VLOOKUP($A21,'BC.116+240'!$B$13:$X$489,8,0)/1000 -> 2.04 | G21: =VLOOKUP($A21,'BC.116+240'!$B$13:$X$489,9,0)/1000 -> 0.04 | H21: =VLOOKUP($A21,'BC.116+240'!$B$13:$X$489,14,0)/1000 -> 1.92 | I21: =VLOOKUP($A21,'BC.116+240'!$B$13:$X$489,15,0)/1000 -> -0.08 | J21: =VLOOKUP($A21,'BC.116+240'!$B$13:$X$489,20,0)/1000 -> 1.97 | K21: =VLOOKUP($A21,'BC.116+240'!$B$13:$X$489,21,0)/1000 -> -0.03 | L21: =(G21-$G$14)*1000 -> 0 | M21: =(I21-$I$14)*1000 -> 0 | N21: =(K21-$K$14)*1000 -> 0
A22: ='BC.116+240'!B21 -> 45289 | B22: 8 | C22: ='BC.116+240'!M21/1000 -> -0.08 | D22: ='BC.116+240'!AA21 -> 0 | E22: ='BC.116+240'!AB21 -> 0 | F22: =VLOOKUP($A22,'BC.116+240'!$B$13:$X$489,8,0)/1000 -> 2.04 | G22: =VLOOKUP($A22,'BC.116+240'!$B$13:$X$489,9,0)/1000 -> 0.04 | H22: =VLOOKUP($A22,'BC.116+240'!$B$13:$X$489,14,0)/1000 -> 1.92 | I22: =VLOOKUP($A22,'BC.116+240'!$B$13:$X$489,15,0)/1000 -> -0.08 | J22: =VLOOKUP($A22,'BC.116+240'!$B$13:$X$489,20,0)/1000 -> 1.97 | K22: =VLOOKUP($A22,'BC.116+240'!$B$13:$X$489,21,0)/1000 -> -0.03 | L22: =(G22-$G$14)*1000 -> 0 | M22: =(I22-$I$14)*1000 -> 0 | N22: =(K22-$K$14)*1000 -> 0
A23: ='BC.116+240'!B22 -> 45290 | B23: 9 | C23: ='BC.116+240'!M22/1000 -> -0.08 | D23: ='BC.116+240'!AA22 -> 0 | E23: ='BC.116+240'!AB22 -> 0 | F23: =VLOOKUP($A23,'BC.116+240'!$B$13:$X$489,8,0)/1000 -> 2.04 | G23: =VLOOKUP($A23,'BC.116+240'!$B$13:$X$489,9,0)/1000 -> 0.04 | H23: =VLOOKUP($A23,'BC.116+240'!$B$13:$X$489,14,0)/1000 -> 1.92 | I23: =VLOOKUP($A23,'BC.116+240'!$B$13:$X$489,15,0)/1000 -> -0.08 | J23: =VLOOKUP($A23,'BC.116+240'!$B$13:$X$489,20,0)/1000 -> 1.97 | K23: =VLOOKUP($A23,'BC.116+240'!$B$13:$X$489,21,0)/1000 -> -0.03 | L23: =(G23-$G$14)*1000 -> 0 | M23: =(I23-$I$14)*1000 -> 0 | N23: =(K23-$K$14)*1000 -> 0
A24: ='BC.116+240'!B23 -> 45291 | B24: 10 | C24: ='BC.116+240'!M23/1000 -> -0.08 | D24: ='BC.116+240'!AA23 -> 0 | E24: ='BC.116+240'!AB23 -> 0 | F24: =VLOOKUP($A24,'BC.116+240'!$B$13:$X$489,8,0)/1000 -> 2.04 | G24: =VLOOKUP($A24,'BC.116+240'!$B$13:$X$489,9,0)/1000 -> 0.04 | H24: =VLOOKUP($A24,'BC.116+240'!$B$13:$X$489,14,0)/1000 -> 1.92 | I24: =VLOOKUP($A24,'BC.116+240'!$B$13:$X$489,15,0)/1000 -> -0.08 | J24: =VLOOKUP($A24,'BC.116+240'!$B$13:$X$489,20,0)/1000 -> 1.97 | K24: =VLOOKUP($A24,'BC.116+240'!$B$13:$X$489,21,0)/1000 -> -0.03 | L24: =(G24-$G$14)*1000 -> 0 | M24: =(I24-$I$14)*1000 -> 0 | N24: =(K24-$K$14)*1000 -> 0
A25: ='BC.116+240'!B24 -> 45292 | B25: 11 | C25: ='BC.116+240'!M24/1000 -> -0.08 | D25: ='BC.116+240'!AA24 -> 0 | E25: ='BC.116+240'!AB24 -> 0 | F25: =VLOOKUP($A25,'BC.116+240'!$B$13:$X$489,8,0)/1000 -> 2.04 | G25: =VLOOKUP($A25,'BC.116+240'!$B$13:$X$489,9,0)/1000 -> 0.04 | H25: =VLOOKUP($A25,'BC.116+240'!$B$13:$X$489,14,0)/1000 -> 1.92 | I25: =VLOOKUP($A25,'BC.116+240'!$B$13:$X$489,15,0)/1000 -> -0.08 | J25: =VLOOKUP($A25,'BC.116+240'!$B$13:$X$489,20,0)/1000 -> 1.97 | K25: =VLOOKUP($A25,'BC.116+240'!$B$13:$X$489,21,0)/1000 -> -0.03 | L25: =(G25-$G$14)*1000 -> 0 | M25: =(I25-$I$14)*1000 -> 0 | N25: =(K25-$K$14)*1000 -> 0
A26: ='BC.116+240'!B25 -> 45293 | B26: 12 | C26: ='BC.116+240'!M25/1000 -> 0.092 | D26: ='BC.116+240'!AA25 -> 0.125 | E26: ='BC.116+240'!AB25 -> 0.164 | F26: =VLOOKUP($A26,'BC.116+240'!$B$13:$X$489,8,0)/1000 -> 2.034 | G26: =VLOOKUP($A26,'BC.116+240'!$B$13:$X$489,9,0)/1000 -> 0.034 | H26: =VLOOKUP($A26,'BC.116+240'!$B$13:$X$489,14,0)/1000 -> 1.912 | I26: =VLOOKUP($A26,'BC.116+240'!$B$13:$X$489,15,0)/1000 -> -0.088 | J26: =VLOOKUP($A26,'BC.116+240'!$B$13:$X$489,20,0)/1000 -> 1.965 | K26: =VLOOKUP($A26,'BC.116+240'!$B$13:$X$489,21,0)/1000 -> -0.035 | L26: =(G26-$G$14)*1000 -> -6 | M26: =(I26-$I$14)*1000 -> -8 | N26: =(K26-$K$14)*1000 -> -5
... A91: ='BC.116+240'!B90 -> 45358 | B91: 77 | C91: ='BC.116+240'!M90/1000 -> 1.767 | D91: ='BC.116+240'!AA90 -> 1.918 | E91: ='BC.116+240'!AB90 -> 1.714 | F91: =VLOOKUP($A91,'BC.116+240'!$B$13:$X$489,8,0)/1000 -> 2.805 | G91: =VLOOKUP($A91,'BC.116+240'!$B$13:$X$489,9,0)/1000 -> -0.195 | H91: =VLOOKUP($A91,'BC.116+240'!$B$13:$X$489,14,0)/1000 -> 2.787 | I91: =VLOOKUP($A91,'BC.116+240'!$B$13:$X$489,15,0)/1000 -> -0.213 | J91: =VLOOKUP($A91,'BC.116+240'!$B$13:$X$489,20,0)/1000 -> 2.886 | K91: =VLOOKUP($A91,'BC.116+240'!$B$13:$X$489,21,0)/1000 -> -0.114 | L91: =(G91-$G$14)*1000 -> -235 | M91: =(I91-$I$14)*1000 -> -133 | N91: =(K91-$K$14)*1000 -> -84
A92: ='BC.116+240'!B91 -> 45359 | B92: 78 | C92: ='BC.116+240'!M91/1000 -> 1.767 | D92: ='BC.116+240'!AA91 -> 1.918 | E92: ='BC.116+240'!AB91 -> 1.714 | F92: =VLOOKUP($A92,'BC.116+240'!$B$13:$X$489,8,0)/1000 -> 2.801 | G92: =VLOOKUP($A92,'BC.116+240'!$B$13:$X$489,9,0)/1000 -> -0.199 | H92: =VLOOKUP($A92,'BC.116+240'!$B$13:$X$489,14,0)/1000 -> 2.787 | I92: =VLOOKUP($A92,'BC.116+240'!$B$13:$X$489,15,0)/1000 -> -0.213 | J92: =VLOOKUP($A92,'BC.116+240'!$B$13:$X$489,20,0)/1000 -> 2.886 | K92: =VLOOKUP($A92,'BC.116+240'!$B$13:$X$489,21,0)/1000 -> -0.114 | L92: =(G92-$G$14)*1000 -> -239 | M92: =(I92-$I$14)*1000 -> -133 | N92: =(K92-$K$14)*1000 -> -84 | Y92: =A21-A14 -> 7
A93: ='BC.116+240'!B92 -> 45360 | B93: 79 | C93: ='BC.116+240'!M92/1000 -> 1.764 | D93: ='BC.116+240'!AA92 -> 1.918 | E93: ='BC.116+240'!AB92 -> 1.708 | F93: =VLOOKUP($A93,'BC.116+240'!$B$13:$X$489,8,0)/1000 -> 2.798 | G93: =VLOOKUP($A93,'BC.116+240'!$B$13:$X$489,9,0)/1000 -> -0.202 | H93: =VLOOKUP($A93,'BC.116+240'!$B$13:$X$489,14,0)/1000 -> 2.784 | I93: =VLOOKUP($A93,'BC.116+240'!$B$13:$X$489,15,0)/1000 -> -0.216 | J93: =VLOOKUP($A93,'BC.116+240'!$B$13:$X$489,20,0)/1000 -> 2.886 | K93: =VLOOKUP($A93,'BC.116+240'!$B$13:$X$489,21,0)/1000 -> -0.114 | L93: =(G93-$G$14)*1000 -> -242 | M93: =(I93-$I$14)*1000 -> -136 | N93: =(K93-$K$14)*1000 -> -84
