Workbook

Sheet QTL-KM117+100
A1: BẢNG SỐ LIỆU QUAN TRẮC THIẾT BỊ ĐO LÚN MẶT
A2: I. SỐ ĐỌC BAN ĐẦU
A3: Vùng (Đường) | B3: Bàn quan trắc lún | D3: Ngày lắp đặt | F3: =+"Cao trình nghiệm thu [m] ("&TEXT(A15,"dd/mm/yy")&")" -> Cao trình nghiệm thu [m] (25/07/25) | L3: Tọa độ | P3: Mốc tọa độ tham chiếu
F4: Cao trình MĐTN | G4: Cao trình đắp | I4: Cao trình đỉnh ống | K4: Cao trình tấm đế | L4: X [m] | N4: Y [m]
A5: VÙNG 2A (ĐƯỜNG N1) | B5: SSP2-4 | P5: CS3
B6: SSP2-5 | P6: Tọa độ [m]
B7: SSP2-6
A9: II. SỐ LIỆU QUAN TRẮC
A10: Ngày quan trắc | B10: ĐỘ LÚN TRÁI | G10: ĐỘ LÚN TIM | L10: ĐỘ LÚN PHẢI | Q10: Áp Đ.hồ Pvac | R10: Ghi chú
B11: Thời gian tích lũy | C11: Cao độ đắp | D11: Cao độ bàn đo lún | E11: Chiều cao đắp | F11: Độ lún | G11: Thời gian tích lũy | H11: Cao độ đắp | I11: Cao độ bàn đo lún | J11: Chiều cao đắp | K11: Độ lún | L11: Thời gian tích lũy | M11: Cao độ đắp | N11: Cao độ bàn đo lún | O11: Chiều cao đắp | P11: Độ lún
B13: [Ngày] | C13: [mm] | D13: [m.m] | E13: [mm] | F13: [m.m] | G13: [Ngày] | H13: [mm] | I13: [m.m] | J13: [mm] | K13: [m.m] | L13: [Ngày] | M13: [mm] | N13: [m.m] | O13: [mm] | P13: [m.m] | Q13: [kPa]
A14: 1 | B14: =+A14+1 -> 2 | C14: =+B14+1 -> 3 | D14: =+C14+1 -> 4 | E14: =+D14+1 -> 5 | F14: =+E14+1 -> 6 | G14: =+F14+1 -> 7 | H14: =+G14+1 -> 8 | I14: =+H14+1 -> 9 | ... R14: =+Q14+1 -> 18
A15: 45863 | B15: 1 | C15: 1821 | D15: -559 | E15: =C15-D15 -> 2380 | F15: 0 | G15: 1 | H15: 1766 | I15: -619 | J15: =H15-I15 -> 2385 | K15: 0 | L15: 1 | M15: 1811 | N15: -449 | O15: =M15-N15 -> 2260 | P15: 0
A16: 45864 | B16: 1 | C16: =$C$15-F16 -> 1810 | D16: -570 | E16: =C16-D16 -> 2380 | F16: =$D$15-D16 -> 11 | G16: 1 | H16: =$H$15-K16 -> 1745 | I16: -640 | J16: =H16-I16 -> 2385 | K16: =$I$15-I16 -> 21 | L16: 1 | M16: =$M$15-P16 -> 1803 | N16: -457 | O16: =M16-N16 -> 2260 | P16: =$N$15-N16 -> 8
A17: 45865 | B17: 1 | C17: =$C$15-F17 -> 1791 | D17: -589 | E17: =C17-D17 -> 2380 | F17: =$D$15-D17 -> 30 | G17: 1 | H17: =$H$15-K17 -> 1721 | I17: -664 | J17: =H17-I17 -> 2385 | K17: =$I$15-I17 -> 45 | L17: 1 | M17: =$M$15-P17 -> 1795 | N17: -465 | O17: =M17-N17 -> 2260 | P17: =$N$15-N17 -> 16
A18: 45866 | B18: 1 | C18: =$C$15-F18 -> 1772 | D18: -608 | E18: =C18-D18 -> 2380 | F18: =$D$15-D18 -> 49 | G18: 1 | H18: =$H$15-K18 -> 1697 | I18: -688 | J18: =H18-I18 -> 2385 | K18: =$I$15-I18 -> 69 | L18: 1 | M18: =$M$15-P18 -> 1787 | N18: -473 | O18: =M18-N18 -> 2260 | P18: =$N$15-N18 -> 24
A19: 45867 | B19: 1 | C19: =$C$15-F19 -> 1753 | D19: -627 | E19: =C19-D19 -> 2380 | F19: =$D$15-D19 -> 68 | G19: 1 | H19: =$H$15-K19 -> 1665 | I19: -720 | J19: =H19-I19 -> 2385 | K19: =$I$15-I19 -> 101 | L19: 1 | M19: =$M$15-P19 -> 1785 | N19: -475 | O19: =M19-N19 -> 2260 | P19: =$N$15-N19 -> 26
A20: 45868 | B20: 1 | C20: =$C$15-F20 -> 1740 | D20: -640 | E20: =C20-D20 -> 2380 | F20: =$D$15-D20 -> 81 | G20: 1 | H20: =$H$15-K20 -> 1637 | I20: -748 | J20: =H20-I20 -> 2385 | K20: =$I$15-I20 -> 129 | L20: 1 | M20: =$M$15-P20 -> 1765 | N20: -495 | O20: =M20-N20 -> 2260 | P20: =$N$15-N20 -> 46
A21: 45869 | B21: 1 | C21: =$C$15-F21 -> 1714 | D21: -666 | E21: =C21-D21 -> 2380 | F21: =$D$15-D21 -> 107 | G21: 1 | H21: =$H$15-K21 -> 1609 | I21: -776 | J21: =H21-I21 -> 2385 | K21: =$I$15-I21 -> 157 | L21: 1 | M21: =$M$15-P21 -> 1739 | N21: -521 | O21: =M21-N21 -> 2260 | P21: =$N$15-N21 -> 72
A22: 45870 | B22: 1 | C22: =$C$15-F22 -> 1688 | D22: -692 | E22: =C22-D22 -> 2380 | F22: =$D$15-D22 -> 133 | G22: 1 | H22: =$H$15-K22 -> 1581 | I22: -804 | J22: =H22-I22 -> 2385 | K22: =$I$15-I22 -> 185 | L22: 1 | M22: =$M$15-P22 -> 1713 | N22: -547 | O22: =M22-N22 -> 2260 | P22: =$N$15-N22 -> 98
A23: 45871 | B23: 1 | C23: =$C$15-F23 -> 1662 | D23: -718 | E23: =C23-D23 -> 2380 | F23: =$D$15-D23 -> 159 | G23: 1 | H23: =$H$15-K23 -> 1553 | I23: -832 | J23: =H23-I23 -> 2385 | K23: =$I$15-I23 -> 213 | L23: 1 | M23: =$M$15-P23 -> 1687 | N23: -573 | O23: =M23-N23 -> 2260 | P23: =$N$15-N23 -> 124
A24: 45872 | B24: 1 | C24: =$C$15-F24 -> 1636 | D24: -744 | E24: =C24-D24 -> 2380 | F24: =$D$15-D24 -> 185 | G24: 1 | H24: =$H$15-K24 -> 1525 | I24: -860 | J24: =H24-I24 -> 2385 | K24: =$I$15-I24 -> 241 | L24: 1 | M24: =$M$15-P24 -> 1661 | N24: -599 | O24: =M24-N24 -> 2260 | P24: =$N$15-N24 -> 150
A25: 45873 | B25: 1 | C25: =$C$15-F25 -> 1610 | D25: -770 | E25: =C25-D25 -> 2380 | F25: =$D$15-D25 -> 211 | G25: 1 | H25: =$H$15-K25 -> 1497 | I25: -888 | J25: =H25-I25 -> 2385 | K25: =$I$15-I25 -> 269 | L25: 1 | M25: =$M$15-P25 -> 1635 | N25: -625 | O25: =M25-N25 -> 2260 | P25: =$N$15-N25 -> 176
A26: 45874 | B26: 1 | C26: 2194 | D26: -796 | E26: =C26-D26 -> 2990 | F26: =$D$15-D26 -> 237 | G26: 1 | H26: 2194 | I26: -916 | J26: =H26-I26 -> 3110 | K26: =$I$15-I26 -> 297 | L26: 1 | M26: 2194 | N26: -651 | O26: =M26-N26 -> 2845 | P26: =$N$15-N26 -> 202

Sheet QTL-KM117+200
A1: BẢNG SỐ LIỆU QUAN TRẮC THIẾT BỊ ĐO LÚN MẶT
A2: I. SỐ ĐỌC BAN ĐẦU
A3: Vùng (Đường) | B3: Bàn quan trắc lún | D3: Ngày lắp đặt | F3: =+"Cao trình nghiệm thu [m] ("&TEXT(A15,"dd/mm/yy")&")" -> Cao trình nghiệm thu [m] (10/06/25) | L3: Tọa độ | P3: Mốc tọa độ tham chiếu
F4: Cao trình MĐTN | G4: Cao trình đắp | I4: Cao trình đỉnh ống | K4: Cao trình tấm đế | L4: X [m] | N4: Y [m]
A5: VÙNG 2A (ĐƯỜNG N1) | B5: SSP2-4 | P5: CS3
B6: SSP2-5 | P6: Tọa độ [m]
B7: SSP2-6
A9: II. SỐ LIỆU QUAN TRẮC
A10: Ngày quan trắc | B10: ĐỘ LÚN TRÁI | G10: ĐỘ LÚN TIM | L10: ĐỘ LÚN PHẢI | Q10: Áp Đ.hồ Pvac | R10: Ghi chú
B11: Thời gian tích lũy | C11: Cao độ đắp | D11: Cao độ bàn đo lún | E11: Chiều cao đắp | F11: Độ lún | G11: Thời gian tích lũy | H11: Cao độ đắp | I11: Cao độ bàn đo lún | J11: Chiều cao đắp | K11: Độ lún | L11: Thời gian tích lũy | M11: Cao độ đắp | N11: Cao độ bàn đo lún | O11: Chiều cao đắp | P11: Độ lún
B13: [Ngày] | C13: [mm] | D13: [m.m] | E13: [mm] | F13: [m.m] | G13: [Ngày] | H13: [mm] | I13: [m.m] | J13: [mm] | K13: [m.m] | L13: [Ngày] | M13: [mm] | N13: [m.m] | O13: [mm] | P13: [m.m] | Q13: [kPa]
A14: 1 | B14: =+A14+1 -> 2 | C14: =+B14+1 -> 3 | D14: =+C14+1 -> 4 | E14: =+D14+1 -> 5 | F14: =+E14+1 -> 6 | G14: =+F14+1 -> 7 | H14: =+G14+1 -> 8 | I14: =+H14+1 -> 9 | ... R14: =+Q14+1 -> 18
A15: 45818 | B15: 1 | C15: 1380 | D15: -1193 | E15: =C15-D15 -> 2573 | F15: 0 | G15: 1 | H15: 1460 | I15: -910 | J15: =H15-I15 -> 2370 | K15: 0 | L15: 1 | M15: 1490 | N15: -851 | O15: =M15-N15 -> 2341 | P15: 0
A16: 45819 | B16: 1 | C16: =$C$15-F16 -> 1377 | D16: -1196 | E16: =C16-D16 -> 2573 | F16: =$D$15-D16 -> 3 | G16: 1 | H16: =$H$15-K16 -> 1455 | I16: -915 | J16: =H16-I16 -> 2370 | K16: =$I$15-I16 -> 5 | L16: 1 | M16: =$M$15-P16 -> 1484 | N16: -857 | O16: =M16-N16 -> 2341 | P16: =$N$15-N16 -> 6
A17: 45820 | B17: 1 | C17: =$C$15-F17 -> 1374 | D17: -1199 | E17: =C17-D17 -> 2573 | F17: =$D$15-D17 -> 6 | G17: 1 | H17: =$H$15-K17 -> 1450 | I17: -920 | J17: =H17-I17 -> 2370 | K17: =$I$15-I17 -> 10 | L17: 1 | M17: =$M$15-P17 -> 1478 | N17: -863 | O17: =M17-N17 -> 2341 | P17: =$N$15-N17 -> 12
A18: 45821 | B18: 1 | C18: =$C$15-F18 -> 1371 | D18: -1202 | E18: =C18-D18 -> 2573 | F18: =$D$15-D18 -> 9 | G18: 1 | H18: =$H$15-K18 -> 1445 | I18: -925 | J18: =H18-I18 -> 2370 | K18: =$I$15-I18 -> 15 | L18: 1 | M18: =$M$15-P18 -> 1472 | N18: -869 | O18: =M18-N18 -> 2341 | P18: =$N$15-N18 -> 18
A19: 45822 | B19: 1 | C19: =$C$15-F19 -> 1368 | D19: -1205 | E19: =C19-D19 -> 2573 | F19: =$D$15-D19 -> 12 | G19: 1 | H19: =$H$15-K19 -> 1440 | I19: -930 | J19: =H19-I19 -> 2370 | K19: =$I$15-I19 -> 20 | L19: 1 | M19: =$M$15-P19 -> 1466 | N19: -875 | O19: =M19-N19 -> 2341 | P19: =$N$15-N19 -> 24
A20: 45823 | B20: 1 | C20: =$C$15-F20 -> 1368 | D20: -1205 | E20: =C20-D20 -> 2573 | F20: =$D$15-D20 -> 12 | G20: 1 | H20: =$H$15-K20 -> 1436 | I20: -934 | J20: =H20-I20 -> 2370 | K20: =$I$15-I20 -> 24 | L20: 1 | M20: =$M$15-P20 -> 1461 | N20: -880 | O20: =M20-N20 -> 2341 | P20: =$N$15-N20 -> 29
A21: 45824 | B21: 1 | C21: =$C$15-F21 -> 1359 | D21: -1214 | E21: =C21-D21 -> 2573 | F21: =$D$15-D21 -> 21 | G21: 1 | H21: =$H$15-K21 -> 1422 | I21: -948 | J21: =H21-I21 -> 2370 | K21: =$I$15-I21 -> 38 | L21: 1 | M21: =$M$15-P21 -> 1456 | N21: -885 | O21: =M21-N21 -> 2341 | P21: =$N$15-N21 -> 34
A22: 45825 | B22: 1 | C22: =$C$15-F22 -> 1350 | D22: -1223 | E22: =C22-D22 -> 2573 | F22: =$D$15-D22 -> 30 | G22: 1 | H22: =$H$15-K22 -> 1410 | I22: -960 | J22: =H22-I22 -> 2370 | K22: =$I$15-I22 -> 50 | L22: 1 | M22: =$M$15-P22 -> 1451 | N22: -890 | O22: =M22-N22 -> 2341 | P22: =$N$15-N22 -> 39
A23: 45826 | B23: 1 | C23: =$C$15-F23 -> 1341 | D23: -1232 | E23: =C23-D23 -> 2573 | F23: =$D$15-D23 -> 39 | G23: 1 | H23: =$H$15-K23 -> 1400 | I23: -970 | J23: =H23-I23 -> 2370 | K23: =$I$15-I23 -> 60 | L23: 1 | M23: =$M$15-P23 -> 1446 | N23: -895 | O23: =M23-N23 -> 2341 | P23: =$N$15-N23 -> 44
A24: 45827 | B24: 1 | C24: =$C$15-F24 -> 1332 | D24: -1241 | E24: =C24-D24 -> 2573 | F24: =$D$15-D24 -> 48 | G24: 1 | H24: =$H$15-K24 -> 1390 | I24: -980 | J24: =H24-I24 -> 2370 | K24: =$I$15-I24 -> 70 | L24: 1 | M24: =$M$15-P24 -> 1441 | N24: -900 | O24: =M24-N24 -> 2341 | P24: =$N$15-N24 -> 49
A25: 45828 | B25: 1 | C25: =$C$15-F25 -> 1323 | D25: -1250 | E25: =C25-D25 -> 2573 | F25: =$D$15-D25 -> 57 | G25: 1 | H25: =$H$15-K25 -> 1380 | I25: -990 | J25: =H25-I25 -> 2370 | K25: =$I$15-I25 -> 80 | L25: 1 | M25: =$M$15-P25 -> 1436 | N25: -905 | O25: =M25-N25 -> 2341 | P25: =$N$15-N25 -> 54
A26: 45829 | B26: 1 | C26: =$C$15-F26 -> 1314 | D26: -1259 | E26: =C26-D26 -> 2573 | F26: =$D$15-D26 -> 66 | G26: 1 | H26: =$H$15-K26 -> 1350 | I26: -1020 | J26: =H26-I26 -> 2370 | K26: =$I$15-I26 -> 110 | L26: 1 | M26: =$M$15-P26 -> 1431 | N26: -910 | O26: =M26-N26 -> 2341 | P26: =$N$15-N26 -> 59
A27: 45830 | B27: 1 | C27: =$C$15-F27 -> 1283 | D27: -1290 | E27: =C27-D27 -> 2573 | F27: =$D$15-D27 -> 97 | G27: 1 | H27: =$H$15-K27 -> 1320 | I27: -1050 | J27: =H27-I27 -> 2370 | K27: =$I$15-I27 -> 140 | L27: 1 | M27: =$M$15-P27 -> 1416 | N27: -925 | O27: =M27-N27 -> 2341 | P27: =$N$15-N27 -> 74
... A61: 45864 | B61: 1 | C61: =$C$15-F61 -> 1125 | D61: -1448 | E61: =C61-D61 -> 2573 | F61: =$D$15-D61 -> 255 | G61: 1 | H61: =$H$15-K61 -> 1124 | I61: -1246 | J61: =H61-I61 -> 2370 | K61: =$I$15-I61 -> 336 | L61: 1 | M61: =$M$15-P61 -> 1284 | N61: -1057 | O61: =M61-N61 -> 2341 | P61: =$N$15-N61 -> 206
A62: 45865 | B62: 1 | C62: =$C$15-F62 -> 1120 | D62: -1453 | E62: =C62-D62 -> 2573 | F62: =$D$15-D62 -> 260 | G62: 1 | H62: 1075 | I62: -1251 | J62: =H62-I62 -> 2326 | K62: =$I$15-I62 -> 341 | L62: 1 | M62: =$M$15-P62 -> 1280 | N62: -1061 | O62: =M62-N62 -> 2341 | P62: =$N$15-N62 -> 210 | S62: =I62-I15 -> -341 | T62: =A62-A15 -> 47
A63: 45866 | B63: 1 | C63: =$C$15-F63 -> 1115 | D63: -1458 | E63: =C63-D63 -> 2573 | F63: =$D$15-D63 -> 265 | G63: 1 | H63: =$H$15-K63 -> 1094 | I63: -1276 | J63: =H63-I63 -> 2370 | K63: =$I$15-I63 -> 366 | L63: 1 | M63: =$M$15-P63 -> 1276 | N63: -1065 | O63: =M63-N63 -> 2341 | P63: =$N$15-N63 -> 214 | T63: =S62/T62 -> -7.2553191
A64: 45867 | B64: 1 | C64: =$C$15-F64 -> 1102 | D64: -1471 | E64: =C64-D64 -> 2573 | F64: =$D$15-D64 -> 278 | G64: 1 | H64: 1076 | I64: -1293 | J64: =H64-I64 -> 2369 | K64: =$I$15-I64 -> 383 | L64: 1 | M64: =$M$15-P64 -> 1272 | N64: -1069 | O64: =M64-N64 -> 2341 | P64: =$N$15-N64 -> 218
A65: 45868 | B65: 1 | C65: =$C$15-F65 -> 1088 | D65: -1485 | E65: =C65-D65 -> 2573 | F65: =$D$15-D65 -> 292 | G65: 1 | H65: =$H$15-K65 -> 1060 | I65: -1310 | J65: =H65-I65 -> 2370 | K65: =$I$15-I65 -> 400 | L65: 1 | M65: =$M$15-P65 -> 1268 | N65: -1073 | O65: =M65-N65 -> 2341 | P65: =$N$15-N65 -> 222
A66: 45869 | B66: 1 | C66: =$C$15-F66 -> 1074 | D66: -1499 | E66: =C66-D66 -> 2573 | F66: =$D$15-D66 -> 306 | G66: 1 | H66: 1077 | I66: -1327 | J66: =H66-I66 -> 2404 | K66: =$I$15-I66 -> 417 | L66: 1 | M66: =$M$15-P66 -> 1262 | N66: -1079 | O66: =M66-N66 -> 2341 | P66: =$N$15-N66 -> 228
A67: 45870 | B67: 1 | C67: =$C$15-F67 -> 1060 | D67: -1513 | E67: =C67-D67 -> 2573 | F67: =$D$15-D67 -> 320 | G67: 1 | H67: =$H$15-K67 -> 1026 | I67: -1344 | J67: =H67-I67 -> 2370 | K67: =$I$15-I67 -> 434 | L67: 1 | M67: =$M$15-P67 -> 1250 | N67: -1091 | O67: =M67-N67 -> 2341 | P67: =$N$15-N67 -> 240
A68: 45871 | B68: 1 | C68: =$C$15-F68 -> 1046 | D68: -1527 | E68: =C68-D68 -> 2573 | F68: =$D$15-D68 -> 334 | G68: 1 | H68: 1078 | I68: -1361 | J68: =H68-I68 -> 2439 | K68: =$I$15-I68 -> 451 | L68: 1 | M68: =$M$15-P68 -> 1232 | N68: -1109 | O68: =M68-N68 -> 2341 | P68: =$N$15-N68 -> 258
A69: 45872 | B69: 1 | C69: =$C$15-F69 -> 1032 | D69: -1541 | E69: =C69-D69 -> 2573 | F69: =$D$15-D69 -> 348 | G69: 1 | H69: =$H$15-K69 -> 992 | I69: -1378 | J69: =H69-I69 -> 2370 | K69: =$I$15-I69 -> 468 | L69: 1 | M69: =$M$15-P69 -> 1214 | N69: -1127 | O69: =M69-N69 -> 2341 | P69: =$N$15-N69 -> 276
A70: 45873 | B70: 1 | C70: =$C$15-F70 -> 1018 | D70: -1555 | E70: =C70-D70 -> 2573 | F70: =$D$15-D70 -> 362 | G70: 1 | H70: 1079 | I70: -1395 | J70: =H70-I70 -> 2474 | K70: =$I$15-I70 -> 485 | L70: 1 | M70: =$M$15-P70 -> 1196 | N70: -1145 | O70: =M70-N70 -> 2341 | P70: =$N$15-N70 -> 294
A71: 45874 | B71: 1 | C71: 1474 | D71: -1569 | E71: =C71-D71 -> 3043 | F71: =$D$15-D71 -> 376 | G71: 1 | H71: 1474 | I71: -1412 | J71: =H71-I71 -> 2886 | K71: =$I$15-I71 -> 502 | L71: 1 | M71: 1474 | N71: -1163 | O71: =M71-N71 -> 2637 | P71: =$N$15-N71 -> 312

Sheet QTL-KM117+300
A1: BẢNG SỐ LIỆU QUAN TRẮC THIẾT BỊ ĐO LÚN MẶT
A2: I. SỐ ĐỌC BAN ĐẦU
A3: Vùng (Đường) | B3: Bàn quan trắc lún | D3: Ngày lắp đặt | F3: =+"Cao trình nghiệm thu [m] ("&TEXT(A15,"dd/mm/yy")&")" -> Cao trình nghiệm thu [m] (10/06/25) | M3: Tọa độ | Q3: Mốc tọa độ tham chiếu
F4: Cao trình MĐTN | H4: Cao trình đắp | J4: Cao trình đỉnh ống | L4: Cao trình tấm đế | M4: X [m] | O4: Y [m]
A5: VÙNG 2A (ĐƯỜNG N1) | B5: SSP2-4 | Q5: CS3
B6: SSP2-5 | Q6: Tọa độ [m]
B7: SSP2-6
A9: II. SỐ LIỆU QUAN TRẮC
A10: Ngày quan trắc | B10: ĐỘ LÚN TRÁI | H10: ĐỘ LÚN TIM | M10: ĐỘ LÚN PHẢI | R10: Áp Đ.hồ Pvac | S10: Ghi chú
B11: Thời gian tích lũy | C11: Cao độ đắp | D11: Cao độ bàn đo lún | E11: Chiều cao đắp | F11: Độ lún | H11: Thời gian tích lũy | I11: Cao độ đắp | J11: Cao độ bàn đo lún | K11: Chiều cao đắp | L11: Độ lún | M11: Thời gian tích lũy | N11: Cao độ đắp | O11: Cao độ bàn đo lún | P11: Chiều cao đắp | Q11: Độ lún
B13: [Ngày] | C13: [mm] | D13: [m.m] | E13: [mm] | F13: [m.m] | H13: [Ngày] | I13: [mm] | J13: [m.m] | K13: [mm] | L13: [m.m] | M13: [Ngày] | N13: [mm] | O13: [m.m] | P13: [mm] | Q13: [m.m] | R13: [kPa]
A14: 1 | B14: =+A14+1 -> 2 | C14: =+B14+1 -> 3 | D14: =+C14+1 -> 4 | E14: =+D14+1 -> 5 | F14: =+E14+1 -> 6 | H14: =+F14+1 -> 7 | I14: =+H14+1 -> 8 | J14: =+I14+1 -> 9 | K14: =+J14+1 -> 10 | L14: =+K14+1 -> 11 | M14: =+L14+1 -> 12 | N14: =+M14+1 -> 13 | O14: =+N14+1 -> 14 | P14: =+O14+1 -> 15 | ... S14: =+R14+1 -> 18
A15: 45818 | B15: 1 | C15: 1585 | D15: -204 | E15: =C15-D15 -> 1789 | F15: 0 | H15: 1 | I15: 1460 | J15: -310 | K15: =I15-J15 -> 1770 | L15: 0 | M15: 1 | N15: 1510 | O15: -417 | P15: =N15-O15 -> 1927 | Q15: 0
A16: 45819 | B16: 1 | C16: =$C$15-F16 -> 1584 | D16: -205 | E16: =C16-D16 -> 1789 | F16: =$D$15-D16 -> 1 | H16: 1 | I16: =$I$15-L16 -> 1459 | J16: -311 | K16: =I16-J16 -> 1770 | L16: =$J$15-J16 -> 1 | M16: 1 | N16: =$N$15-Q16 -> 1509 | O16: -418 | P16: =N16-O16 -> 1927 | Q16: =$O$15-O16 -> 1
A17: 45820 | B17: 1 | C17: =$C$15-F17 -> 1583 | D17: -206 | E17: =C17-D17 -> 1789 | F17: =$D$15-D17 -> 2 | H17: 1 | I17: =$I$15-L17 -> 1458 | J17: -312 | K17: =I17-J17 -> 1770 | L17: =$J$15-J17 -> 2 | M17: 1 | N17: =$N$15-Q17 -> 1508 | O17: -419 | P17: =N17-O17 -> 1927 | Q17: =$O$15-O17 -> 2
A18: 45821 | B18: 1 | C18: =$C$15-F18 -> 1582 | D18: -207 | E18: =C18-D18 -> 1789 | F18: =$D$15-D18 -> 3 | H18: 1 | I18: =$I$15-L18 -> 1457 | J18: -313 | K18: =I18-J18 -> 1770 | L18: =$J$15-J18 -> 3 | M18: 1 | N18: =$N$15-Q18 -> 1507 | O18: -420 | P18: =N18-O18 -> 1927 | Q18: =$O$15-O18 -> 3
A19: 45822 | B19: 1 | C19: =$C$15-F19 -> 1581 | D19: -208 | E19: =C19-D19 -> 1789 | F19: =$D$15-D19 -> 4 | H19: 1 | I19: =$I$15-L19 -> 1445 | J19: -325 | K19: =I19-J19 -> 1770 | L19: =$J$15-J19 -> 15 | M19: 1 | N19: =$N$15-Q19 -> 1507 | O19: -420 | P19: =N19-O19 -> 1927 | Q19: =$O$15-O19 -> 3
A20: 45823 | B20: 1 | C20: =$C$15-F20 -> 1574 | D20: -215 | E20: =C20-D20 -> 1789 | F20: =$D$15-D20 -> 11 | H20: 1 | I20: =$I$15-L20 -> 1433 | J20: -337 | K20: =I20-J20 -> 1770 | L20: =$J$15-J20 -> 27 | M20: 1 | N20: =$N$15-Q20 -> 1505 | O20: -422 | P20: =N20-O20 -> 1927 | Q20: =$O$15-O20 -> 5
A21: 45824 | B21: 1 | C21: =$C$15-F21 -> 1567 | D21: -222 | E21: =C21-D21 -> 1789 | F21: =$D$15-D21 -> 18 | H21: 1 | I21: =$I$15-L21 -> 1421 | J21: -349 | K21: =I21-J21 -> 1770 | L21: =$J$15-J21 -> 39 | M21: 1 | N21: =$N$15-Q21 -> 1500 | O21: -427 | P21: =N21-O21 -> 1927 | Q21: =$O$15-O21 -> 10
A22: 45825 | B22: 1 | C22: =$C$15-F22 -> 1560 | D22: -229 | E22: =C22-D22 -> 1789 | F22: =$D$15-D22 -> 25 | H22: 1 | I22: =$I$15-L22 -> 1409 | J22: -361 | K22: =I22-J22 -> 1770 | L22: =$J$15-J22 -> 51 | M22: 1 | N22: =$N$15-Q22 -> 1495 | O22: -432 | P22: =N22-O22 -> 1927 | Q22: =$O$15-O22 -> 15
A23: 45826 | B23: 1 | C23: =$C$15-F23 -> 1553 | D23: -236 | E23: =C23-D23 -> 1789 | F23: =$D$15-D23 -> 32 | H23: 1 | I23: =$I$15-L23 -> 1397 | J23: -373 | K23: =I23-J23 -> 1770 | L23: =$J$15-J23 -> 63 | M23: 1 | N23: =$N$15-Q23 -> 1490 | O23: -437 | P23: =N23-O23 -> 1927 | Q23: =$O$15-O23 -> 20
A24: 45827 | B24: 1 | C24: =$C$15-F24 -> 1546 | D24: -243 | E24: =C24-D24 -> 1789 | F24: =$D$15-D24 -> 39 | H24: 1 | I24: =$I$15-L24 -> 1390 | J24: -380 | K24: =I24-J24 -> 1770 | L24: =$J$15-J24 -> 70 | M24: 1 | N24: =$N$15-Q24 -> 1485 | O24: -442 | P24: =N24-O24 -> 1927 | Q24: =$O$15-O24 -> 25
A25: 45828 | B25: 1 | C25: =$C$15-F25 -> 1539 | D25: -250 | E25: =C25-D25 -> 1789 | F25: =$D$15-D25 -> 46 | H25: 1 | I25: =$I$15-L25 -> 1385 | J25: -385 | K25: =I25-J25 -> 1770 | L25: =$J$15-J25 -> 75 | M25: 1 | N25: =$N$15-Q25 -> 1480 | O25: -447 | P25: =N25-O25 -> 1927 | Q25: =$O$15-O25 -> 30
A26: 45829 | B26: 1 | C26: =$C$15-F26 -> 1535 | D26: -254 | E26: =C26-D26 -> 1789 | F26: =$D$15-D26 -> 50 | H26: 1 | I26: =$I$15-L26 -> 1380 | J26: -390 | K26: =I26-J26 -> 1770 | L26: =$J$15-J26 -> 80 | M26: 1 | N26: =$N$15-Q26 -> 1475 | O26: -452 | P26: =N26-O26 -> 1927 | Q26: =$O$15-O26 -> 35
A27: 45830 | B27: 1 | C27: =$C$15-F27 -> 1519 | D27: -270 | E27: =C27-D27 -> 1789 | F27: =$D$15-D27 -> 66 | H27: 1 | I27: =$I$15-L27 -> 1355 | J27: -415 | K27: =I27-J27 -> 1770 | L27: =$J$15-J27 -> 105 | M27: 1 | N27: =$N$15-Q27 -> 1462 | O27: -465 | P27: =N27-O27 -> 1927 | Q27: =$O$15-O27 -> 48
... A56: 45859 | B56: 1 | C56: =$C$15-F56 -> 1419 | D56: -370 | E56: =C56-D56 -> 1789 | F56: =$D$15-D56 -> 166 | H56: 1 | I56: =$I$15-L56 -> 1206 | J56: -564 | K56: =I56-J56 -> 1770 | L56: =$J$15-J56 -> 254 | M56: 1 | N56: =$N$15-Q56 -> 1385 | O56: -542 | P56: =N56-O56 -> 1927 | Q56: =$O$15-O56 -> 125
A57: 45860 | B57: 1 | C57: =$C$15-F57 -> 1417 | D57: -372 | E57: =C57-D57 -> 1789 | F57: =$D$15-D57 -> 168 | G57: =F57-F56 -> 2 | H57: 1 | I57: =$I$15-L57 -> 1204 | J57: -566 | K57: =I57-J57 -> 1770 | L57: =$J$15-J57 -> 256 | M57: 1 | N57: =$N$15-Q57 -> 1382 | O57: -545 | P57: =N57-O57 -> 1927 | Q57: =$O$15-O57 -> 128
A58: 45861 | B58: 1 | C58: =$C$15-F58 -> 1413 | D58: -376 | E58: =C58-D58 -> 1789 | F58: =$D$15-D58 -> 172 | H58: 1 | I58: =$I$15-L58 -> 1202 | J58: -568 | K58: =I58-J58 -> 1770 | L58: =$J$15-J58 -> 258 | M58: 1 | N58: =$N$15-Q58 -> 1379 | O58: -548 | P58: =N58-O58 -> 1927 | Q58: =$O$15-O58 -> 131
A59: 45862 | B59: 1 | C59: =$C$15-F59 -> 1409 | D59: -380 | E59: =C59-D59 -> 1789 | F59: =$D$15-D59 -> 176 | H59: 1 | I59: =$I$15-L59 -> 1200 | J59: -570 | K59: =I59-J59 -> 1770 | L59: =$J$15-J59 -> 260 | M59: 1 | N59: =$N$15-Q59 -> 1376 | O59: -551 | P59: =N59-O59 -> 1927 | Q59: =$O$15-O59 -> 134
A60: 45863 | B60: 1 | C60: =$C$15-F60 -> 1405 | D60: -384 | E60: =C60-D60 -> 1789 | F60: =$D$15-D60 -> 180 | H60: 1 | I60: =$I$15-L60 -> 1198 | J60: -572 | K60: =I60-J60 -> 1770 | L60: =$J$15-J60 -> 262 | M60: 1 | N60: =$N$15-Q60 -> 1373 | O60: -554 | P60: =N60-O60 -> 1927 | Q60: =$O$15-O60 -> 137
A61: 45864 | B61: 1 | C61: =$C$15-F61 -> 1401 | D61: -388 | E61: =C61-D61 -> 1789 | F61: =$D$15-D61 -> 184 | H61: 1 | I61: =$I$15-L61 -> 1196 | J61: -574 | K61: =I61-J61 -> 1770 | L61: =$J$15-J61 -> 264 | M61: 1 | N61: =$N$15-Q61 -> 1370 | O61: -557 | P61: =N61-O61 -> 1927 | Q61: =$O$15-O61 -> 140
A62: 45865 | B62: 1 | C62: 1370 | D62: -392 | E62: =C62-D62 -> 1762 | F62: =$D$15-D62 -> 188 | H62: 1 | I62: 1200 | J62: -576 | K62: =I62-J62 -> 1776 | L62: =$J$15-J62 -> 266 | M62: 1 | N62: =$N$15-Q62 -> 1367 | O62: -560 | P62: =N62-O62 -> 1927 | Q62: =$O$15-O62 -> 143
A63: 45866 | B63: 1 | C63: =$C$15-F63 -> 1393 | D63: -396 | E63: =C63-D63 -> 1789 | F63: =$D$15-D63 -> 192 | H63: 1 | I63: =$I$15-L63 -> 1192 | J63: -578 | K63: =I63-J63 -> 1770 | L63: =$J$15-J63 -> 268 | M63: 1 | N63: =$N$15-Q63 -> 1364 | O63: -563 | P63: =N63-O63 -> 1927 | Q63: =$O$15-O63 -> 146
A64: 45867 | B64: 1 | C64: 1371 | D64: -412 | E64: =C64-D64 -> 1783 | F64: =$D$15-D64 -> 208 | H64: 1 | I64: 1201 | J64: -580 | K64: =I64-J64 -> 1781 | L64: =$J$15-J64 -> 270 | M64: 1 | N64: =$N$15-Q64 -> 1361 | O64: -566 | P64: =N64-O64 -> 1927 | Q64: =$O$15-O64 -> 149
A65: 45868 | B65: 1 | C65: =$C$15-F65 -> 1369 | D65: -420 | E65: =C65-D65 -> 1789 | F65: =$D$15-D65 -> 216 | H65: 1 | I65: =$I$15-L65 -> 1188 | J65: -582 | K65: =I65-J65 -> 1770 | L65: =$J$15-J65 -> 272 | M65: 1 | N65: =$N$15-Q65 -> 1339 | O65: -588 | P65: =N65-O65 -> 1927 | Q65: =$O$15-O65 -> 171
A66: 45869 | B66: 1 | C66: 1372 | D66: -428 | E66: =C66-D66 -> 1800 | F66: =$D$15-D66 -> 224 | H66: 1 | I66: 1202 | J66: -616 | K66: =I66-J66 -> 1818 | L66: =$J$15-J66 -> 306 | M66: 1 | N66: =$N$15-Q66 -> 1331 | O66: -596 | P66: =N66-O66 -> 1927 | Q66: =$O$15-O66 -> 179
A67: 45870 | B67: 1 | C67: =$C$15-F67 -> 1353 | D67: -436 | E67: =C67-D67 -> 1789 | F67: =$D$15-D67 -> 232 | H67: 1 | I67: =$I$15-L67 -> 1138 | J67: -632 | K67: =I67-J67 -> 1770 | L67: =$J$15-J67 -> 322 | M67: 1 | N67: =$N$15-Q67 -> 1323 | O67: -604 | P67: =N67-O67 -> 1927 | Q67: =$O$15-O67 -> 187
A68: 45871 | B68: 1 | C68: 1373 | D68: -444 | E68: =C68-D68 -> 1817 | F68: =$D$15-D68 -> 240 | H68: 1 | I68: 1203 | J68: -648 | K68: =I68-J68 -> 1851 | L68: =$J$15-J68 -> 338 | M68: 1 | N68: =$N$15-Q68 -> 1315 | O68: -612 | P68: =N68-O68 -> 1927 | Q68: =$O$15-O68 -> 195
A69: 45872 | B69: 1 | C69: =$C$15-F69 -> 1337 | D69: -452 | E69: =C69-D69 -> 1789 | F69: =$D$15-D69 -> 248 | H69: 1 | I69: =$I$15-L69 -> 1106 | J69: -664 | K69: =I69-J69 -> 1770 | L69: =$J$15-J69 -> 354 | M69: 1 | N69: =$N$15-Q69 -> 1307 | O69: -620 | P69: =N69-O69 -> 1927 | Q69: =$O$15-O69 -> 203
A70: 45873 | B70: 1 | C70: 1374 | D70: -460 | E70: =C70-D70 -> 1834 | F70: =$D$15-D70 -> 256 | H70: 1 | I70: 1204 | J70: -680 | K70: =I70-J70 -> 1884 | L70: =$J$15-J70 -> 370 | M70: 1 | N70: =$N$15-Q70 -> 1299 | O70: -628 | P70: =N70-O70 -> 1927 | Q70: =$O$15-O70 -> 211
...

Sheet QTL-KM117+400
A1: 341
A2: I. SỐ ĐỌC BAN ĐẦU
A3: Vùng (Đường) | B3: Bàn quan trắc lún | D3: Ngày lắp đặt | F3: =+"Cao trình nghiệm thu [m] ("&TEXT(A15,"dd/mm/yy")&")" -> Cao trình nghiệm thu [m] (10/06/25) | L3: Tọa độ | P3: Mốc tọa độ tham chiếu
F4: Cao trình MĐTN | G4: Cao trình đắp | I4: Cao trình đỉnh ống | K4: Cao trình tấm đế | L4: X [m] | N4: Y [m]
A5: VÙNG 2A (ĐƯỜNG N1) | B5: SSP2-4 | P5: CS3
B6: SSP2-5 | P6: Tọa độ [m]
B7: SSP2-6
A9: II. SỐ LIỆU QUAN TRẮC
A10: Ngày quan trắc | B10: ĐỘ LÚN TRÁI | G10: ĐỘ LÚN TIM | L10: ĐỘ LÚN PHẢI | Q10: Áp Đ.hồ Pvac | R10: Ghi chú
B11: Thời gian tích lũy | C11: Cao độ đắp | D11: Cao độ bàn đo lún | E11: Chiều cao đắp | F11: Độ lún | G11: Thời gian tích lũy | H11: Cao độ đắp | I11: Cao độ bàn đo lún | J11: Chiều cao đắp | K11: Độ lún | L11: Thời gian tích lũy | M11: Cao độ đắp | N11: Cao độ bàn đo lún | O11: Chiều cao đắp | P11: Độ lún
B13: [Ngày] | C13: [mm] | D13: [m.m] | E13: [mm] | F13: [m.m] | G13: [Ngày] | H13: [mm] | I13: [m.m] | J13: [mm] | K13: [m.m] | L13: [Ngày] | M13: [mm] | N13: [m.m] | O13: [mm] | P13: [m.m] | Q13: [kPa]
A14: 1 | B14: =+A14+1 -> 2 | C14: =+B14+1 -> 3 | D14: =+C14+1 -> 4 | E14: =+D14+1 -> 5 | F14: =+E14+1 -> 6 | G14: =+F14+1 -> 7 | H14: =+G14+1 -> 8 | I14: =+H14+1 -> 9 | ... R14: =+Q14+1 -> 18
A15: 45818 | B15: 1 | C15: 1585 | D15: -616 | E15: =C15-D15 -> 2201 | F15: 0 | G15: 1 | H15: 1460 | I15: -1165 | J15: =H15-I15 -> 2625 | K15: 0 | L15: 1 | M15: 1570 | N15: -909 | O15: =M15-N15 -> 2479 | P15: 0
A16: 45819 | B16: 1 | C16: =$C$15-F16 -> 1581 | D16: -620 | E16: =C16-D16 -> 2201 | F16: =$D$15-D16 -> 4 | G16: 1 | H16: =$H$15-K16 -> 1456 | I16: -1169 | J16: =H16-I16 -> 2625 | K16: =$I$15-I16 -> 4 | L16: 1 | M16: =$M$15-P16 -> 1567 | N16: -912 | O16: =M16-N16 -> 2479 | P16: =$N$15-N16 -> 3
A17: 45820 | B17: 1 | C17: =$C$15-F17 -> 1577 | D17: -624 | E17: =C17-D17 -> 2201 | F17: =$D$15-D17 -> 8 | G17: 1 | H17: =$H$15-K17 -> 1452 | I17: -1173 | J17: =H17-I17 -> 2625 | K17: =$I$15-I17 -> 8 | L17: 1 | M17: =$M$15-P17 -> 1564 | N17: -915 | O17: =M17-N17 -> 2479 | P17: =$N$15-N17 -> 6
A18: 45821 | B18: 1 | C18: =$C$15-F18 -> 1573 | D18: -628 | E18: =C18-D18 -> 2201 | F18: =$D$15-D18 -> 12 | G18: 1 | H18: =$H$15-K18 -> 1448 | I18: -1177 | J18: =H18-I18 -> 2625 | K18: =$I$15-I18 -> 12 | L18: 1 | M18: =$M$15-P18 -> 1561 | N18: -918 | O18: =M18-N18 -> 2479 | P18: =$N$15-N18 -> 9
A19: 45822 | B19: 1 | C19: =$C$15-F19 -> 1569 | D19: -632 | E19: =C19-D19 -> 2201 | F19: =$D$15-D19 -> 16 | G19: 1 | H19: =$H$15-K19 -> 1444 | I19: -1181 | J19: =H19-I19 -> 2625 | K19: =$I$15-I19 -> 16 | L19: 1 | M19: =$M$15-P19 -> 1558 | N19: -921 | O19: =M19-N19 -> 2479 | P19: =$N$15-N19 -> 12
A20: 45823 | B20: 1 | C20: =$C$15-F20 -> 1565 | D20: -636 | E20: =C20-D20 -> 2201 | F20: =$D$15-D20 -> 20 | G20: 1 | H20: =$H$15-K20 -> 1439 | I20: -1186 | J20: =H20-I20 -> 2625 | K20: =$I$15-I20 -> 21 | L20: 1 | M20: =$M$15-P20 -> 1555 | N20: -924 | O20: =M20-N20 -> 2479 | P20: =$N$15-N20 -> 15
A21: 45824 | B21: 1 | C21: =$C$15-F21 -> 1561 | D21: -640 | E21: =C21-D21 -> 2201 | F21: =$D$15-D21 -> 24 | G21: 1 | H21: =$H$15-K21 -> 1435 | I21: -1190 | J21: =H21-I21 -> 2625 | K21: =$I$15-I21 -> 25 | L21: 1 | M21: =$M$15-P21 -> 1539 | N21: -940 | O21: =M21-N21 -> 2479 | P21: =$N$15-N21 -> 31
A22: 45825 | B22: 1 | C22: =$C$15-F22 -> 1540 | D22: -661 | E22: =C22-D22 -> 2201 | F22: =$D$15-D22 -> 45 | G22: 1 | H22: =$H$15-K22 -> 1420 | I22: -1205 | J22: =H22-I22 -> 2625 | K22: =$I$15-I22 -> 40 | L22: 1 | M22: =$M$15-P22 -> 1523 | N22: -956 | O22: =M22-N22 -> 2479 | P22: =$N$15-N22 -> 47
A23: 45826 | B23: 1 | C23: =$C$15-F23 -> 1519 | D23: -682 | E23: =C23-D23 -> 2201 | F23: =$D$15-D23 -> 66 | G23: 1 | H23: =$H$15-K23 -> 1385 | I23: -1240 | J23: =H23-I23 -> 2625 | K23: =$I$15-I23 -> 75 | L23: 1 | M23: =$M$15-P23 -> 1507 | N23: -972 | O23: =M23-N23 -> 2479 | P23: =$N$15-N23 -> 63
A24: 45827 | B24: 1 | C24: =$C$15-F24 -> 1498 | D24: -703 | E24: =C24-D24 -> 2201 | F24: =$D$15-D24 -> 87 | G24: 1 | H24: =$H$15-K24 -> 1350 | I24: -1275 | J24: =H24-I24 -> 2625 | K24: =$I$15-I24 -> 110 | L24: 1 | M24: =$M$15-P24 -> 1491 | N24: -988 | O24: =M24-N24 -> 2479 | P24: =$N$15-N24 -> 79
A25: 45828 | B25: 1 | C25: =$C$15-F25 -> 1477 | D25: -724 | E25: =C25-D25 -> 2201 | F25: =$D$15-D25 -> 108 | G25: 1 | H25: =$H$15-K25 -> 1315 | I25: -1310 | J25: =H25-I25 -> 2625 | K25: =$I$15-I25 -> 145 | L25: 1 | M25: =$M$15-P25 -> 1489 | N25: -990 | O25: =M25-N25 -> 2479 | P25: =$N$15-N25 -> 81
A26: 45829 | B26: 1 | C26: =$C$15-F26 -> 1468 | D26: -733 | E26: =C26-D26 -> 2201 | F26: =$D$15-D26 -> 117 | G26: 1 | H26: =$H$15-K26 -> 1280 | I26: -1345 | J26: =H26-I26 -> 2625 | K26: =$I$15-I26 -> 180 | L26: 1 | M26: =$M$15-P26 -> 1474 | N26: -1005 | O26: =M26-N26 -> 2479 | P26: =$N$15-N26 -> 96
A27: 45830 | B27: 1 | C27: =$C$15-F27 -> 1451 | D27: -750 | E27: =C27-D27 -> 2201 | F27: =$D$15-D27 -> 134 | G27: 1 | H27: =$H$15-K27 -> 1260 | I27: -1365 | J27: =H27-I27 -> 2625 | K27: =$I$15-I27 -> 200 | L27: 1 | M27: =$M$15-P27 -> 1467 | N27: -1012 | O27: =M27-N27 -> 2479 | P27: =$N$15-N27 -> 103
... A61: 45864 | B61: 1 | C61: =$C$15-F61 -> 1364 | D61: -837 | E61: =C61-D61 -> 2201 | F61: =$D$15-D61 -> 221 | G61: 1 | H61: =$H$15-K61 -> 1125 | I61: -1500 | J61: =H61-I61 -> 2625 | K61: =$I$15-I61 -> 335 | L61: 1 | M61: =$M$15-P61 -> 1375 | N61: -1104 | O61: =M61-N61 -> 2479 | P61: =$N$15-N61 -> 195
A62: 45865 | B62: 1 | C62: 1200 | D62: -838 | E62: =C62-D62 -> 2038 | F62: =$D$15-D62 -> 222 | G62: 1 | H62: =$H$15-K62 -> 1119 | I62: -1506 | J62: =H62-I62 -> 2625 | K62: =$I$15-I62 -> 341 | L62: 1 | M62: =$M$15-P62 -> 1372 | N62: -1107 | O62: =M62-N62 -> 2479 | P62: =$N$15-N62 -> 198
A63: 45866 | B63: 1 | C63: =$C$15-F63 -> 1362 | D63: -839 | E63: =C63-D63 -> 2201 | F63: =$D$15-D63 -> 223 | G63: 1 | H63: =$H$15-K63 -> 1113 | I63: -1512 | J63: =H63-I63 -> 2625 | K63: =$I$15-I63 -> 347 | L63: 1 | M63: =$M$15-P63 -> 1369 | N63: -1110 | O63: =M63-N63 -> 2479 | P63: =$N$15-N63 -> 201
A64: 45867 | B64: 1 | C64: 1201 | D64: -840 | E64: =C64-D64 -> 2041 | F64: =$D$15-D64 -> 224 | G64: 1 | H64: =$H$15-K64 -> 1107 | I64: -1518 | J64: =H64-I64 -> 2625 | K64: =$I$15-I64 -> 353 | L64: 1 | M64: =$M$15-P64 -> 1366 | N64: -1113 | O64: =M64-N64 -> 2479 | P64: =$N$15-N64 -> 204
A65: 45868 | B65: 1 | C65: =$C$15-F65 -> 1360 | D65: -841 | E65: =C65-D65 -> 2201 | F65: =$D$15-D65 -> 225 | G65: 1 | H65: =$H$15-K65 -> 1101 | I65: -1524 | J65: =H65-I65 -> 2625 | K65: =$I$15-I65 -> 359 | L65: 1 | M65: =$M$15-P65 -> 1363 | N65: -1116 | O65: =M65-N65 -> 2479 | P65: =$N$15-N65 -> 207
A66: 45869 | B66: 1 | C66: 1202 | D66: -842 | E66: =C66-D66 -> 2044 | F66: =$D$15-D66 -> 226 | G66: 1 | H66: =$H$15-K66 -> 1095 | I66: -1530 | J66: =H66-I66 -> 2625 | K66: =$I$15-I66 -> 365 | L66: 1 | M66: =$M$15-P66 -> 1360 | N66: -1119 | O66: =M66-N66 -> 2479 | P66: =$N$15-N66 -> 210
A67: 45870 | B67: 1 | C67: =$C$15-F67 -> 1358 | D67: -843 | E67: =C67-D67 -> 2201 | F67: =$D$15-D67 -> 227 | G67: 1 | H67: =$H$15-K67 -> 1089 | I67: -1536 | J67: =H67-I67 -> 2625 | K67: =$I$15-I67 -> 371 | L67: 1 | M67: =$M$15-P67 -> 1357 | N67: -1122 | O67: =M67-N67 -> 2479 | P67: =$N$15-N67 -> 213
A68: 45871 | B68: 1 | C68: 1203 | D68: -844 | E68: =C68-D68 -> 2047 | F68: =$D$15-D68 -> 228 | G68: 1 | H68: =$H$15-K68 -> 1083 | I68: -1542 | J68: =H68-I68 -> 2625 | K68: =$I$15-I68 -> 377 | L68: 1 | M68: =$M$15-P68 -> 1354 | N68: -1125 | O68: =M68-N68 -> 2479 | P68: =$N$15-N68 -> 216
A69: 45872 | B69: 1 | C69: =$C$15-F69 -> 1356 | D69: -845 | E69: =C69-D69 -> 2201 | F69: =$D$15-D69 -> 229 | G69: 1 | H69: =$H$15-K69 -> 1077 | I69: -1548 | J69: =H69-I69 -> 2625 | K69: =$I$15-I69 -> 383 | L69: 1 | M69: =$M$15-P69 -> 1351 | N69: -1128 | O69: =M69-N69 -> 2479 | P69: =$N$15-N69 -> 219
A70: 45873 | B70: 1 | C70: =$C$15-F70 -> 1355 | D70: -846 | E70: =C70-D70 -> 2201 | F70: =$D$15-D70 -> 230 | G70: 1 | H70: =$H$15-K70 -> 1071 | I70: -1554 | J70: =H70-I70 -> 2625 | K70: =$I$15-I70 -> 389 | L70: 1 | M70: =$M$15-P70 -> 1348 | N70: -1131 | O70: =M70-N70 -> 2479 | P70: =$N$15-N70 -> 222
A71: 45874 | B71: 1 | C71: 1597 | D71: -847 | E71: =C71-D71 -> 2444 | F71: =$D$15-D71 -> 231 | G71: 1 | H71: 1597 | I71: -1591 | J71: =H71-I71 -> 3188 | K71: =$I$15-I71 -> 426 | L71: 1 | M71: 1597 | N71: -1163 | O71: =M71-N71 -> 2760 | P71: =$N$15-N71 -> 254

Sheet QTL-KM117+500
A1: BẢNG SỐ LIỆU QUAN TRẮC THIẾT BỊ ĐO LÚN MẶT
A2: I. SỐ ĐỌC BAN ĐẦU
A3: Vùng (Đường) | B3: Bàn quan trắc lún | D3: Ngày lắp đặt | F3: =+"Cao trình nghiệm thu [m] ("&TEXT(A15,"dd/mm/yy")&")" -> Cao trình nghiệm thu [m] (05/06/25) | L3: Tọa độ | P3: Mốc tọa độ tham chiếu
F4: Cao trình MĐTN | G4: Cao trình đắp | I4: Cao trình đỉnh ống | K4: Cao trình tấm đế | L4: X [m] | N4: Y [m]
A5: VÙNG 2A (ĐƯỜNG N1) | B5: SSP2-4 | P5: CS3
B6: SSP2-5 | P6: Tọa độ [m]
B7: SSP2-6
A9: II. SỐ LIỆU QUAN TRẮC
A10: Ngày quan trắc | B10: ĐỘ LÚN TRÁI | G10: ĐỘ LÚN TIM | L10: ĐỘ LÚN PHẢI | Q10: Áp Đ.hồ Pvac | R10: Ghi chú
B11: Thời gian tích lũy | C11: Cao độ đắp | D11: Cao độ bàn đo lún | E11: Chiều cao đắp | F11: Độ lún | G11: Thời gian tích lũy | H11: Cao độ đắp | I11: Cao độ bàn đo lún | J11: Chiều cao đắp | K11: Độ lún | L11: Thời gian tích lũy | M11: Cao độ đắp | N11: Cao độ bàn đo lún | O11: Chiều cao đắp | P11: Độ lún
B13: [Ngày] | C13: [mm] | D13: [m.m] | E13: [mm] | F13: [m.m] | G13: [Ngày] | H13: [mm] | I13: [m.m] | J13: [mm] | K13: [m.m] | L13: [Ngày] | M13: [mm] | N13: [m.m] | O13: [mm] | P13: [m.m] | Q13: [kPa]
A14: 1 | B14: =+A14+1 -> 2 | C14: =+B14+1 -> 3 | D14: =+C14+1 -> 4 | E14: =+D14+1 -> 5 | F14: =+E14+1 -> 6 | G14: =+F14+1 -> 7 | H14: =+G14+1 -> 8 | I14: =+H14+1 -> 9 | ... R14: =+Q14+1 -> 18
A15: 45813 | B15: 1 | C15: 1585 | D15: -818 | E15: =C15-D15 -> 2403 | F15: 0 | G15: 1 | H15: 1460 | I15: -527 | J15: =H15-I15 -> 1987 | K15: 0 | L15: 1 | M15: 1330 | N15: -535 | O15: =M15-N15 -> 1865 | P15: 0
A16: 45814 | B16: 1 | C16: =$C$15-F16 -> 1573 | D16: -830 | E16: =C16-D16 -> 2403 | F16: =$D$15-D16 -> 12 | G16: 1 | H16: =$H$15-K16 -> 1445 | I16: -542 | J16: =H16-I16 -> 1987 | K16: =$I$15-I16 -> 15 | L16: 1 | M16: =$M$15-P16 -> 1318 | N16: -547 | O16: =M16-N16 -> 1865 | P16: =$N$15-N16 -> 12
A17: 45815 | B17: 1 | C17: =$C$15-F17 -> 1561 | D17: -842 | E17: =C17-D17 -> 2403 | F17: =$D$15-D17 -> 24 | G17: 1 | H17: =$H$15-K17 -> 1430 | I17: -557 | J17: =H17-I17 -> 1987 | K17: =$I$15-I17 -> 30 | L17: 1 | M17: =$M$15-P17 -> 1306 | N17: -559 | O17: =M17-N17 -> 1865 | P17: =$N$15-N17 -> 24
A18: 45816 | B18: 1 | C18: =$C$15-F18 -> 1549 | D18: -854 | E18: =C18-D18 -> 2403 | F18: =$D$15-D18 -> 36 | G18: 1 | H18: =$H$15-K18 -> 1415 | I18: -572 | J18: =H18-I18 -> 1987 | K18: =$I$15-I18 -> 45 | L18: 1 | M18: =$M$15-P18 -> 1294 | N18: -571 | O18: =M18-N18 -> 1865 | P18: =$N$15-N18 -> 36
A19: 45817 | B19: 1 | C19: =$C$15-F19 -> 1537 | D19: -866 | E19: =C19-D19 -> 2403 | F19: =$D$15-D19 -> 48 | G19: 1 | H19: =$H$15-K19 -> 1400 | I19: -587 | J19: =H19-I19 -> 1987 | K19: =$I$15-I19 -> 60 | L19: 1 | M19: =$M$15-P19 -> 1282 | N19: -583 | O19: =M19-N19 -> 1865 | P19: =$N$15-N19 -> 48
A20: 45818 | B20: 1 | C20: =$C$15-F20 -> 1525 | D20: -878 | E20: =C20-D20 -> 2403 | F20: =$D$15-D20 -> 60 | G20: 1 | H20: =$H$15-K20 -> 1377 | I20: -610 | J20: =H20-I20 -> 1987 | K20: =$I$15-I20 -> 83 | L20: 1 | M20: =$M$15-P20 -> 1270 | N20: -595 | O20: =M20-N20 -> 1865 | P20: =$N$15-N20 -> 60
A21: 45819 | B21: 1 | C21: =$C$15-F21 -> 1513 | D21: -890 | E21: =C21-D21 -> 2403 | F21: =$D$15-D21 -> 72 | G21: 1 | H21: =$H$15-K21 -> 1354 | I21: -633 | J21: =H21-I21 -> 1987 | K21: =$I$15-I21 -> 106 | L21: 1 | M21: =$M$15-P21 -> 1263 | N21: -602 | O21: =M21-N21 -> 1865 | P21: =$N$15-N21 -> 67
A22: 45820 | B22: 1 | C22: =$C$15-F22 -> 1495 | D22: -908 | E22: =C22-D22 -> 2403 | F22: =$D$15-D22 -> 90 | G22: 1 | H22: =$H$15-K22 -> 1331 | I22: -656 | J22: =H22-I22 -> 1987 | K22: =$I$15-I22 -> 129 | L22: 1 | M22: =$M$15-P22 -> 1256 | N22: -609 | O22: =M22-N22 -> 1865 | P22: =$N$15-N22 -> 74
A23: 45821 | B23: 1 | C23: =$C$15-F23 -> 1487 | D23: -916 | E23: =C23-D23 -> 2403 | F23: =$D$15-D23 -> 98 | G23: 1 | H23: =$H$15-K23 -> 1317 | I23: -670 | J23: =H23-I23 -> 1987 | K23: =$I$15-I23 -> 143 | L23: 1 | M23: =$M$15-P23 -> 1249 | N23: -616 | O23: =M23-N23 -> 1865 | P23: =$N$15-N23 -> 81
A24: 45822 | B24: 1 | C24: =$C$15-F24 -> 1479 | D24: -924 | E24: =C24-D24 -> 2403 | F24: =$D$15-D24 -> 106 | G24: 1 | H24: =$H$15-K24 -> 1307 | I24: -680 | J24: =H24-I24 -> 1987 | K24: =$I$15-I24 -> 153 | L24: 1 | M24: =$M$15-P24 -> 1246 | N24: -619 | O24: =M24-N24 -> 1865 | P24: =$N$15-N24 -> 84
A25: 45823 | B25: 1 | C25: =$C$15-F25 -> 1471 | D25: -932 | E25: =C25-D25 -> 2403 | F25: =$D$15-D25 -> 114 | G25: 1 | H25: =$H$15-K25 -> 1297 | I25: -690 | J25: =H25-I25 -> 1987 | K25: =$I$15-I25 -> 163 | L25: 1 | M25: =$M$15-P25 -> 1241 | N25: -624 | O25: =M25-N25 -> 1865 | P25: =$N$15-N25 -> 89
A26: 45824 | B26: 1 | C26: =$C$15-F26 -> 1463 | D26: -940 | E26: =C26-D26 -> 2403 | F26: =$D$15-D26 -> 122 | G26: 1 | H26: =$H$15-K26 -> 1287 | I26: -700 | J26: =H26-I26 -> 1987 | K26: =$I$15-I26 -> 173 | L26: 1 | M26: =$M$15-P26 -> 1236 | N26: -629 | O26: =M26-N26 -> 1865 | P26: =$N$15-N26 -> 94
A27: 45825 | B27: 1 | C27: =$C$15-F27 -> 1455 | D27: -948 | E27: =C27-D27 -> 2403 | F27: =$D$15-D27 -> 130 | G27: 1 | H27: =$H$15-K27 -> 1277 | I27: -710 | J27: =H27-I27 -> 1987 | K27: =$I$15-I27 -> 183 | L27: 1 | M27: =$M$15-P27 -> 1231 | N27: -634 | O27: =M27-N27 -> 1865 | P27: =$N$15-N27 -> 99
... A66: 45864 | B66: 1 | C66: =$C$15-F66 -> 1295 | D66: -1108 | E66: =C66-D66 -> 2403 | F66: =$D$15-D66 -> 290 | G66: 1 | H66: =$H$15-K66 -> 1091 | I66: -896 | J66: =H66-I66 -> 1987 | K66: =$I$15-I66 -> 369 | L66: 1 | M66: =$M$15-P66 -> 1113 | N66: -752 | O66: =M66-N66 -> 1865 | P66: =$N$15-N66 -> 217
A67: 45865 | B67: 1 | C67: =$C$15-F67 -> 1293 | D67: -1110 | E67: =C67-D67 -> 2403 | F67: =$D$15-D67 -> 292 | G67: 1 | H67: =$H$15-K67 -> 1089 | I67: -898 | J67: =H67-I67 -> 1987 | K67: 371 | L67: 1 | M67: 1000 | N67: -754 | O67: =M67-N67 -> 1754 | P67: =$N$15-N67 -> 219
A68: 45866 | B68: 1 | C68: =$C$15-F68 -> 1291 | D68: -1112 | E68: =C68-D68 -> 2403 | F68: =$D$15-D68 -> 294 | G68: 1 | H68: =$H$15-K68 -> 1087 | I68: -900 | J68: =H68-I68 -> 1987 | K68: =$I$15-I68 -> 373 | L68: 1 | M68: =$M$15-P68 -> 1109 | N68: -756 | O68: =M68-N68 -> 1865 | P68: =$N$15-N68 -> 221
A69: 45867 | B69: 1 | C69: =$C$15-F69 -> 1289 | D69: -1114 | E69: =C69-D69 -> 2403 | F69: =$D$15-D69 -> 296 | G69: 1 | H69: =$H$15-K69 -> 1088 | I69: -902 | J69: =H69-I69 -> 1990 | K69: 372 | L69: 1 | M69: 1001 | N69: -758 | O69: =M69-N69 -> 1759 | P69: =$N$15-N69 -> 223
A70: 45868 | B70: 1 | C70: =$C$15-F70 -> 1287 | D70: -1116 | E70: =C70-D70 -> 2403 | F70: =$D$15-D70 -> 298 | G70: 1 | H70: =$H$15-K70 -> 1083 | I70: -904 | J70: =H70-I70 -> 1987 | K70: =$I$15-I70 -> 377 | L70: 1 | M70: =$M$15-P70 -> 1105 | N70: -760 | O70: =M70-N70 -> 1865 | P70: =$N$15-N70 -> 225
A71: 45869 | B71: 1 | C71: =$C$15-F71 -> 1285 | D71: -1118 | E71: =C71-D71 -> 2403 | F71: =$D$15-D71 -> 300 | G71: 1 | H71: =$H$15-K71 -> 1087 | I71: -906 | J71: =H71-I71 -> 1993 | K71: 373 | L71: 1 | M71: 1002 | N71: -762 | O71: =M71-N71 -> 1764 | P71: =$N$15-N71 -> 227
A72: 45870 | B72: 1 | C72: =$C$15-F72 -> 1283 | D72: -1120 | E72: =C72-D72 -> 2403 | F72: =$D$15-D72 -> 302 | G72: 1 | H72: =$H$15-K72 -> 1079 | I72: -908 | J72: =H72-I72 -> 1987 | K72: =$I$15-I72 -> 381 | L72: 1 | M72: =$M$15-P72 -> 1101 | N72: -764 | O72: =M72-N72 -> 1865 | P72: =$N$15-N72 -> 229
A73: 45871 | B73: 1 | C73: =$C$15-F73 -> 1281 | D73: -1122 | E73: =C73-D73 -> 2403 | F73: =$D$15-D73 -> 304 | G73: 1 | H73: =$H$15-K73 -> 1086 | I73: -910 | J73: =H73-I73 -> 1996 | K73: 374 | L73: 1 | M73: 1003 | N73: -766 | O73: =M73-N73 -> 1769 | P73: =$N$15-N73 -> 231
A74: 45872 | B74: 1 | C74: =$C$15-F74 -> 1279 | D74: -1124 | E74: =C74-D74 -> 2403 | F74: =$D$15-D74 -> 306 | G74: 1 | H74: =$H$15-K74 -> 1075 | I74: -912 | J74: =H74-I74 -> 1987 | K74: =$I$15-I74 -> 385 | L74: 1 | M74: =$M$15-P74 -> 1097 | N74: -768 | O74: =M74-N74 -> 1865 | P74: =$N$15-N74 -> 233
A75: 45873 | B75: 1 | C75: =$C$15-F75 -> 1277 | D75: -1126 | E75: =C75-D75 -> 2403 | F75: =$D$15-D75 -> 308 | G75: 1 | H75: =$H$15-K75 -> 1085 | I75: -914 | J75: =H75-I75 -> 1999 | K75: 375 | L75: 1 | M75: 1004 | N75: -770 | O75: =M75-N75 -> 1774 | P75: =$N$15-N75 -> 235
A76: 45874 | B76: 1 | C76: =$C$15-F76 -> 1227 | D76: -1176 | E76: =C76-D76 -> 2403 | F76: =$D$15-D76 -> 358 | G76: 1 | H76: =$H$15-K76 -> 1014 | I76: -973 | J76: =H76-I76 -> 1987 | K76: =$I$15-I76 -> 446 | L76: 1 | M76: =$M$15-P76 -> 1060 | N76: -805 | O76: =M76-N76 -> 1865 | P76: =$N$15-N76 -> 270

Sheet QTL-KM117+600
A1: BẢNG SỐ LIỆU QUAN TRẮC THIẾT BỊ ĐO LÚN MẶT
A2: I. SỐ ĐỌC BAN ĐẦU
A3: Vùng (Đường) | B3: Bàn quan trắc lún | D3: Ngày lắp đặt | F3: =+"Cao trình nghiệm thu [m] ("&TEXT(A15,"dd/mm/yy")&")" -> Cao trình nghiệm thu [m] (05/06/25) | L3: Tọa độ | P3: Mốc tọa độ tham chiếu
F4: Cao trình MĐTN | G4: Cao trình đắp | I4: Cao trình đỉnh ống | K4: Cao trình tấm đế | L4: X [m] | N4: Y [m]
A5: VÙNG 2A (ĐƯỜNG N1) | B5: SSP2-4 | P5: CS3
B6: SSP2-5 | P6: Tọa độ [m]
B7: SSP2-6
A9: II. SỐ LIỆU QUAN TRẮC
A10: Ngày quan trắc | B10: ĐỘ LÚN TRÁI | G10: ĐỘ LÚN TIM | L10: ĐỘ LÚN PHẢI | Q10: Áp Đ.hồ Pvac | R10: Ghi chú
B11: Thời gian tích lũy | C11: Cao độ đắp | D11: Cao độ bàn đo lún | E11: Chiều cao đắp | F11: Độ lún | G11: Thời gian tích lũy | H11: Cao độ đắp | I11: Cao độ bàn đo lún | J11: Chiều cao đắp | K11: Độ lún | L11: Thời gian tích lũy | M11: Cao độ đắp | N11: Cao độ bàn đo lún | O11: Chiều cao đắp | P11: Độ lún
B13: [Ngày] | C13: [mm] | D13: [m.m] | E13: [mm] | F13: [m.m] | G13: [Ngày] | H13: [mm] | I13: [m.m] | J13: [mm] | K13: [m.m] | L13: [Ngày] | M13: [mm] | N13: [m.m] | O13: [mm] | P13: [m.m] | Q13: [kPa]
A14: 1 | B14: =+A14+1 -> 2 | C14: =+B14+1 -> 3 | D14: =+C14+1 -> 4 | E14: =+D14+1 -> 5 | F14: =+E14+1 -> 6 | G14: =+F14+1 -> 7 | H14: =+G14+1 -> 8 | I14: =+H14+1 -> 9 | ... R14: =+Q14+1 -> 18
A15: 45813 | B15: 1 | C15: 1538 | D15: -649 | E15: =C15-D15 -> 2187 | F15: 0 | G15: 1 | H15: 1528 | I15: -609 | J15: =H15-I15 -> 2137 | K15: 0 | L15: 1 | M15: 1458 | N15: -625 | O15: =M15-N15 -> 2083 | P15: 0
A16: 45814 | B16: 1 | C16: =$C$15-F16 -> 1525 | D16: -662 | E16: =C16-D16 -> 2187 | F16: =$D$15-D16 -> 13 | G16: 1 | H16: =$H$15-K16 -> 1507 | I16: -630 | J16: =H16-I16 -> 2137 | K16: =$I$15-I16 -> 21 | L16: 1 | M16: =$M$15-P16 -> 1445 | N16: -638 | O16: =M16-N16 -> 2083 | P16: =$N$15-N16 -> 13
A17: 45815 | B17: 1 | C17: =$C$15-F17 -> 1512 | D17: -675 | E17: =C17-D17 -> 2187 | F17: =$D$15-D17 -> 26 | G17: 1 | H17: =$H$15-K17 -> 1486 | I17: -651 | J17: =H17-I17 -> 2137 | K17: =$I$15-I17 -> 42 | L17: 1 | M17: =$M$15-P17 -> 1432 | N17: -651 | O17: =M17-N17 -> 2083 | P17: =$N$15-N17 -> 26
A18: 45816 | B18: 1 | C18: =$C$15-F18 -> 1472 | D18: -715 | E18: =C18-D18 -> 2187 | F18: =$D$15-D18 -> 66 | G18: 1 | H18: =$H$15-K18 -> 1465 | I18: -672 | J18: =H18-I18 -> 2137 | K18: =$I$15-I18 -> 63 | L18: 1 | M18: =$M$15-P18 -> 1419 | N18: -664 | O18: =M18-N18 -> 2083 | P18: =$N$15-N18 -> 39
A19: 45817 | B19: 1 | C19: =$C$15-F19 -> 1452 | D19: -735 | E19: =C19-D19 -> 2187 | F19: =$D$15-D19 -> 86 | G19: 1 | H19: =$H$15-K19 -> 1432 | I19: -705 | J19: =H19-I19 -> 2137 | K19: =$I$15-I19 -> 96 | L19: 1 | M19: =$M$15-P19 -> 1406 | N19: -677 | O19: =M19-N19 -> 2083 | P19: =$N$15-N19 -> 52
A20: 45818 | B20: 1 | C20: =$C$15-F20 -> 1432 | D20: -755 | E20: =C20-D20 -> 2187 | F20: =$D$15-D20 -> 106 | G20: 1 | H20: =$H$15-K20 -> 1405 | I20: -732 | J20: =H20-I20 -> 2137 | K20: =$I$15-I20 -> 123 | L20: 1 | M20: =$M$15-P20 -> 1377 | N20: -706 | O20: =M20-N20 -> 2083 | P20: =$N$15-N20 -> 81
A21: 45819 | B21: 1 | C21: =$C$15-F21 -> 1412 | D21: -775 | E21: =C21-D21 -> 2187 | F21: =$D$15-D21 -> 126 | G21: 1 | H21: =$H$15-K21 -> 1378 | I21: -759 | J21: =H21-I21 -> 2137 | K21: =$I$15-I21 -> 150 | L21: 1 | M21: =$M$15-P21 -> 1368 | N21: -715 | O21: =M21-N21 -> 2083 | P21: =$N$15-N21 -> 90
A22: 45820 | B22: 1 | C22: =$C$15-F22 -> 1399 | D22: -788 | E22: =C22-D22 -> 2187 | F22: =$D$15-D22 -> 139 | G22: 1 | H22: =$H$15-K22 -> 1351 | I22: -786 | J22: =H22-I22 -> 2137 | K22: =$I$15-I22 -> 177 | L22: 1 | M22: =$M$15-P22 -> 1363 | N22: -720 | O22: =M22-N22 -> 2083 | P22: =$N$15-N22 -> 95
A23: 45821 | B23: 1 | C23: =$C$15-F23 -> 1395 | D23: -792 | E23: =C23-D23 -> 2187 | F23: =$D$15-D23 -> 143 | G23: 1 | H23: =$H$15-K23 -> 1324 | I23: -813 | J23: =H23-I23 -> 2137 | K23: =$I$15-I23 -> 204 | L23: 1 | M23: =$M$15-P23 -> 1358 | N23: -725 | O23: =M23-N23 -> 2083 | P23: =$N$15-N23 -> 100
A24: 45822 | B24: 1 | C24: =$C$15-F24 -> 1391 | D24: -796 | E24: =C24-D24 -> 2187 | F24: =$D$15-D24 -> 147 | G24: 1 | H24: =$H$15-K24 -> 1297 | I24: -840 | J24: =H24-I24 -> 2137 | K24: =$I$15-I24 -> 231 | L24: 1 | M24: =$M$15-P24 -> 1353 | N24: -730 | O24: =M24-N24 -> 2083 | P24: =$N$15-N24 -> 105
A25: 45823 | B25: 1 | C25: =$C$15-F25 -> 1387 | D25: -800 | E25: =C25-D25 -> 2187 | F25: =$D$15-D25 -> 151 | G25: 1 | H25: =$H$15-K25 -> 1270 | I25: -867 | J25: =H25-I25 -> 2137 | K25: =$I$15-I25 -> 258 | L25: 1 | M25: =$M$15-P25 -> 1348 | N25: -735 | O25: =M25-N25 -> 2083 | P25: =$N$15-N25 -> 110
A26: 45824 | B26: 1 | C26: =$C$15-F26 -> 1383 | D26: -804 | E26: =C26-D26 -> 2187 | F26: =$D$15-D26 -> 155 | G26: 1 | H26: =$H$15-K26 -> 1266 | I26: -871 | J26: =H26-I26 -> 2137 | K26: =$I$15-I26 -> 262 | L26: 1 | M26: =$M$15-P26 -> 1343 | N26: -740 | O26: =M26-N26 -> 2083 | P26: =$N$15-N26 -> 115
A27: 45825 | B27: 1 | C27: =$C$15-F27 -> 1379 | D27: -808 | E27: =C27-D27 -> 2187 | F27: =$D$15-D27 -> 159 | G27: 1 | H27: =$H$15-K27 -> 1260 | I27: -877 | J27: =H27-I27 -> 2137 | K27: =$I$15-I27 -> 268 | L27: 1 | M27: =$M$15-P27 -> 1343 | N27: -740 | O27: =M27-N27 -> 2083 | P27: =$N$15-N27 -> 115
... A76: 45874 | B76: 1 | C76: =$C$15-F76 -> 1169 | D76: -1018 | E76: =C76-D76 -> 2187 | F76: =$D$15-D76 -> 369 | G76: 1 | H76: =$H$15-K76 -> 1041 | I76: -1096 | J76: =H76-I76 -> 2137 | K76: =$I$15-I76 -> 487 | L76: 1 | M76: =$M$15-P76 -> 1157 | N76: -926 | O76: =M76-N76 -> 2083 | P76: =$N$15-N76 -> 301

Sheet QTL-KM117+700
A1: 3
A2: I. SỐ ĐỌC BAN ĐẦU
A3: Vùng (Đường) | B3: Bàn quan trắc lún | D3: Ngày lắp đặt | F3: =+"Cao trình nghiệm thu [m] ("&TEXT(A15,"dd/mm/yy")&")" -> Cao trình nghiệm thu [m] (05/06/25) | L3: Tọa độ | P3: Mốc tọa độ tham chiếu
F4: Cao trình MĐTN | G4: Cao trình đắp | I4: Cao trình đỉnh ống | K4: Cao trình tấm đế | L4: X [m] | N4: Y [m]
A5: VÙNG 2A (ĐƯỜNG N1) | B5: SSP2-4 | P5: CS3
B6: SSP2-5 | P6: Tọa độ [m]
B7: SSP2-6
A9: II. SỐ LIỆU QUAN TRẮC
A10: Ngày quan trắc | B10: ĐỘ LÚN TRÁI | G10: ĐỘ LÚN TIM | L10: ĐỘ LÚN PHẢI | Q10: Áp Đ.hồ Pvac | R10: Ghi chú
B11: Thời gian tích lũy | C11: Cao độ đắp | D11: Cao độ bàn đo lún | E11: Chiều cao đắp | F11: Độ lún | G11: Thời gian tích lũy | H11: Cao độ đắp | I11: Cao độ bàn đo lún | J11: Chiều cao đắp | K11: Độ lún | L11: Thời gian tích lũy | M11: Cao độ đắp | N11: Cao độ bàn đo lún | O11: Chiều cao đắp | P11: Độ lún
B13: [Ngày] | C13: [mm] | D13: [m.m] | E13: [mm] | F13: [m.m] | G13: [Ngày] | H13: [mm] | I13: [m.m] | J13: [mm] | K13: [m.m] | L13: [Ngày] | M13: [mm] | N13: [m.m] | O13: [mm] | P13: [m.m] | Q13: [kPa]
A14: 1 | B14: =+A14+1 -> 2 | C14: =+B14+1 -> 3 | D14: =+C14+1 -> 4 | E14: =+D14+1 -> 5 | F14: =+E14+1 -> 6 | G14: =+F14+1 -> 7 | H14: =+G14+1 -> 8 | I14: =+H14+1 -> 9 | ... R14: =+Q14+1 -> 18
A15: 45813 | B15: 1 | C15: 1503 | D15: -1793 | E15: =C15-D15 -> 3296 | F15: 0 | G15: 1 | H15: 1463 | I15: -1297 | J15: =H15-I15 -> 2760 | K15: 0 | L15: 1 | M15: 1552 | N15: -1352 | O15: =M15-N15 -> 2904 | P15: 0
A16: 45814 | B16: 1 | C16: =$C$15-F16 -> 1491 | D16: -1805 | E16: =C16-D16 -> 3296 | F16: =$D$15-D16 -> 12 | G16: 1 | H16: =$H$15-K16 -> 1447 | I16: -1313 | J16: =H16-I16 -> 2760 | K16: =$I$15-I16 -> 16 | L16: 1 | M16: =$M$15-P16 -> 1540 | N16: -1364 | O16: =M16-N16 -> 2904 | P16: =$N$15-N16 -> 12
A17: 45815 | B17: 1 | C17: =$C$15-F17 -> 1479 | D17: -1817 | E17: =C17-D17 -> 3296 | F17: =$D$15-D17 -> 24 | G17: 1 | H17: =$H$15-K17 -> 1431 | I17: -1329 | J17: =H17-I17 -> 2760 | K17: =$I$15-I17 -> 32 | L17: 1 | M17: =$M$15-P17 -> 1528 | N17: -1376 | O17: =M17-N17 -> 2904 | P17: =$N$15-N17 -> 24
A18: 45816 | B18: 1 | C18: =$C$15-F18 -> 1467 | D18: -1829 | E18: =C18-D18 -> 3296 | F18: =$D$15-D18 -> 36 | G18: 1 | H18: =$H$15-K18 -> 1415 | I18: -1345 | J18: =H18-I18 -> 2760 | K18: =$I$15-I18 -> 48 | L18: 1 | M18: =$M$15-P18 -> 1516 | N18: -1388 | O18: =M18-N18 -> 2904 | P18: =$N$15-N18 -> 36
A19: 45817 | B19: 1 | C19: =$C$15-F19 -> 1455 | D19: -1841 | E19: =C19-D19 -> 3296 | F19: =$D$15-D19 -> 48 | G19: 1 | H19: =$H$15-K19 -> 1415 | I19: -1345 | J19: =H19-I19 -> 2760 | K19: =$I$15-I19 -> 48 | L19: 1 | M19: =$M$15-P19 -> 1504 | N19: -1400 | O19: =M19-N19 -> 2904 | P19: =$N$15-N19 -> 48
A20: 45818 | B20: 1 | C20: =$C$15-F20 -> 1450 | D20: -1846 | E20: =C20-D20 -> 3296 | F20: =$D$15-D20 -> 53 | G20: 1 | H20: =$H$15-K20 -> 1382 | I20: -1378 | J20: =H20-I20 -> 2760 | K20: =$I$15-I20 -> 81 | L20: 1 | M20: =$M$15-P20 -> 1492 | N20: -1412 | O20: =M20-N20 -> 2904 | P20: =$N$15-N20 -> 60
A21: 45819 | B21: 1 | C21: =$C$15-F21 -> 1419 | D21: -1877 | E21: =C21-D21 -> 3296 | F21: =$D$15-D21 -> 84 | G21: 1 | H21: =$H$15-K21 -> 1349 | I21: -1411 | J21: =H21-I21 -> 2760 | K21: =$I$15-I21 -> 114 | L21: 1 | M21: =$M$15-P21 -> 1469 | N21: -1435 | O21: =M21-N21 -> 2904 | P21: =$N$15-N21 -> 83
A22: 45820 | B22: 1 | C22: =$C$15-F22 -> 1395 | D22: -1901 | E22: =C22-D22 -> 3296 | F22: =$D$15-D22 -> 108 | G22: 1 | H22: =$H$15-K22 -> 1316 | I22: -1444 | J22: =H22-I22 -> 2760 | K22: =$I$15-I22 -> 147 | L22: 1 | M22: =$M$15-P22 -> 1465 | N22: -1439 | O22: =M22-N22 -> 2904 | P22: =$N$15-N22 -> 87
A23: 45821 | B23: 1 | C23: =$C$15-F23 -> 1387 | D23: -1909 | E23: =C23-D23 -> 3296 | F23: =$D$15-D23 -> 116 | G23: 1 | H23: =$H$15-K23 -> 1283 | I23: -1477 | J23: =H23-I23 -> 2760 | K23: =$I$15-I23 -> 180 | L23: 1 | M23: =$M$15-P23 -> 1461 | N23: -1443 | O23: =M23-N23 -> 2904 | P23: =$N$15-N23 -> 91
A24: 45822 | B24: 1 | C24: =$C$15-F24 -> 1379 | D24: -1917 | E24: =C24-D24 -> 3296 | F24: =$D$15-D24 -> 124 | G24: 1 | H24: =$H$15-K24 -> 1273 | I24: -1487 | J24: =H24-I24 -> 2760 | K24: =$I$15-I24 -> 190 | L24: 1 | M24: =$M$15-P24 -> 1457 | N24: -1447 | O24: =M24-N24 -> 2904 | P24: =$N$15-N24 -> 95
A25: 45823 | B25: 1 | C25: =$C$15-F25 -> 1371 | D25: -1925 | E25: =C25-D25 -> 3296 | F25: =$D$15-D25 -> 132 | G25: 1 | H25: =$H$15-K25 -> 1268 | I25: -1492 | J25: =H25-I25 -> 2760 | K25: =$I$15-I25 -> 195 | L25: 1 | M25: =$M$15-P25 -> 1452 | N25: -1452 | O25: =M25-N25 -> 2904 | P25: =$N$15-N25 -> 100
A26: 45824 | B26: 1 | C26: =$C$15-F26 -> 1363 | D26: -1933 | E26: =C26-D26 -> 3296 | F26: =$D$15-D26 -> 140 | G26: 1 | H26: =$H$15-K26 -> 1263 | I26: -1497 | J26: =H26-I26 -> 2760 | K26: =$I$15-I26 -> 200 | L26: 1 | M26: =$M$15-P26 -> 1447 | N26: -1457 | O26: =M26-N26 -> 2904 | P26: =$N$15-N26 -> 105
A27: 45825 | B27: 1 | C27: =$C$15-F27 -> 1355 | D27: -1941 | E27: =C27-D27 -> 3296 | F27: =$D$15-D27 -> 148 | G27: 1 | H27: =$H$15-K27 -> 1258 | I27: -1502 | J27: =H27-I27 -> 2760 | K27: =$I$15-I27 -> 205 | L27: 1 | M27: =$M$15-P27 -> 1442 | N27: -1462 | O27: =M27-N27 -> 2904 | P27: =$N$15-N27 -> 110
... A76: 45874 | B76: 1 | C76: =$C$15-F76 -> 1132 | D76: -2164 | E76: =C76-D76 -> 3296 | F76: =$D$15-D76 -> 371 | G76: 1 | H76: =$H$15-K76 -> 999 | I76: -1761 | J76: =H76-I76 -> 2760 | K76: =$I$15-I76 -> 464 | L76: 1 | M76: =$M$15-P76 -> 1216 | N76: -1688 | O76: =M76-N76 -> 2904 | P76: =$N$15-N76 -> 336

Sheet QTL-KM117+800
A1: DỰ ÁN THÀNH PHẦN ĐOẠN HẬU GIANG - CÀ MAU
A2: THUỘC DỰ ÁN XÂY DỰNG CÔNG TRÌNH ĐƯỜNG BỘ CAO TỐC BẮC - NAM PHÍA ĐÔNG GIAI ĐOẠN 2021 - 2025
A3: =UPPER("GÓI THẦU XL03 :Thi Công Xây Dựng Đoạn Tuyến Km114+200 - Km126+223 Bao Gồm Tuyến Nối Nút Giao IC12 Với QL1 (bao gồm khảo sát, thiết kế BVTC)") -> GÓI THẦU XL03 :THI CÔNG XÂY DỰNG ĐOẠN TUYẾN KM114+200 - KM126+223 BAO GỒM TUYẾN NỐI NÚT GIAO IC12 VỚI QL1 (BAO GỒM KHẢO SÁT, THIẾT KẾ BVTC)
A4: CHỦ ĐẦU TƯ | N4: NHÀ THẦU
A5: BAN QUẢN LÝ DỰ ÁN MỸ THUẬN | N5: LIÊN DANH CC1 - HẢI ĐĂNG - VẠN CƯỜNG - 492 - BẮC TRUNG NAM
A7: BẢNG SỐ LIỆU QUAN TRẮC THIẾT BỊ ĐO LÚN MẶT
A8: I. SỐ ĐỌC BAN ĐẦU
A9: Vùng (Đường) | B9: Bàn quan trắc lún | D9: Ngày lắp đặt | F9: =+"Cao trình nghiệm thu [m] ("&TEXT(A21,"dd/mm/yy")&")" -> Cao trình nghiệm thu [m] (20/05/25) | M9: Tọa độ | Q9: Mốc tọa độ tham chiếu
F10: Cao trình MĐTN | G10: Cao trình đắp | I10: Cao trình đỉnh ống | L10: Cao trình tấm đế | M10: X [m] | O10: Y [m]
A11: VÙNG 2A (ĐƯỜNG N1) | B11: SSP2-4 | Q11: CS3
B12: SSP2-5 | Q12: Tọa độ [m]
B13: SSP2-6
A15: II. SỐ LIỆU QUAN TRẮC
A16: Ngày quan trắc | B16: ĐỘ LÚN TRÁI | G16: ĐỘ LÚN TIM | M16: ĐỘ LÚN PHẢI | R16: Áp Đ.hồ Pvac | S16: Ghi chú
B17: Thời gian tích lũy | C17: Cao độ đắp | D17: Cao độ bàn đo lún | E17: Chiều cao đắp | F17: Độ lún | G17: Thời gian tích lũy | H17: Cao độ đắp | I17: Cao độ bàn đo lún | K17: Chiều cao đắp | L17: Độ lún | M17: Thời gian tích lũy | N17: Cao độ đắp | O17: Cao độ bàn đo lún | P17: Chiều cao đắp | Q17: Độ lún
B19: [Ngày] | C19: [mm] | D19: [m.m] | E19: [mm] | F19: [m.m] | G19: [Ngày] | H19: [mm] | I19: [m.m] | K19: [mm] | L19: [m.m] | M19: [Ngày] | N19: [mm] | O19: [m.m] | P19: [mm] | Q19: [m.m] | R19: [kPa]
A20: 1 | B20: =+A20+1 -> 2 | C20: =+B20+1 -> 3 | D20: =+C20+1 -> 4 | E20: =+D20+1 -> 5 | F20: =+E20+1 -> 6 | G20: =+F20+1 -> 7 | H20: =+G20+1 -> 8 | I20: =+H20+1 -> 9 | K20: =+I20+1 -> 10 | L20: =+K20+1 -> 11 | M20: =+L20+1 -> 12 | N20: =+M20+1 -> 13 | O20: =+N20+1 -> 14 | P20: =+O20+1 -> 15 | Q20: =+P20+1 -> 16 | R20: =+Q20+1 -> 17 | S20: =+R20+1 -> 18
A21: 45797 | B21: 1 | C21: 1507 | D21: -413 | E21: =C21-D21 -> 1920 | F21: 0 | G21: 1 | H21: 1492 | I21: -683 | K21: =H21-I21 -> 2175 | L21: 0 | M21: 1 | N21: 1447 | O21: -390 | P21: =N21-O21 -> 1837 | Q21: 0
A22: 45798 | B22: 2 | C22: =$C$21-F22 -> 1502 | D22: -418 | E22: =C22-D22 -> 1920 | F22: =$D$21-D22 -> 5 | G22: =G21+1 -> 2 | H22: =$H$21-L22 -> 1487 | I22: -688 | K22: =H22-I22 -> 2175 | L22: =$I$21-I22 -> 5 | M22: =M21+1 -> 2 | N22: =$N$21-Q22 -> 1447 | O22: -390 | P22: =N22-O22 -> 1837 | Q22: =$O$21-O22 -> 0
A23: 45799 | B23: 3 | C23: =$C$21-F23 -> 1502 | D23: -418 | E23: =C23-D23 -> 1920 | F23: =$D$21-D23 -> 5 | G23: =G22+1 -> 3 | H23: =$H$21-L23 -> 1487 | I23: -688 | K23: =H23-I23 -> 2175 | L23: =$I$21-I23 -> 5 | M23: =M22+1 -> 3 | N23: =$N$21-Q23 -> 1447 | O23: -390 | P23: =N23-O23 -> 1837 | Q23: =$O$21-O23 -> 0
A24: 45800 | B24: 4 | C24: =$C$21-F24 -> 1502 | D24: -418 | E24: =C24-D24 -> 1920 | F24: =$D$21-D24 -> 5 | G24: =G23+1 -> 4 | H24: =$H$21-L24 -> 1487 | I24: -688 | K24: =H24-I24 -> 2175 | L24: =$I$21-I24 -> 5 | M24: =M23+1 -> 4 | N24: =$N$21-Q24 -> 1447 | O24: -390 | P24: =N24-O24 -> 1837 | Q24: =$O$21-O24 -> 0
A25: 45801 | B25: 4 | C25: =$C$21-F25 -> 1502 | D25: -418 | E25: =C25-D25 -> 1920 | F25: =$D$21-D25 -> 5 | G25: =G24+1 -> 5 | H25: =$H$21-L25 -> 1487 | I25: -688 | K25: =H25-I25 -> 2175 | L25: =$I$21-I25 -> 5 | M25: =M24+1 -> 5 | N25: =$N$21-Q25 -> 1447 | O25: -390 | P25: =N25-O25 -> 1837 | Q25: =$O$21-O25 -> 0
A26: 45802 | B26: 4 | C26: =$C$21-F26 -> 1502 | D26: -418 | E26: =C26-D26 -> 1920 | F26: =$D$21-D26 -> 5 | G26: =G25+1 -> 6 | H26: =$H$21-L26 -> 1487 | I26: -688 | K26: =H26-I26 -> 2175 | L26: =$I$21-I26 -> 5 | M26: =M25+1 -> 6 | N26: =$N$21-Q26 -> 1447 | O26: -390 | P26: =N26-O26 -> 1837 | Q26: =$O$21-O26 -> 0
A27: 45803 | B27: 4 | C27: =$C$21-F27 -> 1502 | D27: -418 | E27: =C27-D27 -> 1920 | F27: =$D$21-D27 -> 5 | G27: =G26+1 -> 7 | H27: =$H$21-L27 -> 1487 | I27: -688 | K27: =H27-I27 -> 2175 | L27: =$I$21-I27 -> 5 | M27: =M26+1 -> 7 | N27: =$N$21-Q27 -> 1447 | O27: -390 | P27: =N27-O27 -> 1837 | Q27: =$O$21-O27 -> 0
A28: 45804 | B28: 4 | C28: =$C$21-F28 -> 1502 | D28: -418 | E28: =C28-D28 -> 1920 | F28: =$D$21-D28 -> 5 | G28: =G27+1 -> 8 | H28: =$H$21-L28 -> 1487 | I28: -688 | K28: =H28-I28 -> 2175 | L28: =$I$21-I28 -> 5 | M28: =M27+1 -> 8 | N28: =$N$21-Q28 -> 1447 | O28: -390 | P28: =N28-O28 -> 1837 | Q28: =$O$21-O28 -> 0
A29: 45805 | B29: 4 | C29: =$C$21-F29 -> 1502 | D29: -418 | E29: =C29-D29 -> 1920 | F29: =$D$21-D29 -> 5 | G29: =G28+1 -> 9 | H29: =$H$21-L29 -> 1487 | I29: -688 | K29: =H29-I29 -> 2175 | L29: =$I$21-I29 -> 5 | M29: =M28+1 -> 9 | N29: =$N$21-Q29 -> 1447 | O29: -390 | P29: =N29-O29 -> 1837 | Q29: =$O$21-O29 -> 0
A30: 45806 | B30: 4 | C30: =$C$21-F30 -> 1502 | D30: -418 | E30: =C30-D30 -> 1920 | F30: =$D$21-D30 -> 5 | G30: =G29+1 -> 10 | H30: =$H$21-L30 -> 1487 | I30: -688 | K30: =H30-I30 -> 2175 | L30: =$I$21-I30 -> 5 | M30: =M29+1 -> 10 | N30: =$N$21-Q30 -> 1447 | O30: -390 | P30: =N30-O30 -> 1837 | Q30: =$O$21-O30 -> 0
A31: 45807 | B31: 4 | C31: =$C$21-F31 -> 1502 | D31: -418 | E31: =C31-D31 -> 1920 | F31: =$D$21-D31 -> 5 | G31: =G30+1 -> 11 | H31: =$H$21-L31 -> 1487 | I31: -688 | K31: =H31-I31 -> 2175 | L31: =$I$21-I31 -> 5 | M31: =M30+1 -> 11 | N31: =$N$21-Q31 -> 1447 | O31: -390 | P31: =N31-O31 -> 1837 | Q31: =$O$21-O31 -> 0
A32: 45808 | B32: 4 | C32: =$C$21-F32 -> 1502 | D32: -418 | E32: =C32-D32 -> 1920 | F32: =$D$21-D32 -> 5 | G32: =G31+1 -> 12 | H32: =$H$21-L32 -> 1487 | I32: -688 | K32: =H32-I32 -> 2175 | L32: =$I$21-I32 -> 5 | M32: =M31+1 -> 12 | N32: =$N$21-Q32 -> 1447 | O32: -390 | P32: =N32-O32 -> 1837 | Q32: =$O$21-O32 -> 0
A33: 45809 | B33: 4 | C33: =$C$21-F33 -> 1502 | D33: -418 | E33: =C33-D33 -> 1920 | F33: =$D$21-D33 -> 5 | G33: =G32+1 -> 13 | H33: =$H$21-L33 -> 1473 | I33: -702 | K33: =H33-I33 -> 2175 | L33: =$I$21-I33 -> 19 | M33: =M32+1 -> 13 | N33: =$N$21-Q33 -> 1447 | O33: -390 | P33: =N33-O33 -> 1837 | Q33: =$O$21-O33 -> 0
... A52: 45828 | B52: 4 | C52: =$C$21-F52 -> 1360 | D52: -560 | E52: =C52-D52 -> 1920 | F52: =$D$21-D52 -> 147 | G52: =G51+1 -> 32 | H52: =$H$21-L52 -> 1175 | I52: -1000 | K52: =H52-I52 -> 2175 | L52: =$I$21-I52 -> 317 | M52: =M51+1 -> 32 | N52: =$N$21-Q52 -> 1364 | O52: -473 | P52: =N52-O52 -> 1837 | Q52: =$O$21-O52 -> 83
A53: 45829 | B53: 4 | C53: =$C$21-F53 -> 1350 | D53: -570 | E53: =C53-D53 -> 1920 | F53: =$D$21-D53 -> 157 | G53: =G52+1 -> 33 | H53: =$H$21-L53 -> 1167 | I53: -1008 | J53: =I53-I52 -> -8 | K53: =H53-I53 -> 2175 | L53: =$I$21-I53 -> 325 | M53: =M52+1 -> 33 | N53: =$N$21-Q53 -> 1353 | O53: -484 | P53: =N53-O53 -> 1837 | Q53: =$O$21-O53 -> 94
A54: 45830 | B54: 4 | C54: =$C$21-F54 -> 1340 | D54: -580 | E54: =C54-D54 -> 1920 | F54: =$D$21-D54 -> 167 | G54: =G53+1 -> 34 | H54: =$H$21-L54 -> 1159 | I54: -1016 | J54: =I54-I53 -> -8 | K54: =H54-I54 -> 2175 | L54: =$I$21-I54 -> 333 | M54: =M53+1 -> 34 | N54: =$N$21-Q54 -> 1342 | O54: -495 | P54: =N54-O54 -> 1837 | Q54: =$O$21-O54 -> 105
A55: 45831 | B55: 4 | C55: =$C$21-F55 -> 1330 | D55: -590 | E55: =C55-D55 -> 1920 | F55: =$D$21-D55 -> 177 | G55: =G54+1 -> 35 | H55: =$H$21-L55 -> 1151 | I55: -1024 | J55: =I55-I54 -> -8 | K55: =H55-I55 -> 2175 | L55: =$I$21-I55 -> 341 | M55: =M54+1 -> 35 | N55: =$N$21-Q55 -> 1331 | O55: -506 | P55: =N55-O55 -> 1837 | Q55: =$O$21-O55 -> 116
A56: 45832 | B56: 4 | C56: =$C$21-F56 -> 1320 | D56: -600 | E56: =C56-D56 -> 1920 | F56: =$D$21-D56 -> 187 | G56: =G55+1 -> 36 | H56: =$H$21-L56 -> 1143 | I56: -1032 | J56: =I56-I55 -> -8 | K56: =H56-I56 -> 2175 | L56: =$I$21-I56 -> 349 | M56: =M55+1 -> 36 | N56: =$N$21-Q56 -> 1320 | O56: -517 | P56: =N56-O56 -> 1837 | Q56: =$O$21-O56 -> 127
A57: 45833 | B57: 4 | C57: =$C$21-F57 -> 1310 | D57: -610 | E57: =C57-D57 -> 1920 | F57: =$D$21-D57 -> 197 | G57: =G56+1 -> 37 | H57: =$H$21-L57 -> 1135 | I57: -1040 | J57: =I57-I56 -> -8 | K57: =H57-I57 -> 2175 | L57: =$I$21-I57 -> 357 | M57: =M56+1 -> 37 | N57: =$N$21-Q57 -> 1309 | O57: -528 | P57: =N57-O57 -> 1837 | Q57: =$O$21-O57 -> 138
A58: 45834 | B58: 4 | C58: =$C$21-F58 -> 1300 | D58: -620 | E58: =C58-D58 -> 1920 | F58: =$D$21-D58 -> 207 | G58: =G57+1 -> 38 | H58: =$H$21-L58 -> 1114 | I58: -1061 | J58: =I58-I57 -> -21 | K58: =H58-I58 -> 2175 | L58: =$I$21-I58 -> 378 | M58: =M57+1 -> 38 | N58: =$N$21-Q58 -> 1298 | O58: -539 | P58: =N58-O58 -> 1837 | Q58: =$O$21-O58 -> 149
A59: 45835 | B59: 4 | C59: =$C$21-F59 -> 1295 | D59: -625 | E59: =C59-D59 -> 1920 | F59: =$D$21-D59 -> 212 | G59: =G58+1 -> 39 | H59: =$H$21-L59 -> 1113 | I59: -1062 | J59: =I59-I58 -> -1 | K59: =H59-I59 -> 2175 | L59: =$I$21-I59 -> 379 | M59: =M58+1 -> 39 | N59: =$N$21-Q59 -> 1293 | O59: -544 | P59: =N59-O59 -> 1837 | Q59: =$O$21-O59 -> 154
A60: 45836 | B60: 4 | C60: =$C$21-F60 -> 1290 | D60: -630 | E60: =C60-D60 -> 1920 | F60: =$D$21-D60 -> 217 | G60: =G59+1 -> 40 | H60: =$H$21-L60 -> 1112 | I60: -1063 | J60: =I60-I59 -> -1 | K60: =H60-I60 -> 2175 | L60: =$I$21-I60 -> 380 | M60: =M59+1 -> 40 | N60: =$N$21-Q60 -> 1288 | O60: -549 | P60: =N60-O60 -> 1837 | Q60: =$O$21-O60 -> 159
A61: 45837 | B61: 4 | C61: =$C$21-F61 -> 1285 | D61: -635 | E61: =C61-D61 -> 1920 | F61: =$D$21-D61 -> 222 | G61: =G60+1 -> 41 | H61: =$H$21-L61 -> 1111 | I61: -1064 | J61: =I61-I60 -> -1 | K61: =H61-I61 -> 2175 | L61: =$I$21-I61 -> 381 | M61: =M60+1 -> 41 | N61: =$N$21-Q61 -> 1283 | O61: -554 | P61: =N61-O61 -> 1837 | Q61: =$O$21-O61 -> 164
...

Sheet QTL-KM117+900
A1: DỰ ÁN THÀNH PHẦN ĐOẠN HẬU GIANG - CÀ MAU
A2: THUỘC DỰ ÁN XÂY DỰNG CÔNG TRÌNH ĐƯỜNG BỘ CAO TỐC BẮC - NAM PHÍA ĐÔNG GIAI ĐOẠN 2021 - 2025
