Workbook

Sheet 115+040
A1: =UPPER("GÓI THẦU XL03 :Thi Công Xây Dựng Đoạn Tuyến Km114+200 - Km126+223 Bao Gồm Tuyến Nối Nút Giao IC12 Với QL1 (bao gồm khảo sát, thiết kế BVTC)") -> GÓI THẦU XL03 :THI CÔNG XÂY DỰNG ĐOẠN TUYẾN KM114+200 - KM126+223 BAO GỒM TUYẾN NỐI NÚT GIAO IC12 VỚI QL1 (BAO GỒM KHẢO SÁT, THIẾT KẾ BVTC)
A2: CHỦ ĐẦU TƯ | J2: TƯ VẤN GIÁM SÁT | T2: NHÀ THẦU
A3: BAN QUẢN LÝ DỰ ÁN MỸ THUẬN | J3: =UPPER("Liên danh Phân viện KHCN GTVT phía Nam - Công ty Cổ phần Tư vấn kỹ thuật và xây dựng Hồng Hà") -> LIÊN DANH PHÂN VIỆN KHCN GTVT PHÍA NAM - CÔNG TY CỔ PHẦN TƯ VẤN KỸ THUẬT VÀ XÂY DỰNG HỒNG HÀ | T3: LIÊN DANH CC1 - HẢI ĐĂNG - VẠN CƯỜNG - 492 - BẮC TRUNG NAM
A4: BIỂU GHI ĐO QUAN TRẮC LÚN
A5: Người lập: | L5: Tên mốc:
A6: Thời tiết: | C6: Nắng | L6: Cao độ mốc: | N6: =C11 -> 1069
A7: Lý trình: | C7: Km115+040 | L7: Ngày đặt bàn: | N7: =B11 -> 10/12/2023
A8: Stt | C8: Cao độ mốc (mm) | D8: Số đọc tại mốc (mm) | F8: Số đọc mia (mm) | I8: Cao độ quan trắc (mm) | L8: Chiều dài cần nối (mm) | O8: Cao độ bàn đo lún (mm) | R8: Tốc độ lún (mm) | Y8: Chiều dày lớp đắp (m) | Z8: Đội quan trắc | AA8: Tư Vấn Giám Sát | AB8: Ghi chú
F10: Trái | G10: Giữa | H10: Phải | I10: Trái | J10: Giữa | K10: Phải | L10: Trái | M10: Giữa | N10: Phải | O10: Trái | P10: Giữa | Q10: Phải | R10: Trái | S10: Giữa | T10: Phải | X10: Phải
A11: 0 | B11: 10/12/2023 | C11: 1069 | D11: 1725 | E11: =C11+D11 -> 2794 | F11: =C11+D11-I11 -> 1014 | G11: =C11+D11-J11 -> 1004 | H11: =D11+C11-K11 -> 934 | I11: =L11+O11 -> 1780 | J11: =M11+P11 -> 1790 | K11: =N11+Q11 -> 1860 | L11: 2000 | M11: 2000 | N11: 2000 | O11: -220 | P11: -210 | Q11: -140 | R11: 0 | S11: 0 | T11: 0 | U11: =U10-R11 -> 0 | V11: =V10-S11 -> 0 | W11: =W10-T11 -> 0 | X11: -0.21 | AB11: Lắp đặt ban đầu
A12: 1 | B12: 11/12/2023 | C12: =C11 -> 1069 | D12: =D11-2 -> 1723 | E12: =C12+D12 -> 2792 | F12: =C12+D12-I12 -> 1012 | G12: =C12+D12-J12 -> 1002 | H12: =D12+C12-K12 -> 932 | I12: =L12+O12 -> 1780 | J12: =M12+P12 -> 1790 | K12: =N12+Q12 -> 1860 | L12: =L11 -> 2000 | M12: =M11 -> 2000 | N12: =N11 -> 2000 | O12: =O11-R12 -> -220 | P12: =P11-S12 -> -210 | Q12: =Q11-T12 -> -140 | R12: 0 | S12: 0 | T12: 0 | U12: =U11-R12 -> 0 | V12: =V11-S12 -> 0 | W12: =W11-T12 -> 0 | X12: -0.21
A13: 2 | B13: 12/12/2023 | C13: =C12 -> 1069 | D13: =D12-2 -> 1721 | E13: =C13+D13 -> 2790 | F13: =C13+D13-I13 -> 1010 | G13: =C13+D13-J13 -> 1000 | H13: =D13+C13-K13 -> 930 | I13: =L13+O13 -> 1780 | J13: =M13+P13 -> 1790 | K13: =N13+Q13 -> 1860 | L13: =L12 -> 2000 | M13: =M12 -> 2000 | N13: =N12 -> 2000 | O13: =O12-R13 -> -220 | P13: =P12-S13 -> -210 | Q13: =Q12-T13 -> -140 | R13: 0 | S13: 0 | T13: 0 | U13: =U12-R13 -> 0 | V13: =V12-S13 -> 0 | W13: =W12-T13 -> 0 | X13: -0.21
A14: 3 | B14: 13/12/2023 | C14: =C13 -> 1069 | D14: =D13-2 -> 1719 | E14: =C14+D14 -> 2788 | F14: =C14+D14-I14 -> 1008 | G14: =C14+D14-J14 -> 998 | H14: =D14+C14-K14 -> 928 | I14: =L14+O14 -> 1780 | J14: =M14+P14 -> 1790 | K14: =N14+Q14 -> 1860 | L14: =L13 -> 2000 | M14: =M13 -> 2000 | N14: =N13 -> 2000 | O14: =O13-R14 -> -220 | P14: =P13-S14 -> -210 | Q14: =Q13-T14 -> -140 | R14: 0 | S14: 0 | T14: 0 | U14: =U13-R14 -> 0 | V14: =V13-S14 -> 0 | W14: =W13-T14 -> 0 | X14: -0.21 | AD14: 45273
A15: 4 | B15: 14/12/2023 | C15: =C14 -> 1069 | D15: =D14-2 -> 1717 | E15: =C15+D15 -> 2786 | F15: =C15+D15-I15 -> 1006 | G15: =C15+D15-J15 -> 996 | H15: =D15+C15-K15 -> 926 | I15: =L15+O15 -> 1780 | J15: =M15+P15 -> 1790 | K15: =N15+Q15 -> 1860 | L15: =L14 -> 2000 | M15: =M14 -> 2000 | N15: =N14 -> 2000 | O15: =O14-R15 -> -220 | P15: =P14-S15 -> -210 | Q15: =Q14-T15 -> -140 | R15: 0 | S15: 0 | T15: 0 | U15: =U14-R15 -> 0 | V15: =V14-S15 -> 0 | W15: =W14-T15 -> 0 | X15: -0.21 | AD15: 45277
A16: 5 | B16: 15/12/2023 | C16: =C15 -> 1069 | D16: =D15-2 -> 1715 | E16: =C16+D16 -> 2784 | F16: =C16+D16-I16 -> 1004 | G16: =C16+D16-J16 -> 994 | H16: =D16+C16-K16 -> 924 | I16: =L16+O16 -> 1780 | J16: =M16+P16 -> 1790 | K16: =N16+Q16 -> 1860 | L16: =L15 -> 2000 | M16: =M15 -> 2000 | N16: =N15 -> 2000 | O16: =O15-R16 -> -220 | P16: =P15-S16 -> -210 | Q16: =Q15-T16 -> -140 | R16: 0 | S16: 0 | T16: 0 | U16: =U15-R16 -> 0 | V16: =V15-S16 -> 0 | W16: =W15-T16 -> 0 | X16: -0.21 | AD16: 45281
A17: 6 | B17: 16/12/2023 | C17: =C16 -> 1069 | D17: =D16-2 -> 1713 | E17: =C17+D17 -> 2782 | F17: =C17+D17-I17 -> 1002 | G17: =C17+D17-J17 -> 992 | H17: =D17+C17-K17 -> 922 | I17: =L17+O17 -> 1780 | J17: =M17+P17 -> 1790 | K17: =N17+Q17 -> 1860 | L17: =L16 -> 2000 | M17: =M16 -> 2000 | N17: =N16 -> 2000 | O17: =O16-R17 -> -220 | P17: =P16-S17 -> -210 | Q17: =Q16-T17 -> -140 | R17: 0 | S17: 0 | T17: 0 | U17: =U16-R17 -> 0 | V17: =V16-S17 -> 0 | W17: =W16-T17 -> 0 | X17: -0.21 | AD17: 45287
A18: 7 | B18: 17/12/2023 | C18: =C17 -> 1069 | D18: =D17-2 -> 1711 | E18: =C18+D18 -> 2780 | F18: =C18+D18-I18 -> 1000 | G18: =C18+D18-J18 -> 990 | H18: =D18+C18-K18 -> 920 | I18: =L18+O18 -> 1780 | J18: =M18+P18 -> 1790 | K18: =N18+Q18 -> 1860 | L18: =L17 -> 2000 | M18: =M17 -> 2000 | N18: =N17 -> 2000 | O18: =O17-R18 -> -220 | P18: =P17-S18 -> -210 | Q18: =Q17-T18 -> -140 | R18: 0 | S18: 0 | T18: 0 | U18: =U17-R18 -> 0 | V18: =V17-S18 -> 0 | W18: =W17-T18 -> 0 | X18: -0.21 | AD18: 45293
A19: 8 | B19: 18/12/2023 | C19: =C18 -> 1069 | D19: =D18-2 -> 1709 | E19: =C19+D19 -> 2778 | F19: =C19+D19-I19 -> 998 | G19: =C19+D19-J19 -> 988 | H19: =D19+C19-K19 -> 918 | I19: =L19+O19 -> 1780 | J19: =M19+P19 -> 1790 | K19: =N19+Q19 -> 1860 | L19: =L18 -> 2000 | M19: =M18 -> 2000 | N19: =N18 -> 2000 | O19: =O18-R19 -> -220 | P19: =P18-S19 -> -210 | Q19: =Q18-T19 -> -140 | R19: 0 | S19: 0 | T19: 0 | U19: =U18-R19 -> 0 | V19: =V18-S19 -> 0 | W19: =W18-T19 -> 0 | X19: -0.21 | AD19: 45299
A20: 9 | B20: 19/12/2023 | C20: =C19 -> 1069 | D20: =D19-2 -> 1707 | E20: =C20+D20 -> 2776 | F20: =C20+D20-I20 -> 996 | G20: =C20+D20-J20 -> 986 | H20: =D20+C20-K20 -> 916 | I20: =L20+O20 -> 1780 | J20: =M20+P20 -> 1790 | K20: =N20+Q20 -> 1860 | L20: =L19 -> 2000 | M20: =M19 -> 2000 | N20: =N19 -> 2000 | O20: =O19-R20 -> -220 | P20: =P19-S20 -> -210 | Q20: =Q19-T20 -> -140 | R20: 0 | S20: 0 | T20: 0 | U20: =U19-R20 -> 0 | V20: =V19-S20 -> 0 | W20: =W19-T20 -> 0 | X20: -0.21 | AD20: 45305
A21: 10 | B21: 20/12/2023 | C21: =C20 -> 1069 | D21: =D20-2 -> 1705 | E21: =C21+D21 -> 2774 | F21: =C21+D21-I21 -> 994 | G21: =C21+D21-J21 -> 984 | H21: =D21+C21-K21 -> 914 | I21: =L21+O21 -> 1780 | J21: =M21+P21 -> 1790 | K21: =N21+Q21 -> 1860 | L21: =L20 -> 2000 | M21: =M20 -> 2000 | N21: =N20 -> 2000 | O21: =O20-R21 -> -220 | P21: =P20-S21 -> -210 | Q21: =Q20-T21 -> -140 | R21: 0 | S21: 0 | T21: 0 | U21: =U20-R21 -> 0 | V21: =V20-S21 -> 0 | W21: =W20-T21 -> 0 | X21: -0.21 | AD21: 45311
A22: 11 | B22: 21/12/2023 | C22: =C21 -> 1069 | D22: =D21-2 -> 1703 | E22: =C22+D22 -> 2772 | F22: =C22+D22-I22 -> 992 | G22: =C22+D22-J22 -> 982 | H22: =D22+C22-K22 -> 912 | I22: =L22+O22 -> 1780 | J22: =M22+P22 -> 1790 | K22: =N22+Q22 -> 1860 | L22: =L21 -> 2000 | M22: =M21 -> 2000 | N22: =N21 -> 2000 | O22: =O21-R22 -> -220 | P22: =P21-S22 -> -210 | Q22: =Q21-T22 -> -140 | R22: 0 | S22: 0 | T22: 0 | U22: =U21-R22 -> 0 | V22: =V21-S22 -> 0 | W22: =W21-T22 -> 0 | X22: -0.21 | AD22: 45396
A23: 12 | B23: 22/12/2023 | C23: =C22 -> 1069 | D23: =D22-2 -> 1701 | E23: =C23+D23 -> 2770 | F23: =C23+D23-I23 -> 990 | G23: =C23+D23-J23 -> 980 | H23: =D23+C23-K23 -> 910 | I23: =L23+O23 -> 1780 | J23: =M23+P23 -> 1790 | K23: =N23+Q23 -> 1860 | L23: =L22 -> 2000 | M23: =M22 -> 2000 | N23: =N22 -> 2000 | O23: =O22-R23 -> -220 | P23: =P22-S23 -> -210 | Q23: =Q22-T23 -> -140 | R23: 0 | S23: 0 | T23: 0 | U23: =U22-R23 -> 0 | V23: =V22-S23 -> 0 | W23: =W22-T23 -> 0 | X23: -0.21 | AD23: 45400
A24: 13 | B24: 23/12/2023 | C24: =C23 -> 1069 | D24: =D23-2 -> 1699 | E24: =C24+D24 -> 2768 | F24: =C24+D24-I24 -> 988 | G24: =C24+D24-J24 -> 978 | H24: =D24+C24-K24 -> 908 | I24: =L24+O24 -> 1780 | J24: =M24+P24 -> 1790 | K24: =N24+Q24 -> 1860 | L24: =L23 -> 2000 | M24: =M23 -> 2000 | N24: =N23 -> 2000 | O24: =O23-R24 -> -220 | P24: =P23-S24 -> -210 | Q24: =Q23-T24 -> -140 | R24: 0 | S24: 0 | T24: 0 | U24: =U23-R24 -> 0 | V24: =V23-S24 -> 0 | W24: =W23-T24 -> 0 | X24: -0.21 | AD24: 45405
A25: 14 | B25: 24/12/2023 | C25: =C24 -> 1069 | D25: =D24-2 -> 1697 | E25: =C25+D25 -> 2766 | F25: =C25+D25-I25 -> 986 | G25: =C25+D25-J25 -> 976 | H25: =D25+C25-K25 -> 906 | I25: =L25+O25 -> 1780 | J25: =M25+P25 -> 1790 | K25: =N25+Q25 -> 1860 | L25: =L24 -> 2000 | M25: =M24 -> 2000 | N25: =N24 -> 2000 | O25: =O24-R25 -> -220 | P25: =P24-S25 -> -210 | Q25: =Q24-T25 -> -140 | R25: 0 | S25: 0 | T25: 0 | U25: =U24-R25 -> 0 | V25: =V24-S25 -> 0 | W25: =W24-T25 -> 0 | X25: -0.21
A26: 15 | B26: 25/12/2023 | C26: =C25 -> 1069 | D26: =D25-2 -> 1695 | E26: =C26+D26 -> 2764 | F26: =C26+D26-I26 -> 984 | G26: =C26+D26-J26 -> 974 | H26: =D26+C26-K26 -> 904 | I26: =L26+O26 -> 1780 | J26: =M26+P26 -> 1790 | K26: =N26+Q26 -> 1860 | L26: =L25 -> 2000 | M26: =M25 -> 2000 | N26: =N25 -> 2000 | O26: =O25-R26 -> -220 | P26: =P25-S26 -> -210 | Q26: =Q25-T26 -> -140 | R26: 0 | S26: 0 | T26: 0 | U26: =U25-R26 -> 0 | V26: =V25-S26 -> 0 | W26: =W25-T26 -> 0 | X26: -0.21
A27: 16 | B27: 26/12/2023 | C27: =C26 -> 1069 | D27: =D26-2 -> 1693 | E27: =C27+D27 -> 2762 | F27: =C27+D27-I27 -> 982 | G27: =C27+D27-J27 -> 972 | H27: =D27+C27-K27 -> 902 | I27: =L27+O27 -> 1780 | J27: =M27+P27 -> 1790 | K27: =N27+Q27 -> 1860 | L27: =L26 -> 2000 | M27: =M26 -> 2000 | N27: =N26 -> 2000 | O27: =O26-R27 -> -220 | P27: =P26-S27 -> -210 | Q27: =Q26-T27 -> -140 | R27: 0 | S27: 0 | T27: 0 | U27: =U26-R27 -> 0 | V27: =V26-S27 -> 0 | W27: =W26-T27 -> 0 | X27: -0.21
A28: 17 | B28: 27/12/2023 | C28: =C27 -> 1069 | D28: =D27-2 -> 1691 | E28: =C28+D28 -> 2760 | F28: =C28+D28-I28 -> 987 | G28: =C28+D28-J28 -> 978 | H28: =D28+C28-K28 -> 908 | I28: =L28+O28 -> 1773 | J28: =M28+P28 -> 1782 | K28: =N28+Q28 -> 1852 | L28: =L27 -> 2000 | M28: =M27 -> 2000 | N28: =N27 -> 2000 | O28: =O27-R28 -> -227 | P28: =P27-S28 -> -218 | Q28: =Q27-T28 -> -148 | R28: 7 | S28: 8 | T28: 8 | U28: =U27-R28 -> -7 | V28: =V27-S28 -> -8 | W28: =W27-T28 -> -8 | X28: -0.108 | AB28: 8
A29: 18 | B29: 28/12/2023 | C29: =C28 -> 1069 | D29: =D28-2 -> 1689 | E29: =C29+D29 -> 2758 | F29: =C29+D29-I29 -> 988 | G29: =C29+D29-J29 -> 979 | H29: =D29+C29-K29 -> 912 | I29: =L29+O29 -> 1770 | J29: =M29+P29 -> 1779 | K29: =N29+Q29 -> 1846 | L29: =L28 -> 2000 | M29: =M28 -> 2000 | N29: =N28 -> 2000 | O29: =O28-R29 -> -230 | P29: =P28-S29 -> -221 | Q29: =Q28-T29 -> -154 | R29: 3 | S29: 3 | T29: 6 | U29: =U28-R29 -> -10 | V29: =V28-S29 -> -11 | W29: =W28-T29 -> -14 | X29: -0.111
A30: 19 | B30: 29/12/2023 | C30: =C29 -> 1069 | D30: =D29-2 -> 1687 | E30: =C30+D30 -> 2756 | F30: =C30+D30-I30 -> 990 | G30: =C30+D30-J30 -> 981 | H30: =D30+C30-K30 -> 916 | I30: =L30+O30 -> 1766 | J30: =M30+P30 -> 1775 | K30: =N30+Q30 -> 1840 | L30: =L29 -> 2000 | M30: =M29 -> 2000 | N30: =N29 -> 2000 | O30: =O29-R30 -> -234 | P30: =P29-S30 -> -225 | Q30: =Q29-T30 -> -160 | R30: 4 | S30: 4 | T30: 6 | U30: =U29-R30 -> -14 | V30: =V29-S30 -> -15 | W30: =W29-T30 -> -20 | X30: -0.115
A31: 20 | B31: 30/12/2023 | C31: =C30 -> 1069 | D31: =D30-2 -> 1685 | E31: =C31+D31 -> 2754 | F31: =C31+D31-I31 -> 993 | G31: =C31+D31-J31 -> 981 | H31: =D31+C31-K31 -> 920 | I31: =L31+O31 -> 1761 | J31: =M31+P31 -> 1773 | K31: =N31+Q31 -> 1834 | L31: =L30 -> 2000 | M31: =M30 -> 2000 | N31: =N30 -> 2000 | O31: =O30-R31 -> -239 | P31: =P30-S31 -> -227 | Q31: =Q30-T31 -> -166 | R31: 5 | S31: 2 | T31: 6 | U31: =U30-R31 -> -19 | V31: =V30-S31 -> -17 | W31: =W30-T31 -> -26 | X31: -0.117
A32: 21 | B32: 31/12/2023 | C32: =C31 -> 1069 | D32: =D31-2 -> 1683 | E32: =C32+D32 -> 2752 | F32: =C32+D32-I32 -> 1000 | G32: =C32+D32-J32 -> 987 | H32: =D32+C32-K32 -> 927 | I32: =L32+O32 -> 1752 | J32: =M32+P32 -> 1765 | K32: =N32+Q32 -> 1825 | L32: =L31 -> 2000 | M32: =M31 -> 2000 | N32: =N31 -> 2000 | O32: =O31-R32 -> -248 | P32: =P31-S32 -> -235 | Q32: =Q31-T32 -> -175 | R32: 9 | S32: 8 | T32: 9 | U32: =U31-R32 -> -28 | V32: =V31-S32 -> -25 | W32: =W31-T32 -> -35 | X32: -0.125
A33: 22 | B33: 01/01/2024 | C33: =C32 -> 1069 | D33: =D32-2 -> 1681 | E33: =C33+D33 -> 2750 | F33: =C33+D33-I33 -> 1002 | G33: =C33+D33-J33 -> 988 | H33: =D33+C33-K33 -> 928 | I33: =L33+O33 -> 1748 | J33: =M33+P33 -> 1762 | K33: =N33+Q33 -> 1822 | L33: =L32 -> 2000 | M33: =M32 -> 2000 | N33: =N32 -> 2000 | O33: =O32-R33 -> -252 | P33: =P32-S33 -> -238 | Q33: =Q32-T33 -> -178 | R33: 4 | S33: 3 | T33: 3 | U33: =U32-R33 -> -32 | V33: =V32-S33 -> -28 | W33: =W32-T33 -> -38 | X33: -0.128
A34: 23 | B34: 02/01/2024 | C34: =C33 -> 1069 | D34: =D33-2 -> 1679 | E34: =C34+D34 -> 2748 | F34: =C34+D34-I34 -> 1004 | G34: =C34+D34-J34 -> 991 | H34: =D34+C34-K34 -> 929 | I34: =L34+O34 -> 1744 | J34: =M34+P34 -> 1757 | K34: =N34+Q34 -> 1819 | L34: =L33 -> 2000 | M34: =M33 -> 2000 | N34: =N33 -> 2000 | O34: =O33-R34 -> -256 | P34: =P33-S34 -> -243 | Q34: =Q33-T34 -> -181 | R34: 4 | S34: 5 | T34: 3 | U34: =U33-R34 -> -36 | V34: =V33-S34 -> -33 | W34: =W33-T34 -> -41 | X34: 0.167 | Y34: 0.3 | Z34: =Z33+Y34 -> 0.3 | AB34: 7
A35: 24 | B35: 03/01/2024 | C35: =C34 -> 1069 | D35: =D34-2 -> 1677 | E35: =C35+D35 -> 2746 | F35: =C35+D35-I35 -> 1006 | G35: =C35+D35-J35 -> 993 | H35: =D35+C35-K35 -> 930 | I35: =L35+O35 -> 1740 | J35: =M35+P35 -> 1753 | K35: =N35+Q35 -> 1816 | L35: =L34 -> 2000 | M35: =M34 -> 2000 | N35: =N34 -> 2000 | O35: =O34-R35 -> -260 | P35: =P34-S35 -> -247 | Q35: =Q34-T35 -> -184 | R35: 4 | S35: 4 | T35: 3 | U35: =U34-R35 -> -40 | V35: =V34-S35 -> -37 | W35: =W34-T35 -> -44 | X35: 0.163 | Z35: =Z34+Y35 -> 0.3
A36: 25 | B36: 04/01/2024 | C36: =C35 -> 1069 | D36: =D35-2 -> 1675 | E36: =C36+D36 -> 2744 | F36: =C36+D36-I36 -> 1007 | G36: =C36+D36-J36 -> 994 | H36: =D36+C36-K36 -> 930 | I36: =L36+O36 -> 1737 | J36: =M36+P36 -> 1750 | K36: =N36+Q36 -> 1814 | L36: =L35 -> 2000 | M36: =M35 -> 2000 | N36: =N35 -> 2000 | O36: =O35-R36 -> -263 | P36: =P35-S36 -> -250 | Q36: =Q35-T36 -> -186 | R36: 3 | S36: 3 | T36: 2 | U36: =U35-R36 -> -43 | V36: =V35-S36 -> -40 | W36: =W35-T36 -> -46 | X36: 0.16 | Z36: =Z35+Y36 -> 0.3
A37: 26 | B37: 05/01/2024 | C37: =C36 -> 1069 | D37: =D36-2 -> 1673 | E37: =C37+D37 -> 2742 | F37: =C37+D37-I37 -> 1007 | G37: =C37+D37-J37 -> 995 | H37: =D37+C37-K37 -> 930 | I37: =L37+O37 -> 1735 | J37: =M37+P37 -> 1747 | K37: =N37+Q37 -> 1812 | L37: =L36 -> 2000 | M37: =M36 -> 2000 | N37: =N36 -> 2000 | O37: =O36-R37 -> -265 | P37: =P36-S37 -> -253 | Q37: =Q36-T37 -> -188 | R37: 2 | S37: 3 | T37: 2 | U37: =U36-R37 -> -45 | V37: =V36-S37 -> -43 | W37: =W36-T37 -> -48 | X37: 0.157 | Z37: =Z36+Y37 -> 0.3
A38: 27 | B38: 06/01/2024 | C38: =C37 -> 1069 | D38: =D37-2 -> 1671 | E38: =C38+D38 -> 2740 | F38: =C38+D38-I38 -> 1006 | G38: =C38+D38-J38 -> 994 | H38: =D38+C38-K38 -> 929 | I38: =L38+O38 -> 1734 | J38: =M38+P38 -> 1746 | K38: =N38+Q38 -> 1811 | L38: =L37 -> 2000 | M38: =M37 -> 2000 | N38: =N37 -> 2000 | O38: =O37-R38 -> -266 | P38: =P37-S38 -> -254 | Q38: =Q37-T38 -> -189 | R38: 1 | S38: 1 | T38: 1 | U38: =U37-R38 -> -46 | V38: =V37-S38 -> -44 | W38: =W37-T38 -> -49 | X38: 0.156 | Z38: =Z37+Y38 -> 0.3
A39: 28 | B39: 07/01/2024 | C39: =C38 -> 1069 | D39: =D38-2 -> 1669 | E39: =C39+D39 -> 2738 | F39: =C39+D39-I39 -> 1004 | G39: =C39+D39-J39 -> 992 | H39: =D39+C39-K39 -> 927 | I39: =L39+O39 -> 1734 | J39: =M39+P39 -> 1746 | K39: =N39+Q39 -> 1811 | L39: =L38 -> 2000 | M39: =M38 -> 2000 | N39: =N38 -> 2000 | O39: =O38-R39 -> -266 | P39: =P38-S39 -> -254 | Q39: =Q38-T39 -> -189 | R39: 0 | S39: 0 | T39: 0 | U39: =U38-R39 -> -46 | V39: =V38-S39 -> -44 | W39: =W38-T39 -> -49 | X39: 0.156 | Z39: =Z38+Y39 -> 0.3
A40: 29 | B40: 08/01/2024 | C40: =C39 -> 1069 | D40: =D39-2 -> 1667 | E40: =C40+D40 -> 2736 | F40: =C40+D40-I40 -> 1006 | G40: =C40+D40-J40 -> 995 | H40: =D40+C40-K40 -> 928 | I40: =L40+O40 -> 1730 | J40: =M40+P40 -> 1741 | K40: =N40+Q40 -> 1808 | L40: =L39 -> 2000 | M40: =M39 -> 2000 | N40: =N39 -> 2000 | O40: =O39-R40 -> -270 | P40: =P39-S40 -> -259 | Q40: =Q39-T40 -> -192 | R40: 4 | S40: 5 | T40: 3 | U40: =U39-R40 -> -50 | V40: =V39-S40 -> -49 | W40: =W39-T40 -> -52 | X40: 0.451 | Y40: 0.3 | Z40: =Z39+Y40 -> 0.6 | AB40: 6
A41: 30 | B41: 09/01/2024 | C41: =C40 -> 1069 | D41: =D40-2 -> 1665 | E41: =C41+D41 -> 2734 | F41: =C41+D41-I41 -> 1008 | G41: =C41+D41-J41 -> 997 | H41: =D41+C41-K41 -> 929 | I41: =L41+O41 -> 1726 | J41: =M41+P41 -> 1737 | K41: =N41+Q41 -> 1805 | L41: =L40 -> 2000 | M41: =M40 -> 2000 | N41: =N40 -> 2000 | O41: =O40-R41 -> -274 | P41: =P40-S41 -> -263 | Q41: =Q40-T41 -> -195 | R41: 4 | S41: 4 | T41: 3 | U41: =U40-R41 -> -54 | V41: =V40-S41 -> -53 | W41: =W40-T41 -> -55 | X41: 0.447 | Z41: =Z40+Y41 -> 0.6
...

Sheet BC.115+040
A1: 13 | B1: DỰ ÁN THÀNH PHẦN ĐOẠN HẬU GIANG - CÀ MAU
B2: THUỘC DỰ ÁN XÂY DỰNG CÔNG TRÌNH ĐƯỜNG BỘ CAO TỐC BẮC - NAM PHÍA ĐÔNG GIAI ĐOẠN 2021 - 2025
B3: =UPPER("GÓI THẦU XL03 :Thi Công Xây Dựng Đoạn Tuyến Km114+200 - Km126+223 Bao Gồm Tuyến Nối Nút Giao IC12 Với QL1 (bao gồm khảo sát, thiết kế BVTC)") -> GÓI THẦU XL03 :THI CÔNG XÂY DỰNG ĐOẠN TUYẾN KM114+200 - KM126+223 BAO GỒM TUYẾN NỐI NÚT GIAO IC12 VỚI QL1 (BAO GỒM KHẢO SÁT, THIẾT KẾ BVTC)
B4: CHỦ ĐẦU TƯ | J4: TƯ VẤN GIÁM SÁT | T4: NHÀ THẦU
B5: BAN QUẢN LÝ DỰ ÁN MỸ THUẬN | J5: =UPPER("Liên danh Phân viện KHCN GTVT phía Nam - Công ty Cổ phần Tư vấn kỹ thuật và xây dựng Hồng Hà") -> LIÊN DANH PHÂN VIỆN KHCN GTVT PHÍA NAM - CÔNG TY CỔ PHẦN TƯ VẤN KỸ THUẬT VÀ XÂY DỰNG HỒNG HÀ | T5: LIÊN DANH CC1 - HẢI ĐĂNG - VẠN CƯỜNG - 492 - BẮC TRUNG NAM
B6: BIỂU GHI ĐO QUAN TRẮC LÚN
B7: Người lập: | C7: ='115+040'!C5 -> 0 | L7: Tên mốc: | N7: ='115+040'!N5 -> 0
B8: Thời tiết: | C8: ='115+040'!C6 -> Nắng | L8: Cao độ mốc: | N8: ='115+040'!N6 -> 1069
B9: Lý trình: | C9: ='115+040'!C7 -> Km115+040 | L9: Ngày đặt bàn: | N9: ='115+040'!N7 -> 10/12/2023
B11: Ngày | C11: Ngày cộng dồn | D11: Cao độ mốc | E11: Số đọc mia của mốc | F11: Cao độ đường ngắm | G11: Trái | M11: Tim | S11: Phải | Z11: Chiều dày lớp đắp (m) | AA11: Chiều cao nền đắp (m) | AB11: Chiều dày nền đắp (m)
G12: Cao độ đắp (mm) | H12: Số đọc mia | I12: Cao độ quan trắc (mm) | J12: Cao độ bàn đo lún (mm) | K12: Độ lún (mm) | L12: Độ lún tích lũy (mm) | M12: Cao độ đắp (mm) | N12: Số đọc mia | O12: Cao độ quan trắc (mm) | P12: Cao độ bàn đo lún (mm) | Q12: Độ lún (mm) | R12: Độ lún tích lũy (mm) | S12: Cao độ đắp (mm) | T12: Số đọc mia | U12: Cao độ quan trắc (mm) | V12: Cao độ bàn đo lún (mm) | W12: Độ lún (mm) | X12: Độ lún tích lũy (mm)
B13: ='115+040'!#REF! -> #REF! | C13: 0 | D13: =VLOOKUP(B13,'115+040'!B11:AB112,2,FALSE) -> #REF! | E13: =VLOOKUP(B13,'115+040'!B11:AB112,3,FALSE) -> #REF! | F13: =D13+E13 -> #REF! | G13: =VLOOKUP(B13,'115+040'!$B$11:$AB$112,20,FALSE) -> #REF! | H13: =VLOOKUP(B13,'115+040'!$B$11:$AB$112,4,FALSE) -> #REF! | I13: =F13-H13 -> #REF! | J13: =VLOOKUP(B13,'115+040'!$B$11:$AB$112,13,FALSE) -> #REF! | K13: ='115+040'!R11 -> 0 | L13: 0 | M13: =VLOOKUP(B13,'115+040'!$B$11:$AB$112,21,FALSE) -> #REF! | N13: =VLOOKUP(B13,'115+040'!$B$11:$AB$112,5,FALSE) -> #REF! | O13: =F13-N13 -> #REF! | P13: =VLOOKUP(B13,'115+040'!$B$11:$AB$112,14,FALSE) -> #REF! | Q13: ='115+040'!S11 -> 0 | R13: 0 | S13: =VLOOKUP(B13,'115+040'!$B$11:$AB$112,22,FALSE) -> #REF! | T13: =VLOOKUP(B13,'115+040'!$B$10:$AB$112,6,FALSE) -> #REF! | U13: =F13-T13 -> #REF! | V13: =VLOOKUP(B13,'115+040'!$B$11:$AB$112,15,FALSE) -> #REF! | W13: ='[4]114+940'!S14 -> 0 | X13: 0 | Y13: 0 | Z13: =IF(Y13>0,Y13,0) -> 0 | AA13: =Z13 -> 0 | AB13: 0
B14: ='115+040'!#REF! -> #REF! | C14: =B14-B13 -> #REF! | D14: =D13 -> #REF! | E14: =VLOOKUP(B14,'115+040'!B12:AB113,3,FALSE) -> #REF! | F14: =D14+E14 -> #REF! | G14: =VLOOKUP(B14,'115+040'!$B$12:$AB$112,20,FALSE) -> #REF! | H14: =VLOOKUP(B14,'115+040'!$B$12:$AB$112,4,FALSE) -> #REF! | I14: =F14-H14 -> #REF! | J14: =VLOOKUP(B14,'115+040'!$B$12:$AB$112,13,FALSE) -> #REF! | K14: ='115+040'!R12 -> 0 | L14: =+K14+L13 -> 0 | M14: =VLOOKUP(B14,'115+040'!$B$11:$AB$112,21,FALSE) -> #REF! | N14: =VLOOKUP(B14,'115+040'!$B$12:$AB$112,5,FALSE) -> #REF! | O14: =F14-N14 -> #REF! | P14: =VLOOKUP(B14,'115+040'!$B$12:$AB$112,14,FALSE) -> #REF! | Q14: ='115+040'!S12 -> 0 | R14: =+Q14+R13 -> 0 | S14: =VLOOKUP(B14,'115+040'!$B$11:$AB$112,22,FALSE) -> #REF! | T14: =VLOOKUP(B14,'115+040'!$B$12:$AB$112,6,FALSE) -> #REF! | U14: =F14-T14 -> #REF! | V14: =VLOOKUP(B14,'115+040'!$B$12:$AB$112,15,FALSE) -> #REF! | W14: ='[4]114+940'!S15 -> 0 | X14: =+W14+X13 -> 0 | Y14: =S14-S13 -> #REF! | Z14: =IF(Y14>0,Y14,0)/1000 -> #REF! | AA14: =AA13+Z14 -> #REF! | AB14: =(M14-$M$13-R14)/1000 -> #REF!
A15: 1 | B15: ='115+040'!#REF! -> #REF! | C15: =B15-B14 -> #REF! | D15: =D14 -> #REF! | E15: =VLOOKUP(B15,'115+040'!B13:AB114,3,FALSE) -> #REF! | F15: =D15+E15 -> #REF! | G15: =VLOOKUP(B15,'115+040'!$B$12:$AB$112,20,FALSE) -> #REF! | H15: =VLOOKUP(B15,'115+040'!$B$12:$AB$112,4,FALSE) -> #REF! | I15: =F15-H15 -> #REF! | J15: =VLOOKUP(B15,'115+040'!$B$12:$AB$112,13,FALSE) -> #REF! | K15: ='115+040'!R13 -> 0 | L15: =+K15+L14 -> 0 | M15: =VLOOKUP(B15,'115+040'!$B$11:$AB$112,21,FALSE) -> #REF! | N15: =VLOOKUP(B15,'115+040'!$B$12:$AB$112,5,FALSE) -> #REF! | O15: =F15-N15 -> #REF! | P15: =VLOOKUP(B15,'115+040'!$B$12:$AB$112,14,FALSE) -> #REF! | Q15: ='115+040'!S13 -> 0 | R15: =+Q15+R14 -> 0 | S15: =VLOOKUP(B15,'115+040'!$B$11:$AB$112,22,FALSE) -> #REF! | T15: =VLOOKUP(B15,'115+040'!$B$12:$AB$112,6,FALSE) -> #REF! | U15: =F15-T15 -> #REF! | V15: =VLOOKUP(B15,'115+040'!$B$12:$AB$112,15,FALSE) -> #REF! | W15: ='[4]114+940'!S16 -> 0 | X15: =+W15+X14 -> 0 | Y15: =S15-S14 -> #REF! | Z15: =IF(Y15>0,Y15,0)/1000 -> #REF! | AA15: =AA14+Z15 -> #REF! | AB15: =(M15-$M$13-R15)/1000 -> #REF!
A16: =A15+1 -> 2 | B16: ='115+040'!#REF! -> #REF! | C16: =B16-B15 -> #REF! | D16: =D15 -> #REF! | E16: =VLOOKUP(B16,'115+040'!B14:AB115,3,FALSE) -> #REF! | F16: =D16+E16 -> #REF! | G16: =VLOOKUP(B16,'115+040'!$B$12:$AB$112,20,FALSE) -> #REF! | H16: =VLOOKUP(B16,'115+040'!$B$12:$AB$112,4,FALSE) -> #REF! | I16: =F16-H16 -> #REF! | J16: =VLOOKUP(B16,'115+040'!$B$12:$AB$112,13,FALSE) -> #REF! | K16: ='115+040'!R14 -> 0 | L16: =+K16+L15 -> 0 | M16: =VLOOKUP(B16,'115+040'!$B$11:$AB$112,21,FALSE) -> #REF! | N16: =VLOOKUP(B16,'115+040'!$B$12:$AB$112,5,FALSE) -> #REF! | O16: =F16-N16 -> #REF! | P16: =VLOOKUP(B16,'115+040'!$B$12:$AB$112,14,FALSE) -> #REF! | Q16: ='115+040'!S14 -> 0 | R16: =+Q16+R15 -> 0 | S16: =VLOOKUP(B16,'115+040'!$B$11:$AB$112,22,FALSE) -> #REF! | T16: =VLOOKUP(B16,'115+040'!$B$12:$AB$112,6,FALSE) -> #REF! | U16: =F16-T16 -> #REF! | V16: =VLOOKUP(B16,'115+040'!$B$12:$AB$112,15,FALSE) -> #REF! | W16: ='[4]114+940'!S17 -> 0 | X16: =+W16+X15 -> 0 | Y16: =S16-S15 -> #REF! | Z16: =IF(Y16>0,Y16,0)/1000 -> #REF! | AA16: =AA15+Z16 -> #REF! | AB16: =(M16-$M$13-R16)/1000 -> #REF!
A17: =A16+1 -> 3 | B17: ='115+040'!#REF! -> #REF! | C17: =B17-B16 -> #REF! | D17: =D16 -> #REF! | E17: =VLOOKUP(B17,'115+040'!B15:AB116,3,FALSE) -> #REF! | F17: =D17+E17 -> #REF! | G17: =VLOOKUP(B17,'115+040'!$B$12:$AB$112,20,FALSE) -> #REF! | H17: =VLOOKUP(B17,'115+040'!$B$12:$AB$112,4,FALSE) -> #REF! | I17: =F17-H17 -> #REF! | J17: =VLOOKUP(B17,'115+040'!$B$12:$AB$112,13,FALSE) -> #REF! | K17: ='115+040'!R15 -> 0 | L17: =+K17+L16 -> 0 | M17: =VLOOKUP(B17,'115+040'!$B$11:$AB$112,21,FALSE) -> #REF! | N17: =VLOOKUP(B17,'115+040'!$B$12:$AB$112,5,FALSE) -> #REF! | O17: =F17-N17 -> #REF! | P17: =VLOOKUP(B17,'115+040'!$B$12:$AB$112,14,FALSE) -> #REF! | Q17: ='115+040'!S15 -> 0 | R17: =+Q17+R16 -> 0 | S17: =VLOOKUP(B17,'115+040'!$B$11:$AB$112,22,FALSE) -> #REF! | T17: =VLOOKUP(B17,'115+040'!$B$12:$AB$112,6,FALSE) -> #REF! | U17: =F17-T17 -> #REF! | V17: =VLOOKUP(B17,'115+040'!$B$12:$AB$112,15,FALSE) -> #REF! | W17: ='[4]114+940'!S18 -> 0 | X17: =+W17+X16 -> 0 | Y17: =S17-S16 -> #REF! | Z17: =IF(Y17>0,Y17,0)/1000 -> #REF! | AA17: =AA16+Z17 -> #REF! | AB17: =(M17-$M$13-R17)/1000 -> #REF!
A18: =A17+1 -> 4 | B18: ='115+040'!#REF! -> #REF! | C18: =B18-B17 -> #REF! | D18: =D17 -> #REF! | E18: =VLOOKUP(B18,'115+040'!B16:AB117,3,FALSE) -> #REF! | F18: =D18+E18 -> #REF! | G18: =VLOOKUP(B18,'115+040'!$B$12:$AB$112,20,FALSE) -> #REF! | H18: =VLOOKUP(B18,'115+040'!$B$12:$AB$112,4,FALSE) -> #REF! | I18: =F18-H18 -> #REF! | J18: =VLOOKUP(B18,'115+040'!$B$12:$AB$112,13,FALSE) -> #REF! | K18: ='115+040'!R16 -> 0 | L18: =+K18+L17 -> 0 | M18: =VLOOKUP(B18,'115+040'!$B$11:$AB$112,21,FALSE) -> #REF! | N18: =VLOOKUP(B18,'115+040'!$B$12:$AB$112,5,FALSE) -> #REF! | O18: =F18-N18 -> #REF! | P18: =VLOOKUP(B18,'115+040'!$B$12:$AB$112,14,FALSE) -> #REF! | Q18: ='115+040'!S16 -> 0 | R18: =+Q18+R17 -> 0 | S18: =VLOOKUP(B18,'115+040'!$B$11:$AB$112,22,FALSE) -> #REF! | T18: =VLOOKUP(B18,'115+040'!$B$12:$AB$112,6,FALSE) -> #REF! | U18: =F18-T18 -> #REF! | V18: =VLOOKUP(B18,'115+040'!$B$12:$AB$112,15,FALSE) -> #REF! | W18: ='[4]114+940'!S19 -> 0 | X18: =+W18+X17 -> 0 | Y18: =S18-S17 -> #REF! | Z18: =IF(Y18>0,Y18,0)/1000 -> #REF! | AA18: =AA17+Z18 -> #REF! | AB18: =(M18-$M$13-R18)/1000 -> #REF!
A19: =A18+1 -> 5 | B19: ='115+040'!#REF! -> #REF! | C19: =B19-B18 -> #REF! | D19: =D18 -> #REF! | E19: =VLOOKUP(B19,'115+040'!B17:AB118,3,FALSE) -> #REF! | F19: =D19+E19 -> #REF! | G19: =VLOOKUP(B19,'115+040'!$B$12:$AB$112,20,FALSE) -> #REF! | H19: =VLOOKUP(B19,'115+040'!$B$12:$AB$112,4,FALSE) -> #REF! | I19: =F19-H19 -> #REF! | J19: =VLOOKUP(B19,'115+040'!$B$12:$AB$112,13,FALSE) -> #REF! | K19: ='115+040'!R17 -> 0 | L19: =+K19+L18 -> 0 | M19: =VLOOKUP(B19,'115+040'!$B$11:$AB$112,21,FALSE) -> #REF! | N19: =VLOOKUP(B19,'115+040'!$B$12:$AB$112,5,FALSE) -> #REF! | O19: =F19-N19 -> #REF! | P19: =VLOOKUP(B19,'115+040'!$B$12:$AB$112,14,FALSE) -> #REF! | Q19: ='115+040'!S17 -> 0 | R19: =+Q19+R18 -> 0 | S19: =VLOOKUP(B19,'115+040'!$B$11:$AB$112,22,FALSE) -> #REF! | T19: =VLOOKUP(B19,'115+040'!$B$12:$AB$112,6,FALSE) -> #REF! | U19: =F19-T19 -> #REF! | V19: =VLOOKUP(B19,'115+040'!$B$12:$AB$112,15,FALSE) -> #REF! | W19: ='[4]114+940'!S20 -> 0 | X19: =+W19+X18 -> 0 | Y19: =S19-S18 -> #REF! | Z19: =IF(Y19>0,Y19,0)/1000 -> #REF! | AA19: =AA18+Z19 -> #REF! | AB19: =(M19-$M$13-R19)/1000 -> #REF!
A20: =A19+1 -> 6 | B20: ='115+040'!#REF! -> #REF! | C20: =B20-B19 -> #REF! | D20: =D19 -> #REF! | E20: =VLOOKUP(B20,'115+040'!B18:AB119,3,FALSE) -> #REF! | F20: =D20+E20 -> #REF! | G20: =VLOOKUP(B20,'115+040'!$B$12:$AB$112,20,FALSE) -> #REF! | H20: =VLOOKUP(B20,'115+040'!$B$12:$AB$112,4,FALSE) -> #REF! | I20: =F20-H20 -> #REF! | J20: =VLOOKUP(B20,'115+040'!$B$12:$AB$112,13,FALSE) -> #REF! | K20: ='115+040'!R18 -> 0 | L20: =+K20+L19 -> 0 | M20: =VLOOKUP(B20,'115+040'!$B$11:$AB$112,21,FALSE) -> #REF! | N20: =VLOOKUP(B20,'115+040'!$B$12:$AB$112,5,FALSE) -> #REF! | O20: =F20-N20 -> #REF! | P20: =VLOOKUP(B20,'115+040'!$B$12:$AB$112,14,FALSE) -> #REF! | Q20: ='115+040'!S18 -> 0 | R20: =+Q20+R19 -> 0 | S20: =VLOOKUP(B20,'115+040'!$B$11:$AB$112,22,FALSE) -> #REF! | T20: =VLOOKUP(B20,'115+040'!$B$12:$AB$112,6,FALSE) -> #REF! | U20: =F20-T20 -> #REF! | V20: =VLOOKUP(B20,'115+040'!$B$12:$AB$112,15,FALSE) -> #REF! | W20: ='[4]114+940'!S21 -> 0 | X20: =+W20+X19 -> 0 | Y20: =S20-S19 -> #REF! | Z20: =IF(Y20>0,Y20,0)/1000 -> #REF! | AA20: =AA19+Z20 -> #REF! | AB20: =(M20-$M$13-R20)/1000 -> #REF!
A21: =A20+1 -> 7 | B21: ='115+040'!#REF! -> #REF! | C21: =B21-B20 -> #REF! | D21: =D20 -> #REF! | E21: =VLOOKUP(B21,'115+040'!B19:AB120,3,FALSE) -> #REF! | F21: =D21+E21 -> #REF! | G21: =VLOOKUP(B21,'115+040'!$B$12:$AB$112,20,FALSE) -> #REF! | H21: =VLOOKUP(B21,'115+040'!$B$12:$AB$112,4,FALSE) -> #REF! | I21: =F21-H21 -> #REF! | J21: =VLOOKUP(B21,'115+040'!$B$12:$AB$112,13,FALSE) -> #REF! | K21: ='115+040'!R19 -> 0 | L21: =+K21+L20 -> 0 | M21: =VLOOKUP(B21,'115+040'!$B$11:$AB$112,21,FALSE) -> #REF! | N21: =VLOOKUP(B21,'115+040'!$B$12:$AB$112,5,FALSE) -> #REF! | O21: =F21-N21 -> #REF! | P21: =VLOOKUP(B21,'115+040'!$B$12:$AB$112,14,FALSE) -> #REF! | Q21: ='115+040'!S19 -> 0 | R21: =+Q21+R20 -> 0 | S21: =VLOOKUP(B21,'115+040'!$B$11:$AB$112,22,FALSE) -> #REF! | T21: =VLOOKUP(B21,'115+040'!$B$12:$AB$112,6,FALSE) -> #REF! | U21: =F21-T21 -> #REF! | V21: =VLOOKUP(B21,'115+040'!$B$12:$AB$112,15,FALSE) -> #REF! | W21: ='[4]114+940'!S22 -> 0 | X21: =+W21+X20 -> 0 | Y21: =S21-S20 -> #REF! | Z21: =IF(Y21>0,Y21,0)/1000 -> #REF! | AA21: =AA20+Z21 -> #REF! | AB21: =(M21-$M$13-R21)/1000 -> #REF!
B22: ='115+040'!#REF! -> #REF! | C22: =B22-B21 -> #REF! | D22: =D21 -> #REF! | E22: =VLOOKUP(B22,'115+040'!B20:AB121,3,FALSE) -> #REF! | F22: =D22+E22 -> #REF! | G22: =VLOOKUP(B22,'115+040'!$B$12:$AB$112,20,FALSE) -> #REF! | H22: =VLOOKUP(B22,'115+040'!$B$12:$AB$112,4,FALSE) -> #REF! | I22: =F22-H22 -> #REF! | J22: =VLOOKUP(B22,'115+040'!$B$12:$AB$112,13,FALSE) -> #REF! | K22: ='115+040'!R20 -> 0 | L22: =+K22+L21 -> 0 | M22: =VLOOKUP(B22,'115+040'!$B$11:$AB$112,21,FALSE) -> #REF! | N22: =VLOOKUP(B22,'115+040'!$B$12:$AB$112,5,FALSE) -> #REF! | O22: =F22-N22 -> #REF! | P22: =VLOOKUP(B22,'115+040'!$B$12:$AB$112,14,FALSE) -> #REF! | Q22: ='115+040'!S20 -> 0 | R22: =+Q22+R21 -> 0 | S22: =VLOOKUP(B22,'115+040'!$B$11:$AB$112,22,FALSE) -> #REF! | T22: =VLOOKUP(B22,'115+040'!$B$12:$AB$112,6,FALSE) -> #REF! | U22: =F22-T22 -> #REF! | V22: =VLOOKUP(B22,'115+040'!$B$12:$AB$112,15,FALSE) -> #REF! | W22: ='[4]114+940'!S23 -> 0 | X22: =+W22+X21 -> 0 | Y22: =S22-S21 -> #REF! | Z22: =IF(Y22>0,Y22,0)/1000 -> #REF! | AA22: =AA21+Z22 -> #REF! | AB22: =(M22-$M$13-R22)/1000 -> #REF!
B23: ='115+040'!#REF! -> #REF! | C23: =B23-B22 -> #REF! | D23: =D22 -> #REF! | E23: =VLOOKUP(B23,'115+040'!B21:AB122,3,FALSE) -> #REF! | F23: =D23+E23 -> #REF! | G23: =VLOOKUP(B23,'115+040'!$B$12:$AB$112,20,FALSE) -> #REF! | H23: =VLOOKUP(B23,'115+040'!$B$12:$AB$112,4,FALSE) -> #REF! | I23: =F23-H23 -> #REF! | J23: =VLOOKUP(B23,'115+040'!$B$12:$AB$112,13,FALSE) -> #REF! | K23: ='115+040'!R21 -> 0 | L23: =+K23+L22 -> 0 | M23: =VLOOKUP(B23,'115+040'!$B$11:$AB$112,21,FALSE) -> #REF! | N23: =VLOOKUP(B23,'115+040'!$B$12:$AB$112,5,FALSE) -> #REF! | O23: =F23-N23 -> #REF! | P23: =VLOOKUP(B23,'115+040'!$B$12:$AB$112,14,FALSE) -> #REF! | Q23: ='115+040'!S21 -> 0 | R23: =+Q23+R22 -> 0 | S23: =VLOOKUP(B23,'115+040'!$B$11:$AB$112,22,FALSE) -> #REF! | T23: =VLOOKUP(B23,'115+040'!$B$12:$AB$112,6,FALSE) -> #REF! | U23: =F23-T23 -> #REF! | V23: =VLOOKUP(B23,'115+040'!$B$12:$AB$112,15,FALSE) -> #REF! | W23: ='[4]114+940'!S24 -> 0 | X23: =+W23+X22 -> 0 | Y23: =S23-S22 -> #REF! | Z23: =IF(Y23>0,Y23,0)/1000 -> #REF! | AA23: =AA22+Z23 -> #REF! | AB23: =(M23-$M$13-R23)/1000 -> #REF!
B24: ='115+040'!#REF! -> #REF! | C24: =B24-B23 -> #REF! | D24: =D23 -> #REF! | E24: =VLOOKUP(B24,'115+040'!B22:AB123,3,FALSE) -> #REF! | F24: =D24+E24 -> #REF! | G24: =VLOOKUP(B24,'115+040'!$B$12:$AB$112,20,FALSE) -> #REF! | H24: =VLOOKUP(B24,'115+040'!$B$12:$AB$112,4,FALSE) -> #REF! | I24: =F24-H24 -> #REF! | J24: =VLOOKUP(B24,'115+040'!$B$12:$AB$112,13,FALSE) -> #REF! | K24: ='115+040'!R22 -> 0 | L24: =+K24+L23 -> 0 | M24: =VLOOKUP(B24,'115+040'!$B$11:$AB$112,21,FALSE) -> #REF! | N24: =VLOOKUP(B24,'115+040'!$B$12:$AB$112,5,FALSE) -> #REF! | O24: =F24-N24 -> #REF! | P24: =VLOOKUP(B24,'115+040'!$B$12:$AB$112,14,FALSE) -> #REF! | Q24: ='115+040'!S22 -> 0 | R24: =+Q24+R23 -> 0 | S24: =VLOOKUP(B24,'115+040'!$B$11:$AB$112,22,FALSE) -> #REF! | T24: =VLOOKUP(B24,'115+040'!$B$12:$AB$112,6,FALSE) -> #REF! | U24: =F24-T24 -> #REF! | V24: =VLOOKUP(B24,'115+040'!$B$12:$AB$112,15,FALSE) -> #REF! | W24: ='[4]114+940'!S25 -> 0 | X24: =+W24+X23 -> 0 | Y24: =S24-S23 -> #REF! | Z24: =IF(Y24>0,Y24,0)/1000 -> #REF! | AA24: =AA23+Z24 -> #REF! | AB24: =(M24-$M$13-R24)/1000 -> #REF!
B25: ='115+040'!#REF! -> #REF! | C25: =B25-B24 -> #REF! | D25: =D24 -> #REF! | E25: =VLOOKUP(B25,'115+040'!B23:AB124,3,FALSE) -> #REF! | F25: =D25+E25 -> #REF! | G25: =VLOOKUP(B25,'115+040'!$B$12:$AB$112,20,FALSE) -> #REF! | H25: =VLOOKUP(B25,'115+040'!$B$12:$AB$112,4,FALSE) -> #REF! | I25: =F25-H25 -> #REF! | J25: =VLOOKUP(B25,'115+040'!$B$12:$AB$112,13,FALSE) -> #REF! | K25: ='115+040'!R23 -> 0 | L25: =+K25+L24 -> 0 | M25: =VLOOKUP(B25,'115+040'!$B$11:$AB$112,21,FALSE) -> #REF! | N25: =VLOOKUP(B25,'115+040'!$B$12:$AB$112,5,FALSE) -> #REF! | O25: =F25-N25 -> #REF! | P25: =VLOOKUP(B25,'115+040'!$B$12:$AB$112,14,FALSE) -> #REF! | Q25: ='115+040'!S23 -> 0 | R25: =+Q25+R24 -> 0 | S25: =VLOOKUP(B25,'115+040'!$B$11:$AB$112,22,FALSE) -> #REF! | T25: =VLOOKUP(B25,'115+040'!$B$12:$AB$112,6,FALSE) -> #REF! | U25: =F25-T25 -> #REF! | V25: =VLOOKUP(B25,'115+040'!$B$12:$AB$112,15,FALSE) -> #REF! | W25: ='[4]114+940'!S26 -> 0 | X25: =+W25+X24 -> 0 | Y25: =S25-S24 -> #REF! | Z25: =IF(Y25>0,Y25,0)/1000 -> #REF! | AA25: =AA24+Z25 -> #REF! | AB25: =(M25-$M$13-R25)/1000 -> #REF!
B26: ='115+040'!#REF! -> #REF! | C26: =B26-B25 -> #REF! | D26: =D25 -> #REF! | E26: =VLOOKUP(B26,'115+040'!B24:AB125,3,FALSE) -> #REF! | F26: =D26+E26 -> #REF! | G26: =VLOOKUP(B26,'115+040'!$B$12:$AB$112,20,FALSE) -> #REF! | H26: =VLOOKUP(B26,'115+040'!$B$12:$AB$112,4,FALSE) -> #REF! | I26: =F26-H26 -> #REF! | J26: =VLOOKUP(B26,'115+040'!$B$12:$AB$112,13,FALSE) -> #REF! | K26: ='115+040'!R24 -> 0 | L26: =+K26+L25 -> 0 | M26: =VLOOKUP(B26,'115+040'!$B$11:$AB$112,21,FALSE) -> #REF! | N26: =VLOOKUP(B26,'115+040'!$B$12:$AB$112,5,FALSE) -> #REF! | O26: =F26-N26 -> #REF! | P26: =VLOOKUP(B26,'115+040'!$B$12:$AB$112,14,FALSE) -> #REF! | Q26: ='115+040'!S24 -> 0 | R26: =+Q26+R25 -> 0 | S26: =VLOOKUP(B26,'115+040'!$B$11:$AB$112,22,FALSE) -> #REF! | T26: =VLOOKUP(B26,'115+040'!$B$12:$AB$112,6,FALSE) -> #REF! | U26: =F26-T26 -> #REF! | V26: =VLOOKUP(B26,'115+040'!$B$12:$AB$112,15,FALSE) -> #REF! | W26: ='[4]114+940'!S27 -> 0 | X26: =+W26+X25 -> 0 | Y26: =S26-S25 -> #REF! | Z26: =IF(Y26>0,Y26,0)/1000 -> #REF! | AA26: =AA25+Z26 -> #REF! | AB26: =(M26-$M$13-R26)/1000 -> #REF!
B27: ='115+040'!#REF! -> #REF! | C27: =B27-B26 -> #REF! | D27: =D26 -> #REF! | E27: =VLOOKUP(B27,'115+040'!B25:AB126,3,FALSE) -> #REF! | F27: =D27+E27 -> #REF! | G27: =VLOOKUP(B27,'115+040'!$B$12:$AB$112,20,FALSE) -> #REF! | H27: =VLOOKUP(B27,'115+040'!$B$12:$AB$112,4,FALSE) -> #REF! | I27: =F27-H27 -> #REF! | J27: =VLOOKUP(B27,'115+040'!$B$12:$AB$112,13,FALSE) -> #REF! | K27: ='115+040'!R25 -> 0 | L27: =+K27+L26 -> 0 | M27: =VLOOKUP(B27,'115+040'!$B$11:$AB$112,21,FALSE) -> #REF! | N27: =VLOOKUP(B27,'115+040'!$B$12:$AB$112,5,FALSE) -> #REF! | O27: =F27-N27 -> #REF! | P27: =VLOOKUP(B27,'115+040'!$B$12:$AB$112,14,FALSE) -> #REF! | Q27: ='115+040'!S25 -> 0 | R27: =+Q27+R26 -> 0 | S27: =VLOOKUP(B27,'115+040'!$B$11:$AB$112,22,FALSE) -> #REF! | T27: =VLOOKUP(B27,'115+040'!$B$12:$AB$112,6,FALSE) -> #REF! | U27: =F27-T27 -> #REF! | V27: =VLOOKUP(B27,'115+040'!$B$12:$AB$112,15,FALSE) -> #REF! | W27: ='[4]114+940'!S28 -> 0 | X27: =+W27+X26 -> 0 | Y27: =S27-S26 -> #REF! | Z27: =IF(Y27>0,Y27,0)/1000 -> #REF! | AA27: =AA26+Z27 -> #REF! | AB27: =(M27-$M$13-R27)/1000 -> #REF!
B28: ='115+040'!#REF! -> #REF! | C28: =B28-B27 -> #REF! | D28: =D27 -> #REF! | E28: =VLOOKUP(B28,'115+040'!B26:AB127,3,FALSE) -> #REF! | F28: =D28+E28 -> #REF! | G28: =VLOOKUP(B28,'115+040'!$B$12:$AB$112,20,FALSE) -> #REF! | H28: =VLOOKUP(B28,'115+040'!$B$12:$AB$112,4,FALSE) -> #REF! | I28: =F28-H28 -> #REF! | J28: =VLOOKUP(B28,'115+040'!$B$12:$AB$112,13,FALSE) -> #REF! | K28: ='115+040'!R26 -> 0 | L28: =+K28+L27 -> 0 | M28: =VLOOKUP(B28,'115+040'!$B$11:$AB$112,21,FALSE) -> #REF! | N28: =VLOOKUP(B28,'115+040'!$B$12:$AB$112,5,FALSE) -> #REF! | O28: =F28-N28 -> #REF! | P28: =VLOOKUP(B28,'115+040'!$B$12:$AB$112,14,FALSE) -> #REF! | Q28: ='115+040'!S26 -> 0 | R28: =+Q28+R27 -> 0 | S28: =VLOOKUP(B28,'115+040'!$B$11:$AB$112,22,FALSE) -> #REF! | T28: =VLOOKUP(B28,'115+040'!$B$12:$AB$112,6,FALSE) -> #REF! | U28: =F28-T28 -> #REF! | V28: =VLOOKUP(B28,'115+040'!$B$12:$AB$112,15,FALSE) -> #REF! | W28: ='[4]114+940'!S29 -> 0 | X28: =+W28+X27 -> 0 | Y28: =S28-S27 -> #REF! | Z28: =IF(Y28>0,Y28,0)/1000 -> #REF! | AA28: =AA27+Z28 -> #REF! | AB28: =(M28-$M$13-R28)/1000 -> #REF!
B29: ='115+040'!#REF! -> #REF! | C29: =B29-B28 -> #REF! | D29: =D28 -> #REF! | E29: =VLOOKUP(B29,'115+040'!B27:AB128,3,FALSE) -> #REF! | F29: =D29+E29 -> #REF! | G29: =VLOOKUP(B29,'115+040'!$B$12:$AB$112,20,FALSE) -> #REF! | H29: =VLOOKUP(B29,'115+040'!$B$12:$AB$112,4,FALSE) -> #REF! | I29: =F29-H29 -> #REF! | J29: =VLOOKUP(B29,'115+040'!$B$12:$AB$112,13,FALSE) -> #REF! | K29: ='115+040'!R27 -> 0 | L29: =+K29+L28 -> 0 | M29: =VLOOKUP(B29,'115+040'!$B$11:$AB$112,21,FALSE) -> #REF! | N29: =VLOOKUP(B29,'115+040'!$B$12:$AB$112,5,FALSE) -> #REF! | O29: =F29-N29 -> #REF! | P29: =VLOOKUP(B29,'115+040'!$B$12:$AB$112,14,FALSE) -> #REF! | Q29: ='115+040'!S27 -> 0 | R29: =+Q29+R28 -> 0 | S29: =VLOOKUP(B29,'115+040'!$B$11:$AB$112,22,FALSE) -> #REF! | T29: =VLOOKUP(B29,'115+040'!$B$12:$AB$112,6,FALSE) -> #REF! | U29: =F29-T29 -> #REF! | V29: =VLOOKUP(B29,'115+040'!$B$12:$AB$112,15,FALSE) -> #REF! | W29: ='[4]114+940'!S30 -> 0 | X29: =+W29+X28 -> 0 | Y29: =S29-S28 -> #REF! | Z29: =IF(Y29>0,Y29,0)/1000 -> #REF! | AA29: =AA28+Z29 -> #REF! | AB29: =(M29-$M$13-R29)/1000 -> #REF!
B30: ='115+040'!#REF! -> #REF! | C30: =B30-B29 -> #REF! | D30: =D29 -> #REF! | E30: =VLOOKUP(B30,'115+040'!B28:AB129,3,FALSE) -> #REF! | F30: =D30+E30 -> #REF! | G30: =VLOOKUP(B30,'115+040'!$B$12:$AB$112,20,FALSE) -> #REF! | H30: =VLOOKUP(B30,'115+040'!$B$12:$AB$112,4,FALSE) -> #REF! | I30: =F30-H30 -> #REF! | J30: =VLOOKUP(B30,'115+040'!$B$12:$AB$112,13,FALSE) -> #REF! | K30: ='115+040'!R28 -> 7 | L30: =+K30+L29 -> 7 | M30: =VLOOKUP(B30,'115+040'!$B$11:$AB$112,21,FALSE) -> #REF! | N30: =VLOOKUP(B30,'115+040'!$B$12:$AB$112,5,FALSE) -> #REF! | O30: =F30-N30 -> #REF! | P30: =VLOOKUP(B30,'115+040'!$B$12:$AB$112,14,FALSE) -> #REF! | Q30: ='115+040'!S28 -> 8 | R30: =+Q30+R29 -> 8 | S30: =VLOOKUP(B30,'115+040'!$B$11:$AB$112,22,FALSE) -> #REF! | T30: =VLOOKUP(B30,'115+040'!$B$12:$AB$112,6,FALSE) -> #REF! | U30: =F30-T30 -> #REF! | V30: =VLOOKUP(B30,'115+040'!$B$12:$AB$112,15,FALSE) -> #REF! | W30: ='[4]114+940'!S31 -> 0 | X30: =+W30+X29 -> 0 | Y30: =S30-S29 -> #REF! | Z30: =IF(Y30>0,Y30,0)/1000 -> #REF! | AA30: =AA29+Z30 -> #REF! | AB30: =(M30-$M$13-R30)/1000 -> #REF!
B31: ='115+040'!#REF! -> #REF! | C31: =B31-B30 -> #REF! | D31: =D30 -> #REF! | E31: =VLOOKUP(B31,'115+040'!B29:AB130,3,FALSE) -> #REF! | F31: =D31+E31 -> #REF! | G31: =VLOOKUP(B31,'115+040'!$B$12:$AB$112,20,FALSE) -> #REF! | H31: =VLOOKUP(B31,'115+040'!$B$12:$AB$112,4,FALSE) -> #REF! | I31: =F31-H31 -> #REF! | J31: =VLOOKUP(B31,'115+040'!$B$12:$AB$112,13,FALSE) -> #REF! | K31: ='115+040'!R29 -> 3 | L31: =+K31+L30 -> 10 | M31: =VLOOKUP(B31,'115+040'!$B$11:$AB$112,21,FALSE) -> #REF! | N31: =VLOOKUP(B31,'115+040'!$B$12:$AB$112,5,FALSE) -> #REF! | O31: =F31-N31 -> #REF! | P31: =VLOOKUP(B31,'115+040'!$B$12:$AB$112,14,FALSE) -> #REF! | Q31: ='115+040'!S29 -> 3 | R31: =+Q31+R30 -> 11 | S31: =VLOOKUP(B31,'115+040'!$B$11:$AB$112,22,FALSE) -> #REF! | T31: =VLOOKUP(B31,'115+040'!$B$12:$AB$112,6,FALSE) -> #REF! | U31: =F31-T31 -> #REF! | V31: =VLOOKUP(B31,'115+040'!$B$12:$AB$112,15,FALSE) -> #REF! | W31: ='[4]114+940'!S32 -> 0 | X31: =+W31+X30 -> 0 | Y31: =S31-S30 -> #REF! | Z31: =IF(Y31>0,Y31,0)/1000 -> #REF! | AA31: =AA30+Z31 -> #REF! | AB31: =(M31-$M$13-R31)/1000 -> #REF!
B32: ='115+040'!#REF! -> #REF! | C32: =B32-B31 -> #REF! | D32: =D31 -> #REF! | E32: =VLOOKUP(B32,'115+040'!B30:AB131,3,FALSE) -> #REF! | F32: =D32+E32 -> #REF! | G32: =VLOOKUP(B32,'115+040'!$B$12:$AB$112,20,FALSE) -> #REF! | H32: =VLOOKUP(B32,'115+040'!$B$12:$AB$112,4,FALSE) -> #REF! | I32: =F32-H32 -> #REF! | J32: =VLOOKUP(B32,'115+040'!$B$12:$AB$112,13,FALSE) -> #REF! | K32: ='115+040'!R30 -> 4 | L32: =+K32+L31 -> 14 | M32: =VLOOKUP(B32,'115+040'!$B$11:$AB$112,21,FALSE) -> #REF! | N32: =VLOOKUP(B32,'115+040'!$B$12:$AB$112,5,FALSE) -> #REF! | O32: =F32-N32 -> #REF! | P32: =VLOOKUP(B32,'115+040'!$B$12:$AB$112,14,FALSE) -> #REF! | Q32: ='115+040'!S30 -> 4 | R32: =+Q32+R31 -> 15 | S32: =VLOOKUP(B32,'115+040'!$B$11:$AB$112,22,FALSE) -> #REF! | T32: =VLOOKUP(B32,'115+040'!$B$12:$AB$112,6,FALSE) -> #REF! | U32: =F32-T32 -> #REF! | V32: =VLOOKUP(B32,'115+040'!$B$12:$AB$112,15,FALSE) -> #REF! | W32: ='[4]114+940'!S33 -> 0 | X32: =+W32+X31 -> 0 | Y32: =S32-S31 -> #REF! | Z32: =IF(Y32>0,Y32,0)/1000 -> #REF! | AA32: =AA31+Z32 -> #REF! | AB32: =(M32-$M$13-R32)/1000 -> #REF!
B33: ='115+040'!#REF! -> #REF! | C33: =B33-B32 -> #REF! | D33: =D32 -> #REF! | E33: =VLOOKUP(B33,'115+040'!B31:AB132,3,FALSE) -> #REF! | F33: =D33+E33 -> #REF! | G33: =VLOOKUP(B33,'115+040'!$B$12:$AB$112,20,FALSE) -> #REF! | H33: =VLOOKUP(B33,'115+040'!$B$12:$AB$112,4,FALSE) -> #REF! | I33: =F33-H33 -> #REF! | J33: =VLOOKUP(B33,'115+040'!$B$12:$AB$112,13,FALSE) -> #REF! | K33: ='115+040'!R31 -> 5 | L33: =+K33+L32 -> 19 | M33: =VLOOKUP(B33,'115+040'!$B$11:$AB$112,21,FALSE) -> #REF! | N33: =VLOOKUP(B33,'115+040'!$B$12:$AB$112,5,FALSE) -> #REF! | O33: =F33-N33 -> #REF! | P33: =VLOOKUP(B33,'115+040'!$B$12:$AB$112,14,FALSE) -> #REF! | Q33: ='115+040'!S31 -> 2 | R33: =+Q33+R32 -> 17 | S33: =VLOOKUP(B33,'115+040'!$B$11:$AB$112,22,FALSE) -> #REF! | T33: =VLOOKUP(B33,'115+040'!$B$12:$AB$112,6,FALSE) -> #REF! | U33: =F33-T33 -> #REF! | V33: =VLOOKUP(B33,'115+040'!$B$12:$AB$112,15,FALSE) -> #REF! | W33: ='[4]114+940'!S34 -> 0 | X33: =+W33+X32 -> 0 | Y33: =S33-S32 -> #REF! | Z33: =IF(Y33>0,Y33,0)/1000 -> #REF! | AA33: =AA32+Z33 -> #REF! | AB33: =(M33-$M$13-R33)/1000 -> #REF!
... B76: ='115+040'!#REF! -> #REF! | C76: =B76-B75 -> #REF! | D76: =D75 -> #REF! | E76: =VLOOKUP(B76,'115+040'!B74:AB175,3,FALSE) -> #REF! | F76: =D76+E76 -> #REF! | G76: =VLOOKUP(B76,'115+040'!$B$12:$AB$112,20,FALSE) -> #REF! | H76: =VLOOKUP(B76,'115+040'!$B$12:$AB$112,4,FALSE) -> #REF! | I76: =F76-H76 -> #REF! | J76: =VLOOKUP(B76,'115+040'!$B$12:$AB$112,13,FALSE) -> #REF! | K76: ='115+040'!R74 -> 5 | L76: =+K76+L75 -> 189 | M76: =VLOOKUP(B76,'115+040'!$B$11:$AB$112,21,FALSE) -> #REF! | N76: =VLOOKUP(B76,'115+040'!$B$12:$AB$112,5,FALSE) -> #REF! | O76: =F76-N76 -> #REF! | P76: =VLOOKUP(B76,'115+040'!$B$12:$AB$112,14,FALSE) -> #REF! | Q76: ='115+040'!S74 -> 5 | R76: =+Q76+R75 -> 191 | S76: =VLOOKUP(B76,'115+040'!$B$11:$AB$112,22,FALSE) -> #REF! | T76: =VLOOKUP(B76,'115+040'!$B$12:$AB$112,6,FALSE) -> #REF! | U76: =F76-T76 -> #REF! | V76: =VLOOKUP(B76,'115+040'!$B$12:$AB$112,15,FALSE) -> #REF! | W76: ='[4]114+940'!S77 -> 0 | X76: =+W76+X75 -> 144 | Y76: =S76-S75 -> #REF! | Z76: =IF(Y76>0,Y76,0)/1000 -> #REF! | AA76: =AA75+Z76 -> #REF! | AB76: =(M76-$M$13-R76)/1000 -> #REF!
A77: 42307 | B77: ='115+040'!#REF! -> #REF! | C77: =B77-B76 -> #REF! | D77: =D76 -> #REF! | E77: =VLOOKUP(B77,'115+040'!B75:AB176,3,FALSE) -> #REF! | F77: =D77+E77 -> #REF! | G77: =VLOOKUP(B77,'115+040'!$B$12:$AB$112,20,FALSE) -> #REF! | H77: =VLOOKUP(B77,'115+040'!$B$12:$AB$112,4,FALSE) -> #REF! | I77: =F77-H77 -> #REF! | J77: =VLOOKUP(B77,'115+040'!$B$12:$AB$112,13,FALSE) -> #REF! | K77: ='115+040'!R75 -> 5 | L77: =+K77+L76 -> 194 | M77: =VLOOKUP(B77,'115+040'!$B$11:$AB$112,21,FALSE) -> #REF! | N77: =VLOOKUP(B77,'115+040'!$B$12:$AB$112,5,FALSE) -> #REF! | O77: =F77-N77 -> #REF! | P77: =VLOOKUP(B77,'115+040'!$B$12:$AB$112,14,FALSE) -> #REF! | Q77: ='115+040'!S75 -> 5 | R77: =+Q77+R76 -> 196 | S77: =VLOOKUP(B77,'115+040'!$B$11:$AB$112,22,FALSE) -> #REF! | T77: =VLOOKUP(B77,'115+040'!$B$12:$AB$112,6,FALSE) -> #REF! | U77: =F77-T77 -> #REF! | V77: =VLOOKUP(B77,'115+040'!$B$12:$AB$112,15,FALSE) -> #REF! | W77: ='[4]114+940'!S78 -> 0 | X77: =+W77+X76 -> 144 | Y77: =S77-S76 -> #REF! | Z77: =IF(Y77>0,Y77,0)/1000 -> #REF! | AA77: =AA76+Z77 -> #REF! | AB77: =(M77-$M$13-R77)/1000 -> #REF!
A78: 02/11/015 | B78: ='115+040'!#REF! -> #REF! | C78: =B78-B77 -> #REF! | D78: =D77 -> #REF! | E78: =VLOOKUP(B78,'115+040'!B76:AB177,3,FALSE) -> #REF! | F78: =D78+E78 -> #REF! | G78: =VLOOKUP(B78,'115+040'!$B$12:$AB$112,20,FALSE) -> #REF! | H78: =VLOOKUP(B78,'115+040'!$B$12:$AB$112,4,FALSE) -> #REF! | I78: =F78-H78 -> #REF! | J78: =VLOOKUP(B78,'115+040'!$B$12:$AB$112,13,FALSE) -> #REF! | K78: ='115+040'!R76 -> 5 | L78: =+K78+L77 -> 199 | M78: =VLOOKUP(B78,'115+040'!$B$11:$AB$112,21,FALSE) -> #REF! | N78: =VLOOKUP(B78,'115+040'!$B$12:$AB$112,5,FALSE) -> #REF! | O78: =F78-N78 -> #REF! | P78: =VLOOKUP(B78,'115+040'!$B$12:$AB$112,14,FALSE) -> #REF! | Q78: ='115+040'!S76 -> 5 | R78: =+Q78+R77 -> 201 | S78: =VLOOKUP(B78,'115+040'!$B$11:$AB$112,22,FALSE) -> #REF! | T78: =VLOOKUP(B78,'115+040'!$B$12:$AB$112,6,FALSE) -> #REF! | U78: =F78-T78 -> #REF! | V78: =VLOOKUP(B78,'115+040'!$B$12:$AB$112,15,FALSE) -> #REF! | W78: ='[4]114+940'!S79 -> 0 | X78: =+W78+X77 -> 144 | Y78: =S78-S77 -> #REF! | Z78: =IF(Y78>0,Y78,0)/1000 -> #REF! | AA78: =AA77+Z78 -> #REF! | AB78: =(M78-$M$13-R78)/1000 -> #REF!
A79: 42313 | B79: ='115+040'!#REF! -> #REF! | C79: =B79-B78 -> #REF! | D79: =D78 -> #REF! | E79: =VLOOKUP(B79,'115+040'!B77:AB178,3,FALSE) -> #REF! | F79: =D79+E79 -> #REF! | G79: =VLOOKUP(B79,'115+040'!$B$12:$AB$112,20,FALSE) -> #REF! | H79: =VLOOKUP(B79,'115+040'!$B$12:$AB$112,4,FALSE) -> #REF! | I79: =F79-H79 -> #REF! | J79: =VLOOKUP(B79,'115+040'!$B$12:$AB$112,13,FALSE) -> #REF! | K79: ='115+040'!R77 -> 5 | L79: =+K79+L78 -> 204 | M79: =VLOOKUP(B79,'115+040'!$B$11:$AB$112,21,FALSE) -> #REF! | N79: =VLOOKUP(B79,'115+040'!$B$12:$AB$112,5,FALSE) -> #REF! | O79: =F79-N79 -> #REF! | P79: =VLOOKUP(B79,'115+040'!$B$12:$AB$112,14,FALSE) -> #REF! | Q79: ='115+040'!S77 -> 5 | R79: =+Q79+R78 -> 206 | S79: =VLOOKUP(B79,'115+040'!$B$11:$AB$112,22,FALSE) -> #REF! | T79: =VLOOKUP(B79,'115+040'!$B$12:$AB$112,6,FALSE) -> #REF! | U79: =F79-T79 -> #REF! | V79: =VLOOKUP(B79,'115+040'!$B$12:$AB$112,15,FALSE) -> #REF! | W79: ='[4]114+940'!S80 -> 0 | X79: =+W79+X78 -> 144 | Y79: =S79-S78 -> #REF! | Z79: =IF(Y79>0,Y79,0)/1000 -> #REF! | AA79: =AA78+Z79 -> #REF! | AB79: =(M79-$M$13-R79)/1000 -> #REF!
A80: 42319 | B80: ='115+040'!#REF! -> #REF! | C80: =B80-B79 -> #REF! | D80: =D79 -> #REF! | E80: =VLOOKUP(B80,'115+040'!B78:AB179,3,FALSE) -> #REF! | F80: =D80+E80 -> #REF! | G80: =VLOOKUP(B80,'115+040'!$B$12:$AB$112,20,FALSE) -> #REF! | H80: =VLOOKUP(B80,'115+040'!$B$12:$AB$112,4,FALSE) -> #REF! | I80: =F80-H80 -> #REF! | J80: =VLOOKUP(B80,'115+040'!$B$12:$AB$112,13,FALSE) -> #REF! | K80: ='115+040'!R78 -> 5 | L80: =+K80+L79 -> 209 | M80: =VLOOKUP(B80,'115+040'!$B$11:$AB$112,21,FALSE) -> #REF! | N80: =VLOOKUP(B80,'115+040'!$B$12:$AB$112,5,FALSE) -> #REF! | O80: =F80-N80 -> #REF! | P80: =VLOOKUP(B80,'115+040'!$B$12:$AB$112,14,FALSE) -> #REF! | Q80: ='115+040'!S78 -> 5 | R80: =+Q80+R79 -> 211 | S80: =VLOOKUP(B80,'115+040'!$B$11:$AB$112,22,FALSE) -> #REF! | T80: =VLOOKUP(B80,'115+040'!$B$12:$AB$112,6,FALSE) -> #REF! | U80: =F80-T80 -> #REF! | V80: =VLOOKUP(B80,'115+040'!$B$12:$AB$112,15,FALSE) -> #REF! | W80: ='[4]114+940'!S81 -> 0 | X80: =+W80+X79 -> 144 | Y80: =S80-S79 -> #REF! | Z80: =IF(Y80>0,Y80,0)/1000 -> #REF! | AA80: =AA79+Z80 -> #REF! | AB80: =(M80-$M$13-R80)/1000 -> #REF!
A81: 42322 | B81: ='115+040'!#REF! -> #REF! | C81: =B81-B80 -> #REF! | D81: =D80 -> #REF! | E81: =VLOOKUP(B81,'115+040'!B79:AB180,3,FALSE) -> #REF! | F81: =D81+E81 -> #REF! | G81: =VLOOKUP(B81,'115+040'!$B$12:$AB$112,20,FALSE) -> #REF! | H81: =VLOOKUP(B81,'115+040'!$B$12:$AB$112,4,FALSE) -> #REF! | I81: =F81-H81 -> #REF! | J81: =VLOOKUP(B81,'115+040'!$B$12:$AB$112,13,FALSE) -> #REF! | K81: ='115+040'!R79 -> 5 | L81: =+K81+L80 -> 214 | M81: =VLOOKUP(B81,'115+040'!$B$11:$AB$112,21,FALSE) -> #REF! | N81: =VLOOKUP(B81,'115+040'!$B$12:$AB$112,5,FALSE) -> #REF! | O81: =F81-N81 -> #REF! | P81: =VLOOKUP(B81,'115+040'!$B$12:$AB$112,14,FALSE) -> #REF! | Q81: ='115+040'!S79 -> 5 | R81: =+Q81+R80 -> 216 | S81: =VLOOKUP(B81,'115+040'!$B$11:$AB$112,22,FALSE) -> #REF! | T81: =VLOOKUP(B81,'115+040'!$B$12:$AB$112,6,FALSE) -> #REF! | U81: =F81-T81 -> #REF! | V81: =VLOOKUP(B81,'115+040'!$B$12:$AB$112,15,FALSE) -> #REF! | W81: ='[4]114+940'!S82 -> 0 | X81: =+W81+X80 -> 144 | Y81: =S81-S80 -> #REF! | Z81: =IF(Y81>0,Y81,0)/1000 -> #REF! | AA81: =AA80+Z81 -> #REF! | AB81: =(M81-$M$13-R81)/1000 -> #REF!
A82: 17/11/015 | B82: ='115+040'!#REF! -> #REF! | C82: =B82-B81 -> #REF! | D82: =D81 -> #REF! | E82: =VLOOKUP(B82,'115+040'!B80:AB181,3,FALSE) -> #REF! | F82: =D82+E82 -> #REF! | G82: =VLOOKUP(B82,'115+040'!$B$12:$AB$112,20,FALSE) -> #REF! | H82: =VLOOKUP(B82,'115+040'!$B$12:$AB$112,4,FALSE) -> #REF! | I82: =F82-H82 -> #REF! | J82: =VLOOKUP(B82,'115+040'!$B$12:$AB$112,13,FALSE) -> #REF! | K82: ='115+040'!R80 -> 5 | L82: =+K82+L81 -> 219 | M82: =VLOOKUP(B82,'115+040'!$B$11:$AB$112,21,FALSE) -> #REF! | N82: =VLOOKUP(B82,'115+040'!$B$12:$AB$112,5,FALSE) -> #REF! | O82: =F82-N82 -> #REF! | P82: =VLOOKUP(B82,'115+040'!$B$12:$AB$112,14,FALSE) -> #REF! | Q82: ='115+040'!S80 -> 5 | R82: =+Q82+R81 -> 221 | S82: =VLOOKUP(B82,'115+040'!$B$11:$AB$112,22,FALSE) -> #REF! | T82: =VLOOKUP(B82,'115+040'!$B$12:$AB$112,6,FALSE) -> #REF! | U82: =F82-T82 -> #REF! | V82: =VLOOKUP(B82,'115+040'!$B$12:$AB$112,15,FALSE) -> #REF! | W82: ='[4]114+940'!S83 -> 0 | X82: =+W82+X81 -> 144 | Y82: =S82-S81 -> #REF! | Z82: =IF(Y82>0,Y82,0)/1000 -> #REF! | AA82: =AA81+Z82 -> #REF! | AB82: =(M82-$M$13-R82)/1000 -> #REF!
A83: 42328 | B83: ='115+040'!#REF! -> #REF! | C83: =B83-B82 -> #REF! | D83: =D82 -> #REF! | E83: =VLOOKUP(B83,'115+040'!B81:AB182,3,FALSE) -> #REF! | F83: =D83+E83 -> #REF! | G83: =VLOOKUP(B83,'115+040'!$B$12:$AB$112,20,FALSE) -> #REF! | H83: =VLOOKUP(B83,'115+040'!$B$12:$AB$112,4,FALSE) -> #REF! | I83: =F83-H83 -> #REF! | J83: =VLOOKUP(B83,'115+040'!$B$12:$AB$112,13,FALSE) -> #REF! | K83: ='115+040'!R81 -> 4 | L83: =+K83+L82 -> 223 | M83: =VLOOKUP(B83,'115+040'!$B$11:$AB$112,21,FALSE) -> #REF! | N83: =VLOOKUP(B83,'115+040'!$B$12:$AB$112,5,FALSE) -> #REF! | O83: =F83-N83 -> #REF! | P83: =VLOOKUP(B83,'115+040'!$B$12:$AB$112,14,FALSE) -> #REF! | Q83: ='115+040'!S81 -> 6 | R83: =+Q83+R82 -> 227 | S83: =VLOOKUP(B83,'115+040'!$B$11:$AB$112,22,FALSE) -> #REF! | T83: =VLOOKUP(B83,'115+040'!$B$12:$AB$112,6,FALSE) -> #REF! | U83: =F83-T83 -> #REF! | V83: =VLOOKUP(B83,'115+040'!$B$12:$AB$112,15,FALSE) -> #REF! | W83: ='[4]114+940'!S84 -> 0 | X83: =+W83+X82 -> 144 | Y83: =S83-S82 -> #REF! | Z83: =IF(Y83>0,Y83,0)/1000 -> #REF! | AA83: =AA82+Z83 -> #REF! | AB83: =(M83-$M$13-R83)/1000 -> #REF!
...

Sheet SL.115+040
A1: DỰ ÁN THÀNH PHẦN ĐOẠN HẬU GIANG - CÀ MAU
A2: THUỘC DỰ ÁN XÂY DỰNG CÔNG TRÌNH ĐƯỜNG BỘ CAO TỐC BẮC - NAM PHÍA ĐÔNG GIAI ĐOẠN 2021 - 2025
A3: =UPPER("GÓI THẦU XL03 :Thi Công Xây Dựng Đoạn Tuyến Km114+200 - Km126+223 Bao Gồm Tuyến Nối Nút Giao IC12 Với QL1 (bao gồm khảo sát, thiết kế BVTC)") -> GÓI THẦU XL03 :THI CÔNG XÂY DỰNG ĐOẠN TUYẾN KM114+200 - KM126+223 BAO GỒM TUYẾN NỐI NÚT GIAO IC12 VỚI QL1 (BAO GỒM KHẢO SÁT, THIẾT KẾ BVTC)
A4: CHỦ ĐẦU TƯ | F4: TƯ VẤN GIÁM SÁT | K4: NHÀ THẦU
A5: BAN QUẢN LÝ DỰ ÁN MỸ THUẬN | F5: =UPPER("Liên danh Phân viện KHCN GTVT phía Nam - Công ty Cổ phần Tư vấn kỹ thuật và xây dựng Hồng Hà") -> LIÊN DANH PHÂN VIỆN KHCN GTVT PHÍA NAM - CÔNG TY CỔ PHẦN TƯ VẤN KỸ THUẬT VÀ XÂY DỰNG HỒNG HÀ | K5: LIÊN DANH CC1 - HẢI ĐĂNG - VẠN CƯỜNG - 492 - BẮC TRUNG NAM
A6: BIỂU GHI ĐO QUAN TRẮC LÚN
A7: Người lập: | B7: ='[5]BC.95+020'!C7 -> 0 | K7: Tên mốc: | M7: ='[5]BC.95+020'!N7 -> 0
A8: Thời tiết: | B8: ='[5]BC.95+020'!C8 -> năng | K8: Cao độ mốc: | M8: ='115+040'!N6 -> 1069
A9: Lý trình: | B9: ='115+040'!C7 -> Km115+040 | K9: Ngày đặt bàn: | M9: ='115+040'!N7 -> 10/12/2023
A11: ="BÀN QUAN TRẮC: "&B9 -> BÀN QUAN TRẮC: Km115+040
A12: Ngày đo | B12: Số ngày | C12: Cao độ đắp(m) | D12: Chiều cao nền đắp (m) | E12: chiều dày đắp(m) | F12: Trái | H12: Giữa | J12: Phải | L12: Độ lún (trái) (mm) | M12: Độ lún (giữa) (mm) | N12: Độ lún (phải) (mm) | O12: Ghi chú
F13: Cao độ quan trắc | G13: Cao độ bàn đo lún | H13: Cao độ quan trắc | I13: Cao độ bàn đo lún | J13: Cao độ quan trắc | K13: Cao độ bàn đo lún
A14: ='BC.115+040'!B13 -> #REF! | B14: 0 | C14: ='BC.115+040'!M13/1000 -> #REF! | D14: ='BC.115+040'!AA13 -> 0 | E14: ='BC.115+040'!AB13 -> 0 | F14: =VLOOKUP($A14,'BC.115+040'!$B$13:$X$489,8,0)/1000 -> #REF! | G14: =VLOOKUP($A14,'BC.115+040'!$B$13:$X$489,9,0)/1000 -> #REF! | H14: =VLOOKUP($A14,'BC.115+040'!$B$13:$X$489,14,0)/1000 -> #REF! | I14: =VLOOKUP($A14,'BC.115+040'!$B$13:$X$489,15,0)/1000 -> #REF! | J14: =VLOOKUP($A14,'BC.115+040'!$B$13:$X$489,20,0)/1000 -> #REF! | K14: =VLOOKUP($A14,'BC.115+040'!$B$13:$X$489,21,0)/1000 -> #REF! | L14: =(G14-$G$14)*1000 -> #REF! | M14: =(I14-$I$14)*1000 -> #REF! | N14: 0
A15: ='BC.115+040'!B14 -> #REF! | B15: 1 | C15: ='BC.115+040'!M14/1000 -> #REF! | D15: ='BC.115+040'!AA14 -> #REF! | E15: ='BC.115+040'!AB14 -> #REF! | F15: =VLOOKUP($A15,'BC.115+040'!$B$13:$X$489,8,0)/1000 -> #REF! | G15: =VLOOKUP($A15,'BC.115+040'!$B$13:$X$489,9,0)/1000 -> #REF! | H15: =VLOOKUP($A15,'BC.115+040'!$B$13:$X$489,14,0)/1000 -> #REF! | I15: =VLOOKUP($A15,'BC.115+040'!$B$13:$X$489,15,0)/1000 -> #REF! | J15: =VLOOKUP($A15,'BC.115+040'!$B$13:$X$489,20,0)/1000 -> #REF! | K15: =VLOOKUP($A15,'BC.115+040'!$B$13:$X$489,21,0)/1000 -> #REF! | L15: =(G15-$G$14)*1000 -> #REF! | M15: =(I15-$I$14)*1000 -> #REF! | N15: =(K15-$K$14)*1000 -> #REF!
A16: ='BC.115+040'!B15 -> #REF! | B16: 2 | C16: ='BC.115+040'!M15/1000 -> #REF! | D16: ='BC.115+040'!AA15 -> #REF! | E16: ='BC.115+040'!AB15 -> #REF! | F16: =VLOOKUP($A16,'BC.115+040'!$B$13:$X$489,8,0)/1000 -> #REF! | G16: =VLOOKUP($A16,'BC.115+040'!$B$13:$X$489,9,0)/1000 -> #REF! | H16: =VLOOKUP($A16,'BC.115+040'!$B$13:$X$489,14,0)/1000 -> #REF! | I16: =VLOOKUP($A16,'BC.115+040'!$B$13:$X$489,15,0)/1000 -> #REF! | J16: =VLOOKUP($A16,'BC.115+040'!$B$13:$X$489,20,0)/1000 -> #REF! | K16: =VLOOKUP($A16,'BC.115+040'!$B$13:$X$489,21,0)/1000 -> #REF! | L16: =(G16-$G$14)*1000 -> #REF! | M16: =(I16-$I$14)*1000 -> #REF! | N16: =(K16-$K$14)*1000 -> #REF!
A17: ='BC.115+040'!B16 -> #REF! | B17: 3 | C17: ='BC.115+040'!M16/1000 -> #REF! | D17: ='BC.115+040'!AA16 -> #REF! | E17: ='BC.115+040'!AB16 -> #REF! | F17: =VLOOKUP($A17,'BC.115+040'!$B$13:$X$489,8,0)/1000 -> #REF! | G17: =VLOOKUP($A17,'BC.115+040'!$B$13:$X$489,9,0)/1000 -> #REF! | H17: =VLOOKUP($A17,'BC.115+040'!$B$13:$X$489,14,0)/1000 -> #REF! | I17: =VLOOKUP($A17,'BC.115+040'!$B$13:$X$489,15,0)/1000 -> #REF! | J17: =VLOOKUP($A17,'BC.115+040'!$B$13:$X$489,20,0)/1000 -> #REF! | K17: =VLOOKUP($A17,'BC.115+040'!$B$13:$X$489,21,0)/1000 -> #REF! | L17: =(G17-$G$14)*1000 -> #REF! | M17: =(I17-$I$14)*1000 -> #REF! | N17: =(K17-$K$14)*1000 -> #REF!
A18: ='BC.115+040'!B17 -> #REF! | B18: 4 | C18: ='BC.115+040'!M17/1000 -> #REF! | D18: ='BC.115+040'!AA17 -> #REF! | E18: ='BC.115+040'!AB17 -> #REF! | F18: =VLOOKUP($A18,'BC.115+040'!$B$13:$X$489,8,0)/1000 -> #REF! | G18: =VLOOKUP($A18,'BC.115+040'!$B$13:$X$489,9,0)/1000 -> #REF! | H18: =VLOOKUP($A18,'BC.115+040'!$B$13:$X$489,14,0)/1000 -> #REF! | I18: =VLOOKUP($A18,'BC.115+040'!$B$13:$X$489,15,0)/1000 -> #REF! | J18: =VLOOKUP($A18,'BC.115+040'!$B$13:$X$489,20,0)/1000 -> #REF! | K18: =VLOOKUP($A18,'BC.115+040'!$B$13:$X$489,21,0)/1000 -> #REF! | L18: =(G18-$G$14)*1000 -> #REF! | M18: =(I18-$I$14)*1000 -> #REF! | N18: =(K18-$K$14)*1000 -> #REF!
A19: ='BC.115+040'!B18 -> #REF! | B19: 5 | C19: ='BC.115+040'!M18/1000 -> #REF! | D19: ='BC.115+040'!AA18 -> #REF! | E19: ='BC.115+040'!AB18 -> #REF! | F19: =VLOOKUP($A19,'BC.115+040'!$B$13:$X$489,8,0)/1000 -> #REF! | G19: =VLOOKUP($A19,'BC.115+040'!$B$13:$X$489,9,0)/1000 -> #REF! | H19: =VLOOKUP($A19,'BC.115+040'!$B$13:$X$489,14,0)/1000 -> #REF! | I19: =VLOOKUP($A19,'BC.115+040'!$B$13:$X$489,15,0)/1000 -> #REF! | J19: =VLOOKUP($A19,'BC.115+040'!$B$13:$X$489,20,0)/1000 -> #REF! | K19: =VLOOKUP($A19,'BC.115+040'!$B$13:$X$489,21,0)/1000 -> #REF! | L19: =(G19-$G$14)*1000 -> #REF! | M19: =(I19-$I$14)*1000 -> #REF! | N19: =(K19-$K$14)*1000 -> #REF!
A20: ='BC.115+040'!B19 -> #REF! | B20: 6 | C20: ='BC.115+040'!M19/1000 -> #REF! | D20: ='BC.115+040'!AA19 -> #REF! | E20: ='BC.115+040'!AB19 -> #REF! | F20: =VLOOKUP($A20,'BC.115+040'!$B$13:$X$489,8,0)/1000 -> #REF! | G20: =VLOOKUP($A20,'BC.115+040'!$B$13:$X$489,9,0)/1000 -> #REF! | H20: =VLOOKUP($A20,'BC.115+040'!$B$13:$X$489,14,0)/1000 -> #REF! | I20: =VLOOKUP($A20,'BC.115+040'!$B$13:$X$489,15,0)/1000 -> #REF! | J20: =VLOOKUP($A20,'BC.115+040'!$B$13:$X$489,20,0)/1000 -> #REF! | K20: =VLOOKUP($A20,'BC.115+040'!$B$13:$X$489,21,0)/1000 -> #REF! | L20: =(G20-$G$14)*1000 -> #REF! | M20: =(I20-$I$14)*1000 -> #REF! | N20: =(K20-$K$14)*1000 -> #REF!
A21: ='BC.115+040'!B20 -> #REF! | B21: 7 | C21: ='BC.115+040'!M20/1000 -> #REF! | D21: ='BC.115+040'!AA20 -> #REF! | E21: ='BC.115+040'!AB20 -> #REF! | F21: =VLOOKUP($A21,'BC.115+040'!$B$13:$X$489,8,0)/1000 -> #REF! | G21: =VLOOKUP($A21,'BC.115+040'!$B$13:$X$489,9,0)/1000 -> #REF! | H21: =VLOOKUP($A21,'BC.115+040'!$B$13:$X$489,14,0)/1000 -> #REF! | I21: =VLOOKUP($A21,'BC.115+040'!$B$13:$X$489,15,0)/1000 -> #REF! | J21: =VLOOKUP($A21,'BC.115+040'!$B$13:$X$489,20,0)/1000 -> #REF! | K21: =VLOOKUP($A21,'BC.115+040'!$B$13:$X$489,21,0)/1000 -> #REF! | L21: =(G21-$G$14)*1000 -> #REF! | M21: =(I21-$I$14)*1000 -> #REF! | N21: =(K21-$K$14)*1000 -> #REF!
A22: ='BC.115+040'!B21 -> #REF! | B22: 8 | C22: ='BC.115+040'!M21/1000 -> #REF! | D22: ='BC.115+040'!AA21 -> #REF! | E22: ='BC.115+040'!AB21 -> #REF! | F22: =VLOOKUP($A22,'BC.115+040'!$B$13:$X$489,8,0)/1000 -> #REF! | G22: =VLOOKUP($A22,'BC.115+040'!$B$13:$X$489,9,0)/1000 -> #REF! | H22: =VLOOKUP($A22,'BC.115+040'!$B$13:$X$489,14,0)/1000 -> #REF! | I22: =VLOOKUP($A22,'BC.115+040'!$B$13:$X$489,15,0)/1000 -> #REF! | J22: =VLOOKUP($A22,'BC.115+040'!$B$13:$X$489,20,0)/1000 -> #REF! | K22: =VLOOKUP($A22,'BC.115+040'!$B$13:$X$489,21,0)/1000 -> #REF! | L22: =(G22-$G$14)*1000 -> #REF! | M22: =(I22-$I$14)*1000 -> #REF! | N22: =(K22-$K$14)*1000 -> #REF!
A23: ='BC.115+040'!B22 -> #REF! | B23: 9 | C23: ='BC.115+040'!M22/1000 -> #REF! | D23: ='BC.115+040'!AA22 -> #REF! | E23: ='BC.115+040'!AB22 -> #REF! | F23: =VLOOKUP($A23,'BC.115+040'!$B$13:$X$489,8,0)/1000 -> #REF! | G23: =VLOOKUP($A23,'BC.115+040'!$B$13:$X$489,9,0)/1000 -> #REF! | H23: =VLOOKUP($A23,'BC.115+040'!$B$13:$X$489,14,0)/1000 -> #REF! | I23: =VLOOKUP($A23,'BC.115+040'!$B$13:$X$489,15,0)/1000 -> #REF! | J23: =VLOOKUP($A23,'BC.115+040'!$B$13:$X$489,20,0)/1000 -> #REF! | K23: =VLOOKUP($A23,'BC.115+040'!$B$13:$X$489,21,0)/1000 -> #REF! | L23: =(G23-$G$14)*1000 -> #REF! | M23: =(I23-$I$14)*1000 -> #REF! | N23: =(K23-$K$14)*1000 -> #REF!
A24: ='BC.115+040'!B23 -> #REF! | B24: 10 | C24: ='BC.115+040'!M23/1000 -> #REF! | D24: ='BC.115+040'!AA23 -> #REF! | E24: ='BC.115+040'!AB23 -> #REF! | F24: =VLOOKUP($A24,'BC.115+040'!$B$13:$X$489,8,0)/1000 -> #REF! | G24: =VLOOKUP($A24,'BC.115+040'!$B$13:$X$489,9,0)/1000 -> #REF! | H24: =VLOOKUP($A24,'BC.115+040'!$B$13:$X$489,14,0)/1000 -> #REF! | I24: =VLOOKUP($A24,'BC.115+040'!$B$13:$X$489,15,0)/1000 -> #REF! | J24: =VLOOKUP($A24,'BC.115+040'!$B$13:$X$489,20,0)/1000 -> #REF! | K24: =VLOOKUP($A24,'BC.115+040'!$B$13:$X$489,21,0)/1000 -> #REF! | L24: =(G24-$G$14)*1000 -> #REF! | M24: =(I24-$I$14)*1000 -> #REF! | N24: =(K24-$K$14)*1000 -> #REF!
A25: ='BC.115+040'!B24 -> #REF! | B25: 11 | C25: ='BC.115+040'!M24/1000 -> #REF! | D25: ='BC.115+040'!AA24 -> #REF! | E25: ='BC.115+040'!AB24 -> #REF! | F25: =VLOOKUP($A25,'BC.115+040'!$B$13:$X$489,8,0)/1000 -> #REF! | G25: =VLOOKUP($A25,'BC.115+040'!$B$13:$X$489,9,0)/1000 -> #REF! | H25: =VLOOKUP($A25,'BC.115+040'!$B$13:$X$489,14,0)/1000 -> #REF! | I25: =VLOOKUP($A25,'BC.115+040'!$B$13:$X$489,15,0)/1000 -> #REF! | J25: =VLOOKUP($A25,'BC.115+040'!$B$13:$X$489,20,0)/1000 -> #REF! | K25: =VLOOKUP($A25,'BC.115+040'!$B$13:$X$489,21,0)/1000 -> #REF! | L25: =(G25-$G$14)*1000 -> #REF! | M25: =(I25-$I$14)*1000 -> #REF! | N25: =(K25-$K$14)*1000 -> #REF!
A26: ='BC.115+040'!B25 -> #REF! | B26: 12 | C26: ='BC.115+040'!M25/1000 -> #REF! | D26: ='BC.115+040'!AA25 -> #REF! | E26: ='BC.115+040'!AB25 -> #REF! | F26: =VLOOKUP($A26,'BC.115+040'!$B$13:$X$489,8,0)/1000 -> #REF! | G26: =VLOOKUP($A26,'BC.115+040'!$B$13:$X$489,9,0)/1000 -> #REF! | H26: =VLOOKUP($A26,'BC.115+040'!$B$13:$X$489,14,0)/1000 -> #REF! | I26: =VLOOKUP($A26,'BC.115+040'!$B$13:$X$489,15,0)/1000 -> #REF! | J26: =VLOOKUP($A26,'BC.115+040'!$B$13:$X$489,20,0)/1000 -> #REF! | K26: =VLOOKUP($A26,'BC.115+040'!$B$13:$X$489,21,0)/1000 -> #REF! | L26: =(G26-$G$14)*1000 -> #REF! | M26: =(I26-$I$14)*1000 -> #REF! | N26: =(K26-$K$14)*1000 -> #REF!
