Workbook

Sheet 124+900 
A1: DỰ ÁN THÀNH PHẦN ĐOẠN HẬU GIANG - CÀ MAU
A2: THUỘC DỰ ÁN XÂY DỰNG CÔNG TRÌNH ĐƯỜNG BỘ CAO TỐC BẮC - NAM PHÍA ĐÔNG GIAI ĐOẠN 2021 - 2025
A3: GÓI THẦU: THI CÔNG XÂY DỰNG ĐOẠN TUYẾN KM114+200-KM126+223
A4: CHỦ ĐẦU TƯ | I4: TƯ VẤN GIÁM SÁT | S4: NHÀ THẦU
A5: BAN QUẢN LÝ DỰ ÁN MỸ THUẬN | I5: LIÊN DANH TVGS PHÂN VIỆN KHCN GTVT PHÍA NAM VÀ CÔNG TY CỔ PHẦN TV KT&XD HỒNG HÀ | S5: LIÊN DANH TỔNG CÔNG TY XD SỐ 1 (CTCP) - CÔNG TY CỔ PHẦN HẢI ĐĂNG - CÔNG TY TNHH LIÊN HỢP XD VẠN CƯỜNG - CÔNG TY CỔ PHẦN XD VÀ ĐT 492 - CÔNG TY CỔ PHẦN XÂY DỰNG HẠ TẦNG BẮC TRUNG NAM
A6: BIỂU GHI ĐO QUAN TRẮC LÚN
A7: Người lập: | K7: Tên mốc:
A8: Thời tiết: | C8: năng | K8: Cao độ mốc: | M8: =C13 -> 1026
A9: Lý trình: | C9: Km124+900 | K9: Ngày đặt bàn: | M9: =B13 -> 45243
A11: Stt | B11: Ngày quan trắc | C11: Cao độ mốc (mm) | D11: Số đọc tại mốc (mm) | E11: Số đọc mia (mm) | H11: Cao độ quan trắc (mm) | K11: Chiều dài cần nối (mm) | N11: Cao độ bàn đo lún (mm) | Q11: Tốc độ lún trên ngày (mm) | T11: Số đọc mia tại nền đắp tại tâm (mm) | U11: Cao độ nền đắp (mm) | X11: Đội quan trắc | Y11: Nhà thầu | Z11: Tư Vấn Giám Sát | AA11: Ghi chú
E12: Trái | F12: Giữa | G12: Phải | H12: Trái | I12: Giữa | J12: Phải | K12: Trái | L12: Giữa | M12: Phải | N12: Trái | O12: Giữa | P12: Phải | Q12: Trái | R12: Giữa | S12: Phải | U12: Trái | V12: Giữa | W12: Phải | AC12: Ngày lắp | AE12: 44849
A13: 1 | B13: 45243 | C13: 1026 | D13: 1381 | E13: =C13+D13-H13 -> 1528 | F13: =C13+D13-I13 -> 1530 | G13: =D13+C13-J13 -> 1520 | H13: =K13+N13 -> 879 | I13: =L13+O13 -> 877 | J13: =M13+P13 -> 887 | K13: 1000 | L13: 1000 | M13: 1000 | N13: -121 | O13: -123 | P13: -113 | Q13: 0 | R13: 0 | S13: 0 | T13: =D13+C13-V13 -> 2530 | U13: =N13 -> -121 | V13: =O13 -> -123 | W13: =P13 -> -113 | AA13: Lắp đặt ban đầu
A14: 2 | B14: =B13+1 -> 45244 | C14: =C13 -> 1026 | D14: 1100 | E14: =C14+D14-H14 -> 1247 | F14: =C14+D14-I14 -> 1249 | G14: =D14+C14-J14 -> 1239 | H14: =K14+N14 -> 879 | I14: =L14+O14 -> 877 | J14: =M14+P14 -> 887 | K14: =K13 -> 1000 | L14: =L13 -> 1000 | M14: =M13 -> 1000 | N14: =N13-Q14 -> -121 | O14: =O13-R14 -> -123 | P14: =P13-S14 -> -113 | Q14: 0 | R14: 0 | S14: 0 | T14: =D14+C14-V14 -> 2249 | U14: =U13-Q14 -> -121 | V14: =V13-R14 -> -123 | W14: =W13-S14 -> -113 | AA14: Đang đắp GĐ1
A15: 3 | B15: =B14+1 -> 45245 | C15: =C14 -> 1026 | D15: 1488 | E15: =C15+D15-H15 -> 1635 | F15: =C15+D15-I15 -> 1637 | G15: =D15+C15-J15 -> 1627 | H15: =K15+N15 -> 879 | I15: =L15+O15 -> 877 | J15: =M15+P15 -> 887 | K15: =K14 -> 1000 | L15: =L14 -> 1000 | M15: =M14 -> 1000 | N15: =N14-Q15 -> -121 | O15: =O14-R15 -> -123 | P15: =P14-S15 -> -113 | Q15: 0 | R15: 0 | S15: 0 | T15: =D15+C15-V15 -> 2637 | U15: =U14-Q15 -> -121 | V15: =V14-R15 -> -123 | W15: =W14-S15 -> -113
A16: 4 | B16: =B15+4 -> 45249 | C16: =C15 -> 1026 | D16: 1309 | E16: =C16+D16-H16 -> 1456 | F16: =C16+D16-I16 -> 1458 | G16: =D16+C16-J16 -> 1448 | H16: =K16+N16 -> 879 | I16: =L16+O16 -> 877 | J16: =M16+P16 -> 887 | K16: =K15 -> 1000 | L16: =L15 -> 1000 | M16: =M15 -> 1000 | N16: =N15-Q16 -> -121 | O16: =O15-R16 -> -123 | P16: =P15-S16 -> -113 | Q16: 0 | R16: 0 | S16: 0 | T16: =D16+C16-V16 -> 2458 | U16: =U15-Q16 -> -121 | V16: =V15-R16 -> -123 | W16: =W15-S16 -> -113
A17: 5 | B17: =B16+3 -> 45252 | C17: =C16 -> 1026 | D17: 1374 | E17: =C17+D17-H17 -> 1521 | F17: =C17+D17-I17 -> 1523 | G17: =D17+C17-J17 -> 1513 | H17: =K17+N17 -> 879 | I17: =L17+O17 -> 877 | J17: =M17+P17 -> 887 | K17: =K16 -> 1000 | L17: =L16 -> 1000 | M17: =M16 -> 1000 | N17: =N16-Q17 -> -121 | O17: =O16-R17 -> -123 | P17: =P16-S17 -> -113 | Q17: 0 | R17: 0 | S17: 0 | T17: =D17+C17-V17 -> 2523 | U17: =U16-Q17 -> -121 | V17: =V16-R17 -> -123 | W17: =W16-S17 -> -113
A18: 6 | B18: =B17+7 -> 45259 | C18: =C17 -> 1026 | D18: 1448 | E18: =C18+D18-H18 -> 1595 | F18: =C18+D18-I18 -> 1597 | G18: =D18+C18-J18 -> 1587 | H18: =K18+N18 -> 879 | I18: =L18+O18 -> 877 | J18: =M18+P18 -> 887 | K18: =K17 -> 1000 | L18: =L17 -> 1000 | M18: =M17 -> 1000 | N18: =N17-Q18 -> -121 | O18: =O17-R18 -> -123 | P18: =P17-S18 -> -113 | Q18: 0 | R18: 0 | S18: 0 | T18: =D18+C18-V18 -> 2597 | U18: =U17-Q18 -> -121 | V18: =V17-R18 -> -123 | W18: =W17-S18 -> -113
A19: 7 | B19: =B18+4 -> 45263 | C19: =C18 -> 1026 | D19: 1495 | E19: =C19+D19-H19 -> 1642 | F19: =C19+D19-I19 -> 1644 | G19: =D19+C19-J19 -> 1634 | H19: =K19+N19 -> 879 | I19: =L19+O19 -> 877 | J19: =M19+P19 -> 887 | K19: =K18 -> 1000 | L19: =L18 -> 1000 | M19: =M18 -> 1000 | N19: =N18-Q19 -> -121 | O19: =O18-R19 -> -123 | P19: =P18-S19 -> -113 | Q19: 0 | R19: 0 | S19: 0 | T19: =D19+C19-V19 -> 2644 | U19: =U18-Q19 -> -121 | V19: =V18-R19 -> -123 | W19: =W18-S19 -> -113
A20: 8 | B20: =B19+1 -> 45264 | C20: =C19 -> 1026 | D20: 1152 | E20: =C20+D20-H20 -> 1299 | F20: =C20+D20-I20 -> 1301 | G20: =D20+C20-J20 -> 1291 | H20: =K20+N20 -> 879 | I20: =L20+O20 -> 877 | J20: =M20+P20 -> 887 | K20: =K19 -> 1000 | L20: =L19 -> 1000 | M20: =M19 -> 1000 | N20: =N19-Q20 -> -121 | O20: =O19-R20 -> -123 | P20: =P19-S20 -> -113 | Q20: 0 | R20: 0 | S20: 0 | T20: =D20+C20-V20 -> 2301 | U20: =U19-Q20 -> -121 | V20: =V19-R20 -> -123 | W20: =W19-S20 -> -113
A21: 9 | B21: =B20+1 -> 45265 | C21: =C20 -> 1026 | D21: 1480 | E21: =C21+D21-H21 -> 1627 | F21: =C21+D21-I21 -> 1629 | G21: =D21+C21-J21 -> 1619 | H21: =K21+N21 -> 879 | I21: =L21+O21 -> 877 | J21: =M21+P21 -> 887 | K21: =K20 -> 1000 | L21: =L20 -> 1000 | M21: =M20 -> 1000 | N21: =N20-Q21 -> -121 | O21: =O20-R21 -> -123 | P21: =P20-S21 -> -113 | Q21: 0 | R21: 0 | S21: 0 | T21: =D21+C21-V21 -> 2629 | U21: =U20-Q21 -> -121 | V21: =V20-R21 -> -123 | W21: =W20-S21 -> -113
A22: 10 | B22: =B21+1 -> 45266 | C22: =C21 -> 1026 | D22: 1252 | E22: =C22+D22-H22 -> 1399 | F22: =C22+D22-I22 -> 1401 | G22: =D22+C22-J22 -> 1391 | H22: =K22+N22 -> 879 | I22: =L22+O22 -> 877 | J22: =M22+P22 -> 887 | K22: =K21 -> 1000 | L22: =L21 -> 1000 | M22: =M21 -> 1000 | N22: =N21-Q22 -> -121 | O22: =O21-R22 -> -123 | P22: =P21-S22 -> -113 | Q22: 0 | R22: 0 | S22: 0 | T22: =D22+C22-V22 -> 2401 | U22: =U21-Q22 -> -121 | V22: =V21-R22 -> -123 | W22: =W21-S22 -> -113
A23: 11 | B23: =B22+1 -> 45267 | C23: =C22 -> 1026 | D23: 1432 | E23: =C23+D23-H23 -> 1579 | F23: =C23+D23-I23 -> 1581 | G23: =D23+C23-J23 -> 1571 | H23: =K23+N23 -> 879 | I23: =L23+O23 -> 877 | J23: =M23+P23 -> 887 | K23: =K22 -> 1000 | L23: =L22 -> 1000 | M23: =M22 -> 1000 | N23: =N22-Q23 -> -121 | O23: =O22-R23 -> -123 | P23: =P22-S23 -> -113 | Q23: 0 | R23: 0 | S23: 0 | T23: =D23+C23-V23 -> 2581 | U23: =U22-Q23 -> -121 | V23: =V22-R23 -> -123 | W23: =W22-S23 -> -113
A24: 12 | B24: =B23+1 -> 45268 | C24: =C23 -> 1026 | D24: 1112 | E24: =C24+D24-H24 -> 1259 | F24: =C24+D24-I24 -> 1261 | G24: =D24+C24-J24 -> 1251 | H24: =K24+N24 -> 879 | I24: =L24+O24 -> 877 | J24: =M24+P24 -> 887 | K24: =K23 -> 1000 | L24: =L23 -> 1000 | M24: =M23 -> 1000 | N24: =N23-Q24 -> -121 | O24: =O23-R24 -> -123 | P24: =P23-S24 -> -113 | Q24: 0 | R24: 0 | S24: 0 | T24: =D24+C24-V24 -> 2261 | U24: =U23-Q24 -> -121 | V24: =V23-R24 -> -123 | W24: =W23-S24 -> -113
A25: 13 | B25: =B24+1 -> 45269 | C25: =C24 -> 1026 | D25: 1337 | E25: =C25+D25-H25 -> 1484 | F25: =C25+D25-I25 -> 1486 | G25: =D25+C25-J25 -> 1476 | H25: =K25+N25 -> 879 | I25: =L25+O25 -> 877 | J25: =M25+P25 -> 887 | K25: =K24 -> 1000 | L25: =L24 -> 1000 | M25: =M24 -> 1000 | N25: =N24-Q25 -> -121 | O25: =O24-R25 -> -123 | P25: =P24-S25 -> -113 | Q25: 0 | R25: 0 | S25: 0 | T25: =D25+C25-V25 -> 2486 | U25: =U24-Q25 -> -121 | V25: =V24-R25 -> -123 | W25: =W24-S25 -> -113
A26: 14 | B26: =B25+1 -> 45270 | C26: =C25 -> 1026 | D26: 1249 | E26: =C26+D26-H26 -> 1396 | F26: =C26+D26-I26 -> 1398 | G26: =D26+C26-J26 -> 1388 | H26: =K26+N26 -> 879 | I26: =L26+O26 -> 877 | J26: =M26+P26 -> 887 | K26: =K25 -> 1000 | L26: =L25 -> 1000 | M26: =M25 -> 1000 | N26: =N25-Q26 -> -121 | O26: =O25-R26 -> -123 | P26: =P25-S26 -> -113 | Q26: 0 | R26: 0 | S26: 0 | T26: =D26+C26-V26 -> 2398 | U26: =U25-Q26 -> -121 | V26: =V25-R26 -> -123 | W26: =W25-S26 -> -113
A27: 15 | B27: =B26+1 -> 45271 | C27: =C26 -> 1026 | D27: 1485 | E27: =C27+D27-H27 -> 632 | F27: =C27+D27-I27 -> 634 | G27: =D27+C27-J27 -> 624 | H27: =K27+N27 -> 1879 | I27: =L27+O27 -> 1877 | J27: =M27+P27 -> 1887 | K27: =K26+1000 -> 2000 | L27: =L26+1000 -> 2000 | M27: =M26+1000 -> 2000 | N27: =N26-Q27 -> -121 | O27: =O26-R27 -> -123 | P27: =P26-S27 -> -113 | Q27: 0 | R27: 0 | S27: 0 | T27: =D27+C27-V27 -> 2634 | U27: =U26-Q27 -> -121 | V27: =V26-R27 -> -123 | W27: =W26-S27 -> -113 | AA27: Nối cần
A28: 16 | B28: =B27+1 -> 45272 | C28: =C27 -> 1026 | D28: 1717 | E28: =C28+D28-H28 -> 864 | F28: =C28+D28-I28 -> 866 | G28: =D28+C28-J28 -> 856 | H28: =K28+N28 -> 1879 | I28: =L28+O28 -> 1877 | J28: =M28+P28 -> 1887 | K28: =K27 -> 2000 | L28: =L27 -> 2000 | M28: =M27 -> 2000 | N28: =N27-Q28 -> -121 | O28: =O27-R28 -> -123 | P28: =P27-S28 -> -113 | Q28: 0 | R28: 0 | S28: 0 | T28: =D28+C28-V28 -> 2743 | U28: 0 | V28: 0 | W28: 0 | AA28: đắp lớp 7
A29: 17 | B29: =B28+1 -> 45273 | C29: =C28 -> 1026 | D29: 1620 | E29: =C29+D29-H29 -> 772 | F29: =C29+D29-I29 -> 776 | G29: =D29+C29-J29 -> 767 | H29: =K29+N29 -> 1874 | I29: =L29+O29 -> 1870 | J29: =M29+P29 -> 1879 | K29: =K28 -> 2000 | L29: =L28 -> 2000 | M29: =M28 -> 2000 | N29: =N28-Q29 -> -126 | O29: =O28-R29 -> -130 | P29: =P28-S29 -> -121 | Q29: 5 | R29: 7 | S29: 8 | T29: =D29+C29-V29 -> 2653 | U29: =U28-Q29 -> -5 | V29: =V28-R29 -> -7 | W29: =W28-S29 -> -8
A30: 18 | B30: =B29+1 -> 45274 | C30: =C29 -> 1026 | D30: 1856 | E30: =C30+D30-H30 -> 1012 | F30: =C30+D30-I30 -> 1019 | G30: =D30+C30-J30 -> 1011 | H30: =K30+N30 -> 1870 | I30: =L30+O30 -> 1863 | J30: =M30+P30 -> 1871 | K30: =K29 -> 2000 | L30: =L29 -> 2000 | M30: =M29 -> 2000 | N30: =N29-Q30 -> -130 | O30: =O29-R30 -> -137 | P30: =P29-S30 -> -129 | Q30: 4 | R30: 7 | S30: 8 | T30: =D30+C30-V30 -> 2896 | U30: =U29-Q30 -> -9 | V30: =V29-R30 -> -14 | W30: =W29-S30 -> -16
A31: 19 | B31: =B30+1 -> 45275 | C31: =C30 -> 1026 | D31: 1902 | E31: =C31+D31-H31 -> 1065 | F31: =C31+D31-I31 -> 1071 | G31: =D31+C31-J31 -> 1064 | H31: =K31+N31 -> 1863 | I31: =L31+O31 -> 1857 | J31: =M31+P31 -> 1864 | K31: =K30 -> 2000 | L31: =L30 -> 2000 | M31: =M30 -> 2000 | N31: =N30-Q31 -> -137 | O31: =O30-R31 -> -143 | P31: =P30-S31 -> -136 | Q31: 7 | R31: 6 | S31: 7 | T31: =D31+C31-V31 -> 2628 | U31: 300 | V31: 300 | W31: 300 | AA31: đắp lớp 6
A32: 20 | B32: =B31+1 -> 45276 | C32: =C31 -> 1026 | D32: 1836 | E32: =C32+D32-H32 -> 1004 | F32: =C32+D32-I32 -> 1012 | G32: =D32+C32-J32 -> 1006 | H32: =K32+N32 -> 1858 | I32: =L32+O32 -> 1850 | J32: =M32+P32 -> 1856 | K32: =K31 -> 2000 | L32: =L31 -> 2000 | M32: =M31 -> 2000 | N32: =N31-Q32 -> -142 | O32: =O31-R32 -> -150 | P32: =P31-S32 -> -144 | Q32: 5 | R32: 7 | S32: 8 | T32: =D32+C32-V32 -> 2569 | U32: =U31-Q32 -> 295 | V32: =V31-R32 -> 293 | W32: =W31-S32 -> 292
A33: 21 | B33: =B32+1 -> 45277 | C33: =C32 -> 1026 | D33: 1671 | E33: =C33+D33-H33 -> 846 | F33: =C33+D33-I33 -> 853 | G33: =D33+C33-J33 -> 847 | H33: =K33+N33 -> 1851 | I33: =L33+O33 -> 1844 | J33: =M33+P33 -> 1850 | K33: =K32 -> 2000 | L33: =L32 -> 2000 | M33: =M32 -> 2000 | N33: =N32-Q33 -> -149 | O33: =O32-R33 -> -156 | P33: =P32-S33 -> -150 | Q33: 7 | R33: 6 | S33: 6 | T33: =D33+C33-V33 -> 2410 | U33: =U32-Q33 -> 288 | V33: =V32-R33 -> 287 | W33: =W32-S33 -> 286
A34: 22 | B34: =B33+1 -> 45278 | C34: =C33 -> 1026 | D34: 1740 | E34: =C34+D34-H34 -> 921 | F34: =C34+D34-I34 -> 929 | G34: =D34+C34-J34 -> 923 | H34: =K34+N34 -> 1845 | I34: =L34+O34 -> 1837 | J34: =M34+P34 -> 1843 | K34: =K33 -> 2000 | L34: =L33 -> 2000 | M34: =M33 -> 2000 | N34: =N33-Q34 -> -155 | O34: =O33-R34 -> -163 | P34: =P33-S34 -> -157 | Q34: 6 | R34: 7 | S34: 7 | T34: =D34+C34-V34 -> 2166 | U34: 600 | V34: 600 | W34: 600 | AA34: đắp lớp 5
A35: 23 | B35: =B34+1 -> 45279 | C35: =C34 -> 1026 | D35: 1684 | E35: =C35+D35-H35 -> 870 | F35: =C35+D35-I35 -> 880 | G35: =D35+C35-J35 -> 875 | H35: =K35+N35 -> 1840 | I35: =L35+O35 -> 1830 | J35: =M35+P35 -> 1835 | K35: =K34 -> 2000 | L35: =L34 -> 2000 | M35: =M34 -> 2000 | N35: =N34-Q35 -> -160 | O35: =O34-R35 -> -170 | P35: =P34-S35 -> -165 | Q35: 5 | R35: 7 | S35: 8 | T35: =D35+C35-V35 -> 2117 | U35: =U34-Q35 -> 595 | V35: =V34-R35 -> 593 | W35: =W34-S35 -> 592
A36: 24 | B36: =B35+1 -> 45280 | C36: =C35 -> 1026 | D36: 1957 | E36: =C36+D36-H36 -> 149 | F36: =C36+D36-I36 -> 159 | G36: =D36+C36-J36 -> 154 | H36: =K36+N36 -> 2834 | I36: =L36+O36 -> 2824 | J36: =M36+P36 -> 2829 | K36: =K35+1000 -> 3000 | L36: =L35+1000 -> 3000 | M36: =M35+1000 -> 3000 | N36: =N35-Q36 -> -166 | O36: =O35-R36 -> -176 | P36: =P35-S36 -> -171 | Q36: 6 | R36: 6 | S36: 6 | T36: =D36+C36-V36 -> 2396 | U36: =U35-Q36 -> 589 | V36: =V35-R36 -> 587 | W36: =W35-S36 -> 586 | AA36: Nối cần
A37: 25 | B37: =B36+1 -> 45281 | C37: =C36 -> 1026 | D37: 2495 | E37: =C37+D37-H37 -> 692 | F37: =C37+D37-I37 -> 704 | G37: =D37+C37-J37 -> 699 | H37: =K37+N37 -> 2829 | I37: =L37+O37 -> 2817 | J37: =M37+P37 -> 2822 | K37: =K36 -> 3000 | L37: =L36 -> 3000 | M37: =M36 -> 3000 | N37: =N36-Q37 -> -171 | O37: =O36-R37 -> -183 | P37: =P36-S37 -> -178 | Q37: 5 | R37: 7 | S37: 7 | T37: =D37+C37-V37 -> 2621 | U37: 900 | V37: 900 | W37: 900 | AA37: đắp lớp 4
A38: 26 | B38: =B37+4 -> 45285 | C38: =C37 -> 1026 | D38: 2458 | E38: =C38+D38-H38 -> 661 | F38: =C38+D38-I38 -> 674 | G38: =D38+C38-J38 -> 668 | H38: =K38+N38 -> 2823 | I38: =L38+O38 -> 2810 | J38: =M38+P38 -> 2816 | K38: =K37 -> 3000 | L38: =L37 -> 3000 | M38: =M37 -> 3000 | N38: =N37-Q38 -> -177 | O38: =O37-R38 -> -190 | P38: =P37-S38 -> -184 | Q38: 6 | R38: 7 | S38: 6 | T38: =D38+C38-V38 -> 2591 | U38: =U37-Q38 -> 894 | V38: =V37-R38 -> 893 | W38: =W37-S38 -> 894
A39: 27 | B39: =B38+3 -> 45288 | C39: =C38 -> 1026 | D39: 2156 | E39: =C39+D39-H39 -> 367 | F39: =C39+D39-I39 -> 375 | G39: =D39+C39-J39 -> 371 | H39: =K39+N39 -> 2815 | I39: =L39+O39 -> 2807 | J39: =M39+P39 -> 2811 | K39: =K38 -> 3000 | L39: =L38 -> 3000 | M39: =M38 -> 3000 | N39: =N38-Q39 -> -185 | O39: =O38-R39 -> -193 | P39: =P38-S39 -> -189 | Q39: 8 | R39: 3 | S39: 5 | T39: =D39+C39-V39 -> 2292 | U39: =U38-Q39 -> 886 | V39: =V38-R39 -> 890 | W39: =W38-S39 -> 889
A40: 28 | B40: =B39+7 -> 45295 | C40: =C39 -> 1026 | D40: 2311 | E40: =C40+D40-H40 -> 532 | F40: =C40+D40-I40 -> 542 | G40: =D40+C40-J40 -> 536 | H40: =K40+N40 -> 2805 | I40: =L40+O40 -> 2795 | J40: =M40+P40 -> 2801 | K40: =K39 -> 3000 | L40: =L39 -> 3000 | M40: =M39 -> 3000 | N40: =N39-Q40 -> -195 | O40: =O39-R40 -> -205 | P40: =P39-S40 -> -199 | Q40: 10 | R40: 12 | S40: 10 | T40: =D40+C40-V40 -> 2459 | U40: =U39-Q40 -> 876 | V40: =V39-R40 -> 878 | W40: =W39-S40 -> 879
A41: 29 | B41: =B40+7 -> 45302 | C41: =C40 -> 1026 | D41: 2100 | E41: =C41+D41-H41 -> 343 | F41: =C41+D41-I41 -> 351 | G41: =D41+C41-J41 -> 343 | H41: =K41+N41 -> 2783 | I41: =L41+O41 -> 2775 | J41: =M41+P41 -> 2783 | K41: =K40 -> 3000 | L41: =L40 -> 3000 | M41: =M40 -> 3000 | N41: =N40-Q41 -> -217 | O41: =O40-R41 -> -225 | P41: =P40-S41 -> -217 | Q41: 22 | R41: 20 | S41: 18 | T41: =D41+C41-V41 -> 2268 | U41: =U40-Q41 -> 854 | V41: =V40-R41 -> 858 | W41: =W40-S41 -> 861
...

Sheet BC.124+900 
A1: DỰ ÁN THÀNH PHẦN ĐOẠN HẬU GIANG - CÀ MAU
A2: THUỘC DỰ ÁN XÂY DỰNG CÔNG TRÌNH ĐƯỜNG BỘ CAO TỐC BẮC - NAM PHÍA ĐÔNG GIAI ĐOẠN 2021 - 2025
A3: GÓI THẦU: THI CÔNG XÂY DỰNG ĐOẠN TUYẾN KM114+200-KM126+223
A4: CHỦ ĐẦU TƯ | I4: TƯ VẤN GIÁM SÁT | S4: NHÀ THẦU
A5: BAN QUẢN LÝ DỰ ÁN MỸ THUẬN | I5: LIÊN DANH TVGS PHÂN VIỆN KHCN GTVT PHÍA NAM VÀ CÔNG TY CỔ PHẦN TV KT&XD HỒNG HÀ | S5: LIÊN DANH TỔNG CÔNG TY XD SỐ 1 (CTCP) - CÔNG TY CỔ PHẦN HẢI ĐĂNG - CÔNG TY TNHH LIÊN HỢP XD VẠN CƯỜNG - CÔNG TY CỔ PHẦN XD VÀ ĐT 492 - CÔNG TY CỔ PHẦN XÂY DỰNG HẠ TẦNG BẮC TRUNG NAM
B6: BIỂU GHI ĐO QUAN TRẮC LÚN
B7: Người lập: | L7: Tên mốc:
B8: Thời tiết: | C8: ='[4]124+090'!C8 -> năng | L8: Cao độ mốc: | N8: ='124+900 '!M8 -> 1026
B9: Lý trình: | C9: ='124+900 '!C9 -> Km124+900 | L9: Ngày đặt bàn: | N9: =B13 -> 45243
B11: Ngày | C11: Ngày cộng dồn | D11: Cao độ mốc | E11: Số đọc mia của mốc | F11: Cao độ đường ngắm | G11: Trái | M11: Tim | S11: Phải | Z11: Chiều dày lớp đắp (m) | AA11: Chiều dày nền đắp (m) | AB11: Chiều dày nền đắp (m)
G12: Cao độ đắp (mm) | H12: Số đọc mia | I12: Cao độ quan trắc (mm) | J12: Cao độ bàn đo lún (mm) | K12: Độ lún (mm) | L12: Độ lún tích lũy (mm) | M12: Cao độ đắp (mm) | N12: Số đọc mia | O12: Cao độ quan trắc (mm) | P12: Cao độ bàn đo lún (mm) | Q12: Độ lún (mm) | R12: Độ lún tích lũy (mm) | S12: Cao độ đắp (mm) | T12: Số đọc mia | U12: Cao độ quan trắc (mm) | V12: Cao độ bàn đo lún (mm) | W12: Độ lún (mm) | X12: Độ lún tích lũy (mm)
B13: ='124+900 '!B13 -> 45243 | C13: 0 | D13: =VLOOKUP(B13,'124+900 '!B13:AA315,2,FALSE) -> 1026 | E13: =VLOOKUP(B13,'124+900 '!B13:AA314,3,FALSE) -> 1381 | F13: =D13+E13 -> 2407 | G13: =VLOOKUP(B13,'124+900 '!$B$13:$AA$314,20,FALSE) -> -121 | H13: =VLOOKUP(B13,'124+900 '!$B$13:$AA$314,4,FALSE) -> 1528 | I13: =F13-H13 -> 879 | J13: =VLOOKUP(B13,'124+900 '!$B$13:$AA$314,13,FALSE) -> -121 | K13: 0 | L13: 0 | M13: =VLOOKUP(B13,'124+900 '!$B$13:$AA$314,21,FALSE) -> -123 | N13: =VLOOKUP(B13,'124+900 '!$B$13:$AA$314,5,FALSE) -> 1530 | O13: =F13-N13 -> 877 | P13: =VLOOKUP(B13,'124+900 '!$B$13:$AA$314,14,FALSE) -> -123 | Q13: 0 | R13: 0 | S13: =VLOOKUP(B13,'124+900 '!$B$13:$AA$314,22,FALSE) -> -113 | T13: =VLOOKUP(B13,'124+900 '!$B$13:$AA$314,6,FALSE) -> 1520 | U13: =F13-T13 -> 887 | V13: =VLOOKUP(B13,'124+900 '!$B$13:$AA$314,15,FALSE) -> -113 | W13: 0 | X13: 0 | Y13: 0 | Z13: =IF(Y13>0,Y13,0)/1000 -> 0 | AA13: =Z13 -> 0 | AB13: 0 | AD13: =I13-J13 -> 1000
A14: 1 | B14: ='124+900 '!B14 -> 45244 | C14: =B14-$B$13 -> 1 | D14: =D13 -> 1026 | E14: =VLOOKUP(B14,'124+900 '!B14:AA314,3,FALSE) -> 1100 | F14: =D14+E14 -> 2126 | G14: =VLOOKUP(B14,'124+900 '!$B$13:$AA$314,20,FALSE) -> -121 | H14: =VLOOKUP(B14,'124+900 '!$B$13:$AA$314,4,FALSE) -> 1247 | I14: =F14-H14 -> 879 | J14: =VLOOKUP(B14,'124+900 '!$B$13:$AA$314,13,FALSE) -> -121 | K14: =J14-J13 -> 0 | L14: =L13+K14 -> 0 | M14: =VLOOKUP(B14,'124+900 '!$B$13:$AA$314,21,FALSE) -> -123 | N14: =VLOOKUP(B14,'124+900 '!$B$13:$AA$314,5,FALSE) -> 1249 | O14: =F14-N14 -> 877 | P14: =VLOOKUP(B14,'124+900 '!$B$13:$AA$314,14,FALSE) -> -123 | Q14: =P14-P13 -> 0 | R14: =R13+Q14 -> 0 | S14: =VLOOKUP(B14,'124+900 '!$B$13:$AA$314,22,FALSE) -> -113 | T14: =VLOOKUP(B14,'124+900 '!$B$13:$AA$314,6,FALSE) -> 1239 | U14: =F14-T14 -> 887 | V14: =VLOOKUP(B14,'124+900 '!$B$13:$AA$314,15,FALSE) -> -113 | W14: =V14-V13 -> 0 | X14: =X13+W14 -> 0 | Y14: =M14-M13 -> 0 | Z14: =IF(Y14>0,Y14,0)/1000 -> 0 | AA14: =AA13+Z14 -> 0 | AB14: =(M14-$M$13-R14)/1000 -> 0
A15: =A14+1 -> 2 | B15: ='124+900 '!B15 -> 45245 | C15: =B15-$B$13 -> 2 | D15: =D14 -> 1026 | E15: =VLOOKUP(B15,'124+900 '!B15:AA314,3,FALSE) -> 1488 | F15: =D15+E15 -> 2514 | G15: =VLOOKUP(B15,'124+900 '!$B$13:$AA$314,20,FALSE) -> -121 | H15: =VLOOKUP(B15,'124+900 '!$B$13:$AA$314,4,FALSE) -> 1635 | I15: =F15-H15 -> 879 | J15: =VLOOKUP(B15,'124+900 '!$B$13:$AA$314,13,FALSE) -> -121 | K15: =J15-J14 -> 0 | L15: =L14+K15 -> 0 | M15: =VLOOKUP(B15,'124+900 '!$B$13:$AA$314,21,FALSE) -> -123 | N15: =VLOOKUP(B15,'124+900 '!$B$13:$AA$314,5,FALSE) -> 1637 | O15: =F15-N15 -> 877 | P15: =VLOOKUP(B15,'124+900 '!$B$13:$AA$314,14,FALSE) -> -123 | Q15: =P15-P14 -> 0 | R15: =R14+Q15 -> 0 | S15: =VLOOKUP(B15,'124+900 '!$B$13:$AA$314,22,FALSE) -> -113 | T15: =VLOOKUP(B15,'124+900 '!$B$13:$AA$314,6,FALSE) -> 1627 | U15: =F15-T15 -> 887 | V15: =VLOOKUP(B15,'124+900 '!$B$13:$AA$314,15,FALSE) -> -113 | W15: =V15-V14 -> 0 | X15: =X14+W15 -> 0 | Y15: =M15-M14 -> 0 | Z15: =IF(Y15>0,Y15,0)/1000 -> 0 | AA15: =AA14+Z15 -> 0 | AB15: =(M15-$M$13-R15)/1000 -> 0
A16: =A15+1 -> 3 | B16: ='124+900 '!B16 -> 45249 | C16: =B16-$B$13 -> 6 | D16: =D15 -> 1026 | E16: =VLOOKUP(B16,'124+900 '!B16:AA314,3,FALSE) -> 1309 | F16: =D16+E16 -> 2335 | G16: =VLOOKUP(B16,'124+900 '!$B$13:$AA$314,20,FALSE) -> -121 | H16: =VLOOKUP(B16,'124+900 '!$B$13:$AA$314,4,FALSE) -> 1456 | I16: =F16-H16 -> 879 | J16: =VLOOKUP(B16,'124+900 '!$B$13:$AA$314,13,FALSE) -> -121 | K16: =J16-J15 -> 0 | L16: =L15+K16 -> 0 | M16: =VLOOKUP(B16,'124+900 '!$B$13:$AA$314,21,FALSE) -> -123 | N16: =VLOOKUP(B16,'124+900 '!$B$13:$AA$314,5,FALSE) -> 1458 | O16: =F16-N16 -> 877 | P16: =VLOOKUP(B16,'124+900 '!$B$13:$AA$314,14,FALSE) -> -123 | Q16: =P16-P15 -> 0 | R16: =R15+Q16 -> 0 | S16: =VLOOKUP(B16,'124+900 '!$B$13:$AA$314,22,FALSE) -> -113 | T16: =VLOOKUP(B16,'124+900 '!$B$13:$AA$314,6,FALSE) -> 1448 | U16: =F16-T16 -> 887 | V16: =VLOOKUP(B16,'124+900 '!$B$13:$AA$314,15,FALSE) -> -113 | W16: =V16-V15 -> 0 | X16: =X15+W16 -> 0 | Y16: =M16-M15 -> 0 | Z16: =IF(Y16>0,Y16,0)/1000 -> 0 | AA16: =AA15+Z16 -> 0 | AB16: =(M16-$M$13-R16)/1000 -> 0
A17: =A16+1 -> 4 | B17: ='124+900 '!B17 -> 45252 | C17: =B17-$B$13 -> 9 | D17: =D16 -> 1026 | E17: =VLOOKUP(B17,'124+900 '!B17:AA314,3,FALSE) -> 1374 | F17: =D17+E17 -> 2400 | G17: =VLOOKUP(B17,'124+900 '!$B$13:$AA$314,20,FALSE) -> -121 | H17: =VLOOKUP(B17,'124+900 '!$B$13:$AA$314,4,FALSE) -> 1521 | I17: =F17-H17 -> 879 | J17: =VLOOKUP(B17,'124+900 '!$B$13:$AA$314,13,FALSE) -> -121 | K17: =J17-J16 -> 0 | L17: =L16+K17 -> 0 | M17: =VLOOKUP(B17,'124+900 '!$B$13:$AA$314,21,FALSE) -> -123 | N17: =VLOOKUP(B17,'124+900 '!$B$13:$AA$314,5,FALSE) -> 1523 | O17: =F17-N17 -> 877 | P17: =VLOOKUP(B17,'124+900 '!$B$13:$AA$314,14,FALSE) -> -123 | Q17: =P17-P16 -> 0 | R17: =R16+Q17 -> 0 | S17: =VLOOKUP(B17,'124+900 '!$B$13:$AA$314,22,FALSE) -> -113 | T17: =VLOOKUP(B17,'124+900 '!$B$13:$AA$314,6,FALSE) -> 1513 | U17: =F17-T17 -> 887 | V17: =VLOOKUP(B17,'124+900 '!$B$13:$AA$314,15,FALSE) -> -113 | W17: =V17-V16 -> 0 | X17: =X16+W17 -> 0 | Y17: =M17-M16 -> 0 | Z17: =IF(Y17>0,Y17,0)/1000 -> 0 | AA17: =AA16+Z17 -> 0 | AB17: =(M17-$M$13-R17)/1000 -> 0
A18: =A17+1 -> 5 | B18: ='124+900 '!B18 -> 45259 | C18: =B18-$B$13 -> 16 | D18: =D17 -> 1026 | E18: =VLOOKUP(B18,'124+900 '!B18:AA314,3,FALSE) -> 1448 | F18: =D18+E18 -> 2474 | G18: =VLOOKUP(B18,'124+900 '!$B$13:$AA$314,20,FALSE) -> -121 | H18: =VLOOKUP(B18,'124+900 '!$B$13:$AA$314,4,FALSE) -> 1595 | I18: =F18-H18 -> 879 | J18: =VLOOKUP(B18,'124+900 '!$B$13:$AA$314,13,FALSE) -> -121 | K18: =J18-J17 -> 0 | L18: =L17+K18 -> 0 | M18: =VLOOKUP(B18,'124+900 '!$B$13:$AA$314,21,FALSE) -> -123 | N18: =VLOOKUP(B18,'124+900 '!$B$13:$AA$314,5,FALSE) -> 1597 | O18: =F18-N18 -> 877 | P18: =VLOOKUP(B18,'124+900 '!$B$13:$AA$314,14,FALSE) -> -123 | Q18: =P18-P17 -> 0 | R18: =R17+Q18 -> 0 | S18: =VLOOKUP(B18,'124+900 '!$B$13:$AA$314,22,FALSE) -> -113 | T18: =VLOOKUP(B18,'124+900 '!$B$13:$AA$314,6,FALSE) -> 1587 | U18: =F18-T18 -> 887 | V18: =VLOOKUP(B18,'124+900 '!$B$13:$AA$314,15,FALSE) -> -113 | W18: =V18-V17 -> 0 | X18: =X17+W18 -> 0 | Y18: =M18-M17 -> 0 | Z18: =IF(Y18>0,Y18,0)/1000 -> 0 | AA18: =AA17+Z18 -> 0 | AB18: =(M18-$M$13-R18)/1000 -> 0
A19: =A18+1 -> 6 | B19: ='124+900 '!B19 -> 45263 | C19: =B19-$B$13 -> 20 | D19: =D18 -> 1026 | E19: =VLOOKUP(B19,'124+900 '!B19:AA314,3,FALSE) -> 1495 | F19: =D19+E19 -> 2521 | G19: =VLOOKUP(B19,'124+900 '!$B$13:$AA$314,20,FALSE) -> -121 | H19: =VLOOKUP(B19,'124+900 '!$B$13:$AA$314,4,FALSE) -> 1642 | I19: =F19-H19 -> 879 | J19: =VLOOKUP(B19,'124+900 '!$B$13:$AA$314,13,FALSE) -> -121 | K19: =J19-J18 -> 0 | L19: =L18+K19 -> 0 | M19: =VLOOKUP(B19,'124+900 '!$B$13:$AA$314,21,FALSE) -> -123 | N19: =VLOOKUP(B19,'124+900 '!$B$13:$AA$314,5,FALSE) -> 1644 | O19: =F19-N19 -> 877 | P19: =VLOOKUP(B19,'124+900 '!$B$13:$AA$314,14,FALSE) -> -123 | Q19: =P19-P18 -> 0 | R19: =R18+Q19 -> 0 | S19: =VLOOKUP(B19,'124+900 '!$B$13:$AA$314,22,FALSE) -> -113 | T19: =VLOOKUP(B19,'124+900 '!$B$13:$AA$314,6,FALSE) -> 1634 | U19: =F19-T19 -> 887 | V19: =VLOOKUP(B19,'124+900 '!$B$13:$AA$314,15,FALSE) -> -113 | W19: =V19-V18 -> 0 | X19: =X18+W19 -> 0 | Y19: =M19-M18 -> 0 | Z19: =IF(Y19>0,Y19,0)/1000 -> 0 | AA19: =AA18+Z19 -> 0 | AB19: =(M19-$M$13-R19)/1000 -> 0
A20: =A19+1 -> 7 | B20: ='124+900 '!B20 -> 45264 | C20: =B20-$B$13 -> 21 | D20: =D19 -> 1026 | E20: =VLOOKUP(B20,'124+900 '!B20:AA314,3,FALSE) -> 1152 | F20: =D20+E20 -> 2178 | G20: =VLOOKUP(B20,'124+900 '!$B$13:$AA$314,20,FALSE) -> -121 | H20: =VLOOKUP(B20,'124+900 '!$B$13:$AA$314,4,FALSE) -> 1299 | I20: =F20-H20 -> 879 | J20: =VLOOKUP(B20,'124+900 '!$B$13:$AA$314,13,FALSE) -> -121 | K20: =J20-J19 -> 0 | L20: =L19+K20 -> 0 | M20: =VLOOKUP(B20,'124+900 '!$B$13:$AA$314,21,FALSE) -> -123 | N20: =VLOOKUP(B20,'124+900 '!$B$13:$AA$314,5,FALSE) -> 1301 | O20: =F20-N20 -> 877 | P20: =VLOOKUP(B20,'124+900 '!$B$13:$AA$314,14,FALSE) -> -123 | Q20: =P20-P19 -> 0 | R20: =R19+Q20 -> 0 | S20: =VLOOKUP(B20,'124+900 '!$B$13:$AA$314,22,FALSE) -> -113 | T20: =VLOOKUP(B20,'124+900 '!$B$13:$AA$314,6,FALSE) -> 1291 | U20: =F20-T20 -> 887 | V20: =VLOOKUP(B20,'124+900 '!$B$13:$AA$314,15,FALSE) -> -113 | W20: =V20-V19 -> 0 | X20: =X19+W20 -> 0 | Y20: =M20-M19 -> 0 | Z20: =IF(Y20>0,Y20,0)/1000 -> 0 | AA20: =AA19+Z20 -> 0 | AB20: =(M20-$M$13-R20)/1000 -> 0
B21: ='124+900 '!B21 -> 45265 | C21: =B21-$B$13 -> 22 | D21: =D20 -> 1026 | E21: =VLOOKUP(B21,'124+900 '!B21:AA314,3,FALSE) -> 1480 | F21: =D21+E21 -> 2506 | G21: =VLOOKUP(B21,'124+900 '!$B$13:$AA$314,20,FALSE) -> -121 | H21: =VLOOKUP(B21,'124+900 '!$B$13:$AA$314,4,FALSE) -> 1627 | I21: =F21-H21 -> 879 | J21: =VLOOKUP(B21,'124+900 '!$B$13:$AA$314,13,FALSE) -> -121 | K21: =J21-J20 -> 0 | L21: =L20+K21 -> 0 | M21: =VLOOKUP(B21,'124+900 '!$B$13:$AA$314,21,FALSE) -> -123 | N21: =VLOOKUP(B21,'124+900 '!$B$13:$AA$314,5,FALSE) -> 1629 | O21: =F21-N21 -> 877 | P21: =VLOOKUP(B21,'124+900 '!$B$13:$AA$314,14,FALSE) -> -123 | Q21: =P21-P20 -> 0 | R21: =R20+Q21 -> 0 | S21: =VLOOKUP(B21,'124+900 '!$B$13:$AA$314,22,FALSE) -> -113 | T21: =VLOOKUP(B21,'124+900 '!$B$13:$AA$314,6,FALSE) -> 1619 | U21: =F21-T21 -> 887 | V21: =VLOOKUP(B21,'124+900 '!$B$13:$AA$314,15,FALSE) -> -113 | W21: =V21-V20 -> 0 | X21: =X20+W21 -> 0 | Y21: =M21-M20 -> 0 | Z21: =IF(Y21>0,Y21,0)/1000 -> 0 | AA21: =AA20+Z21 -> 0 | AB21: =(M21-$M$13-R21)/1000 -> 0
B22: ='124+900 '!B22 -> 45266 | C22: =B22-$B$13 -> 23 | D22: =D21 -> 1026 | E22: =VLOOKUP(B22,'124+900 '!B22:AA314,3,FALSE) -> 1252 | F22: =D22+E22 -> 2278 | G22: =VLOOKUP(B22,'124+900 '!$B$13:$AA$314,20,FALSE) -> -121 | H22: =VLOOKUP(B22,'124+900 '!$B$13:$AA$314,4,FALSE) -> 1399 | I22: =F22-H22 -> 879 | J22: =VLOOKUP(B22,'124+900 '!$B$13:$AA$314,13,FALSE) -> -121 | K22: =J22-J21 -> 0 | L22: =L21+K22 -> 0 | M22: =VLOOKUP(B22,'124+900 '!$B$13:$AA$314,21,FALSE) -> -123 | N22: =VLOOKUP(B22,'124+900 '!$B$13:$AA$314,5,FALSE) -> 1401 | O22: =F22-N22 -> 877 | P22: =VLOOKUP(B22,'124+900 '!$B$13:$AA$314,14,FALSE) -> -123 | Q22: =P22-P21 -> 0 | R22: =R21+Q22 -> 0 | S22: =VLOOKUP(B22,'124+900 '!$B$13:$AA$314,22,FALSE) -> -113 | T22: =VLOOKUP(B22,'124+900 '!$B$13:$AA$314,6,FALSE) -> 1391 | U22: =F22-T22 -> 887 | V22: =VLOOKUP(B22,'124+900 '!$B$13:$AA$314,15,FALSE) -> -113 | W22: =V22-V21 -> 0 | X22: =X21+W22 -> 0 | Y22: =M22-M21 -> 0 | Z22: =IF(Y22>0,Y22,0)/1000 -> 0 | AA22: =AA21+Z22 -> 0 | AB22: =(M22-$M$13-R22)/1000 -> 0
B23: ='124+900 '!B23 -> 45267 | C23: =B23-$B$13 -> 24 | D23: =D22 -> 1026 | E23: =VLOOKUP(B23,'124+900 '!B23:AA314,3,FALSE) -> 1432 | F23: =D23+E23 -> 2458 | G23: =VLOOKUP(B23,'124+900 '!$B$13:$AA$314,20,FALSE) -> -121 | H23: =VLOOKUP(B23,'124+900 '!$B$13:$AA$314,4,FALSE) -> 1579 | I23: =F23-H23 -> 879 | J23: =VLOOKUP(B23,'124+900 '!$B$13:$AA$314,13,FALSE) -> -121 | K23: =J23-J22 -> 0 | L23: =L22+K23 -> 0 | M23: =VLOOKUP(B23,'124+900 '!$B$13:$AA$314,21,FALSE) -> -123 | N23: =VLOOKUP(B23,'124+900 '!$B$13:$AA$314,5,FALSE) -> 1581 | O23: =F23-N23 -> 877 | P23: =VLOOKUP(B23,'124+900 '!$B$13:$AA$314,14,FALSE) -> -123 | Q23: =P23-P22 -> 0 | R23: =R22+Q23 -> 0 | S23: =VLOOKUP(B23,'124+900 '!$B$13:$AA$314,22,FALSE) -> -113 | T23: =VLOOKUP(B23,'124+900 '!$B$13:$AA$314,6,FALSE) -> 1571 | U23: =F23-T23 -> 887 | V23: =VLOOKUP(B23,'124+900 '!$B$13:$AA$314,15,FALSE) -> -113 | W23: =V23-V22 -> 0 | X23: =X22+W23 -> 0 | Y23: =M23-M22 -> 0 | Z23: =IF(Y23>0,Y23,0)/1000 -> 0 | AA23: =AA22+Z23 -> 0 | AB23: =(M23-$M$13-R23)/1000 -> 0
B24: ='124+900 '!B24 -> 45268 | C24: =B24-$B$13 -> 25 | D24: =D23 -> 1026 | E24: =VLOOKUP(B24,'124+900 '!B24:AA314,3,FALSE) -> 1112 | F24: =D24+E24 -> 2138 | G24: =VLOOKUP(B24,'124+900 '!$B$13:$AA$314,20,FALSE) -> -121 | H24: =VLOOKUP(B24,'124+900 '!$B$13:$AA$314,4,FALSE) -> 1259 | I24: =F24-H24 -> 879 | J24: =VLOOKUP(B24,'124+900 '!$B$13:$AA$314,13,FALSE) -> -121 | K24: =J24-J23 -> 0 | L24: =L23+K24 -> 0 | M24: =VLOOKUP(B24,'124+900 '!$B$13:$AA$314,21,FALSE) -> -123 | N24: =VLOOKUP(B24,'124+900 '!$B$13:$AA$314,5,FALSE) -> 1261 | O24: =F24-N24 -> 877 | P24: =VLOOKUP(B24,'124+900 '!$B$13:$AA$314,14,FALSE) -> -123 | Q24: =P24-P23 -> 0 | R24: =R23+Q24 -> 0 | S24: =VLOOKUP(B24,'124+900 '!$B$13:$AA$314,22,FALSE) -> -113 | T24: =VLOOKUP(B24,'124+900 '!$B$13:$AA$314,6,FALSE) -> 1251 | U24: =F24-T24 -> 887 | V24: =VLOOKUP(B24,'124+900 '!$B$13:$AA$314,15,FALSE) -> -113 | W24: =V24-V23 -> 0 | X24: =X23+W24 -> 0 | Y24: =M24-M23 -> 0 | Z24: =IF(Y24>0,Y24,0)/1000 -> 0 | AA24: =AA23+Z24 -> 0 | AB24: =(M24-$M$13-R24)/1000 -> 0
B25: ='124+900 '!B25 -> 45269 | C25: =B25-$B$13 -> 26 | D25: =D24 -> 1026 | E25: =VLOOKUP(B25,'124+900 '!B25:AA314,3,FALSE) -> 1337 | F25: =D25+E25 -> 2363 | G25: =VLOOKUP(B25,'124+900 '!$B$13:$AA$314,20,FALSE) -> -121 | H25: =VLOOKUP(B25,'124+900 '!$B$13:$AA$314,4,FALSE) -> 1484 | I25: =F25-H25 -> 879 | J25: =VLOOKUP(B25,'124+900 '!$B$13:$AA$314,13,FALSE) -> -121 | K25: =J25-J24 -> 0 | L25: =L24+K25 -> 0 | M25: =VLOOKUP(B25,'124+900 '!$B$13:$AA$314,21,FALSE) -> -123 | N25: =VLOOKUP(B25,'124+900 '!$B$13:$AA$314,5,FALSE) -> 1486 | O25: =F25-N25 -> 877 | P25: =VLOOKUP(B25,'124+900 '!$B$13:$AA$314,14,FALSE) -> -123 | Q25: =P25-P24 -> 0 | R25: =R24+Q25 -> 0 | S25: =VLOOKUP(B25,'124+900 '!$B$13:$AA$314,22,FALSE) -> -113 | T25: =VLOOKUP(B25,'124+900 '!$B$13:$AA$314,6,FALSE) -> 1476 | U25: =F25-T25 -> 887 | V25: =VLOOKUP(B25,'124+900 '!$B$13:$AA$314,15,FALSE) -> -113 | W25: =V25-V24 -> 0 | X25: =X24+W25 -> 0 | Y25: =M25-M24 -> 0 | Z25: =IF(Y25>0,Y25,0)/1000 -> 0 | AA25: =AA24+Z25 -> 0 | AB25: =(M25-$M$13-R25)/1000 -> 0
B26: ='124+900 '!B26 -> 45270 | C26: =B26-$B$13 -> 27 | D26: =D25 -> 1026 | E26: =VLOOKUP(B26,'124+900 '!B26:AA314,3,FALSE) -> 1249 | F26: =D26+E26 -> 2275 | G26: =VLOOKUP(B26,'124+900 '!$B$13:$AA$314,20,FALSE) -> -121 | H26: =VLOOKUP(B26,'124+900 '!$B$13:$AA$314,4,FALSE) -> 1396 | I26: =F26-H26 -> 879 | J26: =VLOOKUP(B26,'124+900 '!$B$13:$AA$314,13,FALSE) -> -121 | K26: =J26-J25 -> 0 | L26: =L25+K26 -> 0 | M26: =VLOOKUP(B26,'124+900 '!$B$13:$AA$314,21,FALSE) -> -123 | N26: =VLOOKUP(B26,'124+900 '!$B$13:$AA$314,5,FALSE) -> 1398 | O26: =F26-N26 -> 877 | P26: =VLOOKUP(B26,'124+900 '!$B$13:$AA$314,14,FALSE) -> -123 | Q26: =P26-P25 -> 0 | R26: =R25+Q26 -> 0 | S26: =VLOOKUP(B26,'124+900 '!$B$13:$AA$314,22,FALSE) -> -113 | T26: =VLOOKUP(B26,'124+900 '!$B$13:$AA$314,6,FALSE) -> 1388 | U26: =F26-T26 -> 887 | V26: =VLOOKUP(B26,'124+900 '!$B$13:$AA$314,15,FALSE) -> -113 | W26: =V26-V25 -> 0 | X26: =X25+W26 -> 0 | Y26: =M26-M25 -> 0 | Z26: =IF(Y26>0,Y26,0)/1000 -> 0 | AA26: =AA25+Z26 -> 0 | AB26: =(M26-$M$13-R26)/1000 -> 0
B27: ='124+900 '!B27 -> 45271 | C27: =B27-$B$13 -> 28 | D27: =D26 -> 1026 | E27: =VLOOKUP(B27,'124+900 '!B27:AA314,3,FALSE) -> 1485 | F27: =D27+E27 -> 2511 | G27: =VLOOKUP(B27,'124+900 '!$B$13:$AA$314,20,FALSE) -> -121 | H27: =VLOOKUP(B27,'124+900 '!$B$13:$AA$314,4,FALSE) -> 632 | I27: =F27-H27 -> 1879 | J27: =VLOOKUP(B27,'124+900 '!$B$13:$AA$314,13,FALSE) -> -121 | K27: =J27-J26 -> 0 | L27: =L26+K27 -> 0 | M27: =VLOOKUP(B27,'124+900 '!$B$13:$AA$314,21,FALSE) -> -123 | N27: =VLOOKUP(B27,'124+900 '!$B$13:$AA$314,5,FALSE) -> 634 | O27: =F27-N27 -> 1877 | P27: =VLOOKUP(B27,'124+900 '!$B$13:$AA$314,14,FALSE) -> -123 | Q27: =P27-P26 -> 0 | R27: =R26+Q27 -> 0 | S27: =VLOOKUP(B27,'124+900 '!$B$13:$AA$314,22,FALSE) -> -113 | T27: =VLOOKUP(B27,'124+900 '!$B$13:$AA$314,6,FALSE) -> 624 | U27: =F27-T27 -> 1887 | V27: =VLOOKUP(B27,'124+900 '!$B$13:$AA$314,15,FALSE) -> -113 | W27: =V27-V26 -> 0 | X27: =X26+W27 -> 0 | Y27: =M27-M26 -> 0 | Z27: =IF(Y27>0,Y27,0)/1000 -> 0 | AA27: =AA26+Z27 -> 0 | AB27: =(M27-$M$13-R27)/1000 -> 0
B28: ='124+900 '!B28 -> 45272 | C28: =B28-$B$13 -> 29 | D28: =D27 -> 1026 | E28: =VLOOKUP(B28,'124+900 '!B28:AA314,3,FALSE) -> 1717 | F28: =D28+E28 -> 2743 | G28: =VLOOKUP(B28,'124+900 '!$B$13:$AA$314,20,FALSE) -> 0 | H28: =VLOOKUP(B28,'124+900 '!$B$13:$AA$314,4,FALSE) -> 864 | I28: =F28-H28 -> 1879 | J28: =VLOOKUP(B28,'124+900 '!$B$13:$AA$314,13,FALSE) -> -121 | K28: =J28-J27 -> 0 | L28: =L27+K28 -> 0 | M28: =VLOOKUP(B28,'124+900 '!$B$13:$AA$314,21,FALSE) -> 0 | N28: =VLOOKUP(B28,'124+900 '!$B$13:$AA$314,5,FALSE) -> 866 | O28: =F28-N28 -> 1877 | P28: =VLOOKUP(B28,'124+900 '!$B$13:$AA$314,14,FALSE) -> -123 | Q28: =P28-P27 -> 0 | R28: =R27+Q28 -> 0 | S28: =VLOOKUP(B28,'124+900 '!$B$13:$AA$314,22,FALSE) -> 0 | T28: =VLOOKUP(B28,'124+900 '!$B$13:$AA$314,6,FALSE) -> 856 | U28: =F28-T28 -> 1887 | V28: =VLOOKUP(B28,'124+900 '!$B$13:$AA$314,15,FALSE) -> -113 | W28: =V28-V27 -> 0 | X28: =X27+W28 -> 0 | Y28: =M28-M27 -> 123 | Z28: =IF(Y28>0,Y28,0)/1000 -> 0.123 | AA28: =AA27+Z28 -> 0.123 | AB28: =(M28-$M$13-R28)/1000 -> 0.123
B29: ='124+900 '!B29 -> 45273 | C29: =B29-$B$13 -> 30 | D29: =D28 -> 1026 | E29: =VLOOKUP(B29,'124+900 '!B12:AA609,3,FALSE) -> 1620 | F29: =D29+E29 -> 2646 | G29: =VLOOKUP(B29,'124+900 '!$B$13:$AA$314,20,FALSE) -> -5 | H29: =VLOOKUP(B29,'124+900 '!$B$13:$AA$314,4,FALSE) -> 772 | I29: =F29-H29 -> 1874 | J29: =VLOOKUP(B29,'124+900 '!$B$13:$AA$314,13,FALSE) -> -126 | K29: =J29-J28 -> -5 | L29: =L28+K29 -> -5 | M29: =VLOOKUP(B29,'124+900 '!$B$13:$AA$314,21,FALSE) -> -7 | N29: =VLOOKUP(B29,'124+900 '!$B$13:$AA$314,5,FALSE) -> 776 | O29: =F29-N29 -> 1870 | P29: =VLOOKUP(B29,'124+900 '!$B$13:$AA$314,14,FALSE) -> -130 | Q29: =P29-P28 -> -7 | R29: =R28+Q29 -> -7 | S29: =VLOOKUP(B29,'124+900 '!$B$13:$AA$314,22,FALSE) -> -8 | T29: =VLOOKUP(B29,'124+900 '!$B$13:$AA$314,6,FALSE) -> 767 | U29: =F29-T29 -> 1879 | V29: =VLOOKUP(B29,'124+900 '!$B$13:$AA$314,15,FALSE) -> -121 | W29: =V29-V28 -> -8 | X29: =X28+W29 -> -8 | Y29: =M29-M28 -> -7 | Z29: =IF(Y29>0,Y29,0)/1000 -> 0 | AA29: =AA28+Z29 -> 0.123 | AB29: =(M29-$M$13-R29)/1000 -> 0.123
B30: ='124+900 '!B30 -> 45274 | C30: =B30-$B$13 -> 31 | D30: =D29 -> 1026 | E30: =VLOOKUP(B30,'124+900 '!B13:AA610,3,FALSE) -> 1856 | F30: =D30+E30 -> 2882 | G30: =VLOOKUP(B30,'124+900 '!$B$13:$AA$314,20,FALSE) -> -9 | H30: =VLOOKUP(B30,'124+900 '!$B$13:$AA$314,4,FALSE) -> 1012 | I30: =F30-H30 -> 1870 | J30: =VLOOKUP(B30,'124+900 '!$B$13:$AA$314,13,FALSE) -> -130 | K30: =J30-J29 -> -4 | L30: =L29+K30 -> -9 | M30: =VLOOKUP(B30,'124+900 '!$B$13:$AA$314,21,FALSE) -> -14 | N30: =VLOOKUP(B30,'124+900 '!$B$13:$AA$314,5,FALSE) -> 1019 | O30: =F30-N30 -> 1863 | P30: =VLOOKUP(B30,'124+900 '!$B$13:$AA$314,14,FALSE) -> -137 | Q30: =P30-P29 -> -7 | R30: =R29+Q30 -> -14 | S30: =VLOOKUP(B30,'124+900 '!$B$13:$AA$314,22,FALSE) -> -16 | T30: =VLOOKUP(B30,'124+900 '!$B$13:$AA$314,6,FALSE) -> 1011 | U30: =F30-T30 -> 1871 | V30: =VLOOKUP(B30,'124+900 '!$B$13:$AA$314,15,FALSE) -> -129 | W30: =V30-V29 -> -8 | X30: =X29+W30 -> -16 | Y30: =M30-M29 -> -7 | Z30: =IF(Y30>0,Y30,0)/1000 -> 0 | AA30: =AA29+Z30 -> 0.123 | AB30: =(M30-$M$13-R30)/1000 -> 0.123
B31: ='124+900 '!B31 -> 45275 | C31: =B31-$B$13 -> 32 | D31: =D30 -> 1026 | E31: =VLOOKUP(B31,'124+900 '!B13:AA611,3,FALSE) -> 1902 | F31: =D31+E31 -> 2928 | G31: =VLOOKUP(B31,'124+900 '!$B$13:$AA$314,20,FALSE) -> 300 | H31: =VLOOKUP(B31,'124+900 '!$B$13:$AA$314,4,FALSE) -> 1065 | I31: =F31-H31 -> 1863 | J31: =VLOOKUP(B31,'124+900 '!$B$13:$AA$314,13,FALSE) -> -137 | K31: =J31-J30 -> -7 | L31: =L30+K31 -> -16 | M31: =VLOOKUP(B31,'124+900 '!$B$13:$AA$314,21,FALSE) -> 300 | N31: =VLOOKUP(B31,'124+900 '!$B$13:$AA$314,5,FALSE) -> 1071 | O31: =F31-N31 -> 1857 | P31: =VLOOKUP(B31,'124+900 '!$B$13:$AA$314,14,FALSE) -> -143 | Q31: =P31-P30 -> -6 | R31: =R30+Q31 -> -20 | S31: =VLOOKUP(B31,'124+900 '!$B$13:$AA$314,22,FALSE) -> 300 | T31: =VLOOKUP(B31,'124+900 '!$B$13:$AA$314,6,FALSE) -> 1064 | U31: =F31-T31 -> 1864 | V31: =VLOOKUP(B31,'124+900 '!$B$13:$AA$314,15,FALSE) -> -136 | W31: =V31-V30 -> -7 | X31: =X30+W31 -> -23 | Y31: =M31-M30 -> 314 | Z31: =IF(Y31>0,Y31,0)/1000 -> 0.314 | AA31: =AA30+Z31 -> 0.437 | AB31: =(M31-$M$13-R31)/1000 -> 0.443
B32: ='124+900 '!B32 -> 45276 | C32: =B32-$B$13 -> 33 | D32: =D31 -> 1026 | E32: =VLOOKUP(B32,'124+900 '!B14:AA612,3,FALSE) -> 1836 | F32: =D32+E32 -> 2862 | G32: =VLOOKUP(B32,'124+900 '!$B$13:$AA$314,20,FALSE) -> 295 | H32: =VLOOKUP(B32,'124+900 '!$B$13:$AA$314,4,FALSE) -> 1004 | I32: =F32-H32 -> 1858 | J32: =VLOOKUP(B32,'124+900 '!$B$13:$AA$314,13,FALSE) -> -142 | K32: =J32-J31 -> -5 | L32: =L31+K32 -> -21 | M32: =VLOOKUP(B32,'124+900 '!$B$13:$AA$314,21,FALSE) -> 293 | N32: =VLOOKUP(B32,'124+900 '!$B$13:$AA$314,5,FALSE) -> 1012 | O32: =F32-N32 -> 1850 | P32: =VLOOKUP(B32,'124+900 '!$B$13:$AA$314,14,FALSE) -> -150 | Q32: =P32-P31 -> -7 | R32: =R31+Q32 -> -27 | S32: =VLOOKUP(B32,'124+900 '!$B$13:$AA$314,22,FALSE) -> 292 | T32: =VLOOKUP(B32,'124+900 '!$B$13:$AA$314,6,FALSE) -> 1006 | U32: =F32-T32 -> 1856 | V32: =VLOOKUP(B32,'124+900 '!$B$13:$AA$314,15,FALSE) -> -144 | W32: =V32-V31 -> -8 | X32: =X31+W32 -> -31 | Y32: =M32-M31 -> -7 | Z32: =IF(Y32>0,Y32,0)/1000 -> 0 | AA32: =AA31+Z32 -> 0.437 | AB32: =(M32-$M$13-R32)/1000 -> 0.443
B33: ='124+900 '!B33 -> 45277 | C33: =B33-$B$13 -> 34 | D33: =D32 -> 1026 | E33: =VLOOKUP(B33,'124+900 '!B15:AA613,3,FALSE) -> 1671 | F33: =D33+E33 -> 2697 | G33: =VLOOKUP(B33,'124+900 '!$B$13:$AA$314,20,FALSE) -> 288 | H33: =VLOOKUP(B33,'124+900 '!$B$13:$AA$314,4,FALSE) -> 846 | I33: =F33-H33 -> 1851 | J33: =VLOOKUP(B33,'124+900 '!$B$13:$AA$314,13,FALSE) -> -149 | K33: =J33-J32 -> -7 | L33: =L32+K33 -> -28 | M33: =VLOOKUP(B33,'124+900 '!$B$13:$AA$314,21,FALSE) -> 287 | N33: =VLOOKUP(B33,'124+900 '!$B$13:$AA$314,5,FALSE) -> 853 | O33: =F33-N33 -> 1844 | P33: =VLOOKUP(B33,'124+900 '!$B$13:$AA$314,14,FALSE) -> -156 | Q33: =P33-P32 -> -6 | R33: =R32+Q33 -> -33 | S33: =VLOOKUP(B33,'124+900 '!$B$13:$AA$314,22,FALSE) -> 286 | T33: =VLOOKUP(B33,'124+900 '!$B$13:$AA$314,6,FALSE) -> 847 | U33: =F33-T33 -> 1850 | V33: =VLOOKUP(B33,'124+900 '!$B$13:$AA$314,15,FALSE) -> -150 | W33: =V33-V32 -> -6 | X33: =X32+W33 -> -37 | Y33: =M33-M32 -> -6 | Z33: =IF(Y33>0,Y33,0)/1000 -> 0 | AA33: =AA32+Z33 -> 0.437 | AB33: =(M33-$M$13-R33)/1000 -> 0.443
B34: ='124+900 '!B34 -> 45278 | C34: =B34-$B$13 -> 35 | D34: =D33 -> 1026 | E34: =VLOOKUP(B34,'124+900 '!B16:AA614,3,FALSE) -> 1740 | F34: =D34+E34 -> 2766 | G34: =VLOOKUP(B34,'124+900 '!$B$13:$AA$314,20,FALSE) -> 600 | H34: =VLOOKUP(B34,'124+900 '!$B$13:$AA$314,4,FALSE) -> 921 | I34: =F34-H34 -> 1845 | J34: =VLOOKUP(B34,'124+900 '!$B$13:$AA$314,13,FALSE) -> -155 | K34: =J34-J33 -> -6 | L34: =L33+K34 -> -34 | M34: =VLOOKUP(B34,'124+900 '!$B$13:$AA$314,21,FALSE) -> 600 | N34: =VLOOKUP(B34,'124+900 '!$B$13:$AA$314,5,FALSE) -> 929 | O34: =F34-N34 -> 1837 | P34: =VLOOKUP(B34,'124+900 '!$B$13:$AA$314,14,FALSE) -> -163 | Q34: =P34-P33 -> -7 | R34: =R33+Q34 -> -40 | S34: =VLOOKUP(B34,'124+900 '!$B$13:$AA$314,22,FALSE) -> 600 | T34: =VLOOKUP(B34,'124+900 '!$B$13:$AA$314,6,FALSE) -> 923 | U34: =F34-T34 -> 1843 | V34: =VLOOKUP(B34,'124+900 '!$B$13:$AA$314,15,FALSE) -> -157 | W34: =V34-V33 -> -7 | X34: =X33+W34 -> -44 | Y34: =M34-M33 -> 313 | Z34: =IF(Y34>0,Y34,0)/1000 -> 0.313 | AA34: =AA33+Z34 -> 0.75 | AB34: =(M34-$M$13-R34)/1000 -> 0.763
B35: ='124+900 '!B35 -> 45279 | C35: =B35-$B$13 -> 36 | D35: =D34 -> 1026 | E35: =VLOOKUP(B35,'124+900 '!B17:AA615,3,FALSE) -> 1684 | F35: =D35+E35 -> 2710 | G35: =VLOOKUP(B35,'124+900 '!$B$13:$AA$314,20,FALSE) -> 595 | H35: =VLOOKUP(B35,'124+900 '!$B$13:$AA$314,4,FALSE) -> 870 | I35: =F35-H35 -> 1840 | J35: =VLOOKUP(B35,'124+900 '!$B$13:$AA$314,13,FALSE) -> -160 | K35: =J35-J34 -> -5 | L35: =L34+K35 -> -39 | M35: =VLOOKUP(B35,'124+900 '!$B$13:$AA$314,21,FALSE) -> 593 | N35: =VLOOKUP(B35,'124+900 '!$B$13:$AA$314,5,FALSE) -> 880 | O35: =F35-N35 -> 1830 | P35: =VLOOKUP(B35,'124+900 '!$B$13:$AA$314,14,FALSE) -> -170 | Q35: =P35-P34 -> -7 | R35: =R34+Q35 -> -47 | S35: =VLOOKUP(B35,'124+900 '!$B$13:$AA$314,22,FALSE) -> 592 | T35: =VLOOKUP(B35,'124+900 '!$B$13:$AA$314,6,FALSE) -> 875 | U35: =F35-T35 -> 1835 | V35: =VLOOKUP(B35,'124+900 '!$B$13:$AA$314,15,FALSE) -> -165 | W35: =V35-V34 -> -8 | X35: =X34+W35 -> -52 | Y35: =M35-M34 -> -7 | Z35: =IF(Y35>0,Y35,0)/1000 -> 0 | AA35: =AA34+Z35 -> 0.75 | AB35: =(M35-$M$13-R35)/1000 -> 0.763
B36: ='124+900 '!B36 -> 45280 | C36: =B36-$B$13 -> 37 | D36: =D35 -> 1026 | E36: =VLOOKUP(B36,'124+900 '!B18:AA616,3,FALSE) -> 1957 | F36: =D36+E36 -> 2983 | G36: =VLOOKUP(B36,'124+900 '!$B$13:$AA$314,20,FALSE) -> 589 | H36: =VLOOKUP(B36,'124+900 '!$B$13:$AA$314,4,FALSE) -> 149 | I36: =F36-H36 -> 2834 | J36: =VLOOKUP(B36,'124+900 '!$B$13:$AA$314,13,FALSE) -> -166 | K36: =J36-J35 -> -6 | L36: =L35+K36 -> -45 | M36: =VLOOKUP(B36,'124+900 '!$B$13:$AA$314,21,FALSE) -> 587 | N36: =VLOOKUP(B36,'124+900 '!$B$13:$AA$314,5,FALSE) -> 159 | O36: =F36-N36 -> 2824 | P36: =VLOOKUP(B36,'124+900 '!$B$13:$AA$314,14,FALSE) -> -176 | Q36: =P36-P35 -> -6 | R36: =R35+Q36 -> -53 | S36: =VLOOKUP(B36,'124+900 '!$B$13:$AA$314,22,FALSE) -> 586 | T36: =VLOOKUP(B36,'124+900 '!$B$13:$AA$314,6,FALSE) -> 154 | U36: =F36-T36 -> 2829 | V36: =VLOOKUP(B36,'124+900 '!$B$13:$AA$314,15,FALSE) -> -171 | W36: =V36-V35 -> -6 | X36: =X35+W36 -> -58 | Y36: =M36-M35 -> -6 | Z36: =IF(Y36>0,Y36,0)/1000 -> 0 | AA36: =AA35+Z36 -> 0.75 | AB36: =(M36-$M$13-R36)/1000 -> 0.763
B37: ='124+900 '!B37 -> 45281 | C37: =B37-$B$13 -> 38 | D37: =D36 -> 1026 | E37: =VLOOKUP(B37,'124+900 '!B19:AA617,3,FALSE) -> 2495 | F37: =D37+E37 -> 3521 | G37: =VLOOKUP(B37,'124+900 '!$B$13:$AA$314,20,FALSE) -> 900 | H37: =VLOOKUP(B37,'124+900 '!$B$13:$AA$314,4,FALSE) -> 692 | I37: =F37-H37 -> 2829 | J37: =VLOOKUP(B37,'124+900 '!$B$13:$AA$314,13,FALSE) -> -171 | K37: =J37-J36 -> -5 | L37: =L36+K37 -> -50 | M37: =VLOOKUP(B37,'124+900 '!$B$13:$AA$314,21,FALSE) -> 900 | N37: =VLOOKUP(B37,'124+900 '!$B$13:$AA$314,5,FALSE) -> 704 | O37: =F37-N37 -> 2817 | P37: =VLOOKUP(B37,'124+900 '!$B$13:$AA$314,14,FALSE) -> -183 | Q37: =P37-P36 -> -7 | R37: =R36+Q37 -> -60 | S37: =VLOOKUP(B37,'124+900 '!$B$13:$AA$314,22,FALSE) -> 900 | T37: =VLOOKUP(B37,'124+900 '!$B$13:$AA$314,6,FALSE) -> 699 | U37: =F37-T37 -> 2822 | V37: =VLOOKUP(B37,'124+900 '!$B$13:$AA$314,15,FALSE) -> -178 | W37: =V37-V36 -> -7 | X37: =X36+W37 -> -65 | Y37: =M37-M36 -> 313 | Z37: =IF(Y37>0,Y37,0)/1000 -> 0.313 | AA37: =AA36+Z37 -> 1.063 | AB37: =(M37-$M$13-R37)/1000 -> 1.083
B38: ='124+900 '!B38 -> 45285 | C38: =B38-$B$13 -> 42 | D38: =D37 -> 1026 | E38: =VLOOKUP(B38,'124+900 '!B20:AA618,3,FALSE) -> 2458 | F38: =D38+E38 -> 3484 | G38: =VLOOKUP(B38,'124+900 '!$B$13:$AA$314,20,FALSE) -> 894 | H38: =VLOOKUP(B38,'124+900 '!$B$13:$AA$314,4,FALSE) -> 661 | I38: =F38-H38 -> 2823 | J38: =VLOOKUP(B38,'124+900 '!$B$13:$AA$314,13,FALSE) -> -177 | K38: =J38-J37 -> -6 | L38: =L37+K38 -> -56 | M38: =VLOOKUP(B38,'124+900 '!$B$13:$AA$314,21,FALSE) -> 893 | N38: =VLOOKUP(B38,'124+900 '!$B$13:$AA$314,5,FALSE) -> 674 | O38: =F38-N38 -> 2810 | P38: =VLOOKUP(B38,'124+900 '!$B$13:$AA$314,14,FALSE) -> -190 | Q38: =P38-P37 -> -7 | R38: =R37+Q38 -> -67 | S38: =VLOOKUP(B38,'124+900 '!$B$13:$AA$314,22,FALSE) -> 894 | T38: =VLOOKUP(B38,'124+900 '!$B$13:$AA$314,6,FALSE) -> 668 | U38: =F38-T38 -> 2816 | V38: =VLOOKUP(B38,'124+900 '!$B$13:$AA$314,15,FALSE) -> -184 | W38: =V38-V37 -> -6 | X38: =X37+W38 -> -71 | Y38: =M38-M37 -> -7 | Z38: =IF(Y38>0,Y38,0)/1000 -> 0 | AA38: =AA37+Z38 -> 1.063 | AB38: =(M38-$M$13-R38)/1000 -> 1.083
B39: ='124+900 '!B39 -> 45288 | C39: =B39-$B$13 -> 45 | D39: =D38 -> 1026 | E39: =VLOOKUP(B39,'124+900 '!B21:AA619,3,FALSE) -> 2156 | F39: =D39+E39 -> 3182 | G39: =VLOOKUP(B39,'124+900 '!$B$13:$AA$314,20,FALSE) -> 886 | H39: =VLOOKUP(B39,'124+900 '!$B$13:$AA$314,4,FALSE) -> 367 | I39: =F39-H39 -> 2815 | J39: =VLOOKUP(B39,'124+900 '!$B$13:$AA$314,13,FALSE) -> -185 | K39: =J39-J38 -> -8 | L39: =L38+K39 -> -64 | M39: =VLOOKUP(B39,'124+900 '!$B$13:$AA$314,21,FALSE) -> 890 | N39: =VLOOKUP(B39,'124+900 '!$B$13:$AA$314,5,FALSE) -> 375 | O39: =F39-N39 -> 2807 | P39: =VLOOKUP(B39,'124+900 '!$B$13:$AA$314,14,FALSE) -> -193 | Q39: =P39-P38 -> -3 | R39: =R38+Q39 -> -70 | S39: =VLOOKUP(B39,'124+900 '!$B$13:$AA$314,22,FALSE) -> 889 | T39: =VLOOKUP(B39,'124+900 '!$B$13:$AA$314,6,FALSE) -> 371 | U39: =F39-T39 -> 2811 | V39: =VLOOKUP(B39,'124+900 '!$B$13:$AA$314,15,FALSE) -> -189 | W39: =V39-V38 -> -5 | X39: =X38+W39 -> -76 | Y39: =M39-M38 -> -3 | Z39: =IF(Y39>0,Y39,0)/1000 -> 0 | AA39: =AA38+Z39 -> 1.063 | AB39: =(M39-$M$13-R39)/1000 -> 1.083
B40: ='124+900 '!B40 -> 45295 | C40: =B40-$B$13 -> 52 | D40: =D39 -> 1026 | E40: =VLOOKUP(B40,'124+900 '!B22:AA620,3,FALSE) -> 2311 | F40: =D40+E40 -> 3337 | G40: =VLOOKUP(B40,'124+900 '!$B$13:$AA$314,20,FALSE) -> 876 | H40: =VLOOKUP(B40,'124+900 '!$B$13:$AA$314,4,FALSE) -> 532 | I40: =F40-H40 -> 2805 | J40: =VLOOKUP(B40,'124+900 '!$B$13:$AA$314,13,FALSE) -> -195 | K40: =J40-J39 -> -10 | L40: =L39+K40 -> -74 | M40: =VLOOKUP(B40,'124+900 '!$B$13:$AA$314,21,FALSE) -> 878 | N40: =VLOOKUP(B40,'124+900 '!$B$13:$AA$314,5,FALSE) -> 542 | O40: =F40-N40 -> 2795 | P40: =VLOOKUP(B40,'124+900 '!$B$13:$AA$314,14,FALSE) -> -205 | Q40: =P40-P39 -> -12 | R40: =R39+Q40 -> -82 | S40: =VLOOKUP(B40,'124+900 '!$B$13:$AA$314,22,FALSE) -> 879 | T40: =VLOOKUP(B40,'124+900 '!$B$13:$AA$314,6,FALSE) -> 536 | U40: =F40-T40 -> 2801 | V40: =VLOOKUP(B40,'124+900 '!$B$13:$AA$314,15,FALSE) -> -199 | W40: =V40-V39 -> -10 | X40: =X39+W40 -> -86 | Y40: =M40-M39 -> -12 | Z40: =IF(Y40>0,Y40,0)/1000 -> 0 | AA40: =AA39+Z40 -> 1.063 | AB40: =(M40-$M$13-R40)/1000 -> 1.083
B41: ='124+900 '!B41 -> 45302 | C41: =B41-$B$13 -> 59 | D41: =D40 -> 1026 | E41: =VLOOKUP(B41,'124+900 '!B23:AA621,3,FALSE) -> 2100 | F41: =D41+E41 -> 3126 | G41: =VLOOKUP(B41,'124+900 '!$B$13:$AA$314,20,FALSE) -> 854 | H41: =VLOOKUP(B41,'124+900 '!$B$13:$AA$314,4,FALSE) -> 343 | I41: =F41-H41 -> 2783 | J41: =VLOOKUP(B41,'124+900 '!$B$13:$AA$314,13,FALSE) -> -217 | K41: =J41-J40 -> -22 | L41: =L40+K41 -> -96 | M41: =VLOOKUP(B41,'124+900 '!$B$13:$AA$314,21,FALSE) -> 858 | N41: =VLOOKUP(B41,'124+900 '!$B$13:$AA$314,5,FALSE) -> 351 | O41: =F41-N41 -> 2775 | P41: =VLOOKUP(B41,'124+900 '!$B$13:$AA$314,14,FALSE) -> -225 | Q41: =P41-P40 -> -20 | R41: =R40+Q41 -> -102 | S41: =VLOOKUP(B41,'124+900 '!$B$13:$AA$314,22,FALSE) -> 861 | T41: =VLOOKUP(B41,'124+900 '!$B$13:$AA$314,6,FALSE) -> 343 | U41: =F41-T41 -> 2783 | V41: =VLOOKUP(B41,'124+900 '!$B$13:$AA$314,15,FALSE) -> -217 | W41: =V41-V40 -> -18 | X41: =X40+W41 -> -104 | Y41: =M41-M40 -> -20 | Z41: =IF(Y41>0,Y41,0)/1000 -> 0 | AA41: =AA40+Z41 -> 1.063 | AB41: =(M41-$M$13-R41)/1000 -> 1.083
...

Sheet SL.124+900 
A1: DỰ ÁN THÀNH PHẦN ĐOẠN HẬU GIANG - CÀ MAU
A2: THUỘC DỰ ÁN XÂY DỰNG CÔNG TRÌNH ĐƯỜNG BỘ CAO TỐC BẮC - NAM PHÍA ĐÔNG GIAI ĐOẠN 2021 - 2025
A3: GÓI THẦU: THI CÔNG XÂY DỰNG ĐOẠN TUYẾN KM114+200-KM126+223
A4: CHỦ ĐẦU TƯ | F4: TƯ VẤN GIÁM SÁT | K4: NHÀ THẦU
A5: BAN QUẢN LÝ DỰ ÁN MỸ THUẬN | F5: LIÊN DANH TVGS PHÂN VIỆN KHCN GTVT PHÍA NAM VÀ CÔNG TY CỔ PHẦN TV KT&XD HỒNG HÀ | K5: LIÊN DANH TỔNG CÔNG TY XD SỐ 1 (CTCP) - CÔNG TY CỔ PHẦN HẢI ĐĂNG - CÔNG TY TNHH LIÊN HỢP XD VẠN CƯỜNG - CÔNG TY CỔ PHẦN XD VÀ ĐT 492 - CÔNG TY CỔ PHẦN XÂY DỰNG HẠ TẦNG BẮC TRUNG NAM
A6: BIỂU GHI ĐO QUAN TRẮC LÚN
A7: Người lập: | K7: Tên mốc:
A8: Thời tiết: | B8: ='[4]BC.124+090'!C8 -> năng | K8: Cao độ mốc: | M8: ='BC.124+900 '!N8 -> 1026
A9: Lý trình: | B9: ='124+900 '!C9 -> Km124+900 | K9: Ngày đặt bàn: | M9: =A13 -> 45243
A10: BÀN QUAN TRẮC: KM124+900
A11: Ngày đo | B11: Số ngày | C11: Cao độ đắp(m) | D11: Chiều cao nền đắp (m) | E11: chiều dày đắp(m) | F11: Trái | H11: Giữa | J11: Phải | L11: Độ lún (trái) (mm) | M11: Độ lún (giữa) (mm) | N11: Độ lún (phải) (mm) | O11: Ghi chú
F12: Cao độ quan trắc | G12: Cao độ bàn đo lún | H12: Cao độ quan trắc | I12: Cao độ bàn đo lún | J12: Cao độ quan trắc | K12: Cao độ bàn đo lún
A13: ='BC.124+900 '!B13 -> 45243 | B13: 1 | C13: ='BC.124+900 '!M13/1000 -> -0.123 | D13: ='BC.124+900 '!AA13 -> 0 | E13: =+C13-$F$8-(M13/1000) -> -0.123 | F13: =VLOOKUP($A13,'BC.124+900 '!$B$13:$X$862,8,0)/1000 -> 0.879 | G13: =VLOOKUP($A13,'BC.124+900 '!$B$13:$X$862,9,0)/1000 -> -0.121 | H13: =VLOOKUP($A13,'BC.124+900 '!$B$13:$X$862,14,0)/1000 -> 0.877 | I13: =VLOOKUP($A13,'BC.124+900 '!$B$13:$X$862,15,0)/1000 -> -0.123 | J13: =VLOOKUP($A13,'BC.124+900 '!$B$13:$X$862,20,0)/1000 -> 0.887 | K13: =VLOOKUP($A13,'BC.124+900 '!$B$13:$X$862,21,0)/1000 -> -0.113 | L13: =(G13-$G$13)*1000 -> 0 | M13: =(I13-$I$13)*1000 -> 0 | N13: =(K13-$K$13)*1000 -> 0
A14: ='BC.124+900 '!B14 -> 45244 | B14: 2 | C14: ='BC.124+900 '!M14/1000 -> -0.123 | D14: ='BC.124+900 '!AA14 -> 0 | E14: =+C14-$F$8-(M14/1000) -> -0.123 | F14: =VLOOKUP($A14,'BC.124+900 '!$B$13:$X$862,8,0)/1000 -> 0.879 | G14: =VLOOKUP($A14,'BC.124+900 '!$B$13:$X$862,9,0)/1000 -> -0.121 | H14: =VLOOKUP($A14,'BC.124+900 '!$B$13:$X$862,14,0)/1000 -> 0.877 | I14: =VLOOKUP($A14,'BC.124+900 '!$B$13:$X$862,15,0)/1000 -> -0.123 | J14: =VLOOKUP($A14,'BC.124+900 '!$B$13:$X$862,20,0)/1000 -> 0.887 | K14: =VLOOKUP($A14,'BC.124+900 '!$B$13:$X$862,21,0)/1000 -> -0.113 | L14: =(G14-$G$13)*1000 -> 0 | M14: =(I14-$I$13)*1000 -> 0 | N14: =(K14-$K$13)*1000 -> 0
A15: ='BC.124+900 '!B15 -> 45245 | B15: 3 | C15: ='BC.124+900 '!M15/1000 -> -0.123 | D15: ='BC.124+900 '!AA15 -> 0 | E15: =+C15-$F$8-(M15/1000) -> -0.123 | F15: =VLOOKUP($A15,'BC.124+900 '!$B$13:$X$862,8,0)/1000 -> 0.879 | G15: =VLOOKUP($A15,'BC.124+900 '!$B$13:$X$862,9,0)/1000 -> -0.121 | H15: =VLOOKUP($A15,'BC.124+900 '!$B$13:$X$862,14,0)/1000 -> 0.877 | I15: =VLOOKUP($A15,'BC.124+900 '!$B$13:$X$862,15,0)/1000 -> -0.123 | J15: =VLOOKUP($A15,'BC.124+900 '!$B$13:$X$862,20,0)/1000 -> 0.887 | K15: =VLOOKUP($A15,'BC.124+900 '!$B$13:$X$862,21,0)/1000 -> -0.113 | L15: =(G15-$G$13)*1000 -> 0 | M15: =(I15-$I$13)*1000 -> 0 | N15: =(K15-$K$13)*1000 -> 0
A16: ='BC.124+900 '!B16 -> 45249 | B16: 4 | C16: ='BC.124+900 '!M16/1000 -> -0.123 | D16: ='BC.124+900 '!AA16 -> 0 | E16: =+C16-$F$8-(M16/1000) -> -0.123 | F16: =VLOOKUP($A16,'BC.124+900 '!$B$13:$X$862,8,0)/1000 -> 0.879 | G16: =VLOOKUP($A16,'BC.124+900 '!$B$13:$X$862,9,0)/1000 -> -0.121 | H16: =VLOOKUP($A16,'BC.124+900 '!$B$13:$X$862,14,0)/1000 -> 0.877 | I16: =VLOOKUP($A16,'BC.124+900 '!$B$13:$X$862,15,0)/1000 -> -0.123 | J16: =VLOOKUP($A16,'BC.124+900 '!$B$13:$X$862,20,0)/1000 -> 0.887 | K16: =VLOOKUP($A16,'BC.124+900 '!$B$13:$X$862,21,0)/1000 -> -0.113 | L16: =(G16-$G$13)*1000 -> 0 | M16: =(I16-$I$13)*1000 -> 0 | N16: =(K16-$K$13)*1000 -> 0
A17: ='BC.124+900 '!B17 -> 45252 | B17: 5 | C17: ='BC.124+900 '!M17/1000 -> -0.123 | D17: ='BC.124+900 '!AA17 -> 0 | E17: =+C17-$F$8-(M17/1000) -> -0.123 | F17: =VLOOKUP($A17,'BC.124+900 '!$B$13:$X$862,8,0)/1000 -> 0.879 | G17: =VLOOKUP($A17,'BC.124+900 '!$B$13:$X$862,9,0)/1000 -> -0.121 | H17: =VLOOKUP($A17,'BC.124+900 '!$B$13:$X$862,14,0)/1000 -> 0.877 | I17: =VLOOKUP($A17,'BC.124+900 '!$B$13:$X$862,15,0)/1000 -> -0.123 | J17: =VLOOKUP($A17,'BC.124+900 '!$B$13:$X$862,20,0)/1000 -> 0.887 | K17: =VLOOKUP($A17,'BC.124+900 '!$B$13:$X$862,21,0)/1000 -> -0.113 | L17: =(G17-$G$13)*1000 -> 0 | M17: =(I17-$I$13)*1000 -> 0 | N17: =(K17-$K$13)*1000 -> 0
A18: ='BC.124+900 '!B18 -> 45259 | B18: 6 | C18: ='BC.124+900 '!M18/1000 -> -0.123 | D18: ='BC.124+900 '!AA18 -> 0 | E18: =+C18-$F$8-(M18/1000) -> -0.123 | F18: =VLOOKUP($A18,'BC.124+900 '!$B$13:$X$862,8,0)/1000 -> 0.879 | G18: =VLOOKUP($A18,'BC.124+900 '!$B$13:$X$862,9,0)/1000 -> -0.121 | H18: =VLOOKUP($A18,'BC.124+900 '!$B$13:$X$862,14,0)/1000 -> 0.877 | I18: =VLOOKUP($A18,'BC.124+900 '!$B$13:$X$862,15,0)/1000 -> -0.123 | J18: =VLOOKUP($A18,'BC.124+900 '!$B$13:$X$862,20,0)/1000 -> 0.887 | K18: =VLOOKUP($A18,'BC.124+900 '!$B$13:$X$862,21,0)/1000 -> -0.113 | L18: =(G18-$G$13)*1000 -> 0 | M18: =(I18-$I$13)*1000 -> 0 | N18: =(K18-$K$13)*1000 -> 0
A19: ='BC.124+900 '!B19 -> 45263 | B19: 7 | C19: ='BC.124+900 '!M19/1000 -> -0.123 | D19: ='BC.124+900 '!AA19 -> 0 | E19: =+C19-$F$8-(M19/1000) -> -0.123 | F19: =VLOOKUP($A19,'BC.124+900 '!$B$13:$X$862,8,0)/1000 -> 0.879 | G19: =VLOOKUP($A19,'BC.124+900 '!$B$13:$X$862,9,0)/1000 -> -0.121 | H19: =VLOOKUP($A19,'BC.124+900 '!$B$13:$X$862,14,0)/1000 -> 0.877 | I19: =VLOOKUP($A19,'BC.124+900 '!$B$13:$X$862,15,0)/1000 -> -0.123 | J19: =VLOOKUP($A19,'BC.124+900 '!$B$13:$X$862,20,0)/1000 -> 0.887 | K19: =VLOOKUP($A19,'BC.124+900 '!$B$13:$X$862,21,0)/1000 -> -0.113 | L19: =(G19-$G$13)*1000 -> 0 | M19: =(I19-$I$13)*1000 -> 0 | N19: =(K19-$K$13)*1000 -> 0
A20: ='BC.124+900 '!B20 -> 45264 | B20: 8 | C20: ='BC.124+900 '!M20/1000 -> -0.123 | D20: ='BC.124+900 '!AA20 -> 0 | E20: =+C20-$F$8-(M20/1000) -> -0.123 | F20: =VLOOKUP($A20,'BC.124+900 '!$B$13:$X$862,8,0)/1000 -> 0.879 | G20: =VLOOKUP($A20,'BC.124+900 '!$B$13:$X$862,9,0)/1000 -> -0.121 | H20: =VLOOKUP($A20,'BC.124+900 '!$B$13:$X$862,14,0)/1000 -> 0.877 | I20: =VLOOKUP($A20,'BC.124+900 '!$B$13:$X$862,15,0)/1000 -> -0.123 | J20: =VLOOKUP($A20,'BC.124+900 '!$B$13:$X$862,20,0)/1000 -> 0.887 | K20: =VLOOKUP($A20,'BC.124+900 '!$B$13:$X$862,21,0)/1000 -> -0.113 | L20: =(G20-$G$13)*1000 -> 0 | M20: =(I20-$I$13)*1000 -> 0 | N20: =(K20-$K$13)*1000 -> 0
A21: ='BC.124+900 '!B21 -> 45265 | B21: 9 | C21: ='BC.124+900 '!M21/1000 -> -0.123 | D21: ='BC.124+900 '!AA21 -> 0 | E21: =+C21-$F$8-(M21/1000) -> -0.123 | F21: =VLOOKUP($A21,'BC.124+900 '!$B$13:$X$862,8,0)/1000 -> 0.879 | G21: =VLOOKUP($A21,'BC.124+900 '!$B$13:$X$862,9,0)/1000 -> -0.121 | H21: =VLOOKUP($A21,'BC.124+900 '!$B$13:$X$862,14,0)/1000 -> 0.877 | I21: =VLOOKUP($A21,'BC.124+900 '!$B$13:$X$862,15,0)/1000 -> -0.123 | J21: =VLOOKUP($A21,'BC.124+900 '!$B$13:$X$862,20,0)/1000 -> 0.887 | K21: =VLOOKUP($A21,'BC.124+900 '!$B$13:$X$862,21,0)/1000 -> -0.113 | L21: =(G21-$G$13)*1000 -> 0 | M21: =(I21-$I$13)*1000 -> 0 | N21: =(K21-$K$13)*1000 -> 0
A22: ='BC.124+900 '!B22 -> 45266 | B22: 10 | C22: ='BC.124+900 '!M22/1000 -> -0.123 | D22: ='BC.124+900 '!AA22 -> 0 | E22: =+C22-$F$8-(M22/1000) -> -0.123 | F22: =VLOOKUP($A22,'BC.124+900 '!$B$13:$X$862,8,0)/1000 -> 0.879 | G22: =VLOOKUP($A22,'BC.124+900 '!$B$13:$X$862,9,0)/1000 -> -0.121 | H22: =VLOOKUP($A22,'BC.124+900 '!$B$13:$X$862,14,0)/1000 -> 0.877 | I22: =VLOOKUP($A22,'BC.124+900 '!$B$13:$X$862,15,0)/1000 -> -0.123 | J22: =VLOOKUP($A22,'BC.124+900 '!$B$13:$X$862,20,0)/1000 -> 0.887 | K22: =VLOOKUP($A22,'BC.124+900 '!$B$13:$X$862,21,0)/1000 -> -0.113 | L22: =(G22-$G$13)*1000 -> 0 | M22: =(I22-$I$13)*1000 -> 0 | N22: =(K22-$K$13)*1000 -> 0
A23: ='BC.124+900 '!B23 -> 45267 | B23: 11 | C23: ='BC.124+900 '!M23/1000 -> -0.123 | D23: ='BC.124+900 '!AA23 -> 0 | E23: =+C23-$F$8-(M23/1000) -> -0.123 | F23: =VLOOKUP($A23,'BC.124+900 '!$B$13:$X$862,8,0)/1000 -> 0.879 | G23: =VLOOKUP($A23,'BC.124+900 '!$B$13:$X$862,9,0)/1000 -> -0.121 | H23: =VLOOKUP($A23,'BC.124+900 '!$B$13:$X$862,14,0)/1000 -> 0.877 | I23: =VLOOKUP($A23,'BC.124+900 '!$B$13:$X$862,15,0)/1000 -> -0.123 | J23: =VLOOKUP($A23,'BC.124+900 '!$B$13:$X$862,20,0)/1000 -> 0.887 | K23: =VLOOKUP($A23,'BC.124+900 '!$B$13:$X$862,21,0)/1000 -> -0.113 | L23: =(G23-$G$13)*1000 -> 0 | M23: =(I23-$I$13)*1000 -> 0 | N23: =(K23-$K$13)*1000 -> 0
A24: ='BC.124+900 '!B24 -> 45268 | B24: 12 | C24: ='BC.124+900 '!M24/1000 -> -0.123 | D24: ='BC.124+900 '!AA24 -> 0 | E24: =+C24-$F$8-(M24/1000) -> -0.123 | F24: =VLOOKUP($A24,'BC.124+900 '!$B$13:$X$862,8,0)/1000 -> 0.879 | G24: =VLOOKUP($A24,'BC.124+900 '!$B$13:$X$862,9,0)/1000 -> -0.121 | H24: =VLOOKUP($A24,'BC.124+900 '!$B$13:$X$862,14,0)/1000 -> 0.877 | I24: =VLOOKUP($A24,'BC.124+900 '!$B$13:$X$862,15,0)/1000 -> -0.123 | J24: =VLOOKUP($A24,'BC.124+900 '!$B$13:$X$862,20,0)/1000 -> 0.887 | K24: =VLOOKUP($A24,'BC.124+900 '!$B$13:$X$862,21,0)/1000 -> -0.113 | L24: =(G24-$G$13)*1000 -> 0 | M24: =(I24-$I$13)*1000 -> 0 | N24: =(K24-$K$13)*1000 -> 0
... A142: ='BC.124+900 '!B142 -> 45610 | B142: 130 | C142: ='BC.124+900 '!M142/1000 -> 3.71 | D142: ='BC.124+900 '!AA142 -> 5.026 | E142: =+C142-$F$8-(M142/1000) -> 5.079 | F142: =VLOOKUP($A142,'BC.124+900 '!$B$13:$X$862,8,0)/1000 -> 1.728 | G142: =VLOOKUP($A142,'BC.124+900 '!$B$13:$X$862,9,0)/1000 -> -1.272 | H142: =VLOOKUP($A142,'BC.124+900 '!$B$13:$X$862,14,0)/1000 -> 1.508 | I142: =VLOOKUP($A142,'BC.124+900 '!$B$13:$X$862,15,0)/1000 -> -1.492 | J142: =VLOOKUP($A142,'BC.124+900 '!$B$13:$X$862,20,0)/1000 -> 1.916 | K142: =VLOOKUP($A142,'BC.124+900 '!$B$13:$X$862,21,0)/1000 -> -1.084 | L142: =(G142-$G$13)*1000 -> -1151 | M142: =(I142-$I$13)*1000 -> -1369 | N142: =(K142-$K$13)*1000 -> -971
A143: ='BC.124+900 '!B143 -> 45611 | B143: 131 | C143: ='BC.124+900 '!M143/1000 -> 3.94 | D143: ='BC.124+900 '!AA143 -> 5.256 | E143: =+C143-$F$8-(M143/1000) -> 5.319 | F143: =VLOOKUP($A143,'BC.124+900 '!$B$13:$X$862,8,0)/1000 -> 1.718 | G143: =VLOOKUP($A143,'BC.124+900 '!$B$13:$X$862,9,0)/1000 -> -1.282 | H143: =VLOOKUP($A143,'BC.124+900 '!$B$13:$X$862,14,0)/1000 -> 1.498 | I143: =VLOOKUP($A143,'BC.124+900 '!$B$13:$X$862,15,0)/1000 -> -1.502 | J143: =VLOOKUP($A143,'BC.124+900 '!$B$13:$X$862,20,0)/1000 -> 1.913 | K143: =VLOOKUP($A143,'BC.124+900 '!$B$13:$X$862,21,0)/1000 -> -1.087 | L143: =(G143-$G$13)*1000 -> -1161 | M143: =(I143-$I$13)*1000 -> -1379 | N143: =(K143-$K$13)*1000 -> -974 | O143: K.Thúc GT
A144: ='BC.124+900 '!B144 -> 45614 | B144: 132 | C144: ='BC.124+900 '!M144/1000 -> 3.91 | D144: ='BC.124+900 '!AA144 -> 5.256 | E144: =+C144-$F$8-(M144/1000) -> 5.319 | F144: =VLOOKUP($A144,'BC.124+900 '!$B$13:$X$862,8,0)/1000 -> 1.688 | G144: =VLOOKUP($A144,'BC.124+900 '!$B$13:$X$862,9,0)/1000 -> -1.312 | H144: =VLOOKUP($A144,'BC.124+900 '!$B$13:$X$862,14,0)/1000 -> 1.468 | I144: =VLOOKUP($A144,'BC.124+900 '!$B$13:$X$862,15,0)/1000 -> -1.532 | J144: =VLOOKUP($A144,'BC.124+900 '!$B$13:$X$862,20,0)/1000 -> 1.885 | K144: =VLOOKUP($A144,'BC.124+900 '!$B$13:$X$862,21,0)/1000 -> -1.115 | L144: =(G144-$G$13)*1000 -> -1191 | M144: =(I144-$I$13)*1000 -> -1409 | N144: =(K144-$K$13)*1000 -> -1002
A145: ='BC.124+900 '!B145 -> 45618 | B145: 133 | C145: ='BC.124+900 '!M145/1000 -> 3.86 | D145: ='BC.124+900 '!AA145 -> 5.256 | E145: =+C145-$F$8-(M145/1000) -> 5.319 | F145: =VLOOKUP($A145,'BC.124+900 '!$B$13:$X$862,8,0)/1000 -> 2.643 | G145: =VLOOKUP($A145,'BC.124+900 '!$B$13:$X$862,9,0)/1000 -> -1.357 | H145: =VLOOKUP($A145,'BC.124+900 '!$B$13:$X$862,14,0)/1000 -> 2.418 | I145: =VLOOKUP($A145,'BC.124+900 '!$B$13:$X$862,15,0)/1000 -> -1.582 | J145: =VLOOKUP($A145,'BC.124+900 '!$B$13:$X$862,20,0)/1000 -> 2.843 | K145: =VLOOKUP($A145,'BC.124+900 '!$B$13:$X$862,21,0)/1000 -> -1.157 | L145: =(G145-$G$13)*1000 -> -1236 | M145: =(I145-$I$13)*1000 -> -1459 | N145: =(K145-$K$13)*1000 -> -1044
A146: ='BC.124+900 '!B146 -> 45621 | B146: 134 | C146: ='BC.124+900 '!M146/1000 -> 3.825 | D146: ='BC.124+900 '!AA146 -> 5.256 | E146: =+C146-$F$8-(M146/1000) -> 5.319 | F146: =VLOOKUP($A146,'BC.124+900 '!$B$13:$X$862,8,0)/1000 -> 2.617 | G146: =VLOOKUP($A146,'BC.124+900 '!$B$13:$X$862,9,0)/1000 -> -1.383 | H146: =VLOOKUP($A146,'BC.124+900 '!$B$13:$X$862,14,0)/1000 -> 2.383 | I146: =VLOOKUP($A146,'BC.124+900 '!$B$13:$X$862,15,0)/1000 -> -1.617 | J146: =VLOOKUP($A146,'BC.124+900 '!$B$13:$X$862,20,0)/1000 -> 2.819 | K146: =VLOOKUP($A146,'BC.124+900 '!$B$13:$X$862,21,0)/1000 -> -1.181 | L146: =(G146-$G$13)*1000 -> -1262 | M146: =(I146-$I$13)*1000 -> -1494 | N146: =(K146-$K$13)*1000 -> -1068
A147: ='BC.124+900 '!B147 -> 45625 | B147: 135 | C147: ='BC.124+900 '!M147/1000 -> 3.78 | D147: ='BC.124+900 '!AA147 -> 5.256 | E147: =+C147-$F$8-(M147/1000) -> 5.319 | F147: =VLOOKUP($A147,'BC.124+900 '!$B$13:$X$862,8,0)/1000 -> 2.574 | G147: =VLOOKUP($A147,'BC.124+900 '!$B$13:$X$862,9,0)/1000 -> -1.426 | H147: =VLOOKUP($A147,'BC.124+900 '!$B$13:$X$862,14,0)/1000 -> 2.338 | I147: =VLOOKUP($A147,'BC.124+900 '!$B$13:$X$862,15,0)/1000 -> -1.662 | J147: =VLOOKUP($A147,'BC.124+900 '!$B$13:$X$862,20,0)/1000 -> 2.779 | K147: =VLOOKUP($A147,'BC.124+900 '!$B$13:$X$862,21,0)/1000 -> -1.221 | L147: =(G147-$G$13)*1000 -> -1305 | M147: =(I147-$I$13)*1000 -> -1539 | N147: =(K147-$K$13)*1000 -> -1108
