Workbook

Sheet Matsuo-Kawamura KM91-TT 
A1: ='Matsuo-Kawamura KM91-PT '!A1:J1 -> Biểu đồ tính ổn định tại Km91+620 PT
A2: TT | B2: Ngày đo | C2: Lũy kế thời gian | D2: FOS_actual | H2: FOS_actual_corrected
C3: (ngày) | D3: S (m) | E3: H(mm) | F3: H (m) | G3: H/S | H3: S | I3: H | J3: H/S
A4: 0 | B4: 45344 | D4: ='Matsuo-Kawamura KM91-PT '!D4 -> 0.29 | E4: 0 | F4: 0 | G4: =IF(AND(D4>0,F4>0),F4/D4,"") | I4: =F5 -> 0.00056825251 | J4: =IF(AND(H4>0,I4>0),I4/H4,"")
A5: 1 | B5: 45345 | C5: =B5-$B$4 -> 1 | D5: ='Matsuo-Kawamura KM91-PT '!D5 -> 0.292 | E5: 0.56825251 | F5: =E5/1000 -> 0.00056825251 | G5: =IF(AND(D5>0,F5>0),F5/D5,"") -> 0.0019460702 | H5: =D5 -> 0.292 | I5: =F5+$I$4 -> 0.001136505 | J5: =IF(AND(H5>0,I5>0),I5/H5,"") -> 0.0038921405 | K5: =E5/1000 -> 0.00056825251 | N5: =E5/1000 -> 0.00056825251
A6: =A5+1 -> 2 | B6: 45346 | C6: =B6-$B$4 -> 2 | D6: ='Matsuo-Kawamura KM91-PT '!D6 -> 0.294 | E6: 0.66247149 | F6: =E6/1000 -> 0.00066247149 | G6: =IF(AND(D6>0,F6>0),F6/D6,"") -> 0.0022533044 | H6: =D6 -> 0.294 | I6: =F6+$I$4 -> 0.001230724 | J6: =IF(AND(H6>0,I6>0),I6/H6,"") -> 0.0041861361 | K6: =E6/1000 -> 0.00066247149
A7: =A6+1 -> 3 | B7: 45347 | C7: =B7-$B$4 -> 3 | D7: ='Matsuo-Kawamura KM91-PT '!D7 -> 0.296 | E7: 0.74963879 | F7: =E7/1000 -> 0.00074963879 | G7: =IF(AND(D7>0,F7>0),F7/D7,"") -> 0.0025325635 | H7: =D7 -> 0.296 | I7: =F7+$I$4 -> 0.0013178913 | J7: =IF(AND(H7>0,I7>0),I7/H7,"") -> 0.0044523355 | K7: =E7/1000 -> 0.00074963879
A8: =A7+1 -> 4 | B8: 45348 | C8: =B8-$B$4 -> 4 | D8: ='Matsuo-Kawamura KM91-PT '!D8 -> 0.298 | E8: 0.8368061 | F8: =E8/1000 -> 0.0008368061 | G8: =IF(AND(D8>0,F8>0),F8/D8,"") -> 0.0028080741 | H8: =D8 -> 0.298 | I8: =F8+$I$4 -> 0.0014050586 | J8: =IF(AND(H8>0,I8>0),I8/H8,"") -> 0.0047149618 | K8: =E8/1000 -> 0.0008368061
A9: =A8+1 -> 5 | B9: 45349 | C9: =B9-$B$4 -> 5 | D9: ='Matsuo-Kawamura KM91-PT '!D9 -> 0.3 | E9: 0.9239734 | F9: =E9/1000 -> 0.0009239734 | G9: =IF(AND(D9>0,F9>0),F9/D9,"") -> 0.0030799113 | H9: =D9 -> 0.3 | I9: =F9+$I$4 -> 0.0014922259 | J9: =IF(AND(H9>0,I9>0),I9/H9,"") -> 0.0049740864 | K9: =E9/1000 -> 0.0009239734
A10: =A9+1 -> 6 | B10: 45350 | C10: =B10-$B$4 -> 6 | D10: ='Matsuo-Kawamura KM91-PT '!D10 -> 0.301 | E10: 0.96755705 | F10: =E10/1000 -> 0.00096755705 | G10: =IF(AND(D10>0,F10>0),F10/D10,"") -> 0.0032144752 | H10: =D10 -> 0.301 | I10: =F10+$I$4 -> 0.0015358096 | J10: =IF(AND(H10>0,I10>0),I10/H10,"") -> 0.0051023573 | K10: =E10/1000 -> 0.00096755705
A11: =A10+1 -> 7 | B11: 45351 | C11: =B11-$B$4 -> 7 | D11: ='Matsuo-Kawamura KM91-PT '!D11 -> 0.302 | E11: 1.0111407 | F11: =E11/1000 -> 0.0010111407 | G11: =IF(AND(D11>0,F11>0),F11/D11,"") -> 0.003348148 | H11: =D11 -> 0.302 | I11: =F11+$I$4 -> 0.0015793932 | J11: =IF(AND(H11>0,I11>0),I11/H11,"") -> 0.0052297788 | K11: =E11/1000 -> 0.0010111407
A12: =A11+1 -> 8 | B12: 45352 | C12: =B12-$B$4 -> 8 | D12: ='Matsuo-Kawamura KM91-PT '!D12 -> 0.306 | E12: 1.098308 | F12: =E12/1000 -> 0.001098308 | G12: =IF(AND(D12>0,F12>0),F12/D12,"") -> 0.0035892418 | H12: =D12 -> 0.306 | I12: =F12+$I$4 -> 0.0016665605 | J12: =IF(AND(H12>0,I12>0),I12/H12,"") -> 0.0054462762 | K12: =E12/1000 -> 0.001098308
A13: =A12+1 -> 9 | B13: 45353 | C13: =B13-$B$4 -> 9 | D13: ='Matsuo-Kawamura KM91-PT '!D13 -> 0.31 | E13: 1.2543129 | F13: =E13/1000 -> 0.0012543129 | G13: =IF(AND(D13>0,F13>0),F13/D13,"") -> 0.0040461705 | H13: =D13 -> 0.31 | I13: =F13+$I$4 -> 0.0018225654 | J13: =IF(AND(H13>0,I13>0),I13/H13,"") -> 0.0058792432 | K13: =E13/1000 -> 0.0012543129
A14: =A13+1 -> 10 | B14: 45354 | C14: =B14-$B$4 -> 10 | D14: ='Matsuo-Kawamura KM91-PT '!D14 -> 0.314 | E14: 1.4147377 | F14: =E14/1000 -> 0.0014147377 | G14: =IF(AND(D14>0,F14>0),F14/D14,"") -> 0.0045055341 | H14: =D14 -> 0.314 | I14: =F14+$I$4 -> 0.0019829902 | J14: =IF(AND(H14>0,I14>0),I14/H14,"") -> 0.0063152555 | K14: =E14/1000 -> 0.0014147377
A15: =A14+1 -> 11 | B15: 45355 | C15: =B15-$B$4 -> 11 | D15: ='Matsuo-Kawamura KM91-PT '!D15 -> 0.318 | E15: 1.5882203 | F15: =E15/1000 -> 0.0015882203 | G15: =IF(AND(D15>0,F15>0),F15/D15,"") -> 0.0049944035 | H15: =D15 -> 0.318 | I15: =F15+$I$4 -> 0.0021564728 | J15: =IF(AND(H15>0,I15>0),I15/H15,"") -> 0.006781361 | K15: =E15/1000 -> 0.0015882203
A16: =A15+1 -> 12 | B16: 45356 | C16: =B16-$B$4 -> 12 | D16: 0.137 | E16: 1.7617029 | F16: =E16/1000 -> 0.0017617029 | G16: =IF(AND(D16>0,F16>0),F16/D16,"") -> 0.012859145 | H16: =D16 -> 0.137 | I16: =F16+$I$4 -> 0.0023299554 | J16: =IF(AND(H16>0,I16>0),I16/H16,"") -> 0.017006974 | K16: =E16/1000 -> 0.0017617029
A17: =A16+1 -> 13 | B17: 45357 | C17: =B17-$B$4 -> 13 | D17: 0.145 | E17: 1.9351855 | F17: =E17/1000 -> 0.0019351855 | G17: =IF(AND(D17>0,F17>0),F17/D17,"") -> 0.013346107 | H17: =D17 -> 0.145 | I17: =F17+$I$4 -> 0.002503438 | J17: =IF(AND(H17>0,I17>0),I17/H17,"") -> 0.01726509 | K17: =E17/1000 -> 0.0019351855
A18: =A17+1 -> 14 | B18: 45358 | C18: =B18-$B$4 -> 14 | D18: 0.156 | E18: 2.1086681 | F18: =E18/1000 -> 0.0021086681 | G18: =IF(AND(D18>0,F18>0),F18/D18,"") -> 0.013517103 | H18: =D18 -> 0.156 | I18: =F18+$I$4 -> 0.0026769206 | J18: =IF(AND(H18>0,I18>0),I18/H18,"") -> 0.017159748 | K18: =E18/1000 -> 0.0021086681
A19: =A18+1 -> 15 | B19: 45359 | C19: =B19-$B$4 -> 15 | D19: 0.168 | E19: 2.1086681 | F19: =E19/1000 -> 0.0021086681 | G19: =IF(AND(D19>0,F19>0),F19/D19,"") -> 0.012551596 | H19: =D19 -> 0.168 | I19: =F19+$I$4 -> 0.0026769206 | J19: =IF(AND(H19>0,I19>0),I19/H19,"") -> 0.015934051 | K19: =E19/1000 -> 0.0021086681
A20: =A19+1 -> 16 | B20: 45360 | C20: =B20-$B$4 -> 16 | D20: 0.18 | E20: 2.2917476 | F20: =E20/1000 -> 0.0022917476 | G20: =IF(AND(D20>0,F20>0),F20/D20,"") -> 0.012731931 | H20: =D20 -> 0.18 | I20: =F20+$I$4 -> 0.0028600001 | J20: =IF(AND(H20>0,I20>0),I20/H20,"") -> 0.01588889 | K20: =E20/1000 -> 0.0022917476
A21: =A15+1 -> 12 | B21: 45361 | C21: =B21-$B$4 -> 17 | D21: ='Matsuo-Kawamura KM91-PT '!D21 -> 0.34 | E21: 2.4756994 | F21: =E21/1000 -> 0.0024756994 | G21: =IF(AND(D21>0,F21>0),F21/D21,"") -> 0.0072814688 | H21: =D21 -> 0.34 | I21: =F21+$I$4 -> 0.0030439519 | J21: =IF(AND(H21>0,I21>0),I21/H21,"") -> 0.0089527997 | K21: =E21/1000 -> 0.0024756994
A22: =A21+1 -> 13 | B22: 45362 | C22: =B22-$B$4 -> 18 | D22: ='Matsuo-Kawamura KM91-PT '!D22 -> 0.343 | E22: 2.6596512 | F22: =E22/1000 -> 0.0026596512 | G22: =IF(AND(D22>0,F22>0),F22/D22,"") -> 0.0077540851 | H22: =D22 -> 0.343 | I22: =F22+$I$4 -> 0.0032279037 | J22: =IF(AND(H22>0,I22>0),I22/H22,"") -> 0.009410798 | K22: =E22/1000 -> 0.0026596512
A23: =A22+1 -> 14 | B23: 45363 | C23: =B23-$B$4 -> 19 | D23: ='Matsuo-Kawamura KM91-PT '!D23 -> 0.346 | E23: 2.843603 | F23: =E23/1000 -> 0.002843603 | G23: =IF(AND(D23>0,F23>0),F23/D23,"") -> 0.0082185058 | H23: =D23 -> 0.346 | I23: =F23+$I$4 -> 0.0034118555 | J23: =IF(AND(H23>0,I23>0),I23/H23,"") -> 0.0098608541 | K23: =E23/1000 -> 0.002843603
A24: =A23+1 -> 15 | B24: 45364 | C24: =B24-$B$4 -> 20 | D24: ='Matsuo-Kawamura KM91-PT '!D24 -> 0.349 | E24: 3.0275548 | F24: =E24/1000 -> 0.0030275548 | G24: =IF(AND(D24>0,F24>0),F24/D24,"") -> 0.0086749421 | H24: =D24 -> 0.349 | I24: =F24+$I$4 -> 0.0035958073 | J24: =IF(AND(H24>0,I24>0),I24/H24,"") -> 0.010303173 | K24: =E24/1000 -> 0.0030275548
A25: =A24+1 -> 16 | B25: 45365 | C25: =B25-$B$4 -> 21 | D25: ='Matsuo-Kawamura KM91-PT '!D25 -> 0.352 | E25: 3.2115066 | F25: =E25/1000 -> 0.0032115066 | G25: =IF(AND(D25>0,F25>0),F25/D25,"") -> 0.0091235983 | H25: =D25 -> 0.352 | I25: =F25+$I$4 -> 0.0037797591 | J25: =IF(AND(H25>0,I25>0),I25/H25,"") -> 0.010737952 | K25: =E25/1000 -> 0.0032115066
A26: =A25+1 -> 17 | B26: 45366 | C26: =B26-$B$4 -> 22 | D26: ='Matsuo-Kawamura KM91-PT '!D26 -> 0.355 | E26: 3.4874343 | F26: =E26/1000 -> 0.0034874343 | G26: =IF(AND(D26>0,F26>0),F26/D26,"") -> 0.0098237586 | H26: =D26 -> 0.355 | I26: =F26+$I$4 -> 0.0040556868 | J26: =IF(AND(H26>0,I26>0),I26/H26,"") -> 0.01142447 | K26: =E26/1000 -> 0.0034874343
A27: =A26+1 -> 18 | B27: 45367 | C27: =B27-$B$4 -> 23 | D27: ='Matsuo-Kawamura KM91-PT '!D27 -> 0.358 | E27: 3.763362 | F27: =E27/1000 -> 0.003763362 | G27: =IF(AND(D27>0,F27>0),F27/D27,"") -> 0.010512184 | H27: =D27 -> 0.358 | I27: =F27+$I$4 -> 0.0043316145 | J27: =IF(AND(H27>0,I27>0),I27/H27,"") -> 0.012099482 | K27: =E27/1000 -> 0.003763362
A28: =A27+1 -> 19 | B28: 45368 | C28: =B28-$B$4 -> 24 | D28: ='Matsuo-Kawamura KM91-PT '!D28 -> 0.361 | E28: 3.8438687 | F28: =E28/1000 -> 0.0038438687 | G28: =IF(AND(D28>0,F28>0),F28/D28,"") -> 0.010647836 | H28: =D28 -> 0.361 | I28: =F28+$I$4 -> 0.0044121212 | J28: =IF(AND(H28>0,I28>0),I28/H28,"") -> 0.012221942 | K28: =E28/1000 -> 0.0038438687
A29: =A28+1 -> 20 | B29: 45369 | C29: =B29-$B$4 -> 25 | D29: ='Matsuo-Kawamura KM91-PT '!D29 -> 0.363 | E29: 3.9243754 | F29: =E29/1000 -> 0.0039243754 | G29: =IF(AND(D29>0,F29>0),F29/D29,"") -> 0.010810952 | H29: =D29 -> 0.363 | I29: =F29+$I$4 -> 0.0044926279 | J29: =IF(AND(H29>0,I29>0),I29/H29,"") -> 0.012376386 | K29: =E29/1000 -> 0.0039243754
A30: =A29+1 -> 21 | B30: 45370 | C30: =B30-$B$4 -> 26 | D30: ='Matsuo-Kawamura KM91-PT '!D30 -> 0.365 | E30: 4.0048821 | F30: =E30/1000 -> 0.0040048821 | G30: =IF(AND(D30>0,F30>0),F30/D30,"") -> 0.01097228 | H30: =D30 -> 0.365 | I30: =F30+$I$4 -> 0.0045731347 | J30: =IF(AND(H30>0,I30>0),I30/H30,"") -> 0.012529136 | K30: =E30/1000 -> 0.0040048821
A31: =A30+1 -> 22 | B31: 45371 | C31: =B31-$B$4 -> 27 | D31: ='Matsuo-Kawamura KM91-PT '!D31 -> 0.367 | E31: 4.0853889 | F31: =E31/1000 -> 0.0040853889 | G31: =IF(AND(D31>0,F31>0),F31/D31,"") -> 0.01113185 | H31: =D31 -> 0.367 | I31: =F31+$I$4 -> 0.0046536414 | J31: =IF(AND(H31>0,I31>0),I31/H31,"") -> 0.012680222 | K31: =E31/1000 -> 0.0040853889
A32: =A31+1 -> 23 | B32: 45372 | C32: =B32-$B$4 -> 28 | D32: ='Matsuo-Kawamura KM91-PT '!D32 -> 0.369 | E32: 4.1658956 | F32: =E32/1000 -> 0.0041658956 | G32: =IF(AND(D32>0,F32>0),F32/D32,"") -> 0.01128969 | H32: =D32 -> 0.369 | I32: =F32+$I$4 -> 0.0047341481 | J32: =IF(AND(H32>0,I32>0),I32/H32,"") -> 0.01282967 | K32: =E32/1000 -> 0.0041658956
A33: =A32+1 -> 24 | B33: 45373 | C33: =B33-$B$4 -> 29 | D33: ='Matsuo-Kawamura KM91-PT '!D33 -> 0.371 | E33: 4.2464023 | F33: =E33/1000 -> 0.0042464023 | G33: =IF(AND(D33>0,F33>0),F33/D33,"") -> 0.011445828 | H33: =D33 -> 0.371 | I33: =F33+$I$4 -> 0.0048146548 | J33: =IF(AND(H33>0,I33>0),I33/H33,"") -> 0.012977506 | K33: =E33/1000 -> 0.0042464023
... A42: =A41+1 -> 33 | B42: 45382 | C42: =B42-$B$4 -> 38 | D42: ='Matsuo-Kawamura KM91-PT '!D42 -> 0.382 | E42: 4.980752 | F42: =E42/1000 -> 0.004980752 | G42: =IF(AND(D42>0,F42>0),F42/D42,"") -> 0.013038618 | H42: =D42 -> 0.382 | I42: =F42+$I$4 -> 0.0055490045 | J42: =IF(AND(H42>0,I42>0),I42/H42,"") -> 0.01452619 | K42: =E42/1000 -> 0.004980752
A43: =A42+1 -> 34 | B43: 45383 | C43: =B43-$B$4 -> 39 | D43: ='Matsuo-Kawamura KM91-PT '!D43 -> 0.384 | E43: 4.980752 | F43: =E43/1000 -> 0.004980752 | G43: =IF(AND(D43>0,F43>0),F43/D43,"") -> 0.012970708 | K43: =E43/1000 -> 0.004980752
A44: =A43+1 -> 35 | B44: 45384 | C44: =B44-$B$4 -> 40 | D44: ='Matsuo-Kawamura KM91-PT '!D44 -> 0.386 | E44: 5.0298374 | F44: =E44/1000 -> 0.0050298374 | G44: =IF(AND(D44>0,F44>0),F44/D44,"") -> 0.013030667 | K44: =E44/1000 -> 0.0050298374
A45: =A44+1 -> 36 | B45: 45385 | C45: =B45-$B$4 -> 41 | D45: ='Matsuo-Kawamura KM91-PT '!D45 -> 0.388 | E45: 5.0789227 | F45: =E45/1000 -> 0.0050789227 | G45: =IF(AND(D45>0,F45>0),F45/D45,"") -> 0.013090007 | K45: =E45/1000 -> 0.0050789227
A46: =A45+1 -> 37 | B46: 45386 | C46: =B46-$B$4 -> 42 | D46: ='Matsuo-Kawamura KM91-PT '!D46 -> 0.39 | E46: 5.1280081 | F46: =E46/1000 -> 0.0051280081 | G46: =IF(AND(D46>0,F46>0),F46/D46,"") -> 0.013148739 | K46: =E46/1000 -> 0.0051280081
A47: =A46+1 -> 38 | B47: 45387 | C47: =B47-$B$4 -> 43 | D47: ='Matsuo-Kawamura KM91-PT '!D47 -> 0.392 | E47: 5.1770935 | F47: =E47/1000 -> 0.0051770935 | G47: =IF(AND(D47>0,F47>0),F47/D47,"") -> 0.013206871 | K47: =E47/1000 -> 0.0051770935
A48: =A47+1 -> 39 | B48: 45388 | C48: =B48-$B$4 -> 44 | D48: ='Matsuo-Kawamura KM91-PT '!D48 -> 0.393 | E48: 5.2261788 | F48: =E48/1000 -> 0.0052261788 | G48: =IF(AND(D48>0,F48>0),F48/D48,"") -> 0.013298165 | K48: =E48/1000 -> 0.0052261788
...

Sheet Matsuo-Kawamura KM91-PT 
A1: Biểu đồ tính ổn định tại Km91+620 PT
A2: TT | B2: Ngày đo | C2: Lũy kế thời gian | D2: FOS_actual | H2: FOS_actual_corrected
C3: (ngày) | D3: S (m) | E3: H(mm) | F3: H (m) | G3: H/S | H3: S | I3: H | J3: H/S
A4: 0 | B4: 45344 | D4: 0.29 | E4: 0 | F4: 0 | G4: =IF(AND(D4>0,F4>0),F4/D4,"") | I4: =F5 -> 0.00014956015 | J4: =IF(AND(H4>0,I4>0),I4/H4,"")
A5: 1 | B5: 45345 | C5: =B5-$B$4 -> 1 | D5: 0.292 | E5: 0.14956015 | F5: =E5/1000 -> 0.00014956015 | G5: =IF(AND(D5>0,F5>0),F5/D5,"") -> 0.00051219231 | H5: =D5 -> 0.292 | I5: =F5+$I$4 -> 0.00029912031 | J5: =IF(AND(H5>0,I5>0),I5/H5,"") -> 0.0010243846 | L5: =E5/1000 -> 0.00014956015
A6: =A5+1 -> 2 | B6: 45346 | C6: =B6-$B$4 -> 2 | D6: 0.294 | E6: 0.16762735 | F6: =E6/1000 -> 0.00016762735 | G6: =IF(AND(D6>0,F6>0),F6/D6,"") -> 0.00057016105 | H6: =D6 -> 0.294 | I6: =F6+$I$4 -> 0.0003171875 | J6: =IF(AND(H6>0,I6>0),I6/H6,"") -> 0.0010788691 | L6: =E6/1000 -> 0.00016762735
A7: =A6+1 -> 3 | B7: 45347 | C7: =B7-$B$4 -> 3 | D7: 0.296 | E7: 0.18968358 | F7: =E7/1000 -> 0.00018968358 | G7: =IF(AND(D7>0,F7>0),F7/D7,"") -> 0.0006408229 | H7: =D7 -> 0.296 | I7: =F7+$I$4 -> 0.00033924373 | J7: =IF(AND(H7>0,I7>0),I7/H7,"") -> 0.0011460937 | L7: =E7/1000 -> 0.00018968358
A8: =A7+1 -> 4 | B8: 45348 | C8: =B8-$B$4 -> 4 | D8: 0.298 | E8: 0.21173981 | F8: =E8/1000 -> 0.00021173981 | G8: =IF(AND(D8>0,F8>0),F8/D8,"") -> 0.00071053627 | H8: =D8 -> 0.298 | I8: =F8+$I$4 -> 0.00036129996 | J8: =IF(AND(H8>0,I8>0),I8/H8,"") -> 0.001212416 | L8: =E8/1000 -> 0.00021173981
A9: =A8+1 -> 5 | B9: 45349 | C9: =B9-$B$4 -> 5 | D9: 0.3 | E9: 0.23379604 | F9: =E9/1000 -> 0.00023379604 | G9: =IF(AND(D9>0,F9>0),F9/D9,"") -> 0.00077932013 | H9: =D9 -> 0.3 | I9: =F9+$I$4 -> 0.00038335619 | J9: =IF(AND(H9>0,I9>0),I9/H9,"") -> 0.001277854 | L9: =E9/1000 -> 0.00023379604
A10: =A9+1 -> 6 | B10: 45350 | C10: =B10-$B$4 -> 6 | D10: 0.301 | E10: 0.24482415 | F10: =E10/1000 -> 0.00024482415 | G10: =IF(AND(D10>0,F10>0),F10/D10,"") -> 0.00081336928 | H10: =D10 -> 0.301 | I10: =F10+$I$4 -> 0.00039438431 | J10: =IF(AND(H10>0,I10>0),I10/H10,"") -> 0.0013102469 | L10: =E10/1000 -> 0.00024482415
A11: =A10+1 -> 7 | B11: 45351 | C11: =B11-$B$4 -> 7 | D11: 0.302 | E11: 0.25585227 | F11: =E11/1000 -> 0.00025585227 | G11: =IF(AND(D11>0,F11>0),F11/D11,"") -> 0.00084719295 | H11: =D11 -> 0.302 | I11: =F11+$I$4 -> 0.00040541242 | J11: =IF(AND(H11>0,I11>0),I11/H11,"") -> 0.0013424252 | L11: =E11/1000 -> 0.00025585227
A12: =A11+1 -> 8 | B12: 45352 | C12: =B12-$B$4 -> 8 | D12: 0.306 | E12: 0.2779085 | F12: =E12/1000 -> 0.0002779085 | G12: =IF(AND(D12>0,F12>0),F12/D12,"") -> 0.00090819771 | H12: =D12 -> 0.306 | I12: =F12+$I$4 -> 0.00042746865 | J12: =IF(AND(H12>0,I12>0),I12/H12,"") -> 0.0013969564 | L12: =E12/1000 -> 0.0002779085
A13: =A12+1 -> 9 | B13: 45353 | C13: =B13-$B$4 -> 9 | D13: 0.31 | E13: 0.3926176 | F13: =E13/1000 -> 0.0003926176 | G13: =IF(AND(D13>0,F13>0),F13/D13,"") -> 0.0012665084 | H13: =D13 -> 0.31 | I13: =F13+$I$4 -> 0.00054217775 | J13: =IF(AND(H13>0,I13>0),I13/H13,"") -> 0.0017489605 | L13: =E13/1000 -> 0.0003926176
A14: =A13+1 -> 10 | B14: 45354 | C14: =B14-$B$4 -> 10 | D14: 0.314 | E14: 0.5073267 | F14: =E14/1000 -> 0.0005073267 | G14: =IF(AND(D14>0,F14>0),F14/D14,"") -> 0.0016156901 | H14: =D14 -> 0.314 | I14: =F14+$I$4 -> 0.00065688685 | J14: =IF(AND(H14>0,I14>0),I14/H14,"") -> 0.0020919964 | L14: =E14/1000 -> 0.0005073267
A15: =A14+1 -> 11 | B15: 45355 | C15: =B15-$B$4 -> 11 | D15: 0.318 | E15: 0.6220358 | F15: =E15/1000 -> 0.0006220358 | G15: =IF(AND(D15>0,F15>0),F15/D15,"") -> 0.0019560874 | H15: =D15 -> 0.318 | I15: =F15+$I$4 -> 0.00077159595 | J15: =IF(AND(H15>0,I15>0),I15/H15,"") -> 0.0024264024 | L15: =E15/1000 -> 0.0006220358
A16: =A15+1 -> 12 | B16: 45356 | C16: =B16-$B$4 -> 12 | D16: 0.322 | E16: 0.7367449 | F16: =E16/1000 -> 0.0007367449 | G16: =IF(AND(D16>0,F16>0),F16/D16,"") -> 0.0022880276 | H16: =D16 -> 0.322 | I16: =F16+$I$4 -> 0.00088630505 | J16: =IF(AND(H16>0,I16>0),I16/H16,"") -> 0.0027525002 | L16: =E16/1000 -> 0.0007367449
A17: =A16+1 -> 13 | B17: 45357 | C17: =B17-$B$4 -> 13 | D17: 0.326 | E17: 0.851454 | F17: =E17/1000 -> 0.000851454 | G17: =IF(AND(D17>0,F17>0),F17/D17,"") -> 0.0026118221 | H17: =D17 -> 0.326 | I17: =F17+$I$4 -> 0.0010010142 | J17: =IF(AND(H17>0,I17>0),I17/H17,"") -> 0.0030705956 | L17: =E17/1000 -> 0.000851454
... A20: =A19+1 -> 16 | B20: 45360 | C20: =B20-$B$4 -> 16 | D20: 0.337 | E20: 1.0808722 | F20: =E20/1000 -> 0.0010808722 | G20: =IF(AND(D20>0,F20>0),F20/D20,"") -> 0.0032073359 | H20: =D20 -> 0.337 | I20: =F20+$I$4 -> 0.0012304324 | J20: =IF(AND(H20>0,I20>0),I20/H20,"") -> 0.0036511346 | L20: =E20/1000 -> 0.0010808722
A21: =A15+1 -> 12 | B21: 45361 | C21: =B21-$B$4 -> 17 | D21: 0.34 | E21: 1.1955813 | F21: =E21/1000 -> 0.0011955813 | G21: =IF(AND(D21>0,F21>0),F21/D21,"") -> 0.0035164156 | H21: =D21 -> 0.34 | I21: =F21+$I$4 -> 0.0013451415 | J21: =IF(AND(H21>0,I21>0),I21/H21,"") -> 0.0039562984 | L21: =E21/1000 -> 0.0011955813
A22: =A21+1 -> 13 | B22: 45362 | C22: =B22-$B$4 -> 18 | D22: 0.343 | E22: 1.3102904 | F22: =E22/1000 -> 0.0013102904 | G22: =IF(AND(D22>0,F22>0),F22/D22,"") -> 0.0038200886 | H22: =D22 -> 0.343 | I22: =F22+$I$4 -> 0.0014598506 | J22: =IF(AND(H22>0,I22>0),I22/H22,"") -> 0.0042561241 | L22: =E22/1000 -> 0.0013102904
A23: =A22+1 -> 14 | B23: 45363 | C23: =B23-$B$4 -> 19 | D23: 0.346 | E23: 1.4249995 | F23: =E23/1000 -> 0.0014249995 | G23: =IF(AND(D23>0,F23>0),F23/D23,"") -> 0.0041184957 | H23: =D23 -> 0.346 | I23: =F23+$I$4 -> 0.0015745597 | J23: =IF(AND(H23>0,I23>0),I23/H23,"") -> 0.0045507504 | L23: =E23/1000 -> 0.0014249995
A24: =A23+1 -> 15 | B24: 45364 | C24: =B24-$B$4 -> 20 | D24: 0.349 | E24: 1.5397086 | F24: =E24/1000 -> 0.0015397086 | G24: =IF(AND(D24>0,F24>0),F24/D24,"") -> 0.0044117725 | H24: =D24 -> 0.349 | I24: =F24+$I$4 -> 0.0016892688 | J24: =IF(AND(H24>0,I24>0),I24/H24,"") -> 0.0048403116 | L24: =E24/1000 -> 0.0015397086
A25: =A24+1 -> 16 | B25: 45365 | C25: =B25-$B$4 -> 21 | D25: 0.352 | E25: 1.6544177 | F25: =E25/1000 -> 0.0016544177 | G25: =IF(AND(D25>0,F25>0),F25/D25,"") -> 0.0047000503 | H25: =D25 -> 0.352 | I25: =F25+$I$4 -> 0.0018039779 | J25: =IF(AND(H25>0,I25>0),I25/H25,"") -> 0.0051249371 | L25: =E25/1000 -> 0.0016544177
A26: =A25+1 -> 17 | B26: 45366 | C26: =B26-$B$4 -> 22 | D26: 0.355 | E26: 1.8264813 | F26: =E26/1000 -> 0.0018264813 | G26: =IF(AND(D26>0,F26>0),F26/D26,"") -> 0.0051450179 | H26: =D26 -> 0.355 | I26: =F26+$I$4 -> 0.0019760415 | J26: =IF(AND(H26>0,I26>0),I26/H26,"") -> 0.0055663141 | L26: =E26/1000 -> 0.0018264813
A27: =A26+1 -> 18 | B27: 45367 | C27: =B27-$B$4 -> 23 | D27: 0.358 | E27: 1.998545 | F27: =E27/1000 -> 0.001998545 | G27: =IF(AND(D27>0,F27>0),F27/D27,"") -> 0.0055825279 | H27: =D27 -> 0.358 | I27: =F27+$I$4 -> 0.0021481052 | J27: =IF(AND(H27>0,I27>0),I27/H27,"") -> 0.0060002937 | L27: =E27/1000 -> 0.001998545
A28: =A27+1 -> 19 | B28: 45368 | C28: =B28-$B$4 -> 24 | D28: 0.361 | E28: 2.1168376 | F28: =E28/1000 -> 0.0021168376 | G28: =IF(AND(D28>0,F28>0),F28/D28,"") -> 0.0058638162 | H28: =D28 -> 0.361 | I28: =F28+$I$4 -> 0.0022663978 | J28: =IF(AND(H28>0,I28>0),I28/H28,"") -> 0.0062781102 | L28: =E28/1000 -> 0.0021168376
A29: =A28+1 -> 20 | B29: 45369 | C29: =B29-$B$4 -> 25 | D29: 0.363 | E29: 2.2351303 | F29: =E29/1000 -> 0.0022351303 | G29: =IF(AND(D29>0,F29>0),F29/D29,"") -> 0.0061573837 | H29: =D29 -> 0.363 | I29: =F29+$I$4 -> 0.0023846904 | J29: =IF(AND(H29>0,I29>0),I29/H29,"") -> 0.0065693952 | L29: =E29/1000 -> 0.0022351303
A30: =A29+1 -> 21 | B30: 45370 | C30: =B30-$B$4 -> 26 | D30: 0.365 | E30: 2.3534229 | F30: =E30/1000 -> 0.0023534229 | G30: =IF(AND(D30>0,F30>0),F30/D30,"") -> 0.0064477341 | H30: =D30 -> 0.365 | I30: =F30+$I$4 -> 0.0025029831 | J30: =IF(AND(H30>0,I30>0),I30/H30,"") -> 0.0068574879 | L30: =E30/1000 -> 0.0023534229
A31: =A30+1 -> 22 | B31: 45371 | C31: =B31-$B$4 -> 27 | D31: 0.367 | E31: 2.4717156 | F31: =E31/1000 -> 0.0024717156 | G31: =IF(AND(D31>0,F31>0),F31/D31,"") -> 0.0067349198 | H31: =D31 -> 0.367 | I31: =F31+$I$4 -> 0.0026212757 | J31: =IF(AND(H31>0,I31>0),I31/H31,"") -> 0.0071424407 | L31: =E31/1000 -> 0.0024717156
A32: =A31+1 -> 23 | B32: 45372 | C32: =B32-$B$4 -> 28 | D32: 0.369 | E32: 2.5900082 | F32: =E32/1000 -> 0.0025900082 | G32: =IF(AND(D32>0,F32>0),F32/D32,"") -> 0.0070189925 | H32: =D32 -> 0.369 | I32: =F32+$I$4 -> 0.0027395684 | J32: =IF(AND(H32>0,I32>0),I32/H32,"") -> 0.0074243045 | L32: =E32/1000 -> 0.0025900082
A33: =A32+1 -> 24 | B33: 45373 | C33: =B33-$B$4 -> 29 | D33: 0.371 | E33: 2.7083009 | F33: =E33/1000 -> 0.0027083009 | G33: =IF(AND(D33>0,F33>0),F33/D33,"") -> 0.0073000023 | H33: =D33 -> 0.371 | I33: =F33+$I$4 -> 0.002857861 | J33: =IF(AND(H33>0,I33>0),I33/H33,"") -> 0.0077031294 | L33: =E33/1000 -> 0.0027083009
... A42: =A41+1 -> 33 | B42: 45382 | C42: =B42-$B$4 -> 38 | D42: 0.382 | E42: 3.654642 | F42: =E42/1000 -> 0.003654642 | G42: =IF(AND(D42>0,F42>0),F42/D42,"") -> 0.0095671257 | H42: =D42 -> 0.382 | I42: =F42+$I$4 -> 0.0038042022 | J42: =IF(AND(H42>0,I42>0),I42/H42,"") -> 0.0099586444 | L42: =E42/1000 -> 0.003654642
A43: =A42+1 -> 34 | B43: 45383 | C43: =B43-$B$4 -> 39 | D43: 0.384 | E43: 3.654642 | F43: =E43/1000 -> 0.003654642 | G43: =IF(AND(D43>0,F43>0),F43/D43,"") -> 0.0095172969 | L43: =E43/1000 -> 0.003654642
A44: =A43+1 -> 35 | B44: 45384 | C44: =B44-$B$4 -> 40 | D44: 0.386 | E44: 3.717352 | F44: =E44/1000 -> 0.003717352 | G44: =IF(AND(D44>0,F44>0),F44/D44,"") -> 0.0096304456 | L44: =E44/1000 -> 0.003717352
A45: =A44+1 -> 36 | B45: 45385 | C45: =B45-$B$4 -> 41 | D45: 0.388 | E45: 3.780062 | F45: =E45/1000 -> 0.003780062 | G45: =IF(AND(D45>0,F45>0),F45/D45,"") -> 0.0097424278 | L45: =E45/1000 -> 0.003780062
A46: =A45+1 -> 37 | B46: 45386 | C46: =B46-$B$4 -> 42 | D46: 0.39 | E46: 3.842772 | F46: =E46/1000 -> 0.003842772 | G46: =IF(AND(D46>0,F46>0),F46/D46,"") -> 0.0098532615 | L46: =E46/1000 -> 0.003842772
A47: =A46+1 -> 38 | B47: 45387 | C47: =B47-$B$4 -> 43 | D47: 0.392 | E47: 3.905482 | F47: =E47/1000 -> 0.003905482 | G47: =IF(AND(D47>0,F47>0),F47/D47,"") -> 0.0099629643 | L47: =E47/1000 -> 0.003905482
A48: =A47+1 -> 39 | B48: 45388 | C48: =B48-$B$4 -> 44 | D48: 0.393 | E48: 3.968192 | F48: =E48/1000 -> 0.003968192 | G48: =IF(AND(D48>0,F48>0),F48/D48,"") -> 0.010097181 | L48: =E48/1000 -> 0.003968192
A49: =A48+1 -> 40 | B49: 45389 | C49: =B49-$B$4 -> 45 | D49: 0.394 | E49: 4.030902 | F49: =E49/1000 -> 0.004030902 | G49: =IF(AND(D49>0,F49>0),F49/D49,"") -> 0.010230716 | L49: =E49/1000 -> 0.004030902
A50: =A49+1 -> 41 | B50: 45390 | C50: =B50-$B$4 -> 46 | D50: 0.395 | E50: 4.030902 | F50: =E50/1000 -> 0.004030902 | G50: =IF(AND(D50>0,F50>0),F50/D50,"") -> 0.010204815 | L50: =E50/1000 -> 0.004030902
...

Sheet pp
B1: FOS=1 | D1: FOS=1.1 | F1: FOS=1.3 | H1: FOS=1.4 | J1: FOS=1.7
A2: 0 | C2: 0 | E2: 0 | G2: 0 | I2: 0
A3: 0.05 | C3: 0.075 | D3: 2.7 | E3: 0.076 | F3: 2.3 | G3: 0.05 | H3: 1.4 | I3: 0.07 | J3: 0.7
A4: 0.1 | B4: 3.6 | C4: 0.1 | D4: 2.3 | E4: 0.1 | F4: 1.4 | G4: 0.1 | H4: 0.75 | I4: 0.1 | J4: 0.55
A5: 0.15 | B5: 3.25 | C5: 0.15 | D5: 1.77 | E5: 0.15 | F5: 1.01 | G5: 0.15 | H5: 0.57 | I5: 0.15 | J5: 0.35
A6: 0.2 | B6: =2.75+0.125 -> 2.875 | C6: 0.2 | D6: 1.45 | E6: 0.2 | F6: 0.8 | G6: 0.2 | H6: 0.45 | I6: 0.2 | J6: 0.25
A7: 0.25 | B7: 2.55 | C7: 0.25 | D7: 1.31 | E7: 0.25 | F7: 0.7 | G7: 0.25 | H7: 0.4 | I7: 0.25 | J7: 0.208
A8: 0.3 | B8: =2+0.3 -> 2.3 | C8: 0.3 | D8: 1.2 | E8: 0.3 | F8: 0.62 | G8: 0.3 | H8: 0.365 | I8: 0.3 | J8: 0.192
A9: 0.35 | B9: 2.05 | C9: 0.35 | D9: 1.115 | E9: 0.35 | F9: 0.562 | G9: 0.35 | H9: 0.33 | I9: 0.35 | J9: 0.184
A10: 0.4 | B10: 1.875 | C10: 0.4 | D10: 1.03 | E10: 0.4 | F10: 0.5 | G10: 0.4 | H10: 0.3 | I10: 0.4 | J10: 0.175
A11: 0.45 | B11: 1.73 | C11: 0.45 | D11: 0.965 | E11: 0.45 | F11: 0.46 | G11: 0.45 | H11: 0.26 | I11: 0.45 | J11: 0.169
A12: 0.5 | B12: 1.6 | C12: 0.5 | D12: =0.5+0.25+0.25/2 -> 0.875 | E12: 0.5 | F12: 0.425 | G12: 0.5 | H12: 0.24 | I12: 0.5 | J12: 0.163
A13: 0.55 | B13: 1.45 | C13: 0.55 | D13: 0.83 | E13: 0.55 | F13: 0.395 | G13: 0.55 | H13: 0.23 | I13: 0.55 | J13: 0.155
A14: 0.6 | B14: 1.33 | C14: 0.6 | D14: 0.78 | E14: 0.6 | F14: 0.38 | G14: 0.6 | H14: 0.222 | I14: 0.6 | J14: 0.145
A15: 0.65 | B15: 1.2 | C15: 0.65 | D15: 0.74 | E15: 0.65 | F15: 0.372 | G15: 0.65 | H15: 0.21 | I15: 0.65 | J15: 0.135
A16: 0.7 | B16: 1.1 | C16: 0.7 | D16: 0.7 | E16: 0.7 | F16: 0.36 | G16: 0.7 | H16: 0.202 | I16: 0.7 | J16: 0.125
A17: 0.75 | B17: 1.015 | C17: 0.75 | D17: 0.665 | E17: 0.75 | F17: 0.351 | G17: 0.75 | H17: 0.195 | I17: 0.75
A18: 0.8 | B18: 0.95 | C18: 0.8 | D18: 0.645 | E18: 0.8 | F18: 0.335 | G18: 0.8 | H18: 0.191 | I18: 0.8
A19: 0.85 | B19: 0.87 | C19: 0.85 | D19: 0.615 | E19: 0.85 | F19: 0.315 | G19: 0.85 | H19: 0.189 | I19: 0.85
A20: 0.9 | B20: 0.815 | C20: 0.9 | D20: 0.58 | E20: 0.9 | F20: 0.295 | G20: 0.9 | H20: 0.185 | I20: 0.9
A21: 0.95 | B21: 0.775 | C21: 0.95 | D21: 0.535 | E21: 0.95 | F21: 0.286 | G21: 0.95 | I21: 0.95
A22: 1 | B22: 0.745 | C22: 1 | D22: 0.52 | E22: 1 | F22: 0.282 | G22: 1 | I22: 1
A23: 1.05 | B23: 0.725 | C23: 1.05 | D23: 0.496 | E23: 1.05 | F23: 0.27 | G23: 1.05 | I23: 1.05
A24: 1.1 | B24: 0.695 | C24: 1.1 | D24: 0.475 | E24: 1.1 | F24: 0.272 | G24: 1.1 | I24: 1.1
A25: 1.15 | B25: 0.668 | C25: 1.15 | D25: 0.455 | E25: 1.15 | F25: 0.268 | G25: 1.15 | I25: 1.15
A26: 1.2 | B26: 0.65 | C26: 1.2 | D26: 0.42 | E26: 1.2 | F26: 0.252 | G26: 1.2 | I26: 1.2
A27: 1.25 | B27: 0.63 | C27: 1.25 | D27: 0.4 | E27: 1.23 | F27: 0.25 | G27: 1.25 | I27: 1.25
A28: 1.3 | B28: 0.6 | C28: 1.3 | D28: 0.38 | E28: 1.3 | G28: 1.3 | I28: 1.3
A29: 1.35 | B29: 0.58 | C29: 1.35 | E29: 1.35 | G29: 1.35 | I29: 1.35
A30: 1.4 | B30: 0.55 | C30: 1.4 | E30: 1.4 | G30: 1.4 | I30: 1.4
A31: 1.5 | C31: 1.5 | E31: 1.5 | G31: 1.5 | I31: 1.5

Sheet 1(kurihara)
A2: Ngày | B2: KM91+920 TRÁI | G2: KM91+920 PHẢI
B3: Δt | C3: d | D3: d | E3: Δd | F3: Δd/Δt | G3: Δt | H3: d | I3: d | J3: Δd | K3: Δd/Δt
E4: =D5-D4 -> 0 | F4: 0
A5: ='[1](kawam)'!F5 -> 45344 | B5: 0 | C5: ='[1](kawam)'!G5 -> 0 | D5: =C5*100 -> 0 | E5: =D5-D4 -> 0 | F5: =E5/B6 -> 0 | G5: 0 | H5: ='Matsuo-Kawamura KM91-PT '!F4 -> 0 | I5: 0 | K5: 0
A6: ='[1](kawam)'!F6 -> 45345 | B6: =A6-A5 -> 1 | C6: ='Matsuo-Kawamura KM91-TT '!F5 -> 0.00056825251 | D6: =C6*100 -> 0.056825251 | E6: =D6-D5 -> 0.056825251 | F6: =E6/B6 -> 0.056825251 | G6: =B6 -> 1 | H6: ='Matsuo-Kawamura KM91-PT '!F5 -> 0.00014956015 | I6: =H6*100 -> 0.014956015 | J6: =I6-I5 -> 0.014956015 | K6: =J6/G6 -> 0.014956015
A7: ='[1](kawam)'!F7 -> 45346 | B7: =A7-A6 -> 1 | C7: ='Matsuo-Kawamura KM91-TT '!F6 -> 0.00066247149 | D7: =C7*100 -> 0.066247149 | E7: =D7-D6 -> 0.009421898 | F7: =E7/B7 -> 0.009421898 | G7: =B7 -> 1 | H7: ='Matsuo-Kawamura KM91-PT '!F6 -> 0.00016762735 | I7: =H7*100 -> 0.016762735 | J7: =I7-I6 -> 0.0018067194 | K7: =J7/G7 -> 0.0018067194
A8: ='[1](kawam)'!F8 -> 45347 | B8: =A8-A7 -> 1 | C8: ='Matsuo-Kawamura KM91-TT '!F7 -> 0.00074963879 | D8: =C8*100 -> 0.074963879 | E8: =D8-D7 -> 0.0087167302 | F8: =E8/B8 -> 0.0087167302 | G8: =B8 -> 1 | H8: ='Matsuo-Kawamura KM91-PT '!F7 -> 0.00018968358 | I8: =H8*100 -> 0.018968358 | J8: =I8-I7 -> 0.002205623 | K8: =J8/G8 -> 0.002205623
A9: ='[1](kawam)'!F9 -> 45348 | B9: =A9-A8 -> 1 | C9: ='Matsuo-Kawamura KM91-TT '!F8 -> 0.0008368061 | D9: =C9*100 -> 0.08368061 | E9: =D9-D8 -> 0.0087167302 | F9: =E9/B9 -> 0.0087167302 | G9: =B9 -> 1 | H9: ='Matsuo-Kawamura KM91-PT '!F8 -> 0.00021173981 | I9: =H9*100 -> 0.021173981 | J9: =I9-I8 -> 0.002205623 | K9: =J9/G9 -> 0.002205623
A10: ='[1](kawam)'!F10 -> 45349 | B10: =A10-A9 -> 1 | C10: ='Matsuo-Kawamura KM91-TT '!F9 -> 0.0009239734 | D10: =C10*100 -> 0.09239734 | E10: =D10-D9 -> 0.0087167302 | F10: =E10/B10 -> 0.0087167302 | G10: =B10 -> 1 | H10: ='Matsuo-Kawamura KM91-PT '!F9 -> 0.00023379604 | I10: =H10*100 -> 0.023379604 | J10: =I10-I9 -> 0.002205623 | K10: =J10/G10 -> 0.002205623
A11: ='[1](kawam)'!F11 -> 45350 | B11: =A11-A10 -> 1 | C11: ='Matsuo-Kawamura KM91-TT '!F10 -> 0.00096755705 | D11: =C11*100 -> 0.096755705 | E11: =D11-D10 -> 0.0043583651 | F11: =E11/B11 -> 0.0043583651 | G11: =B11 -> 1 | H11: ='Matsuo-Kawamura KM91-PT '!F10 -> 0.00024482415 | I11: =H11*100 -> 0.024482415 | J11: =I11-I10 -> 0.0011028115 | K11: =J11/G11 -> 0.0011028115
A12: ='[1](kawam)'!F12 -> 45351 | B12: =A12-A11 -> 1 | C12: ='Matsuo-Kawamura KM91-TT '!F11 -> 0.0010111407 | D12: =C12*100 -> 0.10111407 | E12: =D12-D11 -> 0.0043583651 | F12: =E12/B12 -> 0.0043583651 | G12: =B12 -> 1 | H12: ='Matsuo-Kawamura KM91-PT '!F11 -> 0.00025585227 | I12: =H12*100 -> 0.025585227 | J12: =I12-I11 -> 0.0011028115 | K12: =J12/G12 -> 0.0011028115
A13: ='[1](kawam)'!F13 -> 45352 | B13: =A13-A12 -> 1 | C13: ='Matsuo-Kawamura KM91-TT '!F12 -> 0.001098308 | D13: =C13*100 -> 0.1098308 | E13: =D13-D12 -> 0.0087167302 | F13: =E13/B13 -> 0.0087167302 | G13: =B13 -> 1 | H13: ='Matsuo-Kawamura KM91-PT '!F12 -> 0.0002779085 | I13: =H13*100 -> 0.02779085 | J13: =I13-I12 -> 0.002205623 | K13: =J13/G13 -> 0.002205623
A14: ='[1](kawam)'!F14 -> 45353 | B14: =A14-A13 -> 1 | C14: ='Matsuo-Kawamura KM91-TT '!F13 -> 0.0012543129 | D14: =C14*100 -> 0.12543129 | E14: =D14-D13 -> 0.015600487 | F14: =E14/B14 -> 0.015600487 | G14: =B14 -> 1 | H14: ='Matsuo-Kawamura KM91-PT '!F13 -> 0.0003926176 | I14: =H14*100 -> 0.03926176 | J14: =I14-I13 -> 0.01147091 | K14: =J14/G14 -> 0.01147091
A15: ='[1](kawam)'!F15 -> 45354 | B15: =A15-A14 -> 1 | C15: ='Matsuo-Kawamura KM91-TT '!F14 -> 0.0014147377 | D15: =C15*100 -> 0.14147377 | E15: =D15-D14 -> 0.016042483 | F15: =E15/B15 -> 0.016042483 | G15: =B15 -> 1 | H15: ='Matsuo-Kawamura KM91-PT '!F14 -> 0.0005073267 | I15: =H15*100 -> 0.05073267 | J15: =I15-I14 -> 0.01147091 | K15: =J15/G15 -> 0.01147091
A16: ='[1](kawam)'!F16 -> 45355 | B16: =A16-A15 -> 1 | C16: ='Matsuo-Kawamura KM91-TT '!F15 -> 0.0015882203 | D16: =C16*100 -> 0.15882203 | E16: =D16-D15 -> 0.01734826 | F16: =E16/B16 -> 0.01734826 | G16: =B16 -> 1 | H16: ='Matsuo-Kawamura KM91-PT '!F15 -> 0.0006220358 | I16: =H16*100 -> 0.06220358 | J16: =I16-I15 -> 0.01147091 | K16: =J16/G16 -> 0.01147091
A17: ='[1](kawam)'!F17 -> 45356 | B17: =A17-A16 -> 1 | C17: ='Matsuo-Kawamura KM91-TT '!F16 -> 0.0017617029 | D17: =C17*100 -> 0.17617029 | E17: =D17-D16 -> 0.01734826 | F17: =E17/B17 -> 0.01734826 | G17: =B17 -> 1 | H17: ='Matsuo-Kawamura KM91-PT '!F16 -> 0.0007367449 | I17: =H17*100 -> 0.07367449 | J17: =I17-I16 -> 0.01147091 | K17: =J17/G17 -> 0.01147091
... A51: ='[1](kawam)'!F51 -> 45438 | B51: =A51-A50 -> 7 | C51: ='Matsuo-Kawamura KM91-TT '!F50 -> 0.0052858204 | D51: =C51*100 -> 0.52858204 | E51: =D51-D50 -> 0 | F51: =E51/B51 -> 0 | G51: =B51 -> 7 | H51: ='Matsuo-Kawamura KM91-PT '!F50 -> 0.004030902 | I51: =H51*100 -> 0.4030902 | J51: =I51-I50 -> 0 | K51: =J51/G51 -> 0
F125: 2 | G125: -2
F126: 2 | G126: -2
A128: =A5 -> 45344 | B128: 0 | C128: 0 | E128: 0 | F128: 0.5 | G128: -0.5 | I128: 0 | J128: 0
A129: =A6 -> 45345 | B129: =A6-$A$5 -> 1 | C129: =F6 -> 0.056825251 | E129: 280 | F129: 0.5 | G129: -0.5 | I129: =B129 -> 1 | J129: =K6 -> 0.014956015
A130: =A7 -> 45346 | B130: =A7-$A$5 -> 2 | C130: =F7 -> 0.009421898 | I130: =B130 -> 2 | J130: =K7 -> 0.0018067194
A131: =A8 -> 45347 | B131: =A8-$A$5 -> 3 | C131: =F8 -> 0.0087167302 | I131: =B131 -> 3 | J131: =K8 -> 0.002205623
A132: =A9 -> 45348 | B132: =A9-$A$5 -> 4 | C132: =F9 -> 0.0087167302 | I132: =B132 -> 4 | J132: =K9 -> 0.002205623
A133: =A10 -> 45349 | B133: =A10-$A$5 -> 5 | C133: =F10 -> 0.0087167302 | I133: =B133 -> 5 | J133: =K10 -> 0.002205623
A134: =A11 -> 45350 | B134: =A11-$A$5 -> 6 | C134: =F11 -> 0.0043583651 | I134: =B134 -> 6 | J134: =K11 -> 0.0011028115
A135: =A12 -> 45351 | B135: =A12-$A$5 -> 7 | C135: =F12 -> 0.0043583651 | I135: =B135 -> 7 | J135: =K12 -> 0.0011028115
A136: =A13 -> 45352 | B136: =A13-$A$5 -> 8 | C136: =F13 -> 0.0087167302 | I136: =B136 -> 8 | J136: =K13 -> 0.002205623
A137: =A14 -> 45353 | B137: =A14-$A$5 -> 9 | C137: =F14 -> 0.015600487 | I137: =B137 -> 9 | J137: =K14 -> 0.01147091
A138: =A15 -> 45354 | B138: =A15-$A$5 -> 10 | C138: =F15 -> 0.016042483 | I138: =B138 -> 10 | J138: =K15 -> 0.01147091
A139: =A16 -> 45355 | B139: =A16-$A$5 -> 11 | C139: =F16 -> 0.01734826 | I139: =B139 -> 11 | J139: =K16 -> 0.01147091
A140: =A17 -> 45356 | B140: =A17-$A$5 -> 12 | C140: =F17 -> 0.01734826 | I140: =B140 -> 12 | J140: =K17 -> 0.01147091
A141: =A18 -> 45357 | B141: =A18-$A$5 -> 13 | C141: =F18 -> 0.01734826 | I141: =B141 -> 13 | J141: =K18 -> 0.01147091
... A174: =A51 -> 45438 | B174: =A51-$A$5 -> 94 | C174: =F51 -> 0 | I174: =B174 -> 94 | J174: =K51 -> 0

Sheet data-1(kurihara)
M10: KM12+580 LEFT
M40: KM12+500 LEFT

Sheet 2(hashimoto)  
B2: DAY | C2: KM91+920 TRÁI | G2: KM91+920 PHẢI
C3: d(m) | D3: d(cm) | E3: s(m) | F3: s(cm) | G3: d(m) | H3: d(cm) | I3: s(m) | J3: s(cm) | K3: x | L3: 0.3 | M3: 0.5
B4: =+'[1](kawam)'!F5 -> 45344 | C4: ='1(kurihara)'!C5 -> 0 | D4: =C4*100 -> 0 | E4: ='Matsuo-Kawamura KM91-TT '!D4 -> 0.29 | F4: =E4*100 -> 29 | G4: ='Matsuo-Kawamura KM91-PT '!F4 -> 0 | H4: =G4*100 -> 0 | I4: ='Matsuo-Kawamura KM91-PT '!D4 -> 0.29 | J4: =I4*100 -> 29
B5: =+'[1](kawam)'!F6 -> 45345 | C5: ='1(kurihara)'!C6 -> 0.00056825251 | D5: =C5*100 -> 0.056825251 | E5: ='Matsuo-Kawamura KM91-TT '!D5 -> 0.292 | F5: =E5*100 -> 29.2 | G5: ='Matsuo-Kawamura KM91-PT '!F5 -> 0.00014956015 | H5: =G5*100 -> 0.014956015 | I5: ='Matsuo-Kawamura KM91-PT '!D5 -> 0.292 | J5: =I5*100 -> 29.2
B6: =+'[1](kawam)'!F7 -> 45346 | C6: ='1(kurihara)'!C7 -> 0.00066247149 | D6: =C6*100 -> 0.066247149 | E6: ='Matsuo-Kawamura KM91-TT '!D6 -> 0.294 | F6: =E6*100 -> 29.4 | G6: ='Matsuo-Kawamura KM91-PT '!F6 -> 0.00016762735 | H6: =G6*100 -> 0.016762735 | I6: ='Matsuo-Kawamura KM91-PT '!D6 -> 0.294 | J6: =I6*100 -> 29.4
B7: =+'[1](kawam)'!F8 -> 45347 | C7: ='1(kurihara)'!C8 -> 0.00074963879 | D7: =C7*100 -> 0.074963879 | E7: ='Matsuo-Kawamura KM91-TT '!D7 -> 0.296 | F7: =E7*100 -> 29.6 | G7: ='Matsuo-Kawamura KM91-PT '!F7 -> 0.00018968358 | H7: =G7*100 -> 0.018968358 | I7: ='Matsuo-Kawamura KM91-PT '!D7 -> 0.296 | J7: =I7*100 -> 29.6
B8: =+'[1](kawam)'!F9 -> 45348 | C8: ='1(kurihara)'!C9 -> 0.0008368061 | D8: =C8*100 -> 0.08368061 | E8: ='Matsuo-Kawamura KM91-TT '!D8 -> 0.298 | F8: =E8*100 -> 29.8 | G8: ='Matsuo-Kawamura KM91-PT '!F8 -> 0.00021173981 | H8: =G8*100 -> 0.021173981 | I8: ='Matsuo-Kawamura KM91-PT '!D8 -> 0.298 | J8: =I8*100 -> 29.8 | K8: 0 | L8: 0 | M8: 0
B9: =+'[1](kawam)'!F10 -> 45349 | C9: ='1(kurihara)'!C10 -> 0.0009239734 | D9: =C9*100 -> 0.09239734 | E9: ='Matsuo-Kawamura KM91-TT '!D9 -> 0.3 | F9: =E9*100 -> 30 | G9: ='Matsuo-Kawamura KM91-PT '!F9 -> 0.00023379604 | H9: =G9*100 -> 0.023379604 | I9: ='Matsuo-Kawamura KM91-PT '!D9 -> 0.3 | J9: =I9*100 -> 30 | K9: 50 | L9: =(K9/0.3) -> 166.66667 | M9: =(K9/0.5) -> 100
B10: =+'[1](kawam)'!F11 -> 45350 | C10: ='1(kurihara)'!C11 -> 0.00096755705 | D10: =C10*100 -> 0.096755705 | E10: ='Matsuo-Kawamura KM91-TT '!D10 -> 0.301 | F10: =E10*100 -> 30.1 | G10: ='Matsuo-Kawamura KM91-PT '!F10 -> 0.00024482415 | H10: =G10*100 -> 0.024482415 | I10: ='Matsuo-Kawamura KM91-PT '!D10 -> 0.301 | J10: =I10*100 -> 30.1 | K10: 50 | L10: =(K10/0.3) -> 166.66667 | M10: =(K10/0.5) -> 100
B11: =+'[1](kawam)'!F12 -> 45351 | C11: ='1(kurihara)'!C12 -> 0.0010111407 | D11: =C11*100 -> 0.10111407 | E11: ='Matsuo-Kawamura KM91-TT '!D11 -> 0.302 | F11: =E11*100 -> 30.2 | G11: ='Matsuo-Kawamura KM91-PT '!F11 -> 0.00025585227 | H11: =G11*100 -> 0.025585227 | I11: ='Matsuo-Kawamura KM91-PT '!D11 -> 0.302 | J11: =I11*100 -> 30.2 | K11: 50 | L11: =(K11/0.3) -> 166.66667 | M11: =(K11/0.5) -> 100
B12: =+'[1](kawam)'!F13 -> 45352 | C12: ='1(kurihara)'!C13 -> 0.001098308 | D12: =C12*100 -> 0.1098308 | E12: ='Matsuo-Kawamura KM91-TT '!D12 -> 0.306 | F12: =E12*100 -> 30.6 | G12: ='Matsuo-Kawamura KM91-PT '!F12 -> 0.0002779085 | H12: =G12*100 -> 0.02779085 | I12: ='Matsuo-Kawamura KM91-PT '!D12 -> 0.306 | J12: =I12*100 -> 30.6
B13: =+'[1](kawam)'!F14 -> 45353 | C13: ='1(kurihara)'!C14 -> 0.0012543129 | D13: =C13*100 -> 0.12543129 | E13: ='Matsuo-Kawamura KM91-TT '!D13 -> 0.31 | F13: =E13*100 -> 31 | G13: ='Matsuo-Kawamura KM91-PT '!F13 -> 0.0003926176 | H13: =G13*100 -> 0.03926176 | I13: ='Matsuo-Kawamura KM91-PT '!D13 -> 0.31 | J13: =I13*100 -> 31
B14: =+'[1](kawam)'!F15 -> 45354 | C14: ='1(kurihara)'!C15 -> 0.0014147377 | D14: =C14*100 -> 0.14147377 | E14: ='Matsuo-Kawamura KM91-TT '!D14 -> 0.314 | F14: =E14*100 -> 31.4 | G14: ='Matsuo-Kawamura KM91-PT '!F14 -> 0.0005073267 | H14: =G14*100 -> 0.05073267 | I14: ='Matsuo-Kawamura KM91-PT '!D14 -> 0.314 | J14: =I14*100 -> 31.4
B15: =+'[1](kawam)'!F16 -> 45355 | C15: ='1(kurihara)'!C16 -> 0.0015882203 | D15: =C15*100 -> 0.15882203 | E15: ='Matsuo-Kawamura KM91-TT '!D15 -> 0.318 | F15: =E15*100 -> 31.8 | G15: ='Matsuo-Kawamura KM91-PT '!F15 -> 0.0006220358 | H15: =G15*100 -> 0.06220358 | I15: ='Matsuo-Kawamura KM91-PT '!D15 -> 0.318 | J15: =I15*100 -> 31.8
B16: =+'[1](kawam)'!F17 -> 45356 | C16: ='1(kurihara)'!C17 -> 0.0017617029 | D16: =C16*100 -> 0.17617029 | E16: ='Matsuo-Kawamura KM91-TT '!D16 -> 0.137 | F16: =E16*100 -> 13.7 | G16: ='Matsuo-Kawamura KM91-PT '!F16 -> 0.0007367449 | H16: =G16*100 -> 0.07367449 | I16: ='Matsuo-Kawamura KM91-PT '!D16 -> 0.322 | J16: =I16*100 -> 32.2
B17: =+'[1](kawam)'!F18 -> 45357 | C17: ='1(kurihara)'!C18 -> 0.0019351855 | D17: =C17*100 -> 0.19351855 | E17: ='Matsuo-Kawamura KM91-TT '!D17 -> 0.145 | F17: =E17*100 -> 14.5 | G17: ='Matsuo-Kawamura KM91-PT '!F17 -> 0.000851454 | H17: =G17*100 -> 0.0851454 | I17: ='Matsuo-Kawamura KM91-PT '!D17 -> 0.326 | J17: =I17*100 -> 32.6
B18: =+'[1](kawam)'!F19 -> 45358 | C18: ='1(kurihara)'!C19 -> 0.0021086681 | D18: =C18*100 -> 0.21086681 | E18: ='Matsuo-Kawamura KM91-TT '!D18 -> 0.156 | F18: =E18*100 -> 15.6 | G18: ='Matsuo-Kawamura KM91-PT '!F18 -> 0.0009661631 | H18: =G18*100 -> 0.09661631 | I18: ='Matsuo-Kawamura KM91-PT '!D18 -> 0.33 | J18: =I18*100 -> 33
B19: =+'[1](kawam)'!F20 -> 45359 | C19: ='1(kurihara)'!C20 -> 0.0021086681 | D19: =C19*100 -> 0.21086681 | E19: ='Matsuo-Kawamura KM91-TT '!D19 -> 0.168 | F19: =E19*100 -> 16.8 | G19: ='Matsuo-Kawamura KM91-PT '!F19 -> 0.0009661631 | H19: =G19*100 -> 0.09661631 | I19: ='Matsuo-Kawamura KM91-PT '!D19 -> 0.334 | J19: =I19*100 -> 33.4
B20: =+'[1](kawam)'!F21 -> 45360 | C20: ='1(kurihara)'!C21 -> 0.0022917476 | D20: =C20*100 -> 0.22917476 | E20: ='Matsuo-Kawamura KM91-TT '!D20 -> 0.18 | F20: =E20*100 -> 18 | G20: ='Matsuo-Kawamura KM91-PT '!F20 -> 0.0010808722 | H20: =G20*100 -> 0.10808722 | I20: ='Matsuo-Kawamura KM91-PT '!D20 -> 0.337 | J20: =I20*100 -> 33.7
B21: =+'[1](kawam)'!F22 -> 45361 | C21: ='1(kurihara)'!C22 -> 0.0024756994 | D21: =C21*100 -> 0.24756994 | E21: ='Matsuo-Kawamura KM91-TT '!D21 -> 0.34 | F21: =E21*100 -> 34 | G21: ='Matsuo-Kawamura KM91-PT '!F21 -> 0.0011955813 | H21: =G21*100 -> 0.11955813 | I21: ='Matsuo-Kawamura KM91-PT '!D21 -> 0.34 | J21: =I21*100 -> 34
B22: =+'[1](kawam)'!F23 -> 45362 | C22: ='1(kurihara)'!C23 -> 0.0026596512 | D22: =C22*100 -> 0.26596512 | E22: ='Matsuo-Kawamura KM91-TT '!D22 -> 0.343 | F22: =E22*100 -> 34.3 | G22: ='Matsuo-Kawamura KM91-PT '!F22 -> 0.0013102904 | H22: =G22*100 -> 0.13102904 | I22: ='Matsuo-Kawamura KM91-PT '!D22 -> 0.343 | J22: =I22*100 -> 34.3
B23: =+'[1](kawam)'!F24 -> 45363 | C23: ='1(kurihara)'!C24 -> 0.002843603 | D23: =C23*100 -> 0.2843603 | E23: ='Matsuo-Kawamura KM91-TT '!D23 -> 0.346 | F23: =E23*100 -> 34.6 | G23: ='Matsuo-Kawamura KM91-PT '!F23 -> 0.0014249995 | H23: =G23*100 -> 0.14249995 | I23: ='Matsuo-Kawamura KM91-PT '!D23 -> 0.346 | J23: =I23*100 -> 34.6
... B50: =+'[1](kawam)'!F51 -> 45438 | C50: ='1(kurihara)'!C51 -> 0.0052858204 | D50: =C50*100 -> 0.52858204 | E50: ='Matsuo-Kawamura KM91-TT '!D50 -> 0.395 | F50: =E50*100 -> 39.5 | G50: ='Matsuo-Kawamura KM91-PT '!F50 -> 0.004030902 | H50: =G50*100 -> 0.4030902 | I50: ='Matsuo-Kawamura KM91-PT '!D50 -> 0.395 | J50: =I50*100 -> 39.5

Sheet data-2(hashimot) 
C26: ='2(hashimoto) '!B4 -> 45344 | D26: =('2(hashimoto) '!D5-'2(hashimoto) '!D4)/-('2(hashimoto) '!F5-'2(hashimoto) '!F4) -> -0.28412626 | E26: =('2(hashimoto) '!H4-'2(hashimoto) '!#REF!)/-('2(hashimoto) '!J5-'2(hashimoto) '!J4) -> #REF! | F26: =('2(hashimoto) '!#REF!-'2(hashimoto) '!#REF!)/-('2(hashimoto) '!#REF!-'2(hashimoto) '!#REF!) -> #REF! | G26: =('2(hashimoto) '!#REF!-'2(hashimoto) '!#REF!)/-('2(hashimoto) '!#REF!-'2(hashimoto) '!#REF!) -> #REF!
C27: ='2(hashimoto) '!B5 -> 45345 | D27: =('2(hashimoto) '!D6-'2(hashimoto) '!D5)/-('2(hashimoto) '!F6-'2(hashimoto) '!F5) -> -0.04710949 | E27: =('2(hashimoto) '!H6-'2(hashimoto) '!H4)/-('2(hashimoto) '!J6-'2(hashimoto) '!J5) -> -0.083813675 | F27: =('2(hashimoto) '!#REF!-'2(hashimoto) '!#REF!)/-('2(hashimoto) '!#REF!-'2(hashimoto) '!#REF!) -> #REF! | G27: =('2(hashimoto) '!#REF!-'2(hashimoto) '!#REF!)/-('2(hashimoto) '!#REF!-'2(hashimoto) '!#REF!) -> #REF!
C28: ='2(hashimoto) '!B6 -> 45346 | D28: =('2(hashimoto) '!D7-'2(hashimoto) '!D6)/-('2(hashimoto) '!F7-'2(hashimoto) '!F6) -> -0.043583651 | E28: =('2(hashimoto) '!H7-'2(hashimoto) '!H6)/-('2(hashimoto) '!J7-'2(hashimoto) '!J6) -> -0.011028115 | F28: =('2(hashimoto) '!#REF!-'2(hashimoto) '!#REF!)/-('2(hashimoto) '!#REF!-'2(hashimoto) '!#REF!) -> #REF! | G28: =('2(hashimoto) '!#REF!-'2(hashimoto) '!#REF!)/-('2(hashimoto) '!#REF!-'2(hashimoto) '!#REF!) -> #REF!
C29: ='2(hashimoto) '!B7 -> 45347 | D29: =('2(hashimoto) '!D8-'2(hashimoto) '!D7)/-('2(hashimoto) '!F8-'2(hashimoto) '!F7) -> -0.043583651 | E29: =('2(hashimoto) '!H8-'2(hashimoto) '!H7)/-('2(hashimoto) '!J8-'2(hashimoto) '!J7) -> -0.011028115 | F29: =('2(hashimoto) '!#REF!-'2(hashimoto) '!#REF!)/-('2(hashimoto) '!#REF!-'2(hashimoto) '!#REF!) -> #REF! | G29: =('2(hashimoto) '!#REF!-'2(hashimoto) '!#REF!)/-('2(hashimoto) '!#REF!-'2(hashimoto) '!#REF!) -> #REF!
C30: ='2(hashimoto) '!B8 -> 45348 | D30: =('2(hashimoto) '!D9-'2(hashimoto) '!D8)/-('2(hashimoto) '!F9-'2(hashimoto) '!F8) -> -0.043583651 | E30: =('2(hashimoto) '!H9-'2(hashimoto) '!H8)/-('2(hashimoto) '!J9-'2(hashimoto) '!J8) -> -0.011028115 | F30: =('2(hashimoto) '!#REF!-'2(hashimoto) '!#REF!)/-('2(hashimoto) '!#REF!-'2(hashimoto) '!#REF!) -> #REF! | G30: =('2(hashimoto) '!#REF!-'2(hashimoto) '!#REF!)/-('2(hashimoto) '!#REF!-'2(hashimoto) '!#REF!) -> #REF!
C31: ='2(hashimoto) '!B9 -> 45349 | D31: =('2(hashimoto) '!D10-'2(hashimoto) '!D9)/-('2(hashimoto) '!F10-'2(hashimoto) '!F9) -> -0.043583651 | E31: =('2(hashimoto) '!H10-'2(hashimoto) '!H9)/-('2(hashimoto) '!J10-'2(hashimoto) '!J9) -> -0.011028115
C32: ='2(hashimoto) '!B10 -> 45350 | D32: =('2(hashimoto) '!D11-'2(hashimoto) '!D10)/-('2(hashimoto) '!F11-'2(hashimoto) '!F10) -> -0.043583651 | E32: =('2(hashimoto) '!H11-'2(hashimoto) '!H10)/-('2(hashimoto) '!J11-'2(hashimoto) '!J10) -> -0.011028115
C33: ='2(hashimoto) '!B11 -> 45351 | D33: =('2(hashimoto) '!D12-'2(hashimoto) '!D11)/-('2(hashimoto) '!F12-'2(hashimoto) '!F11) -> -0.021791825 | E33: =('2(hashimoto) '!H12-'2(hashimoto) '!H11)/-('2(hashimoto) '!J12-'2(hashimoto) '!J11) -> -0.0055140575
C34: ='2(hashimoto) '!B12 -> 45352 | D34: =('2(hashimoto) '!D13-'2(hashimoto) '!D12)/-('2(hashimoto) '!F13-'2(hashimoto) '!F12) -> -0.039001217 | E34: =('2(hashimoto) '!H13-'2(hashimoto) '!H12)/-('2(hashimoto) '!J13-'2(hashimoto) '!J12) -> -0.028677275
C35: ='2(hashimoto) '!B13 -> 45353 | D35: =('2(hashimoto) '!D14-'2(hashimoto) '!D13)/-('2(hashimoto) '!F14-'2(hashimoto) '!F13) -> -0.040106208 | E35: =('2(hashimoto) '!H14-'2(hashimoto) '!H13)/-('2(hashimoto) '!J14-'2(hashimoto) '!J13) -> -0.028677275
C36: ='2(hashimoto) '!B14 -> 45354 | D36: =('2(hashimoto) '!D15-'2(hashimoto) '!D14)/-('2(hashimoto) '!F15-'2(hashimoto) '!F14) -> -0.04337065 | E36: =('2(hashimoto) '!H15-'2(hashimoto) '!H14)/-('2(hashimoto) '!J15-'2(hashimoto) '!J14) -> -0.028677275
C37: ='2(hashimoto) '!B15 -> 45355 | D37: =('2(hashimoto) '!#REF!-'2(hashimoto) '!D15)/-('2(hashimoto) '!#REF!-'2(hashimoto) '!F15) -> #REF! | E37: =('2(hashimoto) '!#REF!-'2(hashimoto) '!H15)/-('2(hashimoto) '!#REF!-'2(hashimoto) '!J15) -> #REF!
