Workbook

Sheet QTL-KM117+100
A1: BẢNG SỐ LIỆU QUAN TRẮC THIẾT BỊ ĐO LÚN MẶT
A2: I. SỐ ĐỌC BAN ĐẦU
A3: Vùng (Đường) | B3: Bàn quan trắc lún | D3: Ngày lắp đặt | F3: =+"Cao trình nghiệm thu [m] ("&TEXT(A15,"dd/mm/yy")&")" -> Cao trình nghiệm thu [m] (25/07/25) | L3: Tọa độ | P3: Mốc tọa độ tham chiếu
F4: Cao trình MĐTN | G4: Cao trình đắp | I4: Cao trình đỉnh ống | K4: Cao trình tấm đế | L4: X [m] | N4: Y [m]
A5: VÙNG 2A (ĐƯỜNG N1) | B5: SSP2-4 | P5: CS3
B6: SSP2-5 | P6: Tọa độ [m]
B7: SSP2-6
A9: II. SỐ LIỆU QUAN TRẮC
A10: Ngày quan trắc | B10: ĐỘ LÚN TRÁI | G10: ĐỘ LÚN TIM | L10: ĐỘ LÚN PHẢI | Q10: Áp Đ.hồ Pvac | R10: Ghi chú
B11: Thời gian tích lũy | C11: Cao độ đắp | D11: Cao độ bàn đo lún | E11: Chiều cao đắp | F11: Độ lún | G11: Thời gian tích lũy | H11: Cao độ đắp | I11: Cao độ bàn đo lún | J11: Chiều cao đắp | K11: Độ lún | L11: Thời gian tích lũy | M11: Cao độ đắp | N11: Cao độ bàn đo lún | O11: Chiều cao đắp | P11: Độ lún
B13: [Ngày] | C13: [mm] | D13: [m.m] | E13: [mm] | F13: [m.m] | G13: [Ngày] | H13: [mm] | I13: [m.m] | J13: [mm] | K13: [m.m] | L13: [Ngày] | M13: [mm] | N13: [m.m] | O13: [mm] | P13: [m.m] | Q13: [kPa]
A14: 1 | B14: =+A14+1 -> 2 | C14: =+B14+1 -> 3 | D14: =+C14+1 -> 4 | E14: =+D14+1 -> 5 | F14: =+E14+1 -> 6 | G14: =+F14+1 -> 7 | H14: =+G14+1 -> 8 | I14: =+H14+1 -> 9 | ... R14: =+Q14+1 -> 18
A15: 45863 | B15: 1 | C15: 1821 | D15: -559 | E15: =C15-D15 -> 2380 | F15: 0 | G15: 1 | H15: 1766 | I15: -619 | J15: =H15-I15 -> 2385 | K15: 0 | L15: 1 | M15: 1811 | N15: -449 | O15: =M15-N15 -> 2260 | P15: 0
A16: 45864 | B16: 1 | C16: =$C$15-F16 -> 1810 | D16: -570 | E16: 2380 | F16: =$D$15-D16 -> 11 | G16: 1 | H16: =$H$15-K16 -> 1745 | I16: -640 | J16: =H16-I16 -> 2385 | K16: =$I$15-I16 -> 21 | L16: 1 | M16: =$M$15-P16 -> 1803 | N16: -457 | O16: =M16-N16 -> 2260 | P16: =$N$15-N16 -> 8
A17: 45865 | B17: 1 | C17: =$C$15-F17 -> 1791 | D17: -589 | E17: =C17-D17 -> 2380 | F17: =$D$15-D17 -> 30 | G17: 1 | H17: =$H$15-K17 -> 1721 | I17: -664 | J17: =H17-I17 -> 2385 | K17: =$I$15-I17 -> 45 | L17: 1 | M17: =$M$15-P17 -> 1795 | N17: -465 | O17: =M17-N17 -> 2260 | P17: =$N$15-N17 -> 16

Sheet QTL-KM117+200
A1: BẢNG SỐ LIỆU QUAN TRẮC THIẾT BỊ ĐO LÚN MẶT
A2: I. SỐ ĐỌC BAN ĐẦU
A3: Vùng (Đường) | B3: Bàn quan trắc lún | D3: Ngày lắp đặt | F3: =+"Cao trình nghiệm thu [m] ("&TEXT(A15,"dd/mm/yy")&")" -> Cao trình nghiệm thu [m] (10/06/25) | L3: Tọa độ | P3: Mốc tọa độ tham chiếu
F4: Cao trình MĐTN | G4: Cao trình đắp | I4: Cao trình đỉnh ống | K4: Cao trình tấm đế | L4: X [m] | N4: Y [m]
A5: VÙNG 2A (ĐƯỜNG N1) | B5: SSP2-4 | P5: CS3
B6: SSP2-5 | P6: Tọa độ [m]
B7: SSP2-6
A9: II. SỐ LIỆU QUAN TRẮC
A10: Ngày quan trắc | B10: ĐỘ LÚN TRÁI | G10: ĐỘ LÚN TIM | L10: ĐỘ LÚN PHẢI | Q10: Áp Đ.hồ Pvac | R10: Ghi chú
B11: Thời gian tích lũy | C11: Cao độ đắp | D11: Cao độ bàn đo lún | E11: Chiều cao đắp | F11: Độ lún | G11: Thời gian tích lũy | H11: Cao độ đắp | I11: Cao độ bàn đo lún | J11: Chiều cao đắp | K11: Độ lún | L11: Thời gian tích lũy | M11: Cao độ đắp | N11: Cao độ bàn đo lún | O11: Chiều cao đắp | P11: Độ lún
B13: [Ngày] | C13: [mm] | D13: [m.m] | E13: [mm] | F13: [m.m] | G13: [Ngày] | H13: [mm] | I13: [m.m] | J13: [mm] | K13: [m.m] | L13: [Ngày] | M13: [mm] | N13: [m.m] | O13: [mm] | P13: [m.m] | Q13: [kPa]
A14: 1 | B14: =+A14+1 -> 2 | C14: =+B14+1 -> 3 | D14: =+C14+1 -> 4 | E14: =+D14+1 -> 5 | F14: =+E14+1 -> 6 | G14: =+F14+1 -> 7 | H14: =+G14+1 -> 8 | I14: =+H14+1 -> 9 | ... R14: =+Q14+1 -> 18
A15: 45818 | B15: 1 | C15: 1380 | D15: -1193 | E15: =C15-D15 -> 2573 | F15: 0 | G15: 1 | H15: 1460 | I15: -910 | J15: =H15-I15 -> 2370 | K15: 0 | L15: 1 | M15: 1490 | N15: -851 | O15: =M15-N15 -> 2341 | P15: 0
A16: 45819 | B16: 1 | C16: =$C$15-F16 -> 1377 | D16: -1196 | E16: =C16-D16 -> 2573 | F16: =$D$15-D16 -> 3 | G16: 1 | H16: =$H$15-K16 -> 1455 | I16: -915 | J16: =H16-I16 -> 2370 | K16: =$I$15-I16 -> 5 | L16: 1 | M16: =$M$15-P16 -> 1484 | N16: -857 | O16: =M16-N16 -> 2341 | P16: =$N$15-N16 -> 6
A17: 45820 | B17: 1 | C17: =$C$15-F17 -> 1374 | D17: -1199 | E17: =C17-D17 -> 2573 | F17: =$D$15-D17 -> 6 | G17: 1 | H17: =$H$15-K17 -> 1450 | I17: -920 | J17: =H17-I17 -> 2370 | K17: =$I$15-I17 -> 10 | L17: 1 | M17: =$M$15-P17 -> 1478 | N17: -863 | O17: =M17-N17 -> 2341 | P17: =$N$15-N17 -> 12
A18: 45821 | B18: 1 | C18: =$C$15-F18 -> 1371 | D18: -1202 | E18: =C18-D18 -> 2573 | F18: =$D$15-D18 -> 9 | G18: 1 | H18: =$H$15-K18 -> 1445 | I18: -925 | J18: =H18-I18 -> 2370 | K18: =$I$15-I18 -> 15 | L18: 1 | M18: =$M$15-P18 -> 1472 | N18: -869 | O18: =M18-N18 -> 2341 | P18: =$N$15-N18 -> 18
A19: 45822 | B19: 1 | C19: =$C$15-F19 -> 1368 | D19: -1205 | E19: =C19-D19 -> 2573 | F19: =$D$15-D19 -> 12 | G19: 1 | H19: =$H$15-K19 -> 1440 | I19: -930 | J19: =H19-I19 -> 2370 | K19: =$I$15-I19 -> 20 | L19: 1 | M19: =$M$15-P19 -> 1466 | N19: -875 | O19: =M19-N19 -> 2341 | P19: =$N$15-N19 -> 24
A20: 45823 | B20: 1 | C20: =$C$15-F20 -> 1368 | D20: -1205 | E20: =C20-D20 -> 2573 | F20: =$D$15-D20 -> 12 | G20: 1 | H20: =$H$15-K20 -> 1436 | I20: -934 | J20: =H20-I20 -> 2370 | K20: =$I$15-I20 -> 24 | L20: 1 | M20: =$M$15-P20 -> 1461 | N20: -880 | O20: =M20-N20 -> 2341 | P20: =$N$15-N20 -> 29
A21: 45824 | B21: 1 | C21: =$C$15-F21 -> 1359 | D21: -1214 | E21: =C21-D21 -> 2573 | F21: =$D$15-D21 -> 21 | G21: 1 | H21: =$H$15-K21 -> 1422 | I21: -948 | J21: =H21-I21 -> 2370 | K21: =$I$15-I21 -> 38 | L21: 1 | M21: =$M$15-P21 -> 1456 | N21: -885 | O21: =M21-N21 -> 2341 | P21: =$N$15-N21 -> 34
A22: 45825 | B22: 1 | C22: =$C$15-F22 -> 1350 | D22: -1223 | E22: =C22-D22 -> 2573 | F22: =$D$15-D22 -> 30 | G22: 1 | H22: =$H$15-K22 -> 1410 | I22: -960 | J22: =H22-I22 -> 2370 | K22: =$I$15-I22 -> 50 | L22: 1 | M22: =$M$15-P22 -> 1451 | N22: -890 | O22: =M22-N22 -> 2341 | P22: =$N$15-N22 -> 39
A23: 45826 | B23: 1 | C23: =$C$15-F23 -> 1341 | D23: -1232 | E23: =C23-D23 -> 2573 | F23: =$D$15-D23 -> 39 | G23: 1 | H23: =$H$15-K23 -> 1400 | I23: -970 | J23: =H23-I23 -> 2370 | K23: =$I$15-I23 -> 60 | L23: 1 | M23: =$M$15-P23 -> 1446 | N23: -895 | O23: =M23-N23 -> 2341 | P23: =$N$15-N23 -> 44
A24: 45827 | B24: 1 | C24: =$C$15-F24 -> 1332 | D24: -1241 | E24: =C24-D24 -> 2573 | F24: =$D$15-D24 -> 48 | G24: 1 | H24: =$H$15-K24 -> 1390 | I24: -980 | J24: =H24-I24 -> 2370 | K24: =$I$15-I24 -> 70 | L24: 1 | M24: =$M$15-P24 -> 1441 | N24: -900 | O24: =M24-N24 -> 2341 | P24: =$N$15-N24 -> 49
A25: 45828 | B25: 1 | C25: =$C$15-F25 -> 1323 | D25: -1250 | E25: =C25-D25 -> 2573 | F25: =$D$15-D25 -> 57 | G25: 1 | H25: =$H$15-K25 -> 1380 | I25: -990 | J25: =H25-I25 -> 2370 | K25: =$I$15-I25 -> 80 | L25: 1 | M25: =$M$15-P25 -> 1436 | N25: -905 | O25: =M25-N25 -> 2341 | P25: =$N$15-N25 -> 54
A26: 45829 | B26: 1 | C26: =$C$15-F26 -> 1314 | D26: -1259 | E26: =C26-D26 -> 2573 | F26: =$D$15-D26 -> 66 | G26: 1 | H26: =$H$15-K26 -> 1350 | I26: -1020 | J26: =H26-I26 -> 2370 | K26: =$I$15-I26 -> 110 | L26: 1 | M26: =$M$15-P26 -> 1431 | N26: -910 | O26: =M26-N26 -> 2341 | P26: =$N$15-N26 -> 59
A27: 45830 | B27: 1 | C27: =$C$15-F27 -> 1283 | D27: -1290 | E27: =C27-D27 -> 2573 | F27: =$D$15-D27 -> 97 | G27: 1 | H27: =$H$15-K27 -> 1320 | I27: -1050 | J27: =H27-I27 -> 2370 | K27: =$I$15-I27 -> 140 | L27: 1 | M27: =$M$15-P27 -> 1416 | N27: -925 | O27: =M27-N27 -> 2341 | P27: =$N$15-N27 -> 74
... A61: 45864 | B61: 1 | C61: =$C$15-F61 -> 1125 | D61: -1448 | E61: =C61-D61 -> 2573 | F61: =$D$15-D61 -> 255 | G61: 1 | H61: =$H$15-K61 -> 1124 | I61: -1246 | J61: =H61-I61 -> 2370 | K61: =$I$15-I61 -> 336 | L61: 1 | M61: =$M$15-P61 -> 1284 | N61: -1057 | O61: =M61-N61 -> 2341 | P61: =$N$15-N61 -> 206
A62: 45865 | B62: 1 | C62: =$C$15-F62 -> 1120 | D62: -1453 | E62: =C62-D62 -> 2573 | F62: =$D$15-D62 -> 260 | G62: 1 | H62: 1075 | I62: -1251 | J62: =H62-I62 -> 2326 | K62: =$I$15-I62 -> 341 | L62: 1 | M62: =$M$15-P62 -> 1280 | N62: -1061 | O62: =M62-N62 -> 2341 | P62: =$N$15-N62 -> 210

Sheet QTL-KM117+300
A1: BẢNG SỐ LIỆU QUAN TRẮC THIẾT BỊ ĐO LÚN MẶT
A2: I. SỐ ĐỌC BAN ĐẦU
A3: Vùng (Đường) | B3: Bàn quan trắc lún | D3: Ngày lắp đặt | F3: =+"Cao trình nghiệm thu [m] ("&TEXT(A15,"dd/mm/yy")&")" -> Cao trình nghiệm thu [m] (10/06/25) | L3: Tọa độ | P3: Mốc tọa độ tham chiếu
F4: Cao trình MĐTN | G4: Cao trình đắp | I4: Cao trình đỉnh ống | K4: Cao trình tấm đế | L4: X [m] | N4: Y [m]
A5: VÙNG 2A (ĐƯỜNG N1) | B5: SSP2-4 | P5: CS3
B6: SSP2-5 | P6: Tọa độ [m]
B7: SSP2-6
A9: II. SỐ LIỆU QUAN TRẮC
A10: Ngày quan trắc | B10: ĐỘ LÚN TRÁI | G10: ĐỘ LÚN TIM | L10: ĐỘ LÚN PHẢI | Q10: Áp Đ.hồ Pvac | R10: Ghi chú
B11: Thời gian tích lũy | C11: Cao độ đắp | D11: Cao độ bàn đo lún | E11: Chiều cao đắp | F11: Độ lún | G11: Thời gian tích lũy | H11: Cao độ đắp | I11: Cao độ bàn đo lún | J11: Chiều cao đắp | K11: Độ lún | L11: Thời gian tích lũy | M11: Cao độ đắp | N11: Cao độ bàn đo lún | O11: Chiều cao đắp | P11: Độ lún
B13: [Ngày] | C13: [mm] | D13: [m.m] | E13: [mm] | F13: [m.m] | G13: [Ngày] | H13: [mm] | I13: [m.m] | J13: [mm] | K13: [m.m] | L13: [Ngày] | M13: [mm] | N13: [m.m] | O13: [mm] | P13: [m.m] | Q13: [kPa]
A14: 1 | B14: =+A14+1 -> 2 | C14: =+B14+1 -> 3 | D14: =+C14+1 -> 4 | E14: =+D14+1 -> 5 | F14: =+E14+1 -> 6 | G14: =+F14+1 -> 7 | H14: =+G14+1 -> 8 | I14: =+H14+1 -> 9 | ... R14: =+Q14+1 -> 18
A15: 45818 | B15: 1 | C15: 1585 | D15: -204 | E15: =C15-D15 -> 1789 | F15: 0 | G15: 1 | H15: 1460 | I15: -310 | J15: =H15-I15 -> 1770 | K15: 0 | L15: 1 | M15: 1510 | N15: -417 | O15: =M15-N15 -> 1927 | P15: 0
A16: 45819 | B16: 1 | C16: =$C$15-F16 -> 1584 | D16: -205 | E16: =C16-D16 -> 1789 | F16: =$D$15-D16 -> 1 | G16: 1 | H16: =$H$15-K16 -> 1459 | I16: -311 | J16: =H16-I16 -> 1770 | K16: =$I$15-I16 -> 1 | L16: 1 | M16: =$M$15-P16 -> 1509 | N16: -418 | O16: =M16-N16 -> 1927 | P16: =$N$15-N16 -> 1
A17: 45820 | B17: 1 | C17: =$C$15-F17 -> 1583 | D17: -206 | E17: =C17-D17 -> 1789 | F17: =$D$15-D17 -> 2 | G17: 1 | H17: =$H$15-K17 -> 1458 | I17: -312 | J17: =H17-I17 -> 1770 | K17: =$I$15-I17 -> 2 | L17: 1 | M17: =$M$15-P17 -> 1508 | N17: -419 | O17: =M17-N17 -> 1927 | P17: =$N$15-N17 -> 2
A18: 45821 | B18: 1 | C18: =$C$15-F18 -> 1582 | D18: -207 | E18: =C18-D18 -> 1789 | F18: =$D$15-D18 -> 3 | G18: 1 | H18: =$H$15-K18 -> 1457 | I18: -313 | J18: =H18-I18 -> 1770 | K18: =$I$15-I18 -> 3 | L18: 1 | M18: =$M$15-P18 -> 1507 | N18: -420 | O18: =M18-N18 -> 1927 | P18: =$N$15-N18 -> 3
A19: 45822 | B19: 1 | C19: =$C$15-F19 -> 1581 | D19: -208 | E19: =C19-D19 -> 1789 | F19: =$D$15-D19 -> 4 | G19: 1 | H19: =$H$15-K19 -> 1445 | I19: -325 | J19: =H19-I19 -> 1770 | K19: =$I$15-I19 -> 15 | L19: 1 | M19: =$M$15-P19 -> 1507 | N19: -420 | O19: =M19-N19 -> 1927 | P19: =$N$15-N19 -> 3
A20: 45823 | B20: 1 | C20: =$C$15-F20 -> 1574 | D20: -215 | E20: =C20-D20 -> 1789 | F20: =$D$15-D20 -> 11 | G20: 1 | H20: =$H$15-K20 -> 1433 | I20: -337 | J20: =H20-I20 -> 1770 | K20: =$I$15-I20 -> 27 | L20: 1 | M20: =$M$15-P20 -> 1505 | N20: -422 | O20: =M20-N20 -> 1927 | P20: =$N$15-N20 -> 5
A21: 45824 | B21: 1 | C21: =$C$15-F21 -> 1567 | D21: -222 | E21: =C21-D21 -> 1789 | F21: =$D$15-D21 -> 18 | G21: 1 | H21: =$H$15-K21 -> 1421 | I21: -349 | J21: =H21-I21 -> 1770 | K21: =$I$15-I21 -> 39 | L21: 1 | M21: =$M$15-P21 -> 1500 | N21: -427 | O21: =M21-N21 -> 1927 | P21: =$N$15-N21 -> 10
A22: 45825 | B22: 1 | C22: =$C$15-F22 -> 1560 | D22: -229 | E22: =C22-D22 -> 1789 | F22: =$D$15-D22 -> 25 | G22: 1 | H22: =$H$15-K22 -> 1409 | I22: -361 | J22: =H22-I22 -> 1770 | K22: =$I$15-I22 -> 51 | L22: 1 | M22: =$M$15-P22 -> 1495 | N22: -432 | O22: =M22-N22 -> 1927 | P22: =$N$15-N22 -> 15
A23: 45826 | B23: 1 | C23: =$C$15-F23 -> 1553 | D23: -236 | E23: =C23-D23 -> 1789 | F23: =$D$15-D23 -> 32 | G23: 1 | H23: =$H$15-K23 -> 1397 | I23: -373 | J23: =H23-I23 -> 1770 | K23: =$I$15-I23 -> 63 | L23: 1 | M23: =$M$15-P23 -> 1490 | N23: -437 | O23: =M23-N23 -> 1927 | P23: =$N$15-N23 -> 20
A24: 45827 | B24: 1 | C24: =$C$15-F24 -> 1546 | D24: -243 | E24: =C24-D24 -> 1789 | F24: =$D$15-D24 -> 39 | G24: 1 | H24: =$H$15-K24 -> 1390 | I24: -380 | J24: =H24-I24 -> 1770 | K24: =$I$15-I24 -> 70 | L24: 1 | M24: =$M$15-P24 -> 1485 | N24: -442 | O24: =M24-N24 -> 1927 | P24: =$N$15-N24 -> 25
A25: 45828 | B25: 1 | C25: =$C$15-F25 -> 1539 | D25: -250 | E25: =C25-D25 -> 1789 | F25: =$D$15-D25 -> 46 | G25: 1 | H25: =$H$15-K25 -> 1385 | I25: -385 | J25: =H25-I25 -> 1770 | K25: =$I$15-I25 -> 75 | L25: 1 | M25: =$M$15-P25 -> 1480 | N25: -447 | O25: =M25-N25 -> 1927 | P25: =$N$15-N25 -> 30
A26: 45829 | B26: 1 | C26: =$C$15-F26 -> 1535 | D26: -254 | E26: =C26-D26 -> 1789 | F26: =$D$15-D26 -> 50 | G26: 1 | H26: =$H$15-K26 -> 1380 | I26: -390 | J26: =H26-I26 -> 1770 | K26: =$I$15-I26 -> 80 | L26: 1 | M26: =$M$15-P26 -> 1475 | N26: -452 | O26: =M26-N26 -> 1927 | P26: =$N$15-N26 -> 35
A27: 45830 | B27: 1 | C27: =$C$15-F27 -> 1519 | D27: -270 | E27: =C27-D27 -> 1789 | F27: =$D$15-D27 -> 66 | G27: 1 | H27: =$H$15-K27 -> 1355 | I27: -415 | J27: =H27-I27 -> 1770 | K27: =$I$15-I27 -> 105 | L27: 1 | M27: =$M$15-P27 -> 1462 | N27: -465 | O27: =M27-N27 -> 1927 | P27: =$N$15-N27 -> 48
... A61: 45864 | B61: 1 | C61: =$C$15-F61 -> 1401 | D61: -388 | E61: =C61-D61 -> 1789 | F61: =$D$15-D61 -> 184 | G61: 1 | H61: =$H$15-K61 -> 1196 | I61: -574 | J61: =H61-I61 -> 1770 | K61: =$I$15-I61 -> 264 | L61: 1 | M61: =$M$15-P61 -> 1370 | N61: -557 | O61: =M61-N61 -> 1927 | P61: =$N$15-N61 -> 140
A62: 45865 | B62: 1 | C62: 1370 | D62: -392 | E62: =C62-D62 -> 1762 | F62: =$D$15-D62 -> 188 | G62: 1 | H62: 1200 | I62: -576 | J62: =H62-I62 -> 1776 | K62: =$I$15-I62 -> 266 | L62: 1 | M62: =$M$15-P62 -> 1367 | N62: -560 | O62: =M62-N62 -> 1927 | P62: =$N$15-N62 -> 143

Sheet QTL-KM117+400
A1: BẢNG SỐ LIỆU QUAN TRẮC THIẾT BỊ ĐO LÚN MẶT
A2: I. SỐ ĐỌC BAN ĐẦU
A3: Vùng (Đường) | B3: Bàn quan trắc lún | D3: Ngày lắp đặt | F3: =+"Cao trình nghiệm thu [m] ("&TEXT(A15,"dd/mm/yy")&")" -> Cao trình nghiệm thu [m] (10/06/25) | L3: Tọa độ | P3: Mốc tọa độ tham chiếu
F4: Cao trình MĐTN | G4: Cao trình đắp | I4: Cao trình đỉnh ống | K4: Cao trình tấm đế | L4: X [m] | N4: Y [m]
A5: VÙNG 2A (ĐƯỜNG N1) | B5: SSP2-4 | P5: CS3
B6: SSP2-5 | P6: Tọa độ [m]
B7: SSP2-6
A9: II. SỐ LIỆU QUAN TRẮC
A10: Ngày quan trắc | B10: ĐỘ LÚN TRÁI | G10: ĐỘ LÚN TIM | L10: ĐỘ LÚN PHẢI | Q10: Áp Đ.hồ Pvac | R10: Ghi chú
B11: Thời gian tích lũy | C11: Cao độ đắp | D11: Cao độ bàn đo lún | E11: Chiều cao đắp | F11: Độ lún | G11: Thời gian tích lũy | H11: Cao độ đắp | I11: Cao độ bàn đo lún | J11: Chiều cao đắp | K11: Độ lún | L11: Thời gian tích lũy | M11: Cao độ đắp | N11: Cao độ bàn đo lún | O11: Chiều cao đắp | P11: Độ lún
B13: [Ngày] | C13: [mm] | D13: [m.m] | E13: [mm] | F13: [m.m] | G13: [Ngày] | H13: [mm] | I13: [m.m] | J13: [mm] | K13: [m.m] | L13: [Ngày] | M13: [mm] | N13: [m.m] | O13: [mm] | P13: [m.m] | Q13: [kPa]
A14: 1 | B14: =+A14+1 -> 2 | C14: =+B14+1 -> 3 | D14: =+C14+1 -> 4 | E14: =+D14+1 -> 5 | F14: =+E14+1 -> 6 | G14: =+F14+1 -> 7 | H14: =+G14+1 -> 8 | I14: =+H14+1 -> 9 | ... R14: =+Q14+1 -> 18
A15: 45818 | B15: 1 | C15: 1585 | D15: -616 | E15: =C15-D15 -> 2201 | F15: 0 | G15: 1 | H15: 1460 | I15: -1165 | J15: =H15-I15 -> 2625 | K15: 0 | L15: 1 | M15: 1570 | N15: -909 | O15: =M15-N15 -> 2479 | P15: 0
A16: 45819 | B16: 1 | C16: =$C$15-F16 -> 1581 | D16: -620 | E16: =C16-D16 -> 2201 | F16: =$D$15-D16 -> 4 | G16: 1 | H16: =$H$15-K16 -> 1456 | I16: -1169 | J16: =H16-I16 -> 2625 | K16: =$I$15-I16 -> 4 | L16: 1 | M16: =$M$15-P16 -> 1567 | N16: -912 | O16: =M16-N16 -> 2479 | P16: =$N$15-N16 -> 3
A17: 45820 | B17: 1 | C17: =$C$15-F17 -> 1577 | D17: -624 | E17: =C17-D17 -> 2201 | F17: =$D$15-D17 -> 8 | G17: 1 | H17: =$H$15-K17 -> 1452 | I17: -1173 | J17: =H17-I17 -> 2625 | K17: =$I$15-I17 -> 8 | L17: 1 | M17: =$M$15-P17 -> 1564 | N17: -915 | O17: =M17-N17 -> 2479 | P17: =$N$15-N17 -> 6
A18: 45821 | B18: 1 | C18: =$C$15-F18 -> 1573 | D18: -628 | E18: =C18-D18 -> 2201 | F18: =$D$15-D18 -> 12 | G18: 1 | H18: =$H$15-K18 -> 1448 | I18: -1177 | J18: =H18-I18 -> 2625 | K18: =$I$15-I18 -> 12 | L18: 1 | M18: =$M$15-P18 -> 1561 | N18: -918 | O18: =M18-N18 -> 2479 | P18: =$N$15-N18 -> 9
A19: 45822 | B19: 1 | C19: =$C$15-F19 -> 1569 | D19: -632 | E19: =C19-D19 -> 2201 | F19: =$D$15-D19 -> 16 | G19: 1 | H19: =$H$15-K19 -> 1444 | I19: -1181 | J19: =H19-I19 -> 2625 | K19: =$I$15-I19 -> 16 | L19: 1 | M19: =$M$15-P19 -> 1558 | N19: -921 | O19: =M19-N19 -> 2479 | P19: =$N$15-N19 -> 12
A20: 45823 | B20: 1 | C20: =$C$15-F20 -> 1565 | D20: -636 | E20: =C20-D20 -> 2201 | F20: =$D$15-D20 -> 20 | G20: 1 | H20: =$H$15-K20 -> 1439 | I20: -1186 | J20: =H20-I20 -> 2625 | K20: =$I$15-I20 -> 21 | L20: 1 | M20: =$M$15-P20 -> 1555 | N20: -924 | O20: =M20-N20 -> 2479 | P20: =$N$15-N20 -> 15
A21: 45824 | B21: 1 | C21: =$C$15-F21 -> 1561 | D21: -640 | E21: =C21-D21 -> 2201 | F21: =$D$15-D21 -> 24 | G21: 1 | H21: =$H$15-K21 -> 1435 | I21: -1190 | J21: =H21-I21 -> 2625 | K21: =$I$15-I21 -> 25 | L21: 1 | M21: =$M$15-P21 -> 1539 | N21: -940 | O21: =M21-N21 -> 2479 | P21: =$N$15-N21 -> 31
A22: 45825 | B22: 1 | C22: =$C$15-F22 -> 1540 | D22: -661 | E22: =C22-D22 -> 2201 | F22: =$D$15-D22 -> 45 | G22: 1 | H22: =$H$15-K22 -> 1420 | I22: -1205 | J22: =H22-I22 -> 2625 | K22: =$I$15-I22 -> 40 | L22: 1 | M22: =$M$15-P22 -> 1523 | N22: -956 | O22: =M22-N22 -> 2479 | P22: =$N$15-N22 -> 47
A23: 45826 | B23: 1 | C23: =$C$15-F23 -> 1519 | D23: -682 | E23: =C23-D23 -> 2201 | F23: =$D$15-D23 -> 66 | G23: 1 | H23: =$H$15-K23 -> 1385 | I23: -1240 | J23: =H23-I23 -> 2625 | K23: =$I$15-I23 -> 75 | L23: 1 | M23: =$M$15-P23 -> 1507 | N23: -972 | O23: =M23-N23 -> 2479 | P23: =$N$15-N23 -> 63
A24: 45827 | B24: 1 | C24: =$C$15-F24 -> 1498 | D24: -703 | E24: =C24-D24 -> 2201 | F24: =$D$15-D24 -> 87 | G24: 1 | H24: =$H$15-K24 -> 1350 | I24: -1275 | J24: =H24-I24 -> 2625 | K24: =$I$15-I24 -> 110 | L24: 1 | M24: =$M$15-P24 -> 1491 | N24: -988 | O24: =M24-N24 -> 2479 | P24: =$N$15-N24 -> 79
A25: 45828 | B25: 1 | C25: =$C$15-F25 -> 1477 | D25: -724 | E25: =C25-D25 -> 2201 | F25: =$D$15-D25 -> 108 | G25: 1 | H25: =$H$15-K25 -> 1315 | I25: -1310 | J25: =H25-I25 -> 2625 | K25: =$I$15-I25 -> 145 | L25: 1 | M25: =$M$15-P25 -> 1489 | N25: -990 | O25: =M25-N25 -> 2479 | P25: =$N$15-N25 -> 81
A26: 45829 | B26: 1 | C26: =$C$15-F26 -> 1468 | D26: -733 | E26: =C26-D26 -> 2201 | F26: =$D$15-D26 -> 117 | G26: 1 | H26: =$H$15-K26 -> 1280 | I26: -1345 | J26: =H26-I26 -> 2625 | K26: =$I$15-I26 -> 180 | L26: 1 | M26: =$M$15-P26 -> 1474 | N26: -1005 | O26: =M26-N26 -> 2479 | P26: =$N$15-N26 -> 96
A27: 45830 | B27: 1 | C27: =$C$15-F27 -> 1451 | D27: -750 | E27: =C27-D27 -> 2201 | F27: =$D$15-D27 -> 134 | G27: 1 | H27: =$H$15-K27 -> 1260 | I27: -1365 | J27: =H27-I27 -> 2625 | K27: =$I$15-I27 -> 200 | L27: 1 | M27: =$M$15-P27 -> 1467 | N27: -1012 | O27: =M27-N27 -> 2479 | P27: =$N$15-N27 -> 103
... A61: 45864 | B61: 1 | C61: =$C$15-F61 -> 1364 | D61: -837 | E61: =C61-D61 -> 2201 | F61: =$D$15-D61 -> 221 | G61: 1 | H61: =$H$15-K61 -> 1125 | I61: -1500 | J61: =H61-I61 -> 2625 | K61: =$I$15-I61 -> 335 | L61: 1 | M61: =$M$15-P61 -> 1375 | N61: -1104 | O61: =M61-N61 -> 2479 | P61: =$N$15-N61 -> 195
A62: 45865 | B62: 1 | C62: 1200 | D62: -838 | E62: =C62-D62 -> 2038 | F62: =$D$15-D62 -> 222 | G62: 1 | H62: =$H$15-K62 -> 1119 | I62: -1506 | J62: =H62-I62 -> 2625 | K62: =$I$15-I62 -> 341 | L62: 1 | M62: =$M$15-P62 -> 1372 | N62: -1107 | O62: =M62-N62 -> 2479 | P62: =$N$15-N62 -> 198

Sheet QTL-KM117+500
A1: BẢNG SỐ LIỆU QUAN TRẮC THIẾT BỊ ĐO LÚN MẶT
A2: I. SỐ ĐỌC BAN ĐẦU
A3: Vùng (Đường) | B3: Bàn quan trắc lún | D3: Ngày lắp đặt | F3: =+"Cao trình nghiệm thu [m] ("&TEXT(A15,"dd/mm/yy")&")" -> Cao trình nghiệm thu [m] (05/06/25) | L3: Tọa độ | P3: Mốc tọa độ tham chiếu
F4: Cao trình MĐTN | G4: Cao trình đắp | I4: Cao trình đỉnh ống | K4: Cao trình tấm đế | L4: X [m] | N4: Y [m]
A5: VÙNG 2A (ĐƯỜNG N1) | B5: SSP2-4 | P5: CS3
B6: SSP2-5 | P6: Tọa độ [m]
B7: SSP2-6
A9: II. SỐ LIỆU QUAN TRẮC
A10: Ngày quan trắc | B10: ĐỘ LÚN TRÁI | G10: ĐỘ LÚN TIM | L10: ĐỘ LÚN PHẢI | Q10: Áp Đ.hồ Pvac | R10: Ghi chú
B11: Thời gian tích lũy | C11: Cao độ đắp | D11: Cao độ bàn đo lún | E11: Chiều cao đắp | F11: Độ lún | G11: Thời gian tích lũy | H11: Cao độ đắp | I11: Cao độ bàn đo lún | J11: Chiều cao đắp | K11: Độ lún | L11: Thời gian tích lũy | M11: Cao độ đắp | N11: Cao độ bàn đo lún | O11: Chiều cao đắp | P11: Độ lún
B13: [Ngày] | C13: [mm] | D13: [m.m] | E13: [mm] | F13: [m.m] | G13: [Ngày] | H13: [mm] | I13: [m.m] | J13: [mm] | K13: [m.m] | L13: [Ngày] | M13: [mm] | N13: [m.m] | O13: [mm] | P13: [m.m] | Q13: [kPa]
A14: 1 | B14: =+A14+1 -> 2 | C14: =+B14+1 -> 3 | D14: =+C14+1 -> 4 | E14: =+D14+1 -> 5 | F14: =+E14+1 -> 6 | G14: =+F14+1 -> 7 | H14: =+G14+1 -> 8 | I14: =+H14+1 -> 9 | ... R14: =+Q14+1 -> 18
A15: 45813 | B15: 1 | C15: 1585 | D15: -818 | E15: =C15-D15 -> 2403 | F15: 0 | G15: 1 | H15: 1460 | I15: -527 | J15: =H15-I15 -> 1987 | K15: 0 | L15: 1 | M15: 1330 | N15: -535 | O15: =M15-N15 -> 1865 | P15: 0
A16: 45814 | B16: 1 | C16: =$C$15-F16 -> 1573 | D16: -830 | E16: =C16-D16 -> 2403 | F16: =$D$15-D16 -> 12 | G16: 1 | H16: =$H$15-K16 -> 1445 | I16: -542 | J16: =H16-I16 -> 1987 | K16: =$I$15-I16 -> 15 | L16: 1 | M16: =$M$15-P16 -> 1318 | N16: -547 | O16: =M16-N16 -> 1865 | P16: =$N$15-N16 -> 12
A17: 45815 | B17: 1 | C17: =$C$15-F17 -> 1561 | D17: -842 | E17: =C17-D17 -> 2403 | F17: =$D$15-D17 -> 24 | G17: 1 | H17: =$H$15-K17 -> 1430 | I17: -557 | J17: =H17-I17 -> 1987 | K17: =$I$15-I17 -> 30 | L17: 1 | M17: =$M$15-P17 -> 1306 | N17: -559 | O17: =M17-N17 -> 1865 | P17: =$N$15-N17 -> 24
A18: 45816 | B18: 1 | C18: =$C$15-F18 -> 1549 | D18: -854 | E18: =C18-D18 -> 2403 | F18: =$D$15-D18 -> 36 | G18: 1 | H18: =$H$15-K18 -> 1415 | I18: -572 | J18: =H18-I18 -> 1987 | K18: =$I$15-I18 -> 45 | L18: 1 | M18: =$M$15-P18 -> 1294 | N18: -571 | O18: =M18-N18 -> 1865 | P18: =$N$15-N18 -> 36
A19: 45817 | B19: 1 | C19: =$C$15-F19 -> 1537 | D19: -866 | E19: =C19-D19 -> 2403 | F19: =$D$15-D19 -> 48 | G19: 1 | H19: =$H$15-K19 -> 1400 | I19: -587 | J19: =H19-I19 -> 1987 | K19: =$I$15-I19 -> 60 | L19: 1 | M19: =$M$15-P19 -> 1282 | N19: -583 | O19: =M19-N19 -> 1865 | P19: =$N$15-N19 -> 48
A20: 45818 | B20: 1 | C20: =$C$15-F20 -> 1525 | D20: -878 | E20: =C20-D20 -> 2403 | F20: =$D$15-D20 -> 60 | G20: 1 | H20: =$H$15-K20 -> 1377 | I20: -610 | J20: =H20-I20 -> 1987 | K20: =$I$15-I20 -> 83 | L20: 1 | M20: =$M$15-P20 -> 1270 | N20: -595 | O20: =M20-N20 -> 1865 | P20: =$N$15-N20 -> 60
A21: 45819 | B21: 1 | C21: =$C$15-F21 -> 1513 | D21: -890 | E21: =C21-D21 -> 2403 | F21: =$D$15-D21 -> 72 | G21: 1 | H21: =$H$15-K21 -> 1354 | I21: -633 | J21: =H21-I21 -> 1987 | K21: =$I$15-I21 -> 106 | L21: 1 | M21: =$M$15-P21 -> 1263 | N21: -602 | O21: =M21-N21 -> 1865 | P21: =$N$15-N21 -> 67
A22: 45820 | B22: 1 | C22: =$C$15-F22 -> 1495 | D22: -908 | E22: =C22-D22 -> 2403 | F22: =$D$15-D22 -> 90 | G22: 1 | H22: =$H$15-K22 -> 1331 | I22: -656 | J22: =H22-I22 -> 1987 | K22: =$I$15-I22 -> 129 | L22: 1 | M22: =$M$15-P22 -> 1256 | N22: -609 | O22: =M22-N22 -> 1865 | P22: =$N$15-N22 -> 74
A23: 45821 | B23: 1 | C23: =$C$15-F23 -> 1487 | D23: -916 | E23: =C23-D23 -> 2403 | F23: =$D$15-D23 -> 98 | G23: 1 | H23: =$H$15-K23 -> 1317 | I23: -670 | J23: =H23-I23 -> 1987 | K23: =$I$15-I23 -> 143 | L23: 1 | M23: =$M$15-P23 -> 1249 | N23: -616 | O23: =M23-N23 -> 1865 | P23: =$N$15-N23 -> 81
A24: 45822 | B24: 1 | C24: =$C$15-F24 -> 1479 | D24: -924 | E24: =C24-D24 -> 2403 | F24: =$D$15-D24 -> 106 | G24: 1 | H24: =$H$15-K24 -> 1307 | I24: -680 | J24: =H24-I24 -> 1987 | K24: =$I$15-I24 -> 153 | L24: 1 | M24: =$M$15-P24 -> 1246 | N24: -619 | O24: =M24-N24 -> 1865 | P24: =$N$15-N24 -> 84
A25: 45823 | B25: 1 | C25: =$C$15-F25 -> 1471 | D25: -932 | E25: =C25-D25 -> 2403 | F25: =$D$15-D25 -> 114 | G25: 1 | H25: =$H$15-K25 -> 1297 | I25: -690 | J25: =H25-I25 -> 1987 | K25: =$I$15-I25 -> 163 | L25: 1 | M25: =$M$15-P25 -> 1241 | N25: -624 | O25: =M25-N25 -> 1865 | P25: =$N$15-N25 -> 89
A26: 45824 | B26: 1 | C26: =$C$15-F26 -> 1463 | D26: -940 | E26: =C26-D26 -> 2403 | F26: =$D$15-D26 -> 122 | G26: 1 | H26: =$H$15-K26 -> 1287 | I26: -700 | J26: =H26-I26 -> 1987 | K26: =$I$15-I26 -> 173 | L26: 1 | M26: =$M$15-P26 -> 1236 | N26: -629 | O26: =M26-N26 -> 1865 | P26: =$N$15-N26 -> 94
A27: 45825 | B27: 1 | C27: =$C$15-F27 -> 1455 | D27: -948 | E27: =C27-D27 -> 2403 | F27: =$D$15-D27 -> 130 | G27: 1 | H27: =$H$15-K27 -> 1277 | I27: -710 | J27: =H27-I27 -> 1987 | K27: =$I$15-I27 -> 183 | L27: 1 | M27: =$M$15-P27 -> 1231 | N27: -634 | O27: =M27-N27 -> 1865 | P27: =$N$15-N27 -> 99
... A66: 45864 | B66: 1 | C66: =$C$15-F66 -> 1295 | D66: -1108 | E66: =C66-D66 -> 2403 | F66: =$D$15-D66 -> 290 | G66: 1 | H66: =$H$15-K66 -> 1091 | I66: -896 | J66: =H66-I66 -> 1987 | K66: =$I$15-I66 -> 369 | L66: 1 | M66: =$M$15-P66 -> 1113 | N66: -752 | O66: =M66-N66 -> 1865 | P66: =$N$15-N66 -> 217
A67: 45865 | B67: 1 | C67: =$C$15-F67 -> 1293 | D67: -1110 | E67: =C67-D67 -> 2403 | F67: =$D$15-D67 -> 292 | G67: 1 | H67: =$H$15-K67 -> 1089 | I67: -898 | J67: =H67-I67 -> 1987 | K67: =$I$15-I67 -> 371 | L67: 1 | M67: 1000 | N67: -754 | O67: =M67-N67 -> 1754 | P67: =$N$15-N67 -> 219

Sheet QTL-KM117+600
A1: BẢNG SỐ LIỆU QUAN TRẮC THIẾT BỊ ĐO LÚN MẶT
A2: I. SỐ ĐỌC BAN ĐẦU
A3: Vùng (Đường) | B3: Bàn quan trắc lún | D3: Ngày lắp đặt | F3: =+"Cao trình nghiệm thu [m] ("&TEXT(A15,"dd/mm/yy")&")" -> Cao trình nghiệm thu [m] (05/06/25) | L3: Tọa độ | P3: Mốc tọa độ tham chiếu
F4: Cao trình MĐTN | G4: Cao trình đắp | I4: Cao trình đỉnh ống | K4: Cao trình tấm đế | L4: X [m] | N4: Y [m]
A5: VÙNG 2A (ĐƯỜNG N1) | B5: SSP2-4 | P5: CS3
B6: SSP2-5 | P6: Tọa độ [m]
B7: SSP2-6
A9: II. SỐ LIỆU QUAN TRẮC
A10: Ngày quan trắc | B10: ĐỘ LÚN TRÁI | G10: ĐỘ LÚN TIM | L10: ĐỘ LÚN PHẢI | Q10: Áp Đ.hồ Pvac | R10: Ghi chú
B11: Thời gian tích lũy | C11: Cao độ đắp | D11: Cao độ bàn đo lún | E11: Chiều cao đắp | F11: Độ lún | G11: Thời gian tích lũy | H11: Cao độ đắp | I11: Cao độ bàn đo lún | J11: Chiều cao đắp | K11: Độ lún | L11: Thời gian tích lũy | M11: Cao độ đắp | N11: Cao độ bàn đo lún | O11: Chiều cao đắp | P11: Độ lún
B13: [Ngày] | C13: [mm] | D13: [m.m] | E13: [mm] | F13: [m.m] | G13: [Ngày] | H13: [mm] | I13: [m.m] | J13: [mm] | K13: [m.m] | L13: [Ngày] | M13: [mm] | N13: [m.m] | O13: [mm] | P13: [m.m] | Q13: [kPa]
A14: 1 | B14: =+A14+1 -> 2 | C14: =+B14+1 -> 3 | D14: =+C14+1 -> 4 | E14: =+D14+1 -> 5 | F14: =+E14+1 -> 6 | G14: =+F14+1 -> 7 | H14: =+G14+1 -> 8 | I14: =+H14+1 -> 9 | ... R14: =+Q14+1 -> 18
A15: 45813 | B15: 1 | C15: 1538 | D15: -649 | E15: =C15-D15 -> 2187 | F15: 0 | G15: 1 | H15: 1528 | I15: -609 | J15: =H15-I15 -> 2137 | K15: 0 | L15: 1 | M15: 1458 | N15: -625 | O15: =M15-N15 -> 2083 | P15: 0
A16: 45814 | B16: 1 | C16: =$C$15-F16 -> 1525 | D16: -662 | E16: =C16-D16 -> 2187 | F16: =$D$15-D16 -> 13 | G16: 1 | H16: =$H$15-K16 -> 1507 | I16: -630 | J16: =H16-I16 -> 2137 | K16: =$I$15-I16 -> 21 | L16: 1 | M16: =$M$15-P16 -> 1445 | N16: -638 | O16: =M16-N16 -> 2083 | P16: =$N$15-N16 -> 13
A17: 45815 | B17: 1 | C17: =$C$15-F17 -> 1512 | D17: -675 | E17: =C17-D17 -> 2187 | F17: =$D$15-D17 -> 26 | G17: 1 | H17: =$H$15-K17 -> 1486 | I17: -651 | J17: =H17-I17 -> 2137 | K17: =$I$15-I17 -> 42 | L17: 1 | M17: =$M$15-P17 -> 1432 | N17: -651 | O17: =M17-N17 -> 2083 | P17: =$N$15-N17 -> 26
A18: 45816 | B18: 1 | C18: =$C$15-F18 -> 1472 | D18: -715 | E18: =C18-D18 -> 2187 | F18: =$D$15-D18 -> 66 | G18: 1 | H18: =$H$15-K18 -> 1465 | I18: -672 | J18: =H18-I18 -> 2137 | K18: =$I$15-I18 -> 63 | L18: 1 | M18: =$M$15-P18 -> 1419 | N18: -664 | O18: =M18-N18 -> 2083 | P18: =$N$15-N18 -> 39
A19: 45817 | B19: 1 | C19: =$C$15-F19 -> 1452 | D19: -735 | E19: =C19-D19 -> 2187 | F19: =$D$15-D19 -> 86 | G19: 1 | H19: =$H$15-K19 -> 1432 | I19: -705 | J19: =H19-I19 -> 2137 | K19: =$I$15-I19 -> 96 | L19: 1 | M19: =$M$15-P19 -> 1406 | N19: -677 | O19: =M19-N19 -> 2083 | P19: =$N$15-N19 -> 52
A20: 45818 | B20: 1 | C20: =$C$15-F20 -> 1432 | D20: -755 | E20: =C20-D20 -> 2187 | F20: =$D$15-D20 -> 106 | G20: 1 | H20: =$H$15-K20 -> 1405 | I20: -732 | J20: =H20-I20 -> 2137 | K20: =$I$15-I20 -> 123 | L20: 1 | M20: =$M$15-P20 -> 1377 | N20: -706 | O20: =M20-N20 -> 2083 | P20: =$N$15-N20 -> 81
A21: 45819 | B21: 1 | C21: =$C$15-F21 -> 1412 | D21: -775 | E21: =C21-D21 -> 2187 | F21: =$D$15-D21 -> 126 | G21: 1 | H21: =$H$15-K21 -> 1378 | I21: -759 | J21: =H21-I21 -> 2137 | K21: =$I$15-I21 -> 150 | L21: 1 | M21: =$M$15-P21 -> 1368 | N21: -715 | O21: =M21-N21 -> 2083 | P21: =$N$15-N21 -> 90
A22: 45820 | B22: 1 | C22: =$C$15-F22 -> 1399 | D22: -788 | E22: =C22-D22 -> 2187 | F22: =$D$15-D22 -> 139 | G22: 1 | H22: =$H$15-K22 -> 1351 | I22: -786 | J22: =H22-I22 -> 2137 | K22: =$I$15-I22 -> 177 | L22: 1 | M22: =$M$15-P22 -> 1363 | N22: -720 | O22: =M22-N22 -> 2083 | P22: =$N$15-N22 -> 95
A23: 45821 | B23: 1 | C23: =$C$15-F23 -> 1395 | D23: -792 | E23: =C23-D23 -> 2187 | F23: =$D$15-D23 -> 143 | G23: 1 | H23: =$H$15-K23 -> 1324 | I23: -813 | J23: =H23-I23 -> 2137 | K23: =$I$15-I23 -> 204 | L23: 1 | M23: =$M$15-P23 -> 1358 | N23: -725 | O23: =M23-N23 -> 2083 | P23: =$N$15-N23 -> 100
A24: 45822 | B24: 1 | C24: =$C$15-F24 -> 1391 | D24: -796 | E24: =C24-D24 -> 2187 | F24: =$D$15-D24 -> 147 | G24: 1 | H24: =$H$15-K24 -> 1297 | I24: -840 | J24: =H24-I24 -> 2137 | K24: =$I$15-I24 -> 231 | L24: 1 | M24: =$M$15-P24 -> 1353 | N24: -730 | O24: =M24-N24 -> 2083 | P24: =$N$15-N24 -> 105
A25: 45823 | B25: 1 | C25: =$C$15-F25 -> 1387 | D25: -800 | E25: =C25-D25 -> 2187 | F25: =$D$15-D25 -> 151 | G25: 1 | H25: =$H$15-K25 -> 1270 | I25: -867 | J25: =H25-I25 -> 2137 | K25: =$I$15-I25 -> 258 | L25: 1 | M25: =$M$15-P25 -> 1348 | N25: -735 | O25: =M25-N25 -> 2083 | P25: =$N$15-N25 -> 110
A26: 45824 | B26: 1 | C26: =$C$15-F26 -> 1383 | D26: -804 | E26: =C26-D26 -> 2187 | F26: =$D$15-D26 -> 155 | G26: 1 | H26: =$H$15-K26 -> 1266 | I26: -871 | J26: =H26-I26 -> 2137 | K26: =$I$15-I26 -> 262 | L26: 1 | M26: =$M$15-P26 -> 1343 | N26: -740 | O26: =M26-N26 -> 2083 | P26: =$N$15-N26 -> 115
A27: 45825 | B27: 1 | C27: =$C$15-F27 -> 1379 | D27: -808 | E27: =C27-D27 -> 2187 | F27: =$D$15-D27 -> 159 | G27: 1 | H27: =$H$15-K27 -> 1260 | I27: -877 | J27: =H27-I27 -> 2137 | K27: =$I$15-I27 -> 268 | L27: 1 | M27: =$M$15-P27 -> 1338 | N27: -745 | O27: =M27-N27 -> 2083 | P27: =$N$15-N27 -> 120
... A59: 45857 | B59: 1 | C59: =$C$15-F59 -> 1237 | D59: -950 | E59: =C59-D59 -> 2187 | F59: =$D$15-D59 -> 301 | G59: 1 | H59: =$H$15-K59 -> 1087 | I59: -1050 | J59: =H59-I59 -> 2137 | K59: =$I$15-I59 -> 441 | L59: 1 | M59: =$M$15-P59 -> 1151 | N59: -932 | O59: =M59-N59 -> 2083 | P59: =$N$15-N59 -> 307

Sheet QTL-KM117+700
A1: BẢNG SỐ LIỆU QUAN TRẮC THIẾT BỊ ĐO LÚN MẶT
A2: I. SỐ ĐỌC BAN ĐẦU
A3: Vùng (Đường) | B3: Bàn quan trắc lún | D3: Ngày lắp đặt | F3: =+"Cao trình nghiệm thu [m] ("&TEXT(A15,"dd/mm/yy")&")" -> Cao trình nghiệm thu [m] (05/06/25) | L3: Tọa độ | P3: Mốc tọa độ tham chiếu
F4: Cao trình MĐTN | G4: Cao trình đắp | I4: Cao trình đỉnh ống | K4: Cao trình tấm đế | L4: X [m] | N4: Y [m]
A5: VÙNG 2A (ĐƯỜNG N1) | B5: SSP2-4 | P5: CS3
B6: SSP2-5 | P6: Tọa độ [m]
B7: SSP2-6
A9: II. SỐ LIỆU QUAN TRẮC
A10: Ngày quan trắc | B10: ĐỘ LÚN TRÁI | G10: ĐỘ LÚN TIM | L10: ĐỘ LÚN PHẢI | Q10: Áp Đ.hồ Pvac | R10: Ghi chú
B11: Thời gian tích lũy | C11: Cao độ đắp | D11: Cao độ bàn đo lún | E11: Chiều cao đắp | F11: Độ lún | G11: Thời gian tích lũy | H11: Cao độ đắp | I11: Cao độ bàn đo lún | J11: Chiều cao đắp | K11: Độ lún | L11: Thời gian tích lũy | M11: Cao độ đắp | N11: Cao độ bàn đo lún | O11: Chiều cao đắp | P11: Độ lún
B13: [Ngày] | C13: [mm] | D13: [m.m] | E13: [mm] | F13: [m.m] | G13: [Ngày] | H13: [mm] | I13: [m.m] | J13: [mm] | K13: [m.m] | L13: [Ngày] | M13: [mm] | N13: [m.m] | O13: [mm] | P13: [m.m] | Q13: [kPa]
A14: 1 | B14: =+A14+1 -> 2 | C14: =+B14+1 -> 3 | D14: =+C14+1 -> 4 | E14: =+D14+1 -> 5 | F14: =+E14+1 -> 6 | G14: =+F14+1 -> 7 | H14: =+G14+1 -> 8 | I14: =+H14+1 -> 9 | ... R14: =+Q14+1 -> 18
A15: 45813 | B15: 1 | C15: 1503 | D15: -1793 | E15: =C15-D15 -> 3296 | F15: 0 | G15: 1 | H15: 1463 | I15: -1297 | J15: =H15-I15 -> 2760 | K15: 0 | L15: 1 | M15: 1552 | N15: -1352 | O15: =M15-N15 -> 2904 | P15: 0
A16: 45814 | B16: 1 | C16: =$C$15-F16 -> 1491 | D16: -1805 | E16: =C16-D16 -> 3296 | F16: =$D$15-D16 -> 12 | G16: 1 | H16: =$H$15-K16 -> 1447 | I16: -1313 | J16: =H16-I16 -> 2760 | K16: =$I$15-I16 -> 16 | L16: 1 | M16: =$M$15-P16 -> 1540 | N16: -1364 | O16: =M16-N16 -> 2904 | P16: =$N$15-N16 -> 12
A17: 45815 | B17: 1 | C17: =$C$15-F17 -> 1479 | D17: -1817 | E17: =C17-D17 -> 3296 | F17: =$D$15-D17 -> 24 | G17: 1 | H17: =$H$15-K17 -> 1431 | I17: -1329 | J17: =H17-I17 -> 2760 | K17: =$I$15-I17 -> 32 | L17: 1 | M17: =$M$15-P17 -> 1528 | N17: -1376 | O17: =M17-N17 -> 2904 | P17: =$N$15-N17 -> 24
A18: 45816 | B18: 1 | C18: =$C$15-F18 -> 1467 | D18: -1829 | E18: =C18-D18 -> 3296 | F18: =$D$15-D18 -> 36 | G18: 1 | H18: =$H$15-K18 -> 1415 | I18: -1345 | J18: =H18-I18 -> 2760 | K18: =$I$15-I18 -> 48 | L18: 1 | M18: =$M$15-P18 -> 1516 | N18: -1388 | O18: =M18-N18 -> 2904 | P18: =$N$15-N18 -> 36
A19: 45817 | B19: 1 | C19: =$C$15-F19 -> 1455 | D19: -1841 | E19: =C19-D19 -> 3296 | F19: =$D$15-D19 -> 48 | G19: 1 | H19: =$H$15-K19 -> 1415 | I19: -1345 | J19: =H19-I19 -> 2760 | K19: =$I$15-I19 -> 48 | L19: 1 | M19: =$M$15-P19 -> 1504 | N19: -1400 | O19: =M19-N19 -> 2904 | P19: =$N$15-N19 -> 48
A20: 45818 | B20: 1 | C20: =$C$15-F20 -> 1450 | D20: -1846 | E20: =C20-D20 -> 3296 | F20: =$D$15-D20 -> 53 | G20: 1 | H20: =$H$15-K20 -> 1382 | I20: -1378 | J20: =H20-I20 -> 2760 | K20: =$I$15-I20 -> 81 | L20: 1 | M20: =$M$15-P20 -> 1492 | N20: -1412 | O20: =M20-N20 -> 2904 | P20: =$N$15-N20 -> 60
A21: 45819 | B21: 1 | C21: =$C$15-F21 -> 1419 | D21: -1877 | E21: =C21-D21 -> 3296 | F21: =$D$15-D21 -> 84 | G21: 1 | H21: =$H$15-K21 -> 1349 | I21: -1411 | J21: =H21-I21 -> 2760 | K21: =$I$15-I21 -> 114 | L21: 1 | M21: =$M$15-P21 -> 1469 | N21: -1435 | O21: =M21-N21 -> 2904 | P21: =$N$15-N21 -> 83
A22: 45820 | B22: 1 | C22: =$C$15-F22 -> 1395 | D22: -1901 | E22: =C22-D22 -> 3296 | F22: =$D$15-D22 -> 108 | G22: 1 | H22: =$H$15-K22 -> 1316 | I22: -1444 | J22: =H22-I22 -> 2760 | K22: =$I$15-I22 -> 147 | L22: 1 | M22: =$M$15-P22 -> 1465 | N22: -1439 | O22: =M22-N22 -> 2904 | P22: =$N$15-N22 -> 87
A23: 45821 | B23: 1 | C23: =$C$15-F23 -> 1387 | D23: -1909 | E23: =C23-D23 -> 3296 | F23: =$D$15-D23 -> 116 | G23: 1 | H23: =$H$15-K23 -> 1283 | I23: -1477 | J23: =H23-I23 -> 2760 | K23: =$I$15-I23 -> 180 | L23: 1 | M23: =$M$15-P23 -> 1461 | N23: -1443 | O23: =M23-N23 -> 2904 | P23: =$N$15-N23 -> 91
A24: 45822 | B24: 1 | C24: =$C$15-F24 -> 1379 | D24: -1917 | E24: =C24-D24 -> 3296 | F24: =$D$15-D24 -> 124 | G24: 1 | H24: =$H$15-K24 -> 1273 | I24: -1487 | J24: =H24-I24 -> 2760 | K24: =$I$15-I24 -> 190 | L24: 1 | M24: =$M$15-P24 -> 1457 | N24: -1447 | O24: =M24-N24 -> 2904 | P24: =$N$15-N24 -> 95
A25: 45823 | B25: 1 | C25: =$C$15-F25 -> 1371 | D25: -1925 | E25: =C25-D25 -> 3296 | F25: =$D$15-D25 -> 132 | G25: 1 | H25: =$H$15-K25 -> 1268 | I25: -1492 | J25: =H25-I25 -> 2760 | K25: =$I$15-I25 -> 195 | L25: 1 | M25: =$M$15-P25 -> 1452 | N25: -1452 | O25: =M25-N25 -> 2904 | P25: =$N$15-N25 -> 100
A26: 45824 | B26: 1 | C26: =$C$15-F26 -> 1363 | D26: -1933 | E26: =C26-D26 -> 3296 | F26: =$D$15-D26 -> 140 | G26: 1 | H26: =$H$15-K26 -> 1263 | I26: -1497 | J26: =H26-I26 -> 2760 | K26: =$I$15-I26 -> 200 | L26: 1 | M26: =$M$15-P26 -> 1447 | N26: -1457 | O26: =M26-N26 -> 2904 | P26: =$N$15-N26 -> 105
A27: 45825 | B27: 1 | C27: =$C$15-F27 -> 1355 | D27: -1941 | E27: =C27-D27 -> 3296 | F27: =$D$15-D27 -> 148 | G27: 1 | H27: =$H$15-K27 -> 1258 | I27: -1502 | J27: =H27-I27 -> 2760 | K27: =$I$15-I27 -> 205 | L27: 1 | M27: =$M$15-P27 -> 1442 | N27: -1462 | O27: =M27-N27 -> 2904 | P27: =$N$15-N27 -> 110
... A67: 45865 | B67: 1 | C67: =$C$15-F67 -> 1195 | D67: -2101 | E67: =C67-D67 -> 3296 | F67: =$D$15-D67 -> 308 | G67: 1 | H67: =$H$15-K67 -> 1095 | I67: -1665 | J67: =H67-I67 -> 2760 | K67: =$I$15-I67 -> 368 | L67: 1 | M67: =$M$15-P67 -> 1194 | N67: -1710 | O67: =M67-N67 -> 2904 | P67: =$N$15-N67 -> 358

Sheet QTL-KM117+800
A1: DỰ ÁN THÀNH PHẦN ĐOẠN HẬU GIANG - CÀ MAU
A2: THUỘC DỰ ÁN XÂY DỰNG CÔNG TRÌNH ĐƯỜNG BỘ CAO TỐC BẮC - NAM PHÍA ĐÔNG GIAI ĐOẠN 2021 - 2025
A3: =UPPER("GÓI THẦU XL03 :Thi Công Xây Dựng Đoạn Tuyến Km114+200 - Km126+223 Bao Gồm Tuyến Nối Nút Giao IC12 Với QL1 (bao gồm khảo sát, thiết kế BVTC)") -> GÓI THẦU XL03 :THI CÔNG XÂY DỰNG ĐOẠN TUYẾN KM114+200 - KM126+223 BAO GỒM TUYẾN NỐI NÚT GIAO IC12 VỚI QL1 (BAO GỒM KHẢO SÁT, THIẾT KẾ BVTC)
A4: CHỦ ĐẦU TƯ | M4: NHÀ THẦU
A5: BAN QUẢN LÝ DỰ ÁN MỸ THUẬN | M5: LIÊN DANH CC1 - HẢI ĐĂNG - VẠN CƯỜNG - 492 - BẮC TRUNG NAM
A7: BẢNG SỐ LIỆU QUAN TRẮC THIẾT BỊ ĐO LÚN MẶT
A8: I. SỐ ĐỌC BAN ĐẦU
A9: Vùng (Đường) | B9: Bàn quan trắc lún | D9: Ngày lắp đặt | F9: =+"Cao trình nghiệm thu [m] ("&TEXT(A21,"dd/mm/yy")&")" -> Cao trình nghiệm thu [m] (20/05/25) | L9: Tọa độ | P9: Mốc tọa độ tham chiếu
F10: Cao trình MĐTN | G10: Cao trình đắp | I10: Cao trình đỉnh ống | K10: Cao trình tấm đế | L10: X [m] | N10: Y [m]
A11: VÙNG 2A (ĐƯỜNG N1) | B11: SSP2-4 | P11: CS3
B12: SSP2-5 | P12: Tọa độ [m]
B13: SSP2-6
A15: II. SỐ LIỆU QUAN TRẮC
A16: Ngày quan trắc | B16: ĐỘ LÚN TRÁI | G16: ĐỘ LÚN TIM | L16: ĐỘ LÚN PHẢI | Q16: Áp Đ.hồ Pvac | R16: Ghi chú
B17: Thời gian tích lũy | C17: Cao độ đắp | D17: Cao độ bàn đo lún | E17: Chiều cao đắp | F17: Độ lún | G17: Thời gian tích lũy | H17: Cao độ đắp | I17: Cao độ bàn đo lún | J17: Chiều cao đắp | K17: Độ lún | L17: Thời gian tích lũy | M17: Cao độ đắp | N17: Cao độ bàn đo lún | O17: Chiều cao đắp | P17: Độ lún
B19: [Ngày] | C19: [mm] | D19: [m.m] | E19: [mm] | F19: [m.m] | G19: [Ngày] | H19: [mm] | I19: [m.m] | J19: [mm] | K19: [m.m] | L19: [Ngày] | M19: [mm] | N19: [m.m] | O19: [mm] | P19: [m.m] | Q19: [kPa]
A20: 1 | B20: =+A20+1 -> 2 | C20: =+B20+1 -> 3 | D20: =+C20+1 -> 4 | E20: =+D20+1 -> 5 | F20: =+E20+1 -> 6 | G20: =+F20+1 -> 7 | H20: =+G20+1 -> 8 | I20: =+H20+1 -> 9 | ... R20: =+Q20+1 -> 18
A21: 45797 | B21: 1 | C21: 1507 | D21: -413 | E21: =C21-D21 -> 1920 | F21: 0 | G21: 1 | H21: 1492 | I21: -683 | J21: =H21-I21 -> 2175 | K21: 0 | L21: 1 | M21: 1447 | N21: -390 | O21: =M21-N21 -> 1837 | P21: 0
A22: 45798 | B22: 2 | C22: =$C$21-F22 -> 1502 | D22: -418 | E22: =C22-D22 -> 1920 | F22: =$D$21-D22 -> 5 | G22: =G21+1 -> 2 | H22: =$H$21-K22 -> 1487 | I22: -688 | J22: =H22-I22 -> 2175 | K22: =$I$21-I22 -> 5 | L22: =L21+1 -> 2 | M22: =$M$21-P22 -> 1447 | N22: -390 | O22: =M22-N22 -> 1837 | P22: =$N$21-N22 -> 0
A23: 45799 | B23: 3 | C23: =$C$21-F23 -> 1502 | D23: -418 | E23: =C23-D23 -> 1920 | F23: =$D$21-D23 -> 5 | G23: =G22+1 -> 3 | H23: =$H$21-K23 -> 1487 | I23: -688 | J23: =H23-I23 -> 2175 | K23: =$I$21-I23 -> 5 | L23: =L22+1 -> 3 | M23: =$M$21-P23 -> 1447 | N23: -390 | O23: =M23-N23 -> 1837 | P23: =$N$21-N23 -> 0
A24: 45800 | B24: 4 | C24: =$C$21-F24 -> 1502 | D24: -418 | E24: =C24-D24 -> 1920 | F24: =$D$21-D24 -> 5 | G24: =G23+1 -> 4 | H24: =$H$21-K24 -> 1487 | I24: -688 | J24: =H24-I24 -> 2175 | K24: =$I$21-I24 -> 5 | L24: =L23+1 -> 4 | M24: =$M$21-P24 -> 1447 | N24: -390 | O24: =M24-N24 -> 1837 | P24: =$N$21-N24 -> 0
A25: 45801 | B25: 4 | C25: =$C$21-F25 -> 1502 | D25: -418 | E25: =C25-D25 -> 1920 | F25: =$D$21-D25 -> 5 | G25: =G24+1 -> 5 | H25: =$H$21-K25 -> 1487 | I25: -688 | J25: =H25-I25 -> 2175 | K25: =$I$21-I25 -> 5 | L25: =L24+1 -> 5 | M25: =$M$21-P25 -> 1447 | N25: -390 | O25: =M25-N25 -> 1837 | P25: =$N$21-N25 -> 0
A26: 45802 | B26: 4 | C26: =$C$21-F26 -> 1502 | D26: -418 | E26: =C26-D26 -> 1920 | F26: =$D$21-D26 -> 5 | G26: =G25+1 -> 6 | H26: =$H$21-K26 -> 1487 | I26: -688 | J26: =H26-I26 -> 2175 | K26: =$I$21-I26 -> 5 | L26: =L25+1 -> 6 | M26: =$M$21-P26 -> 1447 | N26: -390 | O26: =M26-N26 -> 1837 | P26: =$N$21-N26 -> 0
A27: 45803 | B27: 4 | C27: =$C$21-F27 -> 1502 | D27: -418 | E27: =C27-D27 -> 1920 | F27: =$D$21-D27 -> 5 | G27: =G26+1 -> 7 | H27: =$H$21-K27 -> 1487 | I27: -688 | J27: =H27-I27 -> 2175 | K27: =$I$21-I27 -> 5 | L27: =L26+1 -> 7 | M27: =$M$21-P27 -> 1447 | N27: -390 | O27: =M27-N27 -> 1837 | P27: =$N$21-N27 -> 0
A28: 45804 | B28: 4 | C28: =$C$21-F28 -> 1502 | D28: -418 | E28: =C28-D28 -> 1920 | F28: =$D$21-D28 -> 5 | G28: =G27+1 -> 8 | H28: =$H$21-K28 -> 1487 | I28: -688 | J28: =H28-I28 -> 2175 | K28: =$I$21-I28 -> 5 | L28: =L27+1 -> 8 | M28: =$M$21-P28 -> 1447 | N28: -390 | O28: =M28-N28 -> 1837 | P28: =$N$21-N28 -> 0
A29: 45805 | B29: 4 | C29: =$C$21-F29 -> 1502 | D29: -418 | E29: =C29-D29 -> 1920 | F29: =$D$21-D29 -> 5 | G29: =G28+1 -> 9 | H29: =$H$21-K29 -> 1487 | I29: -688 | J29: =H29-I29 -> 2175 | K29: =$I$21-I29 -> 5 | L29: =L28+1 -> 9 | M29: =$M$21-P29 -> 1447 | N29: -390 | O29: =M29-N29 -> 1837 | P29: =$N$21-N29 -> 0
A30: 45806 | B30: 4 | C30: =$C$21-F30 -> 1502 | D30: -418 | E30: =C30-D30 -> 1920 | F30: =$D$21-D30 -> 5 | G30: =G29+1 -> 10 | H30: =$H$21-K30 -> 1487 | I30: -688 | J30: =H30-I30 -> 2175 | K30: =$I$21-I30 -> 5 | L30: =L29+1 -> 10 | M30: =$M$21-P30 -> 1447 | N30: -390 | O30: =M30-N30 -> 1837 | P30: =$N$21-N30 -> 0
A31: 45807 | B31: 4 | C31: =$C$21-F31 -> 1502 | D31: -418 | E31: =C31-D31 -> 1920 | F31: =$D$21-D31 -> 5 | G31: =G30+1 -> 11 | H31: =$H$21-K31 -> 1487 | I31: -688 | J31: =H31-I31 -> 2175 | K31: =$I$21-I31 -> 5 | L31: =L30+1 -> 11 | M31: =$M$21-P31 -> 1447 | N31: -390 | O31: =M31-N31 -> 1837 | P31: =$N$21-N31 -> 0
A32: 45808 | B32: 4 | C32: =$C$21-F32 -> 1502 | D32: -418 | E32: =C32-D32 -> 1920 | F32: =$D$21-D32 -> 5 | G32: =G31+1 -> 12 | H32: =$H$21-K32 -> 1487 | I32: -688 | J32: =H32-I32 -> 2175 | K32: =$I$21-I32 -> 5 | L32: =L31+1 -> 12 | M32: =$M$21-P32 -> 1447 | N32: -390 | O32: =M32-N32 -> 1837 | P32: =$N$21-N32 -> 0
A33: 45809 | B33: 4 | C33: =$C$21-F33 -> 1502 | D33: -418 | E33: =C33-D33 -> 1920 | F33: =$D$21-D33 -> 5 | G33: =G32+1 -> 13 | H33: =$H$21-K33 -> 1473 | I33: -702 | J33: =H33-I33 -> 2175 | K33: =$I$21-I33 -> 19 | L33: =L32+1 -> 13 | M33: =$M$21-P33 -> 1447 | N33: -390 | O33: =M33-N33 -> 1837 | P33: =$N$21-N33 -> 0
... A89: 45865 | B89: 4 | C89: =$C$21-F89 -> 1149 | D89: -771 | E89: =C89-D89 -> 1920 | F89: =$D$21-D89 -> 358 | G89: =G88+1 -> 69 | H89: =$H$21-K89 -> 1064 | I89: -1111 | J89: =H89-I89 -> 2175 | K89: =$I$21-I89 -> 428 | L89: =L88+1 -> 69 | M89: =$M$21-P89 -> 1131 | N89: -706 | O89: =M89-N89 -> 1837 | P89: =$N$21-N89 -> 316

Sheet QTL-KM117+900
A1: DỰ ÁN THÀNH PHẦN ĐOẠN HẬU GIANG - CÀ MAU
A2: THUỘC DỰ ÁN XÂY DỰNG CÔNG TRÌNH ĐƯỜNG BỘ CAO TỐC BẮC - NAM PHÍA ĐÔNG GIAI ĐOẠN 2021 - 2025
A3: =UPPER("GÓI THẦU XL03 :Thi Công Xây Dựng Đoạn Tuyến Km114+200 - Km126+223 Bao Gồm Tuyến Nối Nút Giao IC12 Với QL1 (bao gồm khảo sát, thiết kế BVTC)") -> GÓI THẦU XL03 :THI CÔNG XÂY DỰNG ĐOẠN TUYẾN KM114+200 - KM126+223 BAO GỒM TUYẾN NỐI NÚT GIAO IC12 VỚI QL1 (BAO GỒM KHẢO SÁT, THIẾT KẾ BVTC)
A4: CHỦ ĐẦU TƯ | M4: NHÀ THẦU
A5: BAN QUẢN LÝ DỰ ÁN MỸ THUẬN | M5: LIÊN DANH CC1 - HẢI ĐĂNG - VẠN CƯỜNG - 492 - BẮC TRUNG NAM
A7: BẢNG SỐ LIỆU QUAN TRẮC THIẾT BỊ ĐO LÚN MẶT
A8: I. SỐ ĐỌC BAN ĐẦU
A9: Vùng (Đường) | B9: Bàn quan trắc lún | D9: Ngày lắp đặt | F9: =+"Cao trình nghiệm thu [m] ("&TEXT(A21,"dd/mm/yy")&")" -> Cao trình nghiệm thu [m] (20/05/25) | L9: Tọa độ | P9: Mốc tọa độ tham chiếu
F10: Cao trình MĐTN | G10: Cao trình đắp | I10: Cao trình đỉnh ống | K10: Cao trình tấm đế | L10: X [m] | N10: Y [m]
A11: VÙNG 2A (ĐƯỜNG N1) | B11: SSP2-4 | P11: CS3
B12: SSP2-5 | P12: Tọa độ [m]
B13: SSP2-6
A15: II. SỐ LIỆU QUAN TRẮC
A16: Ngày quan trắc | B16: ĐỘ LÚN TRÁI | G16: ĐỘ LÚN TIM | L16: ĐỘ LÚN PHẢI | Q16: Áp Đ.hồ Pvac | R16: Ghi chú
B17: Thời gian tích lũy | C17: Cao độ đắp | D17: Cao độ bàn đo lún | E17: Chiều cao đắp | F17: Độ lún | G17: Thời gian tích lũy | H17: Cao độ đắp | I17: Cao độ bàn đo lún | J17: Chiều cao đắp | K17: Độ lún | L17: Thời gian tích lũy | M17: Cao độ đắp | N17: Cao độ bàn đo lún | O17: Chiều cao đắp | P17: Độ lún
B19: [Ngày] | C19: [mm] | D19: [m.m] | E19: [mm] | F19: [m.m] | G19: [Ngày] | H19: [mm] | I19: [m.m] | J19: [mm] | K19: [m.m] | L19: [Ngày] | M19: [mm] | N19: [m.m] | O19: [mm] | P19: [m.m] | Q19: [kPa]
A20: 1 | B20: =+A20+1 -> 2 | C20: =+B20+1 -> 3 | D20: =+C20+1 -> 4 | E20: =+D20+1 -> 5 | F20: =+E20+1 -> 6 | G20: =+F20+1 -> 7 | H20: =+G20+1 -> 8 | I20: =+H20+1 -> 9 | ... R20: =+Q20+1 -> 18
A21: 45797 | B21: 1 | C21: 1517 | D21: -778 | E21: =C21-D21 -> 2295 | F21: 0 | G21: 1 | H21: 1482 | I21: -1093 | J21: =H21-I21 -> 2575 | K21: 0 | L21: 1 | M21: 1472 | N21: -468 | O21: =M21-N21 -> 1940 | P21: 0
A22: 45798 | B22: 2 | C22: =$C$21-F22 -> 1512 | D22: -783 | E22: =C22-D22 -> 2295 | F22: =$D$21-D22 -> 5 | G22: =G21+1 -> 2 | H22: =$H$21-K22 -> 1482 | I22: -1093 | J22: =H22-I22 -> 2575 | K22: =$I$21-I22 -> 0 | L22: =L21+1 -> 2 | M22: =$M$21-P22 -> 1467 | N22: -473 | O22: =M22-N22 -> 1940 | P22: =$N$21-N22 -> 5
A23: 45799 | B23: 3 | C23: =$C$21-F23 -> 1512 | D23: -783 | E23: =C23-D23 -> 2295 | F23: =$D$21-D23 -> 5 | G23: =G22+1 -> 3 | H23: =$H$21-K23 -> 1482 | I23: -1093 | J23: =H23-I23 -> 2575 | K23: =$I$21-I23 -> 0 | L23: =L22+1 -> 3 | M23: =$M$21-P23 -> 1467 | N23: -473 | O23: =M23-N23 -> 1940 | P23: =$N$21-N23 -> 5
A24: 45800 | B24: 4 | C24: =$C$21-F24 -> 1512 | D24: -783 | E24: =C24-D24 -> 2295 | F24: =$D$21-D24 -> 5 | G24: =G23+1 -> 4 | H24: =$H$21-K24 -> 1482 | I24: -1093 | J24: =H24-I24 -> 2575 | K24: =$I$21-I24 -> 0 | L24: =L23+1 -> 4 | M24: =$M$21-P24 -> 1467 | N24: -473 | O24: =M24-N24 -> 1940 | P24: =$N$21-N24 -> 5
A25: 45801 | B25: 4 | C25: =$C$21-F25 -> 1512 | D25: -783 | E25: =C25-D25 -> 2295 | F25: =$D$21-D25 -> 5 | G25: =G24+1 -> 5 | H25: =$H$21-K25 -> 1482 | I25: -1093 | J25: =H25-I25 -> 2575 | K25: =$I$21-I25 -> 0 | L25: =L24+1 -> 5 | M25: =$M$21-P25 -> 1467 | N25: -473 | O25: =M25-N25 -> 1940 | P25: =$N$21-N25 -> 5
A26: 45802 | B26: 4 | C26: =$C$21-F26 -> 1512 | D26: -783 | E26: =C26-D26 -> 2295 | F26: =$D$21-D26 -> 5 | G26: =G25+1 -> 6 | H26: =$H$21-K26 -> 1482 | I26: -1093 | J26: =H26-I26 -> 2575 | K26: =$I$21-I26 -> 0 | L26: =L25+1 -> 6 | M26: =$M$21-P26 -> 1467 | N26: -473 | O26: =M26-N26 -> 1940 | P26: =$N$21-N26 -> 5
A27: 45803 | B27: 4 | C27: =$C$21-F27 -> 1512 | D27: -783 | E27: =C27-D27 -> 2295 | F27: =$D$21-D27 -> 5 | G27: =G26+1 -> 7 | H27: =$H$21-K27 -> 1482 | I27: -1093 | J27: =H27-I27 -> 2575 | K27: =$I$21-I27 -> 0 | L27: =L26+1 -> 7 | M27: =$M$21-P27 -> 1467 | N27: -473 | O27: =M27-N27 -> 1940 | P27: =$N$21-N27 -> 5
A28: 45804 | B28: 4 | C28: =$C$21-F28 -> 1512 | D28: -783 | E28: =C28-D28 -> 2295 | F28: =$D$21-D28 -> 5 | G28: =G27+1 -> 8 | H28: =$H$21-K28 -> 1482 | I28: -1093 | J28: =H28-I28 -> 2575 | K28: =$I$21-I28 -> 0 | L28: =L27+1 -> 8 | M28: =$M$21-P28 -> 1467 | N28: -473 | O28: =M28-N28 -> 1940 | P28: =$N$21-N28 -> 5
A29: 45805 | B29: 4 | C29: =$C$21-F29 -> 1512 | D29: -783 | E29: =C29-D29 -> 2295 | F29: =$D$21-D29 -> 5 | G29: =G28+1 -> 9 | H29: =$H$21-K29 -> 1482 | I29: -1093 | J29: =H29-I29 -> 2575 | K29: =$I$21-I29 -> 0 | L29: =L28+1 -> 9 | M29: =$M$21-P29 -> 1467 | N29: -473 | O29: =M29-N29 -> 1940 | P29: =$N$21-N29 -> 5
A30: 45806 | B30: 4 | C30: =$C$21-F30 -> 1512 | D30: -783 | E30: =C30-D30 -> 2295 | F30: =$D$21-D30 -> 5 | G30: =G29+1 -> 10 | H30: =$H$21-K30 -> 1482 | I30: -1093 | J30: =H30-I30 -> 2575 | K30: =$I$21-I30 -> 0 | L30: =L29+1 -> 10 | M30: =$M$21-P30 -> 1467 | N30: -473 | O30: =M30-N30 -> 1940 | P30: =$N$21-N30 -> 5
A31: 45807 | B31: 4 | C31: =$C$21-F31 -> 1512 | D31: -783 | E31: =C31-D31 -> 2295 | F31: =$D$21-D31 -> 5 | G31: =G30+1 -> 11 | H31: =$H$21-K31 -> 1482 | I31: -1093 | J31: =H31-I31 -> 2575 | K31: =$I$21-I31 -> 0 | L31: =L30+1 -> 11 | M31: =$M$21-P31 -> 1467 | N31: -473 | O31: =M31-N31 -> 1940 | P31: =$N$21-N31 -> 5
A32: 45808 | B32: 4 | C32: =$C$21-F32 -> 1512 | D32: -783 | E32: =C32-D32 -> 2295 | F32: =$D$21-D32 -> 5 | G32: =G31+1 -> 12 | H32: =$H$21-K32 -> 1482 | I32: -1093 | J32: =H32-I32 -> 2575 | K32: =$I$21-I32 -> 0 | L32: =L31+1 -> 12 | M32: =$M$21-P32 -> 1467 | N32: -473 | O32: =M32-N32 -> 1940 | P32: =$N$21-N32 -> 5
A33: 45809 | B33: 4 | C33: =$C$21-F33 -> 1512 | D33: -783 | E33: =C33-D33 -> 2295 | F33: =$D$21-D33 -> 5 | G33: =G32+1 -> 13 | H33: =$H$21-K33 -> 1482 | I33: -1093 | J33: =H33-I33 -> 2575 | K33: =$I$21-I33 -> 0 | L33: =L32+1 -> 13 | M33: =$M$21-P33 -> 1467 | N33: -473 | O33: =M33-N33 -> 1940 | P33: =$N$21-N33 -> 5
... A89: 45865 | B89: 4 | C89: =$C$21-F89 -> 1152 | D89: -1143 | E89: =C89-D89 -> 2295 | F89: =$D$21-D89 -> 365 | G89: =G88+1 -> 69 | H89: =$H$21-K89 -> 1046 | I89: -1529 | J89: =H89-I89 -> 2575 | K89: =$I$21-I89 -> 436 | L89: =L88+1 -> 69 | M89: =$M$21-P89 -> 1136 | N89: -804 | O89: =M89-N89 -> 1940 | P89: =$N$21-N89 -> 336

Sheet QTL-KM118+00
A1: DỰ ÁN THÀNH PHẦN ĐOẠN HẬU GIANG - CÀ MAU
A2: THUỘC DỰ ÁN XÂY DỰNG CÔNG TRÌNH ĐƯỜNG BỘ CAO TỐC BẮC - NAM PHÍA ĐÔNG GIAI ĐOẠN 2021 - 2025
A3: =UPPER("GÓI THẦU XL03 :Thi Công Xây Dựng Đoạn Tuyến Km114+200 - Km126+223 Bao Gồm Tuyến Nối Nút Giao IC12 Với QL1 (bao gồm khảo sát, thiết kế BVTC)") -> GÓI THẦU XL03 :THI CÔNG XÂY DỰNG ĐOẠN TUYẾN KM114+200 - KM126+223 BAO GỒM TUYẾN NỐI NÚT GIAO IC12 VỚI QL1 (BAO GỒM KHẢO SÁT, THIẾT KẾ BVTC)
A4: CHỦ ĐẦU TƯ | M4: NHÀ THẦU
A5: BAN QUẢN LÝ DỰ ÁN MỸ THUẬN | M5: LIÊN DANH CC1 - HẢI ĐĂNG - VẠN CƯỜNG - 492 - BẮC TRUNG NAM
A7: BẢNG SỐ LIỆU QUAN TRẮC THIẾT BỊ ĐO LÚN MẶT
A8: I. SỐ ĐỌC BAN ĐẦU
A9: Vùng (Đường) | B9: Bàn quan trắc lún | D9: Ngày lắp đặt | F9: =+"Cao trình nghiệm thu [m] ("&TEXT(A21,"dd/mm/yy")&")" -> Cao trình nghiệm thu [m] (20/05/25) | L9: Tọa độ | P9: Mốc tọa độ tham chiếu
F10: Cao trình MĐTN | G10: Cao trình đắp | I10: Cao trình đỉnh ống | K10: Cao trình tấm đế | L10: X [m] | N10: Y [m]
A11: VÙNG 2A (ĐƯỜNG N1) | B11: SSP2-4 | P11: CS3
B12: SSP2-5 | P12: Tọa độ [m]
B13: SSP2-6
A15: II. SỐ LIỆU QUAN TRẮC
A16: Ngày quan trắc | B16: ĐỘ LÚN TRÁI | G16: ĐỘ LÚN TIM | L16: ĐỘ LÚN PHẢI | Q16: Áp Đ.hồ Pvac | R16: Ghi chú
B17: Thời gian tích lũy | C17: Cao độ đắp | D17: Cao độ bàn đo lún | E17: Chiều cao đắp | F17: Độ lún | G17: Thời gian tích lũy | H17: Cao độ đắp | I17: Cao độ bàn đo lún | J17: Chiều cao đắp | K17: Độ lún | L17: Thời gian tích lũy | M17: Cao độ đắp | N17: Cao độ bàn đo lún | O17: Chiều cao đắp | P17: Độ lún
B19: [Ngày] | C19: [mm] | D19: [m.m] | E19: [mm] | F19: [m.m] | G19: [Ngày] | H19: [mm] | I19: [m.m] | J19: [mm] | K19: [m.m] | L19: [Ngày] | M19: [mm] | N19: [m.m] | O19: [mm] | P19: [m.m] | Q19: [kPa]
A20: 1 | B20: =+A20+1 -> 2 | C20: =+B20+1 -> 3 | D20: =+C20+1 -> 4 | E20: =+D20+1 -> 5 | F20: =+E20+1 -> 6 | G20: =+F20+1 -> 7 | H20: =+G20+1 -> 8 | I20: =+H20+1 -> 9 | ... R20: =+Q20+1 -> 18
A21: 45797 | B21: 1 | C21: 1370 | D21: -723 | E21: =C21-D21 -> 2093 | F21: 0 | G21: 1 | H21: 1420 | I21: -1315 | J21: =H21-I21 -> 2735 | K21: 0 | L21: 1 | M21: 1487 | N21: -1792 | O21: =M21-N21 -> 3279 | P21: 0
A22: 45798 | B22: 2 | C22: =$C$21-F22 -> 1367 | D22: -726 | E22: =C22-D22 -> 2093 | F22: =$D$21-D22 -> 3 | G22: =G21+1 -> 2 | H22: =$H$21-K22 -> 1417 | I22: -1318 | J22: =H22-I22 -> 2735 | K22: =$I$21-I22 -> 3 | L22: =L21+1 -> 2 | M22: =$M$21-P22 -> 1471 | N22: -1808 | O22: =M22-N22 -> 3279 | P22: =$N$21-N22 -> 16
A23: 45799 | B23: 3 | C23: =$C$21-F23 -> 1367 | D23: -726 | E23: =C23-D23 -> 2093 | F23: =$D$21-D23 -> 3 | G23: =G22+1 -> 3 | H23: =$H$21-K23 -> 1417 | I23: -1318 | J23: =H23-I23 -> 2735 | K23: =$I$21-I23 -> 3 | L23: =L22+1 -> 3 | M23: =$M$21-P23 -> 1471 | N23: -1808 | O23: =M23-N23 -> 3279 | P23: =$N$21-N23 -> 16
A24: 45800 | B24: 4 | C24: =$C$21-F24 -> 1367 | D24: -726 | E24: =C24-D24 -> 2093 | F24: =$D$21-D24 -> 3 | G24: =G23+1 -> 4 | H24: =$H$21-K24 -> 1417 | I24: -1318 | J24: =H24-I24 -> 2735 | K24: =$I$21-I24 -> 3 | L24: =L23+1 -> 4 | M24: =$M$21-P24 -> 1471 | N24: -1808 | O24: =M24-N24 -> 3279 | P24: =$N$21-N24 -> 16
A25: 45801 | B25: 4 | C25: =$C$21-F25 -> 1367 | D25: -726 | E25: =C25-D25 -> 2093 | F25: =$D$21-D25 -> 3 | G25: =G24+1 -> 5 | H25: =$H$21-K25 -> 1417 | I25: -1318 | J25: =H25-I25 -> 2735 | K25: =$I$21-I25 -> 3 | L25: =L24+1 -> 5 | M25: =$M$21-P25 -> 1471 | N25: -1808 | O25: =M25-N25 -> 3279 | P25: =$N$21-N25 -> 16
A26: 45802 | B26: 4 | C26: =$C$21-F26 -> 1367 | D26: -726 | E26: =C26-D26 -> 2093 | F26: =$D$21-D26 -> 3 | G26: =G25+1 -> 6 | H26: =$H$21-K26 -> 1417 | I26: -1318 | J26: =H26-I26 -> 2735 | K26: =$I$21-I26 -> 3 | L26: =L25+1 -> 6 | M26: =$M$21-P26 -> 1471 | N26: -1808 | O26: =M26-N26 -> 3279 | P26: =$N$21-N26 -> 16
A27: 45803 | B27: 4 | C27: =$C$21-F27 -> 1367 | D27: -726 | E27: =C27-D27 -> 2093 | F27: =$D$21-D27 -> 3 | G27: =G26+1 -> 7 | H27: =$H$21-K27 -> 1417 | I27: -1318 | J27: =H27-I27 -> 2735 | K27: =$I$21-I27 -> 3 | L27: =L26+1 -> 7 | M27: =$M$21-P27 -> 1471 | N27: -1808 | O27: =M27-N27 -> 3279 | P27: =$N$21-N27 -> 16
A28: 45804 | B28: 4 | C28: =$C$21-F28 -> 1367 | D28: -726 | E28: =C28-D28 -> 2093 | F28: =$D$21-D28 -> 3 | G28: =G27+1 -> 8 | H28: =$H$21-K28 -> 1417 | I28: -1318 | J28: =H28-I28 -> 2735 | K28: =$I$21-I28 -> 3 | L28: =L27+1 -> 8 | M28: =$M$21-P28 -> 1471 | N28: -1808 | O28: =M28-N28 -> 3279 | P28: =$N$21-N28 -> 16
A29: 45805 | B29: 4 | C29: =$C$21-F29 -> 1367 | D29: -726 | E29: =C29-D29 -> 2093 | F29: =$D$21-D29 -> 3 | G29: =G28+1 -> 9 | H29: =$H$21-K29 -> 1417 | I29: -1318 | J29: =H29-I29 -> 2735 | K29: =$I$21-I29 -> 3 | L29: =L28+1 -> 9 | M29: =$M$21-P29 -> 1471 | N29: -1808 | O29: =M29-N29 -> 3279 | P29: =$N$21-N29 -> 16
A30: 45806 | B30: 4 | C30: =$C$21-F30 -> 1367 | D30: -726 | E30: =C30-D30 -> 2093 | F30: =$D$21-D30 -> 3 | G30: =G29+1 -> 10 | H30: =$H$21-K30 -> 1417 | I30: -1318 | J30: =H30-I30 -> 2735 | K30: =$I$21-I30 -> 3 | L30: =L29+1 -> 10 | M30: =$M$21-P30 -> 1471 | N30: -1808 | O30: =M30-N30 -> 3279 | P30: =$N$21-N30 -> 16
A31: 45807 | B31: 4 | C31: =$C$21-F31 -> 1367 | D31: -726 | E31: =C31-D31 -> 2093 | F31: =$D$21-D31 -> 3 | G31: =G30+1 -> 11 | H31: =$H$21-K31 -> 1417 | I31: -1318 | J31: =H31-I31 -> 2735 | K31: =$I$21-I31 -> 3 | L31: =L30+1 -> 11 | M31: =$M$21-P31 -> 1471 | N31: -1808 | O31: =M31-N31 -> 3279 | P31: =$N$21-N31 -> 16
A32: 45808 | B32: 4 | C32: =$C$21-F32 -> 1367 | D32: -726 | E32: =C32-D32 -> 2093 | F32: =$D$21-D32 -> 3 | G32: =G31+1 -> 12 | H32: =$H$21-K32 -> 1417 | I32: -1318 | J32: =H32-I32 -> 2735 | K32: =$I$21-I32 -> 3 | L32: =L31+1 -> 12 | M32: =$M$21-P32 -> 1471 | N32: -1808 | O32: =M32-N32 -> 3279 | P32: =$N$21-N32 -> 16
A33: 45809 | B33: 4 | C33: =$C$21-F33 -> 1367 | D33: -726 | E33: =C33-D33 -> 2093 | F33: =$D$21-D33 -> 3 | G33: =G32+1 -> 13 | H33: =$H$21-K33 -> 1417 | I33: -1318 | J33: =H33-I33 -> 2735 | K33: =$I$21-I33 -> 3 | L33: =L32+1 -> 13 | M33: =$M$21-P33 -> 1471 | N33: -1808 | O33: =M33-N33 -> 3279 | P33: =$N$21-N33 -> 16
... A89: 45865 | B89: 4 | C89: =$C$21-F89 -> 1061 | D89: -1032 | E89: =C89-D89 -> 2093 | F89: =$D$21-D89 -> 309 | G89: =G88+1 -> 69 | H89: =$H$21-K89 -> 991 | I89: -1744 | J89: =H89-I89 -> 2735 | K89: =$I$21-I89 -> 429 | L89: =L88+1 -> 69 | M89: =$M$21-P89 -> 1180 | N89: -2099 | O89: =M89-N89 -> 3279 | P89: =$N$21-N89 -> 307

Sheet QTL-KM118+100
A1: DỰ ÁN THÀNH PHẦN ĐOẠN HẬU GIANG - CÀ MAU
A2: THUỘC DỰ ÁN XÂY DỰNG CÔNG TRÌNH ĐƯỜNG BỘ CAO TỐC BẮC - NAM PHÍA ĐÔNG GIAI ĐOẠN 2021 - 2025
A3: =UPPER("GÓI THẦU XL03 :Thi Công Xây Dựng Đoạn Tuyến Km114+200 - Km126+223 Bao Gồm Tuyến Nối Nút Giao IC12 Với QL1 (bao gồm khảo sát, thiết kế BVTC)") -> GÓI THẦU XL03 :THI CÔNG XÂY DỰNG ĐOẠN TUYẾN KM114+200 - KM126+223 BAO GỒM TUYẾN NỐI NÚT GIAO IC12 VỚI QL1 (BAO GỒM KHẢO SÁT, THIẾT KẾ BVTC)
A4: CHỦ ĐẦU TƯ | M4: NHÀ THẦU
A5: BAN QUẢN LÝ DỰ ÁN MỸ THUẬN | M5: LIÊN DANH CC1 - HẢI ĐĂNG - VẠN CƯỜNG - 492 - BẮC TRUNG NAM
A7: BẢNG SỐ LIỆU QUAN TRẮC THIẾT BỊ ĐO LÚN MẶT
A8: I. SỐ ĐỌC BAN ĐẦU
A9: Vùng (Đường) | B9: Bàn quan trắc lún | D9: Ngày lắp đặt | F9: =+"Cao trình nghiệm thu [m] ("&TEXT(A21,"dd/mm/yy")&")" -> Cao trình nghiệm thu [m] (20/05/25) | L9: Tọa độ | P9: Mốc tọa độ tham chiếu
F10: Cao trình MĐTN | G10: Cao trình đắp | I10: Cao trình đỉnh ống | K10: Cao trình tấm đế | L10: X [m] | N10: Y [m]
A11: VÙNG 2A (ĐƯỜNG N1) | B11: SSP2-4 | P11: CS3
B12: SSP2-5 | P12: Tọa độ [m]
B13: SSP2-6
A15: II. SỐ LIỆU QUAN TRẮC
A16: Ngày quan trắc | B16: ĐỘ LÚN TRÁI | G16: ĐỘ LÚN TIM | L16: ĐỘ LÚN PHẢI | Q16: Áp Đ.hồ Pvac | R16: Ghi chú
B17: Thời gian tích lũy | C17: Cao độ đắp | D17: Cao độ bàn đo lún | E17: Chiều cao đắp | F17: Độ lún | G17: Thời gian tích lũy | H17: Cao độ đắp | I17: Cao độ bàn đo lún | J17: Chiều cao đắp | K17: Độ lún | L17: Thời gian tích lũy | M17: Cao độ đắp | N17: Cao độ bàn đo lún | O17: Chiều cao đắp | P17: Độ lún
B19: [Ngày] | C19: [mm] | D19: [m.m] | E19: [mm] | F19: [m.m] | G19: [Ngày] | H19: [mm] | I19: [m.m] | J19: [mm] | K19: [m.m] | L19: [Ngày] | M19: [mm] | N19: [m.m] | O19: [mm] | P19: [m.m] | Q19: [kPa]
A20: 1 | B20: =+A20+1 -> 2 | C20: =+B20+1 -> 3 | D20: =+C20+1 -> 4 | E20: =+D20+1 -> 5 | F20: =+E20+1 -> 6 | G20: =+F20+1 -> 7 | H20: =+G20+1 -> 8 | I20: =+H20+1 -> 9 | ... R20: =+Q20+1 -> 18
A21: 45797 | B21: 1 | C21: 1490 | D21: -477 | E21: =C21-D21 -> 1967 | F21: 0 | G21: 1 | H21: 1484 | I21: -1004 | J21: =H21-I21 -> 2488 | K21: 0 | L21: 1 | M21: 1592 | N21: -578 | O21: =M21-N21 -> 2170 | P21: 0
A22: 45798 | B22: 1 | C22: =$C$21-F22 -> 1488 | D22: -479 | E22: =C22-D22 -> 1967 | F22: =$D$21-D22 -> 2 | G22: =G21+1 -> 2 | H22: =$H$21-K22 -> 1476 | I22: -1012 | J22: =H22-I22 -> 2488 | K22: =$I$21-I22 -> 8 | L22: =L21+1 -> 2 | M22: =$M$21-P22 -> 1591 | N22: -579 | O22: =M22-N22 -> 2170 | P22: =$N$21-N22 -> 1
A23: 45799 | B23: 1 | C23: =$C$21-F23 -> 1488 | D23: -479 | E23: =C23-D23 -> 1967 | F23: =$D$21-D23 -> 2 | G23: =G22+1 -> 3 | H23: =$H$21-K23 -> 1476 | I23: -1012 | J23: =H23-I23 -> 2488 | K23: =$I$21-I23 -> 8 | L23: =L22+1 -> 3 | M23: =$M$21-P23 -> 1591 | N23: -579 | O23: =M23-N23 -> 2170 | P23: =$N$21-N23 -> 1
A24: 45800 | B24: 1 | C24: =$C$21-F24 -> 1488 | D24: -479 | E24: =C24-D24 -> 1967 | F24: =$D$21-D24 -> 2 | G24: =G23+1 -> 4 | H24: =$H$21-K24 -> 1476 | I24: -1012 | J24: =H24-I24 -> 2488 | K24: =$I$21-I24 -> 8 | L24: =L23+1 -> 4 | M24: =$M$21-P24 -> 1591 | N24: -579 | O24: =M24-N24 -> 2170 | P24: =$N$21-N24 -> 1
A25: 45801 | B25: 1 | C25: =$C$21-F25 -> 1488 | D25: -479 | E25: =C25-D25 -> 1967 | F25: =$D$21-D25 -> 2 | G25: =G24+1 -> 5 | H25: =$H$21-K25 -> 1476 | I25: -1012 | J25: =H25-I25 -> 2488 | K25: =$I$21-I25 -> 8 | L25: =L24+1 -> 5 | M25: =$M$21-P25 -> 1591 | N25: -579 | O25: =M25-N25 -> 2170 | P25: =$N$21-N25 -> 1
A26: 45802 | B26: 1 | C26: =$C$21-F26 -> 1488 | D26: -479 | E26: =C26-D26 -> 1967 | F26: =$D$21-D26 -> 2 | G26: =G25+1 -> 6 | H26: =$H$21-K26 -> 1476 | I26: -1012 | J26: =H26-I26 -> 2488 | K26: =$I$21-I26 -> 8 | L26: =L25+1 -> 6 | M26: =$M$21-P26 -> 1591 | N26: -579 | O26: =M26-N26 -> 2170 | P26: =$N$21-N26 -> 1
A27: 45803 | B27: 1 | C27: =$C$21-F27 -> 1488 | D27: -479 | E27: =C27-D27 -> 1967 | F27: =$D$21-D27 -> 2 | G27: =G26+1 -> 7 | H27: =$H$21-K27 -> 1476 | I27: -1012 | J27: =H27-I27 -> 2488 | K27: =$I$21-I27 -> 8 | L27: =L26+1 -> 7 | M27: =$M$21-P27 -> 1591 | N27: -579 | O27: =M27-N27 -> 2170 | P27: =$N$21-N27 -> 1
A28: 45804 | B28: 1 | C28: =$C$21-F28 -> 1488 | D28: -479 | E28: =C28-D28 -> 1967 | F28: =$D$21-D28 -> 2 | G28: =G27+1 -> 8 | H28: =$H$21-K28 -> 1476 | I28: -1012 | J28: =H28-I28 -> 2488 | K28: =$I$21-I28 -> 8 | L28: =L27+1 -> 8 | M28: =$M$21-P28 -> 1591 | N28: -579 | O28: =M28-N28 -> 2170 | P28: =$N$21-N28 -> 1
A29: 45805 | B29: 1 | C29: =$C$21-F29 -> 1488 | D29: -479 | E29: =C29-D29 -> 1967 | F29: =$D$21-D29 -> 2 | G29: =G28+1 -> 9 | H29: =$H$21-K29 -> 1476 | I29: -1012 | J29: =H29-I29 -> 2488 | K29: =$I$21-I29 -> 8 | L29: =L28+1 -> 9 | M29: =$M$21-P29 -> 1591 | N29: -579 | O29: =M29-N29 -> 2170 | P29: =$N$21-N29 -> 1
A30: 45806 | B30: 1 | C30: =$C$21-F30 -> 1488 | D30: -479 | E30: =C30-D30 -> 1967 | F30: =$D$21-D30 -> 2 | G30: =G29+1 -> 10 | H30: =$H$21-K30 -> 1476 | I30: -1012 | J30: =H30-I30 -> 2488 | K30: =$I$21-I30 -> 8 | L30: =L29+1 -> 10 | M30: =$M$21-P30 -> 1591 | N30: -579 | O30: =M30-N30 -> 2170 | P30: =$N$21-N30 -> 1
A31: 45807 | B31: 1 | C31: =$C$21-F31 -> 1488 | D31: -479 | E31: =C31-D31 -> 1967 | F31: =$D$21-D31 -> 2 | G31: =G30+1 -> 11 | H31: =$H$21-K31 -> 1476 | I31: -1012 | J31: =H31-I31 -> 2488 | K31: =$I$21-I31 -> 8 | L31: =L30+1 -> 11 | M31: =$M$21-P31 -> 1591 | N31: -579 | O31: =M31-N31 -> 2170 | P31: =$N$21-N31 -> 1
A32: 45808 | B32: 1 | C32: =$C$21-F32 -> 1488 | D32: -479 | E32: =C32-D32 -> 1967 | F32: =$D$21-D32 -> 2 | G32: =G31+1 -> 12 | H32: =$H$21-K32 -> 1476 | I32: -1012 | J32: =H32-I32 -> 2488 | K32: =$I$21-I32 -> 8 | L32: =L31+1 -> 12 | M32: =$M$21-P32 -> 1591 | N32: -579 | O32: =M32-N32 -> 2170 | P32: =$N$21-N32 -> 1
