Workbook

Sheet 114+840
B1: 1 | C1: =+B1+1 -> 2 | D1: =+C1+1 -> 3 | E1: =+D1+1 -> 4 | F1: =+E1+1 -> 5 | G1: =+F1+1 -> 6 | H1: =+G1+1 -> 7 | I1: =+H1+1 -> 8 | J1: =+I1+1 -> 9 | ... W1: =+V1+1 -> 22 | Y1: =+W1+1 -> 23 | Z1: =+Y1+1 -> 24 | AA1: =+Z1+1 -> 25 | AB1: =+AA1+1 -> 26
A2: DỰ ÁN THÀNH PHẦN ĐOẠN HẬU GIANG - CÀ MAU
A3: THUỘC DỰ ÁN XÂY DỰNG CÔNG TRÌNH ĐƯỜNG BỘ CAO TỐC BẮC - NAM PHÍA ĐÔNG GIAI ĐOẠN 2021 - 2025
A4: =UPPER("GÓI THẦU XL03 :Thi Công Xây Dựng Đoạn Tuyến Km114+200 - Km126+223 Bao Gồm Tuyến Nối Nút Giao IC12 Với QL1 (bao gồm khảo sát, thiết kế BVTC)") -> GÓI THẦU XL03 :THI CÔNG XÂY DỰNG ĐOẠN TUYẾN KM114+200 - KM126+223 BAO GỒM TUYẾN NỐI NÚT GIAO IC12 VỚI QL1 (BAO GỒM KHẢO SÁT, THIẾT KẾ BVTC)
A5: CHỦ ĐẦU TƯ | I5: TƯ VẤN GIÁM SÁT | S5: NHÀ THẦU
A6: BAN QUẢN LÝ DỰ ÁN MỸ THUẬN | I6: =UPPER("Liên danh Phân viện KHCN GTVT phía Nam - Công ty Cổ phần Tư vấn kỹ thuật và xây dựng Hồng Hà") -> LIÊN DANH PHÂN VIỆN KHCN GTVT PHÍA NAM - CÔNG TY CỔ PHẦN TƯ VẤN KỸ THUẬT VÀ XÂY DỰNG HỒNG HÀ | S6: LIÊN DANH CC1 - HẢI ĐĂNG - VẠN CƯỜNG - 492 - BẮC TRUNG NAM
A7: BIỂU GHI ĐO QUAN TRẮC LÚN
A8: Người lập: | K8: Tên mốc:
A9: Thời tiết: | C9: Nắng | K9: Cao độ mốc: | M9: =C14 -> 842
A10: Lý trình: | C10: Km114+840 | K10: Ngày đặt bàn: | M10: =B14 -> 45270
A12: Stt | B12: Ngày quan trắc | C12: Cao độ mốc (mm) | D12: Số đọc tại mốc (mm) | E12: Số đọc mia (mm) | H12: Cao độ quan trắc (mm) | K12: Chiều dài cần nối (mm) | N12: Cao độ bàn đo lún (mm) | Q12: Tốc độ lún (mm) | T12: Số đọc mia tại nền đắp tại tâm (mm) | U12: Cao độ nền đắp (mm) | X12: Chiều dày lớp đắp (m) | Y12: Đội quan trắc | Z12: Nhà thầu | AA12: Tư Vấn Giám Sát | AB12: Ghi chú
E13: Trái | F13: Giữa | G13: Phải | H13: Trái | I13: Giữa | J13: Phải | K13: Trái | L13: Giữa | M13: Phải | N13: Trái | O13: Giữa | P13: Phải | Q13: Trái | R13: Giữa | S13: Phải | U13: Trái | V13: Giữa | W13: Phải
A14: 0 | B14: 45270 | C14: 842 | D14: 1623 | E14: =C14+D14-H14 -> 545 | F14: =C14+D14-I14 -> 365 | G14: =D14+C14-J14 -> 855 | H14: =K14+N14 -> 1920 | I14: =L14+O14 -> 2100 | J14: =M14+P14 -> 1610 | K14: 2000 | L14: 2000 | M14: 2000 | N14: -80 | O14: 100 | P14: -390 | Q14: 0 | R14: 0 | S14: 0 | T14: =D14+C14-V14 -> 2365 | U14: =N14 -> -80 | V14: =O14 -> 100 | W14: =P14 -> -390 | AB14: Lắp đặt ban đầu
A15: 1 | B15: =B14+1 -> 45271 | C15: =C14 -> 842 | D15: =D14-2 -> 1621 | E15: =C15+D15-H15 -> 543 | F15: =C15+D15-I15 -> 363 | G15: =D15+C15-J15 -> 853 | H15: =K15+N15 -> 1920 | I15: =L15+O15 -> 2100 | J15: =M15+P15 -> 1610 | K15: =K14 -> 2000 | L15: =L14 -> 2000 | M15: =M14 -> 2000 | N15: =N14-Q15 -> -80 | O15: =O14-R15 -> 100 | P15: =P14-S15 -> -390 | Q15: 0 | R15: 0 | S15: 0 | T15: =D15+C15-V15 -> 2363 | U15: =N15 -> -80 | V15: =O15 -> 100 | W15: =P15 -> -390
A16: 2 | B16: =B15+1 -> 45272 | C16: =C15 -> 842 | D16: =D15-2 -> 1619 | E16: =C16+D16-H16 -> 541 | F16: =C16+D16-I16 -> 361 | G16: =D16+C16-J16 -> 851 | H16: =K16+N16 -> 1920 | I16: =L16+O16 -> 2100 | J16: =M16+P16 -> 1610 | K16: =K15 -> 2000 | L16: =L15 -> 2000 | M16: =M15 -> 2000 | N16: =N15-Q16 -> -80 | O16: =O15-R16 -> 100 | P16: =P15-S16 -> -390 | Q16: 0 | R16: 0 | S16: 0 | T16: =D16+C16-V16 -> 2361 | U16: =N16 -> -80 | V16: =O16 -> 100 | W16: =P16 -> -390
A17: 3 | B17: =B16+1 -> 45273 | C17: =C16 -> 842 | D17: =D16-2 -> 1617 | E17: =C17+D17-H17 -> 539 | F17: =C17+D17-I17 -> 359 | G17: =D17+C17-J17 -> 849 | H17: =K17+N17 -> 1920 | I17: =L17+O17 -> 2100 | J17: =M17+P17 -> 1610 | K17: =K16 -> 2000 | L17: =L16 -> 2000 | M17: =M16 -> 2000 | N17: =N16-Q17 -> -80 | O17: =O16-R17 -> 100 | P17: =P16-S17 -> -390 | Q17: 0 | R17: 0 | S17: 0 | T17: =D17+C17-V17 -> 2359 | U17: =N17 -> -80 | V17: =O17 -> 100 | W17: =P17 -> -390 | AD17: 45273
A18: 4 | B18: =B17+1 -> 45274 | C18: =C17 -> 842 | D18: =D17-2 -> 1615 | E18: =C18+D18-H18 -> 537 | F18: =C18+D18-I18 -> 357 | G18: =D18+C18-J18 -> 847 | H18: =K18+N18 -> 1920 | I18: =L18+O18 -> 2100 | J18: =M18+P18 -> 1610 | K18: =K17 -> 2000 | L18: =L17 -> 2000 | M18: =M17 -> 2000 | N18: =N17-Q18 -> -80 | O18: =O17-R18 -> 100 | P18: =P17-S18 -> -390 | Q18: 0 | R18: 0 | S18: 0 | T18: =D18+C18-V18 -> 2357 | U18: =N18 -> -80 | V18: =O18 -> 100 | W18: =P18 -> -390 | AD18: 45277
A19: 5 | B19: =B18+1 -> 45275 | C19: =C18 -> 842 | D19: =D18-2 -> 1613 | E19: =C19+D19-H19 -> 535 | F19: =C19+D19-I19 -> 355 | G19: =D19+C19-J19 -> 845 | H19: =K19+N19 -> 1920 | I19: =L19+O19 -> 2100 | J19: =M19+P19 -> 1610 | K19: =K18 -> 2000 | L19: =L18 -> 2000 | M19: =M18 -> 2000 | N19: =N18-Q19 -> -80 | O19: =O18-R19 -> 100 | P19: =P18-S19 -> -390 | Q19: 0 | R19: 0 | S19: 0 | T19: =D19+C19-V19 -> 2355 | U19: =N19 -> -80 | V19: =O19 -> 100 | W19: =P19 -> -390 | AD19: 45281
A20: 6 | B20: =B19+1 -> 45276 | C20: =C19 -> 842 | D20: =D19-2 -> 1611 | E20: =C20+D20-H20 -> 533 | F20: =C20+D20-I20 -> 353 | G20: =D20+C20-J20 -> 843 | H20: =K20+N20 -> 1920 | I20: =L20+O20 -> 2100 | J20: =M20+P20 -> 1610 | K20: =K19 -> 2000 | L20: =L19 -> 2000 | M20: =M19 -> 2000 | N20: =N19-Q20 -> -80 | O20: =O19-R20 -> 100 | P20: =P19-S20 -> -390 | Q20: 0 | R20: 0 | S20: 0 | T20: =D20+C20-V20 -> 2353 | U20: =N20 -> -80 | V20: =O20 -> 100 | W20: =P20 -> -390 | AD20: 45287
A21: 7 | B21: =B20+1 -> 45277 | C21: =C20 -> 842 | D21: =D20-2 -> 1609 | E21: =C21+D21-H21 -> 531 | F21: =C21+D21-I21 -> 351 | G21: =D21+C21-J21 -> 841 | H21: =K21+N21 -> 1920 | I21: =L21+O21 -> 2100 | J21: =M21+P21 -> 1610 | K21: =K20 -> 2000 | L21: =L20 -> 2000 | M21: =M20 -> 2000 | N21: =N20-Q21 -> -80 | O21: =O20-R21 -> 100 | P21: =P20-S21 -> -390 | Q21: 0 | R21: 0 | S21: 0 | T21: =D21+C21-V21 -> 2351 | U21: =N21 -> -80 | V21: =O21 -> 100 | W21: =P21 -> -390 | AD21: 45293
A22: 8 | B22: =B21+1 -> 45278 | C22: =C21 -> 842 | D22: =D21-2 -> 1607 | E22: =C22+D22-H22 -> 529 | F22: =C22+D22-I22 -> 349 | G22: =D22+C22-J22 -> 839 | H22: =K22+N22 -> 1920 | I22: =L22+O22 -> 2100 | J22: =M22+P22 -> 1610 | K22: =K21 -> 2000 | L22: =L21 -> 2000 | M22: =M21 -> 2000 | N22: =N21-Q22 -> -80 | O22: =O21-R22 -> 100 | P22: =P21-S22 -> -390 | Q22: 0 | R22: 0 | S22: 0 | T22: =D22+C22-V22 -> 2349 | U22: =N22 -> -80 | V22: =O22 -> 100 | W22: =P22 -> -390 | AD22: 45299
A23: 9 | B23: =B22+1 -> 45279 | C23: =C22 -> 842 | D23: =D22-2 -> 1605 | E23: =C23+D23-H23 -> 527 | F23: =C23+D23-I23 -> 347 | G23: =D23+C23-J23 -> 837 | H23: =K23+N23 -> 1920 | I23: =L23+O23 -> 2100 | J23: =M23+P23 -> 1610 | K23: =K22 -> 2000 | L23: =L22 -> 2000 | M23: =M22 -> 2000 | N23: =N22-Q23 -> -80 | O23: =O22-R23 -> 100 | P23: =P22-S23 -> -390 | Q23: 0 | R23: 0 | S23: 0 | T23: =D23+C23-V23 -> 2347 | U23: =U22+$X23*1000-Q23 -> -80 | V23: =V22+$X23*1000-R23 -> 100 | W23: =W22+$X23*1000-S23 -> -390 | AD23: 45305
A24: 10 | B24: =B23+1 -> 45280 | C24: =C23 -> 842 | D24: =D23-2 -> 1603 | E24: =C24+D24-H24 -> 525 | F24: =C24+D24-I24 -> 345 | G24: =D24+C24-J24 -> 835 | H24: =K24+N24 -> 1920 | I24: =L24+O24 -> 2100 | J24: =M24+P24 -> 1610 | K24: =K23 -> 2000 | L24: =L23 -> 2000 | M24: =M23 -> 2000 | N24: =N23-Q24 -> -80 | O24: =O23-R24 -> 100 | P24: =P23-S24 -> -390 | Q24: 0 | R24: 0 | S24: 0 | T24: =D24+C24-V24 -> 2345 | U24: =U23+$X24*1000-Q24 -> -80 | V24: =V23+$X24*1000-R24 -> 100 | W24: =W23+$X24*1000-S24 -> -390 | AD24: 45311
A25: 11 | B25: =B24+1 -> 45281 | C25: =C24 -> 842 | D25: =D24-2 -> 1601 | E25: =C25+D25-H25 -> 523 | F25: =C25+D25-I25 -> 343 | G25: =D25+C25-J25 -> 833 | H25: =K25+N25 -> 1920 | I25: =L25+O25 -> 2100 | J25: =M25+P25 -> 1610 | K25: =K24 -> 2000 | L25: =L24 -> 2000 | M25: =M24 -> 2000 | N25: =N24-Q25 -> -80 | O25: =O24-R25 -> 100 | P25: =P24-S25 -> -390 | Q25: 0 | R25: 0 | S25: 0 | T25: =D25+C25-V25 -> 2343 | U25: =U24+$X25*1000-Q25 -> -80 | V25: =V24+$X25*1000-R25 -> 100 | W25: =W24+$X25*1000-S25 -> -390 | AD25: 45396
A26: 12 | B26: =B25+1 -> 45282 | C26: =C25 -> 842 | D26: =D25-2 -> 1599 | E26: =C26+D26-H26 -> 521 | F26: =C26+D26-I26 -> 341 | G26: =D26+C26-J26 -> 831 | H26: =K26+N26 -> 1920 | I26: =L26+O26 -> 2100 | J26: =M26+P26 -> 1610 | K26: =K25 -> 2000 | L26: =L25 -> 2000 | M26: =M25 -> 2000 | N26: =N25-Q26 -> -80 | O26: =O25-R26 -> 100 | P26: =P25-S26 -> -390 | Q26: 0 | R26: 0 | S26: 0 | T26: =D26+C26-V26 -> 2341 | U26: =U25+$X26*1000-Q26 -> -80 | V26: =V25+$X26*1000-R26 -> 100 | W26: =W25+$X26*1000-S26 -> -390 | AD26: 45400
A27: 13 | B27: =B26+1 -> 45283 | C27: =C26 -> 842 | D27: =D26-2 -> 1597 | E27: =C27+D27-H27 -> 519 | F27: =C27+D27-I27 -> 339 | G27: =D27+C27-J27 -> 829 | H27: =K27+N27 -> 1920 | I27: =L27+O27 -> 2100 | J27: =M27+P27 -> 1610 | K27: =K26 -> 2000 | L27: =L26 -> 2000 | M27: =M26 -> 2000 | N27: =N26-Q27 -> -80 | O27: =O26-R27 -> 100 | P27: =P26-S27 -> -390 | Q27: 0 | R27: 0 | S27: 0 | T27: =D27+C27-V27 -> 2339 | U27: =U26+$X27*1000-Q27 -> -80 | V27: =V26+$X27*1000-R27 -> 100 | W27: =W26+$X27*1000-S27 -> -390 | AD27: 45405
A28: 14 | B28: =B27+1 -> 45284 | C28: =C27 -> 842 | D28: =D27-2 -> 1595 | E28: =C28+D28-H28 -> 517 | F28: =C28+D28-I28 -> 337 | G28: =D28+C28-J28 -> 827 | H28: =K28+N28 -> 1920 | I28: =L28+O28 -> 2100 | J28: =M28+P28 -> 1610 | K28: =K27 -> 2000 | L28: =L27 -> 2000 | M28: =M27 -> 2000 | N28: =N27-Q28 -> -80 | O28: =O27-R28 -> 100 | P28: =P27-S28 -> -390 | Q28: 0 | R28: 0 | S28: 0 | T28: =D28+C28-V28 -> 2337 | U28: =U27+$X28*1000-Q28 -> -80 | V28: =V27+$X28*1000-R28 -> 100 | W28: =W27+$X28*1000-S28 -> -390
A29: 15 | B29: =B28+1 -> 45285 | C29: =C28 -> 842 | D29: =D28-2 -> 1593 | E29: =C29+D29-H29 -> 515 | F29: =C29+D29-I29 -> 335 | G29: =D29+C29-J29 -> 825 | H29: =K29+N29 -> 1920 | I29: =L29+O29 -> 2100 | J29: =M29+P29 -> 1610 | K29: =K28 -> 2000 | L29: =L28 -> 2000 | M29: =M28 -> 2000 | N29: =N28-Q29 -> -80 | O29: =O28-R29 -> 100 | P29: =P28-S29 -> -390 | Q29: 0 | R29: 0 | S29: 0 | T29: =D29+C29-V29 -> 2335 | U29: =U28+$X29*1000-Q29 -> -80 | V29: =V28+$X29*1000-R29 -> 100 | W29: =W28+$X29*1000-S29 -> -390
A30: 16 | B30: =B29+1 -> 45286 | C30: =C29 -> 842 | D30: =D29-2 -> 1591 | E30: =C30+D30-H30 -> 513 | F30: =C30+D30-I30 -> 333 | G30: =D30+C30-J30 -> 823 | H30: =K30+N30 -> 1920 | I30: =L30+O30 -> 2100 | J30: =M30+P30 -> 1610 | K30: =K29 -> 2000 | L30: =L29 -> 2000 | M30: =M29 -> 2000 | N30: =N29-Q30 -> -80 | O30: =O29-R30 -> 100 | P30: =P29-S30 -> -390 | Q30: 0 | R30: 0 | S30: 0 | T30: =D30+C30-V30 -> 2333 | U30: =U29+$X30*1000-Q30 -> -80 | V30: =V29+$X30*1000-R30 -> 100 | W30: =W29+$X30*1000-S30 -> -390
A31: 17 | B31: =B30+1 -> 45287 | C31: =C30 -> 842 | D31: =D30-2 -> 1589 | E31: =C31+D31-H31 -> 511 | F31: =C31+D31-I31 -> 331 | G31: =D31+C31-J31 -> 829 | H31: =K31+N31 -> 1920 | I31: =L31+O31 -> 2100 | J31: =M31+P31 -> 1602 | K31: =K30 -> 2000 | L31: =L30 -> 2000 | M31: =M30 -> 2000 | N31: =N30-Q31 -> -80 | O31: =O30-R31 -> 100 | P31: =P30-S31 -> -398 | Q31: 0 | R31: 0 | S31: 8 | T31: =D31+C31-V31 -> 2331 | U31: =U30+$X31*1000-Q31 -> -80 | V31: =V30+$X31*1000-R31 -> 100 | W31: =W30+0.29*1000-S31 -> -108 | Y31: -100 | Z31: -100 | AA31: -100 | AB31: 8
A32: 18 | B32: =B31+1 -> 45288 | C32: =C31 -> 842 | D32: =D31-2 -> 1587 | E32: =C32+D32-H32 -> 509 | F32: =C32+D32-I32 -> 329 | G32: =D32+C32-J32 -> 833 | H32: =K32+N32 -> 1920 | I32: =L32+O32 -> 2100 | J32: =M32+P32 -> 1596 | K32: =K31 -> 2000 | L32: =L31 -> 2000 | M32: =M31 -> 2000 | N32: =N31-Q32 -> -80 | O32: =O31-R32 -> 100 | P32: =P31-S32 -> -404 | Q32: 0 | R32: 0 | S32: 6 | T32: =D32+C32-V32 -> 2329 | U32: =U31+$X32*1000-Q32 -> -80 | V32: =V31+$X32*1000-R32 -> 100 | W32: =W31+$X32*1000-S32 -> -114
A33: 19 | B33: =B32+1 -> 45289 | C33: =C32 -> 842 | D33: =D32-2 -> 1585 | E33: =C33+D33-H33 -> 507 | F33: =C33+D33-I33 -> 327 | G33: =D33+C33-J33 -> 837 | H33: =K33+N33 -> 1920 | I33: =L33+O33 -> 2100 | J33: =M33+P33 -> 1590 | K33: =K32 -> 2000 | L33: =L32 -> 2000 | M33: =M32 -> 2000 | N33: =N32-Q33 -> -80 | O33: =O32-R33 -> 100 | P33: =P32-S33 -> -410 | Q33: 0 | R33: 0 | S33: 6 | T33: =D33+C33-V33 -> 2327 | U33: =U32+$X33*1000-Q33 -> -80 | V33: =V32+$X33*1000-R33 -> 100 | W33: =W32+$X33*1000-S33 -> -120
A34: 20 | B34: =B33+1 -> 45290 | C34: =C33 -> 842 | D34: =D33-2 -> 1583 | E34: =C34+D34-H34 -> 505 | F34: =C34+D34-I34 -> 325 | G34: =D34+C34-J34 -> 841 | H34: =K34+N34 -> 1920 | I34: =L34+O34 -> 2100 | J34: =M34+P34 -> 1584 | K34: =K33 -> 2000 | L34: =L33 -> 2000 | M34: =M33 -> 2000 | N34: =N33-Q34 -> -80 | O34: =O33-R34 -> 100 | P34: =P33-S34 -> -416 | Q34: 0 | R34: 0 | S34: 6 | T34: =D34+C34-V34 -> 2325 | U34: =U33+$X34*1000-Q34 -> -80 | V34: =V33+$X34*1000-R34 -> 100 | W34: =W33+$X34*1000-S34 -> -126
A35: 21 | B35: =B34+1 -> 45291 | C35: =C34 -> 842 | D35: =D34-2 -> 1581 | E35: =C35+D35-H35 -> 503 | F35: =C35+D35-I35 -> 323 | G35: =D35+C35-J35 -> 848 | H35: =K35+N35 -> 1920 | I35: =L35+O35 -> 2100 | J35: =M35+P35 -> 1575 | K35: =K34 -> 2000 | L35: =L34 -> 2000 | M35: =M34 -> 2000 | N35: =N34-Q35 -> -80 | O35: =O34-R35 -> 100 | P35: =P34-S35 -> -425 | Q35: 0 | R35: 0 | S35: 9 | T35: =D35+C35-V35 -> 2323 | U35: =U34+$X35*1000-Q35 -> -80 | V35: =V34+$X35*1000-R35 -> 100 | W35: =W34+$X35*1000-S35 -> -135
A36: 22 | B36: =B35+1 -> 45292 | C36: =C35 -> 842 | D36: =D35-2 -> 1579 | E36: =C36+D36-H36 -> 501 | F36: =C36+D36-I36 -> 321 | G36: =D36+C36-J36 -> 849 | H36: =K36+N36 -> 1920 | I36: =L36+O36 -> 2100 | J36: =M36+P36 -> 1572 | K36: =K35 -> 2000 | L36: =L35 -> 2000 | M36: =M35 -> 2000 | N36: =N35-Q36 -> -80 | O36: =O35-R36 -> 100 | P36: =P35-S36 -> -428 | Q36: 0 | R36: 0 | S36: 3 | T36: =D36+C36-V36 -> 2321 | U36: =U35+$X36*1000-Q36 -> -80 | V36: =V35+$X36*1000-R36 -> 100 | W36: =W35+$X36*1000-S36 -> -138
A37: 23 | B37: =B36+1 -> 45293 | C37: =C36 -> 842 | D37: =D36-2 -> 1577 | E37: =C37+D37-H37 -> 507 | F37: =C37+D37-I37 -> 327 | G37: =D37+C37-J37 -> 854 | H37: =K37+N37 -> 1912 | I37: =L37+O37 -> 2092 | J37: =M37+P37 -> 1565 | K37: =K36 -> 2000 | L37: =L36 -> 2000 | M37: =M36 -> 2000 | N37: =N36-Q37 -> -88 | O37: =O36-R37 -> 92 | P37: =P36-S37 -> -435 | Q37: 8 | R37: 8 | S37: 7 | T37: =D37+C37-V37 -> 2227 | U37: =U36+0.28*1000-Q37 -> 192 | V37: =V36+0.1*1000-R37 -> 192 | W37: =W36+$X37*1000-S37 -> 155 | X37: 0.3 | AB37: 7
A38: 24 | B38: =B37+1 -> 45294 | C38: =C37 -> 842 | D38: =D37-2 -> 1575 | E38: =C38+D38-H38 -> 508 | F38: =C38+D38-I38 -> 331 | G38: =D38+C38-J38 -> 855 | H38: =K38+N38 -> 1909 | I38: =L38+O38 -> 2086 | J38: =M38+P38 -> 1562 | K38: =K37 -> 2000 | L38: =L37 -> 2000 | M38: =M37 -> 2000 | N38: =N37-Q38 -> -91 | O38: =O37-R38 -> 86 | P38: =P37-S38 -> -438 | Q38: 3 | R38: 6 | S38: 3 | T38: =D38+C38-V38 -> 2231 | U38: =U37+$X38*1000-Q38 -> 189 | V38: =V37+$X38*1000-R38 -> 186 | W38: =W37+$X38*1000-S38 -> 152
A39: 25 | B39: =B38+1 -> 45295 | C39: =C38 -> 842 | D39: =D38-2 -> 1573 | E39: =C39+D39-H39 -> 510 | F39: =C39+D39-I39 -> 335 | G39: =D39+C39-J39 -> 857 | H39: =K39+N39 -> 1905 | I39: =L39+O39 -> 2080 | J39: =M39+P39 -> 1558 | K39: =K38 -> 2000 | L39: =L38 -> 2000 | M39: =M38 -> 2000 | N39: =N38-Q39 -> -95 | O39: =O38-R39 -> 80 | P39: =P38-S39 -> -442 | Q39: 4 | R39: 6 | S39: 4 | T39: =D39+C39-V39 -> 2235 | U39: =U38+$X39*1000-Q39 -> 185 | V39: =V38+$X39*1000-R39 -> 180 | W39: =W38+$X39*1000-S39 -> 148
A40: 26 | B40: =B39+1 -> 45296 | C40: =C39 -> 842 | D40: =D39-2 -> 1571 | E40: =C40+D40-H40 -> 510 | F40: =C40+D40-I40 -> 339 | G40: =D40+C40-J40 -> 860 | H40: =K40+N40 -> 1903 | I40: =L40+O40 -> 2074 | J40: =M40+P40 -> 1553 | K40: =K39 -> 2000 | L40: =L39 -> 2000 | M40: =M39 -> 2000 | N40: =N39-Q40 -> -97 | O40: =O39-R40 -> 74 | P40: =P39-S40 -> -447 | Q40: 2 | R40: 6 | S40: 5 | T40: =D40+C40-V40 -> 2239 | U40: =U39+$X40*1000-Q40 -> 183 | V40: =V39+$X40*1000-R40 -> 174 | W40: =W39+$X40*1000-S40 -> 143
A41: 27 | B41: =B40+1 -> 45297 | C41: =C40 -> 842 | D41: =D40-2 -> 1569 | E41: =C41+D41-H41 -> 516 | F41: =C41+D41-I41 -> 346 | G41: =D41+C41-J41 -> 867 | H41: =K41+N41 -> 1895 | I41: =L41+O41 -> 2065 | J41: =M41+P41 -> 1544 | K41: =K40 -> 2000 | L41: =L40 -> 2000 | M41: =M40 -> 2000 | N41: =N40-Q41 -> -105 | O41: =O40-R41 -> 65 | P41: =P40-S41 -> -456 | Q41: 8 | R41: 9 | S41: 9 | T41: =D41+C41-V41 -> 2246 | U41: =U40+$X41*1000-Q41 -> 175 | V41: =V40+$X41*1000-R41 -> 165 | W41: =W40+$X41*1000-S41 -> 134
...

Sheet BC.114+840
A1: 13 | B1: DỰ ÁN THÀNH PHẦN ĐOẠN HẬU GIANG - CÀ MAU
B2: THUỘC DỰ ÁN XÂY DỰNG CÔNG TRÌNH ĐƯỜNG BỘ CAO TỐC BẮC - NAM PHÍA ĐÔNG GIAI ĐOẠN 2021 - 2025
B3: =UPPER("GÓI THẦU XL03 :Thi Công Xây Dựng Đoạn Tuyến Km114+200 - Km126+223 Bao Gồm Tuyến Nối Nút Giao IC12 Với QL1 (bao gồm khảo sát, thiết kế BVTC)") -> GÓI THẦU XL03 :THI CÔNG XÂY DỰNG ĐOẠN TUYẾN KM114+200 - KM126+223 BAO GỒM TUYẾN NỐI NÚT GIAO IC12 VỚI QL1 (BAO GỒM KHẢO SÁT, THIẾT KẾ BVTC)
B4: CHỦ ĐẦU TƯ | J4: TƯ VẤN GIÁM SÁT | T4: NHÀ THẦU
B5: BAN QUẢN LÝ DỰ ÁN MỸ THUẬN | J5: =UPPER("Liên danh Phân viện KHCN GTVT phía Nam - Công ty Cổ phần Tư vấn kỹ thuật và xây dựng Hồng Hà") -> LIÊN DANH PHÂN VIỆN KHCN GTVT PHÍA NAM - CÔNG TY CỔ PHẦN TƯ VẤN KỸ THUẬT VÀ XÂY DỰNG HỒNG HÀ | T5: LIÊN DANH CC1 - HẢI ĐĂNG - VẠN CƯỜNG - 492 - BẮC TRUNG NAM
B6: BIỂU GHI ĐO QUAN TRẮC LÚN
B7: Người lập: | C7: ='114+840'!C8 -> 0 | L7: Tên mốc: | N7: ='114+840'!M8 -> 0
B8: Thời tiết: | C8: ='114+840'!C9 -> Nắng | L8: Cao độ mốc: | N8: ='114+840'!M9 -> 842
B9: Lý trình: | C9: ='114+840'!C10 -> Km114+840 | L9: Ngày đặt bàn: | N9: ='114+840'!M10 -> 45270
B11: Ngày | C11: Ngày cộng dồn | D11: Cao độ mốc | E11: Số đọc mia của mốc | F11: Cao độ đường ngắm | G11: Trái | M11: Tim | S11: Phải | Z11: Chiều dày lớp đắp (m) | AA11: Chiều cao nền đắp (m) | AB11: Chiều dày nền đắp (m)
G12: Cao độ đắp (mm) | H12: Số đọc mia | I12: Cao độ quan trắc (mm) | J12: Cao độ bàn đo lún (mm) | K12: Độ lún (mm) | L12: Độ lún tích lũy (mm) | M12: Cao độ đắp (mm) | N12: Số đọc mia | O12: Cao độ quan trắc (mm) | P12: Cao độ bàn đo lún (mm) | Q12: Độ lún (mm) | R12: Độ lún tích lũy (mm) | S12: Cao độ đắp (mm) | T12: Số đọc mia | U12: Cao độ quan trắc (mm) | V12: Cao độ bàn đo lún (mm) | W12: Độ lún (mm) | X12: Độ lún tích lũy (mm)
B13: ='114+840'!B14 -> 45270 | C13: 0 | D13: =VLOOKUP(B13,'114+840'!B14:AB115,2,FALSE) -> 842 | E13: =VLOOKUP(B13,'114+840'!B14:AB115,3,FALSE) -> 1623 | F13: =D13+E13 -> 2465 | G13: =VLOOKUP(B13,'114+840'!$B$14:$AB$115,20,FALSE) -> -80 | H13: =VLOOKUP(B13,'114+840'!$B$14:$AB$115,4,FALSE) -> 545 | I13: =F13-H13 -> 1920 | J13: =VLOOKUP(B13,'114+840'!$B$14:$AB$115,13,FALSE) -> -80 | K13: ='114+840'!Q14 -> 0 | L13: 0 | M13: =VLOOKUP(B13,'114+840'!$B$14:$AB$115,21,FALSE) -> 100 | N13: =VLOOKUP(B13,'114+840'!$B$14:$AB$115,5,FALSE) -> 365 | O13: =F13-N13 -> 2100 | P13: =VLOOKUP(B13,'114+840'!$B$14:$AB$115,14,FALSE) -> 100 | Q13: ='114+840'!R14 -> 0 | R13: 0 | S13: =VLOOKUP(B13,'114+840'!$B$14:$AB$115,22,FALSE) -> -390 | T13: =VLOOKUP(B13,'114+840'!$B$13:$AB$115,6,FALSE) -> 855 | U13: =F13-T13 -> 1610 | V13: =VLOOKUP(B13,'114+840'!$B$14:$AB$115,15,FALSE) -> -390 | W13: ='114+840'!S14 -> 0 | X13: 0 | Y13: 0 | Z13: =IF(Y13>0,Y13,0) -> 0 | AA13: =Z13 -> 0 | AB13: 0
B14: ='114+840'!B15 -> 45271 | C14: =B14-B13 -> 1 | D14: =D13 -> 842 | E14: =VLOOKUP(B14,'114+840'!B15:AB116,3,FALSE) -> 1621 | F14: =D14+E14 -> 2463 | G14: =VLOOKUP(B14,'114+840'!$B$15:$AB$115,20,FALSE) -> -80 | H14: =VLOOKUP(B14,'114+840'!$B$15:$AB$115,4,FALSE) -> 543 | I14: =F14-H14 -> 1920 | J14: =VLOOKUP(B14,'114+840'!$B$15:$AB$115,13,FALSE) -> -80 | K14: ='114+840'!Q15 -> 0 | L14: =+K14+L13 -> 0 | M14: =VLOOKUP(B14,'114+840'!$B$14:$AB$115,21,FALSE) -> 100 | N14: =VLOOKUP(B14,'114+840'!$B$15:$AB$115,5,FALSE) -> 363 | O14: =F14-N14 -> 2100 | P14: =VLOOKUP(B14,'114+840'!$B$15:$AB$115,14,FALSE) -> 100 | Q14: ='114+840'!R15 -> 0 | R14: =+Q14+R13 -> 0 | S14: =VLOOKUP(B14,'114+840'!$B$14:$AB$115,22,FALSE) -> -390 | T14: =VLOOKUP(B14,'114+840'!$B$15:$AB$115,6,FALSE) -> 853 | U14: =F14-T14 -> 1610 | V14: =VLOOKUP(B14,'114+840'!$B$15:$AB$115,15,FALSE) -> -390 | W14: ='114+840'!S15 -> 0 | X14: =+W14+X13 -> 0 | Y14: =S14-S13 -> 0 | Z14: =IF(Y14>0,Y14,0)/1000 -> 0 | AA14: =AA13+Z14 -> 0 | AB14: =(M14-$M$13-R14)/1000 -> 0
A15: 1 | B15: ='114+840'!B16 -> 45272 | C15: =B15-B14 -> 1 | D15: =D14 -> 842 | E15: =VLOOKUP(B15,'114+840'!B16:AB117,3,FALSE) -> 1619 | F15: =D15+E15 -> 2461 | G15: =VLOOKUP(B15,'114+840'!$B$15:$AB$115,20,FALSE) -> -80 | H15: =VLOOKUP(B15,'114+840'!$B$15:$AB$115,4,FALSE) -> 541 | I15: =F15-H15 -> 1920 | J15: =VLOOKUP(B15,'114+840'!$B$15:$AB$115,13,FALSE) -> -80 | K15: ='114+840'!Q16 -> 0 | L15: =+K15+L14 -> 0 | M15: =VLOOKUP(B15,'114+840'!$B$14:$AB$115,21,FALSE) -> 100 | N15: =VLOOKUP(B15,'114+840'!$B$15:$AB$115,5,FALSE) -> 361 | O15: =F15-N15 -> 2100 | P15: =VLOOKUP(B15,'114+840'!$B$15:$AB$115,14,FALSE) -> 100 | Q15: ='114+840'!R16 -> 0 | R15: =+Q15+R14 -> 0 | S15: =VLOOKUP(B15,'114+840'!$B$14:$AB$115,22,FALSE) -> -390 | T15: =VLOOKUP(B15,'114+840'!$B$15:$AB$115,6,FALSE) -> 851 | U15: =F15-T15 -> 1610 | V15: =VLOOKUP(B15,'114+840'!$B$15:$AB$115,15,FALSE) -> -390 | W15: ='114+840'!S16 -> 0 | X15: =+W15+X14 -> 0 | Y15: =S15-S14 -> 0 | Z15: =IF(Y15>0,Y15,0)/1000 -> 0 | AA15: =AA14+Z15 -> 0 | AB15: =(M15-$M$13-R15)/1000 -> 0
A16: =A15+1 -> 2 | B16: ='114+840'!B17 -> 45273 | C16: =B16-B15 -> 1 | D16: =D15 -> 842 | E16: =VLOOKUP(B16,'114+840'!B17:AB118,3,FALSE) -> 1617 | F16: =D16+E16 -> 2459 | G16: =VLOOKUP(B16,'114+840'!$B$15:$AB$115,20,FALSE) -> -80 | H16: =VLOOKUP(B16,'114+840'!$B$15:$AB$115,4,FALSE) -> 539 | I16: =F16-H16 -> 1920 | J16: =VLOOKUP(B16,'114+840'!$B$15:$AB$115,13,FALSE) -> -80 | K16: ='114+840'!Q17 -> 0 | L16: =+K16+L15 -> 0 | M16: =VLOOKUP(B16,'114+840'!$B$14:$AB$115,21,FALSE) -> 100 | N16: =VLOOKUP(B16,'114+840'!$B$15:$AB$115,5,FALSE) -> 359 | O16: =F16-N16 -> 2100 | P16: =VLOOKUP(B16,'114+840'!$B$15:$AB$115,14,FALSE) -> 100 | Q16: ='114+840'!R17 -> 0 | R16: =+Q16+R15 -> 0 | S16: =VLOOKUP(B16,'114+840'!$B$14:$AB$115,22,FALSE) -> -390 | T16: =VLOOKUP(B16,'114+840'!$B$15:$AB$115,6,FALSE) -> 849 | U16: =F16-T16 -> 1610 | V16: =VLOOKUP(B16,'114+840'!$B$15:$AB$115,15,FALSE) -> -390 | W16: ='114+840'!S17 -> 0 | X16: =+W16+X15 -> 0 | Y16: =S16-S15 -> 0 | Z16: =IF(Y16>0,Y16,0)/1000 -> 0 | AA16: =AA15+Z16 -> 0 | AB16: =(M16-$M$13-R16)/1000 -> 0
A17: =A16+1 -> 3 | B17: ='114+840'!B18 -> 45274 | C17: =B17-B16 -> 1 | D17: =D16 -> 842 | E17: =VLOOKUP(B17,'114+840'!B18:AB119,3,FALSE) -> 1615 | F17: =D17+E17 -> 2457 | G17: =VLOOKUP(B17,'114+840'!$B$15:$AB$115,20,FALSE) -> -80 | H17: =VLOOKUP(B17,'114+840'!$B$15:$AB$115,4,FALSE) -> 537 | I17: =F17-H17 -> 1920 | J17: =VLOOKUP(B17,'114+840'!$B$15:$AB$115,13,FALSE) -> -80 | K17: ='114+840'!Q18 -> 0 | L17: =+K17+L16 -> 0 | M17: =VLOOKUP(B17,'114+840'!$B$14:$AB$115,21,FALSE) -> 100 | N17: =VLOOKUP(B17,'114+840'!$B$15:$AB$115,5,FALSE) -> 357 | O17: =F17-N17 -> 2100 | P17: =VLOOKUP(B17,'114+840'!$B$15:$AB$115,14,FALSE) -> 100 | Q17: ='114+840'!R18 -> 0 | R17: =+Q17+R16 -> 0 | S17: =VLOOKUP(B17,'114+840'!$B$14:$AB$115,22,FALSE) -> -390 | T17: =VLOOKUP(B17,'114+840'!$B$15:$AB$115,6,FALSE) -> 847 | U17: =F17-T17 -> 1610 | V17: =VLOOKUP(B17,'114+840'!$B$15:$AB$115,15,FALSE) -> -390 | W17: ='114+840'!S18 -> 0 | X17: =+W17+X16 -> 0 | Y17: =S17-S16 -> 0 | Z17: =IF(Y17>0,Y17,0)/1000 -> 0 | AA17: =AA16+Z17 -> 0 | AB17: =(M17-$M$13-R17)/1000 -> 0
A18: =A17+1 -> 4 | B18: ='114+840'!B19 -> 45275 | C18: =B18-B17 -> 1 | D18: =D17 -> 842 | E18: =VLOOKUP(B18,'114+840'!B19:AB120,3,FALSE) -> 1613 | F18: =D18+E18 -> 2455 | G18: =VLOOKUP(B18,'114+840'!$B$15:$AB$115,20,FALSE) -> -80 | H18: =VLOOKUP(B18,'114+840'!$B$15:$AB$115,4,FALSE) -> 535 | I18: =F18-H18 -> 1920 | J18: =VLOOKUP(B18,'114+840'!$B$15:$AB$115,13,FALSE) -> -80 | K18: ='114+840'!Q19 -> 0 | L18: =+K18+L17 -> 0 | M18: =VLOOKUP(B18,'114+840'!$B$14:$AB$115,21,FALSE) -> 100 | N18: =VLOOKUP(B18,'114+840'!$B$15:$AB$115,5,FALSE) -> 355 | O18: =F18-N18 -> 2100 | P18: =VLOOKUP(B18,'114+840'!$B$15:$AB$115,14,FALSE) -> 100 | Q18: ='114+840'!R19 -> 0 | R18: =+Q18+R17 -> 0 | S18: =VLOOKUP(B18,'114+840'!$B$14:$AB$115,22,FALSE) -> -390 | T18: =VLOOKUP(B18,'114+840'!$B$15:$AB$115,6,FALSE) -> 845 | U18: =F18-T18 -> 1610 | V18: =VLOOKUP(B18,'114+840'!$B$15:$AB$115,15,FALSE) -> -390 | W18: ='114+840'!S19 -> 0 | X18: =+W18+X17 -> 0 | Y18: =S18-S17 -> 0 | Z18: =IF(Y18>0,Y18,0)/1000 -> 0 | AA18: =AA17+Z18 -> 0 | AB18: =(M18-$M$13-R18)/1000 -> 0
A19: =A18+1 -> 5 | B19: ='114+840'!B20 -> 45276 | C19: =B19-B18 -> 1 | D19: =D18 -> 842 | E19: =VLOOKUP(B19,'114+840'!B20:AB121,3,FALSE) -> 1611 | F19: =D19+E19 -> 2453 | G19: =VLOOKUP(B19,'114+840'!$B$15:$AB$115,20,FALSE) -> -80 | H19: =VLOOKUP(B19,'114+840'!$B$15:$AB$115,4,FALSE) -> 533 | I19: =F19-H19 -> 1920 | J19: =VLOOKUP(B19,'114+840'!$B$15:$AB$115,13,FALSE) -> -80 | K19: ='114+840'!Q20 -> 0 | L19: =+K19+L18 -> 0 | M19: =VLOOKUP(B19,'114+840'!$B$14:$AB$115,21,FALSE) -> 100 | N19: =VLOOKUP(B19,'114+840'!$B$15:$AB$115,5,FALSE) -> 353 | O19: =F19-N19 -> 2100 | P19: =VLOOKUP(B19,'114+840'!$B$15:$AB$115,14,FALSE) -> 100 | Q19: ='114+840'!R20 -> 0 | R19: =+Q19+R18 -> 0 | S19: =VLOOKUP(B19,'114+840'!$B$14:$AB$115,22,FALSE) -> -390 | T19: =VLOOKUP(B19,'114+840'!$B$15:$AB$115,6,FALSE) -> 843 | U19: =F19-T19 -> 1610 | V19: =VLOOKUP(B19,'114+840'!$B$15:$AB$115,15,FALSE) -> -390 | W19: ='114+840'!S20 -> 0 | X19: =+W19+X18 -> 0 | Y19: =S19-S18 -> 0 | Z19: =IF(Y19>0,Y19,0)/1000 -> 0 | AA19: =AA18+Z19 -> 0 | AB19: =(M19-$M$13-R19)/1000 -> 0
A20: =A19+1 -> 6 | B20: ='114+840'!B21 -> 45277 | C20: =B20-B19 -> 1 | D20: =D19 -> 842 | E20: =VLOOKUP(B20,'114+840'!B21:AB122,3,FALSE) -> 1609 | F20: =D20+E20 -> 2451 | G20: =VLOOKUP(B20,'114+840'!$B$15:$AB$115,20,FALSE) -> -80 | H20: =VLOOKUP(B20,'114+840'!$B$15:$AB$115,4,FALSE) -> 531 | I20: =F20-H20 -> 1920 | J20: =VLOOKUP(B20,'114+840'!$B$15:$AB$115,13,FALSE) -> -80 | K20: ='114+840'!Q21 -> 0 | L20: =+K20+L19 -> 0 | M20: =VLOOKUP(B20,'114+840'!$B$14:$AB$115,21,FALSE) -> 100 | N20: =VLOOKUP(B20,'114+840'!$B$15:$AB$115,5,FALSE) -> 351 | O20: =F20-N20 -> 2100 | P20: =VLOOKUP(B20,'114+840'!$B$15:$AB$115,14,FALSE) -> 100 | Q20: ='114+840'!R21 -> 0 | R20: =+Q20+R19 -> 0 | S20: =VLOOKUP(B20,'114+840'!$B$14:$AB$115,22,FALSE) -> -390 | T20: =VLOOKUP(B20,'114+840'!$B$15:$AB$115,6,FALSE) -> 841 | U20: =F20-T20 -> 1610 | V20: =VLOOKUP(B20,'114+840'!$B$15:$AB$115,15,FALSE) -> -390 | W20: ='114+840'!S21 -> 0 | X20: =+W20+X19 -> 0 | Y20: =S20-S19 -> 0 | Z20: =IF(Y20>0,Y20,0)/1000 -> 0 | AA20: =AA19+Z20 -> 0 | AB20: =(M20-$M$13-R20)/1000 -> 0
A21: =A20+1 -> 7 | B21: ='114+840'!B22 -> 45278 | C21: =B21-B20 -> 1 | D21: =D20 -> 842 | E21: =VLOOKUP(B21,'114+840'!B22:AB123,3,FALSE) -> 1607 | F21: =D21+E21 -> 2449 | G21: =VLOOKUP(B21,'114+840'!$B$15:$AB$115,20,FALSE) -> -80 | H21: =VLOOKUP(B21,'114+840'!$B$15:$AB$115,4,FALSE) -> 529 | I21: =F21-H21 -> 1920 | J21: =VLOOKUP(B21,'114+840'!$B$15:$AB$115,13,FALSE) -> -80 | K21: ='114+840'!Q22 -> 0 | L21: =+K21+L20 -> 0 | M21: =VLOOKUP(B21,'114+840'!$B$14:$AB$115,21,FALSE) -> 100 | N21: =VLOOKUP(B21,'114+840'!$B$15:$AB$115,5,FALSE) -> 349 | O21: =F21-N21 -> 2100 | P21: =VLOOKUP(B21,'114+840'!$B$15:$AB$115,14,FALSE) -> 100 | Q21: ='114+840'!R22 -> 0 | R21: =+Q21+R20 -> 0 | S21: =VLOOKUP(B21,'114+840'!$B$14:$AB$115,22,FALSE) -> -390 | T21: =VLOOKUP(B21,'114+840'!$B$15:$AB$115,6,FALSE) -> 839 | U21: =F21-T21 -> 1610 | V21: =VLOOKUP(B21,'114+840'!$B$15:$AB$115,15,FALSE) -> -390 | W21: ='114+840'!S22 -> 0 | X21: =+W21+X20 -> 0 | Y21: =S21-S20 -> 0 | Z21: =IF(Y21>0,Y21,0)/1000 -> 0 | AA21: =AA20+Z21 -> 0 | AB21: =(M21-$M$13-R21)/1000 -> 0
B22: ='114+840'!B23 -> 45279 | C22: =B22-B21 -> 1 | D22: =D21 -> 842 | E22: =VLOOKUP(B22,'114+840'!B23:AB124,3,FALSE) -> 1605 | F22: =D22+E22 -> 2447 | G22: =VLOOKUP(B22,'114+840'!$B$15:$AB$115,20,FALSE) -> -80 | H22: =VLOOKUP(B22,'114+840'!$B$15:$AB$115,4,FALSE) -> 527 | I22: =F22-H22 -> 1920 | J22: =VLOOKUP(B22,'114+840'!$B$15:$AB$115,13,FALSE) -> -80 | K22: ='114+840'!Q23 -> 0 | L22: =+K22+L21 -> 0 | M22: =VLOOKUP(B22,'114+840'!$B$14:$AB$115,21,FALSE) -> 100 | N22: =VLOOKUP(B22,'114+840'!$B$15:$AB$115,5,FALSE) -> 347 | O22: =F22-N22 -> 2100 | P22: =VLOOKUP(B22,'114+840'!$B$15:$AB$115,14,FALSE) -> 100 | Q22: ='114+840'!R23 -> 0 | R22: =+Q22+R21 -> 0 | S22: =VLOOKUP(B22,'114+840'!$B$14:$AB$115,22,FALSE) -> -390 | T22: =VLOOKUP(B22,'114+840'!$B$15:$AB$115,6,FALSE) -> 837 | U22: =F22-T22 -> 1610 | V22: =VLOOKUP(B22,'114+840'!$B$15:$AB$115,15,FALSE) -> -390 | W22: ='114+840'!S23 -> 0 | X22: =+W22+X21 -> 0 | Y22: =S22-S21 -> 0 | Z22: =IF(Y22>0,Y22,0)/1000 -> 0 | AA22: =AA21+Z22 -> 0 | AB22: =(M22-$M$13-R22)/1000 -> 0
B23: ='114+840'!B24 -> 45280 | C23: =B23-B22 -> 1 | D23: =D22 -> 842 | E23: =VLOOKUP(B23,'114+840'!B24:AB125,3,FALSE) -> 1603 | F23: =D23+E23 -> 2445 | G23: =VLOOKUP(B23,'114+840'!$B$15:$AB$115,20,FALSE) -> -80 | H23: =VLOOKUP(B23,'114+840'!$B$15:$AB$115,4,FALSE) -> 525 | I23: =F23-H23 -> 1920 | J23: =VLOOKUP(B23,'114+840'!$B$15:$AB$115,13,FALSE) -> -80 | K23: ='114+840'!Q24 -> 0 | L23: =+K23+L22 -> 0 | M23: =VLOOKUP(B23,'114+840'!$B$14:$AB$115,21,FALSE) -> 100 | N23: =VLOOKUP(B23,'114+840'!$B$15:$AB$115,5,FALSE) -> 345 | O23: =F23-N23 -> 2100 | P23: =VLOOKUP(B23,'114+840'!$B$15:$AB$115,14,FALSE) -> 100 | Q23: ='114+840'!R24 -> 0 | R23: =+Q23+R22 -> 0 | S23: =VLOOKUP(B23,'114+840'!$B$14:$AB$115,22,FALSE) -> -390 | T23: =VLOOKUP(B23,'114+840'!$B$15:$AB$115,6,FALSE) -> 835 | U23: =F23-T23 -> 1610 | V23: =VLOOKUP(B23,'114+840'!$B$15:$AB$115,15,FALSE) -> -390 | W23: ='114+840'!S24 -> 0 | X23: =+W23+X22 -> 0 | Y23: =S23-S22 -> 0 | Z23: =IF(Y23>0,Y23,0)/1000 -> 0 | AA23: =AA22+Z23 -> 0 | AB23: =(M23-$M$13-R23)/1000 -> 0
B24: ='114+840'!B25 -> 45281 | C24: =B24-B23 -> 1 | D24: =D23 -> 842 | E24: =VLOOKUP(B24,'114+840'!B25:AB126,3,FALSE) -> 1601 | F24: =D24+E24 -> 2443 | G24: =VLOOKUP(B24,'114+840'!$B$15:$AB$115,20,FALSE) -> -80 | H24: =VLOOKUP(B24,'114+840'!$B$15:$AB$115,4,FALSE) -> 523 | I24: =F24-H24 -> 1920 | J24: =VLOOKUP(B24,'114+840'!$B$15:$AB$115,13,FALSE) -> -80 | K24: ='114+840'!Q25 -> 0 | L24: =+K24+L23 -> 0 | M24: =VLOOKUP(B24,'114+840'!$B$14:$AB$115,21,FALSE) -> 100 | N24: =VLOOKUP(B24,'114+840'!$B$15:$AB$115,5,FALSE) -> 343 | O24: =F24-N24 -> 2100 | P24: =VLOOKUP(B24,'114+840'!$B$15:$AB$115,14,FALSE) -> 100 | Q24: ='114+840'!R25 -> 0 | R24: =+Q24+R23 -> 0 | S24: =VLOOKUP(B24,'114+840'!$B$14:$AB$115,22,FALSE) -> -390 | T24: =VLOOKUP(B24,'114+840'!$B$15:$AB$115,6,FALSE) -> 833 | U24: =F24-T24 -> 1610 | V24: =VLOOKUP(B24,'114+840'!$B$15:$AB$115,15,FALSE) -> -390 | W24: ='114+840'!S25 -> 0 | X24: =+W24+X23 -> 0 | Y24: =S24-S23 -> 0 | Z24: =IF(Y24>0,Y24,0)/1000 -> 0 | AA24: =AA23+Z24 -> 0 | AB24: =(M24-$M$13-R24)/1000 -> 0
B25: ='114+840'!B26 -> 45282 | C25: =B25-B24 -> 1 | D25: =D24 -> 842 | E25: =VLOOKUP(B25,'114+840'!B26:AB127,3,FALSE) -> 1599 | F25: =D25+E25 -> 2441 | G25: =VLOOKUP(B25,'114+840'!$B$15:$AB$115,20,FALSE) -> -80 | H25: =VLOOKUP(B25,'114+840'!$B$15:$AB$115,4,FALSE) -> 521 | I25: =F25-H25 -> 1920 | J25: =VLOOKUP(B25,'114+840'!$B$15:$AB$115,13,FALSE) -> -80 | K25: ='114+840'!Q26 -> 0 | L25: =+K25+L24 -> 0 | M25: =VLOOKUP(B25,'114+840'!$B$14:$AB$115,21,FALSE) -> 100 | N25: =VLOOKUP(B25,'114+840'!$B$15:$AB$115,5,FALSE) -> 341 | O25: =F25-N25 -> 2100 | P25: =VLOOKUP(B25,'114+840'!$B$15:$AB$115,14,FALSE) -> 100 | Q25: ='114+840'!R26 -> 0 | R25: =+Q25+R24 -> 0 | S25: =VLOOKUP(B25,'114+840'!$B$14:$AB$115,22,FALSE) -> -390 | T25: =VLOOKUP(B25,'114+840'!$B$15:$AB$115,6,FALSE) -> 831 | U25: =F25-T25 -> 1610 | V25: =VLOOKUP(B25,'114+840'!$B$15:$AB$115,15,FALSE) -> -390 | W25: ='114+840'!S26 -> 0 | X25: =+W25+X24 -> 0 | Y25: =S25-S24 -> 0 | Z25: =IF(Y25>0,Y25,0)/1000 -> 0 | AA25: =AA24+Z25 -> 0 | AB25: =(M25-$M$13-R25)/1000 -> 0
B26: ='114+840'!B27 -> 45283 | C26: =B26-B25 -> 1 | D26: =D25 -> 842 | E26: =VLOOKUP(B26,'114+840'!B27:AB128,3,FALSE) -> 1597 | F26: =D26+E26 -> 2439 | G26: =VLOOKUP(B26,'114+840'!$B$15:$AB$115,20,FALSE) -> -80 | H26: =VLOOKUP(B26,'114+840'!$B$15:$AB$115,4,FALSE) -> 519 | I26: =F26-H26 -> 1920 | J26: =VLOOKUP(B26,'114+840'!$B$15:$AB$115,13,FALSE) -> -80 | K26: ='114+840'!Q27 -> 0 | L26: =+K26+L25 -> 0 | M26: =VLOOKUP(B26,'114+840'!$B$14:$AB$115,21,FALSE) -> 100 | N26: =VLOOKUP(B26,'114+840'!$B$15:$AB$115,5,FALSE) -> 339 | O26: =F26-N26 -> 2100 | P26: =VLOOKUP(B26,'114+840'!$B$15:$AB$115,14,FALSE) -> 100 | Q26: ='114+840'!R27 -> 0 | R26: =+Q26+R25 -> 0 | S26: =VLOOKUP(B26,'114+840'!$B$14:$AB$115,22,FALSE) -> -390 | T26: =VLOOKUP(B26,'114+840'!$B$15:$AB$115,6,FALSE) -> 829 | U26: =F26-T26 -> 1610 | V26: =VLOOKUP(B26,'114+840'!$B$15:$AB$115,15,FALSE) -> -390 | W26: ='114+840'!S27 -> 0 | X26: =+W26+X25 -> 0 | Y26: =S26-S25 -> 0 | Z26: =IF(Y26>0,Y26,0)/1000 -> 0 | AA26: =AA25+Z26 -> 0 | AB26: =(M26-$M$13-R26)/1000 -> 0
B27: ='114+840'!B28 -> 45284 | C27: =B27-B26 -> 1 | D27: =D26 -> 842 | E27: =VLOOKUP(B27,'114+840'!B28:AB129,3,FALSE) -> 1595 | F27: =D27+E27 -> 2437 | G27: =VLOOKUP(B27,'114+840'!$B$15:$AB$115,20,FALSE) -> -80 | H27: =VLOOKUP(B27,'114+840'!$B$15:$AB$115,4,FALSE) -> 517 | I27: =F27-H27 -> 1920 | J27: =VLOOKUP(B27,'114+840'!$B$15:$AB$115,13,FALSE) -> -80 | K27: ='114+840'!Q28 -> 0 | L27: =+K27+L26 -> 0 | M27: =VLOOKUP(B27,'114+840'!$B$14:$AB$115,21,FALSE) -> 100 | N27: =VLOOKUP(B27,'114+840'!$B$15:$AB$115,5,FALSE) -> 337 | O27: =F27-N27 -> 2100 | P27: =VLOOKUP(B27,'114+840'!$B$15:$AB$115,14,FALSE) -> 100 | Q27: ='114+840'!R28 -> 0 | R27: =+Q27+R26 -> 0 | S27: =VLOOKUP(B27,'114+840'!$B$14:$AB$115,22,FALSE) -> -390 | T27: =VLOOKUP(B27,'114+840'!$B$15:$AB$115,6,FALSE) -> 827 | U27: =F27-T27 -> 1610 | V27: =VLOOKUP(B27,'114+840'!$B$15:$AB$115,15,FALSE) -> -390 | W27: ='114+840'!S28 -> 0 | X27: =+W27+X26 -> 0 | Y27: =S27-S26 -> 0 | Z27: =IF(Y27>0,Y27,0)/1000 -> 0 | AA27: =AA26+Z27 -> 0 | AB27: =(M27-$M$13-R27)/1000 -> 0
B28: ='114+840'!B29 -> 45285 | C28: =B28-B27 -> 1 | D28: =D27 -> 842 | E28: =VLOOKUP(B28,'114+840'!B29:AB130,3,FALSE) -> 1593 | F28: =D28+E28 -> 2435 | G28: =VLOOKUP(B28,'114+840'!$B$15:$AB$115,20,FALSE) -> -80 | H28: =VLOOKUP(B28,'114+840'!$B$15:$AB$115,4,FALSE) -> 515 | I28: =F28-H28 -> 1920 | J28: =VLOOKUP(B28,'114+840'!$B$15:$AB$115,13,FALSE) -> -80 | K28: ='114+840'!Q29 -> 0 | L28: =+K28+L27 -> 0 | M28: =VLOOKUP(B28,'114+840'!$B$14:$AB$115,21,FALSE) -> 100 | N28: =VLOOKUP(B28,'114+840'!$B$15:$AB$115,5,FALSE) -> 335 | O28: =F28-N28 -> 2100 | P28: =VLOOKUP(B28,'114+840'!$B$15:$AB$115,14,FALSE) -> 100 | Q28: ='114+840'!R29 -> 0 | R28: =+Q28+R27 -> 0 | S28: =VLOOKUP(B28,'114+840'!$B$14:$AB$115,22,FALSE) -> -390 | T28: =VLOOKUP(B28,'114+840'!$B$15:$AB$115,6,FALSE) -> 825 | U28: =F28-T28 -> 1610 | V28: =VLOOKUP(B28,'114+840'!$B$15:$AB$115,15,FALSE) -> -390 | W28: ='114+840'!S29 -> 0 | X28: =+W28+X27 -> 0 | Y28: =S28-S27 -> 0 | Z28: =IF(Y28>0,Y28,0)/1000 -> 0 | AA28: =AA27+Z28 -> 0 | AB28: =(M28-$M$13-R28)/1000 -> 0
B29: ='114+840'!B30 -> 45286 | C29: =B29-B28 -> 1 | D29: =D28 -> 842 | E29: =VLOOKUP(B29,'114+840'!B30:AB131,3,FALSE) -> 1591 | F29: =D29+E29 -> 2433 | G29: =VLOOKUP(B29,'114+840'!$B$15:$AB$115,20,FALSE) -> -80 | H29: =VLOOKUP(B29,'114+840'!$B$15:$AB$115,4,FALSE) -> 513 | I29: =F29-H29 -> 1920 | J29: =VLOOKUP(B29,'114+840'!$B$15:$AB$115,13,FALSE) -> -80 | K29: ='114+840'!Q30 -> 0 | L29: =+K29+L28 -> 0 | M29: =VLOOKUP(B29,'114+840'!$B$14:$AB$115,21,FALSE) -> 100 | N29: =VLOOKUP(B29,'114+840'!$B$15:$AB$115,5,FALSE) -> 333 | O29: =F29-N29 -> 2100 | P29: =VLOOKUP(B29,'114+840'!$B$15:$AB$115,14,FALSE) -> 100 | Q29: ='114+840'!R30 -> 0 | R29: =+Q29+R28 -> 0 | S29: =VLOOKUP(B29,'114+840'!$B$14:$AB$115,22,FALSE) -> -390 | T29: =VLOOKUP(B29,'114+840'!$B$15:$AB$115,6,FALSE) -> 823 | U29: =F29-T29 -> 1610 | V29: =VLOOKUP(B29,'114+840'!$B$15:$AB$115,15,FALSE) -> -390 | W29: ='114+840'!S30 -> 0 | X29: =+W29+X28 -> 0 | Y29: =S29-S28 -> 0 | Z29: =IF(Y29>0,Y29,0)/1000 -> 0 | AA29: =AA28+Z29 -> 0 | AB29: =(M29-$M$13-R29)/1000 -> 0
B30: ='114+840'!B31 -> 45287 | C30: =B30-B29 -> 1 | D30: =D29 -> 842 | E30: =VLOOKUP(B30,'114+840'!B31:AB132,3,FALSE) -> 1589 | F30: =D30+E30 -> 2431 | G30: =VLOOKUP(B30,'114+840'!$B$15:$AB$115,20,FALSE) -> -80 | H30: =VLOOKUP(B30,'114+840'!$B$15:$AB$115,4,FALSE) -> 511 | I30: =F30-H30 -> 1920 | J30: =VLOOKUP(B30,'114+840'!$B$15:$AB$115,13,FALSE) -> -80 | K30: ='114+840'!Q31 -> 0 | L30: =+K30+L29 -> 0 | M30: =VLOOKUP(B30,'114+840'!$B$14:$AB$115,21,FALSE) -> 100 | N30: =VLOOKUP(B30,'114+840'!$B$15:$AB$115,5,FALSE) -> 331 | O30: =F30-N30 -> 2100 | P30: =VLOOKUP(B30,'114+840'!$B$15:$AB$115,14,FALSE) -> 100 | Q30: ='114+840'!R31 -> 0 | R30: =+Q30+R29 -> 0 | S30: =VLOOKUP(B30,'114+840'!$B$14:$AB$115,22,FALSE) -> -108 | T30: =VLOOKUP(B30,'114+840'!$B$15:$AB$115,6,FALSE) -> 829 | U30: =F30-T30 -> 1602 | V30: =VLOOKUP(B30,'114+840'!$B$15:$AB$115,15,FALSE) -> -398 | W30: ='114+840'!S31 -> 8 | X30: =+W30+X29 -> 8 | Y30: =S30-S29 -> 282 | Z30: =IF(Y30>0,Y30,0)/1000 -> 0.282 | AA30: =AA29+Z30 -> 0.282 | AB30: =(M30-$M$13-R30)/1000 -> 0
B31: ='114+840'!B32 -> 45288 | C31: =B31-B30 -> 1 | D31: =D30 -> 842 | E31: =VLOOKUP(B31,'114+840'!B32:AB133,3,FALSE) -> 1587 | F31: =D31+E31 -> 2429 | G31: =VLOOKUP(B31,'114+840'!$B$15:$AB$115,20,FALSE) -> -80 | H31: =VLOOKUP(B31,'114+840'!$B$15:$AB$115,4,FALSE) -> 509 | I31: =F31-H31 -> 1920 | J31: =VLOOKUP(B31,'114+840'!$B$15:$AB$115,13,FALSE) -> -80 | K31: ='114+840'!Q32 -> 0 | L31: =+K31+L30 -> 0 | M31: =VLOOKUP(B31,'114+840'!$B$14:$AB$115,21,FALSE) -> 100 | N31: =VLOOKUP(B31,'114+840'!$B$15:$AB$115,5,FALSE) -> 329 | O31: =F31-N31 -> 2100 | P31: =VLOOKUP(B31,'114+840'!$B$15:$AB$115,14,FALSE) -> 100 | Q31: ='114+840'!R32 -> 0 | R31: =+Q31+R30 -> 0 | S31: =VLOOKUP(B31,'114+840'!$B$14:$AB$115,22,FALSE) -> -114 | T31: =VLOOKUP(B31,'114+840'!$B$15:$AB$115,6,FALSE) -> 833 | U31: =F31-T31 -> 1596 | V31: =VLOOKUP(B31,'114+840'!$B$15:$AB$115,15,FALSE) -> -404 | W31: ='114+840'!S32 -> 6 | X31: =+W31+X30 -> 14 | Y31: =S31-S30 -> -6 | Z31: =IF(Y31>0,Y31,0)/1000 -> 0 | AA31: =AA30+Z31 -> 0.282 | AB31: =(M31-$M$13-R31)/1000 -> 0
B32: ='114+840'!B33 -> 45289 | C32: =B32-B31 -> 1 | D32: =D31 -> 842 | E32: =VLOOKUP(B32,'114+840'!B33:AB134,3,FALSE) -> 1585 | F32: =D32+E32 -> 2427 | G32: =VLOOKUP(B32,'114+840'!$B$15:$AB$115,20,FALSE) -> -80 | H32: =VLOOKUP(B32,'114+840'!$B$15:$AB$115,4,FALSE) -> 507 | I32: =F32-H32 -> 1920 | J32: =VLOOKUP(B32,'114+840'!$B$15:$AB$115,13,FALSE) -> -80 | K32: ='114+840'!Q33 -> 0 | L32: =+K32+L31 -> 0 | M32: =VLOOKUP(B32,'114+840'!$B$14:$AB$115,21,FALSE) -> 100 | N32: =VLOOKUP(B32,'114+840'!$B$15:$AB$115,5,FALSE) -> 327 | O32: =F32-N32 -> 2100 | P32: =VLOOKUP(B32,'114+840'!$B$15:$AB$115,14,FALSE) -> 100 | Q32: ='114+840'!R33 -> 0 | R32: =+Q32+R31 -> 0 | S32: =VLOOKUP(B32,'114+840'!$B$14:$AB$115,22,FALSE) -> -120 | T32: =VLOOKUP(B32,'114+840'!$B$15:$AB$115,6,FALSE) -> 837 | U32: =F32-T32 -> 1590 | V32: =VLOOKUP(B32,'114+840'!$B$15:$AB$115,15,FALSE) -> -410 | W32: ='114+840'!S33 -> 6 | X32: =+W32+X31 -> 20 | Y32: =S32-S31 -> -6 | Z32: =IF(Y32>0,Y32,0)/1000 -> 0 | AA32: =AA31+Z32 -> 0.282 | AB32: =(M32-$M$13-R32)/1000 -> 0
B33: ='114+840'!B34 -> 45290 | C33: =B33-B32 -> 1 | D33: =D32 -> 842 | E33: =VLOOKUP(B33,'114+840'!B34:AB135,3,FALSE) -> 1583 | F33: =D33+E33 -> 2425 | G33: =VLOOKUP(B33,'114+840'!$B$15:$AB$115,20,FALSE) -> -80 | H33: =VLOOKUP(B33,'114+840'!$B$15:$AB$115,4,FALSE) -> 505 | I33: =F33-H33 -> 1920 | J33: =VLOOKUP(B33,'114+840'!$B$15:$AB$115,13,FALSE) -> -80 | K33: ='114+840'!Q34 -> 0 | L33: =+K33+L32 -> 0 | M33: =VLOOKUP(B33,'114+840'!$B$14:$AB$115,21,FALSE) -> 100 | N33: =VLOOKUP(B33,'114+840'!$B$15:$AB$115,5,FALSE) -> 325 | O33: =F33-N33 -> 2100 | P33: =VLOOKUP(B33,'114+840'!$B$15:$AB$115,14,FALSE) -> 100 | Q33: ='114+840'!R34 -> 0 | R33: =+Q33+R32 -> 0 | S33: =VLOOKUP(B33,'114+840'!$B$14:$AB$115,22,FALSE) -> -126 | T33: =VLOOKUP(B33,'114+840'!$B$15:$AB$115,6,FALSE) -> 841 | U33: =F33-T33 -> 1584 | V33: =VLOOKUP(B33,'114+840'!$B$15:$AB$115,15,FALSE) -> -416 | W33: ='114+840'!S34 -> 6 | X33: =+W33+X32 -> 26 | Y33: =S33-S32 -> -6 | Z33: =IF(Y33>0,Y33,0)/1000 -> 0 | AA33: =AA32+Z33 -> 0.282 | AB33: =(M33-$M$13-R33)/1000 -> 0
... B76: ='114+840'!B77 -> 45333 | C76: =B76-B75 -> 1 | D76: =D75 -> 842 | E76: =VLOOKUP(B76,'114+840'!B77:AB178,3,FALSE) -> 1497 | F76: =D76+E76 -> 2339 | G76: =VLOOKUP(B76,'114+840'!$B$15:$AB$115,20,FALSE) -> 916 | H76: =VLOOKUP(B76,'114+840'!$B$15:$AB$115,4,FALSE) -> 603 | I76: =F76-H76 -> 1736 | J76: =VLOOKUP(B76,'114+840'!$B$15:$AB$115,13,FALSE) -> -264 | K76: ='114+840'!Q77 -> 4 | L76: =+K76+L75 -> 184 | M76: =VLOOKUP(B76,'114+840'!$B$14:$AB$115,21,FALSE) -> 883 | N76: =VLOOKUP(B76,'114+840'!$B$15:$AB$115,5,FALSE) -> 456 | O76: =F76-N76 -> 1883 | P76: =VLOOKUP(B76,'114+840'!$B$15:$AB$115,14,FALSE) -> -117 | Q76: ='114+840'!R77 -> 4 | R76: =+Q76+R75 -> 217 | S76: =VLOOKUP(B76,'114+840'!$B$14:$AB$115,22,FALSE) -> 918 | T76: =VLOOKUP(B76,'114+840'!$B$15:$AB$115,6,FALSE) -> 911 | U76: =F76-T76 -> 1428 | V76: =VLOOKUP(B76,'114+840'!$B$15:$AB$115,15,FALSE) -> -572 | W76: ='114+840'!S77 -> 0 | X76: =+W76+X75 -> 182 | Y76: =S76-S75 -> 0 | Z76: =IF(Y76>0,Y76,0)/1000 -> 0 | AA76: =AA75+Z76 -> 1.449 | AB76: =(M76-$M$13-R76)/1000 -> 0.566
A77: 42307 | B77: ='114+840'!B78 -> 45334 | C77: =B77-B76 -> 1 | D77: =D76 -> 842 | E77: =VLOOKUP(B77,'114+840'!B78:AB179,3,FALSE) -> 1495 | F77: =D77+E77 -> 2337 | G77: =VLOOKUP(B77,'114+840'!$B$15:$AB$115,20,FALSE) -> 914 | H77: =VLOOKUP(B77,'114+840'!$B$15:$AB$115,4,FALSE) -> 603 | I77: =F77-H77 -> 1734 | J77: =VLOOKUP(B77,'114+840'!$B$15:$AB$115,13,FALSE) -> -266 | K77: ='114+840'!Q78 -> 2 | L77: =+K77+L76 -> 186 | M77: =VLOOKUP(B77,'114+840'!$B$14:$AB$115,21,FALSE) -> 876 | N77: =VLOOKUP(B77,'114+840'!$B$15:$AB$115,5,FALSE) -> 461 | O77: =F77-N77 -> 1876 | P77: =VLOOKUP(B77,'114+840'!$B$15:$AB$115,14,FALSE) -> -124 | Q77: ='114+840'!R78 -> 7 | R77: =+Q77+R76 -> 224 | S77: =VLOOKUP(B77,'114+840'!$B$14:$AB$115,22,FALSE) -> 918 | T77: =VLOOKUP(B77,'114+840'!$B$15:$AB$115,6,FALSE) -> 909 | U77: =F77-T77 -> 1428 | V77: =VLOOKUP(B77,'114+840'!$B$15:$AB$115,15,FALSE) -> -572 | W77: ='114+840'!S78 -> 0 | X77: =+W77+X76 -> 182 | Y77: =S77-S76 -> 0 | Z77: =IF(Y77>0,Y77,0)/1000 -> 0 | AA77: =AA76+Z77 -> 1.449 | AB77: =(M77-$M$13-R77)/1000 -> 0.552
A78: 02/11/015 | B78: ='114+840'!B79 -> 45335 | C78: =B78-B77 -> 1 | D78: =D77 -> 842 | E78: =VLOOKUP(B78,'114+840'!B79:AB180,3,FALSE) -> 1493 | F78: =D78+E78 -> 2335 | G78: =VLOOKUP(B78,'114+840'!$B$15:$AB$115,20,FALSE) -> 910 | H78: =VLOOKUP(B78,'114+840'!$B$15:$AB$115,4,FALSE) -> 605 | I78: =F78-H78 -> 1730 | J78: =VLOOKUP(B78,'114+840'!$B$15:$AB$115,13,FALSE) -> -270 | K78: ='114+840'!Q79 -> 4 | L78: =+K78+L77 -> 190 | M78: =VLOOKUP(B78,'114+840'!$B$14:$AB$115,21,FALSE) -> 871 | N78: =VLOOKUP(B78,'114+840'!$B$15:$AB$115,5,FALSE) -> 464 | O78: =F78-N78 -> 1871 | P78: =VLOOKUP(B78,'114+840'!$B$15:$AB$115,14,FALSE) -> -129 | Q78: ='114+840'!R79 -> 5 | R78: =+Q78+R77 -> 229 | S78: =VLOOKUP(B78,'114+840'!$B$14:$AB$115,22,FALSE) -> 917 | T78: =VLOOKUP(B78,'114+840'!$B$15:$AB$115,6,FALSE) -> 908 | U78: =F78-T78 -> 1427 | V78: =VLOOKUP(B78,'114+840'!$B$15:$AB$115,15,FALSE) -> -573 | W78: ='114+840'!S79 -> 1 | X78: =+W78+X77 -> 183 | Y78: =S78-S77 -> -1 | Z78: =IF(Y78>0,Y78,0)/1000 -> 0 | AA78: =AA77+Z78 -> 1.449 | AB78: =(M78-$M$13-R78)/1000 -> 0.542
A79: 42313 | B79: ='114+840'!B80 -> 45336 | C79: =B79-B78 -> 1 | D79: =D78 -> 842 | E79: =VLOOKUP(B79,'114+840'!B80:AB181,3,FALSE) -> 1491 | F79: =D79+E79 -> 2333 | G79: =VLOOKUP(B79,'114+840'!$B$15:$AB$115,20,FALSE) -> 908 | H79: =VLOOKUP(B79,'114+840'!$B$15:$AB$115,4,FALSE) -> 605 | I79: =F79-H79 -> 1728 | J79: =VLOOKUP(B79,'114+840'!$B$15:$AB$115,13,FALSE) -> -272 | K79: ='114+840'!Q80 -> 2 | L79: =+K79+L78 -> 192 | M79: =VLOOKUP(B79,'114+840'!$B$14:$AB$115,21,FALSE) -> 867 | N79: =VLOOKUP(B79,'114+840'!$B$15:$AB$115,5,FALSE) -> 466 | O79: =F79-N79 -> 1867 | P79: =VLOOKUP(B79,'114+840'!$B$15:$AB$115,14,FALSE) -> -133 | Q79: ='114+840'!R80 -> 4 | R79: =+Q79+R78 -> 233 | S79: =VLOOKUP(B79,'114+840'!$B$14:$AB$115,22,FALSE) -> 917 | T79: =VLOOKUP(B79,'114+840'!$B$15:$AB$115,6,FALSE) -> 906 | U79: =F79-T79 -> 1427 | V79: =VLOOKUP(B79,'114+840'!$B$15:$AB$115,15,FALSE) -> -573 | W79: ='114+840'!S80 -> 0 | X79: =+W79+X78 -> 183 | Y79: =S79-S78 -> 0 | Z79: =IF(Y79>0,Y79,0)/1000 -> 0 | AA79: =AA78+Z79 -> 1.449 | AB79: =(M79-$M$13-R79)/1000 -> 0.534
A80: 42319 | B80: ='114+840'!B81 -> 45337 | C80: =B80-B79 -> 1 | D80: =D79 -> 842 | E80: =VLOOKUP(B80,'114+840'!B81:AB182,3,FALSE) -> 1489 | F80: =D80+E80 -> 2331 | G80: =VLOOKUP(B80,'114+840'!$B$15:$AB$115,20,FALSE) -> 904 | H80: =VLOOKUP(B80,'114+840'!$B$15:$AB$115,4,FALSE) -> 607 | I80: =F80-H80 -> 1724 | J80: =VLOOKUP(B80,'114+840'!$B$15:$AB$115,13,FALSE) -> -276 | K80: ='114+840'!Q81 -> 4 | L80: =+K80+L79 -> 196 | M80: =VLOOKUP(B80,'114+840'!$B$14:$AB$115,21,FALSE) -> 859 | N80: =VLOOKUP(B80,'114+840'!$B$15:$AB$115,5,FALSE) -> 472 | O80: =F80-N80 -> 1859 | P80: =VLOOKUP(B80,'114+840'!$B$15:$AB$115,14,FALSE) -> -141 | Q80: ='114+840'!R81 -> 8 | R80: =+Q80+R79 -> 241 | S80: =VLOOKUP(B80,'114+840'!$B$14:$AB$115,22,FALSE) -> 917 | T80: =VLOOKUP(B80,'114+840'!$B$15:$AB$115,6,FALSE) -> 904 | U80: =F80-T80 -> 1427 | V80: =VLOOKUP(B80,'114+840'!$B$15:$AB$115,15,FALSE) -> -573 | W80: ='114+840'!S81 -> 0 | X80: =+W80+X79 -> 183 | Y80: =S80-S79 -> 0 | Z80: =IF(Y80>0,Y80,0)/1000 -> 0 | AA80: =AA79+Z80 -> 1.449 | AB80: =(M80-$M$13-R80)/1000 -> 0.518
A81: 42322 | B81: ='114+840'!B82 -> 45338 | C81: =B81-B80 -> 1 | D81: =D80 -> 842 | E81: =VLOOKUP(B81,'114+840'!B82:AB183,3,FALSE) -> 1487 | F81: =D81+E81 -> 2329 | G81: =VLOOKUP(B81,'114+840'!$B$15:$AB$115,20,FALSE) -> 904 | H81: =VLOOKUP(B81,'114+840'!$B$15:$AB$115,4,FALSE) -> 605 | I81: =F81-H81 -> 1724 | J81: =VLOOKUP(B81,'114+840'!$B$15:$AB$115,13,FALSE) -> -276 | K81: ='114+840'!Q82 -> 0 | L81: =+K81+L80 -> 196 | M81: =VLOOKUP(B81,'114+840'!$B$14:$AB$115,21,FALSE) -> 857 | N81: =VLOOKUP(B81,'114+840'!$B$15:$AB$115,5,FALSE) -> 472 | O81: =F81-N81 -> 1857 | P81: =VLOOKUP(B81,'114+840'!$B$15:$AB$115,14,FALSE) -> -143 | Q81: ='114+840'!R82 -> 2 | R81: =+Q81+R80 -> 243 | S81: =VLOOKUP(B81,'114+840'!$B$14:$AB$115,22,FALSE) -> 917 | T81: =VLOOKUP(B81,'114+840'!$B$15:$AB$115,6,FALSE) -> 902 | U81: =F81-T81 -> 1427 | V81: =VLOOKUP(B81,'114+840'!$B$15:$AB$115,15,FALSE) -> -573 | W81: ='114+840'!S82 -> 0 | X81: =+W81+X80 -> 183 | Y81: =S81-S80 -> 0 | Z81: =IF(Y81>0,Y81,0)/1000 -> 0 | AA81: =AA80+Z81 -> 1.449 | AB81: =(M81-$M$13-R81)/1000 -> 0.514
A82: 17/11/015 | B82: ='114+840'!B83 -> 45339 | C82: =B82-B81 -> 1 | D82: =D81 -> 842 | E82: =VLOOKUP(B82,'114+840'!B83:AB184,3,FALSE) -> 1485 | F82: =D82+E82 -> 2327 | G82: =VLOOKUP(B82,'114+840'!$B$15:$AB$115,20,FALSE) -> 904 | H82: =VLOOKUP(B82,'114+840'!$B$15:$AB$115,4,FALSE) -> 603 | I82: =F82-H82 -> 1724 | J82: =VLOOKUP(B82,'114+840'!$B$15:$AB$115,13,FALSE) -> -276 | K82: ='114+840'!Q83 -> 0 | L82: =+K82+L81 -> 196 | M82: =VLOOKUP(B82,'114+840'!$B$14:$AB$115,21,FALSE) -> 853 | N82: =VLOOKUP(B82,'114+840'!$B$15:$AB$115,5,FALSE) -> 474 | O82: =F82-N82 -> 1853 | P82: =VLOOKUP(B82,'114+840'!$B$15:$AB$115,14,FALSE) -> -147 | Q82: ='114+840'!R83 -> 4 | R82: =+Q82+R81 -> 247 | S82: =VLOOKUP(B82,'114+840'!$B$14:$AB$115,22,FALSE) -> 917 | T82: =VLOOKUP(B82,'114+840'!$B$15:$AB$115,6,FALSE) -> 900 | U82: =F82-T82 -> 1427 | V82: =VLOOKUP(B82,'114+840'!$B$15:$AB$115,15,FALSE) -> -573 | W82: ='114+840'!S83 -> 0 | X82: =+W82+X81 -> 183 | Y82: =S82-S81 -> 0 | Z82: =IF(Y82>0,Y82,0)/1000 -> 0 | AA82: =AA81+Z82 -> 1.449 | AB82: =(M82-$M$13-R82)/1000 -> 0.506
A83: 42328 | B83: ='114+840'!B84 -> 45340 | C83: =B83-B82 -> 1 | D83: =D82 -> 842 | E83: =VLOOKUP(B83,'114+840'!B84:AB185,3,FALSE) -> 1483 | F83: =D83+E83 -> 2325 | G83: =VLOOKUP(B83,'114+840'!$B$15:$AB$115,20,FALSE) -> 904 | H83: =VLOOKUP(B83,'114+840'!$B$15:$AB$115,4,FALSE) -> 601 | I83: =F83-H83 -> 1724 | J83: =VLOOKUP(B83,'114+840'!$B$15:$AB$115,13,FALSE) -> -276 | K83: ='114+840'!Q84 -> 0 | L83: =+K83+L82 -> 196 | M83: =VLOOKUP(B83,'114+840'!$B$14:$AB$115,21,FALSE) -> 846 | N83: =VLOOKUP(B83,'114+840'!$B$15:$AB$115,5,FALSE) -> 479 | O83: =F83-N83 -> 1846 | P83: =VLOOKUP(B83,'114+840'!$B$15:$AB$115,14,FALSE) -> -154 | Q83: ='114+840'!R84 -> 7 | R83: =+Q83+R82 -> 254 | S83: =VLOOKUP(B83,'114+840'!$B$14:$AB$115,22,FALSE) -> 917 | T83: =VLOOKUP(B83,'114+840'!$B$15:$AB$115,6,FALSE) -> 898 | U83: =F83-T83 -> 1427 | V83: =VLOOKUP(B83,'114+840'!$B$15:$AB$115,15,FALSE) -> -573 | W83: ='114+840'!S84 -> 0 | X83: =+W83+X82 -> 183 | Y83: =S83-S82 -> 0 | Z83: =IF(Y83>0,Y83,0)/1000 -> 0 | AA83: =AA82+Z83 -> 1.449 | AB83: =(M83-$M$13-R83)/1000 -> 0.492
...

Sheet SL.114+840
A1: DỰ ÁN THÀNH PHẦN ĐOẠN HẬU GIANG - CÀ MAU
A2: THUỘC DỰ ÁN XÂY DỰNG CÔNG TRÌNH ĐƯỜNG BỘ CAO TỐC BẮC - NAM PHÍA ĐÔNG GIAI ĐOẠN 2021 - 2025
A3: =UPPER("GÓI THẦU XL03 :Thi Công Xây Dựng Đoạn Tuyến Km114+200 - Km126+223 Bao Gồm Tuyến Nối Nút Giao IC12 Với QL1 (bao gồm khảo sát, thiết kế BVTC)") -> GÓI THẦU XL03 :THI CÔNG XÂY DỰNG ĐOẠN TUYẾN KM114+200 - KM126+223 BAO GỒM TUYẾN NỐI NÚT GIAO IC12 VỚI QL1 (BAO GỒM KHẢO SÁT, THIẾT KẾ BVTC)
A4: CHỦ ĐẦU TƯ | F4: TƯ VẤN GIÁM SÁT | K4: NHÀ THẦU
A5: BAN QUẢN LÝ DỰ ÁN MỸ THUẬN | F5: =UPPER("Liên danh Phân viện KHCN GTVT phía Nam - Công ty Cổ phần Tư vấn kỹ thuật và xây dựng Hồng Hà") -> LIÊN DANH PHÂN VIỆN KHCN GTVT PHÍA NAM - CÔNG TY CỔ PHẦN TƯ VẤN KỸ THUẬT VÀ XÂY DỰNG HỒNG HÀ | K5: LIÊN DANH CC1 - HẢI ĐĂNG - VẠN CƯỜNG - 492 - BẮC TRUNG NAM
A6: BIỂU GHI ĐO QUAN TRẮC LÚN
A7: Người lập: | B7: ='[4]BC.95+020'!C7 -> 0 | K7: Tên mốc: | M7: ='[4]BC.95+020'!N7 -> 0
A8: Thời tiết: | B8: ='[4]BC.95+020'!C8 -> năng | K8: Cao độ mốc: | M8: ='114+840'!M9 -> 842
A9: Lý trình: | B9: ='114+840'!C10 -> Km114+840 | K9: Ngày đặt bàn: | M9: ='114+840'!M10 -> 45270
A11: BÀN QUAN TRẮC: KM114+840
A12: Ngày đo | B12: Số ngày | C12: Cao độ đắp(m) | D12: Chiều cao nền đắp (m) | E12: chiều dày đắp(m) | F12: Trái | H12: Giữa | J12: Phải | L12: Độ lún (trái) (mm) | M12: Độ lún (giữa) (mm) | N12: Độ lún (phải) (mm) | O12: Ghi chú
F13: Cao độ quan trắc | G13: Cao độ bàn đo lún | H13: Cao độ quan trắc | I13: Cao độ bàn đo lún | J13: Cao độ quan trắc | K13: Cao độ bàn đo lún
A14: ='BC.114+840'!B13 -> 45270 | B14: 0 | C14: ='BC.114+840'!M13/1000 -> 0.1 | D14: ='BC.114+840'!AA13 -> 0 | E14: ='BC.114+840'!AB13 -> 0 | F14: =VLOOKUP($A14,'BC.114+840'!$B$13:$X$470,8,0)/1000 -> 1.92 | G14: =VLOOKUP($A14,'BC.114+840'!$B$13:$X$470,9,0)/1000 -> -0.08 | H14: =VLOOKUP($A14,'BC.114+840'!$B$13:$X$470,14,0)/1000 -> 2.1 | I14: =VLOOKUP($A14,'BC.114+840'!$B$13:$X$470,15,0)/1000 -> 0.1 | J14: =VLOOKUP($A14,'BC.114+840'!$B$13:$X$470,20,0)/1000 -> 1.61 | K14: =VLOOKUP($A14,'BC.114+840'!$B$13:$X$470,21,0)/1000 -> -0.39 | L14: =(G14-$G$14)*1000 -> 0 | M14: =(I14-$I$14)*1000 -> 0 | N14: 0
A15: ='BC.114+840'!B14 -> 45271 | B15: 1 | C15: ='BC.114+840'!M14/1000 -> 0.1 | D15: ='BC.114+840'!AA14 -> 0 | E15: ='BC.114+840'!AB14 -> 0 | F15: =VLOOKUP($A15,'BC.114+840'!$B$13:$X$470,8,0)/1000 -> 1.92 | G15: =VLOOKUP($A15,'BC.114+840'!$B$13:$X$470,9,0)/1000 -> -0.08 | H15: =VLOOKUP($A15,'BC.114+840'!$B$13:$X$470,14,0)/1000 -> 2.1 | I15: =VLOOKUP($A15,'BC.114+840'!$B$13:$X$470,15,0)/1000 -> 0.1 | J15: =VLOOKUP($A15,'BC.114+840'!$B$13:$X$470,20,0)/1000 -> 1.61 | K15: =VLOOKUP($A15,'BC.114+840'!$B$13:$X$470,21,0)/1000 -> -0.39 | L15: =(G15-$G$14)*1000 -> 0 | M15: =(I15-$I$14)*1000 -> 0 | N15: =(K15-$K$14)*1000 -> 0
A16: ='BC.114+840'!B15 -> 45272 | B16: 2 | C16: ='BC.114+840'!M15/1000 -> 0.1 | D16: ='BC.114+840'!AA15 -> 0 | E16: ='BC.114+840'!AB15 -> 0 | F16: =VLOOKUP($A16,'BC.114+840'!$B$13:$X$470,8,0)/1000 -> 1.92 | G16: =VLOOKUP($A16,'BC.114+840'!$B$13:$X$470,9,0)/1000 -> -0.08 | H16: =VLOOKUP($A16,'BC.114+840'!$B$13:$X$470,14,0)/1000 -> 2.1 | I16: =VLOOKUP($A16,'BC.114+840'!$B$13:$X$470,15,0)/1000 -> 0.1 | J16: =VLOOKUP($A16,'BC.114+840'!$B$13:$X$470,20,0)/1000 -> 1.61 | K16: =VLOOKUP($A16,'BC.114+840'!$B$13:$X$470,21,0)/1000 -> -0.39 | L16: =(G16-$G$14)*1000 -> 0 | M16: =(I16-$I$14)*1000 -> 0 | N16: =(K16-$K$14)*1000 -> 0
A17: ='BC.114+840'!B16 -> 45273 | B17: 3 | C17: ='BC.114+840'!M16/1000 -> 0.1 | D17: ='BC.114+840'!AA16 -> 0 | E17: ='BC.114+840'!AB16 -> 0 | F17: =VLOOKUP($A17,'BC.114+840'!$B$13:$X$470,8,0)/1000 -> 1.92 | G17: =VLOOKUP($A17,'BC.114+840'!$B$13:$X$470,9,0)/1000 -> -0.08 | H17: =VLOOKUP($A17,'BC.114+840'!$B$13:$X$470,14,0)/1000 -> 2.1 | I17: =VLOOKUP($A17,'BC.114+840'!$B$13:$X$470,15,0)/1000 -> 0.1 | J17: =VLOOKUP($A17,'BC.114+840'!$B$13:$X$470,20,0)/1000 -> 1.61 | K17: =VLOOKUP($A17,'BC.114+840'!$B$13:$X$470,21,0)/1000 -> -0.39 | L17: =(G17-$G$14)*1000 -> 0 | M17: =(I17-$I$14)*1000 -> 0 | N17: =(K17-$K$14)*1000 -> 0
A18: ='BC.114+840'!B17 -> 45274 | B18: 4 | C18: ='BC.114+840'!M17/1000 -> 0.1 | D18: ='BC.114+840'!AA17 -> 0 | E18: ='BC.114+840'!AB17 -> 0 | F18: =VLOOKUP($A18,'BC.114+840'!$B$13:$X$470,8,0)/1000 -> 1.92 | G18: =VLOOKUP($A18,'BC.114+840'!$B$13:$X$470,9,0)/1000 -> -0.08 | H18: =VLOOKUP($A18,'BC.114+840'!$B$13:$X$470,14,0)/1000 -> 2.1 | I18: =VLOOKUP($A18,'BC.114+840'!$B$13:$X$470,15,0)/1000 -> 0.1 | J18: =VLOOKUP($A18,'BC.114+840'!$B$13:$X$470,20,0)/1000 -> 1.61 | K18: =VLOOKUP($A18,'BC.114+840'!$B$13:$X$470,21,0)/1000 -> -0.39 | L18: =(G18-$G$14)*1000 -> 0 | M18: =(I18-$I$14)*1000 -> 0 | N18: =(K18-$K$14)*1000 -> 0
A19: ='BC.114+840'!B18 -> 45275 | B19: 5 | C19: ='BC.114+840'!M18/1000 -> 0.1 | D19: ='BC.114+840'!AA18 -> 0 | E19: ='BC.114+840'!AB18 -> 0 | F19: =VLOOKUP($A19,'BC.114+840'!$B$13:$X$470,8,0)/1000 -> 1.92 | G19: =VLOOKUP($A19,'BC.114+840'!$B$13:$X$470,9,0)/1000 -> -0.08 | H19: =VLOOKUP($A19,'BC.114+840'!$B$13:$X$470,14,0)/1000 -> 2.1 | I19: =VLOOKUP($A19,'BC.114+840'!$B$13:$X$470,15,0)/1000 -> 0.1 | J19: =VLOOKUP($A19,'BC.114+840'!$B$13:$X$470,20,0)/1000 -> 1.61 | K19: =VLOOKUP($A19,'BC.114+840'!$B$13:$X$470,21,0)/1000 -> -0.39 | L19: =(G19-$G$14)*1000 -> 0 | M19: =(I19-$I$14)*1000 -> 0 | N19: =(K19-$K$14)*1000 -> 0
A20: ='BC.114+840'!B19 -> 45276 | B20: 6 | C20: ='BC.114+840'!M19/1000 -> 0.1 | D20: ='BC.114+840'!AA19 -> 0 | E20: ='BC.114+840'!AB19 -> 0 | F20: =VLOOKUP($A20,'BC.114+840'!$B$13:$X$470,8,0)/1000 -> 1.92 | G20: =VLOOKUP($A20,'BC.114+840'!$B$13:$X$470,9,0)/1000 -> -0.08 | H20: =VLOOKUP($A20,'BC.114+840'!$B$13:$X$470,14,0)/1000 -> 2.1 | I20: =VLOOKUP($A20,'BC.114+840'!$B$13:$X$470,15,0)/1000 -> 0.1 | J20: =VLOOKUP($A20,'BC.114+840'!$B$13:$X$470,20,0)/1000 -> 1.61 | K20: =VLOOKUP($A20,'BC.114+840'!$B$13:$X$470,21,0)/1000 -> -0.39 | L20: =(G20-$G$14)*1000 -> 0 | M20: =(I20-$I$14)*1000 -> 0 | N20: =(K20-$K$14)*1000 -> 0
A21: ='BC.114+840'!B20 -> 45277 | B21: 7 | C21: ='BC.114+840'!M20/1000 -> 0.1 | D21: ='BC.114+840'!AA20 -> 0 | E21: ='BC.114+840'!AB20 -> 0 | F21: =VLOOKUP($A21,'BC.114+840'!$B$13:$X$470,8,0)/1000 -> 1.92 | G21: =VLOOKUP($A21,'BC.114+840'!$B$13:$X$470,9,0)/1000 -> -0.08 | H21: =VLOOKUP($A21,'BC.114+840'!$B$13:$X$470,14,0)/1000 -> 2.1 | I21: =VLOOKUP($A21,'BC.114+840'!$B$13:$X$470,15,0)/1000 -> 0.1 | J21: =VLOOKUP($A21,'BC.114+840'!$B$13:$X$470,20,0)/1000 -> 1.61 | K21: =VLOOKUP($A21,'BC.114+840'!$B$13:$X$470,21,0)/1000 -> -0.39 | L21: =(G21-$G$14)*1000 -> 0 | M21: =(I21-$I$14)*1000 -> 0 | N21: =(K21-$K$14)*1000 -> 0
A22: ='BC.114+840'!B21 -> 45278 | B22: 8 | C22: ='BC.114+840'!M21/1000 -> 0.1 | D22: ='BC.114+840'!AA21 -> 0 | E22: ='BC.114+840'!AB21 -> 0 | F22: =VLOOKUP($A22,'BC.114+840'!$B$13:$X$470,8,0)/1000 -> 1.92 | G22: =VLOOKUP($A22,'BC.114+840'!$B$13:$X$470,9,0)/1000 -> -0.08 | H22: =VLOOKUP($A22,'BC.114+840'!$B$13:$X$470,14,0)/1000 -> 2.1 | I22: =VLOOKUP($A22,'BC.114+840'!$B$13:$X$470,15,0)/1000 -> 0.1 | J22: =VLOOKUP($A22,'BC.114+840'!$B$13:$X$470,20,0)/1000 -> 1.61 | K22: =VLOOKUP($A22,'BC.114+840'!$B$13:$X$470,21,0)/1000 -> -0.39 | L22: =(G22-$G$14)*1000 -> 0 | M22: =(I22-$I$14)*1000 -> 0 | N22: =(K22-$K$14)*1000 -> 0
A23: ='BC.114+840'!B22 -> 45279 | B23: 9 | C23: ='BC.114+840'!M22/1000 -> 0.1 | D23: ='BC.114+840'!AA22 -> 0 | E23: ='BC.114+840'!AB22 -> 0 | F23: =VLOOKUP($A23,'BC.114+840'!$B$13:$X$470,8,0)/1000 -> 1.92 | G23: =VLOOKUP($A23,'BC.114+840'!$B$13:$X$470,9,0)/1000 -> -0.08 | H23: =VLOOKUP($A23,'BC.114+840'!$B$13:$X$470,14,0)/1000 -> 2.1 | I23: =VLOOKUP($A23,'BC.114+840'!$B$13:$X$470,15,0)/1000 -> 0.1 | J23: =VLOOKUP($A23,'BC.114+840'!$B$13:$X$470,20,0)/1000 -> 1.61 | K23: =VLOOKUP($A23,'BC.114+840'!$B$13:$X$470,21,0)/1000 -> -0.39 | L23: =(G23-$G$14)*1000 -> 0 | M23: =(I23-$I$14)*1000 -> 0 | N23: =(K23-$K$14)*1000 -> 0
A24: ='BC.114+840'!B23 -> 45280 | B24: 10 | C24: ='BC.114+840'!M23/1000 -> 0.1 | D24: ='BC.114+840'!AA23 -> 0 | E24: ='BC.114+840'!AB23 -> 0 | F24: =VLOOKUP($A24,'BC.114+840'!$B$13:$X$470,8,0)/1000 -> 1.92 | G24: =VLOOKUP($A24,'BC.114+840'!$B$13:$X$470,9,0)/1000 -> -0.08 | H24: =VLOOKUP($A24,'BC.114+840'!$B$13:$X$470,14,0)/1000 -> 2.1 | I24: =VLOOKUP($A24,'BC.114+840'!$B$13:$X$470,15,0)/1000 -> 0.1 | J24: =VLOOKUP($A24,'BC.114+840'!$B$13:$X$470,20,0)/1000 -> 1.61 | K24: =VLOOKUP($A24,'BC.114+840'!$B$13:$X$470,21,0)/1000 -> -0.39 | L24: =(G24-$G$14)*1000 -> 0 | M24: =(I24-$I$14)*1000 -> 0 | N24: =(K24-$K$14)*1000 -> 0
A25: ='BC.114+840'!B24 -> 45281 | B25: 11 | C25: ='BC.114+840'!M24/1000 -> 0.1 | D25: ='BC.114+840'!AA24 -> 0 | E25: ='BC.114+840'!AB24 -> 0 | F25: =VLOOKUP($A25,'BC.114+840'!$B$13:$X$470,8,0)/1000 -> 1.92 | G25: =VLOOKUP($A25,'BC.114+840'!$B$13:$X$470,9,0)/1000 -> -0.08 | H25: =VLOOKUP($A25,'BC.114+840'!$B$13:$X$470,14,0)/1000 -> 2.1 | I25: =VLOOKUP($A25,'BC.114+840'!$B$13:$X$470,15,0)/1000 -> 0.1 | J25: =VLOOKUP($A25,'BC.114+840'!$B$13:$X$470,20,0)/1000 -> 1.61 | K25: =VLOOKUP($A25,'BC.114+840'!$B$13:$X$470,21,0)/1000 -> -0.39 | L25: =(G25-$G$14)*1000 -> 0 | M25: =(I25-$I$14)*1000 -> 0 | N25: =(K25-$K$14)*1000 -> 0
A26: ='BC.114+840'!B25 -> 45282 | B26: 12 | C26: ='BC.114+840'!M25/1000 -> 0.1 | D26: ='BC.114+840'!AA25 -> 0 | E26: ='BC.114+840'!AB25 -> 0 | F26: =VLOOKUP($A26,'BC.114+840'!$B$13:$X$470,8,0)/1000 -> 1.92 | G26: =VLOOKUP($A26,'BC.114+840'!$B$13:$X$470,9,0)/1000 -> -0.08 | H26: =VLOOKUP($A26,'BC.114+840'!$B$13:$X$470,14,0)/1000 -> 2.1 | I26: =VLOOKUP($A26,'BC.114+840'!$B$13:$X$470,15,0)/1000 -> 0.1 | J26: =VLOOKUP($A26,'BC.114+840'!$B$13:$X$470,20,0)/1000 -> 1.61 | K26: =VLOOKUP($A26,'BC.114+840'!$B$13:$X$470,21,0)/1000 -> -0.39 | L26: =(G26-$G$14)*1000 -> 0 | M26: =(I26-$I$14)*1000 -> 0 | N26: =(K26-$K$14)*1000 -> 0
... A91: ='BC.114+840'!B90 -> 45347 | B91: 77 | C91: ='BC.114+840'!M90/1000 -> 0.811 | D91: ='BC.114+840'!AA90 -> 1.449 | E91: ='BC.114+840'!AB90 -> 0.422 | F91: =VLOOKUP($A91,'BC.114+840'!$B$13:$X$470,8,0)/1000 -> 1.724 | G91: =VLOOKUP($A91,'BC.114+840'!$B$13:$X$470,9,0)/1000 -> -0.276 | H91: =VLOOKUP($A91,'BC.114+840'!$B$13:$X$470,14,0)/1000 -> 1.811 | I91: =VLOOKUP($A91,'BC.114+840'!$B$13:$X$470,15,0)/1000 -> -0.189 | J91: =VLOOKUP($A91,'BC.114+840'!$B$13:$X$470,20,0)/1000 -> 1.427 | K91: =VLOOKUP($A91,'BC.114+840'!$B$13:$X$470,21,0)/1000 -> -0.573 | L91: =(G91-$G$14)*1000 -> -196 | M91: =(I91-$I$14)*1000 -> -289 | N91: =(K91-$K$14)*1000 -> -183
A92: ='BC.114+840'!B91 -> 45348 | B92: 78 | C92: ='BC.114+840'!M91/1000 -> 0.809 | D92: ='BC.114+840'!AA91 -> 1.449 | E92: ='BC.114+840'!AB91 -> 0.418 | F92: =VLOOKUP($A92,'BC.114+840'!$B$13:$X$470,8,0)/1000 -> 1.724 | G92: =VLOOKUP($A92,'BC.114+840'!$B$13:$X$470,9,0)/1000 -> -0.276 | H92: =VLOOKUP($A92,'BC.114+840'!$B$13:$X$470,14,0)/1000 -> 1.809 | I92: =VLOOKUP($A92,'BC.114+840'!$B$13:$X$470,15,0)/1000 -> -0.191 | J92: =VLOOKUP($A92,'BC.114+840'!$B$13:$X$470,20,0)/1000 -> 1.427 | K92: =VLOOKUP($A92,'BC.114+840'!$B$13:$X$470,21,0)/1000 -> -0.573 | L92: =(G92-$G$14)*1000 -> -196 | M92: =(I92-$I$14)*1000 -> -291 | N92: =(K92-$K$14)*1000 -> -183 | Y92: =A21-A14 -> 7
A93: ='BC.114+840'!B92 -> 45349 | B93: 79 | C93: ='BC.114+840'!M92/1000 -> 0.809 | D93: ='BC.114+840'!AA92 -> 1.449 | E93: ='BC.114+840'!AB92 -> 0.418 | F93: =VLOOKUP($A93,'BC.114+840'!$B$13:$X$470,8,0)/1000 -> 1.724 | G93: =VLOOKUP($A93,'BC.114+840'!$B$13:$X$470,9,0)/1000 -> -0.276 | H93: =VLOOKUP($A93,'BC.114+840'!$B$13:$X$470,14,0)/1000 -> 1.809 | I93: =VLOOKUP($A93,'BC.114+840'!$B$13:$X$470,15,0)/1000 -> -0.191 | J93: =VLOOKUP($A93,'BC.114+840'!$B$13:$X$470,20,0)/1000 -> 1.427 | K93: =VLOOKUP($A93,'BC.114+840'!$B$13:$X$470,21,0)/1000 -> -0.573 | L93: =(G93-$G$14)*1000 -> -196 | M93: =(I93-$I$14)*1000 -> -291 | N93: =(K93-$K$14)*1000 -> -183
