Workbook

Sheet 115+260
B1: 1 | C1: =+B1+1 -> 2 | D1: =+C1+1 -> 3 | E1: =+D1+1 -> 4 | F1: =+E1+1 -> 5 | G1: =+F1+1 -> 6 | H1: =+G1+1 -> 7 | I1: =+H1+1 -> 8 | J1: =+I1+1 -> 9 | ... W1: =+V1+1 -> 22 | Y1: =+W1+1 -> 23 | Z1: =+Y1+1 -> 24 | AA1: =+Z1+1 -> 25 | AB1: =+AA1+1 -> 26
A2: DỰ ÁN THÀNH PHẦN ĐOẠN HẬU GIANG - CÀ MAU
A3: THUỘC DỰ ÁN XÂY DỰNG CÔNG TRÌNH ĐƯỜNG BỘ CAO TỐC BẮC - NAM PHÍA ĐÔNG GIAI ĐOẠN 2021 - 2025
A4: =UPPER("GÓI THẦU XL03 :Thi Công Xây Dựng Đoạn Tuyến Km114+200 - Km126+223 Bao Gồm Tuyến Nối Nút Giao IC12 Với QL1 (bao gồm khảo sát, thiết kế BVTC)") -> GÓI THẦU XL03 :THI CÔNG XÂY DỰNG ĐOẠN TUYẾN KM114+200 - KM126+223 BAO GỒM TUYẾN NỐI NÚT GIAO IC12 VỚI QL1 (BAO GỒM KHẢO SÁT, THIẾT KẾ BVTC)
A5: CHỦ ĐẦU TƯ | I5: TƯ VẤN GIÁM SÁT | S5: NHÀ THẦU
A6: BAN QUẢN LÝ DỰ ÁN MỸ THUẬN | I6: =UPPER("Liên danh Phân viện KHCN GTVT phía Nam - Công ty Cổ phần Tư vấn kỹ thuật và xây dựng Hồng Hà") -> LIÊN DANH PHÂN VIỆN KHCN GTVT PHÍA NAM - CÔNG TY CỔ PHẦN TƯ VẤN KỸ THUẬT VÀ XÂY DỰNG HỒNG HÀ | S6: LIÊN DANH CC1 - HẢI ĐĂNG - VẠN CƯỜNG - 492 - BẮC TRUNG NAM
A7: BIỂU GHI ĐO QUAN TRẮC LÚN
A8: Người lập: | K8: Tên mốc:
A9: Thời tiết: | C9: Nắng | K9: Cao độ mốc: | M9: =C14 -> 1069
A10: Lý trình: | C10: Km115+260 | K10: Ngày đặt bàn: | M10: =B14 -> 45251
A12: Stt | B12: Ngày quan trắc | C12: Cao độ mốc (mm) | D12: Số đọc tại mốc (mm) | E12: Số đọc mia (mm) | H12: Cao độ quan trắc (mm) | K12: Chiều dài cần nối (mm) | N12: Cao độ bàn đo lún (mm) | Q12: Tốc độ lún (mm) | T12: Số đọc mia tại nền đắp tại tâm (mm) | U12: Cao độ nền đắp (mm) | X12: Chiều dày lớp đắp (m) | Y12: Đội quan trắc | Z12: Nhà thầu | AA12: Tư Vấn Giám Sát | AB12: Ghi chú
E13: Trái | F13: Giữa | G13: Phải | H13: Trái | I13: Giữa | J13: Phải | K13: Trái | L13: Giữa | M13: Phải | N13: Trái | O13: Giữa | P13: Phải | Q13: Trái | R13: Giữa | S13: Phải | U13: Trái | V13: Giữa | W13: Phải
A14: 0 | B14: 45251 | C14: 1069 | D14: 1725 | E14: =C14+D14-H14 -> 994 | F14: =C14+D14-I14 -> 1014 | G14: =D14+C14-J14 -> 1044 | H14: =K14+N14 -> 1800 | I14: =L14+O14 -> 1780 | J14: =M14+P14 -> 1750 | K14: 2000 | L14: 2000 | M14: 2000 | N14: -200 | O14: -220 | P14: -250 | Q14: 0 | R14: 0 | S14: 0 | T14: =D14+C14-V14 -> 3014 | U14: =N14 -> -200 | V14: =O14 -> -220 | W14: =P14 -> -250 | AB14: Lắp đặt ban đầu
A15: 1 | B15: =B14+1 -> 45252 | C15: =C14 -> 1069 | D15: =D14-2 -> 1723 | E15: =C15+D15-H15 -> 992 | F15: =C15+D15-I15 -> 1012 | G15: =D15+C15-J15 -> 1042 | H15: =K15+N15 -> 1800 | I15: =L15+O15 -> 1780 | J15: =M15+P15 -> 1750 | K15: =K14 -> 2000 | L15: =L14 -> 2000 | M15: =M14 -> 2000 | N15: =N14-Q15 -> -200 | O15: =O14-R15 -> -220 | P15: =P14-S15 -> -250 | Q15: 0 | R15: 0 | S15: 0 | T15: =D15+C15-V15 -> 3012 | U15: =U14+$X15*1000-Q15 -> -200 | V15: =V14+$X15*1000-R15 -> -220 | W15: =W14+$X15*1000-S15 -> -250
A16: 2 | B16: =B15+1 -> 45253 | C16: =C15 -> 1069 | D16: =D15-2 -> 1721 | E16: =C16+D16-H16 -> 990 | F16: =C16+D16-I16 -> 1010 | G16: =D16+C16-J16 -> 1040 | H16: =K16+N16 -> 1800 | I16: =L16+O16 -> 1780 | J16: =M16+P16 -> 1750 | K16: =K15 -> 2000 | L16: =L15 -> 2000 | M16: =M15 -> 2000 | N16: =N15-Q16 -> -200 | O16: =O15-R16 -> -220 | P16: =P15-S16 -> -250 | Q16: 0 | R16: 0 | S16: 0 | T16: =D16+C16-V16 -> 3010 | U16: =U15+$X16*1000-Q16 -> -200 | V16: =V15+$X16*1000-R16 -> -220 | W16: =W15+$X16*1000-S16 -> -250
A17: 3 | B17: =B16+1 -> 45254 | C17: =C16 -> 1069 | D17: =D16-2 -> 1719 | E17: =C17+D17-H17 -> 988 | F17: =C17+D17-I17 -> 1008 | G17: =D17+C17-J17 -> 1038 | H17: =K17+N17 -> 1800 | I17: =L17+O17 -> 1780 | J17: =M17+P17 -> 1750 | K17: =K16 -> 2000 | L17: =L16 -> 2000 | M17: =M16 -> 2000 | N17: =N16-Q17 -> -200 | O17: =O16-R17 -> -220 | P17: =P16-S17 -> -250 | Q17: 0 | R17: 0 | S17: 0 | T17: =D17+C17-V17 -> 3008 | U17: =U16+$X17*1000-Q17 -> -200 | V17: =V16+$X17*1000-R17 -> -220 | W17: =W16+$X17*1000-S17 -> -250 | AE17: 45256
A18: 4 | B18: =B17+1 -> 45255 | C18: =C17 -> 1069 | D18: =D17-2 -> 1717 | E18: =C18+D18-H18 -> 986 | F18: =C18+D18-I18 -> 1006 | G18: =D18+C18-J18 -> 1036 | H18: =K18+N18 -> 1800 | I18: =L18+O18 -> 1780 | J18: =M18+P18 -> 1750 | K18: =K17 -> 2000 | L18: =L17 -> 2000 | M18: =M17 -> 2000 | N18: =N17-Q18 -> -200 | O18: =O17-R18 -> -220 | P18: =P17-S18 -> -250 | Q18: 0 | R18: 0 | S18: 0 | T18: =D18+C18-V18 -> 3006 | U18: =U17+$X18*1000-Q18 -> -200 | V18: =V17+$X18*1000-R18 -> -220 | W18: =W17+$X18*1000-S18 -> -250 | AE18: 45260
A19: 5 | B19: =B18+1 -> 45256 | C19: =C18 -> 1069 | D19: =D18-2 -> 1715 | E19: =C19+D19-H19 -> 984 | F19: =C19+D19-I19 -> 1004 | G19: =D19+C19-J19 -> 1034 | H19: =K19+N19 -> 1800 | I19: =L19+O19 -> 1780 | J19: =M19+P19 -> 1750 | K19: =K18 -> 2000 | L19: =L18 -> 2000 | M19: =M18 -> 2000 | N19: =N18-Q19 -> -200 | O19: =O18-R19 -> -220 | P19: =P18-S19 -> -250 | Q19: 0 | R19: 0 | S19: 0 | T19: =D19+C19-V19 -> 3004 | U19: =U18+$X19*1000-Q19 -> -200 | V19: =V18+$X19*1000-R19 -> -220 | W19: =W18+$X19*1000-S19 -> -250 | AE19: 45264
A20: 6 | B20: =B19+1 -> 45257 | C20: =C19 -> 1069 | D20: =D19-2 -> 1713 | E20: =C20+D20-H20 -> 982 | F20: =C20+D20-I20 -> 1002 | G20: =D20+C20-J20 -> 1032 | H20: =K20+N20 -> 1800 | I20: =L20+O20 -> 1780 | J20: =M20+P20 -> 1750 | K20: =K19 -> 2000 | L20: =L19 -> 2000 | M20: =M19 -> 2000 | N20: =N19-Q20 -> -200 | O20: =O19-R20 -> -220 | P20: =P19-S20 -> -250 | Q20: 0 | R20: 0 | S20: 0 | T20: =D20+C20-V20 -> 3002 | U20: =U19+$X20*1000-Q20 -> -200 | V20: =V19+$X20*1000-R20 -> -220 | W20: =W19+$X20*1000-S20 -> -250 | AE20: 45268
A21: 7 | B21: =B20+1 -> 45258 | C21: =C20 -> 1069 | D21: =D20-2 -> 1711 | E21: =C21+D21-H21 -> 980 | F21: =C21+D21-I21 -> 1000 | G21: =D21+C21-J21 -> 1030 | H21: =K21+N21 -> 1800 | I21: =L21+O21 -> 1780 | J21: =M21+P21 -> 1750 | K21: =K20 -> 2000 | L21: =L20 -> 2000 | M21: =M20 -> 2000 | N21: =N20-Q21 -> -200 | O21: =O20-R21 -> -220 | P21: =P20-S21 -> -250 | Q21: 0 | R21: 0 | S21: 0 | T21: =D21+C21-V21 -> 3000 | U21: =U20+$X21*1000-Q21 -> -200 | V21: =V20+$X21*1000-R21 -> -220 | W21: =W20+$X21*1000-S21 -> -250 | AE21: 45272
A22: 8 | B22: =B21+1 -> 45259 | C22: =C21 -> 1069 | D22: =D21-2 -> 1709 | E22: =C22+D22-H22 -> 978 | F22: =C22+D22-I22 -> 998 | G22: =D22+C22-J22 -> 1028 | H22: =K22+N22 -> 1800 | I22: =L22+O22 -> 1780 | J22: =M22+P22 -> 1750 | K22: =K21 -> 2000 | L22: =L21 -> 2000 | M22: =M21 -> 2000 | N22: =N21-Q22 -> -200 | O22: =O21-R22 -> -220 | P22: =P21-S22 -> -250 | Q22: 0 | R22: 0 | S22: 0 | T22: =D22+C22-V22 -> 2998 | U22: =U21+$X22*1000-Q22 -> -200 | V22: =V21+$X22*1000-R22 -> -220 | W22: =W21+$X22*1000-S22 -> -250 | AE22: 45276
A23: 9 | B23: =B22+1 -> 45260 | C23: =C22 -> 1069 | D23: =D22-2 -> 1707 | E23: =C23+D23-H23 -> 976 | F23: =C23+D23-I23 -> 996 | G23: =D23+C23-J23 -> 1026 | H23: =K23+N23 -> 1800 | I23: =L23+O23 -> 1780 | J23: =M23+P23 -> 1750 | K23: =K22 -> 2000 | L23: =L22 -> 2000 | M23: =M22 -> 2000 | N23: =N22-Q23 -> -200 | O23: =O22-R23 -> -220 | P23: =P22-S23 -> -250 | Q23: 0 | R23: 0 | S23: 0 | T23: =D23+C23-V23 -> 2996 | U23: =U22+$X23*1000-Q23 -> -200 | V23: =V22+$X23*1000-R23 -> -220 | W23: =W22+$X23*1000-S23 -> -250 | AE23: 45280
A24: 10 | B24: =B23+1 -> 45261 | C24: =C23 -> 1069 | D24: =D23-2 -> 1705 | E24: =C24+D24-H24 -> 974 | F24: =C24+D24-I24 -> 994 | G24: =D24+C24-J24 -> 1024 | H24: =K24+N24 -> 1800 | I24: =L24+O24 -> 1780 | J24: =M24+P24 -> 1750 | K24: =K23 -> 2000 | L24: =L23 -> 2000 | M24: =M23 -> 2000 | N24: =N23-Q24 -> -200 | O24: =O23-R24 -> -220 | P24: =P23-S24 -> -250 | Q24: 0 | R24: 0 | S24: 0 | T24: =D24+C24-V24 -> 2994 | U24: =U23+$X24*1000-Q24 -> -200 | V24: =V23+$X24*1000-R24 -> -220 | W24: =W23+$X24*1000-S24 -> -250 | AE24: 45284
A25: 11 | B25: =B24+1 -> 45262 | C25: =C24 -> 1069 | D25: =D24-2 -> 1703 | E25: =C25+D25-H25 -> 972 | F25: =C25+D25-I25 -> 992 | G25: =D25+C25-J25 -> 1022 | H25: =K25+N25 -> 1800 | I25: =L25+O25 -> 1780 | J25: =M25+P25 -> 1750 | K25: =K24 -> 2000 | L25: =L24 -> 2000 | M25: =M24 -> 2000 | N25: =N24-Q25 -> -200 | O25: =O24-R25 -> -220 | P25: =P24-S25 -> -250 | Q25: 0 | R25: 0 | S25: 0 | T25: =D25+C25-V25 -> 2992 | U25: =U24+$X25*1000-Q25 -> -200 | V25: =V24+$X25*1000-R25 -> -220 | W25: =W24+$X25*1000-S25 -> -250 | AE25: 45402
A26: 12 | B26: =B25+1 -> 45263 | C26: =C25 -> 1069 | D26: =D25-2 -> 1701 | E26: =C26+D26-H26 -> 970 | F26: =C26+D26-I26 -> 990 | G26: =D26+C26-J26 -> 1020 | H26: =K26+N26 -> 1800 | I26: =L26+O26 -> 1780 | J26: =M26+P26 -> 1750 | K26: =K25 -> 2000 | L26: =L25 -> 2000 | M26: =M25 -> 2000 | N26: =N25-Q26 -> -200 | O26: =O25-R26 -> -220 | P26: =P25-S26 -> -250 | Q26: 0 | R26: 0 | S26: 0 | T26: =D26+C26-V26 -> 2990 | U26: =U25+$X26*1000-Q26 -> -200 | V26: =V25+$X26*1000-R26 -> -220 | W26: =W25+$X26*1000-S26 -> -250 | AE26: 45406
A27: 13 | B27: =B26+1 -> 45264 | C27: =C26 -> 1069 | D27: =D26-2 -> 1699 | E27: =C27+D27-H27 -> 968 | F27: =C27+D27-I27 -> 988 | G27: =D27+C27-J27 -> 1018 | H27: =K27+N27 -> 1800 | I27: =L27+O27 -> 1780 | J27: =M27+P27 -> 1750 | K27: =K26 -> 2000 | L27: =L26 -> 2000 | M27: =M26 -> 2000 | N27: =N26-Q27 -> -200 | O27: =O26-R27 -> -220 | P27: =P26-S27 -> -250 | Q27: 0 | R27: 0 | S27: 0 | T27: =D27+C27-V27 -> 2988 | U27: =U26+$X27*1000-Q27 -> -200 | V27: =V26+$X27*1000-R27 -> -220 | W27: =W26+$X27*1000-S27 -> -250 | AE27: 45411
A28: 14 | B28: =B27+1 -> 45265 | C28: =C27 -> 1069 | D28: =D27-2 -> 1697 | E28: =C28+D28-H28 -> 966 | F28: =C28+D28-I28 -> 986 | G28: =D28+C28-J28 -> 1016 | H28: =K28+N28 -> 1800 | I28: =L28+O28 -> 1780 | J28: =M28+P28 -> 1750 | K28: =K27 -> 2000 | L28: =L27 -> 2000 | M28: =M27 -> 2000 | N28: =N27-Q28 -> -200 | O28: =O27-R28 -> -220 | P28: =P27-S28 -> -250 | Q28: 0 | R28: 0 | S28: 0 | T28: =D28+C28-V28 -> 2986 | U28: =U27+$X28*1000-Q28 -> -200 | V28: =V27+$X28*1000-R28 -> -220 | W28: =W27+$X28*1000-S28 -> -250 | AE28: 45415
A29: 15 | B29: =B28+1 -> 45266 | C29: =C28 -> 1069 | D29: =D28-2 -> 1695 | E29: =C29+D29-H29 -> 964 | F29: =C29+D29-I29 -> 984 | G29: =D29+C29-J29 -> 1014 | H29: =K29+N29 -> 1800 | I29: =L29+O29 -> 1780 | J29: =M29+P29 -> 1750 | K29: =K28 -> 2000 | L29: =L28 -> 2000 | M29: =M28 -> 2000 | N29: =N28-Q29 -> -200 | O29: =O28-R29 -> -220 | P29: =P28-S29 -> -250 | Q29: 0 | R29: 0 | S29: 0 | T29: =D29+C29-V29 -> 2984 | U29: =U28+$X29*1000-Q29 -> -200 | V29: =V28+$X29*1000-R29 -> -220 | W29: =W28+$X29*1000-S29 -> -250
A30: 16 | B30: =B29+1 -> 45267 | C30: =C29 -> 1069 | D30: =D29-2 -> 1693 | E30: =C30+D30-H30 -> 962 | F30: =C30+D30-I30 -> 982 | G30: =D30+C30-J30 -> 1012 | H30: =K30+N30 -> 1800 | I30: =L30+O30 -> 1780 | J30: =M30+P30 -> 1750 | K30: =K29 -> 2000 | L30: =L29 -> 2000 | M30: =M29 -> 2000 | N30: =N29-Q30 -> -200 | O30: =O29-R30 -> -220 | P30: =P29-S30 -> -250 | Q30: 0 | R30: 0 | S30: 0 | T30: =D30+C30-V30 -> 2982 | U30: =U29+$X30*1000-Q30 -> -200 | V30: =V29+$X30*1000-R30 -> -220 | W30: =W29+$X30*1000-S30 -> -250
A31: 17 | B31: =B30+1 -> 45268 | C31: =C30 -> 1069 | D31: =D30-2 -> 1691 | E31: =C31+D31-H31 -> 969 | F31: =C31+D31-I31 -> 988 | G31: =D31+C31-J31 -> 1019 | H31: =K31+N31 -> 1791 | I31: =L31+O31 -> 1772 | J31: =M31+P31 -> 1741 | K31: =K30 -> 2000 | L31: =L30 -> 2000 | M31: =M30 -> 2000 | N31: =N30-Q31 -> -209 | O31: =O30-R31 -> -228 | P31: =P30-S31 -> -259 | Q31: 9 | R31: 8 | S31: 9 | T31: =D31+C31-V31 -> 2688 | U31: =U30+$X31*1000-Q31 -> 91 | V31: =V30+$X31*1000-R31 -> 72 | W31: =W30+$X31*1000-S31 -> 41 | X31: 0.3 | AB31: 9
A32: 18 | B32: =B31+1 -> 45269 | C32: =C31 -> 1069 | D32: =D31-2 -> 1689 | E32: =C32+D32-H32 -> 970 | F32: =C32+D32-I32 -> 989 | G32: =D32+C32-J32 -> 1020 | H32: =K32+N32 -> 1788 | I32: =L32+O32 -> 1769 | J32: =M32+P32 -> 1738 | K32: =K31 -> 2000 | L32: =L31 -> 2000 | M32: =M31 -> 2000 | N32: =N31-Q32 -> -212 | O32: =O31-R32 -> -231 | P32: =P31-S32 -> -262 | Q32: 3 | R32: 3 | S32: 3 | T32: =D32+C32-V32 -> 2689 | U32: =U31+$X32*1000-Q32 -> 88 | V32: =V31+$X32*1000-R32 -> 69 | W32: =W31+$X32*1000-S32 -> 38
A33: 19 | B33: =B32+1 -> 45270 | C33: =C32 -> 1069 | D33: =D32-2 -> 1687 | E33: =C33+D33-H33 -> 972 | F33: =C33+D33-I33 -> 992 | G33: =D33+C33-J33 -> 1022 | H33: =K33+N33 -> 1784 | I33: =L33+O33 -> 1764 | J33: =M33+P33 -> 1734 | K33: =K32 -> 2000 | L33: =L32 -> 2000 | M33: =M32 -> 2000 | N33: =N32-Q33 -> -216 | O33: =O32-R33 -> -236 | P33: =P32-S33 -> -266 | Q33: 4 | R33: 5 | S33: 4 | T33: =D33+C33-V33 -> 2692 | U33: =U32+$X33*1000-Q33 -> 84 | V33: =V32+$X33*1000-R33 -> 64 | W33: =W32+$X33*1000-S33 -> 34
A34: 20 | B34: =B33+1 -> 45271 | C34: =C33 -> 1069 | D34: =D33-2 -> 1685 | E34: =C34+D34-H34 -> 976 | F34: =C34+D34-I34 -> 993 | G34: =D34+C34-J34 -> 1023 | H34: =K34+N34 -> 1778 | I34: =L34+O34 -> 1761 | J34: =M34+P34 -> 1731 | K34: =K33 -> 2000 | L34: =L33 -> 2000 | M34: =M33 -> 2000 | N34: =N33-Q34 -> -222 | O34: =O33-R34 -> -239 | P34: =P33-S34 -> -269 | Q34: 6 | R34: 3 | S34: 3 | T34: =D34+C34-V34 -> 2693 | U34: =U33+$X34*1000-Q34 -> 78 | V34: =V33+$X34*1000-R34 -> 61 | W34: =W33+$X34*1000-S34 -> 31
A35: 21 | B35: =B34+1 -> 45272 | C35: =C34 -> 1069 | D35: =D34-2 -> 1683 | E35: =C35+D35-H35 -> 983 | F35: =C35+D35-I35 -> 999 | G35: =D35+C35-J35 -> 1030 | H35: =K35+N35 -> 1769 | I35: =L35+O35 -> 1753 | J35: =M35+P35 -> 1722 | K35: =K34 -> 2000 | L35: =L34 -> 2000 | M35: =M34 -> 2000 | N35: =N34-Q35 -> -231 | O35: =O34-R35 -> -247 | P35: =P34-S35 -> -278 | Q35: 9 | R35: 8 | S35: 9 | T35: =D35+C35-V35 -> 2379 | U35: =U34+$X35*1000-Q35 -> 369 | V35: =V34+0.32*1000-R35 -> 373 | W35: =W34+0.35*1000-S35 -> 372 | X35: 0.3 | AB35: 8
A36: 22 | B36: =B35+1 -> 45273 | C36: =C35 -> 1069 | D36: =D35-2 -> 1681 | E36: =C36+D36-H36 -> 989 | F36: =C36+D36-I36 -> 999 | G36: =D36+C36-J36 -> 1030 | H36: =K36+N36 -> 1761 | I36: =L36+O36 -> 1751 | J36: =M36+P36 -> 1720 | K36: =K35 -> 2000 | L36: =L35 -> 2000 | M36: =M35 -> 2000 | N36: =N35-Q36 -> -239 | O36: =O35-R36 -> -249 | P36: =P35-S36 -> -280 | Q36: 8 | R36: 2 | S36: 2 | T36: =D36+C36-V36 -> 2379 | U36: =U35+$X36*1000-Q36 -> 361 | V36: =V35+$X36*1000-R36 -> 371 | W36: =W35+$X36*1000-S36 -> 370
A37: 23 | B37: =B36+1 -> 45274 | C37: =C36 -> 1069 | D37: =D36-2 -> 1679 | E37: =C37+D37-H37 -> 992 | F37: =C37+D37-I37 -> 999 | G37: =D37+C37-J37 -> 1032 | H37: =K37+N37 -> 1756 | I37: =L37+O37 -> 1749 | J37: =M37+P37 -> 1716 | K37: =K36 -> 2000 | L37: =L36 -> 2000 | M37: =M36 -> 2000 | N37: =N36-Q37 -> -244 | O37: =O36-R37 -> -251 | P37: =P36-S37 -> -284 | Q37: 5 | R37: 2 | S37: 4 | T37: =D37+C37-V37 -> 2379 | U37: =U36+$X37*1000-Q37 -> 356 | V37: =V36+$X37*1000-R37 -> 369 | W37: =W36+$X37*1000-S37 -> 366
A38: 24 | B38: =B37+1 -> 45275 | C38: =C37 -> 1069 | D38: =D37-2 -> 1677 | E38: =C38+D38-H38 -> 994 | F38: =C38+D38-I38 -> 1000 | G38: =D38+C38-J38 -> 1033 | H38: =K38+N38 -> 1752 | I38: =L38+O38 -> 1746 | J38: =M38+P38 -> 1713 | K38: =K37 -> 2000 | L38: =L37 -> 2000 | M38: =M37 -> 2000 | N38: =N37-Q38 -> -248 | O38: =O37-R38 -> -254 | P38: =P37-S38 -> -287 | Q38: 4 | R38: 3 | S38: 3 | T38: =D38+C38-V38 -> 2380 | U38: =U37+$X38*1000-Q38 -> 352 | V38: =V37+$X38*1000-R38 -> 366 | W38: =W37+$X38*1000-S38 -> 363
A39: 25 | B39: =B38+1 -> 45276 | C39: =C38 -> 1069 | D39: =D38-2 -> 1675 | E39: =C39+D39-H39 -> 1001 | F39: =C39+D39-I39 -> 1006 | G39: =D39+C39-J39 -> 1040 | H39: =K39+N39 -> 1743 | I39: =L39+O39 -> 1738 | J39: =M39+P39 -> 1704 | K39: =K38 -> 2000 | L39: =L38 -> 2000 | M39: =M38 -> 2000 | N39: =N38-Q39 -> -257 | O39: =O38-R39 -> -262 | P39: =P38-S39 -> -296 | Q39: 9 | R39: 8 | S39: 9 | T39: =D39+C39-V39 -> 2186 | U39: =U38+$X39*1000-Q39 -> 543 | V39: =V38+$X39*1000-R39 -> 558 | W39: =W38+$X39*1000-S39 -> 554 | X39: 0.2 | AB39: 7
A40: 26 | B40: =B39+1 -> 45277 | C40: =C39 -> 1069 | D40: =D39-2 -> 1673 | E40: =C40+D40-H40 -> 1001 | F40: =C40+D40-I40 -> 1009 | G40: =D40+C40-J40 -> 1040 | H40: =K40+N40 -> 1741 | I40: =L40+O40 -> 1733 | J40: =M40+P40 -> 1702 | K40: =K39 -> 2000 | L40: =L39 -> 2000 | M40: =M39 -> 2000 | N40: =N39-Q40 -> -259 | O40: =O39-R40 -> -267 | P40: =P39-S40 -> -298 | Q40: 2 | R40: 5 | S40: 2 | T40: =D40+C40-V40 -> 2189 | U40: =U39+$X40*1000-Q40 -> 541 | V40: =V39+$X40*1000-R40 -> 553 | W40: =W39+$X40*1000-S40 -> 552
A41: 27 | B41: =B40+1 -> 45278 | C41: =C40 -> 1069 | D41: =D40-2 -> 1671 | E41: =C41+D41-H41 -> 1003 | F41: =C41+D41-I41 -> 1012 | G41: =D41+C41-J41 -> 1040 | H41: =K41+N41 -> 1737 | I41: =L41+O41 -> 1728 | J41: =M41+P41 -> 1700 | K41: =K40 -> 2000 | L41: =L40 -> 2000 | M41: =M40 -> 2000 | N41: =N40-Q41 -> -263 | O41: =O40-R41 -> -272 | P41: =P40-S41 -> -300 | Q41: 4 | R41: 5 | S41: 2 | T41: =D41+C41-V41 -> 2192 | U41: =U40+$X41*1000-Q41 -> 537 | V41: =V40+$X41*1000-R41 -> 548 | W41: =W40+$X41*1000-S41 -> 550
...

Sheet BC.115+260
A1: 13 | B1: DỰ ÁN THÀNH PHẦN ĐOẠN HẬU GIANG - CÀ MAU
B2: THUỘC DỰ ÁN XÂY DỰNG CÔNG TRÌNH ĐƯỜNG BỘ CAO TỐC BẮC - NAM PHÍA ĐÔNG GIAI ĐOẠN 2021 - 2025
B3: =UPPER("GÓI THẦU XL03 :Thi Công Xây Dựng Đoạn Tuyến Km114+200 - Km126+223 Bao Gồm Tuyến Nối Nút Giao IC12 Với QL1 (bao gồm khảo sát, thiết kế BVTC)") -> GÓI THẦU XL03 :THI CÔNG XÂY DỰNG ĐOẠN TUYẾN KM114+200 - KM126+223 BAO GỒM TUYẾN NỐI NÚT GIAO IC12 VỚI QL1 (BAO GỒM KHẢO SÁT, THIẾT KẾ BVTC)
B4: CHỦ ĐẦU TƯ | J4: TƯ VẤN GIÁM SÁT | T4: NHÀ THẦU
B5: BAN QUẢN LÝ DỰ ÁN MỸ THUẬN | J5: =UPPER("Liên danh Phân viện KHCN GTVT phía Nam - Công ty Cổ phần Tư vấn kỹ thuật và xây dựng Hồng Hà") -> LIÊN DANH PHÂN VIỆN KHCN GTVT PHÍA NAM - CÔNG TY CỔ PHẦN TƯ VẤN KỸ THUẬT VÀ XÂY DỰNG HỒNG HÀ | T5: LIÊN DANH CC1 - HẢI ĐĂNG - VẠN CƯỜNG - 492 - BẮC TRUNG NAM
B6: BIỂU GHI ĐO QUAN TRẮC LÚN
B7: Người lập: | C7: ='115+260'!C8 -> 0 | L7: Tên mốc: | N7: ='115+260'!M8 -> 0
B8: Thời tiết: | C8: ='115+260'!C9 -> Nắng | L8: Cao độ mốc: | N8: ='115+260'!M9 -> 1069
B9: Lý trình: | C9: ='115+260'!C10 -> Km115+260 | L9: Ngày đặt bàn: | N9: ='115+260'!M10 -> 45251
B11: Ngày | C11: Ngày cộng dồn | D11: Cao độ mốc | E11: Số đọc mia của mốc | F11: Cao độ đường ngắm | G11: Trái | M11: Tim | S11: Phải | Z11: Chiều dày lớp đắp (m) | AA11: Chiều cao nền đắp (m) | AB11: Chiều dày nền đắp (m)
G12: Cao độ đắp (mm) | H12: Số đọc mia | I12: Cao độ quan trắc (mm) | J12: Cao độ bàn đo lún (mm) | K12: Độ lún (mm) | L12: Độ lún tích lũy (mm) | M12: Cao độ đắp (mm) | N12: Số đọc mia | O12: Cao độ quan trắc (mm) | P12: Cao độ bàn đo lún (mm) | Q12: Độ lún (mm) | R12: Độ lún tích lũy (mm) | S12: Cao độ đắp (mm) | T12: Số đọc mia | U12: Cao độ quan trắc (mm) | V12: Cao độ bàn đo lún (mm) | W12: Độ lún (mm) | X12: Độ lún tích lũy (mm)
B13: ='115+260'!B14 -> 45251 | C13: 0 | D13: =VLOOKUP(B13,'115+260'!B14:AB115,2,FALSE) -> 1069 | E13: =VLOOKUP(B13,'115+260'!B14:AB115,3,FALSE) -> 1725 | F13: =D13+E13 -> 2794 | G13: =VLOOKUP(B13,'115+260'!$B$14:$AB$115,20,FALSE) -> -200 | H13: =VLOOKUP(B13,'115+260'!$B$14:$AB$115,4,FALSE) -> 994 | I13: =F13-H13 -> 1800 | J13: =VLOOKUP(B13,'115+260'!$B$14:$AB$115,13,FALSE) -> -200 | K13: ='115+260'!Q14 -> 0 | L13: 0 | M13: =VLOOKUP(B13,'115+260'!$B$14:$AB$115,21,FALSE) -> -220 | N13: =VLOOKUP(B13,'115+260'!$B$14:$AB$115,5,FALSE) -> 1014 | O13: =F13-N13 -> 1780 | P13: =VLOOKUP(B13,'115+260'!$B$14:$AB$115,14,FALSE) -> -220 | Q13: ='115+260'!R14 -> 0 | R13: 0 | S13: =VLOOKUP(B13,'115+260'!$B$14:$AB$115,22,FALSE) -> -250 | T13: =VLOOKUP(B13,'115+260'!$B$13:$AB$115,6,FALSE) -> 1044 | U13: =F13-T13 -> 1750 | V13: =VLOOKUP(B13,'115+260'!$B$14:$AB$115,15,FALSE) -> -250 | W13: ='115+260'!S14 -> 0 | X13: 0 | Y13: 0 | Z13: =IF(Y13>0,Y13,0) -> 0 | AA13: =Z13 -> 0 | AB13: 0
B14: ='115+260'!B15 -> 45252 | C14: =B14-B13 -> 1 | D14: =D13 -> 1069 | E14: =VLOOKUP(B14,'115+260'!B15:AB116,3,FALSE) -> 1723 | F14: =D14+E14 -> 2792 | G14: =VLOOKUP(B14,'115+260'!$B$15:$AB$115,20,FALSE) -> -200 | H14: =VLOOKUP(B14,'115+260'!$B$15:$AB$115,4,FALSE) -> 992 | I14: =F14-H14 -> 1800 | J14: =VLOOKUP(B14,'115+260'!$B$15:$AB$115,13,FALSE) -> -200 | K14: ='115+260'!Q15 -> 0 | L14: =+K14+L13 -> 0 | M14: =VLOOKUP(B14,'115+260'!$B$14:$AB$115,21,FALSE) -> -220 | N14: =VLOOKUP(B14,'115+260'!$B$15:$AB$115,5,FALSE) -> 1012 | O14: =F14-N14 -> 1780 | P14: =VLOOKUP(B14,'115+260'!$B$15:$AB$115,14,FALSE) -> -220 | Q14: ='115+260'!R15 -> 0 | R14: =+Q14+R13 -> 0 | S14: =VLOOKUP(B14,'115+260'!$B$14:$AB$115,22,FALSE) -> -250 | T14: =VLOOKUP(B14,'115+260'!$B$15:$AB$115,6,FALSE) -> 1042 | U14: =F14-T14 -> 1750 | V14: =VLOOKUP(B14,'115+260'!$B$15:$AB$115,15,FALSE) -> -250 | W14: ='115+260'!S15 -> 0 | X14: =+W14+X13 -> 0 | Y14: =S14-S13 -> 0 | Z14: =IF(Y14>0,Y14,0)/1000 -> 0 | AA14: =AA13+Z14 -> 0 | AB14: =(M14-$M$13-R14)/1000 -> 0
A15: 1 | B15: ='115+260'!B16 -> 45253 | C15: =B15-B14 -> 1 | D15: =D14 -> 1069 | E15: =VLOOKUP(B15,'115+260'!B16:AB117,3,FALSE) -> 1721 | F15: =D15+E15 -> 2790 | G15: =VLOOKUP(B15,'115+260'!$B$15:$AB$115,20,FALSE) -> -200 | H15: =VLOOKUP(B15,'115+260'!$B$15:$AB$115,4,FALSE) -> 990 | I15: =F15-H15 -> 1800 | J15: =VLOOKUP(B15,'115+260'!$B$15:$AB$115,13,FALSE) -> -200 | K15: ='115+260'!Q16 -> 0 | L15: =+K15+L14 -> 0 | M15: =VLOOKUP(B15,'115+260'!$B$14:$AB$115,21,FALSE) -> -220 | N15: =VLOOKUP(B15,'115+260'!$B$15:$AB$115,5,FALSE) -> 1010 | O15: =F15-N15 -> 1780 | P15: =VLOOKUP(B15,'115+260'!$B$15:$AB$115,14,FALSE) -> -220 | Q15: ='115+260'!R16 -> 0 | R15: =+Q15+R14 -> 0 | S15: =VLOOKUP(B15,'115+260'!$B$14:$AB$115,22,FALSE) -> -250 | T15: =VLOOKUP(B15,'115+260'!$B$15:$AB$115,6,FALSE) -> 1040 | U15: =F15-T15 -> 1750 | V15: =VLOOKUP(B15,'115+260'!$B$15:$AB$115,15,FALSE) -> -250 | W15: ='115+260'!S16 -> 0 | X15: =+W15+X14 -> 0 | Y15: =S15-S14 -> 0 | Z15: =IF(Y15>0,Y15,0)/1000 -> 0 | AA15: =AA14+Z15 -> 0 | AB15: =(M15-$M$13-R15)/1000 -> 0
A16: =A15+1 -> 2 | B16: ='115+260'!B17 -> 45254 | C16: =B16-B15 -> 1 | D16: =D15 -> 1069 | E16: =VLOOKUP(B16,'115+260'!B17:AB118,3,FALSE) -> 1719 | F16: =D16+E16 -> 2788 | G16: =VLOOKUP(B16,'115+260'!$B$15:$AB$115,20,FALSE) -> -200 | H16: =VLOOKUP(B16,'115+260'!$B$15:$AB$115,4,FALSE) -> 988 | I16: =F16-H16 -> 1800 | J16: =VLOOKUP(B16,'115+260'!$B$15:$AB$115,13,FALSE) -> -200 | K16: ='115+260'!Q17 -> 0 | L16: =+K16+L15 -> 0 | M16: =VLOOKUP(B16,'115+260'!$B$14:$AB$115,21,FALSE) -> -220 | N16: =VLOOKUP(B16,'115+260'!$B$15:$AB$115,5,FALSE) -> 1008 | O16: =F16-N16 -> 1780 | P16: =VLOOKUP(B16,'115+260'!$B$15:$AB$115,14,FALSE) -> -220 | Q16: ='115+260'!R17 -> 0 | R16: =+Q16+R15 -> 0 | S16: =VLOOKUP(B16,'115+260'!$B$14:$AB$115,22,FALSE) -> -250 | T16: =VLOOKUP(B16,'115+260'!$B$15:$AB$115,6,FALSE) -> 1038 | U16: =F16-T16 -> 1750 | V16: =VLOOKUP(B16,'115+260'!$B$15:$AB$115,15,FALSE) -> -250 | W16: ='115+260'!S17 -> 0 | X16: =+W16+X15 -> 0 | Y16: =S16-S15 -> 0 | Z16: =IF(Y16>0,Y16,0)/1000 -> 0 | AA16: =AA15+Z16 -> 0 | AB16: =(M16-$M$13-R16)/1000 -> 0
A17: =A16+1 -> 3 | B17: ='115+260'!B18 -> 45255 | C17: =B17-B16 -> 1 | D17: =D16 -> 1069 | E17: =VLOOKUP(B17,'115+260'!B18:AB119,3,FALSE) -> 1717 | F17: =D17+E17 -> 2786 | G17: =VLOOKUP(B17,'115+260'!$B$15:$AB$115,20,FALSE) -> -200 | H17: =VLOOKUP(B17,'115+260'!$B$15:$AB$115,4,FALSE) -> 986 | I17: =F17-H17 -> 1800 | J17: =VLOOKUP(B17,'115+260'!$B$15:$AB$115,13,FALSE) -> -200 | K17: ='115+260'!Q18 -> 0 | L17: =+K17+L16 -> 0 | M17: =VLOOKUP(B17,'115+260'!$B$14:$AB$115,21,FALSE) -> -220 | N17: =VLOOKUP(B17,'115+260'!$B$15:$AB$115,5,FALSE) -> 1006 | O17: =F17-N17 -> 1780 | P17: =VLOOKUP(B17,'115+260'!$B$15:$AB$115,14,FALSE) -> -220 | Q17: ='115+260'!R18 -> 0 | R17: =+Q17+R16 -> 0 | S17: =VLOOKUP(B17,'115+260'!$B$14:$AB$115,22,FALSE) -> -250 | T17: =VLOOKUP(B17,'115+260'!$B$15:$AB$115,6,FALSE) -> 1036 | U17: =F17-T17 -> 1750 | V17: =VLOOKUP(B17,'115+260'!$B$15:$AB$115,15,FALSE) -> -250 | W17: ='115+260'!S18 -> 0 | X17: =+W17+X16 -> 0 | Y17: =S17-S16 -> 0 | Z17: =IF(Y17>0,Y17,0)/1000 -> 0 | AA17: =AA16+Z17 -> 0 | AB17: =(M17-$M$13-R17)/1000 -> 0
A18: =A17+1 -> 4 | B18: ='115+260'!B19 -> 45256 | C18: =B18-B17 -> 1 | D18: =D17 -> 1069 | E18: =VLOOKUP(B18,'115+260'!B19:AB120,3,FALSE) -> 1715 | F18: =D18+E18 -> 2784 | G18: =VLOOKUP(B18,'115+260'!$B$15:$AB$115,20,FALSE) -> -200 | H18: =VLOOKUP(B18,'115+260'!$B$15:$AB$115,4,FALSE) -> 984 | I18: =F18-H18 -> 1800 | J18: =VLOOKUP(B18,'115+260'!$B$15:$AB$115,13,FALSE) -> -200 | K18: ='115+260'!Q19 -> 0 | L18: =+K18+L17 -> 0 | M18: =VLOOKUP(B18,'115+260'!$B$14:$AB$115,21,FALSE) -> -220 | N18: =VLOOKUP(B18,'115+260'!$B$15:$AB$115,5,FALSE) -> 1004 | O18: =F18-N18 -> 1780 | P18: =VLOOKUP(B18,'115+260'!$B$15:$AB$115,14,FALSE) -> -220 | Q18: ='115+260'!R19 -> 0 | R18: =+Q18+R17 -> 0 | S18: =VLOOKUP(B18,'115+260'!$B$14:$AB$115,22,FALSE) -> -250 | T18: =VLOOKUP(B18,'115+260'!$B$15:$AB$115,6,FALSE) -> 1034 | U18: =F18-T18 -> 1750 | V18: =VLOOKUP(B18,'115+260'!$B$15:$AB$115,15,FALSE) -> -250 | W18: ='115+260'!S19 -> 0 | X18: =+W18+X17 -> 0 | Y18: =S18-S17 -> 0 | Z18: =IF(Y18>0,Y18,0)/1000 -> 0 | AA18: =AA17+Z18 -> 0 | AB18: =(M18-$M$13-R18)/1000 -> 0
A19: =A18+1 -> 5 | B19: ='115+260'!B20 -> 45257 | C19: =B19-B18 -> 1 | D19: =D18 -> 1069 | E19: =VLOOKUP(B19,'115+260'!B20:AB121,3,FALSE) -> 1713 | F19: =D19+E19 -> 2782 | G19: =VLOOKUP(B19,'115+260'!$B$15:$AB$115,20,FALSE) -> -200 | H19: =VLOOKUP(B19,'115+260'!$B$15:$AB$115,4,FALSE) -> 982 | I19: =F19-H19 -> 1800 | J19: =VLOOKUP(B19,'115+260'!$B$15:$AB$115,13,FALSE) -> -200 | K19: ='115+260'!Q20 -> 0 | L19: =+K19+L18 -> 0 | M19: =VLOOKUP(B19,'115+260'!$B$14:$AB$115,21,FALSE) -> -220 | N19: =VLOOKUP(B19,'115+260'!$B$15:$AB$115,5,FALSE) -> 1002 | O19: =F19-N19 -> 1780 | P19: =VLOOKUP(B19,'115+260'!$B$15:$AB$115,14,FALSE) -> -220 | Q19: ='115+260'!R20 -> 0 | R19: =+Q19+R18 -> 0 | S19: =VLOOKUP(B19,'115+260'!$B$14:$AB$115,22,FALSE) -> -250 | T19: =VLOOKUP(B19,'115+260'!$B$15:$AB$115,6,FALSE) -> 1032 | U19: =F19-T19 -> 1750 | V19: =VLOOKUP(B19,'115+260'!$B$15:$AB$115,15,FALSE) -> -250 | W19: ='115+260'!S20 -> 0 | X19: =+W19+X18 -> 0 | Y19: =S19-S18 -> 0 | Z19: =IF(Y19>0,Y19,0)/1000 -> 0 | AA19: =AA18+Z19 -> 0 | AB19: =(M19-$M$13-R19)/1000 -> 0
A20: =A19+1 -> 6 | B20: ='115+260'!B21 -> 45258 | C20: =B20-B19 -> 1 | D20: =D19 -> 1069 | E20: =VLOOKUP(B20,'115+260'!B21:AB122,3,FALSE) -> 1711 | F20: =D20+E20 -> 2780 | G20: =VLOOKUP(B20,'115+260'!$B$15:$AB$115,20,FALSE) -> -200 | H20: =VLOOKUP(B20,'115+260'!$B$15:$AB$115,4,FALSE) -> 980 | I20: =F20-H20 -> 1800 | J20: =VLOOKUP(B20,'115+260'!$B$15:$AB$115,13,FALSE) -> -200 | K20: ='115+260'!Q21 -> 0 | L20: =+K20+L19 -> 0 | M20: =VLOOKUP(B20,'115+260'!$B$14:$AB$115,21,FALSE) -> -220 | N20: =VLOOKUP(B20,'115+260'!$B$15:$AB$115,5,FALSE) -> 1000 | O20: =F20-N20 -> 1780 | P20: =VLOOKUP(B20,'115+260'!$B$15:$AB$115,14,FALSE) -> -220 | Q20: ='115+260'!R21 -> 0 | R20: =+Q20+R19 -> 0 | S20: =VLOOKUP(B20,'115+260'!$B$14:$AB$115,22,FALSE) -> -250 | T20: =VLOOKUP(B20,'115+260'!$B$15:$AB$115,6,FALSE) -> 1030 | U20: =F20-T20 -> 1750 | V20: =VLOOKUP(B20,'115+260'!$B$15:$AB$115,15,FALSE) -> -250 | W20: ='115+260'!S21 -> 0 | X20: =+W20+X19 -> 0 | Y20: =S20-S19 -> 0 | Z20: =IF(Y20>0,Y20,0)/1000 -> 0 | AA20: =AA19+Z20 -> 0 | AB20: =(M20-$M$13-R20)/1000 -> 0
A21: =A20+1 -> 7 | B21: ='115+260'!B22 -> 45259 | C21: =B21-B20 -> 1 | D21: =D20 -> 1069 | E21: =VLOOKUP(B21,'115+260'!B22:AB123,3,FALSE) -> 1709 | F21: =D21+E21 -> 2778 | G21: =VLOOKUP(B21,'115+260'!$B$15:$AB$115,20,FALSE) -> -200 | H21: =VLOOKUP(B21,'115+260'!$B$15:$AB$115,4,FALSE) -> 978 | I21: =F21-H21 -> 1800 | J21: =VLOOKUP(B21,'115+260'!$B$15:$AB$115,13,FALSE) -> -200 | K21: ='115+260'!Q22 -> 0 | L21: =+K21+L20 -> 0 | M21: =VLOOKUP(B21,'115+260'!$B$14:$AB$115,21,FALSE) -> -220 | N21: =VLOOKUP(B21,'115+260'!$B$15:$AB$115,5,FALSE) -> 998 | O21: =F21-N21 -> 1780 | P21: =VLOOKUP(B21,'115+260'!$B$15:$AB$115,14,FALSE) -> -220 | Q21: ='115+260'!R22 -> 0 | R21: =+Q21+R20 -> 0 | S21: =VLOOKUP(B21,'115+260'!$B$14:$AB$115,22,FALSE) -> -250 | T21: =VLOOKUP(B21,'115+260'!$B$15:$AB$115,6,FALSE) -> 1028 | U21: =F21-T21 -> 1750 | V21: =VLOOKUP(B21,'115+260'!$B$15:$AB$115,15,FALSE) -> -250 | W21: ='115+260'!S22 -> 0 | X21: =+W21+X20 -> 0 | Y21: =S21-S20 -> 0 | Z21: =IF(Y21>0,Y21,0)/1000 -> 0 | AA21: =AA20+Z21 -> 0 | AB21: =(M21-$M$13-R21)/1000 -> 0
B22: ='115+260'!B23 -> 45260 | C22: =B22-B21 -> 1 | D22: =D21 -> 1069 | E22: =VLOOKUP(B22,'115+260'!B23:AB124,3,FALSE) -> 1707 | F22: =D22+E22 -> 2776 | G22: =VLOOKUP(B22,'115+260'!$B$15:$AB$115,20,FALSE) -> -200 | H22: =VLOOKUP(B22,'115+260'!$B$15:$AB$115,4,FALSE) -> 976 | I22: =F22-H22 -> 1800 | J22: =VLOOKUP(B22,'115+260'!$B$15:$AB$115,13,FALSE) -> -200 | K22: ='115+260'!Q23 -> 0 | L22: =+K22+L21 -> 0 | M22: =VLOOKUP(B22,'115+260'!$B$14:$AB$115,21,FALSE) -> -220 | N22: =VLOOKUP(B22,'115+260'!$B$15:$AB$115,5,FALSE) -> 996 | O22: =F22-N22 -> 1780 | P22: =VLOOKUP(B22,'115+260'!$B$15:$AB$115,14,FALSE) -> -220 | Q22: ='115+260'!R23 -> 0 | R22: =+Q22+R21 -> 0 | S22: =VLOOKUP(B22,'115+260'!$B$14:$AB$115,22,FALSE) -> -250 | T22: =VLOOKUP(B22,'115+260'!$B$15:$AB$115,6,FALSE) -> 1026 | U22: =F22-T22 -> 1750 | V22: =VLOOKUP(B22,'115+260'!$B$15:$AB$115,15,FALSE) -> -250 | W22: ='115+260'!S23 -> 0 | X22: =+W22+X21 -> 0 | Y22: =S22-S21 -> 0 | Z22: =IF(Y22>0,Y22,0)/1000 -> 0 | AA22: =AA21+Z22 -> 0 | AB22: =(M22-$M$13-R22)/1000 -> 0
B23: ='115+260'!B24 -> 45261 | C23: =B23-B22 -> 1 | D23: =D22 -> 1069 | E23: =VLOOKUP(B23,'115+260'!B24:AB125,3,FALSE) -> 1705 | F23: =D23+E23 -> 2774 | G23: =VLOOKUP(B23,'115+260'!$B$15:$AB$115,20,FALSE) -> -200 | H23: =VLOOKUP(B23,'115+260'!$B$15:$AB$115,4,FALSE) -> 974 | I23: =F23-H23 -> 1800 | J23: =VLOOKUP(B23,'115+260'!$B$15:$AB$115,13,FALSE) -> -200 | K23: ='115+260'!Q24 -> 0 | L23: =+K23+L22 -> 0 | M23: =VLOOKUP(B23,'115+260'!$B$14:$AB$115,21,FALSE) -> -220 | N23: =VLOOKUP(B23,'115+260'!$B$15:$AB$115,5,FALSE) -> 994 | O23: =F23-N23 -> 1780 | P23: =VLOOKUP(B23,'115+260'!$B$15:$AB$115,14,FALSE) -> -220 | Q23: ='115+260'!R24 -> 0 | R23: =+Q23+R22 -> 0 | S23: =VLOOKUP(B23,'115+260'!$B$14:$AB$115,22,FALSE) -> -250 | T23: =VLOOKUP(B23,'115+260'!$B$15:$AB$115,6,FALSE) -> 1024 | U23: =F23-T23 -> 1750 | V23: =VLOOKUP(B23,'115+260'!$B$15:$AB$115,15,FALSE) -> -250 | W23: ='115+260'!S24 -> 0 | X23: =+W23+X22 -> 0 | Y23: =S23-S22 -> 0 | Z23: =IF(Y23>0,Y23,0)/1000 -> 0 | AA23: =AA22+Z23 -> 0 | AB23: =(M23-$M$13-R23)/1000 -> 0
B24: ='115+260'!B25 -> 45262 | C24: =B24-B23 -> 1 | D24: =D23 -> 1069 | E24: =VLOOKUP(B24,'115+260'!B25:AB126,3,FALSE) -> 1703 | F24: =D24+E24 -> 2772 | G24: =VLOOKUP(B24,'115+260'!$B$15:$AB$115,20,FALSE) -> -200 | H24: =VLOOKUP(B24,'115+260'!$B$15:$AB$115,4,FALSE) -> 972 | I24: =F24-H24 -> 1800 | J24: =VLOOKUP(B24,'115+260'!$B$15:$AB$115,13,FALSE) -> -200 | K24: ='115+260'!Q25 -> 0 | L24: =+K24+L23 -> 0 | M24: =VLOOKUP(B24,'115+260'!$B$14:$AB$115,21,FALSE) -> -220 | N24: =VLOOKUP(B24,'115+260'!$B$15:$AB$115,5,FALSE) -> 992 | O24: =F24-N24 -> 1780 | P24: =VLOOKUP(B24,'115+260'!$B$15:$AB$115,14,FALSE) -> -220 | Q24: ='115+260'!R25 -> 0 | R24: =+Q24+R23 -> 0 | S24: =VLOOKUP(B24,'115+260'!$B$14:$AB$115,22,FALSE) -> -250 | T24: =VLOOKUP(B24,'115+260'!$B$15:$AB$115,6,FALSE) -> 1022 | U24: =F24-T24 -> 1750 | V24: =VLOOKUP(B24,'115+260'!$B$15:$AB$115,15,FALSE) -> -250 | W24: ='115+260'!S25 -> 0 | X24: =+W24+X23 -> 0 | Y24: =S24-S23 -> 0 | Z24: =IF(Y24>0,Y24,0)/1000 -> 0 | AA24: =AA23+Z24 -> 0 | AB24: =(M24-$M$13-R24)/1000 -> 0
B25: ='115+260'!B26 -> 45263 | C25: =B25-B24 -> 1 | D25: =D24 -> 1069 | E25: =VLOOKUP(B25,'115+260'!B26:AB127,3,FALSE) -> 1701 | F25: =D25+E25 -> 2770 | G25: =VLOOKUP(B25,'115+260'!$B$15:$AB$115,20,FALSE) -> -200 | H25: =VLOOKUP(B25,'115+260'!$B$15:$AB$115,4,FALSE) -> 970 | I25: =F25-H25 -> 1800 | J25: =VLOOKUP(B25,'115+260'!$B$15:$AB$115,13,FALSE) -> -200 | K25: ='115+260'!Q26 -> 0 | L25: =+K25+L24 -> 0 | M25: =VLOOKUP(B25,'115+260'!$B$14:$AB$115,21,FALSE) -> -220 | N25: =VLOOKUP(B25,'115+260'!$B$15:$AB$115,5,FALSE) -> 990 | O25: =F25-N25 -> 1780 | P25: =VLOOKUP(B25,'115+260'!$B$15:$AB$115,14,FALSE) -> -220 | Q25: ='115+260'!R26 -> 0 | R25: =+Q25+R24 -> 0 | S25: =VLOOKUP(B25,'115+260'!$B$14:$AB$115,22,FALSE) -> -250 | T25: =VLOOKUP(B25,'115+260'!$B$15:$AB$115,6,FALSE) -> 1020 | U25: =F25-T25 -> 1750 | V25: =VLOOKUP(B25,'115+260'!$B$15:$AB$115,15,FALSE) -> -250 | W25: ='115+260'!S26 -> 0 | X25: =+W25+X24 -> 0 | Y25: =S25-S24 -> 0 | Z25: =IF(Y25>0,Y25,0)/1000 -> 0 | AA25: =AA24+Z25 -> 0 | AB25: =(M25-$M$13-R25)/1000 -> 0
B26: ='115+260'!B27 -> 45264 | C26: =B26-B25 -> 1 | D26: =D25 -> 1069 | E26: =VLOOKUP(B26,'115+260'!B27:AB128,3,FALSE) -> 1699 | F26: =D26+E26 -> 2768 | G26: =VLOOKUP(B26,'115+260'!$B$15:$AB$115,20,FALSE) -> -200 | H26: =VLOOKUP(B26,'115+260'!$B$15:$AB$115,4,FALSE) -> 968 | I26: =F26-H26 -> 1800 | J26: =VLOOKUP(B26,'115+260'!$B$15:$AB$115,13,FALSE) -> -200 | K26: ='115+260'!Q27 -> 0 | L26: =+K26+L25 -> 0 | M26: =VLOOKUP(B26,'115+260'!$B$14:$AB$115,21,FALSE) -> -220 | N26: =VLOOKUP(B26,'115+260'!$B$15:$AB$115,5,FALSE) -> 988 | O26: =F26-N26 -> 1780 | P26: =VLOOKUP(B26,'115+260'!$B$15:$AB$115,14,FALSE) -> -220 | Q26: ='115+260'!R27 -> 0 | R26: =+Q26+R25 -> 0 | S26: =VLOOKUP(B26,'115+260'!$B$14:$AB$115,22,FALSE) -> -250 | T26: =VLOOKUP(B26,'115+260'!$B$15:$AB$115,6,FALSE) -> 1018 | U26: =F26-T26 -> 1750 | V26: =VLOOKUP(B26,'115+260'!$B$15:$AB$115,15,FALSE) -> -250 | W26: ='115+260'!S27 -> 0 | X26: =+W26+X25 -> 0 | Y26: =S26-S25 -> 0 | Z26: =IF(Y26>0,Y26,0)/1000 -> 0 | AA26: =AA25+Z26 -> 0 | AB26: =(M26-$M$13-R26)/1000 -> 0
B27: ='115+260'!B28 -> 45265 | C27: =B27-B26 -> 1 | D27: =D26 -> 1069 | E27: =VLOOKUP(B27,'115+260'!B28:AB129,3,FALSE) -> 1697 | F27: =D27+E27 -> 2766 | G27: =VLOOKUP(B27,'115+260'!$B$15:$AB$115,20,FALSE) -> -200 | H27: =VLOOKUP(B27,'115+260'!$B$15:$AB$115,4,FALSE) -> 966 | I27: =F27-H27 -> 1800 | J27: =VLOOKUP(B27,'115+260'!$B$15:$AB$115,13,FALSE) -> -200 | K27: ='115+260'!Q28 -> 0 | L27: =+K27+L26 -> 0 | M27: =VLOOKUP(B27,'115+260'!$B$14:$AB$115,21,FALSE) -> -220 | N27: =VLOOKUP(B27,'115+260'!$B$15:$AB$115,5,FALSE) -> 986 | O27: =F27-N27 -> 1780 | P27: =VLOOKUP(B27,'115+260'!$B$15:$AB$115,14,FALSE) -> -220 | Q27: ='115+260'!R28 -> 0 | R27: =+Q27+R26 -> 0 | S27: =VLOOKUP(B27,'115+260'!$B$14:$AB$115,22,FALSE) -> -250 | T27: =VLOOKUP(B27,'115+260'!$B$15:$AB$115,6,FALSE) -> 1016 | U27: =F27-T27 -> 1750 | V27: =VLOOKUP(B27,'115+260'!$B$15:$AB$115,15,FALSE) -> -250 | W27: ='115+260'!S28 -> 0 | X27: =+W27+X26 -> 0 | Y27: =S27-S26 -> 0 | Z27: =IF(Y27>0,Y27,0)/1000 -> 0 | AA27: =AA26+Z27 -> 0 | AB27: =(M27-$M$13-R27)/1000 -> 0
B28: ='115+260'!B29 -> 45266 | C28: =B28-B27 -> 1 | D28: =D27 -> 1069 | E28: =VLOOKUP(B28,'115+260'!B29:AB130,3,FALSE) -> 1695 | F28: =D28+E28 -> 2764 | G28: =VLOOKUP(B28,'115+260'!$B$15:$AB$115,20,FALSE) -> -200 | H28: =VLOOKUP(B28,'115+260'!$B$15:$AB$115,4,FALSE) -> 964 | I28: =F28-H28 -> 1800 | J28: =VLOOKUP(B28,'115+260'!$B$15:$AB$115,13,FALSE) -> -200 | K28: ='115+260'!Q29 -> 0 | L28: =+K28+L27 -> 0 | M28: =VLOOKUP(B28,'115+260'!$B$14:$AB$115,21,FALSE) -> -220 | N28: =VLOOKUP(B28,'115+260'!$B$15:$AB$115,5,FALSE) -> 984 | O28: =F28-N28 -> 1780 | P28: =VLOOKUP(B28,'115+260'!$B$15:$AB$115,14,FALSE) -> -220 | Q28: ='115+260'!R29 -> 0 | R28: =+Q28+R27 -> 0 | S28: =VLOOKUP(B28,'115+260'!$B$14:$AB$115,22,FALSE) -> -250 | T28: =VLOOKUP(B28,'115+260'!$B$15:$AB$115,6,FALSE) -> 1014 | U28: =F28-T28 -> 1750 | V28: =VLOOKUP(B28,'115+260'!$B$15:$AB$115,15,FALSE) -> -250 | W28: ='115+260'!S29 -> 0 | X28: =+W28+X27 -> 0 | Y28: =S28-S27 -> 0 | Z28: =IF(Y28>0,Y28,0)/1000 -> 0 | AA28: =AA27+Z28 -> 0 | AB28: =(M28-$M$13-R28)/1000 -> 0
B29: ='115+260'!B30 -> 45267 | C29: =B29-B28 -> 1 | D29: =D28 -> 1069 | E29: =VLOOKUP(B29,'115+260'!B30:AB131,3,FALSE) -> 1693 | F29: =D29+E29 -> 2762 | G29: =VLOOKUP(B29,'115+260'!$B$15:$AB$115,20,FALSE) -> -200 | H29: =VLOOKUP(B29,'115+260'!$B$15:$AB$115,4,FALSE) -> 962 | I29: =F29-H29 -> 1800 | J29: =VLOOKUP(B29,'115+260'!$B$15:$AB$115,13,FALSE) -> -200 | K29: ='115+260'!Q30 -> 0 | L29: =+K29+L28 -> 0 | M29: =VLOOKUP(B29,'115+260'!$B$14:$AB$115,21,FALSE) -> -220 | N29: =VLOOKUP(B29,'115+260'!$B$15:$AB$115,5,FALSE) -> 982 | O29: =F29-N29 -> 1780 | P29: =VLOOKUP(B29,'115+260'!$B$15:$AB$115,14,FALSE) -> -220 | Q29: ='115+260'!R30 -> 0 | R29: =+Q29+R28 -> 0 | S29: =VLOOKUP(B29,'115+260'!$B$14:$AB$115,22,FALSE) -> -250 | T29: =VLOOKUP(B29,'115+260'!$B$15:$AB$115,6,FALSE) -> 1012 | U29: =F29-T29 -> 1750 | V29: =VLOOKUP(B29,'115+260'!$B$15:$AB$115,15,FALSE) -> -250 | W29: ='115+260'!S30 -> 0 | X29: =+W29+X28 -> 0 | Y29: =S29-S28 -> 0 | Z29: =IF(Y29>0,Y29,0)/1000 -> 0 | AA29: =AA28+Z29 -> 0 | AB29: =(M29-$M$13-R29)/1000 -> 0
B30: ='115+260'!B31 -> 45268 | C30: =B30-B29 -> 1 | D30: =D29 -> 1069 | E30: =VLOOKUP(B30,'115+260'!B31:AB132,3,FALSE) -> 1691 | F30: =D30+E30 -> 2760 | G30: =VLOOKUP(B30,'115+260'!$B$15:$AB$115,20,FALSE) -> 91 | H30: =VLOOKUP(B30,'115+260'!$B$15:$AB$115,4,FALSE) -> 969 | I30: =F30-H30 -> 1791 | J30: =VLOOKUP(B30,'115+260'!$B$15:$AB$115,13,FALSE) -> -209 | K30: ='115+260'!Q31 -> 9 | L30: =+K30+L29 -> 9 | M30: =VLOOKUP(B30,'115+260'!$B$14:$AB$115,21,FALSE) -> 72 | N30: =VLOOKUP(B30,'115+260'!$B$15:$AB$115,5,FALSE) -> 988 | O30: =F30-N30 -> 1772 | P30: =VLOOKUP(B30,'115+260'!$B$15:$AB$115,14,FALSE) -> -228 | Q30: ='115+260'!R31 -> 8 | R30: =+Q30+R29 -> 8 | S30: =VLOOKUP(B30,'115+260'!$B$14:$AB$115,22,FALSE) -> 41 | T30: =VLOOKUP(B30,'115+260'!$B$15:$AB$115,6,FALSE) -> 1019 | U30: =F30-T30 -> 1741 | V30: =VLOOKUP(B30,'115+260'!$B$15:$AB$115,15,FALSE) -> -259 | W30: ='115+260'!S31 -> 9 | X30: =+W30+X29 -> 9 | Y30: =S30-S29 -> 291 | Z30: =IF(Y30>0,Y30,0)/1000 -> 0.291 | AA30: =AA29+Z30 -> 0.291 | AB30: =(M30-$M$13-R30)/1000 -> 0.284
B31: ='115+260'!B32 -> 45269 | C31: =B31-B30 -> 1 | D31: =D30 -> 1069 | E31: =VLOOKUP(B31,'115+260'!B32:AB133,3,FALSE) -> 1689 | F31: =D31+E31 -> 2758 | G31: =VLOOKUP(B31,'115+260'!$B$15:$AB$115,20,FALSE) -> 88 | H31: =VLOOKUP(B31,'115+260'!$B$15:$AB$115,4,FALSE) -> 970 | I31: =F31-H31 -> 1788 | J31: =VLOOKUP(B31,'115+260'!$B$15:$AB$115,13,FALSE) -> -212 | K31: ='115+260'!Q32 -> 3 | L31: =+K31+L30 -> 12 | M31: =VLOOKUP(B31,'115+260'!$B$14:$AB$115,21,FALSE) -> 69 | N31: =VLOOKUP(B31,'115+260'!$B$15:$AB$115,5,FALSE) -> 989 | O31: =F31-N31 -> 1769 | P31: =VLOOKUP(B31,'115+260'!$B$15:$AB$115,14,FALSE) -> -231 | Q31: ='115+260'!R32 -> 3 | R31: =+Q31+R30 -> 11 | S31: =VLOOKUP(B31,'115+260'!$B$14:$AB$115,22,FALSE) -> 38 | T31: =VLOOKUP(B31,'115+260'!$B$15:$AB$115,6,FALSE) -> 1020 | U31: =F31-T31 -> 1738 | V31: =VLOOKUP(B31,'115+260'!$B$15:$AB$115,15,FALSE) -> -262 | W31: ='115+260'!S32 -> 3 | X31: =+W31+X30 -> 12 | Y31: =S31-S30 -> -3 | Z31: =IF(Y31>0,Y31,0)/1000 -> 0 | AA31: =AA30+Z31 -> 0.291 | AB31: =(M31-$M$13-R31)/1000 -> 0.278
B32: ='115+260'!B33 -> 45270 | C32: =B32-B31 -> 1 | D32: =D31 -> 1069 | E32: =VLOOKUP(B32,'115+260'!B33:AB134,3,FALSE) -> 1687 | F32: =D32+E32 -> 2756 | G32: =VLOOKUP(B32,'115+260'!$B$15:$AB$115,20,FALSE) -> 84 | H32: =VLOOKUP(B32,'115+260'!$B$15:$AB$115,4,FALSE) -> 972 | I32: =F32-H32 -> 1784 | J32: =VLOOKUP(B32,'115+260'!$B$15:$AB$115,13,FALSE) -> -216 | K32: ='115+260'!Q33 -> 4 | L32: =+K32+L31 -> 16 | M32: =VLOOKUP(B32,'115+260'!$B$14:$AB$115,21,FALSE) -> 64 | N32: =VLOOKUP(B32,'115+260'!$B$15:$AB$115,5,FALSE) -> 992 | O32: =F32-N32 -> 1764 | P32: =VLOOKUP(B32,'115+260'!$B$15:$AB$115,14,FALSE) -> -236 | Q32: ='115+260'!R33 -> 5 | R32: =+Q32+R31 -> 16 | S32: =VLOOKUP(B32,'115+260'!$B$14:$AB$115,22,FALSE) -> 34 | T32: =VLOOKUP(B32,'115+260'!$B$15:$AB$115,6,FALSE) -> 1022 | U32: =F32-T32 -> 1734 | V32: =VLOOKUP(B32,'115+260'!$B$15:$AB$115,15,FALSE) -> -266 | W32: ='115+260'!S33 -> 4 | X32: =+W32+X31 -> 16 | Y32: =S32-S31 -> -4 | Z32: =IF(Y32>0,Y32,0)/1000 -> 0 | AA32: =AA31+Z32 -> 0.291 | AB32: =(M32-$M$13-R32)/1000 -> 0.268
B33: ='115+260'!B34 -> 45271 | C33: =B33-B32 -> 1 | D33: =D32 -> 1069 | E33: =VLOOKUP(B33,'115+260'!B34:AB135,3,FALSE) -> 1685 | F33: =D33+E33 -> 2754 | G33: =VLOOKUP(B33,'115+260'!$B$15:$AB$115,20,FALSE) -> 78 | H33: =VLOOKUP(B33,'115+260'!$B$15:$AB$115,4,FALSE) -> 976 | I33: =F33-H33 -> 1778 | J33: =VLOOKUP(B33,'115+260'!$B$15:$AB$115,13,FALSE) -> -222 | K33: ='115+260'!Q34 -> 6 | L33: =+K33+L32 -> 22 | M33: =VLOOKUP(B33,'115+260'!$B$14:$AB$115,21,FALSE) -> 61 | N33: =VLOOKUP(B33,'115+260'!$B$15:$AB$115,5,FALSE) -> 993 | O33: =F33-N33 -> 1761 | P33: =VLOOKUP(B33,'115+260'!$B$15:$AB$115,14,FALSE) -> -239 | Q33: ='115+260'!R34 -> 3 | R33: =+Q33+R32 -> 19 | S33: =VLOOKUP(B33,'115+260'!$B$14:$AB$115,22,FALSE) -> 31 | T33: =VLOOKUP(B33,'115+260'!$B$15:$AB$115,6,FALSE) -> 1023 | U33: =F33-T33 -> 1731 | V33: =VLOOKUP(B33,'115+260'!$B$15:$AB$115,15,FALSE) -> -269 | W33: ='115+260'!S34 -> 3 | X33: =+W33+X32 -> 19 | Y33: =S33-S32 -> -3 | Z33: =IF(Y33>0,Y33,0)/1000 -> 0 | AA33: =AA32+Z33 -> 0.291 | AB33: =(M33-$M$13-R33)/1000 -> 0.262
... B76: ='115+260'!B77 -> 45314 | C76: =B76-B75 -> 1 | D76: =D75 -> 1069 | E76: =VLOOKUP(B76,'115+260'!B77:AB178,3,FALSE) -> 1599 | F76: =D76+E76 -> 2668 | G76: =VLOOKUP(B76,'115+260'!$B$15:$AB$115,20,FALSE) -> 959 | H76: =VLOOKUP(B76,'115+260'!$B$15:$AB$115,4,FALSE) -> 1009 | I76: =F76-H76 -> 1659 | J76: =VLOOKUP(B76,'115+260'!$B$15:$AB$115,13,FALSE) -> -341 | K76: ='115+260'!Q77 -> 0 | L76: =+K76+L75 -> 141 | M76: =VLOOKUP(B76,'115+260'!$B$14:$AB$115,21,FALSE) -> 969 | N76: =VLOOKUP(B76,'115+260'!$B$15:$AB$115,5,FALSE) -> 1019 | O76: =F76-N76 -> 1649 | P76: =VLOOKUP(B76,'115+260'!$B$15:$AB$115,14,FALSE) -> -351 | Q76: ='115+260'!R77 -> 0 | R76: =+Q76+R75 -> 131 | S76: =VLOOKUP(B76,'115+260'!$B$14:$AB$115,22,FALSE) -> 975 | T76: =VLOOKUP(B76,'115+260'!$B$15:$AB$115,6,FALSE) -> 1043 | U76: =F76-T76 -> 1625 | V76: =VLOOKUP(B76,'115+260'!$B$15:$AB$115,15,FALSE) -> -375 | W76: ='115+260'!S77 -> 0 | X76: =+W76+X75 -> 125 | Y76: =S76-S75 -> 0 | Z76: =IF(Y76>0,Y76,0)/1000 -> 0 | AA76: =AA75+Z76 -> 1.306 | AB76: =(M76-$M$13-R76)/1000 -> 1.058
A77: 42307 | B77: ='115+260'!B78 -> 45315 | C77: =B77-B76 -> 1 | D77: =D76 -> 1069 | E77: =VLOOKUP(B77,'115+260'!B78:AB179,3,FALSE) -> 1597 | F77: =D77+E77 -> 2666 | G77: =VLOOKUP(B77,'115+260'!$B$15:$AB$115,20,FALSE) -> 959 | H77: =VLOOKUP(B77,'115+260'!$B$15:$AB$115,4,FALSE) -> 1007 | I77: =F77-H77 -> 1659 | J77: =VLOOKUP(B77,'115+260'!$B$15:$AB$115,13,FALSE) -> -341 | K77: ='115+260'!Q78 -> 0 | L77: =+K77+L76 -> 141 | M77: =VLOOKUP(B77,'115+260'!$B$14:$AB$115,21,FALSE) -> 969 | N77: =VLOOKUP(B77,'115+260'!$B$15:$AB$115,5,FALSE) -> 1017 | O77: =F77-N77 -> 1649 | P77: =VLOOKUP(B77,'115+260'!$B$15:$AB$115,14,FALSE) -> -351 | Q77: ='115+260'!R78 -> 0 | R77: =+Q77+R76 -> 131 | S77: =VLOOKUP(B77,'115+260'!$B$14:$AB$115,22,FALSE) -> 975 | T77: =VLOOKUP(B77,'115+260'!$B$15:$AB$115,6,FALSE) -> 1041 | U77: =F77-T77 -> 1625 | V77: =VLOOKUP(B77,'115+260'!$B$15:$AB$115,15,FALSE) -> -375 | W77: ='115+260'!S78 -> 0 | X77: =+W77+X76 -> 125 | Y77: =S77-S76 -> 0 | Z77: =IF(Y77>0,Y77,0)/1000 -> 0 | AA77: =AA76+Z77 -> 1.306 | AB77: =(M77-$M$13-R77)/1000 -> 1.058
A78: 02/11/015 | B78: ='115+260'!B79 -> 45316 | C78: =B78-B77 -> 1 | D78: =D77 -> 1069 | E78: =VLOOKUP(B78,'115+260'!B79:AB180,3,FALSE) -> 1595 | F78: =D78+E78 -> 2664 | G78: =VLOOKUP(B78,'115+260'!$B$15:$AB$115,20,FALSE) -> 959 | H78: =VLOOKUP(B78,'115+260'!$B$15:$AB$115,4,FALSE) -> 1005 | I78: =F78-H78 -> 1659 | J78: =VLOOKUP(B78,'115+260'!$B$15:$AB$115,13,FALSE) -> -341 | K78: ='115+260'!Q79 -> 0 | L78: =+K78+L77 -> 141 | M78: =VLOOKUP(B78,'115+260'!$B$14:$AB$115,21,FALSE) -> 969 | N78: =VLOOKUP(B78,'115+260'!$B$15:$AB$115,5,FALSE) -> 1015 | O78: =F78-N78 -> 1649 | P78: =VLOOKUP(B78,'115+260'!$B$15:$AB$115,14,FALSE) -> -351 | Q78: ='115+260'!R79 -> 0 | R78: =+Q78+R77 -> 131 | S78: =VLOOKUP(B78,'115+260'!$B$14:$AB$115,22,FALSE) -> 975 | T78: =VLOOKUP(B78,'115+260'!$B$15:$AB$115,6,FALSE) -> 1039 | U78: =F78-T78 -> 1625 | V78: =VLOOKUP(B78,'115+260'!$B$15:$AB$115,15,FALSE) -> -375 | W78: ='115+260'!S79 -> 0 | X78: =+W78+X77 -> 125 | Y78: =S78-S77 -> 0 | Z78: =IF(Y78>0,Y78,0)/1000 -> 0 | AA78: =AA77+Z78 -> 1.306 | AB78: =(M78-$M$13-R78)/1000 -> 1.058
A79: 42313 | B79: ='115+260'!B80 -> 45317 | C79: =B79-B78 -> 1 | D79: =D78 -> 1069 | E79: =VLOOKUP(B79,'115+260'!B80:AB181,3,FALSE) -> 1593 | F79: =D79+E79 -> 2662 | G79: =VLOOKUP(B79,'115+260'!$B$15:$AB$115,20,FALSE) -> 959 | H79: =VLOOKUP(B79,'115+260'!$B$15:$AB$115,4,FALSE) -> 1003 | I79: =F79-H79 -> 1659 | J79: =VLOOKUP(B79,'115+260'!$B$15:$AB$115,13,FALSE) -> -341 | K79: ='115+260'!Q80 -> 0 | L79: =+K79+L78 -> 141 | M79: =VLOOKUP(B79,'115+260'!$B$14:$AB$115,21,FALSE) -> 969 | N79: =VLOOKUP(B79,'115+260'!$B$15:$AB$115,5,FALSE) -> 1013 | O79: =F79-N79 -> 1649 | P79: =VLOOKUP(B79,'115+260'!$B$15:$AB$115,14,FALSE) -> -351 | Q79: ='115+260'!R80 -> 0 | R79: =+Q79+R78 -> 131 | S79: =VLOOKUP(B79,'115+260'!$B$14:$AB$115,22,FALSE) -> 975 | T79: =VLOOKUP(B79,'115+260'!$B$15:$AB$115,6,FALSE) -> 1037 | U79: =F79-T79 -> 1625 | V79: =VLOOKUP(B79,'115+260'!$B$15:$AB$115,15,FALSE) -> -375 | W79: ='115+260'!S80 -> 0 | X79: =+W79+X78 -> 125 | Y79: =S79-S78 -> 0 | Z79: =IF(Y79>0,Y79,0)/1000 -> 0 | AA79: =AA78+Z79 -> 1.306 | AB79: =(M79-$M$13-R79)/1000 -> 1.058
A80: 42319 | B80: ='115+260'!B81 -> 45318 | C80: =B80-B79 -> 1 | D80: =D79 -> 1069 | E80: =VLOOKUP(B80,'115+260'!B81:AB182,3,FALSE) -> 1591 | F80: =D80+E80 -> 2660 | G80: =VLOOKUP(B80,'115+260'!$B$15:$AB$115,20,FALSE) -> 959 | H80: =VLOOKUP(B80,'115+260'!$B$15:$AB$115,4,FALSE) -> 1001 | I80: =F80-H80 -> 1659 | J80: =VLOOKUP(B80,'115+260'!$B$15:$AB$115,13,FALSE) -> -341 | K80: ='115+260'!Q81 -> 0 | L80: =+K80+L79 -> 141 | M80: =VLOOKUP(B80,'115+260'!$B$14:$AB$115,21,FALSE) -> 969 | N80: =VLOOKUP(B80,'115+260'!$B$15:$AB$115,5,FALSE) -> 1011 | O80: =F80-N80 -> 1649 | P80: =VLOOKUP(B80,'115+260'!$B$15:$AB$115,14,FALSE) -> -351 | Q80: ='115+260'!R81 -> 0 | R80: =+Q80+R79 -> 131 | S80: =VLOOKUP(B80,'115+260'!$B$14:$AB$115,22,FALSE) -> 975 | T80: =VLOOKUP(B80,'115+260'!$B$15:$AB$115,6,FALSE) -> 1035 | U80: =F80-T80 -> 1625 | V80: =VLOOKUP(B80,'115+260'!$B$15:$AB$115,15,FALSE) -> -375 | W80: ='115+260'!S81 -> 0 | X80: =+W80+X79 -> 125 | Y80: =S80-S79 -> 0 | Z80: =IF(Y80>0,Y80,0)/1000 -> 0 | AA80: =AA79+Z80 -> 1.306 | AB80: =(M80-$M$13-R80)/1000 -> 1.058
A81: 42322 | B81: ='115+260'!B82 -> 45319 | C81: =B81-B80 -> 1 | D81: =D80 -> 1069 | E81: =VLOOKUP(B81,'115+260'!B82:AB183,3,FALSE) -> 1589 | F81: =D81+E81 -> 2658 | G81: =VLOOKUP(B81,'115+260'!$B$15:$AB$115,20,FALSE) -> 959 | H81: =VLOOKUP(B81,'115+260'!$B$15:$AB$115,4,FALSE) -> 999 | I81: =F81-H81 -> 1659 | J81: =VLOOKUP(B81,'115+260'!$B$15:$AB$115,13,FALSE) -> -341 | K81: ='115+260'!Q82 -> 0 | L81: =+K81+L80 -> 141 | M81: =VLOOKUP(B81,'115+260'!$B$14:$AB$115,21,FALSE) -> 969 | N81: =VLOOKUP(B81,'115+260'!$B$15:$AB$115,5,FALSE) -> 1009 | O81: =F81-N81 -> 1649 | P81: =VLOOKUP(B81,'115+260'!$B$15:$AB$115,14,FALSE) -> -351 | Q81: ='115+260'!R82 -> 0 | R81: =+Q81+R80 -> 131 | S81: =VLOOKUP(B81,'115+260'!$B$14:$AB$115,22,FALSE) -> 975 | T81: =VLOOKUP(B81,'115+260'!$B$15:$AB$115,6,FALSE) -> 1033 | U81: =F81-T81 -> 1625 | V81: =VLOOKUP(B81,'115+260'!$B$15:$AB$115,15,FALSE) -> -375 | W81: ='115+260'!S82 -> 0 | X81: =+W81+X80 -> 125 | Y81: =S81-S80 -> 0 | Z81: =IF(Y81>0,Y81,0)/1000 -> 0 | AA81: =AA80+Z81 -> 1.306 | AB81: =(M81-$M$13-R81)/1000 -> 1.058
A82: 17/11/015 | B82: ='115+260'!B83 -> 45320 | C82: =B82-B81 -> 1 | D82: =D81 -> 1069 | E82: =VLOOKUP(B82,'115+260'!B83:AB184,3,FALSE) -> 1587 | F82: =D82+E82 -> 2656 | G82: =VLOOKUP(B82,'115+260'!$B$15:$AB$115,20,FALSE) -> 959 | H82: =VLOOKUP(B82,'115+260'!$B$15:$AB$115,4,FALSE) -> 997 | I82: =F82-H82 -> 1659 | J82: =VLOOKUP(B82,'115+260'!$B$15:$AB$115,13,FALSE) -> -341 | K82: ='115+260'!Q83 -> 0 | L82: =+K82+L81 -> 141 | M82: =VLOOKUP(B82,'115+260'!$B$14:$AB$115,21,FALSE) -> 969 | N82: =VLOOKUP(B82,'115+260'!$B$15:$AB$115,5,FALSE) -> 1007 | O82: =F82-N82 -> 1649 | P82: =VLOOKUP(B82,'115+260'!$B$15:$AB$115,14,FALSE) -> -351 | Q82: ='115+260'!R83 -> 0 | R82: =+Q82+R81 -> 131 | S82: =VLOOKUP(B82,'115+260'!$B$14:$AB$115,22,FALSE) -> 975 | T82: =VLOOKUP(B82,'115+260'!$B$15:$AB$115,6,FALSE) -> 1031 | U82: =F82-T82 -> 1625 | V82: =VLOOKUP(B82,'115+260'!$B$15:$AB$115,15,FALSE) -> -375 | W82: ='115+260'!S83 -> 0 | X82: =+W82+X81 -> 125 | Y82: =S82-S81 -> 0 | Z82: =IF(Y82>0,Y82,0)/1000 -> 0 | AA82: =AA81+Z82 -> 1.306 | AB82: =(M82-$M$13-R82)/1000 -> 1.058
A83: 42328 | B83: ='115+260'!B84 -> 45321 | C83: =B83-B82 -> 1 | D83: =D82 -> 1069 | E83: =VLOOKUP(B83,'115+260'!B84:AB185,3,FALSE) -> 1585 | F83: =D83+E83 -> 2654 | G83: =VLOOKUP(B83,'115+260'!$B$15:$AB$115,20,FALSE) -> 959 | H83: =VLOOKUP(B83,'115+260'!$B$15:$AB$115,4,FALSE) -> 995 | I83: =F83-H83 -> 1659 | J83: =VLOOKUP(B83,'115+260'!$B$15:$AB$115,13,FALSE) -> -341 | K83: ='115+260'!Q84 -> 0 | L83: =+K83+L82 -> 141 | M83: =VLOOKUP(B83,'115+260'!$B$14:$AB$115,21,FALSE) -> 969 | N83: =VLOOKUP(B83,'115+260'!$B$15:$AB$115,5,FALSE) -> 1005 | O83: =F83-N83 -> 1649 | P83: =VLOOKUP(B83,'115+260'!$B$15:$AB$115,14,FALSE) -> -351 | Q83: ='115+260'!R84 -> 0 | R83: =+Q83+R82 -> 131 | S83: =VLOOKUP(B83,'115+260'!$B$14:$AB$115,22,FALSE) -> 975 | T83: =VLOOKUP(B83,'115+260'!$B$15:$AB$115,6,FALSE) -> 1029 | U83: =F83-T83 -> 1625 | V83: =VLOOKUP(B83,'115+260'!$B$15:$AB$115,15,FALSE) -> -375 | W83: ='115+260'!S84 -> 0 | X83: =+W83+X82 -> 125 | Y83: =S83-S82 -> 0 | Z83: =IF(Y83>0,Y83,0)/1000 -> 0 | AA83: =AA82+Z83 -> 1.306 | AB83: =(M83-$M$13-R83)/1000 -> 1.058
...

Sheet SL.115+260
A1: DỰ ÁN THÀNH PHẦN ĐOẠN HẬU GIANG - CÀ MAU
A2: THUỘC DỰ ÁN XÂY DỰNG CÔNG TRÌNH ĐƯỜNG BỘ CAO TỐC BẮC - NAM PHÍA ĐÔNG GIAI ĐOẠN 2021 - 2025
A3: =UPPER("GÓI THẦU XL03 :Thi Công Xây Dựng Đoạn Tuyến Km114+200 - Km126+223 Bao Gồm Tuyến Nối Nút Giao IC12 Với QL1 (bao gồm khảo sát, thiết kế BVTC)") -> GÓI THẦU XL03 :THI CÔNG XÂY DỰNG ĐOẠN TUYẾN KM114+200 - KM126+223 BAO GỒM TUYẾN NỐI NÚT GIAO IC12 VỚI QL1 (BAO GỒM KHẢO SÁT, THIẾT KẾ BVTC)
A4: CHỦ ĐẦU TƯ | F4: TƯ VẤN GIÁM SÁT | K4: NHÀ THẦU
A5: BAN QUẢN LÝ DỰ ÁN MỸ THUẬN | F5: =UPPER("Liên danh Phân viện KHCN GTVT phía Nam - Công ty Cổ phần Tư vấn kỹ thuật và xây dựng Hồng Hà") -> LIÊN DANH PHÂN VIỆN KHCN GTVT PHÍA NAM - CÔNG TY CỔ PHẦN TƯ VẤN KỸ THUẬT VÀ XÂY DỰNG HỒNG HÀ | K5: LIÊN DANH CC1 - HẢI ĐĂNG - VẠN CƯỜNG - 492 - BẮC TRUNG NAM
A6: BIỂU GHI ĐO QUAN TRẮC LÚN
A7: Người lập: | B7: ='[4]BC.95+020'!C7 -> 0 | K7: Tên mốc: | M7: ='[4]BC.95+020'!N7 -> 0
A8: Thời tiết: | B8: ='[4]BC.95+020'!C8 -> năng | K8: Cao độ mốc: | M8: ='115+260'!M9 -> 1069
A9: Lý trình: | B9: ='115+260'!C10 -> Km115+260 | K9: Ngày đặt bàn: | M9: ='115+260'!M10 -> 45251
A11: ="BÀN QUAN TRẮC: "&B9 -> BÀN QUAN TRẮC: Km115+260
A12: Ngày đo | B12: Số ngày | C12: Cao độ đắp(m) | D12: Chiều cao nền đắp (m) | E12: chiều dày đắp(m) | F12: Trái | H12: Giữa | J12: Phải | L12: Độ lún (trái) (mm) | M12: Độ lún (giữa) (mm) | N12: Độ lún (phải) (mm) | O12: Ghi chú
F13: Cao độ quan trắc | G13: Cao độ bàn đo lún | H13: Cao độ quan trắc | I13: Cao độ bàn đo lún | J13: Cao độ quan trắc | K13: Cao độ bàn đo lún
A14: ='BC.115+260'!B13 -> 45251 | B14: 0 | C14: ='BC.115+260'!M13/1000 -> -0.22 | D14: ='BC.115+260'!AA13 -> 0 | E14: ='BC.115+260'!AB13 -> 0 | F14: =VLOOKUP($A14,'BC.115+260'!$B$13:$X$489,8,0)/1000 -> 1.8 | G14: =VLOOKUP($A14,'BC.115+260'!$B$13:$X$489,9,0)/1000 -> -0.2 | H14: =VLOOKUP($A14,'BC.115+260'!$B$13:$X$489,14,0)/1000 -> 1.78 | I14: =VLOOKUP($A14,'BC.115+260'!$B$13:$X$489,15,0)/1000 -> -0.22 | J14: =VLOOKUP($A14,'BC.115+260'!$B$13:$X$489,20,0)/1000 -> 1.75 | K14: =VLOOKUP($A14,'BC.115+260'!$B$13:$X$489,21,0)/1000 -> -0.25 | L14: =(G14-$G$14)*1000 -> 0 | M14: =(I14-$I$14)*1000 -> 0 | N14: 0
A15: ='BC.115+260'!B14 -> 45252 | B15: 1 | C15: ='BC.115+260'!M14/1000 -> -0.22 | D15: ='BC.115+260'!AA14 -> 0 | E15: ='BC.115+260'!AB14 -> 0 | F15: =VLOOKUP($A15,'BC.115+260'!$B$13:$X$489,8,0)/1000 -> 1.8 | G15: =VLOOKUP($A15,'BC.115+260'!$B$13:$X$489,9,0)/1000 -> -0.2 | H15: =VLOOKUP($A15,'BC.115+260'!$B$13:$X$489,14,0)/1000 -> 1.78 | I15: =VLOOKUP($A15,'BC.115+260'!$B$13:$X$489,15,0)/1000 -> -0.22 | J15: =VLOOKUP($A15,'BC.115+260'!$B$13:$X$489,20,0)/1000 -> 1.75 | K15: =VLOOKUP($A15,'BC.115+260'!$B$13:$X$489,21,0)/1000 -> -0.25 | L15: =(G15-$G$14)*1000 -> 0 | M15: =(I15-$I$14)*1000 -> 0 | N15: =(K15-$K$14)*1000 -> 0
A16: ='BC.115+260'!B15 -> 45253 | B16: 2 | C16: ='BC.115+260'!M15/1000 -> -0.22 | D16: ='BC.115+260'!AA15 -> 0 | E16: ='BC.115+260'!AB15 -> 0 | F16: =VLOOKUP($A16,'BC.115+260'!$B$13:$X$489,8,0)/1000 -> 1.8 | G16: =VLOOKUP($A16,'BC.115+260'!$B$13:$X$489,9,0)/1000 -> -0.2 | H16: =VLOOKUP($A16,'BC.115+260'!$B$13:$X$489,14,0)/1000 -> 1.78 | I16: =VLOOKUP($A16,'BC.115+260'!$B$13:$X$489,15,0)/1000 -> -0.22 | J16: =VLOOKUP($A16,'BC.115+260'!$B$13:$X$489,20,0)/1000 -> 1.75 | K16: =VLOOKUP($A16,'BC.115+260'!$B$13:$X$489,21,0)/1000 -> -0.25 | L16: =(G16-$G$14)*1000 -> 0 | M16: =(I16-$I$14)*1000 -> 0 | N16: =(K16-$K$14)*1000 -> 0
A17: ='BC.115+260'!B16 -> 45254 | B17: 3 | C17: ='BC.115+260'!M16/1000 -> -0.22 | D17: ='BC.115+260'!AA16 -> 0 | E17: ='BC.115+260'!AB16 -> 0 | F17: =VLOOKUP($A17,'BC.115+260'!$B$13:$X$489,8,0)/1000 -> 1.8 | G17: =VLOOKUP($A17,'BC.115+260'!$B$13:$X$489,9,0)/1000 -> -0.2 | H17: =VLOOKUP($A17,'BC.115+260'!$B$13:$X$489,14,0)/1000 -> 1.78 | I17: =VLOOKUP($A17,'BC.115+260'!$B$13:$X$489,15,0)/1000 -> -0.22 | J17: =VLOOKUP($A17,'BC.115+260'!$B$13:$X$489,20,0)/1000 -> 1.75 | K17: =VLOOKUP($A17,'BC.115+260'!$B$13:$X$489,21,0)/1000 -> -0.25 | L17: =(G17-$G$14)*1000 -> 0 | M17: =(I17-$I$14)*1000 -> 0 | N17: =(K17-$K$14)*1000 -> 0
A18: ='BC.115+260'!B17 -> 45255 | B18: 4 | C18: ='BC.115+260'!M17/1000 -> -0.22 | D18: ='BC.115+260'!AA17 -> 0 | E18: ='BC.115+260'!AB17 -> 0 | F18: =VLOOKUP($A18,'BC.115+260'!$B$13:$X$489,8,0)/1000 -> 1.8 | G18: =VLOOKUP($A18,'BC.115+260'!$B$13:$X$489,9,0)/1000 -> -0.2 | H18: =VLOOKUP($A18,'BC.115+260'!$B$13:$X$489,14,0)/1000 -> 1.78 | I18: =VLOOKUP($A18,'BC.115+260'!$B$13:$X$489,15,0)/1000 -> -0.22 | J18: =VLOOKUP($A18,'BC.115+260'!$B$13:$X$489,20,0)/1000 -> 1.75 | K18: =VLOOKUP($A18,'BC.115+260'!$B$13:$X$489,21,0)/1000 -> -0.25 | L18: =(G18-$G$14)*1000 -> 0 | M18: =(I18-$I$14)*1000 -> 0 | N18: =(K18-$K$14)*1000 -> 0
A19: ='BC.115+260'!B18 -> 45256 | B19: 5 | C19: ='BC.115+260'!M18/1000 -> -0.22 | D19: ='BC.115+260'!AA18 -> 0 | E19: ='BC.115+260'!AB18 -> 0 | F19: =VLOOKUP($A19,'BC.115+260'!$B$13:$X$489,8,0)/1000 -> 1.8 | G19: =VLOOKUP($A19,'BC.115+260'!$B$13:$X$489,9,0)/1000 -> -0.2 | H19: =VLOOKUP($A19,'BC.115+260'!$B$13:$X$489,14,0)/1000 -> 1.78 | I19: =VLOOKUP($A19,'BC.115+260'!$B$13:$X$489,15,0)/1000 -> -0.22 | J19: =VLOOKUP($A19,'BC.115+260'!$B$13:$X$489,20,0)/1000 -> 1.75 | K19: =VLOOKUP($A19,'BC.115+260'!$B$13:$X$489,21,0)/1000 -> -0.25 | L19: =(G19-$G$14)*1000 -> 0 | M19: =(I19-$I$14)*1000 -> 0 | N19: =(K19-$K$14)*1000 -> 0
A20: ='BC.115+260'!B19 -> 45257 | B20: 6 | C20: ='BC.115+260'!M19/1000 -> -0.22 | D20: ='BC.115+260'!AA19 -> 0 | E20: ='BC.115+260'!AB19 -> 0 | F20: =VLOOKUP($A20,'BC.115+260'!$B$13:$X$489,8,0)/1000 -> 1.8 | G20: =VLOOKUP($A20,'BC.115+260'!$B$13:$X$489,9,0)/1000 -> -0.2 | H20: =VLOOKUP($A20,'BC.115+260'!$B$13:$X$489,14,0)/1000 -> 1.78 | I20: =VLOOKUP($A20,'BC.115+260'!$B$13:$X$489,15,0)/1000 -> -0.22 | J20: =VLOOKUP($A20,'BC.115+260'!$B$13:$X$489,20,0)/1000 -> 1.75 | K20: =VLOOKUP($A20,'BC.115+260'!$B$13:$X$489,21,0)/1000 -> -0.25 | L20: =(G20-$G$14)*1000 -> 0 | M20: =(I20-$I$14)*1000 -> 0 | N20: =(K20-$K$14)*1000 -> 0
A21: ='BC.115+260'!B20 -> 45258 | B21: 7 | C21: ='BC.115+260'!M20/1000 -> -0.22 | D21: ='BC.115+260'!AA20 -> 0 | E21: ='BC.115+260'!AB20 -> 0 | F21: =VLOOKUP($A21,'BC.115+260'!$B$13:$X$489,8,0)/1000 -> 1.8 | G21: =VLOOKUP($A21,'BC.115+260'!$B$13:$X$489,9,0)/1000 -> -0.2 | H21: =VLOOKUP($A21,'BC.115+260'!$B$13:$X$489,14,0)/1000 -> 1.78 | I21: =VLOOKUP($A21,'BC.115+260'!$B$13:$X$489,15,0)/1000 -> -0.22 | J21: =VLOOKUP($A21,'BC.115+260'!$B$13:$X$489,20,0)/1000 -> 1.75 | K21: =VLOOKUP($A21,'BC.115+260'!$B$13:$X$489,21,0)/1000 -> -0.25 | L21: =(G21-$G$14)*1000 -> 0 | M21: =(I21-$I$14)*1000 -> 0 | N21: =(K21-$K$14)*1000 -> 0
A22: ='BC.115+260'!B21 -> 45259 | B22: 8 | C22: ='BC.115+260'!M21/1000 -> -0.22 | D22: ='BC.115+260'!AA21 -> 0 | E22: ='BC.115+260'!AB21 -> 0 | F22: =VLOOKUP($A22,'BC.115+260'!$B$13:$X$489,8,0)/1000 -> 1.8 | G22: =VLOOKUP($A22,'BC.115+260'!$B$13:$X$489,9,0)/1000 -> -0.2 | H22: =VLOOKUP($A22,'BC.115+260'!$B$13:$X$489,14,0)/1000 -> 1.78 | I22: =VLOOKUP($A22,'BC.115+260'!$B$13:$X$489,15,0)/1000 -> -0.22 | J22: =VLOOKUP($A22,'BC.115+260'!$B$13:$X$489,20,0)/1000 -> 1.75 | K22: =VLOOKUP($A22,'BC.115+260'!$B$13:$X$489,21,0)/1000 -> -0.25 | L22: =(G22-$G$14)*1000 -> 0 | M22: =(I22-$I$14)*1000 -> 0 | N22: =(K22-$K$14)*1000 -> 0
A23: ='BC.115+260'!B22 -> 45260 | B23: 9 | C23: ='BC.115+260'!M22/1000 -> -0.22 | D23: ='BC.115+260'!AA22 -> 0 | E23: ='BC.115+260'!AB22 -> 0 | F23: =VLOOKUP($A23,'BC.115+260'!$B$13:$X$489,8,0)/1000 -> 1.8 | G23: =VLOOKUP($A23,'BC.115+260'!$B$13:$X$489,9,0)/1000 -> -0.2 | H23: =VLOOKUP($A23,'BC.115+260'!$B$13:$X$489,14,0)/1000 -> 1.78 | I23: =VLOOKUP($A23,'BC.115+260'!$B$13:$X$489,15,0)/1000 -> -0.22 | J23: =VLOOKUP($A23,'BC.115+260'!$B$13:$X$489,20,0)/1000 -> 1.75 | K23: =VLOOKUP($A23,'BC.115+260'!$B$13:$X$489,21,0)/1000 -> -0.25 | L23: =(G23-$G$14)*1000 -> 0 | M23: =(I23-$I$14)*1000 -> 0 | N23: =(K23-$K$14)*1000 -> 0
A24: ='BC.115+260'!B23 -> 45261 | B24: 10 | C24: ='BC.115+260'!M23/1000 -> -0.22 | D24: ='BC.115+260'!AA23 -> 0 | E24: ='BC.115+260'!AB23 -> 0 | F24: =VLOOKUP($A24,'BC.115+260'!$B$13:$X$489,8,0)/1000 -> 1.8 | G24: =VLOOKUP($A24,'BC.115+260'!$B$13:$X$489,9,0)/1000 -> -0.2 | H24: =VLOOKUP($A24,'BC.115+260'!$B$13:$X$489,14,0)/1000 -> 1.78 | I24: =VLOOKUP($A24,'BC.115+260'!$B$13:$X$489,15,0)/1000 -> -0.22 | J24: =VLOOKUP($A24,'BC.115+260'!$B$13:$X$489,20,0)/1000 -> 1.75 | K24: =VLOOKUP($A24,'BC.115+260'!$B$13:$X$489,21,0)/1000 -> -0.25 | L24: =(G24-$G$14)*1000 -> 0 | M24: =(I24-$I$14)*1000 -> 0 | N24: =(K24-$K$14)*1000 -> 0
A25: ='BC.115+260'!B24 -> 45262 | B25: 11 | C25: ='BC.115+260'!M24/1000 -> -0.22 | D25: ='BC.115+260'!AA24 -> 0 | E25: ='BC.115+260'!AB24 -> 0 | F25: =VLOOKUP($A25,'BC.115+260'!$B$13:$X$489,8,0)/1000 -> 1.8 | G25: =VLOOKUP($A25,'BC.115+260'!$B$13:$X$489,9,0)/1000 -> -0.2 | H25: =VLOOKUP($A25,'BC.115+260'!$B$13:$X$489,14,0)/1000 -> 1.78 | I25: =VLOOKUP($A25,'BC.115+260'!$B$13:$X$489,15,0)/1000 -> -0.22 | J25: =VLOOKUP($A25,'BC.115+260'!$B$13:$X$489,20,0)/1000 -> 1.75 | K25: =VLOOKUP($A25,'BC.115+260'!$B$13:$X$489,21,0)/1000 -> -0.25 | L25: =(G25-$G$14)*1000 -> 0 | M25: =(I25-$I$14)*1000 -> 0 | N25: =(K25-$K$14)*1000 -> 0
A26: ='BC.115+260'!B25 -> 45263 | B26: 12 | C26: ='BC.115+260'!M25/1000 -> -0.22 | D26: ='BC.115+260'!AA25 -> 0 | E26: ='BC.115+260'!AB25 -> 0 | F26: =VLOOKUP($A26,'BC.115+260'!$B$13:$X$489,8,0)/1000 -> 1.8 | G26: =VLOOKUP($A26,'BC.115+260'!$B$13:$X$489,9,0)/1000 -> -0.2 | H26: =VLOOKUP($A26,'BC.115+260'!$B$13:$X$489,14,0)/1000 -> 1.78 | I26: =VLOOKUP($A26,'BC.115+260'!$B$13:$X$489,15,0)/1000 -> -0.22 | J26: =VLOOKUP($A26,'BC.115+260'!$B$13:$X$489,20,0)/1000 -> 1.75 | K26: =VLOOKUP($A26,'BC.115+260'!$B$13:$X$489,21,0)/1000 -> -0.25 | L26: =(G26-$G$14)*1000 -> 0 | M26: =(I26-$I$14)*1000 -> 0 | N26: =(K26-$K$14)*1000 -> 0
... A91: ='BC.115+260'!B90 -> 45328 | B91: 77 | C91: ='BC.115+260'!M90/1000 -> 0.969 | D91: ='BC.115+260'!AA90 -> 1.306 | E91: ='BC.115+260'!AB90 -> 1.058 | F91: =VLOOKUP($A91,'BC.115+260'!$B$13:$X$489,8,0)/1000 -> 1.659 | G91: =VLOOKUP($A91,'BC.115+260'!$B$13:$X$489,9,0)/1000 -> -0.341 | H91: =VLOOKUP($A91,'BC.115+260'!$B$13:$X$489,14,0)/1000 -> 1.649 | I91: =VLOOKUP($A91,'BC.115+260'!$B$13:$X$489,15,0)/1000 -> -0.351 | J91: =VLOOKUP($A91,'BC.115+260'!$B$13:$X$489,20,0)/1000 -> 1.625 | K91: =VLOOKUP($A91,'BC.115+260'!$B$13:$X$489,21,0)/1000 -> -0.375 | L91: =(G91-$G$14)*1000 -> -141 | M91: =(I91-$I$14)*1000 -> -131 | N91: =(K91-$K$14)*1000 -> -125
A92: ='BC.115+260'!B91 -> 45329 | B92: 78 | C92: ='BC.115+260'!M91/1000 -> 0.969 | D92: ='BC.115+260'!AA91 -> 1.306 | E92: ='BC.115+260'!AB91 -> 1.058 | F92: =VLOOKUP($A92,'BC.115+260'!$B$13:$X$489,8,0)/1000 -> 1.659 | G92: =VLOOKUP($A92,'BC.115+260'!$B$13:$X$489,9,0)/1000 -> -0.341 | H92: =VLOOKUP($A92,'BC.115+260'!$B$13:$X$489,14,0)/1000 -> 1.649 | I92: =VLOOKUP($A92,'BC.115+260'!$B$13:$X$489,15,0)/1000 -> -0.351 | J92: =VLOOKUP($A92,'BC.115+260'!$B$13:$X$489,20,0)/1000 -> 1.625 | K92: =VLOOKUP($A92,'BC.115+260'!$B$13:$X$489,21,0)/1000 -> -0.375 | L92: =(G92-$G$14)*1000 -> -141 | M92: =(I92-$I$14)*1000 -> -131 | N92: =(K92-$K$14)*1000 -> -125 | Y92: =A21-A14 -> 7
