Workbook

Sheet 114+320
B1: 1 | C1: =+B1+1 -> 2 | D1: =+C1+1 -> 3 | E1: =+D1+1 -> 4 | F1: =+E1+1 -> 5 | G1: =+F1+1 -> 6 | H1: =+G1+1 -> 7 | I1: =+H1+1 -> 8 | J1: =+I1+1 -> 9 | ... W1: =+V1+1 -> 22 | Y1: =+W1+1 -> 23 | Z1: =+Y1+1 -> 24 | AA1: =+Z1+1 -> 25 | AB1: =+AA1+1 -> 26
A2: DỰ ÁN THÀNH PHẦN ĐOẠN HẬU GIANG - CÀ MAU
A3: THUỘC DỰ ÁN XÂY DỰNG CÔNG TRÌNH ĐƯỜNG BỘ CAO TỐC BẮC - NAM PHÍA ĐÔNG GIAI ĐOẠN 2021 - 2025
A4: =UPPER("GÓI THẦU XL03 :Thi Công Xây Dựng Đoạn Tuyến Km114+200 - Km126+223 Bao Gồm Tuyến Nối Nút Giao IC12 Với QL1 (bao gồm khảo sát, thiết kế BVTC)") -> GÓI THẦU XL03 :THI CÔNG XÂY DỰNG ĐOẠN TUYẾN KM114+200 - KM126+223 BAO GỒM TUYẾN NỐI NÚT GIAO IC12 VỚI QL1 (BAO GỒM KHẢO SÁT, THIẾT KẾ BVTC)
A5: CHỦ ĐẦU TƯ | I5: TƯ VẤN GIÁM SÁT | S5: NHÀ THẦU
A6: BAN QUẢN LÝ DỰ ÁN MỸ THUẬN | I6: =UPPER("Liên danh Phân viện KHCN GTVT phía Nam - Công ty Cổ phần Tư vấn kỹ thuật và xây dựng Hồng Hà") -> LIÊN DANH PHÂN VIỆN KHCN GTVT PHÍA NAM - CÔNG TY CỔ PHẦN TƯ VẤN KỸ THUẬT VÀ XÂY DỰNG HỒNG HÀ | S6: LIÊN DANH CC1 - HẢI ĐĂNG - VẠN CƯỜNG - 492 - BẮC TRUNG NAM
A7: BIỂU GHI ĐO QUAN TRẮC LÚN
A8: Người lập: | K8: Tên mốc:
A9: Thời tiết: | C9: Nắng | K9: Cao độ mốc: | M9: =C14 -> 842
A10: Lý trình: | C10: Km114+320 | K10: Ngày đặt bàn: | M10: =B14 -> 45043
A12: Stt | B12: Ngày quan trắc | C12: Cao độ mốc (mm) | D12: Số đọc tại mốc (mm) | E12: Số đọc mia (mm) | H12: Cao độ quan trắc (mm) | K12: Chiều dài cần nối (mm) | N12: Cao độ bàn đo lún (mm) | Q12: Tốc độ lún (mm) | T12: Số đọc mia tại nền đắp tại tâm (mm) | U12: Cao độ nền đắp (mm) | X12: Chiều dày lớp đắp (m) | Y12: Đội quan trắc | Z12: Nhà thầu | AA12: Tư Vấn Giám Sát | AB12: Ghi chú
E13: Trái | F13: Giữa | G13: Phải | H13: Trái | I13: Giữa | J13: Phải | K13: Trái | L13: Giữa | M13: Phải | N13: Trái | O13: Giữa | P13: Phải | Q13: Trái | R13: Giữa | S13: Phải | U13: Trái | V13: Giữa | W13: Phải
A14: 0 | B14: 45043 | C14: 842 | D14: 1674 | E14: =C14+D14-H14 -> 696 | F14: =C14+D14-I14 -> 696 | G14: =D14+C14-J14 -> 636 | H14: =K14+N14 -> 1820 | I14: =L14+O14 -> 1820 | J14: =M14+P14 -> 1880 | K14: 2000 | L14: 2000 | M14: 2000 | N14: -180 | O14: -180 | P14: -120 | Q14: 0 | R14: 0 | S14: 0 | T14: =D14+C14-V14 -> 2696 | U14: =N14 -> -180 | V14: =O14 -> -180 | W14: =P14 -> -120 | AB14: Lắp đặt ban đầu
A15: 1 | B15: =B14+1 -> 45044 | C15: =C14 -> 842 | D15: =D14-2 -> 1672 | E15: =C15+D15-H15 -> 694 | F15: =C15+D15-I15 -> 694 | G15: =D15+C15-J15 -> 634 | H15: =K15+N15 -> 1820 | I15: =L15+O15 -> 1820 | J15: =M15+P15 -> 1880 | K15: =K14 -> 2000 | L15: =L14 -> 2000 | M15: =M14 -> 2000 | N15: =N14-Q15 -> -180 | O15: =O14-R15 -> -180 | P15: =P14-S15 -> -120 | Q15: 0 | R15: 0 | S15: 0 | T15: =D15+C15-V15 -> 2694 | U15: =N15 -> -180 | V15: =O15 -> -180 | W15: =P15 -> -120
A16: 2 | B16: =B15+1 -> 45045 | C16: =C15 -> 842 | D16: =D15-2 -> 1670 | E16: =C16+D16-H16 -> 692 | F16: =C16+D16-I16 -> 692 | G16: =D16+C16-J16 -> 632 | H16: =K16+N16 -> 1820 | I16: =L16+O16 -> 1820 | J16: =M16+P16 -> 1880 | K16: =K15 -> 2000 | L16: =L15 -> 2000 | M16: =M15 -> 2000 | N16: =N15-Q16 -> -180 | O16: =O15-R16 -> -180 | P16: =P15-S16 -> -120 | Q16: 0 | R16: 0 | S16: 0 | T16: =D16+C16-V16 -> 2692 | U16: =N16 -> -180 | V16: =O16 -> -180 | W16: =P16 -> -120
A17: 3 | B17: =B16+1 -> 45046 | C17: =C16 -> 842 | D17: =D16-2 -> 1668 | E17: =C17+D17-H17 -> 690 | F17: =C17+D17-I17 -> 690 | G17: =D17+C17-J17 -> 630 | H17: =K17+N17 -> 1820 | I17: =L17+O17 -> 1820 | J17: =M17+P17 -> 1880 | K17: =K16 -> 2000 | L17: =L16 -> 2000 | M17: =M16 -> 2000 | N17: =N16-Q17 -> -180 | O17: =O16-R17 -> -180 | P17: =P16-S17 -> -120 | Q17: 0 | R17: 0 | S17: 0 | T17: =D17+C17-V17 -> 2690 | U17: =N17 -> -180 | V17: =O17 -> -180 | W17: =P17 -> -120
A18: 4 | B18: =B17+1 -> 45047 | C18: =C17 -> 842 | D18: =D17-2 -> 1666 | E18: =C18+D18-H18 -> 688 | F18: =C18+D18-I18 -> 688 | G18: =D18+C18-J18 -> 628 | H18: =K18+N18 -> 1820 | I18: =L18+O18 -> 1820 | J18: =M18+P18 -> 1880 | K18: =K17 -> 2000 | L18: =L17 -> 2000 | M18: =M17 -> 2000 | N18: =N17-Q18 -> -180 | O18: =O17-R18 -> -180 | P18: =P17-S18 -> -120 | Q18: 0 | R18: 0 | S18: 0 | T18: =D18+C18-V18 -> 2688 | U18: =N18 -> -180 | V18: =O18 -> -180 | W18: =P18 -> -120
A19: 5 | B19: =B18+1 -> 45048 | C19: =C18 -> 842 | D19: =D18-2 -> 1664 | E19: =C19+D19-H19 -> 686 | F19: =C19+D19-I19 -> 686 | G19: =D19+C19-J19 -> 626 | H19: =K19+N19 -> 1820 | I19: =L19+O19 -> 1820 | J19: =M19+P19 -> 1880 | K19: =K18 -> 2000 | L19: =L18 -> 2000 | M19: =M18 -> 2000 | N19: =N18-Q19 -> -180 | O19: =O18-R19 -> -180 | P19: =P18-S19 -> -120 | Q19: 0 | R19: 0 | S19: 0 | T19: =D19+C19-V19 -> 2686 | U19: =N19 -> -180 | V19: =O19 -> -180 | W19: =P19 -> -120
A20: 6 | B20: =B19+1 -> 45049 | C20: =C19 -> 842 | D20: =D19-2 -> 1662 | E20: =C20+D20-H20 -> 684 | F20: =C20+D20-I20 -> 684 | G20: =D20+C20-J20 -> 624 | H20: =K20+N20 -> 1820 | I20: =L20+O20 -> 1820 | J20: =M20+P20 -> 1880 | K20: =K19 -> 2000 | L20: =L19 -> 2000 | M20: =M19 -> 2000 | N20: =N19-Q20 -> -180 | O20: =O19-R20 -> -180 | P20: =P19-S20 -> -120 | Q20: 0 | R20: 0 | S20: 0 | T20: =D20+C20-V20 -> 2684 | U20: =N20 -> -180 | V20: =O20 -> -180 | W20: =P20 -> -120
A21: 7 | B21: =B20+1 -> 45050 | C21: =C20 -> 842 | D21: =D20-2 -> 1660 | E21: =C21+D21-H21 -> 682 | F21: =C21+D21-I21 -> 682 | G21: =D21+C21-J21 -> 622 | H21: =K21+N21 -> 1820 | I21: =L21+O21 -> 1820 | J21: =M21+P21 -> 1880 | K21: =K20 -> 2000 | L21: =L20 -> 2000 | M21: =M20 -> 2000 | N21: =N20-Q21 -> -180 | O21: =O20-R21 -> -180 | P21: =P20-S21 -> -120 | Q21: 0 | R21: 0 | S21: 0 | T21: =D21+C21-V21 -> 2682 | U21: =U20+$X21*1000-Q21 -> -180 | V21: =V20+$X21*1000-R21 -> -180 | W21: =W20+$X21*1000-S21 -> -120
A22: 8 | B22: =B21+1 -> 45051 | C22: =C21 -> 842 | D22: =D21-2 -> 1658 | E22: =C22+D22-H22 -> 680 | F22: =C22+D22-I22 -> 680 | G22: =D22+C22-J22 -> 620 | H22: =K22+N22 -> 1820 | I22: =L22+O22 -> 1820 | J22: =M22+P22 -> 1880 | K22: =K21 -> 2000 | L22: =L21 -> 2000 | M22: =M21 -> 2000 | N22: =N21-Q22 -> -180 | O22: =O21-R22 -> -180 | P22: =P21-S22 -> -120 | Q22: 0 | R22: 0 | S22: 0 | T22: =D22+C22-V22 -> 2680 | U22: =U21+$X22*1000-Q22 -> -180 | V22: =V21+$X22*1000-R22 -> -180 | W22: =W21+$X22*1000-S22 -> -120
A23: 9 | B23: =B22+1 -> 45052 | C23: =C22 -> 842 | D23: =D22-2 -> 1656 | E23: =C23+D23-H23 -> 678 | F23: =C23+D23-I23 -> 678 | G23: =D23+C23-J23 -> 618 | H23: =K23+N23 -> 1820 | I23: =L23+O23 -> 1820 | J23: =M23+P23 -> 1880 | K23: =K22 -> 2000 | L23: =L22 -> 2000 | M23: =M22 -> 2000 | N23: =N22-Q23 -> -180 | O23: =O22-R23 -> -180 | P23: =P22-S23 -> -120 | Q23: 0 | R23: 0 | S23: 0 | T23: =D23+C23-V23 -> 2678 | U23: =U22+$X23*1000-Q23 -> -180 | V23: =V22+$X23*1000-R23 -> -180 | W23: =W22+$X23*1000-S23 -> -120
A24: 10 | B24: =B23+1 -> 45053 | C24: =C23 -> 842 | D24: =D23-2 -> 1654 | E24: =C24+D24-H24 -> 676 | F24: =C24+D24-I24 -> 676 | G24: =D24+C24-J24 -> 616 | H24: =K24+N24 -> 1820 | I24: =L24+O24 -> 1820 | J24: =M24+P24 -> 1880 | K24: =K23 -> 2000 | L24: =L23 -> 2000 | M24: =M23 -> 2000 | N24: =N23-Q24 -> -180 | O24: =O23-R24 -> -180 | P24: =P23-S24 -> -120 | Q24: 0 | R24: 0 | S24: 0 | T24: =D24+C24-V24 -> 2676 | U24: =U23+$X24*1000-Q24 -> -180 | V24: =V23+$X24*1000-R24 -> -180 | W24: =W23+$X24*1000-S24 -> -120
A25: 11 | B25: =B24+1 -> 45054 | C25: =C24 -> 842 | D25: =D24-2 -> 1652 | E25: =C25+D25-H25 -> 674 | F25: =C25+D25-I25 -> 674 | G25: =D25+C25-J25 -> 614 | H25: =K25+N25 -> 1820 | I25: =L25+O25 -> 1820 | J25: =M25+P25 -> 1880 | K25: =K24 -> 2000 | L25: =L24 -> 2000 | M25: =M24 -> 2000 | N25: =N24-Q25 -> -180 | O25: =O24-R25 -> -180 | P25: =P24-S25 -> -120 | Q25: 0 | R25: 0 | S25: 0 | T25: =D25+C25-V25 -> 2674 | U25: =U24+$X25*1000-Q25 -> -180 | V25: =V24+$X25*1000-R25 -> -180 | W25: =W24+$X25*1000-S25 -> -120
A26: 12 | B26: =B25+1 -> 45055 | C26: =C25 -> 842 | D26: =D25-2 -> 1650 | E26: =C26+D26-H26 -> 672 | F26: =C26+D26-I26 -> 672 | G26: =D26+C26-J26 -> 612 | H26: =K26+N26 -> 1820 | I26: =L26+O26 -> 1820 | J26: =M26+P26 -> 1880 | K26: =K25 -> 2000 | L26: =L25 -> 2000 | M26: =M25 -> 2000 | N26: =N25-Q26 -> -180 | O26: =O25-R26 -> -180 | P26: =P25-S26 -> -120 | Q26: 0 | R26: 0 | S26: 0 | T26: =D26+C26-V26 -> 2672 | U26: =U25+$X26*1000-Q26 -> -180 | V26: =V25+$X26*1000-R26 -> -180 | W26: =W25+$X26*1000-S26 -> -120
A27: 13 | B27: =B26+1 -> 45056 | C27: =C26 -> 842 | D27: =D26-2 -> 1648 | E27: =C27+D27-H27 -> 670 | F27: =C27+D27-I27 -> 670 | G27: =D27+C27-J27 -> 610 | H27: =K27+N27 -> 1820 | I27: =L27+O27 -> 1820 | J27: =M27+P27 -> 1880 | K27: =K26 -> 2000 | L27: =L26 -> 2000 | M27: =M26 -> 2000 | N27: =N26-Q27 -> -180 | O27: =O26-R27 -> -180 | P27: =P26-S27 -> -120 | Q27: 0 | R27: 0 | S27: 0 | T27: =D27+C27-V27 -> 2670 | U27: =U26+$X27*1000-Q27 -> -180 | V27: =V26+$X27*1000-R27 -> -180 | W27: =W26+$X27*1000-S27 -> -120
A28: 14 | B28: =B27+1 -> 45057 | C28: =C27 -> 842 | D28: =D27-2 -> 1646 | E28: =C28+D28-H28 -> 668 | F28: =C28+D28-I28 -> 668 | G28: =D28+C28-J28 -> 608 | H28: =K28+N28 -> 1820 | I28: =L28+O28 -> 1820 | J28: =M28+P28 -> 1880 | K28: =K27 -> 2000 | L28: =L27 -> 2000 | M28: =M27 -> 2000 | N28: =N27-Q28 -> -180 | O28: =O27-R28 -> -180 | P28: =P27-S28 -> -120 | Q28: 0 | R28: 0 | S28: 0 | T28: =D28+C28-V28 -> 2668 | U28: =U27+$X28*1000-Q28 -> -180 | V28: =V27+$X28*1000-R28 -> -180 | W28: =W27+$X28*1000-S28 -> -120
A29: 15 | B29: =B28+1 -> 45058 | C29: =C28 -> 842 | D29: =D28-2 -> 1644 | E29: =C29+D29-H29 -> 666 | F29: =C29+D29-I29 -> 666 | G29: =D29+C29-J29 -> 606 | H29: =K29+N29 -> 1820 | I29: =L29+O29 -> 1820 | J29: =M29+P29 -> 1880 | K29: =K28 -> 2000 | L29: =L28 -> 2000 | M29: =M28 -> 2000 | N29: =N28-Q29 -> -180 | O29: =O28-R29 -> -180 | P29: =P28-S29 -> -120 | Q29: 0 | R29: 0 | S29: 0 | T29: =D29+C29-V29 -> 2666 | U29: =U28+$X29*1000-Q29 -> -180 | V29: =V28+$X29*1000-R29 -> -180 | W29: =W28+$X29*1000-S29 -> -120
A30: 16 | B30: =B29+1 -> 45059 | C30: =C29 -> 842 | D30: =D29-2 -> 1642 | E30: =C30+D30-H30 -> 664 | F30: =C30+D30-I30 -> 664 | G30: =D30+C30-J30 -> 604 | H30: =K30+N30 -> 1820 | I30: =L30+O30 -> 1820 | J30: =M30+P30 -> 1880 | K30: =K29 -> 2000 | L30: =L29 -> 2000 | M30: =M29 -> 2000 | N30: =N29-Q30 -> -180 | O30: =O29-R30 -> -180 | P30: =P29-S30 -> -120 | Q30: 0 | R30: 0 | S30: 0 | T30: =D30+C30-V30 -> 2664 | U30: =U29+$X30*1000-Q30 -> -180 | V30: =V29+$X30*1000-R30 -> -180 | W30: =W29+$X30*1000-S30 -> -120
A31: 17 | B31: =B30+1 -> 45060 | C31: =C30 -> 842 | D31: =D30-2 -> 1640 | E31: =C31+D31-H31 -> 662 | F31: =C31+D31-I31 -> 662 | G31: =D31+C31-J31 -> 602 | H31: =K31+N31 -> 1820 | I31: =L31+O31 -> 1820 | J31: =M31+P31 -> 1880 | K31: =K30 -> 2000 | L31: =L30 -> 2000 | M31: =M30 -> 2000 | N31: =N30-Q31 -> -180 | O31: =O30-R31 -> -180 | P31: =P30-S31 -> -120 | Q31: 0 | R31: 0 | S31: 0 | T31: =D31+C31-V31 -> 2662 | U31: =U30+$X31*1000-Q31 -> -180 | V31: =V30+$X31*1000-R31 -> -180 | W31: =W30+$X31*1000-S31 -> -120
A32: 18 | B32: =B31+1 -> 45061 | C32: =C31 -> 842 | D32: =D31-2 -> 1638 | E32: =C32+D32-H32 -> 660 | F32: =C32+D32-I32 -> 660 | G32: =D32+C32-J32 -> 600 | H32: =K32+N32 -> 1820 | I32: =L32+O32 -> 1820 | J32: =M32+P32 -> 1880 | K32: =K31 -> 2000 | L32: =L31 -> 2000 | M32: =M31 -> 2000 | N32: =N31-Q32 -> -180 | O32: =O31-R32 -> -180 | P32: =P31-S32 -> -120 | Q32: 0 | R32: 0 | S32: 0 | T32: =D32+C32-V32 -> 2660 | U32: =U31+$X32*1000-Q32 -> -180 | V32: =V31+$X32*1000-R32 -> -180 | W32: =W31+$X32*1000-S32 -> -120
... A37: 23 | B37: =B36+1 -> 45066 | C37: =C36 -> 842 | D37: =D36-2 -> 1628 | E37: =C37+D37-H37 -> 650 | F37: =C37+D37-I37 -> 650 | G37: =D37+C37-J37 -> 590 | H37: =K37+N37 -> 1820 | I37: =L37+O37 -> 1820 | J37: =M37+P37 -> 1880 | K37: =K36 -> 2000 | L37: =L36 -> 2000 | M37: =M36 -> 2000 | N37: =N36-Q37 -> -180 | O37: =O36-R37 -> -180 | P37: =P36-S37 -> -120 | Q37: 0 | R37: 0 | S37: 0 | T37: =D37+C37-V37 -> 2650 | U37: =U36+$X37*1000-Q37 -> -180 | V37: =V36+$X37*1000-R37 -> -180 | W37: =W36+$X37*1000-S37 -> -120
A38: 24 | B38: =B37+1 -> 45067 | C38: =C37 -> 842 | D38: =D37-2 -> 1626 | E38: =C38+D38-H38 -> 648 | F38: =C38+D38-I38 -> 648 | G38: =D38+C38-J38 -> 588 | H38: =K38+N38 -> 1820 | I38: =L38+O38 -> 1820 | J38: =M38+P38 -> 1880 | K38: =K37 -> 2000 | L38: =L37 -> 2000 | M38: =M37 -> 2000 | N38: =N37-Q38 -> -180 | O38: =O37-R38 -> -180 | P38: =P37-S38 -> -120 | Q38: 0 | R38: 0 | S38: 0 | T38: =D38+C38-V38 -> 2568 | U38: =U37+0.08*1000-Q38 -> -100 | V38: =V37+0.08*1000-R38 -> -100 | W38: =W37+0.02*1000-S38 -> -100
A39: 25 | B39: =B38+1 -> 45068 | C39: =C38 -> 842 | D39: =D38-2 -> 1624 | E39: =C39+D39-H39 -> 652 | F39: =C39+D39-I39 -> 653 | G39: =D39+C39-J39 -> 593 | H39: =K39+N39 -> 1814 | I39: =L39+O39 -> 1813 | J39: =M39+P39 -> 1873 | K39: =K38 -> 2000 | L39: =L38 -> 2000 | M39: =M38 -> 2000 | N39: =N38-Q39 -> -186 | O39: =O38-R39 -> -187 | P39: =P38-S39 -> -127 | Q39: 6 | R39: 7 | S39: 7 | T39: =D39+C39-V39 -> 2273 | U39: =U38+0.3*1000-Q39 -> 194 | V39: =V38+0.3*1000-R39 -> 193 | W39: =W38+0.3*1000-S39 -> 193 | AB39: 8
A40: 26 | B40: =B39+1 -> 45069 | C40: =C39 -> 842 | D40: =D39-2 -> 1622 | E40: =C40+D40-H40 -> 654 | F40: =C40+D40-I40 -> 658 | G40: =D40+C40-J40 -> 595 | H40: =K40+N40 -> 1810 | I40: =L40+O40 -> 1806 | J40: =M40+P40 -> 1869 | K40: =K39 -> 2000 | L40: =L39 -> 2000 | M40: =M39 -> 2000 | N40: =N39-Q40 -> -190 | O40: =O39-R40 -> -194 | P40: =P39-S40 -> -131 | Q40: 4 | R40: 7 | S40: 4 | T40: =D40+C40-V40 -> 2278 | U40: =U39+$X40*1000-Q40 -> 190 | V40: =V39+$X40*1000-R40 -> 186 | W40: =W39+$X40*1000-S40 -> 189
A41: 27 | B41: =B40+1 -> 45070 | C41: =C40 -> 842 | D41: =D40-2 -> 1620 | E41: =C41+D41-H41 -> 655 | F41: =C41+D41-I41 -> 661 | G41: =D41+C41-J41 -> 596 | H41: =K41+N41 -> 1807 | I41: =L41+O41 -> 1801 | J41: =M41+P41 -> 1866 | K41: =K40 -> 2000 | L41: =L40 -> 2000 | M41: =M40 -> 2000 | N41: =N40-Q41 -> -193 | O41: =O40-R41 -> -199 | P41: =P40-S41 -> -134 | Q41: 3 | R41: 5 | S41: 3 | T41: =D41+C41-V41 -> 2281 | U41: =U40+$X41*1000-Q41 -> 187 | V41: =V40+$X41*1000-R41 -> 181 | W41: =W40+$X41*1000-S41 -> 186
A42: 28 | B42: =B41+1 -> 45071 | C42: =C41 -> 842 | D42: =D41-2 -> 1618 | E42: =C42+D42-H42 -> 655 | F42: =C42+D42-I42 -> 664 | G42: =D42+C42-J42 -> 596 | H42: =K42+N42 -> 1805 | I42: =L42+O42 -> 1796 | J42: =M42+P42 -> 1864 | K42: =K41 -> 2000 | L42: =L41 -> 2000 | M42: =M41 -> 2000 | N42: =N41-Q42 -> -195 | O42: =O41-R42 -> -204 | P42: =P41-S42 -> -136 | Q42: 2 | R42: 5 | S42: 2 | T42: =D42+C42-V42 -> 2284 | U42: =U41+$X42*1000-Q42 -> 185 | V42: =V41+$X42*1000-R42 -> 176 | W42: =W41+$X42*1000-S42 -> 184
A43: 29 | B43: =B42+1 -> 45072 | C43: =C42 -> 842 | D43: =D42-2 -> 1616 | E43: =C43+D43-H43 -> 659 | F43: =C43+D43-I43 -> 669 | G43: =D43+C43-J43 -> 601 | H43: =K43+N43 -> 1799 | I43: =L43+O43 -> 1789 | J43: =M43+P43 -> 1857 | K43: =K42 -> 2000 | L43: =L42 -> 2000 | M43: =M42 -> 2000 | N43: =N42-Q43 -> -201 | O43: =O42-R43 -> -211 | P43: =P42-S43 -> -143 | Q43: 6 | R43: 7 | S43: 7 | T43: =D43+C43-V43 -> 1989 | U43: =U42+$X43*1000-Q43 -> 479 | V43: =V42+$X43*1000-R43 -> 469 | W43: =W42+$X43*1000-S43 -> 477 | X43: 0.3 | AB43: =+AB39-1 -> 7
A44: 30 | B44: =B43+1 -> 45073 | C44: =C43 -> 842 | D44: =D43-2 -> 1614 | E44: =C44+D44-H44 -> 660 | F44: =C44+D44-I44 -> 670 | G44: =D44+C44-J44 -> 602 | H44: =K44+N44 -> 1796 | I44: =L44+O44 -> 1786 | J44: =M44+P44 -> 1854 | K44: =K43 -> 2000 | L44: =L43 -> 2000 | M44: =M43 -> 2000 | N44: =N43-Q44 -> -204 | O44: =O43-R44 -> -214 | P44: =P43-S44 -> -146 | Q44: 3 | R44: 3 | S44: 3 | T44: =D44+C44-V44 -> 1990 | U44: =U43+$X44*1000-Q44 -> 476 | V44: =V43+$X44*1000-R44 -> 466 | W44: =W43+$X44*1000-S44 -> 474
A45: 31 | B45: =B44+1 -> 45074 | C45: =C44 -> 842 | D45: =D44-2 -> 1612 | E45: =C45+D45-H45 -> 660 | F45: =C45+D45-I45 -> 670 | G45: =D45+C45-J45 -> 602 | H45: =K45+N45 -> 1794 | I45: =L45+O45 -> 1784 | J45: =M45+P45 -> 1852 | K45: =K44 -> 2000 | L45: =L44 -> 2000 | M45: =M44 -> 2000 | N45: =N44-Q45 -> -206 | O45: =O44-R45 -> -216 | P45: =P44-S45 -> -148 | Q45: 2 | R45: 2 | S45: 2 | T45: =D45+C45-V45 -> 1990 | U45: =U44+$X45*1000-Q45 -> 474 | V45: =V44+$X45*1000-R45 -> 464 | W45: =W44+$X45*1000-S45 -> 472
...

Sheet BC.114+320
A1: 13 | B1: DỰ ÁN THÀNH PHẦN ĐOẠN HẬU GIANG - CÀ MAU
B2: THUỘC DỰ ÁN XÂY DỰNG CÔNG TRÌNH ĐƯỜNG BỘ CAO TỐC BẮC - NAM PHÍA ĐÔNG GIAI ĐOẠN 2021 - 2025
B3: =UPPER("GÓI THẦU XL03 :Thi Công Xây Dựng Đoạn Tuyến Km114+200 - Km126+223 Bao Gồm Tuyến Nối Nút Giao IC12 Với QL1 (bao gồm khảo sát, thiết kế BVTC)") -> GÓI THẦU XL03 :THI CÔNG XÂY DỰNG ĐOẠN TUYẾN KM114+200 - KM126+223 BAO GỒM TUYẾN NỐI NÚT GIAO IC12 VỚI QL1 (BAO GỒM KHẢO SÁT, THIẾT KẾ BVTC)
B4: CHỦ ĐẦU TƯ | J4: TƯ VẤN GIÁM SÁT | T4: NHÀ THẦU
B5: BAN QUẢN LÝ DỰ ÁN MỸ THUẬN | J5: =UPPER("Liên danh Phân viện KHCN GTVT phía Nam - Công ty Cổ phần Tư vấn kỹ thuật và xây dựng Hồng Hà") -> LIÊN DANH PHÂN VIỆN KHCN GTVT PHÍA NAM - CÔNG TY CỔ PHẦN TƯ VẤN KỸ THUẬT VÀ XÂY DỰNG HỒNG HÀ | T5: LIÊN DANH CC1 - HẢI ĐĂNG - VẠN CƯỜNG - 492 - BẮC TRUNG NAM
B6: BIỂU GHI ĐO QUAN TRẮC LÚN
B7: Người lập: | C7: ='114+320'!C8 -> 0 | L7: Tên mốc: | N7: ='114+320'!M8 -> 0
B8: Thời tiết: | C8: ='114+320'!C9 -> Nắng | L8: Cao độ mốc: | N8: ='114+320'!M9 -> 842
B9: Lý trình: | C9: ='114+320'!C10 -> Km114+320 | L9: Ngày đặt bàn: | N9: ='114+320'!M10 -> 45043
B11: Ngày | C11: Ngày cộng dồn | D11: Cao độ mốc | E11: Số đọc mia của mốc | F11: Cao độ đường ngắm | G11: Trái | M11: Tim | S11: Phải | Z11: Chiều dày lớp đắp (m) | AA11: Chiều cao nền đắp (m) | AB11: Chiều dày nền đắp (m)
G12: Cao độ đắp (mm) | H12: Số đọc mia | I12: Cao độ quan trắc (mm) | J12: Cao độ bàn đo lún (mm) | K12: Độ lún (mm) | L12: Độ lún tích lũy (mm) | M12: Cao độ đắp (mm) | N12: Số đọc mia | O12: Cao độ quan trắc (mm) | P12: Cao độ bàn đo lún (mm) | Q12: Độ lún (mm) | R12: Độ lún tích lũy (mm) | S12: Cao độ đắp (mm) | T12: Số đọc mia | U12: Cao độ quan trắc (mm) | V12: Cao độ bàn đo lún (mm) | W12: Độ lún (mm) | X12: Độ lún tích lũy (mm)
B13: ='114+320'!B14 -> 45043 | C13: 0 | D13: =VLOOKUP(B13,'114+320'!B14:AB115,2,FALSE) -> 842 | E13: =VLOOKUP(B13,'114+320'!B14:AB115,3,FALSE) -> 1674 | F13: =D13+E13 -> 2516 | G13: =VLOOKUP(B13,'114+320'!$B$14:$AB$115,20,FALSE) -> -180 | H13: =VLOOKUP(B13,'114+320'!$B$14:$AB$115,4,FALSE) -> 696 | I13: =F13-H13 -> 1820 | J13: =VLOOKUP(B13,'114+320'!$B$14:$AB$115,13,FALSE) -> -180 | K13: ='114+320'!Q14 -> 0 | L13: 0 | M13: =VLOOKUP(B13,'114+320'!$B$14:$AB$115,21,FALSE) -> -180 | N13: =VLOOKUP(B13,'114+320'!$B$14:$AB$115,5,FALSE) -> 696 | O13: =F13-N13 -> 1820 | P13: =VLOOKUP(B13,'114+320'!$B$14:$AB$115,14,FALSE) -> -180 | Q13: ='114+320'!R14 -> 0 | R13: 0 | S13: =VLOOKUP(B13,'114+320'!$B$14:$AB$115,22,FALSE) -> -120 | T13: =VLOOKUP(B13,'114+320'!$B$13:$AB$115,6,FALSE) -> 636 | U13: =F13-T13 -> 1880 | V13: =VLOOKUP(B13,'114+320'!$B$14:$AB$115,15,FALSE) -> -120 | W13: ='114+320'!S14 -> 0 | X13: 0 | Y13: 0 | Z13: =IF(Y13>0,Y13,0) -> 0 | AA13: =Z13 -> 0 | AB13: 0
B14: ='114+320'!B15 -> 45044 | C14: =B14-B13 -> 1 | D14: =D13 -> 842 | E14: =VLOOKUP(B14,'114+320'!B15:AB116,3,FALSE) -> 1672 | F14: =D14+E14 -> 2514 | G14: =VLOOKUP(B14,'114+320'!$B$15:$AB$115,20,FALSE) -> -180 | H14: =VLOOKUP(B14,'114+320'!$B$15:$AB$115,4,FALSE) -> 694 | I14: =F14-H14 -> 1820 | J14: =VLOOKUP(B14,'114+320'!$B$15:$AB$115,13,FALSE) -> -180 | K14: ='114+320'!Q15 -> 0 | L14: =+K14+L13 -> 0 | M14: =VLOOKUP(B14,'114+320'!$B$14:$AB$115,21,FALSE) -> -180 | N14: =VLOOKUP(B14,'114+320'!$B$15:$AB$115,5,FALSE) -> 694 | O14: =F14-N14 -> 1820 | P14: =VLOOKUP(B14,'114+320'!$B$15:$AB$115,14,FALSE) -> -180 | Q14: ='114+320'!R15 -> 0 | R14: =+Q14+R13 -> 0 | S14: =VLOOKUP(B14,'114+320'!$B$14:$AB$115,22,FALSE) -> -120 | T14: =VLOOKUP(B14,'114+320'!$B$15:$AB$115,6,FALSE) -> 634 | U14: =F14-T14 -> 1880 | V14: =VLOOKUP(B14,'114+320'!$B$15:$AB$115,15,FALSE) -> -120 | W14: ='114+320'!S15 -> 0 | X14: =+W14+X13 -> 0 | Y14: =S14-S13 -> 0 | Z14: =IF(Y14>0,Y14,0)/1000 -> 0 | AA14: =AA13+Z14 -> 0 | AB14: =(M14-$M$13-R14)/1000 -> 0
A15: 1 | B15: ='114+320'!B16 -> 45045 | C15: =B15-B14 -> 1 | D15: =D14 -> 842 | E15: =VLOOKUP(B15,'114+320'!B16:AB117,3,FALSE) -> 1670 | F15: =D15+E15 -> 2512 | G15: =VLOOKUP(B15,'114+320'!$B$15:$AB$115,20,FALSE) -> -180 | H15: =VLOOKUP(B15,'114+320'!$B$15:$AB$115,4,FALSE) -> 692 | I15: =F15-H15 -> 1820 | J15: =VLOOKUP(B15,'114+320'!$B$15:$AB$115,13,FALSE) -> -180 | K15: ='114+320'!Q16 -> 0 | L15: =+K15+L14 -> 0 | M15: =VLOOKUP(B15,'114+320'!$B$14:$AB$115,21,FALSE) -> -180 | N15: =VLOOKUP(B15,'114+320'!$B$15:$AB$115,5,FALSE) -> 692 | O15: =F15-N15 -> 1820 | P15: =VLOOKUP(B15,'114+320'!$B$15:$AB$115,14,FALSE) -> -180 | Q15: ='114+320'!R16 -> 0 | R15: =+Q15+R14 -> 0 | S15: =VLOOKUP(B15,'114+320'!$B$14:$AB$115,22,FALSE) -> -120 | T15: =VLOOKUP(B15,'114+320'!$B$15:$AB$115,6,FALSE) -> 632 | U15: =F15-T15 -> 1880 | V15: =VLOOKUP(B15,'114+320'!$B$15:$AB$115,15,FALSE) -> -120 | W15: ='114+320'!S16 -> 0 | X15: =+W15+X14 -> 0 | Y15: =S15-S14 -> 0 | Z15: =IF(Y15>0,Y15,0)/1000 -> 0 | AA15: =AA14+Z15 -> 0 | AB15: =(M15-$M$13-R15)/1000 -> 0
A16: =A15+1 -> 2 | B16: ='114+320'!B17 -> 45046 | C16: =B16-B15 -> 1 | D16: =D15 -> 842 | E16: =VLOOKUP(B16,'114+320'!B17:AB118,3,FALSE) -> 1668 | F16: =D16+E16 -> 2510 | G16: =VLOOKUP(B16,'114+320'!$B$15:$AB$115,20,FALSE) -> -180 | H16: =VLOOKUP(B16,'114+320'!$B$15:$AB$115,4,FALSE) -> 690 | I16: =F16-H16 -> 1820 | J16: =VLOOKUP(B16,'114+320'!$B$15:$AB$115,13,FALSE) -> -180 | K16: ='114+320'!Q17 -> 0 | L16: =+K16+L15 -> 0 | M16: =VLOOKUP(B16,'114+320'!$B$14:$AB$115,21,FALSE) -> -180 | N16: =VLOOKUP(B16,'114+320'!$B$15:$AB$115,5,FALSE) -> 690 | O16: =F16-N16 -> 1820 | P16: =VLOOKUP(B16,'114+320'!$B$15:$AB$115,14,FALSE) -> -180 | Q16: ='114+320'!R17 -> 0 | R16: =+Q16+R15 -> 0 | S16: =VLOOKUP(B16,'114+320'!$B$14:$AB$115,22,FALSE) -> -120 | T16: =VLOOKUP(B16,'114+320'!$B$15:$AB$115,6,FALSE) -> 630 | U16: =F16-T16 -> 1880 | V16: =VLOOKUP(B16,'114+320'!$B$15:$AB$115,15,FALSE) -> -120 | W16: ='114+320'!S17 -> 0 | X16: =+W16+X15 -> 0 | Y16: =S16-S15 -> 0 | Z16: =IF(Y16>0,Y16,0)/1000 -> 0 | AA16: =AA15+Z16 -> 0 | AB16: =(M16-$M$13-R16)/1000 -> 0
A17: =A16+1 -> 3 | B17: ='114+320'!B18 -> 45047 | C17: =B17-B16 -> 1 | D17: =D16 -> 842 | E17: =VLOOKUP(B17,'114+320'!B18:AB119,3,FALSE) -> 1666 | F17: =D17+E17 -> 2508 | G17: =VLOOKUP(B17,'114+320'!$B$15:$AB$115,20,FALSE) -> -180 | H17: =VLOOKUP(B17,'114+320'!$B$15:$AB$115,4,FALSE) -> 688 | I17: =F17-H17 -> 1820 | J17: =VLOOKUP(B17,'114+320'!$B$15:$AB$115,13,FALSE) -> -180 | K17: ='114+320'!Q18 -> 0 | L17: =+K17+L16 -> 0 | M17: =VLOOKUP(B17,'114+320'!$B$14:$AB$115,21,FALSE) -> -180 | N17: =VLOOKUP(B17,'114+320'!$B$15:$AB$115,5,FALSE) -> 688 | O17: =F17-N17 -> 1820 | P17: =VLOOKUP(B17,'114+320'!$B$15:$AB$115,14,FALSE) -> -180 | Q17: ='114+320'!R18 -> 0 | R17: =+Q17+R16 -> 0 | S17: =VLOOKUP(B17,'114+320'!$B$14:$AB$115,22,FALSE) -> -120 | T17: =VLOOKUP(B17,'114+320'!$B$15:$AB$115,6,FALSE) -> 628 | U17: =F17-T17 -> 1880 | V17: =VLOOKUP(B17,'114+320'!$B$15:$AB$115,15,FALSE) -> -120 | W17: ='114+320'!S18 -> 0 | X17: =+W17+X16 -> 0 | Y17: =S17-S16 -> 0 | Z17: =IF(Y17>0,Y17,0)/1000 -> 0 | AA17: =AA16+Z17 -> 0 | AB17: =(M17-$M$13-R17)/1000 -> 0
A18: =A17+1 -> 4 | B18: ='114+320'!B19 -> 45048 | C18: =B18-B17 -> 1 | D18: =D17 -> 842 | E18: =VLOOKUP(B18,'114+320'!B19:AB120,3,FALSE) -> 1664 | F18: =D18+E18 -> 2506 | G18: =VLOOKUP(B18,'114+320'!$B$15:$AB$115,20,FALSE) -> -180 | H18: =VLOOKUP(B18,'114+320'!$B$15:$AB$115,4,FALSE) -> 686 | I18: =F18-H18 -> 1820 | J18: =VLOOKUP(B18,'114+320'!$B$15:$AB$115,13,FALSE) -> -180 | K18: ='114+320'!Q19 -> 0 | L18: =+K18+L17 -> 0 | M18: =VLOOKUP(B18,'114+320'!$B$14:$AB$115,21,FALSE) -> -180 | N18: =VLOOKUP(B18,'114+320'!$B$15:$AB$115,5,FALSE) -> 686 | O18: =F18-N18 -> 1820 | P18: =VLOOKUP(B18,'114+320'!$B$15:$AB$115,14,FALSE) -> -180 | Q18: ='114+320'!R19 -> 0 | R18: =+Q18+R17 -> 0 | S18: =VLOOKUP(B18,'114+320'!$B$14:$AB$115,22,FALSE) -> -120 | T18: =VLOOKUP(B18,'114+320'!$B$15:$AB$115,6,FALSE) -> 626 | U18: =F18-T18 -> 1880 | V18: =VLOOKUP(B18,'114+320'!$B$15:$AB$115,15,FALSE) -> -120 | W18: ='114+320'!S19 -> 0 | X18: =+W18+X17 -> 0 | Y18: =S18-S17 -> 0 | Z18: =IF(Y18>0,Y18,0)/1000 -> 0 | AA18: =AA17+Z18 -> 0 | AB18: =(M18-$M$13-R18)/1000 -> 0
A19: =A18+1 -> 5 | B19: ='114+320'!B20 -> 45049 | C19: =B19-B18 -> 1 | D19: =D18 -> 842 | E19: =VLOOKUP(B19,'114+320'!B20:AB121,3,FALSE) -> 1662 | F19: =D19+E19 -> 2504 | G19: =VLOOKUP(B19,'114+320'!$B$15:$AB$115,20,FALSE) -> -180 | H19: =VLOOKUP(B19,'114+320'!$B$15:$AB$115,4,FALSE) -> 684 | I19: =F19-H19 -> 1820 | J19: =VLOOKUP(B19,'114+320'!$B$15:$AB$115,13,FALSE) -> -180 | K19: ='114+320'!Q20 -> 0 | L19: =+K19+L18 -> 0 | M19: =VLOOKUP(B19,'114+320'!$B$14:$AB$115,21,FALSE) -> -180 | N19: =VLOOKUP(B19,'114+320'!$B$15:$AB$115,5,FALSE) -> 684 | O19: =F19-N19 -> 1820 | P19: =VLOOKUP(B19,'114+320'!$B$15:$AB$115,14,FALSE) -> -180 | Q19: ='114+320'!R20 -> 0 | R19: =+Q19+R18 -> 0 | S19: =VLOOKUP(B19,'114+320'!$B$14:$AB$115,22,FALSE) -> -120 | T19: =VLOOKUP(B19,'114+320'!$B$15:$AB$115,6,FALSE) -> 624 | U19: =F19-T19 -> 1880 | V19: =VLOOKUP(B19,'114+320'!$B$15:$AB$115,15,FALSE) -> -120 | W19: ='114+320'!S20 -> 0 | X19: =+W19+X18 -> 0 | Y19: =S19-S18 -> 0 | Z19: =IF(Y19>0,Y19,0)/1000 -> 0 | AA19: =AA18+Z19 -> 0 | AB19: =(M19-$M$13-R19)/1000 -> 0
A20: =A19+1 -> 6 | B20: ='114+320'!B21 -> 45050 | C20: =B20-B19 -> 1 | D20: =D19 -> 842 | E20: =VLOOKUP(B20,'114+320'!B21:AB122,3,FALSE) -> 1660 | F20: =D20+E20 -> 2502 | G20: =VLOOKUP(B20,'114+320'!$B$15:$AB$115,20,FALSE) -> -180 | H20: =VLOOKUP(B20,'114+320'!$B$15:$AB$115,4,FALSE) -> 682 | I20: =F20-H20 -> 1820 | J20: =VLOOKUP(B20,'114+320'!$B$15:$AB$115,13,FALSE) -> -180 | K20: ='114+320'!Q21 -> 0 | L20: =+K20+L19 -> 0 | M20: =VLOOKUP(B20,'114+320'!$B$14:$AB$115,21,FALSE) -> -180 | N20: =VLOOKUP(B20,'114+320'!$B$15:$AB$115,5,FALSE) -> 682 | O20: =F20-N20 -> 1820 | P20: =VLOOKUP(B20,'114+320'!$B$15:$AB$115,14,FALSE) -> -180 | Q20: ='114+320'!R21 -> 0 | R20: =+Q20+R19 -> 0 | S20: =VLOOKUP(B20,'114+320'!$B$14:$AB$115,22,FALSE) -> -120 | T20: =VLOOKUP(B20,'114+320'!$B$15:$AB$115,6,FALSE) -> 622 | U20: =F20-T20 -> 1880 | V20: =VLOOKUP(B20,'114+320'!$B$15:$AB$115,15,FALSE) -> -120 | W20: ='114+320'!S21 -> 0 | X20: =+W20+X19 -> 0 | Y20: =S20-S19 -> 0 | Z20: =IF(Y20>0,Y20,0)/1000 -> 0 | AA20: =AA19+Z20 -> 0 | AB20: =(M20-$M$13-R20)/1000 -> 0
A21: =A20+1 -> 7 | B21: ='114+320'!B22 -> 45051 | C21: =B21-B20 -> 1 | D21: =D20 -> 842 | E21: =VLOOKUP(B21,'114+320'!B22:AB123,3,FALSE) -> 1658 | F21: =D21+E21 -> 2500 | G21: =VLOOKUP(B21,'114+320'!$B$15:$AB$115,20,FALSE) -> -180 | H21: =VLOOKUP(B21,'114+320'!$B$15:$AB$115,4,FALSE) -> 680 | I21: =F21-H21 -> 1820 | J21: =VLOOKUP(B21,'114+320'!$B$15:$AB$115,13,FALSE) -> -180 | K21: ='114+320'!Q22 -> 0 | L21: =+K21+L20 -> 0 | M21: =VLOOKUP(B21,'114+320'!$B$14:$AB$115,21,FALSE) -> -180 | N21: =VLOOKUP(B21,'114+320'!$B$15:$AB$115,5,FALSE) -> 680 | O21: =F21-N21 -> 1820 | P21: =VLOOKUP(B21,'114+320'!$B$15:$AB$115,14,FALSE) -> -180 | Q21: ='114+320'!R22 -> 0 | R21: =+Q21+R20 -> 0 | S21: =VLOOKUP(B21,'114+320'!$B$14:$AB$115,22,FALSE) -> -120 | T21: =VLOOKUP(B21,'114+320'!$B$15:$AB$115,6,FALSE) -> 620 | U21: =F21-T21 -> 1880 | V21: =VLOOKUP(B21,'114+320'!$B$15:$AB$115,15,FALSE) -> -120 | W21: ='114+320'!S22 -> 0 | X21: =+W21+X20 -> 0 | Y21: =S21-S20 -> 0 | Z21: =IF(Y21>0,Y21,0)/1000 -> 0 | AA21: =AA20+Z21 -> 0 | AB21: =(M21-$M$13-R21)/1000 -> 0
B22: ='114+320'!B23 -> 45052 | C22: =B22-B21 -> 1 | D22: =D21 -> 842 | E22: =VLOOKUP(B22,'114+320'!B23:AB124,3,FALSE) -> 1656 | F22: =D22+E22 -> 2498 | G22: =VLOOKUP(B22,'114+320'!$B$15:$AB$115,20,FALSE) -> -180 | H22: =VLOOKUP(B22,'114+320'!$B$15:$AB$115,4,FALSE) -> 678 | I22: =F22-H22 -> 1820 | J22: =VLOOKUP(B22,'114+320'!$B$15:$AB$115,13,FALSE) -> -180 | K22: ='114+320'!Q23 -> 0 | L22: =+K22+L21 -> 0 | M22: =VLOOKUP(B22,'114+320'!$B$14:$AB$115,21,FALSE) -> -180 | N22: =VLOOKUP(B22,'114+320'!$B$15:$AB$115,5,FALSE) -> 678 | O22: =F22-N22 -> 1820 | P22: =VLOOKUP(B22,'114+320'!$B$15:$AB$115,14,FALSE) -> -180 | Q22: ='114+320'!R23 -> 0 | R22: =+Q22+R21 -> 0 | S22: =VLOOKUP(B22,'114+320'!$B$14:$AB$115,22,FALSE) -> -120 | T22: =VLOOKUP(B22,'114+320'!$B$15:$AB$115,6,FALSE) -> 618 | U22: =F22-T22 -> 1880 | V22: =VLOOKUP(B22,'114+320'!$B$15:$AB$115,15,FALSE) -> -120 | W22: ='114+320'!S23 -> 0 | X22: =+W22+X21 -> 0 | Y22: =S22-S21 -> 0 | Z22: =IF(Y22>0,Y22,0)/1000 -> 0 | AA22: =AA21+Z22 -> 0 | AB22: =(M22-$M$13-R22)/1000 -> 0
B23: ='114+320'!B24 -> 45053 | C23: =B23-B22 -> 1 | D23: =D22 -> 842 | E23: =VLOOKUP(B23,'114+320'!B24:AB125,3,FALSE) -> 1654 | F23: =D23+E23 -> 2496 | G23: =VLOOKUP(B23,'114+320'!$B$15:$AB$115,20,FALSE) -> -180 | H23: =VLOOKUP(B23,'114+320'!$B$15:$AB$115,4,FALSE) -> 676 | I23: =F23-H23 -> 1820 | J23: =VLOOKUP(B23,'114+320'!$B$15:$AB$115,13,FALSE) -> -180 | K23: ='114+320'!Q24 -> 0 | L23: =+K23+L22 -> 0 | M23: =VLOOKUP(B23,'114+320'!$B$14:$AB$115,21,FALSE) -> -180 | N23: =VLOOKUP(B23,'114+320'!$B$15:$AB$115,5,FALSE) -> 676 | O23: =F23-N23 -> 1820 | P23: =VLOOKUP(B23,'114+320'!$B$15:$AB$115,14,FALSE) -> -180 | Q23: ='114+320'!R24 -> 0 | R23: =+Q23+R22 -> 0 | S23: =VLOOKUP(B23,'114+320'!$B$14:$AB$115,22,FALSE) -> -120 | T23: =VLOOKUP(B23,'114+320'!$B$15:$AB$115,6,FALSE) -> 616 | U23: =F23-T23 -> 1880 | V23: =VLOOKUP(B23,'114+320'!$B$15:$AB$115,15,FALSE) -> -120 | W23: ='114+320'!S24 -> 0 | X23: =+W23+X22 -> 0 | Y23: =S23-S22 -> 0 | Z23: =IF(Y23>0,Y23,0)/1000 -> 0 | AA23: =AA22+Z23 -> 0 | AB23: =(M23-$M$13-R23)/1000 -> 0
B24: ='114+320'!B25 -> 45054 | C24: =B24-B23 -> 1 | D24: =D23 -> 842 | E24: =VLOOKUP(B24,'114+320'!B25:AB126,3,FALSE) -> 1652 | F24: =D24+E24 -> 2494 | G24: =VLOOKUP(B24,'114+320'!$B$15:$AB$115,20,FALSE) -> -180 | H24: =VLOOKUP(B24,'114+320'!$B$15:$AB$115,4,FALSE) -> 674 | I24: =F24-H24 -> 1820 | J24: =VLOOKUP(B24,'114+320'!$B$15:$AB$115,13,FALSE) -> -180 | K24: ='114+320'!Q25 -> 0 | L24: =+K24+L23 -> 0 | M24: =VLOOKUP(B24,'114+320'!$B$14:$AB$115,21,FALSE) -> -180 | N24: =VLOOKUP(B24,'114+320'!$B$15:$AB$115,5,FALSE) -> 674 | O24: =F24-N24 -> 1820 | P24: =VLOOKUP(B24,'114+320'!$B$15:$AB$115,14,FALSE) -> -180 | Q24: ='114+320'!R25 -> 0 | R24: =+Q24+R23 -> 0 | S24: =VLOOKUP(B24,'114+320'!$B$14:$AB$115,22,FALSE) -> -120 | T24: =VLOOKUP(B24,'114+320'!$B$15:$AB$115,6,FALSE) -> 614 | U24: =F24-T24 -> 1880 | V24: =VLOOKUP(B24,'114+320'!$B$15:$AB$115,15,FALSE) -> -120 | W24: ='114+320'!S25 -> 0 | X24: =+W24+X23 -> 0 | Y24: =S24-S23 -> 0 | Z24: =IF(Y24>0,Y24,0)/1000 -> 0 | AA24: =AA23+Z24 -> 0 | AB24: =(M24-$M$13-R24)/1000 -> 0
B25: ='114+320'!B26 -> 45055 | C25: =B25-B24 -> 1 | D25: =D24 -> 842 | E25: =VLOOKUP(B25,'114+320'!B26:AB127,3,FALSE) -> 1650 | F25: =D25+E25 -> 2492 | G25: =VLOOKUP(B25,'114+320'!$B$15:$AB$115,20,FALSE) -> -180 | H25: =VLOOKUP(B25,'114+320'!$B$15:$AB$115,4,FALSE) -> 672 | I25: =F25-H25 -> 1820 | J25: =VLOOKUP(B25,'114+320'!$B$15:$AB$115,13,FALSE) -> -180 | K25: ='114+320'!Q26 -> 0 | L25: =+K25+L24 -> 0 | M25: =VLOOKUP(B25,'114+320'!$B$14:$AB$115,21,FALSE) -> -180 | N25: =VLOOKUP(B25,'114+320'!$B$15:$AB$115,5,FALSE) -> 672 | O25: =F25-N25 -> 1820 | P25: =VLOOKUP(B25,'114+320'!$B$15:$AB$115,14,FALSE) -> -180 | Q25: ='114+320'!R26 -> 0 | R25: =+Q25+R24 -> 0 | S25: =VLOOKUP(B25,'114+320'!$B$14:$AB$115,22,FALSE) -> -120 | T25: =VLOOKUP(B25,'114+320'!$B$15:$AB$115,6,FALSE) -> 612 | U25: =F25-T25 -> 1880 | V25: =VLOOKUP(B25,'114+320'!$B$15:$AB$115,15,FALSE) -> -120 | W25: ='114+320'!S26 -> 0 | X25: =+W25+X24 -> 0 | Y25: =S25-S24 -> 0 | Z25: =IF(Y25>0,Y25,0)/1000 -> 0 | AA25: =AA24+Z25 -> 0 | AB25: =(M25-$M$13-R25)/1000 -> 0
B26: ='114+320'!B27 -> 45056 | C26: =B26-B25 -> 1 | D26: =D25 -> 842 | E26: =VLOOKUP(B26,'114+320'!B27:AB128,3,FALSE) -> 1648 | F26: =D26+E26 -> 2490 | G26: =VLOOKUP(B26,'114+320'!$B$15:$AB$115,20,FALSE) -> -180 | H26: =VLOOKUP(B26,'114+320'!$B$15:$AB$115,4,FALSE) -> 670 | I26: =F26-H26 -> 1820 | J26: =VLOOKUP(B26,'114+320'!$B$15:$AB$115,13,FALSE) -> -180 | K26: ='114+320'!Q27 -> 0 | L26: =+K26+L25 -> 0 | M26: =VLOOKUP(B26,'114+320'!$B$14:$AB$115,21,FALSE) -> -180 | N26: =VLOOKUP(B26,'114+320'!$B$15:$AB$115,5,FALSE) -> 670 | O26: =F26-N26 -> 1820 | P26: =VLOOKUP(B26,'114+320'!$B$15:$AB$115,14,FALSE) -> -180 | Q26: ='114+320'!R27 -> 0 | R26: =+Q26+R25 -> 0 | S26: =VLOOKUP(B26,'114+320'!$B$14:$AB$115,22,FALSE) -> -120 | T26: =VLOOKUP(B26,'114+320'!$B$15:$AB$115,6,FALSE) -> 610 | U26: =F26-T26 -> 1880 | V26: =VLOOKUP(B26,'114+320'!$B$15:$AB$115,15,FALSE) -> -120 | W26: ='114+320'!S27 -> 0 | X26: =+W26+X25 -> 0 | Y26: =S26-S25 -> 0 | Z26: =IF(Y26>0,Y26,0)/1000 -> 0 | AA26: =AA25+Z26 -> 0 | AB26: =(M26-$M$13-R26)/1000 -> 0
B27: ='114+320'!B28 -> 45057 | C27: =B27-B26 -> 1 | D27: =D26 -> 842 | E27: =VLOOKUP(B27,'114+320'!B28:AB129,3,FALSE) -> 1646 | F27: =D27+E27 -> 2488 | G27: =VLOOKUP(B27,'114+320'!$B$15:$AB$115,20,FALSE) -> -180 | H27: =VLOOKUP(B27,'114+320'!$B$15:$AB$115,4,FALSE) -> 668 | I27: =F27-H27 -> 1820 | J27: =VLOOKUP(B27,'114+320'!$B$15:$AB$115,13,FALSE) -> -180 | K27: ='114+320'!Q28 -> 0 | L27: =+K27+L26 -> 0 | M27: =VLOOKUP(B27,'114+320'!$B$14:$AB$115,21,FALSE) -> -180 | N27: =VLOOKUP(B27,'114+320'!$B$15:$AB$115,5,FALSE) -> 668 | O27: =F27-N27 -> 1820 | P27: =VLOOKUP(B27,'114+320'!$B$15:$AB$115,14,FALSE) -> -180 | Q27: ='114+320'!R28 -> 0 | R27: =+Q27+R26 -> 0 | S27: =VLOOKUP(B27,'114+320'!$B$14:$AB$115,22,FALSE) -> -120 | T27: =VLOOKUP(B27,'114+320'!$B$15:$AB$115,6,FALSE) -> 608 | U27: =F27-T27 -> 1880 | V27: =VLOOKUP(B27,'114+320'!$B$15:$AB$115,15,FALSE) -> -120 | W27: ='114+320'!S28 -> 0 | X27: =+W27+X26 -> 0 | Y27: =S27-S26 -> 0 | Z27: =IF(Y27>0,Y27,0)/1000 -> 0 | AA27: =AA26+Z27 -> 0 | AB27: =(M27-$M$13-R27)/1000 -> 0
B28: ='114+320'!B29 -> 45058 | C28: =B28-B27 -> 1 | D28: =D27 -> 842 | E28: =VLOOKUP(B28,'114+320'!B29:AB130,3,FALSE) -> 1644 | F28: =D28+E28 -> 2486 | G28: =VLOOKUP(B28,'114+320'!$B$15:$AB$115,20,FALSE) -> -180 | H28: =VLOOKUP(B28,'114+320'!$B$15:$AB$115,4,FALSE) -> 666 | I28: =F28-H28 -> 1820 | J28: =VLOOKUP(B28,'114+320'!$B$15:$AB$115,13,FALSE) -> -180 | K28: ='114+320'!Q29 -> 0 | L28: =+K28+L27 -> 0 | M28: =VLOOKUP(B28,'114+320'!$B$14:$AB$115,21,FALSE) -> -180 | N28: =VLOOKUP(B28,'114+320'!$B$15:$AB$115,5,FALSE) -> 666 | O28: =F28-N28 -> 1820 | P28: =VLOOKUP(B28,'114+320'!$B$15:$AB$115,14,FALSE) -> -180 | Q28: ='114+320'!R29 -> 0 | R28: =+Q28+R27 -> 0 | S28: =VLOOKUP(B28,'114+320'!$B$14:$AB$115,22,FALSE) -> -120 | T28: =VLOOKUP(B28,'114+320'!$B$15:$AB$115,6,FALSE) -> 606 | U28: =F28-T28 -> 1880 | V28: =VLOOKUP(B28,'114+320'!$B$15:$AB$115,15,FALSE) -> -120 | W28: ='114+320'!S29 -> 0 | X28: =+W28+X27 -> 0 | Y28: =S28-S27 -> 0 | Z28: =IF(Y28>0,Y28,0)/1000 -> 0 | AA28: =AA27+Z28 -> 0 | AB28: =(M28-$M$13-R28)/1000 -> 0
B29: ='114+320'!B30 -> 45059 | C29: =B29-B28 -> 1 | D29: =D28 -> 842 | E29: =VLOOKUP(B29,'114+320'!B30:AB131,3,FALSE) -> 1642 | F29: =D29+E29 -> 2484 | G29: =VLOOKUP(B29,'114+320'!$B$15:$AB$115,20,FALSE) -> -180 | H29: =VLOOKUP(B29,'114+320'!$B$15:$AB$115,4,FALSE) -> 664 | I29: =F29-H29 -> 1820 | J29: =VLOOKUP(B29,'114+320'!$B$15:$AB$115,13,FALSE) -> -180 | K29: ='114+320'!Q30 -> 0 | L29: =+K29+L28 -> 0 | M29: =VLOOKUP(B29,'114+320'!$B$14:$AB$115,21,FALSE) -> -180 | N29: =VLOOKUP(B29,'114+320'!$B$15:$AB$115,5,FALSE) -> 664 | O29: =F29-N29 -> 1820 | P29: =VLOOKUP(B29,'114+320'!$B$15:$AB$115,14,FALSE) -> -180 | Q29: ='114+320'!R30 -> 0 | R29: =+Q29+R28 -> 0 | S29: =VLOOKUP(B29,'114+320'!$B$14:$AB$115,22,FALSE) -> -120 | T29: =VLOOKUP(B29,'114+320'!$B$15:$AB$115,6,FALSE) -> 604 | U29: =F29-T29 -> 1880 | V29: =VLOOKUP(B29,'114+320'!$B$15:$AB$115,15,FALSE) -> -120 | W29: ='114+320'!S30 -> 0 | X29: =+W29+X28 -> 0 | Y29: =S29-S28 -> 0 | Z29: =IF(Y29>0,Y29,0)/1000 -> 0 | AA29: =AA28+Z29 -> 0 | AB29: =(M29-$M$13-R29)/1000 -> 0
B30: ='114+320'!B31 -> 45060 | C30: =B30-B29 -> 1 | D30: =D29 -> 842 | E30: =VLOOKUP(B30,'114+320'!B31:AB132,3,FALSE) -> 1640 | F30: =D30+E30 -> 2482 | G30: =VLOOKUP(B30,'114+320'!$B$15:$AB$115,20,FALSE) -> -180 | H30: =VLOOKUP(B30,'114+320'!$B$15:$AB$115,4,FALSE) -> 662 | I30: =F30-H30 -> 1820 | J30: =VLOOKUP(B30,'114+320'!$B$15:$AB$115,13,FALSE) -> -180 | K30: ='114+320'!Q31 -> 0 | L30: =+K30+L29 -> 0 | M30: =VLOOKUP(B30,'114+320'!$B$14:$AB$115,21,FALSE) -> -180 | N30: =VLOOKUP(B30,'114+320'!$B$15:$AB$115,5,FALSE) -> 662 | O30: =F30-N30 -> 1820 | P30: =VLOOKUP(B30,'114+320'!$B$15:$AB$115,14,FALSE) -> -180 | Q30: ='114+320'!R31 -> 0 | R30: =+Q30+R29 -> 0 | S30: =VLOOKUP(B30,'114+320'!$B$14:$AB$115,22,FALSE) -> -120 | T30: =VLOOKUP(B30,'114+320'!$B$15:$AB$115,6,FALSE) -> 602 | U30: =F30-T30 -> 1880 | V30: =VLOOKUP(B30,'114+320'!$B$15:$AB$115,15,FALSE) -> -120 | W30: ='114+320'!S31 -> 0 | X30: =+W30+X29 -> 0 | Y30: =S30-S29 -> 0 | Z30: =IF(Y30>0,Y30,0)/1000 -> 0 | AA30: =AA29+Z30 -> 0 | AB30: =(M30-$M$13-R30)/1000 -> 0
B31: ='114+320'!B32 -> 45061 | C31: =B31-B30 -> 1 | D31: =D30 -> 842 | E31: =VLOOKUP(B31,'114+320'!B32:AB133,3,FALSE) -> 1638 | F31: =D31+E31 -> 2480 | G31: =VLOOKUP(B31,'114+320'!$B$15:$AB$115,20,FALSE) -> -180 | H31: =VLOOKUP(B31,'114+320'!$B$15:$AB$115,4,FALSE) -> 660 | I31: =F31-H31 -> 1820 | J31: =VLOOKUP(B31,'114+320'!$B$15:$AB$115,13,FALSE) -> -180 | K31: ='114+320'!Q32 -> 0 | L31: =+K31+L30 -> 0 | M31: =VLOOKUP(B31,'114+320'!$B$14:$AB$115,21,FALSE) -> -180 | N31: =VLOOKUP(B31,'114+320'!$B$15:$AB$115,5,FALSE) -> 660 | O31: =F31-N31 -> 1820 | P31: =VLOOKUP(B31,'114+320'!$B$15:$AB$115,14,FALSE) -> -180 | Q31: ='114+320'!R32 -> 0 | R31: =+Q31+R30 -> 0 | S31: =VLOOKUP(B31,'114+320'!$B$14:$AB$115,22,FALSE) -> -120 | T31: =VLOOKUP(B31,'114+320'!$B$15:$AB$115,6,FALSE) -> 600 | U31: =F31-T31 -> 1880 | V31: =VLOOKUP(B31,'114+320'!$B$15:$AB$115,15,FALSE) -> -120 | W31: ='114+320'!S32 -> 0 | X31: =+W31+X30 -> 0 | Y31: =S31-S30 -> 0 | Z31: =IF(Y31>0,Y31,0)/1000 -> 0 | AA31: =AA30+Z31 -> 0 | AB31: =(M31-$M$13-R31)/1000 -> 0
B32: ='114+320'!B33 -> 45062 | C32: =B32-B31 -> 1 | D32: =D31 -> 842 | E32: =VLOOKUP(B32,'114+320'!B33:AB134,3,FALSE) -> 1636 | F32: =D32+E32 -> 2478 | G32: =VLOOKUP(B32,'114+320'!$B$15:$AB$115,20,FALSE) -> -180 | H32: =VLOOKUP(B32,'114+320'!$B$15:$AB$115,4,FALSE) -> 658 | I32: =F32-H32 -> 1820 | J32: =VLOOKUP(B32,'114+320'!$B$15:$AB$115,13,FALSE) -> -180 | K32: ='114+320'!Q33 -> 0 | L32: =+K32+L31 -> 0 | M32: =VLOOKUP(B32,'114+320'!$B$14:$AB$115,21,FALSE) -> -180 | N32: =VLOOKUP(B32,'114+320'!$B$15:$AB$115,5,FALSE) -> 658 | O32: =F32-N32 -> 1820 | P32: =VLOOKUP(B32,'114+320'!$B$15:$AB$115,14,FALSE) -> -180 | Q32: ='114+320'!R33 -> 0 | R32: =+Q32+R31 -> 0 | S32: =VLOOKUP(B32,'114+320'!$B$14:$AB$115,22,FALSE) -> -120 | T32: =VLOOKUP(B32,'114+320'!$B$15:$AB$115,6,FALSE) -> 598 | U32: =F32-T32 -> 1880 | V32: =VLOOKUP(B32,'114+320'!$B$15:$AB$115,15,FALSE) -> -120 | W32: ='114+320'!S33 -> 0 | X32: =+W32+X31 -> 0 | Y32: =S32-S31 -> 0 | Z32: =IF(Y32>0,Y32,0)/1000 -> 0 | AA32: =AA31+Z32 -> 0 | AB32: =(M32-$M$13-R32)/1000 -> 0
B33: ='114+320'!B34 -> 45063 | C33: =B33-B32 -> 1 | D33: =D32 -> 842 | E33: =VLOOKUP(B33,'114+320'!B34:AB135,3,FALSE) -> 1634 | F33: =D33+E33 -> 2476 | G33: =VLOOKUP(B33,'114+320'!$B$15:$AB$115,20,FALSE) -> -180 | H33: =VLOOKUP(B33,'114+320'!$B$15:$AB$115,4,FALSE) -> 656 | I33: =F33-H33 -> 1820 | J33: =VLOOKUP(B33,'114+320'!$B$15:$AB$115,13,FALSE) -> -180 | K33: ='114+320'!Q34 -> 0 | L33: =+K33+L32 -> 0 | M33: =VLOOKUP(B33,'114+320'!$B$14:$AB$115,21,FALSE) -> -180 | N33: =VLOOKUP(B33,'114+320'!$B$15:$AB$115,5,FALSE) -> 656 | O33: =F33-N33 -> 1820 | P33: =VLOOKUP(B33,'114+320'!$B$15:$AB$115,14,FALSE) -> -180 | Q33: ='114+320'!R34 -> 0 | R33: =+Q33+R32 -> 0 | S33: =VLOOKUP(B33,'114+320'!$B$14:$AB$115,22,FALSE) -> -120 | T33: =VLOOKUP(B33,'114+320'!$B$15:$AB$115,6,FALSE) -> 596 | U33: =F33-T33 -> 1880 | V33: =VLOOKUP(B33,'114+320'!$B$15:$AB$115,15,FALSE) -> -120 | W33: ='114+320'!S34 -> 0 | X33: =+W33+X32 -> 0 | Y33: =S33-S32 -> 0 | Z33: =IF(Y33>0,Y33,0)/1000 -> 0 | AA33: =AA32+Z33 -> 0 | AB33: =(M33-$M$13-R33)/1000 -> 0
... B76: ='114+320'!B77 -> 45106 | C76: =B76-B75 -> 1 | D76: =D75 -> 842 | E76: =VLOOKUP(B76,'114+320'!B77:AB178,3,FALSE) -> 1548 | F76: =D76+E76 -> 2390 | G76: =VLOOKUP(B76,'114+320'!$B$15:$AB$115,20,FALSE) -> 694 | H76: =VLOOKUP(B76,'114+320'!$B$15:$AB$115,4,FALSE) -> 676 | I76: =F76-H76 -> 1714 | J76: =VLOOKUP(B76,'114+320'!$B$15:$AB$115,13,FALSE) -> -286 | K76: ='114+320'!Q77 -> 0 | L76: =+K76+L75 -> 106 | M76: =VLOOKUP(B76,'114+320'!$B$14:$AB$115,21,FALSE) -> 677 | N76: =VLOOKUP(B76,'114+320'!$B$15:$AB$115,5,FALSE) -> 693 | O76: =F76-N76 -> 1697 | P76: =VLOOKUP(B76,'114+320'!$B$15:$AB$115,14,FALSE) -> -303 | Q76: ='114+320'!R77 -> 0 | R76: =+Q76+R75 -> 123 | S76: =VLOOKUP(B76,'114+320'!$B$14:$AB$115,22,FALSE) -> 689 | T76: =VLOOKUP(B76,'114+320'!$B$15:$AB$115,6,FALSE) -> 621 | U76: =F76-T76 -> 1769 | V76: =VLOOKUP(B76,'114+320'!$B$15:$AB$115,15,FALSE) -> -231 | W76: ='114+320'!S77 -> 0 | X76: =+W76+X75 -> 111 | Y76: =S76-S75 -> 0 | Z76: =IF(Y76>0,Y76,0)/1000 -> 0 | AA76: =AA75+Z76 -> 0.899 | AB76: =(M76-$M$13-R76)/1000 -> 0.734
A77: 42307 | B77: ='114+320'!B78 -> 45107 | C77: =B77-B76 -> 1 | D77: =D76 -> 842 | E77: =VLOOKUP(B77,'114+320'!B78:AB179,3,FALSE) -> 1546 | F77: =D77+E77 -> 2388 | G77: =VLOOKUP(B77,'114+320'!$B$15:$AB$115,20,FALSE) -> 694 | H77: =VLOOKUP(B77,'114+320'!$B$15:$AB$115,4,FALSE) -> 674 | I77: =F77-H77 -> 1714 | J77: =VLOOKUP(B77,'114+320'!$B$15:$AB$115,13,FALSE) -> -286 | K77: ='114+320'!Q78 -> 0 | L77: =+K77+L76 -> 106 | M77: =VLOOKUP(B77,'114+320'!$B$14:$AB$115,21,FALSE) -> 677 | N77: =VLOOKUP(B77,'114+320'!$B$15:$AB$115,5,FALSE) -> 691 | O77: =F77-N77 -> 1697 | P77: =VLOOKUP(B77,'114+320'!$B$15:$AB$115,14,FALSE) -> -303 | Q77: ='114+320'!R78 -> 0 | R77: =+Q77+R76 -> 123 | S77: =VLOOKUP(B77,'114+320'!$B$14:$AB$115,22,FALSE) -> 689 | T77: =VLOOKUP(B77,'114+320'!$B$15:$AB$115,6,FALSE) -> 619 | U77: =F77-T77 -> 1769 | V77: =VLOOKUP(B77,'114+320'!$B$15:$AB$115,15,FALSE) -> -231 | W77: ='114+320'!S78 -> 0 | X77: =+W77+X76 -> 111 | Y77: =S77-S76 -> 0 | Z77: =IF(Y77>0,Y77,0)/1000 -> 0 | AA77: =AA76+Z77 -> 0.899 | AB77: =(M77-$M$13-R77)/1000 -> 0.734
A78: 02/11/015 | B78: ='114+320'!B79 -> 45108 | C78: =B78-B77 -> 1 | D78: =D77 -> 842 | E78: =VLOOKUP(B78,'114+320'!B79:AB180,3,FALSE) -> 1544 | F78: =D78+E78 -> 2386 | G78: =VLOOKUP(B78,'114+320'!$B$15:$AB$115,20,FALSE) -> 694 | H78: =VLOOKUP(B78,'114+320'!$B$15:$AB$115,4,FALSE) -> 672 | I78: =F78-H78 -> 1714 | J78: =VLOOKUP(B78,'114+320'!$B$15:$AB$115,13,FALSE) -> -286 | K78: ='114+320'!Q79 -> 0 | L78: =+K78+L77 -> 106 | M78: =VLOOKUP(B78,'114+320'!$B$14:$AB$115,21,FALSE) -> 677 | N78: =VLOOKUP(B78,'114+320'!$B$15:$AB$115,5,FALSE) -> 689 | O78: =F78-N78 -> 1697 | P78: =VLOOKUP(B78,'114+320'!$B$15:$AB$115,14,FALSE) -> -303 | Q78: ='114+320'!R79 -> 0 | R78: =+Q78+R77 -> 123 | S78: =VLOOKUP(B78,'114+320'!$B$14:$AB$115,22,FALSE) -> 689 | T78: =VLOOKUP(B78,'114+320'!$B$15:$AB$115,6,FALSE) -> 617 | U78: =F78-T78 -> 1769 | V78: =VLOOKUP(B78,'114+320'!$B$15:$AB$115,15,FALSE) -> -231 | W78: ='114+320'!S79 -> 0 | X78: =+W78+X77 -> 111 | Y78: =S78-S77 -> 0 | Z78: =IF(Y78>0,Y78,0)/1000 -> 0 | AA78: =AA77+Z78 -> 0.899 | AB78: =(M78-$M$13-R78)/1000 -> 0.734
A79: 42313 | B79: ='114+320'!B80 -> 45109 | C79: =B79-B78 -> 1 | D79: =D78 -> 842 | E79: =VLOOKUP(B79,'114+320'!B80:AB181,3,FALSE) -> 1542 | F79: =D79+E79 -> 2384 | G79: =VLOOKUP(B79,'114+320'!$B$15:$AB$115,20,FALSE) -> 694 | H79: =VLOOKUP(B79,'114+320'!$B$15:$AB$115,4,FALSE) -> 670 | I79: =F79-H79 -> 1714 | J79: =VLOOKUP(B79,'114+320'!$B$15:$AB$115,13,FALSE) -> -286 | K79: ='114+320'!Q80 -> 0 | L79: =+K79+L78 -> 106 | M79: =VLOOKUP(B79,'114+320'!$B$14:$AB$115,21,FALSE) -> 677 | N79: =VLOOKUP(B79,'114+320'!$B$15:$AB$115,5,FALSE) -> 687 | O79: =F79-N79 -> 1697 | P79: =VLOOKUP(B79,'114+320'!$B$15:$AB$115,14,FALSE) -> -303 | Q79: ='114+320'!R80 -> 0 | R79: =+Q79+R78 -> 123 | S79: =VLOOKUP(B79,'114+320'!$B$14:$AB$115,22,FALSE) -> 689 | T79: =VLOOKUP(B79,'114+320'!$B$15:$AB$115,6,FALSE) -> 615 | U79: =F79-T79 -> 1769 | V79: =VLOOKUP(B79,'114+320'!$B$15:$AB$115,15,FALSE) -> -231 | W79: ='114+320'!S80 -> 0 | X79: =+W79+X78 -> 111 | Y79: =S79-S78 -> 0 | Z79: =IF(Y79>0,Y79,0)/1000 -> 0 | AA79: =AA78+Z79 -> 0.899 | AB79: =(M79-$M$13-R79)/1000 -> 0.734
A80: 42319 | B80: ='114+320'!B81 -> 45110 | C80: =B80-B79 -> 1 | D80: =D79 -> 842 | E80: =VLOOKUP(B80,'114+320'!B81:AB182,3,FALSE) -> 1540 | F80: =D80+E80 -> 2382 | G80: =VLOOKUP(B80,'114+320'!$B$15:$AB$115,20,FALSE) -> 694 | H80: =VLOOKUP(B80,'114+320'!$B$15:$AB$115,4,FALSE) -> 668 | I80: =F80-H80 -> 1714 | J80: =VLOOKUP(B80,'114+320'!$B$15:$AB$115,13,FALSE) -> -286 | K80: ='114+320'!Q81 -> 0 | L80: =+K80+L79 -> 106 | M80: =VLOOKUP(B80,'114+320'!$B$14:$AB$115,21,FALSE) -> 677 | N80: =VLOOKUP(B80,'114+320'!$B$15:$AB$115,5,FALSE) -> 685 | O80: =F80-N80 -> 1697 | P80: =VLOOKUP(B80,'114+320'!$B$15:$AB$115,14,FALSE) -> -303 | Q80: ='114+320'!R81 -> 0 | R80: =+Q80+R79 -> 123 | S80: =VLOOKUP(B80,'114+320'!$B$14:$AB$115,22,FALSE) -> 689 | T80: =VLOOKUP(B80,'114+320'!$B$15:$AB$115,6,FALSE) -> 613 | U80: =F80-T80 -> 1769 | V80: =VLOOKUP(B80,'114+320'!$B$15:$AB$115,15,FALSE) -> -231 | W80: ='114+320'!S81 -> 0 | X80: =+W80+X79 -> 111 | Y80: =S80-S79 -> 0 | Z80: =IF(Y80>0,Y80,0)/1000 -> 0 | AA80: =AA79+Z80 -> 0.899 | AB80: =(M80-$M$13-R80)/1000 -> 0.734
A81: 42322 | B81: ='114+320'!B82 -> 45111 | C81: =B81-B80 -> 1 | D81: =D80 -> 842 | E81: =VLOOKUP(B81,'114+320'!B82:AB183,3,FALSE) -> 1538 | F81: =D81+E81 -> 2380 | G81: =VLOOKUP(B81,'114+320'!$B$15:$AB$115,20,FALSE) -> 694 | H81: =VLOOKUP(B81,'114+320'!$B$15:$AB$115,4,FALSE) -> 666 | I81: =F81-H81 -> 1714 | J81: =VLOOKUP(B81,'114+320'!$B$15:$AB$115,13,FALSE) -> -286 | K81: ='114+320'!Q82 -> 0 | L81: =+K81+L80 -> 106 | M81: =VLOOKUP(B81,'114+320'!$B$14:$AB$115,21,FALSE) -> 677 | N81: =VLOOKUP(B81,'114+320'!$B$15:$AB$115,5,FALSE) -> 683 | O81: =F81-N81 -> 1697 | P81: =VLOOKUP(B81,'114+320'!$B$15:$AB$115,14,FALSE) -> -303 | Q81: ='114+320'!R82 -> 0 | R81: =+Q81+R80 -> 123 | S81: =VLOOKUP(B81,'114+320'!$B$14:$AB$115,22,FALSE) -> 689 | T81: =VLOOKUP(B81,'114+320'!$B$15:$AB$115,6,FALSE) -> 611 | U81: =F81-T81 -> 1769 | V81: =VLOOKUP(B81,'114+320'!$B$15:$AB$115,15,FALSE) -> -231 | W81: ='114+320'!S82 -> 0 | X81: =+W81+X80 -> 111 | Y81: =S81-S80 -> 0 | Z81: =IF(Y81>0,Y81,0)/1000 -> 0 | AA81: =AA80+Z81 -> 0.899 | AB81: =(M81-$M$13-R81)/1000 -> 0.734
A82: 17/11/015 | B82: ='114+320'!B83 -> 45112 | C82: =B82-B81 -> 1 | D82: =D81 -> 842 | E82: =VLOOKUP(B82,'114+320'!B83:AB184,3,FALSE) -> 1536 | F82: =D82+E82 -> 2378 | G82: =VLOOKUP(B82,'114+320'!$B$15:$AB$115,20,FALSE) -> 694 | H82: =VLOOKUP(B82,'114+320'!$B$15:$AB$115,4,FALSE) -> 664 | I82: =F82-H82 -> 1714 | J82: =VLOOKUP(B82,'114+320'!$B$15:$AB$115,13,FALSE) -> -286 | K82: ='114+320'!Q83 -> 0 | L82: =+K82+L81 -> 106 | M82: =VLOOKUP(B82,'114+320'!$B$14:$AB$115,21,FALSE) -> 677 | N82: =VLOOKUP(B82,'114+320'!$B$15:$AB$115,5,FALSE) -> 681 | O82: =F82-N82 -> 1697 | P82: =VLOOKUP(B82,'114+320'!$B$15:$AB$115,14,FALSE) -> -303 | Q82: ='114+320'!R83 -> 0 | R82: =+Q82+R81 -> 123 | S82: =VLOOKUP(B82,'114+320'!$B$14:$AB$115,22,FALSE) -> 689 | T82: =VLOOKUP(B82,'114+320'!$B$15:$AB$115,6,FALSE) -> 609 | U82: =F82-T82 -> 1769 | V82: =VLOOKUP(B82,'114+320'!$B$15:$AB$115,15,FALSE) -> -231 | W82: ='114+320'!S83 -> 0 | X82: =+W82+X81 -> 111 | Y82: =S82-S81 -> 0 | Z82: =IF(Y82>0,Y82,0)/1000 -> 0 | AA82: =AA81+Z82 -> 0.899 | AB82: =(M82-$M$13-R82)/1000 -> 0.734
A83: 42328 | B83: ='114+320'!B84 -> 45113 | C83: =B83-B82 -> 1 | D83: =D82 -> 842 | E83: =VLOOKUP(B83,'114+320'!B84:AB185,3,FALSE) -> 1534 | F83: =D83+E83 -> 2376 | G83: =VLOOKUP(B83,'114+320'!$B$15:$AB$115,20,FALSE) -> 694 | H83: =VLOOKUP(B83,'114+320'!$B$15:$AB$115,4,FALSE) -> 662 | I83: =F83-H83 -> 1714 | J83: =VLOOKUP(B83,'114+320'!$B$15:$AB$115,13,FALSE) -> -286 | K83: ='114+320'!Q84 -> 0 | L83: =+K83+L82 -> 106 | M83: =VLOOKUP(B83,'114+320'!$B$14:$AB$115,21,FALSE) -> 677 | N83: =VLOOKUP(B83,'114+320'!$B$15:$AB$115,5,FALSE) -> 679 | O83: =F83-N83 -> 1697 | P83: =VLOOKUP(B83,'114+320'!$B$15:$AB$115,14,FALSE) -> -303 | Q83: ='114+320'!R84 -> 0 | R83: =+Q83+R82 -> 123 | S83: =VLOOKUP(B83,'114+320'!$B$14:$AB$115,22,FALSE) -> 689 | T83: =VLOOKUP(B83,'114+320'!$B$15:$AB$115,6,FALSE) -> 607 | U83: =F83-T83 -> 1769 | V83: =VLOOKUP(B83,'114+320'!$B$15:$AB$115,15,FALSE) -> -231 | W83: ='114+320'!S84 -> 0 | X83: =+W83+X82 -> 111 | Y83: =S83-S82 -> 0 | Z83: =IF(Y83>0,Y83,0)/1000 -> 0 | AA83: =AA82+Z83 -> 0.899 | AB83: =(M83-$M$13-R83)/1000 -> 0.734
...

Sheet SL.114+320
A1: DỰ ÁN THÀNH PHẦN ĐOẠN HẬU GIANG - CÀ MAU
A2: THUỘC DỰ ÁN XÂY DỰNG CÔNG TRÌNH ĐƯỜNG BỘ CAO TỐC BẮC - NAM PHÍA ĐÔNG GIAI ĐOẠN 2021 - 2025
A3: =UPPER("GÓI THẦU XL03 :Thi Công Xây Dựng Đoạn Tuyến Km114+200 - Km126+223 Bao Gồm Tuyến Nối Nút Giao IC12 Với QL1 (bao gồm khảo sát, thiết kế BVTC)") -> GÓI THẦU XL03 :THI CÔNG XÂY DỰNG ĐOẠN TUYẾN KM114+200 - KM126+223 BAO GỒM TUYẾN NỐI NÚT GIAO IC12 VỚI QL1 (BAO GỒM KHẢO SÁT, THIẾT KẾ BVTC)
A4: CHỦ ĐẦU TƯ | F4: TƯ VẤN GIÁM SÁT | K4: NHÀ THẦU
A5: BAN QUẢN LÝ DỰ ÁN MỸ THUẬN | F5: =UPPER("Liên danh Phân viện KHCN GTVT phía Nam - Công ty Cổ phần Tư vấn kỹ thuật và xây dựng Hồng Hà") -> LIÊN DANH PHÂN VIỆN KHCN GTVT PHÍA NAM - CÔNG TY CỔ PHẦN TƯ VẤN KỸ THUẬT VÀ XÂY DỰNG HỒNG HÀ | K5: LIÊN DANH CC1 - HẢI ĐĂNG - VẠN CƯỜNG - 492 - BẮC TRUNG NAM
A6: BIỂU GHI ĐO QUAN TRẮC LÚN
A7: Người lập: | B7: ='[4]BC.95+020'!C7 -> 0 | K7: Tên mốc: | M7: ='[4]BC.95+020'!N7 -> 0
A8: Thời tiết: | B8: ='[4]BC.95+020'!C8 -> năng | K8: Cao độ mốc: | M8: ='114+320'!M9 -> 842
A9: Lý trình: | B9: ='114+320'!C10 -> Km114+320 | K9: Ngày đặt bàn: | M9: ='114+320'!M10 -> 45043
A11: BÀN QUAN TRẮC: KM114+320
A12: Ngày đo | B12: Số ngày | C12: Cao độ đắp(m) | D12: Chiều cao nền đắp (m) | E12: chiều dày đắp(m) | F12: Trái | H12: Giữa | J12: Phải | L12: Độ lún (trái) (mm) | M12: Độ lún (giữa) (mm) | N12: Độ lún (phải) (mm) | O12: Ghi chú
F13: Cao độ quan trắc | G13: Cao độ bàn đo lún | H13: Cao độ quan trắc | I13: Cao độ bàn đo lún | J13: Cao độ quan trắc | K13: Cao độ bàn đo lún
A14: ='BC.114+320'!B13 -> 45043 | B14: 0 | C14: ='BC.114+320'!M13/1000 -> -0.18 | D14: ='BC.114+320'!AA13 -> 0 | E14: ='BC.114+320'!AB13 -> 0 | F14: =VLOOKUP($A14,'BC.114+320'!$B$13:$X$489,8,0)/1000 -> 1.82 | G14: =VLOOKUP($A14,'BC.114+320'!$B$13:$X$489,9,0)/1000 -> -0.18 | H14: =VLOOKUP($A14,'BC.114+320'!$B$13:$X$489,14,0)/1000 -> 1.82 | I14: =VLOOKUP($A14,'BC.114+320'!$B$13:$X$489,15,0)/1000 -> -0.18 | J14: =VLOOKUP($A14,'BC.114+320'!$B$13:$X$489,20,0)/1000 -> 1.88 | K14: =VLOOKUP($A14,'BC.114+320'!$B$13:$X$489,21,0)/1000 -> -0.12 | L14: =(G14-$G$14)*1000 -> 0 | M14: =(I14-$I$14)*1000 -> 0 | N14: 0
A15: ='BC.114+320'!B14 -> 45044 | B15: 1 | C15: ='BC.114+320'!M14/1000 -> -0.18 | D15: ='BC.114+320'!AA14 -> 0 | E15: ='BC.114+320'!AB14 -> 0 | F15: =VLOOKUP($A15,'BC.114+320'!$B$13:$X$489,8,0)/1000 -> 1.82 | G15: =VLOOKUP($A15,'BC.114+320'!$B$13:$X$489,9,0)/1000 -> -0.18 | H15: =VLOOKUP($A15,'BC.114+320'!$B$13:$X$489,14,0)/1000 -> 1.82 | I15: =VLOOKUP($A15,'BC.114+320'!$B$13:$X$489,15,0)/1000 -> -0.18 | J15: =VLOOKUP($A15,'BC.114+320'!$B$13:$X$489,20,0)/1000 -> 1.88 | K15: =VLOOKUP($A15,'BC.114+320'!$B$13:$X$489,21,0)/1000 -> -0.12 | L15: =(G15-$G$14)*1000 -> 0 | M15: =(I15-$I$14)*1000 -> 0 | N15: =(K15-$K$14)*1000 -> 0
A16: ='BC.114+320'!B15 -> 45045 | B16: =+B15+1 -> 2 | C16: ='BC.114+320'!M15/1000 -> -0.18 | D16: ='BC.114+320'!AA15 -> 0 | E16: ='BC.114+320'!AB15 -> 0 | F16: =VLOOKUP($A16,'BC.114+320'!$B$13:$X$489,8,0)/1000 -> 1.82 | G16: =VLOOKUP($A16,'BC.114+320'!$B$13:$X$489,9,0)/1000 -> -0.18 | H16: =VLOOKUP($A16,'BC.114+320'!$B$13:$X$489,14,0)/1000 -> 1.82 | I16: =VLOOKUP($A16,'BC.114+320'!$B$13:$X$489,15,0)/1000 -> -0.18 | J16: =VLOOKUP($A16,'BC.114+320'!$B$13:$X$489,20,0)/1000 -> 1.88 | K16: =VLOOKUP($A16,'BC.114+320'!$B$13:$X$489,21,0)/1000 -> -0.12 | L16: =(G16-$G$14)*1000 -> 0 | M16: =(I16-$I$14)*1000 -> 0 | N16: =(K16-$K$14)*1000 -> 0
A17: ='BC.114+320'!B16 -> 45046 | B17: =+B16+1 -> 3 | C17: ='BC.114+320'!M16/1000 -> -0.18 | D17: ='BC.114+320'!AA16 -> 0 | E17: ='BC.114+320'!AB16 -> 0 | F17: =VLOOKUP($A17,'BC.114+320'!$B$13:$X$489,8,0)/1000 -> 1.82 | G17: =VLOOKUP($A17,'BC.114+320'!$B$13:$X$489,9,0)/1000 -> -0.18 | H17: =VLOOKUP($A17,'BC.114+320'!$B$13:$X$489,14,0)/1000 -> 1.82 | I17: =VLOOKUP($A17,'BC.114+320'!$B$13:$X$489,15,0)/1000 -> -0.18 | J17: =VLOOKUP($A17,'BC.114+320'!$B$13:$X$489,20,0)/1000 -> 1.88 | K17: =VLOOKUP($A17,'BC.114+320'!$B$13:$X$489,21,0)/1000 -> -0.12 | L17: =(G17-$G$14)*1000 -> 0 | M17: =(I17-$I$14)*1000 -> 0 | N17: =(K17-$K$14)*1000 -> 0
A18: ='BC.114+320'!B17 -> 45047 | B18: =+B17+1 -> 4 | C18: ='BC.114+320'!M17/1000 -> -0.18 | D18: ='BC.114+320'!AA17 -> 0 | E18: ='BC.114+320'!AB17 -> 0 | F18: =VLOOKUP($A18,'BC.114+320'!$B$13:$X$489,8,0)/1000 -> 1.82 | G18: =VLOOKUP($A18,'BC.114+320'!$B$13:$X$489,9,0)/1000 -> -0.18 | H18: =VLOOKUP($A18,'BC.114+320'!$B$13:$X$489,14,0)/1000 -> 1.82 | I18: =VLOOKUP($A18,'BC.114+320'!$B$13:$X$489,15,0)/1000 -> -0.18 | J18: =VLOOKUP($A18,'BC.114+320'!$B$13:$X$489,20,0)/1000 -> 1.88 | K18: =VLOOKUP($A18,'BC.114+320'!$B$13:$X$489,21,0)/1000 -> -0.12 | L18: =(G18-$G$14)*1000 -> 0 | M18: =(I18-$I$14)*1000 -> 0 | N18: =(K18-$K$14)*1000 -> 0
A19: ='BC.114+320'!B18 -> 45048 | B19: =+B18+1 -> 5 | C19: ='BC.114+320'!M18/1000 -> -0.18 | D19: ='BC.114+320'!AA18 -> 0 | E19: ='BC.114+320'!AB18 -> 0 | F19: =VLOOKUP($A19,'BC.114+320'!$B$13:$X$489,8,0)/1000 -> 1.82 | G19: =VLOOKUP($A19,'BC.114+320'!$B$13:$X$489,9,0)/1000 -> -0.18 | H19: =VLOOKUP($A19,'BC.114+320'!$B$13:$X$489,14,0)/1000 -> 1.82 | I19: =VLOOKUP($A19,'BC.114+320'!$B$13:$X$489,15,0)/1000 -> -0.18 | J19: =VLOOKUP($A19,'BC.114+320'!$B$13:$X$489,20,0)/1000 -> 1.88 | K19: =VLOOKUP($A19,'BC.114+320'!$B$13:$X$489,21,0)/1000 -> -0.12 | L19: =(G19-$G$14)*1000 -> 0 | M19: =(I19-$I$14)*1000 -> 0 | N19: =(K19-$K$14)*1000 -> 0
A20: ='BC.114+320'!B19 -> 45049 | B20: =+B19+1 -> 6 | C20: ='BC.114+320'!M19/1000 -> -0.18 | D20: ='BC.114+320'!AA19 -> 0 | E20: ='BC.114+320'!AB19 -> 0 | F20: =VLOOKUP($A20,'BC.114+320'!$B$13:$X$489,8,0)/1000 -> 1.82 | G20: =VLOOKUP($A20,'BC.114+320'!$B$13:$X$489,9,0)/1000 -> -0.18 | H20: =VLOOKUP($A20,'BC.114+320'!$B$13:$X$489,14,0)/1000 -> 1.82 | I20: =VLOOKUP($A20,'BC.114+320'!$B$13:$X$489,15,0)/1000 -> -0.18 | J20: =VLOOKUP($A20,'BC.114+320'!$B$13:$X$489,20,0)/1000 -> 1.88 | K20: =VLOOKUP($A20,'BC.114+320'!$B$13:$X$489,21,0)/1000 -> -0.12 | L20: =(G20-$G$14)*1000 -> 0 | M20: =(I20-$I$14)*1000 -> 0 | N20: =(K20-$K$14)*1000 -> 0
A21: ='BC.114+320'!B20 -> 45050 | B21: =+B20+1 -> 7 | C21: ='BC.114+320'!M20/1000 -> -0.18 | D21: ='BC.114+320'!AA20 -> 0 | E21: ='BC.114+320'!AB20 -> 0 | F21: =VLOOKUP($A21,'BC.114+320'!$B$13:$X$489,8,0)/1000 -> 1.82 | G21: =VLOOKUP($A21,'BC.114+320'!$B$13:$X$489,9,0)/1000 -> -0.18 | H21: =VLOOKUP($A21,'BC.114+320'!$B$13:$X$489,14,0)/1000 -> 1.82 | I21: =VLOOKUP($A21,'BC.114+320'!$B$13:$X$489,15,0)/1000 -> -0.18 | J21: =VLOOKUP($A21,'BC.114+320'!$B$13:$X$489,20,0)/1000 -> 1.88 | K21: =VLOOKUP($A21,'BC.114+320'!$B$13:$X$489,21,0)/1000 -> -0.12 | L21: =(G21-$G$14)*1000 -> 0 | M21: =(I21-$I$14)*1000 -> 0 | N21: =(K21-$K$14)*1000 -> 0
A22: ='BC.114+320'!B21 -> 45051 | B22: =+B21+1 -> 8 | C22: ='BC.114+320'!M21/1000 -> -0.18 | D22: ='BC.114+320'!AA21 -> 0 | E22: ='BC.114+320'!AB21 -> 0 | F22: =VLOOKUP($A22,'BC.114+320'!$B$13:$X$489,8,0)/1000 -> 1.82 | G22: =VLOOKUP($A22,'BC.114+320'!$B$13:$X$489,9,0)/1000 -> -0.18 | H22: =VLOOKUP($A22,'BC.114+320'!$B$13:$X$489,14,0)/1000 -> 1.82 | I22: =VLOOKUP($A22,'BC.114+320'!$B$13:$X$489,15,0)/1000 -> -0.18 | J22: =VLOOKUP($A22,'BC.114+320'!$B$13:$X$489,20,0)/1000 -> 1.88 | K22: =VLOOKUP($A22,'BC.114+320'!$B$13:$X$489,21,0)/1000 -> -0.12 | L22: =(G22-$G$14)*1000 -> 0 | M22: =(I22-$I$14)*1000 -> 0 | N22: =(K22-$K$14)*1000 -> 0
A23: ='BC.114+320'!B22 -> 45052 | B23: =+B22+1 -> 9 | C23: ='BC.114+320'!M22/1000 -> -0.18 | D23: ='BC.114+320'!AA22 -> 0 | E23: ='BC.114+320'!AB22 -> 0 | F23: =VLOOKUP($A23,'BC.114+320'!$B$13:$X$489,8,0)/1000 -> 1.82 | G23: =VLOOKUP($A23,'BC.114+320'!$B$13:$X$489,9,0)/1000 -> -0.18 | H23: =VLOOKUP($A23,'BC.114+320'!$B$13:$X$489,14,0)/1000 -> 1.82 | I23: =VLOOKUP($A23,'BC.114+320'!$B$13:$X$489,15,0)/1000 -> -0.18 | J23: =VLOOKUP($A23,'BC.114+320'!$B$13:$X$489,20,0)/1000 -> 1.88 | K23: =VLOOKUP($A23,'BC.114+320'!$B$13:$X$489,21,0)/1000 -> -0.12 | L23: =(G23-$G$14)*1000 -> 0 | M23: =(I23-$I$14)*1000 -> 0 | N23: =(K23-$K$14)*1000 -> 0
A24: ='BC.114+320'!B23 -> 45053 | B24: =+B23+1 -> 10 | C24: ='BC.114+320'!M23/1000 -> -0.18 | D24: ='BC.114+320'!AA23 -> 0 | E24: ='BC.114+320'!AB23 -> 0 | F24: =VLOOKUP($A24,'BC.114+320'!$B$13:$X$489,8,0)/1000 -> 1.82 | G24: =VLOOKUP($A24,'BC.114+320'!$B$13:$X$489,9,0)/1000 -> -0.18 | H24: =VLOOKUP($A24,'BC.114+320'!$B$13:$X$489,14,0)/1000 -> 1.82 | I24: =VLOOKUP($A24,'BC.114+320'!$B$13:$X$489,15,0)/1000 -> -0.18 | J24: =VLOOKUP($A24,'BC.114+320'!$B$13:$X$489,20,0)/1000 -> 1.88 | K24: =VLOOKUP($A24,'BC.114+320'!$B$13:$X$489,21,0)/1000 -> -0.12 | L24: =(G24-$G$14)*1000 -> 0 | M24: =(I24-$I$14)*1000 -> 0 | N24: =(K24-$K$14)*1000 -> 0
A25: ='BC.114+320'!B24 -> 45054 | B25: =+B24+1 -> 11 | C25: ='BC.114+320'!M24/1000 -> -0.18 | D25: ='BC.114+320'!AA24 -> 0 | E25: ='BC.114+320'!AB24 -> 0 | F25: =VLOOKUP($A25,'BC.114+320'!$B$13:$X$489,8,0)/1000 -> 1.82 | G25: =VLOOKUP($A25,'BC.114+320'!$B$13:$X$489,9,0)/1000 -> -0.18 | H25: =VLOOKUP($A25,'BC.114+320'!$B$13:$X$489,14,0)/1000 -> 1.82 | I25: =VLOOKUP($A25,'BC.114+320'!$B$13:$X$489,15,0)/1000 -> -0.18 | J25: =VLOOKUP($A25,'BC.114+320'!$B$13:$X$489,20,0)/1000 -> 1.88 | K25: =VLOOKUP($A25,'BC.114+320'!$B$13:$X$489,21,0)/1000 -> -0.12 | L25: =(G25-$G$14)*1000 -> 0 | M25: =(I25-$I$14)*1000 -> 0 | N25: =(K25-$K$14)*1000 -> 0
A26: ='BC.114+320'!B25 -> 45055 | B26: =+B25+1 -> 12 | C26: ='BC.114+320'!M25/1000 -> -0.18 | D26: ='BC.114+320'!AA25 -> 0 | E26: ='BC.114+320'!AB25 -> 0 | F26: =VLOOKUP($A26,'BC.114+320'!$B$13:$X$489,8,0)/1000 -> 1.82 | G26: =VLOOKUP($A26,'BC.114+320'!$B$13:$X$489,9,0)/1000 -> -0.18 | H26: =VLOOKUP($A26,'BC.114+320'!$B$13:$X$489,14,0)/1000 -> 1.82 | I26: =VLOOKUP($A26,'BC.114+320'!$B$13:$X$489,15,0)/1000 -> -0.18 | J26: =VLOOKUP($A26,'BC.114+320'!$B$13:$X$489,20,0)/1000 -> 1.88 | K26: =VLOOKUP($A26,'BC.114+320'!$B$13:$X$489,21,0)/1000 -> -0.12 | L26: =(G26-$G$14)*1000 -> 0 | M26: =(I26-$I$14)*1000 -> 0 | N26: =(K26-$K$14)*1000 -> 0
A27: ='BC.114+320'!B26 -> 45056 | B27: =+B26+1 -> 13 | C27: ='BC.114+320'!M26/1000 -> -0.18 | D27: ='BC.114+320'!AA26 -> 0 | E27: ='BC.114+320'!AB26 -> 0 | F27: =VLOOKUP($A27,'BC.114+320'!$B$13:$X$489,8,0)/1000 -> 1.82 | G27: =VLOOKUP($A27,'BC.114+320'!$B$13:$X$489,9,0)/1000 -> -0.18 | H27: =VLOOKUP($A27,'BC.114+320'!$B$13:$X$489,14,0)/1000 -> 1.82 | I27: =VLOOKUP($A27,'BC.114+320'!$B$13:$X$489,15,0)/1000 -> -0.18 | J27: =VLOOKUP($A27,'BC.114+320'!$B$13:$X$489,20,0)/1000 -> 1.88 | K27: =VLOOKUP($A27,'BC.114+320'!$B$13:$X$489,21,0)/1000 -> -0.12 | L27: =(G27-$G$14)*1000 -> 0 | M27: =(I27-$I$14)*1000 -> 0 | N27: =(K27-$K$14)*1000 -> 0
... A91: ='BC.114+320'!B90 -> 45120 | B91: =+B90+1 -> 77 | C91: ='BC.114+320'!M90/1000 -> 0.677 | D91: ='BC.114+320'!AA90 -> 0.899 | E91: ='BC.114+320'!AB90 -> 0.734 | F91: =VLOOKUP($A91,'BC.114+320'!$B$13:$X$489,8,0)/1000 -> 1.714 | G91: =VLOOKUP($A91,'BC.114+320'!$B$13:$X$489,9,0)/1000 -> -0.286 | H91: =VLOOKUP($A91,'BC.114+320'!$B$13:$X$489,14,0)/1000 -> 1.697 | I91: =VLOOKUP($A91,'BC.114+320'!$B$13:$X$489,15,0)/1000 -> -0.303 | J91: =VLOOKUP($A91,'BC.114+320'!$B$13:$X$489,20,0)/1000 -> 1.769 | K91: =VLOOKUP($A91,'BC.114+320'!$B$13:$X$489,21,0)/1000 -> -0.231 | L91: =(G91-$G$14)*1000 -> -106 | M91: =(I91-$I$14)*1000 -> -123 | N91: =(K91-$K$14)*1000 -> -111
A92: ='BC.114+320'!B91 -> 45121 | B92: =+B91+1 -> 78 | C92: ='BC.114+320'!M91/1000 -> 0.677 | D92: ='BC.114+320'!AA91 -> 0.899 | E92: ='BC.114+320'!AB91 -> 0.734 | F92: =VLOOKUP($A92,'BC.114+320'!$B$13:$X$489,8,0)/1000 -> 1.714 | G92: =VLOOKUP($A92,'BC.114+320'!$B$13:$X$489,9,0)/1000 -> -0.286 | H92: =VLOOKUP($A92,'BC.114+320'!$B$13:$X$489,14,0)/1000 -> 1.697 | I92: =VLOOKUP($A92,'BC.114+320'!$B$13:$X$489,15,0)/1000 -> -0.303 | J92: =VLOOKUP($A92,'BC.114+320'!$B$13:$X$489,20,0)/1000 -> 1.769 | K92: =VLOOKUP($A92,'BC.114+320'!$B$13:$X$489,21,0)/1000 -> -0.231 | L92: =(G92-$G$14)*1000 -> -106 | M92: =(I92-$I$14)*1000 -> -123 | N92: =(K92-$K$14)*1000 -> -111 | Y92: =A21-A14 -> 7
